{
  "version": 8,
  "blockIdVersion": 11,
  "anchorX": 0,
  "anchorY": 0,
  "anchorZ": 7,
  "blocks": [
    {
      "x": -5,
      "y": 0,
      "z": -7,
      "name": "Rock_CastIron_Brick_Smooth"
    },
    {
      "x": -5,
      "y": 1,
      "z": -7,
      "name": "Rock_CastIron_Brick"
    },
    {
      "x": -5,
      "y": 2,
      "z": -7,
      "name": "Rock_CastIron_Brick"
    },
    {
      "x": -5,
      "y": 3,
      "z": -7,
      "name": "Rock_CastIron_Brick"
    },
    {
      "x": -5,
      "y": 4,
      "z": -7,
      "name": "Rock_CastIron_Brick"
    },
    {
      "x": -5,
      "y": 5,
      "z": -7,
      "name": "Rock_DarkConcrete"
    },
    {
      "x": -5,
      "y": 6,
      "z": -7,
      "name": "Rock_DarkConcrete"
    },
    {
      "x": -5,
      "y": 7,
      "z": -7,
      "name": "Rock_DarkConcrete"
    },
    {
      "x": -5,
      "y": 0,
      "z": -6,
      "name": "Rock_CastIron_Brick_Smooth"
    },
    {
      "x": -5,
      "y": 1,
      "z": -6,
      "name": "Rock_CastIron_Brick"
    },
    {
      "x": -5,
      "y": 2,
      "z": -6,
      "name": "Rock_CastIron_Brick"
    },
    {
      "x": -5,
      "y": 3,
      "z": -6,
      "name": "Rock_CastIron_Brick"
    },
    {
      "x": -5,
      "y": 4,
      "z": -6,
      "name": "Rock_CastIron_Brick"
    },
    {
      "x": -5,
      "y": 5,
      "z": -6,
      "name": "Rock_DarkConcrete"
    },
    {
      "x": -5,
      "y": 6,
      "z": -6,
      "name": "Rock_DarkConcrete"
    },
    {
      "x": -5,
      "y": 7,
      "z": -6,
      "name": "Rock_DarkConcrete"
    },
    {
      "x": -5,
      "y": 0,
      "z": -5,
      "name": "Rock_CastIron_Brick_Smooth"
    },
    {
      "x": -5,
      "y": 1,
      "z": -5,
      "name": "Rock_CastIron"
    },
    {
      "x": -5,
      "y": 2,
      "z": -5,
      "name": "Rock_CastIron"
    },
    {
      "x": -5,
      "y": 3,
      "z": -5,
      "name": "Rock_CastIron"
    },
    {
      "x": -5,
      "y": 4,
      "z": -5,
      "name": "Rock_CastIron"
    },
    {
      "x": -5,
      "y": 5,
      "z": -5,
      "name": "Rock_DarkConcrete"
    },
    {
      "x": -5,
      "y": 6,
      "z": -5,
      "name": "Rock_DarkConcrete"
    },
    {
      "x": -5,
      "y": 7,
      "z": -5,
      "name": "Rock_DarkConcrete"
    },
    {
      "x": -5,
      "y": 0,
      "z": -4,
      "name": "Rock_CastIron_Brick_Smooth"
    },
    {
      "x": -5,
      "y": 1,
      "z": -4,
      "name": "Rock_CastIron"
    },
    {
      "x": -5,
      "y": 2,
      "z": -4,
      "name": "Rock_CastIron"
    },
    {
      "x": -5,
      "y": 3,
      "z": -4,
      "name": "Rock_CastIron"
    },
    {
      "x": -5,
      "y": 4,
      "z": -4,
      "name": "Rock_CastIron"
    },
    {
      "x": -5,
      "y": 5,
      "z": -4,
      "name": "Rock_DarkConcrete"
    },
    {
      "x": -5,
      "y": 6,
      "z": -4,
      "name": "Rock_DarkConcrete"
    },
    {
      "x": -5,
      "y": 7,
      "z": -4,
      "name": "Rock_DarkConcrete"
    },
    {
      "x": -5,
      "y": 0,
      "z": -3,
      "name": "Rock_CastIron_Brick_Smooth"
    },
    {
      "x": -5,
      "y": 1,
      "z": -3,
      "name": "Rock_CastIron_Brick"
    },
    {
      "x": -5,
      "y": 2,
      "z": -3,
      "name": "Rock_CastIron_Brick"
    },
    {
      "x": -5,
      "y": 3,
      "z": -3,
      "name": "Rock_CastIron_Brick"
    },
    {
      "x": -5,
      "y": 4,
      "z": -3,
      "name": "Rock_CastIron_Brick"
    },
    {
      "x": -5,
      "y": 5,
      "z": -3,
      "name": "Rock_DarkConcrete"
    },
    {
      "x": -5,
      "y": 6,
      "z": -3,
      "name": "Rock_DarkConcrete"
    },
    {
      "x": -5,
      "y": 7,
      "z": -3,
      "name": "Rock_DarkConcrete"
    },
    {
      "x": -5,
      "y": 0,
      "z": -2,
      "name": "Rock_CastIron_Brick_Smooth"
    },
    {
      "x": -5,
      "y": 1,
      "z": -2,
      "name": "Rock_CastIron_Brick"
    },
    {
      "x": -5,
      "y": 2,
      "z": -2,
      "name": "Rock_CastIron_Brick"
    },
    {
      "x": -5,
      "y": 3,
      "z": -2,
      "name": "Rock_CastIron_Brick"
    },
    {
      "x": -5,
      "y": 4,
      "z": -2,
      "name": "Rock_CastIron_Brick"
    },
    {
      "x": -5,
      "y": 5,
      "z": -2,
      "name": "Rock_DarkConcrete"
    },
    {
      "x": -5,
      "y": 6,
      "z": -2,
      "name": "Rock_DarkConcrete"
    },
    {
      "x": -5,
      "y": 7,
      "z": -2,
      "name": "Rock_DarkConcrete"
    },
    {
      "x": -5,
      "y": 0,
      "z": -1,
      "name": "Rock_CastIron_Brick_Smooth"
    },
    {
      "x": -5,
      "y": 1,
      "z": -1,
      "name": "Rock_CastIron"
    },
    {
      "x": -5,
      "y": 2,
      "z": -1,
      "name": "Rock_CastIron"
    },
    {
      "x": -5,
      "y": 3,
      "z": -1,
      "name": "Rock_CastIron"
    },
    {
      "x": -5,
      "y": 4,
      "z": -1,
      "name": "Rock_CastIron"
    },
    {
      "x": -5,
      "y": 5,
      "z": -1,
      "name": "Rock_DarkConcrete"
    },
    {
      "x": -5,
      "y": 6,
      "z": -1,
      "name": "Rock_DarkConcrete"
    },
    {
      "x": -5,
      "y": 7,
      "z": -1,
      "name": "Rock_DarkConcrete"
    },
    {
      "x": -5,
      "y": 0,
      "z": 0,
      "name": "Rock_CastIron_Brick_Smooth"
    },
    {
      "x": -5,
      "y": 1,
      "z": 0,
      "name": "Rock_CastIron"
    },
    {
      "x": -5,
      "y": 2,
      "z": 0,
      "name": "Rock_CastIron"
    },
    {
      "x": -5,
      "y": 3,
      "z": 0,
      "name": "Rock_CastIron"
    },
    {
      "x": -5,
      "y": 4,
      "z": 0,
      "name": "Rock_CastIron"
    },
    {
      "x": -5,
      "y": 5,
      "z": 0,
      "name": "Rock_DarkConcrete"
    },
    {
      "x": -5,
      "y": 6,
      "z": 0,
      "name": "Rock_DarkConcrete"
    },
    {
      "x": -5,
      "y": 7,
      "z": 0,
      "name": "Rock_DarkConcrete"
    },
    {
      "x": -5,
      "y": 0,
      "z": 1,
      "name": "Rock_CastIron_Brick_Smooth"
    },
    {
      "x": -5,
      "y": 1,
      "z": 1,
      "name": "Rock_CastIron"
    },
    {
      "x": -5,
      "y": 2,
      "z": 1,
      "name": "Rock_CastIron"
    },
    {
      "x": -5,
      "y": 3,
      "z": 1,
      "name": "Rock_CastIron"
    },
    {
      "x": -5,
      "y": 4,
      "z": 1,
      "name": "Rock_CastIron"
    },
    {
      "x": -5,
      "y": 5,
      "z": 1,
      "name": "Rock_DarkConcrete"
    },
    {
      "x": -5,
      "y": 6,
      "z": 1,
      "name": "Rock_DarkConcrete"
    },
    {
      "x": -5,
      "y": 7,
      "z": 1,
      "name": "Rock_DarkConcrete"
    },
    {
      "x": -5,
      "y": 0,
      "z": 2,
      "name": "Rock_CastIron_Brick_Smooth"
    },
    {
      "x": -5,
      "y": 1,
      "z": 2,
      "name": "Rock_CastIron_Brick"
    },
    {
      "x": -5,
      "y": 2,
      "z": 2,
      "name": "Rock_CastIron_Brick"
    },
    {
      "x": -5,
      "y": 3,
      "z": 2,
      "name": "Rock_CastIron_Brick"
    },
    {
      "x": -5,
      "y": 4,
      "z": 2,
      "name": "Rock_CastIron_Brick"
    },
    {
      "x": -5,
      "y": 5,
      "z": 2,
      "name": "Rock_DarkConcrete"
    },
    {
      "x": -5,
      "y": 6,
      "z": 2,
      "name": "Rock_DarkConcrete"
    },
    {
      "x": -5,
      "y": 7,
      "z": 2,
      "name": "Rock_DarkConcrete"
    },
    {
      "x": -5,
      "y": 0,
      "z": 3,
      "name": "Rock_CastIron_Brick_Smooth"
    },
    {
      "x": -5,
      "y": 1,
      "z": 3,
      "name": "Rock_CastIron_Brick"
    },
    {
      "x": -5,
      "y": 2,
      "z": 3,
      "name": "Rock_CastIron_Brick"
    },
    {
      "x": -5,
      "y": 3,
      "z": 3,
      "name": "Rock_CastIron_Brick"
    },
    {
      "x": -5,
      "y": 4,
      "z": 3,
      "name": "Rock_CastIron_Brick"
    },
    {
      "x": -5,
      "y": 5,
      "z": 3,
      "name": "Rock_DarkConcrete"
    },
    {
      "x": -5,
      "y": 6,
      "z": 3,
      "name": "Rock_DarkConcrete"
    },
    {
      "x": -5,
      "y": 7,
      "z": 3,
      "name": "Rock_DarkConcrete"
    },
    {
      "x": -5,
      "y": 0,
      "z": 4,
      "name": "Rock_CastIron_Brick_Smooth"
    },
    {
      "x": -5,
      "y": 1,
      "z": 4,
      "name": "Rock_CastIron"
    },
    {
      "x": -5,
      "y": 2,
      "z": 4,
      "name": "Rock_CastIron"
    },
    {
      "x": -5,
      "y": 3,
      "z": 4,
      "name": "Rock_CastIron"
    },
    {
      "x": -5,
      "y": 4,
      "z": 4,
      "name": "Rock_CastIron"
    },
    {
      "x": -5,
      "y": 5,
      "z": 4,
      "name": "Rock_DarkConcrete"
    },
    {
      "x": -5,
      "y": 6,
      "z": 4,
      "name": "Rock_DarkConcrete"
    },
    {
      "x": -5,
      "y": 7,
      "z": 4,
      "name": "Rock_DarkConcrete"
    },
    {
      "x": -5,
      "y": 0,
      "z": 5,
      "name": "Rock_CastIron_Brick_Smooth"
    },
    {
      "x": -5,
      "y": 1,
      "z": 5,
      "name": "Rock_CastIron"
    },
    {
      "x": -5,
      "y": 2,
      "z": 5,
      "name": "Rock_CastIron"
    },
    {
      "x": -5,
      "y": 3,
      "z": 5,
      "name": "Rock_CastIron"
    },
    {
      "x": -5,
      "y": 4,
      "z": 5,
      "name": "Rock_CastIron"
    },
    {
      "x": -5,
      "y": 5,
      "z": 5,
      "name": "Rock_DarkConcrete"
    },
    {
      "x": -5,
      "y": 6,
      "z": 5,
      "name": "Rock_DarkConcrete"
    },
    {
      "x": -5,
      "y": 7,
      "z": 5,
      "name": "Rock_DarkConcrete"
    },
    {
      "x": -5,
      "y": 0,
      "z": 6,
      "name": "Rock_CastIron_Brick_Smooth"
    },
    {
      "x": -5,
      "y": 1,
      "z": 6,
      "name": "Rock_CastIron_Brick"
    },
    {
      "x": -5,
      "y": 2,
      "z": 6,
      "name": "Rock_CastIron_Brick"
    },
    {
      "x": -5,
      "y": 3,
      "z": 6,
      "name": "Rock_CastIron_Brick"
    },
    {
      "x": -5,
      "y": 4,
      "z": 6,
      "name": "Rock_CastIron_Brick"
    },
    {
      "x": -5,
      "y": 5,
      "z": 6,
      "name": "Rock_DarkConcrete"
    },
    {
      "x": -5,
      "y": 6,
      "z": 6,
      "name": "Rock_DarkConcrete"
    },
    {
      "x": -5,
      "y": 7,
      "z": 6,
      "name": "Rock_DarkConcrete"
    },
    {
      "x": -5,
      "y": 0,
      "z": 7,
      "name": "Rock_CastIron_Brick_Smooth"
    },
    {
      "x": -5,
      "y": 1,
      "z": 7,
      "name": "Rock_CastIron_Brick"
    },
    {
      "x": -5,
      "y": 2,
      "z": 7,
      "name": "Rock_CastIron_Brick"
    },
    {
      "x": -5,
      "y": 3,
      "z": 7,
      "name": "Rock_CastIron_Brick"
    },
    {
      "x": -5,
      "y": 4,
      "z": 7,
      "name": "Rock_CastIron_Brick"
    },
    {
      "x": -5,
      "y": 5,
      "z": 7,
      "name": "Rock_DarkConcrete"
    },
    {
      "x": -5,
      "y": 6,
      "z": 7,
      "name": "Rock_DarkConcrete"
    },
    {
      "x": -5,
      "y": 7,
      "z": 7,
      "name": "Rock_DarkConcrete"
    },
    {
      "x": -4,
      "y": 0,
      "z": -7,
      "name": "Rock_CastIron_Brick_Smooth"
    },
    {
      "x": -4,
      "y": 1,
      "z": -7,
      "name": "Rock_CastIron_Brick_Smooth"
    },
    {
      "x": -4,
      "y": 2,
      "z": -7,
      "name": "Rock_CastIron_Brick_Pillar_Base"
    },
    {
      "x": -4,
      "y": 3,
      "z": -7,
      "name": "Rock_CastIron_Brick_Pillar_Middle"
    },
    {
      "x": -4,
      "y": 4,
      "z": -7,
      "name": "Rock_CastIron_Brick_Pillar_Base",
      "rotation": 8
    },
    {
      "x": -4,
      "y": 5,
      "z": -7,
      "name": "Rock_CastIron_Brick"
    },
    {
      "x": -4,
      "y": 6,
      "z": -7,
      "name": "Rock_CastIron_Brick"
    },
    {
      "x": -4,
      "y": 7,
      "z": -7,
      "name": "Rock_DarkConcrete"
    },
    {
      "x": -4,
      "y": 0,
      "z": -6,
      "name": "Rock_CastIron_Brick_Smooth"
    },
    {
      "x": -4,
      "y": 1,
      "z": -6,
      "name": "Rock_CastIron_Brick_Stairs",
      "rotation": 11
    },
    {
      "x": -4,
      "y": 2,
      "z": -6,
      "name": "Empty"
    },
    {
      "x": -4,
      "y": 3,
      "z": -6,
      "name": "Plant_Vine_Wall",
      "support": 15,
      "rotation": 1
    },
    {
      "x": -4,
      "y": 4,
      "z": -6,
      "name": "Empty"
    },
    {
      "x": -4,
      "y": 5,
      "z": -6,
      "name": "Rock_CastIron_Brick_Stairs",
      "rotation": 10
    },
    {
      "x": -4,
      "y": 6,
      "z": -6,
      "name": "Rock_CastIron_Brick"
    },
    {
      "x": -4,
      "y": 7,
      "z": -6,
      "name": "Rock_DarkConcrete"
    },
    {
      "x": -4,
      "y": 0,
      "z": -5,
      "name": "Rock_CastIron_Brick_Smooth"
    },
    {
      "x": -4,
      "y": 1,
      "z": -5,
      "name": "Rock_CastIron_Brick_Stairs",
      "rotation": 11
    },
    {
      "x": -4,
      "y": 2,
      "z": -5,
      "name": "Empty"
    },
    {
      "x": -4,
      "y": 3,
      "z": -5,
      "name": "Plant_Vine_Wall",
      "support": 15,
      "rotation": 1
    },
    {
      "x": -4,
      "y": 4,
      "z": -5,
      "name": "Empty"
    },
    {
      "x": -4,
      "y": 5,
      "z": -5,
      "name": "Empty"
    },
    {
      "x": -4,
      "y": 6,
      "z": -5,
      "name": "Rock_CastIron_Brick"
    },
    {
      "x": -4,
      "y": 7,
      "z": -5,
      "name": "Rock_DarkConcrete"
    },
    {
      "x": -4,
      "y": 0,
      "z": -4,
      "name": "Rock_CastIron_Brick_Smooth"
    },
    {
      "x": -4,
      "y": 1,
      "z": -4,
      "name": "Rock_CastIron_Brick_Stairs",
      "rotation": 11
    },
    {
      "x": -4,
      "y": 2,
      "z": -4,
      "name": "Empty"
    },
    {
      "x": -4,
      "y": 3,
      "z": -4,
      "name": "Empty"
    },
    {
      "x": -4,
      "y": 4,
      "z": -4,
      "name": "Empty"
    },
    {
      "x": -4,
      "y": 5,
      "z": -4,
      "name": "Empty"
    },
    {
      "x": -4,
      "y": 6,
      "z": -4,
      "name": "Rock_CastIron_Brick"
    },
    {
      "x": -4,
      "y": 7,
      "z": -4,
      "name": "Rock_DarkConcrete"
    },
    {
      "x": -4,
      "y": 0,
      "z": -3,
      "name": "Rock_CastIron_Brick_Smooth"
    },
    {
      "x": -4,
      "y": 1,
      "z": -3,
      "name": "Rock_CastIron_Brick_Stairs",
      "rotation": 11
    },
    {
      "x": -4,
      "y": 2,
      "z": -3,
      "name": "Empty"
    },
    {
      "x": -4,
      "y": 3,
      "z": -3,
      "name": "Empty"
    },
    {
      "x": -4,
      "y": 4,
      "z": -3,
      "name": "Empty"
    },
    {
      "x": -4,
      "y": 5,
      "z": -3,
      "name": "Rock_CastIron_Brick_Stairs",
      "rotation": 8
    },
    {
      "x": -4,
      "y": 6,
      "z": -3,
      "name": "Rock_CastIron_Brick"
    },
    {
      "x": -4,
      "y": 7,
      "z": -3,
      "name": "Rock_DarkConcrete"
    },
    {
      "x": -4,
      "y": 0,
      "z": -2,
      "name": "Rock_CastIron_Brick_Smooth"
    },
    {
      "x": -4,
      "y": 1,
      "z": -2,
      "name": "Rock_CastIron_Brick_Smooth"
    },
    {
      "x": -4,
      "y": 2,
      "z": -2,
      "name": "Rock_CastIron_Brick_Pillar_Base"
    },
    {
      "x": -4,
      "y": 3,
      "z": -2,
      "name": "Rock_CastIron_Brick_Pillar_Middle"
    },
    {
      "x": -4,
      "y": 4,
      "z": -2,
      "name": "Rock_CastIron_Brick_Pillar_Base",
      "rotation": 8
    },
    {
      "x": -4,
      "y": 5,
      "z": -2,
      "name": "Rock_CastIron_Brick"
    },
    {
      "x": -4,
      "y": 6,
      "z": -2,
      "name": "Rock_CastIron_Brick"
    },
    {
      "x": -4,
      "y": 7,
      "z": -2,
      "name": "Rock_DarkConcrete"
    },
    {
      "x": -4,
      "y": 0,
      "z": -1,
      "name": "Rock_CastIron_Brick_Smooth"
    },
    {
      "x": -4,
      "y": 1,
      "z": -1,
      "name": "Rock_DarkConcrete_Brick"
    },
    {
      "x": -4,
      "y": 2,
      "z": -1,
      "name": "Rock_DarkConcrete_Brick"
    },
    {
      "x": -4,
      "y": 3,
      "z": -1,
      "name": "Rock_DarkConcrete_Brick"
    },
    {
      "x": -4,
      "y": 4,
      "z": -1,
      "name": "Rock_DarkConcrete_Brick"
    },
    {
      "x": -4,
      "y": 5,
      "z": -1,
      "name": "Rock_DarkConcrete_Brick"
    },
    {
      "x": -4,
      "y": 6,
      "z": -1,
      "name": "Rock_DarkConcrete_Brick"
    },
    {
      "x": -4,
      "y": 7,
      "z": -1,
      "name": "Rock_DarkConcrete"
    },
    {
      "x": -4,
      "y": 0,
      "z": 0,
      "name": "Rock_CastIron_Brick_Smooth"
    },
    {
      "x": -4,
      "y": 1,
      "z": 0,
      "name": "Rock_DarkConcrete_Brick"
    },
    {
      "x": -4,
      "y": 2,
      "z": 0,
      "name": "Rock_DarkConcrete_Brick"
    },
    {
      "x": -4,
      "y": 3,
      "z": 0,
      "name": "Rock_DarkConcrete_Brick"
    },
    {
      "x": -4,
      "y": 4,
      "z": 0,
      "name": "Rock_DarkConcrete_Brick"
    },
    {
      "x": -4,
      "y": 5,
      "z": 0,
      "name": "Rock_DarkConcrete_Brick"
    },
    {
      "x": -4,
      "y": 6,
      "z": 0,
      "name": "Rock_DarkConcrete_Brick"
    },
    {
      "x": -4,
      "y": 7,
      "z": 0,
      "name": "Rock_DarkConcrete"
    },
    {
      "x": -4,
      "y": 0,
      "z": 1,
      "name": "Rock_CastIron_Brick_Smooth"
    },
    {
      "x": -4,
      "y": 1,
      "z": 1,
      "name": "Rock_DarkConcrete_Brick"
    },
    {
      "x": -4,
      "y": 2,
      "z": 1,
      "name": "Rock_DarkConcrete_Brick"
    },
    {
      "x": -4,
      "y": 3,
      "z": 1,
      "name": "Rock_DarkConcrete_Brick"
    },
    {
      "x": -4,
      "y": 4,
      "z": 1,
      "name": "Rock_DarkConcrete_Brick"
    },
    {
      "x": -4,
      "y": 5,
      "z": 1,
      "name": "Rock_DarkConcrete_Brick"
    },
    {
      "x": -4,
      "y": 6,
      "z": 1,
      "name": "Rock_DarkConcrete_Brick"
    },
    {
      "x": -4,
      "y": 7,
      "z": 1,
      "name": "Rock_DarkConcrete"
    },
    {
      "x": -4,
      "y": 0,
      "z": 2,
      "name": "Rock_CastIron_Brick_Smooth"
    },
    {
      "x": -4,
      "y": 1,
      "z": 2,
      "name": "Rock_CastIron_Brick_Smooth"
    },
    {
      "x": -4,
      "y": 2,
      "z": 2,
      "name": "Rock_CastIron_Brick_Pillar_Base"
    },
    {
      "x": -4,
      "y": 3,
      "z": 2,
      "name": "Rock_CastIron_Brick_Pillar_Middle"
    },
    {
      "x": -4,
      "y": 4,
      "z": 2,
      "name": "Rock_CastIron_Brick_Pillar_Base",
      "rotation": 8
    },
    {
      "x": -4,
      "y": 5,
      "z": 2,
      "name": "Rock_CastIron_Brick"
    },
    {
      "x": -4,
      "y": 6,
      "z": 2,
      "name": "Rock_CastIron_Brick"
    },
    {
      "x": -4,
      "y": 7,
      "z": 2,
      "name": "Rock_DarkConcrete"
    },
    {
      "x": -4,
      "y": 0,
      "z": 3,
      "name": "Rock_CastIron_Brick_Smooth"
    },
    {
      "x": -4,
      "y": 1,
      "z": 3,
      "name": "Rock_CastIron_Brick_Stairs",
      "rotation": 11
    },
    {
      "x": -4,
      "y": 2,
      "z": 3,
      "name": "Plant_Leaves_Wisteria_Wild",
      "support": 15
    },
    {
      "x": -4,
      "y": 3,
      "z": 3,
      "name": "Empty"
    },
    {
      "x": -4,
      "y": 4,
      "z": 3,
      "name": "Empty"
    },
    {
      "x": -4,
      "y": 5,
      "z": 3,
      "name": "Rock_CastIron_Brick_Stairs",
      "rotation": 10
    },
    {
      "x": -4,
      "y": 6,
      "z": 3,
      "name": "Rock_CastIron_Brick"
    },
    {
      "x": -4,
      "y": 7,
      "z": 3,
      "name": "Rock_DarkConcrete"
    },
    {
      "x": -4,
      "y": 0,
      "z": 4,
      "name": "Rock_CastIron_Brick_Smooth"
    },
    {
      "x": -4,
      "y": 1,
      "z": 4,
      "name": "Rock_CastIron_Brick_Stairs",
      "rotation": 11
    },
    {
      "x": -4,
      "y": 2,
      "z": 4,
      "name": "Empty"
    },
    {
      "x": -4,
      "y": 3,
      "z": 4,
      "name": "Empty"
    },
    {
      "x": -4,
      "y": 4,
      "z": 4,
      "name": "Empty"
    },
    {
      "x": -4,
      "y": 5,
      "z": 4,
      "name": "Empty"
    },
    {
      "x": -4,
      "y": 6,
      "z": 4,
      "name": "Rock_CastIron_Brick"
    },
    {
      "x": -4,
      "y": 7,
      "z": 4,
      "name": "Rock_DarkConcrete"
    },
    {
      "x": -4,
      "y": 0,
      "z": 5,
      "name": "Rock_CastIron_Brick_Smooth"
    },
    {
      "x": -4,
      "y": 1,
      "z": 5,
      "name": "Rock_CastIron_Brick_Stairs",
      "rotation": 11
    },
    {
      "x": -4,
      "y": 2,
      "z": 5,
      "name": "Empty"
    },
    {
      "x": -4,
      "y": 3,
      "z": 5,
      "name": "Empty"
    },
    {
      "x": -4,
      "y": 4,
      "z": 5,
      "name": "Empty"
    },
    {
      "x": -4,
      "y": 5,
      "z": 5,
      "name": "Empty"
    },
    {
      "x": -4,
      "y": 6,
      "z": 5,
      "name": "Rock_CastIron_Brick"
    },
    {
      "x": -4,
      "y": 7,
      "z": 5,
      "name": "Rock_DarkConcrete"
    },
    {
      "x": -4,
      "y": 0,
      "z": 6,
      "name": "Rock_CastIron_Brick_Smooth"
    },
    {
      "x": -4,
      "y": 1,
      "z": 6,
      "name": "Rock_CastIron_Brick_Stairs",
      "rotation": 11
    },
    {
      "x": -4,
      "y": 2,
      "z": 6,
      "name": "Empty"
    },
    {
      "x": -4,
      "y": 3,
      "z": 6,
      "name": "Empty"
    },
    {
      "x": -4,
      "y": 4,
      "z": 6,
      "name": "Empty"
    },
    {
      "x": -4,
      "y": 5,
      "z": 6,
      "name": "Rock_CastIron_Brick_Stairs",
      "rotation": 8
    },
    {
      "x": -4,
      "y": 6,
      "z": 6,
      "name": "Rock_CastIron_Brick"
    },
    {
      "x": -4,
      "y": 7,
      "z": 6,
      "name": "Rock_DarkConcrete"
    },
    {
      "x": -4,
      "y": 0,
      "z": 7,
      "name": "Rock_CastIron_Brick_Smooth"
    },
    {
      "x": -4,
      "y": 1,
      "z": 7,
      "name": "Rock_CastIron_Brick_Smooth"
    },
    {
      "x": -4,
      "y": 2,
      "z": 7,
      "name": "Rock_CastIron_Brick_Pillar_Base"
    },
    {
      "x": -4,
      "y": 3,
      "z": 7,
      "name": "Rock_CastIron_Brick_Pillar_Middle"
    },
    {
      "x": -4,
      "y": 4,
      "z": 7,
      "name": "Rock_CastIron_Brick_Pillar_Base",
      "rotation": 8
    },
    {
      "x": -4,
      "y": 5,
      "z": 7,
      "name": "Rock_CastIron_Brick"
    },
    {
      "x": -4,
      "y": 6,
      "z": 7,
      "name": "Rock_CastIron_Brick"
    },
    {
      "x": -4,
      "y": 7,
      "z": 7,
      "name": "Rock_DarkConcrete"
    },
    {
      "x": -3,
      "y": 0,
      "z": -7,
      "name": "Rock_CastIron_Brick_Smooth"
    },
    {
      "x": -3,
      "y": 1,
      "z": -7,
      "name": "Empty"
    },
    {
      "x": -3,
      "y": 2,
      "z": -7,
      "name": "Empty"
    },
    {
      "x": -3,
      "y": 3,
      "z": -7,
      "name": "Empty"
    },
    {
      "x": -3,
      "y": 4,
      "z": -7,
      "name": "Empty"
    },
    {
      "x": -3,
      "y": 5,
      "z": -7,
      "name": "Empty"
    },
    {
      "x": -3,
      "y": 6,
      "z": -7,
      "name": "Rock_CastIron_Brick_Stairs",
      "rotation": 11
    },
    {
      "x": -3,
      "y": 7,
      "z": -7,
      "name": "Rock_DarkConcrete"
    },
    {
      "x": -3,
      "y": 0,
      "z": -6,
      "name": "Rock_CastIron_Brick_Smooth"
    },
    {
      "x": -3,
      "y": 1,
      "z": -6,
      "name": "Empty"
    },
    {
      "x": -3,
      "y": 2,
      "z": -6,
      "name": "Empty"
    },
    {
      "x": -3,
      "y": 3,
      "z": -6,
      "name": "Empty"
    },
    {
      "x": -3,
      "y": 4,
      "z": -6,
      "name": "Empty"
    },
    {
      "x": -3,
      "y": 5,
      "z": -6,
      "name": "Empty"
    },
    {
      "x": -3,
      "y": 6,
      "z": -6,
      "name": "Empty"
    },
    {
      "x": -3,
      "y": 7,
      "z": -6,
      "name": "Rock_DarkConcrete"
    },
    {
      "x": -3,
      "y": 0,
      "z": -5,
      "name": "Rock_CastIron_Brick_Smooth"
    },
    {
      "x": -3,
      "y": 1,
      "z": -5,
      "name": "Empty"
    },
    {
      "x": -3,
      "y": 2,
      "z": -5,
      "name": "Empty"
    },
    {
      "x": -3,
      "y": 3,
      "z": -5,
      "name": "Empty"
    },
    {
      "x": -3,
      "y": 4,
      "z": -5,
      "name": "Empty"
    },
    {
      "x": -3,
      "y": 5,
      "z": -5,
      "name": "Empty"
    },
    {
      "x": -3,
      "y": 6,
      "z": -5,
      "name": "Empty"
    },
    {
      "x": -3,
      "y": 7,
      "z": -5,
      "name": "Rock_DarkConcrete"
    },
    {
      "x": -3,
      "y": 0,
      "z": -4,
      "name": "Rock_CastIron_Brick_Smooth"
    },
    {
      "x": -3,
      "y": 1,
      "z": -4,
      "name": "Furniture_Ancient_Barrel"
    },
    {
      "x": -3,
      "y": 2,
      "z": -4,
      "name": "Empty"
    },
    {
      "x": -3,
      "y": 3,
      "z": -4,
      "name": "Empty"
    },
    {
      "x": -3,
      "y": 4,
      "z": -4,
      "name": "Empty"
    },
    {
      "x": -3,
      "y": 5,
      "z": -4,
      "name": "Empty"
    },
    {
      "x": -3,
      "y": 6,
      "z": -4,
      "name": "Empty"
    },
    {
      "x": -3,
      "y": 7,
      "z": -4,
      "name": "Rock_DarkConcrete"
    },
    {
      "x": -3,
      "y": 0,
      "z": -3,
      "name": "Rock_CastIron_Brick_Smooth"
    },
    {
      "x": -3,
      "y": 1,
      "z": -3,
      "name": "Furniture_Ancient_Barrel"
    },
    {
      "x": -3,
      "y": 2,
      "z": -3,
      "name": "Empty"
    },
    {
      "x": -3,
      "y": 3,
      "z": -3,
      "name": "Empty"
    },
    {
      "x": -3,
      "y": 4,
      "z": -3,
      "name": "Empty"
    },
    {
      "x": -3,
      "y": 5,
      "z": -3,
      "name": "Empty"
    },
    {
      "x": -3,
      "y": 6,
      "z": -3,
      "name": "Empty"
    },
    {
      "x": -3,
      "y": 7,
      "z": -3,
      "name": "Rock_DarkConcrete"
    },
    {
      "x": -3,
      "y": 0,
      "z": -2,
      "name": "Rock_CastIron_Brick_Smooth"
    },
    {
      "x": -3,
      "y": 1,
      "z": -2,
      "name": "Empty"
    },
    {
      "x": -3,
      "y": 2,
      "z": -2,
      "name": "Empty"
    },
    {
      "x": -3,
      "y": 3,
      "z": -2,
      "name": "Empty"
    },
    {
      "x": -3,
      "y": 4,
      "z": -2,
      "name": "Empty"
    },
    {
      "x": -3,
      "y": 5,
      "z": -2,
      "name": "Empty"
    },
    {
      "x": -3,
      "y": 6,
      "z": -2,
      "name": "Rock_CastIron_Brick_Stairs",
      "rotation": 11
    },
    {
      "x": -3,
      "y": 7,
      "z": -2,
      "name": "Rock_DarkConcrete"
    },
    {
      "x": -3,
      "y": 0,
      "z": -1,
      "name": "Rock_CastIron_Brick"
    },
    {
      "x": -3,
      "y": 1,
      "z": -1,
      "name": "Empty"
    },
    {
      "x": -3,
      "y": 2,
      "z": -1,
      "name": "Empty"
    },
    {
      "x": -3,
      "y": 3,
      "z": -1,
      "name": "Empty"
    },
    {
      "x": -3,
      "y": 4,
      "z": -1,
      "name": "Rock_DarkConcrete_Brick_Half",
      "rotation": 5
    },
    {
      "x": -3,
      "y": 5,
      "z": -1,
      "name": "Rock_DarkConcrete_Brick"
    },
    {
      "x": -3,
      "y": 6,
      "z": -1,
      "name": "Rock_DarkConcrete_Brick"
    },
    {
      "x": -3,
      "y": 7,
      "z": -1,
      "name": "Rock_DarkConcrete"
    },
    {
      "x": -3,
      "y": 0,
      "z": 0,
      "name": "Rock_CastIron_Brick"
    },
    {
      "x": -3,
      "y": 1,
      "z": 0,
      "name": "Rock_CastIron_Brick_Beam"
    },
    {
      "x": -3,
      "y": 2,
      "z": 0,
      "name": "Furniture_Human_Ruins_Torch",
      "rotation": 1
    },
    {
      "x": -3,
      "y": 3,
      "z": 0,
      "name": "Empty"
    },
    {
      "x": -3,
      "y": 4,
      "z": 0,
      "name": "Rock_DarkConcrete_Brick_Half",
      "rotation": 5
    },
    {
      "x": -3,
      "y": 5,
      "z": 0,
      "name": "Rock_DarkConcrete_Brick"
    },
    {
      "x": -3,
      "y": 6,
      "z": 0,
      "name": "Rock_DarkConcrete_Brick"
    },
    {
      "x": -3,
      "y": 7,
      "z": 0,
      "name": "Rock_DarkConcrete"
    },
    {
      "x": -3,
      "y": 0,
      "z": 1,
      "name": "Rock_CastIron_Brick"
    },
    {
      "x": -3,
      "y": 1,
      "z": 1,
      "name": "Empty"
    },
    {
      "x": -3,
      "y": 2,
      "z": 1,
      "name": "Empty"
    },
    {
      "x": -3,
      "y": 3,
      "z": 1,
      "name": "Empty"
    },
    {
      "x": -3,
      "y": 4,
      "z": 1,
      "name": "Rock_DarkConcrete_Brick_Half",
      "rotation": 5
    },
    {
      "x": -3,
      "y": 5,
      "z": 1,
      "name": "Rock_DarkConcrete_Brick"
    },
    {
      "x": -3,
      "y": 6,
      "z": 1,
      "name": "Rock_DarkConcrete_Brick"
    },
    {
      "x": -3,
      "y": 7,
      "z": 1,
      "name": "Rock_DarkConcrete"
    },
    {
      "x": -3,
      "y": 0,
      "z": 2,
      "name": "Rock_CastIron_Brick_Smooth"
    },
    {
      "x": -3,
      "y": 1,
      "z": 2,
      "name": "Empty"
    },
    {
      "x": -3,
      "y": 2,
      "z": 2,
      "name": "Empty"
    },
    {
      "x": -3,
      "y": 3,
      "z": 2,
      "name": "Empty"
    },
    {
      "x": -3,
      "y": 4,
      "z": 2,
      "name": "Empty"
    },
    {
      "x": -3,
      "y": 5,
      "z": 2,
      "name": "Empty"
    },
    {
      "x": -3,
      "y": 6,
      "z": 2,
      "name": "Rock_CastIron_Brick_Stairs",
      "rotation": 11
    },
    {
      "x": -3,
      "y": 7,
      "z": 2,
      "name": "Rock_DarkConcrete"
    },
    {
      "x": -3,
      "y": 0,
      "z": 3,
      "name": "Rock_CastIron_Brick_Smooth"
    },
    {
      "x": -3,
      "y": 1,
      "z": 3,
      "name": "Empty"
    },
    {
      "x": -3,
      "y": 2,
      "z": 3,
      "name": "Empty"
    },
    {
      "x": -3,
      "y": 3,
      "z": 3,
      "name": "Empty"
    },
    {
      "x": -3,
      "y": 4,
      "z": 3,
      "name": "Empty"
    },
    {
      "x": -3,
      "y": 5,
      "z": 3,
      "name": "Empty"
    },
    {
      "x": -3,
      "y": 6,
      "z": 3,
      "name": "Empty"
    },
    {
      "x": -3,
      "y": 7,
      "z": 3,
      "name": "Rock_DarkConcrete"
    },
    {
      "x": -3,
      "y": 0,
      "z": 4,
      "name": "Rock_CastIron_Brick_Smooth"
    },
    {
      "x": -3,
      "y": 1,
      "z": 4,
      "name": "Empty"
    },
    {
      "x": -3,
      "y": 2,
      "z": 4,
      "name": "Empty"
    },
    {
      "x": -3,
      "y": 3,
      "z": 4,
      "name": "Empty"
    },
    {
      "x": -3,
      "y": 4,
      "z": 4,
      "name": "Empty"
    },
    {
      "x": -3,
      "y": 5,
      "z": 4,
      "name": "Empty"
    },
    {
      "x": -3,
      "y": 6,
      "z": 4,
      "name": "Empty"
    },
    {
      "x": -3,
      "y": 7,
      "z": 4,
      "name": "Rock_DarkConcrete"
    },
    {
      "x": -3,
      "y": 0,
      "z": 5,
      "name": "Rock_CastIron_Brick_Smooth"
    },
    {
      "x": -3,
      "y": 1,
      "z": 5,
      "name": "Furniture_Ancient_Barrel"
    },
    {
      "x": -3,
      "y": 2,
      "z": 5,
      "name": "Empty"
    },
    {
      "x": -3,
      "y": 3,
      "z": 5,
      "name": "Empty"
    },
    {
      "x": -3,
      "y": 4,
      "z": 5,
      "name": "Empty"
    },
    {
      "x": -3,
      "y": 5,
      "z": 5,
      "name": "Empty"
    },
    {
      "x": -3,
      "y": 6,
      "z": 5,
      "name": "Empty"
    },
    {
      "x": -3,
      "y": 7,
      "z": 5,
      "name": "Rock_DarkConcrete"
    },
    {
      "x": -3,
      "y": 0,
      "z": 6,
      "name": "Rock_CastIron_Brick_Smooth"
    },
    {
      "x": -3,
      "y": 1,
      "z": 6,
      "name": "Furniture_Ancient_Barrel"
    },
    {
      "x": -3,
      "y": 2,
      "z": 6,
      "name": "Empty"
    },
    {
      "x": -3,
      "y": 3,
      "z": 6,
      "name": "Empty"
    },
    {
      "x": -3,
      "y": 4,
      "z": 6,
      "name": "Empty"
    },
    {
      "x": -3,
      "y": 5,
      "z": 6,
      "name": "Empty"
    },
    {
      "x": -3,
      "y": 6,
      "z": 6,
      "name": "Empty"
    },
    {
      "x": -3,
      "y": 7,
      "z": 6,
      "name": "Rock_DarkConcrete"
    },
    {
      "x": -3,
      "y": 0,
      "z": 7,
      "name": "Rock_CastIron_Brick_Smooth"
    },
    {
      "x": -3,
      "y": 1,
      "z": 7,
      "name": "Furniture_Ancient_Barrel"
    },
    {
      "x": -3,
      "y": 2,
      "z": 7,
      "name": "Empty"
    },
    {
      "x": -3,
      "y": 3,
      "z": 7,
      "name": "Empty"
    },
    {
      "x": -3,
      "y": 4,
      "z": 7,
      "name": "Empty"
    },
    {
      "x": -3,
      "y": 5,
      "z": 7,
      "name": "Empty"
    },
    {
      "x": -3,
      "y": 6,
      "z": 7,
      "name": "Rock_CastIron_Brick_Stairs",
      "rotation": 11
    },
    {
      "x": -3,
      "y": 7,
      "z": 7,
      "name": "Rock_DarkConcrete"
    },
    {
      "x": -2,
      "y": 0,
      "z": -7,
      "name": "Rock_CastIron"
    },
    {
      "x": -2,
      "y": 1,
      "z": -7,
      "name": "Empty"
    },
    {
      "x": -2,
      "y": 2,
      "z": -7,
      "name": "Empty"
    },
    {
      "x": -2,
      "y": 3,
      "z": -7,
      "name": "Empty"
    },
    {
      "x": -2,
      "y": 4,
      "z": -7,
      "name": "Empty"
    },
    {
      "x": -2,
      "y": 5,
      "z": -7,
      "name": "Empty"
    },
    {
      "x": -2,
      "y": 6,
      "z": -7,
      "name": "Empty"
    },
    {
      "x": -2,
      "y": 7,
      "z": -7,
      "name": "Rock_DarkConcrete"
    },
    {
      "x": -2,
      "y": 0,
      "z": -6,
      "name": "Soil_Dirt_Cold"
    },
    {
      "x": -2,
      "y": 1,
      "z": -6,
      "name": "Plant_Grass_Gnarled_Tall",
      "support": 15
    },
    {
      "x": -2,
      "y": 2,
      "z": -6,
      "name": "Plant_Grass_Gnarled_Tall",
      "filler": 1024
    },
    {
      "x": -2,
      "y": 3,
      "z": -6,
      "name": "Empty"
    },
    {
      "x": -2,
      "y": 4,
      "z": -6,
      "name": "Empty"
    },
    {
      "x": -2,
      "y": 5,
      "z": -6,
      "name": "Empty"
    },
    {
      "x": -2,
      "y": 6,
      "z": -6,
      "name": "Empty"
    },
    {
      "x": -2,
      "y": 7,
      "z": -6,
      "name": "Rock_DarkConcrete"
    },
    {
      "x": -2,
      "y": 0,
      "z": -5,
      "name": "Soil_Dirt_Cold"
    },
    {
      "x": -2,
      "y": 1,
      "z": -5,
      "name": "Plant_Flower_Bushy_Green"
    },
    {
      "x": -2,
      "y": 2,
      "z": -5,
      "name": "Empty"
    },
    {
      "x": -2,
      "y": 3,
      "z": -5,
      "name": "Empty"
    },
    {
      "x": -2,
      "y": 4,
      "z": -5,
      "name": "Empty"
    },
    {
      "x": -2,
      "y": 5,
      "z": -5,
      "name": "Empty"
    },
    {
      "x": -2,
      "y": 6,
      "z": -5,
      "name": "Empty"
    },
    {
      "x": -2,
      "y": 7,
      "z": -5,
      "name": "Rock_DarkConcrete"
    },
    {
      "x": -2,
      "y": 0,
      "z": -4,
      "name": "Rock_CastIron"
    },
    {
      "x": -2,
      "y": 1,
      "z": -4,
      "name": "Empty"
    },
    {
      "x": -2,
      "y": 2,
      "z": -4,
      "name": "Empty"
    },
    {
      "x": -2,
      "y": 3,
      "z": -4,
      "name": "Empty"
    },
    {
      "x": -2,
      "y": 4,
      "z": -4,
      "name": "Empty"
    },
    {
      "x": -2,
      "y": 5,
      "z": -4,
      "name": "Empty"
    },
    {
      "x": -2,
      "y": 6,
      "z": -4,
      "name": "Empty"
    },
    {
      "x": -2,
      "y": 7,
      "z": -4,
      "name": "Rock_DarkConcrete"
    },
    {
      "x": -2,
      "y": 0,
      "z": -3,
      "name": "Rock_CastIron"
    },
    {
      "x": -2,
      "y": 1,
      "z": -3,
      "name": "Furniture_Ancient_Barrel"
    },
    {
      "x": -2,
      "y": 2,
      "z": -3,
      "name": "Empty"
    },
    {
      "x": -2,
      "y": 3,
      "z": -3,
      "name": "Empty"
    },
    {
      "x": -2,
      "y": 4,
      "z": -3,
      "name": "Empty"
    },
    {
      "x": -2,
      "y": 5,
      "z": -3,
      "name": "Empty"
    },
    {
      "x": -2,
      "y": 6,
      "z": -3,
      "name": "Empty"
    },
    {
      "x": -2,
      "y": 7,
      "z": -3,
      "name": "Rock_DarkConcrete"
    },
    {
      "x": -2,
      "y": 0,
      "z": -2,
      "name": "Soil_Dirt_Cold"
    },
    {
      "x": -2,
      "y": 1,
      "z": -2,
      "name": "*Plant_Crop_Berry_Winter_Block_State_Definitions_StageFinal"
    },
    {
      "x": -2,
      "y": 2,
      "z": -2,
      "name": "Empty"
    },
    {
      "x": -2,
      "y": 3,
      "z": -2,
      "name": "Empty"
    },
    {
      "x": -2,
      "y": 4,
      "z": -2,
      "name": "Empty"
    },
    {
      "x": -2,
      "y": 5,
      "z": -2,
      "name": "Empty"
    },
    {
      "x": -2,
      "y": 6,
      "z": -2,
      "name": "Empty"
    },
    {
      "x": -2,
      "y": 7,
      "z": -2,
      "name": "Rock_DarkConcrete"
    },
    {
      "x": -2,
      "y": 0,
      "z": -1,
      "name": "Rock_CastIron_Brick"
    },
    {
      "x": -2,
      "y": 1,
      "z": -1,
      "name": "Empty"
    },
    {
      "x": -2,
      "y": 2,
      "z": -1,
      "name": "Empty"
    },
    {
      "x": -2,
      "y": 3,
      "z": -1,
      "name": "Empty"
    },
    {
      "x": -2,
      "y": 4,
      "z": -1,
      "name": "Empty"
    },
    {
      "x": -2,
      "y": 5,
      "z": -1,
      "name": "Rock_DarkConcrete_Brick_Half",
      "rotation": 8
    },
    {
      "x": -2,
      "y": 6,
      "z": -1,
      "name": "Rock_DarkConcrete_Brick"
    },
    {
      "x": -2,
      "y": 7,
      "z": -1,
      "name": "Rock_DarkConcrete"
    },
    {
      "x": -2,
      "y": 0,
      "z": 0,
      "name": "Rock_CastIron_Brick"
    },
    {
      "x": -2,
      "y": 1,
      "z": 0,
      "name": "Empty"
    },
    {
      "x": -2,
      "y": 2,
      "z": 0,
      "name": "Empty"
    },
    {
      "x": -2,
      "y": 3,
      "z": 0,
      "name": "Empty"
    },
    {
      "x": -2,
      "y": 4,
      "z": 0,
      "name": "Empty"
    },
    {
      "x": -2,
      "y": 5,
      "z": 0,
      "name": "Rock_DarkConcrete_Brick_Half",
      "rotation": 8
    },
    {
      "x": -2,
      "y": 6,
      "z": 0,
      "name": "Rock_DarkConcrete_Brick"
    },
    {
      "x": -2,
      "y": 7,
      "z": 0,
      "name": "Rock_DarkConcrete"
    },
    {
      "x": -2,
      "y": 0,
      "z": 1,
      "name": "Rock_CastIron_Brick"
    },
    {
      "x": -2,
      "y": 1,
      "z": 1,
      "name": "Empty"
    },
    {
      "x": -2,
      "y": 2,
      "z": 1,
      "name": "Empty"
    },
    {
      "x": -2,
      "y": 3,
      "z": 1,
      "name": "Empty"
    },
    {
      "x": -2,
      "y": 4,
      "z": 1,
      "name": "Empty"
    },
    {
      "x": -2,
      "y": 5,
      "z": 1,
      "name": "Rock_DarkConcrete_Brick_Half",
      "rotation": 8
    },
    {
      "x": -2,
      "y": 6,
      "z": 1,
      "name": "Rock_DarkConcrete_Brick"
    },
    {
      "x": -2,
      "y": 7,
      "z": 1,
      "name": "Rock_DarkConcrete"
    },
    {
      "x": -2,
      "y": 0,
      "z": 2,
      "name": "Rock_CastIron"
    },
    {
      "x": -2,
      "y": 1,
      "z": 2,
      "name": "Empty"
    },
    {
      "x": -2,
      "y": 2,
      "z": 2,
      "name": "Empty"
    },
    {
      "x": -2,
      "y": 3,
      "z": 2,
      "name": "Empty"
    },
    {
      "x": -2,
      "y": 4,
      "z": 2,
      "name": "Empty"
    },
    {
      "x": -2,
      "y": 5,
      "z": 2,
      "name": "Empty"
    },
    {
      "x": -2,
      "y": 6,
      "z": 2,
      "name": "Empty"
    },
    {
      "x": -2,
      "y": 7,
      "z": 2,
      "name": "Rock_DarkConcrete"
    },
    {
      "x": -2,
      "y": 0,
      "z": 3,
      "name": "Soil_Dirt_Cold"
    },
    {
      "x": -2,
      "y": 1,
      "z": 3,
      "name": "Empty"
    },
    {
      "x": -2,
      "y": 2,
      "z": 3,
      "name": "Empty"
    },
    {
      "x": -2,
      "y": 3,
      "z": 3,
      "name": "Empty"
    },
    {
      "x": -2,
      "y": 4,
      "z": 3,
      "name": "Empty"
    },
    {
      "x": -2,
      "y": 5,
      "z": 3,
      "name": "Empty"
    },
    {
      "x": -2,
      "y": 6,
      "z": 3,
      "name": "Empty"
    },
    {
      "x": -2,
      "y": 7,
      "z": 3,
      "name": "Rock_DarkConcrete"
    },
    {
      "x": -2,
      "y": 0,
      "z": 4,
      "name": "Soil_Dirt_Cold"
    },
    {
      "x": -2,
      "y": 1,
      "z": 4,
      "name": "Plant_Grass_Sharp_Tall",
      "support": 15
    },
    {
      "x": -2,
      "y": 2,
      "z": 4,
      "name": "Plant_Grass_Sharp_Tall",
      "filler": 1024
    },
    {
      "x": -2,
      "y": 3,
      "z": 4,
      "name": "Empty"
    },
    {
      "x": -2,
      "y": 4,
      "z": 4,
      "name": "Empty"
    },
    {
      "x": -2,
      "y": 5,
      "z": 4,
      "name": "Empty"
    },
    {
      "x": -2,
      "y": 6,
      "z": 4,
      "name": "Empty"
    },
    {
      "x": -2,
      "y": 7,
      "z": 4,
      "name": "Rock_DarkConcrete"
    },
    {
      "x": -2,
      "y": 0,
      "z": 5,
      "name": "Soil_Dirt_Cold"
    },
    {
      "x": -2,
      "y": 1,
      "z": 5,
      "name": "Furniture_Ancient_Barrel"
    },
    {
      "x": -2,
      "y": 2,
      "z": 5,
      "name": "Empty"
    },
    {
      "x": -2,
      "y": 3,
      "z": 5,
      "name": "Empty"
    },
    {
      "x": -2,
      "y": 4,
      "z": 5,
      "name": "Empty"
    },
    {
      "x": -2,
      "y": 5,
      "z": 5,
      "name": "Empty"
    },
    {
      "x": -2,
      "y": 6,
      "z": 5,
      "name": "Empty"
    },
    {
      "x": -2,
      "y": 7,
      "z": 5,
      "name": "Rock_DarkConcrete"
    },
    {
      "x": -2,
      "y": 0,
      "z": 6,
      "name": "Soil_Dirt_Cold"
    },
    {
      "x": -2,
      "y": 1,
      "z": 6,
      "name": "Furniture_Ancient_Crate"
    },
    {
      "x": -2,
      "y": 2,
      "z": 6,
      "name": "Empty"
    },
    {
      "x": -2,
      "y": 3,
      "z": 6,
      "name": "Empty"
    },
    {
      "x": -2,
      "y": 4,
      "z": 6,
      "name": "Empty"
    },
    {
      "x": -2,
      "y": 5,
      "z": 6,
      "name": "Empty"
    },
    {
      "x": -2,
      "y": 6,
      "z": 6,
      "name": "Empty"
    },
    {
      "x": -2,
      "y": 7,
      "z": 6,
      "name": "Rock_DarkConcrete"
    },
    {
      "x": -2,
      "y": 0,
      "z": 7,
      "name": "Soil_Dirt_Cold"
    },
    {
      "x": -2,
      "y": 1,
      "z": 7,
      "name": "Empty"
    },
    {
      "x": -2,
      "y": 2,
      "z": 7,
      "name": "Empty"
    },
    {
      "x": -2,
      "y": 3,
      "z": 7,
      "name": "Empty"
    },
    {
      "x": -2,
      "y": 4,
      "z": 7,
      "name": "Empty"
    },
    {
      "x": -2,
      "y": 5,
      "z": 7,
      "name": "Empty"
    },
    {
      "x": -2,
      "y": 6,
      "z": 7,
      "name": "Empty"
    },
    {
      "x": -2,
      "y": 7,
      "z": 7,
      "name": "Rock_DarkConcrete"
    },
    {
      "x": -1,
      "y": 0,
      "z": -7,
      "name": "Rock_CastIron"
    },
    {
      "x": -1,
      "y": 1,
      "z": -7,
      "name": "Empty"
    },
    {
      "x": -1,
      "y": 2,
      "z": -7,
      "name": "Empty"
    },
    {
      "x": -1,
      "y": 3,
      "z": -7,
      "name": "Empty"
    },
    {
      "x": -1,
      "y": 4,
      "z": -7,
      "name": "Empty"
    },
    {
      "x": -1,
      "y": 5,
      "z": -7,
      "name": "Empty"
    },
    {
      "x": -1,
      "y": 6,
      "z": -7,
      "name": "Empty"
    },
    {
      "x": -1,
      "y": 7,
      "z": -7,
      "name": "Rock_DarkConcrete"
    },
    {
      "x": -1,
      "y": 0,
      "z": -6,
      "name": "Rock_CastIron"
    },
    {
      "x": -1,
      "y": 1,
      "z": -6,
      "name": "Plant_Moss_Rug_Green_Dark",
      "support": 15
    },
    {
      "x": -1,
      "y": 2,
      "z": -6,
      "name": "Empty"
    },
    {
      "x": -1,
      "y": 3,
      "z": -6,
      "name": "Empty"
    },
    {
      "x": -1,
      "y": 4,
      "z": -6,
      "name": "Empty"
    },
    {
      "x": -1,
      "y": 5,
      "z": -6,
      "name": "Empty"
    },
    {
      "x": -1,
      "y": 6,
      "z": -6,
      "name": "Empty"
    },
    {
      "x": -1,
      "y": 7,
      "z": -6,
      "name": "Rock_DarkConcrete"
    },
    {
      "x": -1,
      "y": 0,
      "z": -5,
      "name": "Soil_Dirt_Cold"
    },
    {
      "x": -1,
      "y": 1,
      "z": -5,
      "name": "Empty"
    },
    {
      "x": -1,
      "y": 2,
      "z": -5,
      "name": "Empty"
    },
    {
      "x": -1,
      "y": 3,
      "z": -5,
      "name": "Empty"
    },
    {
      "x": -1,
      "y": 4,
      "z": -5,
      "name": "Empty"
    },
    {
      "x": -1,
      "y": 5,
      "z": -5,
      "name": "Empty"
    },
    {
      "x": -1,
      "y": 6,
      "z": -5,
      "name": "Empty"
    },
    {
      "x": -1,
      "y": 7,
      "z": -5,
      "name": "Rock_DarkConcrete"
    },
    {
      "x": -1,
      "y": 0,
      "z": -4,
      "name": "Rock_CastIron"
    },
    {
      "x": -1,
      "y": 1,
      "z": -4,
      "name": "Plant_Moss_Rug_Green_Dark",
      "support": 15
    },
    {
      "x": -1,
      "y": 2,
      "z": -4,
      "name": "Empty"
    },
    {
      "x": -1,
      "y": 3,
      "z": -4,
      "name": "Empty"
    },
    {
      "x": -1,
      "y": 4,
      "z": -4,
      "name": "Empty"
    },
    {
      "x": -1,
      "y": 5,
      "z": -4,
      "name": "Empty"
    },
    {
      "x": -1,
      "y": 6,
      "z": -4,
      "name": "Empty"
    },
    {
      "x": -1,
      "y": 7,
      "z": -4,
      "name": "Rock_DarkConcrete"
    },
    {
      "x": -1,
      "y": 0,
      "z": -3,
      "name": "Rock_CastIron"
    },
    {
      "x": -1,
      "y": 1,
      "z": -3,
      "name": "Empty"
    },
    {
      "x": -1,
      "y": 2,
      "z": -3,
      "name": "Empty"
    },
    {
      "x": -1,
      "y": 3,
      "z": -3,
      "name": "Empty"
    },
    {
      "x": -1,
      "y": 4,
      "z": -3,
      "name": "Empty"
    },
    {
      "x": -1,
      "y": 5,
      "z": -3,
      "name": "Empty"
    },
    {
      "x": -1,
      "y": 6,
      "z": -3,
      "name": "Empty"
    },
    {
      "x": -1,
      "y": 7,
      "z": -3,
      "name": "Rock_DarkConcrete"
    },
    {
      "x": -1,
      "y": 0,
      "z": -2,
      "name": "Soil_Dirt_Cold"
    },
    {
      "x": -1,
      "y": 1,
      "z": -2,
      "name": "Empty"
    },
    {
      "x": -1,
      "y": 2,
      "z": -2,
      "name": "Empty"
    },
    {
      "x": -1,
      "y": 3,
      "z": -2,
      "name": "Empty"
    },
    {
      "x": -1,
      "y": 4,
      "z": -2,
      "name": "Plant_Leaves_Wisteria_Wild",
      "support": 15
    },
    {
      "x": -1,
      "y": 5,
      "z": -2,
      "name": "Plant_Leaves_Wisteria_Wild",
      "support": 15
    },
    {
      "x": -1,
      "y": 6,
      "z": -2,
      "name": "Plant_Leaves_Wisteria_Wild",
      "support": 15
    },
    {
      "x": -1,
      "y": 7,
      "z": -2,
      "name": "Rock_DarkConcrete"
    },
    {
      "x": -1,
      "y": 0,
      "z": -1,
      "name": "Soil_Dirt_Cold"
    },
    {
      "x": -1,
      "y": 1,
      "z": -1,
      "name": "Plant_Moss_Rug_Green_Dark",
      "support": 15
    },
    {
      "x": -1,
      "y": 2,
      "z": -1,
      "name": "Empty"
    },
    {
      "x": -1,
      "y": 3,
      "z": -1,
      "name": "Empty"
    },
    {
      "x": -1,
      "y": 4,
      "z": -1,
      "name": "Empty"
    },
    {
      "x": -1,
      "y": 5,
      "z": -1,
      "name": "Empty"
    },
    {
      "x": -1,
      "y": 6,
      "z": -1,
      "name": "Rock_DarkConcrete_Brick"
    },
    {
      "x": -1,
      "y": 7,
      "z": -1,
      "name": "Rock_DarkConcrete"
    },
    {
      "x": -1,
      "y": 0,
      "z": 0,
      "name": "Soil_Dirt_Cold"
    },
    {
      "x": -1,
      "y": 1,
      "z": 0,
      "name": "Empty"
    },
    {
      "x": -1,
      "y": 2,
      "z": 0,
      "name": "Empty"
    },
    {
      "x": -1,
      "y": 3,
      "z": 0,
      "name": "Empty"
    },
    {
      "x": -1,
      "y": 4,
      "z": 0,
      "name": "Empty"
    },
    {
      "x": -1,
      "y": 5,
      "z": 0,
      "name": "Empty"
    },
    {
      "x": -1,
      "y": 6,
      "z": 0,
      "name": "Rock_DarkConcrete_Brick"
    },
    {
      "x": -1,
      "y": 7,
      "z": 0,
      "name": "Rock_DarkConcrete"
    },
    {
      "x": -1,
      "y": 0,
      "z": 1,
      "name": "Soil_Dirt_Cold"
    },
    {
      "x": -1,
      "y": 1,
      "z": 1,
      "name": "Plant_Flower_Bushy_Green"
    },
    {
      "x": -1,
      "y": 2,
      "z": 1,
      "name": "Empty"
    },
    {
      "x": -1,
      "y": 3,
      "z": 1,
      "name": "Empty"
    },
    {
      "x": -1,
      "y": 4,
      "z": 1,
      "name": "Empty"
    },
    {
      "x": -1,
      "y": 5,
      "z": 1,
      "name": "Empty"
    },
    {
      "x": -1,
      "y": 6,
      "z": 1,
      "name": "Rock_DarkConcrete_Brick"
    },
    {
      "x": -1,
      "y": 7,
      "z": 1,
      "name": "Rock_DarkConcrete"
    },
    {
      "x": -1,
      "y": 0,
      "z": 2,
      "name": "Rock_CastIron"
    },
    {
      "x": -1,
      "y": 1,
      "z": 2,
      "name": "Empty"
    },
    {
      "x": -1,
      "y": 2,
      "z": 2,
      "name": "Empty"
    },
    {
      "x": -1,
      "y": 3,
      "z": 2,
      "name": "Empty"
    },
    {
      "x": -1,
      "y": 4,
      "z": 2,
      "name": "Empty"
    },
    {
      "x": -1,
      "y": 5,
      "z": 2,
      "name": "Empty"
    },
    {
      "x": -1,
      "y": 6,
      "z": 2,
      "name": "Empty"
    },
    {
      "x": -1,
      "y": 7,
      "z": 2,
      "name": "Rock_DarkConcrete"
    },
    {
      "x": -1,
      "y": 0,
      "z": 3,
      "name": "Rock_CastIron"
    },
    {
      "x": -1,
      "y": 1,
      "z": 3,
      "name": "Empty"
    },
    {
      "x": -1,
      "y": 2,
      "z": 3,
      "name": "Empty"
    },
    {
      "x": -1,
      "y": 3,
      "z": 3,
      "name": "Empty"
    },
    {
      "x": -1,
      "y": 4,
      "z": 3,
      "name": "Empty"
    },
    {
      "x": -1,
      "y": 5,
      "z": 3,
      "name": "Empty"
    },
    {
      "x": -1,
      "y": 6,
      "z": 3,
      "name": "Empty"
    },
    {
      "x": -1,
      "y": 7,
      "z": 3,
      "name": "Rock_DarkConcrete"
    },
    {
      "x": -1,
      "y": 0,
      "z": 4,
      "name": "Rock_CastIron"
    },
    {
      "x": -1,
      "y": 1,
      "z": 4,
      "name": "Plant_Leaves_Wisteria_Wild",
      "support": 15
    },
    {
      "x": -1,
      "y": 2,
      "z": 4,
      "name": "Empty"
    },
    {
      "x": -1,
      "y": 3,
      "z": 4,
      "name": "Empty"
    },
    {
      "x": -1,
      "y": 4,
      "z": 4,
      "name": "Empty"
    },
    {
      "x": -1,
      "y": 5,
      "z": 4,
      "name": "Empty"
    },
    {
      "x": -1,
      "y": 6,
      "z": 4,
      "name": "Empty"
    },
    {
      "x": -1,
      "y": 7,
      "z": 4,
      "name": "Rock_DarkConcrete"
    },
    {
      "x": -1,
      "y": 0,
      "z": 5,
      "name": "Soil_Dirt_Cold"
    },
    {
      "x": -1,
      "y": 1,
      "z": 5,
      "name": "Empty"
    },
    {
      "x": -1,
      "y": 2,
      "z": 5,
      "name": "Empty"
    },
    {
      "x": -1,
      "y": 3,
      "z": 5,
      "name": "Empty"
    },
    {
      "x": -1,
      "y": 4,
      "z": 5,
      "name": "Empty"
    },
    {
      "x": -1,
      "y": 5,
      "z": 5,
      "name": "Empty"
    },
    {
      "x": -1,
      "y": 6,
      "z": 5,
      "name": "Empty"
    },
    {
      "x": -1,
      "y": 7,
      "z": 5,
      "name": "Rock_DarkConcrete"
    },
    {
      "x": -1,
      "y": 0,
      "z": 6,
      "name": "Rock_CastIron"
    },
    {
      "x": -1,
      "y": 1,
      "z": 6,
      "name": "Empty"
    },
    {
      "x": -1,
      "y": 2,
      "z": 6,
      "name": "Empty"
    },
    {
      "x": -1,
      "y": 3,
      "z": 6,
      "name": "Empty"
    },
    {
      "x": -1,
      "y": 4,
      "z": 6,
      "name": "Empty"
    },
    {
      "x": -1,
      "y": 5,
      "z": 6,
      "name": "Empty"
    },
    {
      "x": -1,
      "y": 6,
      "z": 6,
      "name": "Empty"
    },
    {
      "x": -1,
      "y": 7,
      "z": 6,
      "name": "Rock_DarkConcrete"
    },
    {
      "x": -1,
      "y": 0,
      "z": 7,
      "name": "Soil_Dirt_Cold"
    },
    {
      "x": -1,
      "y": 1,
      "z": 7,
      "name": "Plant_Flower_Bushy_Green"
    },
    {
      "x": -1,
      "y": 2,
      "z": 7,
      "name": "Empty"
    },
    {
      "x": -1,
      "y": 3,
      "z": 7,
      "name": "Empty"
    },
    {
      "x": -1,
      "y": 4,
      "z": 7,
      "name": "Empty"
    },
    {
      "x": -1,
      "y": 5,
      "z": 7,
      "name": "Empty"
    },
    {
      "x": -1,
      "y": 6,
      "z": 7,
      "name": "Empty"
    },
    {
      "x": -1,
      "y": 7,
      "z": 7,
      "name": "Rock_DarkConcrete"
    },
    {
      "x": 0,
      "y": 0,
      "z": -7,
      "name": "Rock_CastIron"
    },
    {
      "x": 0,
      "y": 1,
      "z": -7,
      "name": "Empty"
    },
    {
      "x": 0,
      "y": 2,
      "z": -7,
      "name": "Empty"
    },
    {
      "x": 0,
      "y": 3,
      "z": -7,
      "name": "Empty"
    },
    {
      "x": 0,
      "y": 4,
      "z": -7,
      "name": "Empty"
    },
    {
      "x": 0,
      "y": 5,
      "z": -7,
      "name": "Empty"
    },
    {
      "x": 0,
      "y": 6,
      "z": -7,
      "name": "Empty"
    },
    {
      "x": 0,
      "y": 7,
      "z": -7,
      "name": "Rock_DarkConcrete"
    },
    {
      "x": 0,
      "y": 0,
      "z": -6,
      "name": "Soil_Dirt_Cold"
    },
    {
      "x": 0,
      "y": 1,
      "z": -6,
      "name": "Empty"
    },
    {
      "x": 0,
      "y": 2,
      "z": -6,
      "name": "Empty"
    },
    {
      "x": 0,
      "y": 3,
      "z": -6,
      "name": "Empty"
    },
    {
      "x": 0,
      "y": 4,
      "z": -6,
      "name": "Empty"
    },
    {
      "x": 0,
      "y": 5,
      "z": -6,
      "name": "Empty"
    },
    {
      "x": 0,
      "y": 6,
      "z": -6,
      "name": "Empty"
    },
    {
      "x": 0,
      "y": 7,
      "z": -6,
      "name": "Rock_DarkConcrete"
    },
    {
      "x": 0,
      "y": 0,
      "z": -5,
      "name": "Rock_CastIron"
    },
    {
      "x": 0,
      "y": 1,
      "z": -5,
      "name": "Plant_Moss_Rug_Green_Dark",
      "support": 15
    },
    {
      "x": 0,
      "y": 2,
      "z": -5,
      "name": "Empty"
    },
    {
      "x": 0,
      "y": 3,
      "z": -5,
      "name": "Empty"
    },
    {
      "x": 0,
      "y": 4,
      "z": -5,
      "name": "Empty"
    },
    {
      "x": 0,
      "y": 5,
      "z": -5,
      "name": "Empty"
    },
    {
      "x": 0,
      "y": 6,
      "z": -5,
      "name": "Empty"
    },
    {
      "x": 0,
      "y": 7,
      "z": -5,
      "name": "Rock_DarkConcrete"
    },
    {
      "x": 0,
      "y": 0,
      "z": -4,
      "name": "Rock_CastIron"
    },
    {
      "x": 0,
      "y": 1,
      "z": -4,
      "name": "Empty"
    },
    {
      "x": 0,
      "y": 2,
      "z": -4,
      "name": "Empty"
    },
    {
      "x": 0,
      "y": 3,
      "z": -4,
      "name": "Empty"
    },
    {
      "x": 0,
      "y": 4,
      "z": -4,
      "name": "Empty"
    },
    {
      "x": 0,
      "y": 5,
      "z": -4,
      "name": "Empty"
    },
    {
      "x": 0,
      "y": 6,
      "z": -4,
      "name": "Empty"
    },
    {
      "x": 0,
      "y": 7,
      "z": -4,
      "name": "Rock_DarkConcrete"
    },
    {
      "x": 0,
      "y": 0,
      "z": -3,
      "name": "Rock_CastIron"
    },
    {
      "x": 0,
      "y": 1,
      "z": -3,
      "name": "Plant_Moss_Rug_Green_Dark",
      "support": 15
    },
    {
      "x": 0,
      "y": 2,
      "z": -3,
      "name": "Empty"
    },
    {
      "x": 0,
      "y": 3,
      "z": -3,
      "name": "Empty"
    },
    {
      "x": 0,
      "y": 4,
      "z": -3,
      "name": "Empty"
    },
    {
      "x": 0,
      "y": 5,
      "z": -3,
      "name": "Empty"
    },
    {
      "x": 0,
      "y": 6,
      "z": -3,
      "name": "Empty"
    },
    {
      "x": 0,
      "y": 7,
      "z": -3,
      "name": "Rock_DarkConcrete"
    },
    {
      "x": 0,
      "y": 0,
      "z": -2,
      "name": "Rock_CastIron"
    },
    {
      "x": 0,
      "y": 1,
      "z": -2,
      "name": "Plant_Moss_Rug_Green_Dark",
      "support": 15
    },
    {
      "x": 0,
      "y": 2,
      "z": -2,
      "name": "Empty"
    },
    {
      "x": 0,
      "y": 3,
      "z": -2,
      "name": "Empty"
    },
    {
      "x": 0,
      "y": 4,
      "z": -2,
      "name": "Empty"
    },
    {
      "x": 0,
      "y": 5,
      "z": -2,
      "name": "Plant_Leaves_Wisteria_Wild",
      "support": 15
    },
    {
      "x": 0,
      "y": 6,
      "z": -2,
      "name": "Plant_Leaves_Wisteria_Wild",
      "support": 15
    },
    {
      "x": 0,
      "y": 7,
      "z": -2,
      "name": "Rock_DarkConcrete"
    },
    {
      "x": 0,
      "y": 0,
      "z": -1,
      "name": "Rock_CastIron"
    },
    {
      "x": 0,
      "y": 1,
      "z": -1,
      "name": "Empty"
    },
    {
      "x": 0,
      "y": 2,
      "z": -1,
      "name": "Empty"
    },
    {
      "x": 0,
      "y": 3,
      "z": -1,
      "name": "Empty"
    },
    {
      "x": 0,
      "y": 4,
      "z": -1,
      "name": "Empty"
    },
    {
      "x": 0,
      "y": 5,
      "z": -1,
      "name": "Empty"
    },
    {
      "x": 0,
      "y": 6,
      "z": -1,
      "name": "Rock_DarkConcrete_Brick"
    },
    {
      "x": 0,
      "y": 7,
      "z": -1,
      "name": "Rock_DarkConcrete"
    },
    {
      "x": 0,
      "y": 0,
      "z": 0,
      "name": "Rock_CastIron"
    },
    {
      "x": 0,
      "y": 1,
      "z": 0,
      "name": "Plant_Moss_Rug_Green_Dark",
      "support": 15
    },
    {
      "x": 0,
      "y": 2,
      "z": 0,
      "name": "Empty"
    },
    {
      "x": 0,
      "y": 3,
      "z": 0,
      "name": "Empty"
    },
    {
      "x": 0,
      "y": 4,
      "z": 0,
      "name": "Empty"
    },
    {
      "x": 0,
      "y": 5,
      "z": 0,
      "name": "Empty"
    },
    {
      "x": 0,
      "y": 6,
      "z": 0,
      "name": "Rock_DarkConcrete_Brick"
    },
    {
      "x": 0,
      "y": 7,
      "z": 0,
      "name": "Rock_DarkConcrete"
    },
    {
      "x": 0,
      "y": 0,
      "z": 1,
      "name": "Rock_CastIron"
    },
    {
      "x": 0,
      "y": 1,
      "z": 1,
      "name": "Empty"
    },
    {
      "x": 0,
      "y": 2,
      "z": 1,
      "name": "Empty"
    },
    {
      "x": 0,
      "y": 3,
      "z": 1,
      "name": "Empty"
    },
    {
      "x": 0,
      "y": 4,
      "z": 1,
      "name": "Empty"
    },
    {
      "x": 0,
      "y": 5,
      "z": 1,
      "name": "Empty"
    },
    {
      "x": 0,
      "y": 6,
      "z": 1,
      "name": "Rock_DarkConcrete_Brick"
    },
    {
      "x": 0,
      "y": 7,
      "z": 1,
      "name": "Rock_DarkConcrete"
    },
    {
      "x": 0,
      "y": 0,
      "z": 2,
      "name": "Rock_CastIron"
    },
    {
      "x": 0,
      "y": 1,
      "z": 2,
      "name": "Plant_Moss_Rug_Green_Dark",
      "support": 15
    },
    {
      "x": 0,
      "y": 2,
      "z": 2,
      "name": "Empty"
    },
    {
      "x": 0,
      "y": 3,
      "z": 2,
      "name": "Empty"
    },
    {
      "x": 0,
      "y": 4,
      "z": 2,
      "name": "Empty"
    },
    {
      "x": 0,
      "y": 5,
      "z": 2,
      "name": "Empty"
    },
    {
      "x": 0,
      "y": 6,
      "z": 2,
      "name": "Empty"
    },
    {
      "x": 0,
      "y": 7,
      "z": 2,
      "name": "Rock_DarkConcrete"
    },
    {
      "x": 0,
      "y": 0,
      "z": 3,
      "name": "Rock_CastIron"
    },
    {
      "x": 0,
      "y": 1,
      "z": 3,
      "name": "Empty"
    },
    {
      "x": 0,
      "y": 2,
      "z": 3,
      "name": "Empty"
    },
    {
      "x": 0,
      "y": 3,
      "z": 3,
      "name": "Empty"
    },
    {
      "x": 0,
      "y": 4,
      "z": 3,
      "name": "Empty"
    },
    {
      "x": 0,
      "y": 5,
      "z": 3,
      "name": "Empty"
    },
    {
      "x": 0,
      "y": 6,
      "z": 3,
      "name": "Empty"
    },
    {
      "x": 0,
      "y": 7,
      "z": 3,
      "name": "Rock_DarkConcrete"
    },
    {
      "x": 0,
      "y": 0,
      "z": 4,
      "name": "Rock_CastIron"
    },
    {
      "x": 0,
      "y": 1,
      "z": 4,
      "name": "Plant_Moss_Rug_Green_Dark",
      "support": 15
    },
    {
      "x": 0,
      "y": 2,
      "z": 4,
      "name": "Empty"
    },
    {
      "x": 0,
      "y": 3,
      "z": 4,
      "name": "Empty"
    },
    {
      "x": 0,
      "y": 4,
      "z": 4,
      "name": "Empty"
    },
    {
      "x": 0,
      "y": 5,
      "z": 4,
      "name": "Empty"
    },
    {
      "x": 0,
      "y": 6,
      "z": 4,
      "name": "Empty"
    },
    {
      "x": 0,
      "y": 7,
      "z": 4,
      "name": "Rock_DarkConcrete"
    },
    {
      "x": 0,
      "y": 0,
      "z": 5,
      "name": "Rock_CastIron"
    },
    {
      "x": 0,
      "y": 1,
      "z": 5,
      "name": "Empty"
    },
    {
      "x": 0,
      "y": 2,
      "z": 5,
      "name": "Empty"
    },
    {
      "x": 0,
      "y": 3,
      "z": 5,
      "name": "Empty"
    },
    {
      "x": 0,
      "y": 4,
      "z": 5,
      "name": "Empty"
    },
    {
      "x": 0,
      "y": 5,
      "z": 5,
      "name": "Empty"
    },
    {
      "x": 0,
      "y": 6,
      "z": 5,
      "name": "Empty"
    },
    {
      "x": 0,
      "y": 7,
      "z": 5,
      "name": "Rock_DarkConcrete"
    },
    {
      "x": 0,
      "y": 0,
      "z": 6,
      "name": "Rock_CastIron"
    },
    {
      "x": 0,
      "y": 1,
      "z": 6,
      "name": "Empty"
    },
    {
      "x": 0,
      "y": 2,
      "z": 6,
      "name": "Empty"
    },
    {
      "x": 0,
      "y": 3,
      "z": 6,
      "name": "Empty"
    },
    {
      "x": 0,
      "y": 4,
      "z": 6,
      "name": "Empty"
    },
    {
      "x": 0,
      "y": 5,
      "z": 6,
      "name": "Empty"
    },
    {
      "x": 0,
      "y": 6,
      "z": 6,
      "name": "Empty"
    },
    {
      "x": 0,
      "y": 7,
      "z": 6,
      "name": "Rock_DarkConcrete"
    },
    {
      "x": 0,
      "y": 0,
      "z": 7,
      "name": "Rock_CastIron"
    },
    {
      "x": 0,
      "y": 1,
      "z": 7,
      "name": "Empty"
    },
    {
      "x": 0,
      "y": 2,
      "z": 7,
      "name": "Empty"
    },
    {
      "x": 0,
      "y": 3,
      "z": 7,
      "name": "Empty"
    },
    {
      "x": 0,
      "y": 4,
      "z": 7,
      "name": "Empty"
    },
    {
      "x": 0,
      "y": 5,
      "z": 7,
      "name": "Empty"
    },
    {
      "x": 0,
      "y": 6,
      "z": 7,
      "name": "Empty"
    },
    {
      "x": 0,
      "y": 7,
      "z": 7,
      "name": "Rock_DarkConcrete"
    },
    {
      "x": 1,
      "y": 0,
      "z": -7,
      "name": "Rock_CastIron"
    },
    {
      "x": 1,
      "y": 1,
      "z": -7,
      "name": "Empty"
    },
    {
      "x": 1,
      "y": 2,
      "z": -7,
      "name": "Empty"
    },
    {
      "x": 1,
      "y": 3,
      "z": -7,
      "name": "Empty"
    },
    {
      "x": 1,
      "y": 4,
      "z": -7,
      "name": "Empty"
    },
    {
      "x": 1,
      "y": 5,
      "z": -7,
      "name": "Empty"
    },
    {
      "x": 1,
      "y": 6,
      "z": -7,
      "name": "Empty"
    },
    {
      "x": 1,
      "y": 7,
      "z": -7,
      "name": "Rock_DarkConcrete"
    },
    {
      "x": 1,
      "y": 0,
      "z": -6,
      "name": "Rock_CastIron"
    },
    {
      "x": 1,
      "y": 1,
      "z": -6,
      "name": "Empty"
    },
    {
      "x": 1,
      "y": 2,
      "z": -6,
      "name": "Empty"
    },
    {
      "x": 1,
      "y": 3,
      "z": -6,
      "name": "Empty"
    },
    {
      "x": 1,
      "y": 4,
      "z": -6,
      "name": "Empty"
    },
    {
      "x": 1,
      "y": 5,
      "z": -6,
      "name": "Empty"
    },
    {
      "x": 1,
      "y": 6,
      "z": -6,
      "name": "Empty"
    },
    {
      "x": 1,
      "y": 7,
      "z": -6,
      "name": "Rock_DarkConcrete"
    },
    {
      "x": 1,
      "y": 0,
      "z": -5,
      "name": "Rock_CastIron"
    },
    {
      "x": 1,
      "y": 1,
      "z": -5,
      "name": "Plant_Moss_Rug_Green_Dark",
      "support": 15
    },
    {
      "x": 1,
      "y": 2,
      "z": -5,
      "name": "Empty"
    },
    {
      "x": 1,
      "y": 3,
      "z": -5,
      "name": "Empty"
    },
    {
      "x": 1,
      "y": 4,
      "z": -5,
      "name": "Empty"
    },
    {
      "x": 1,
      "y": 5,
      "z": -5,
      "name": "Empty"
    },
    {
      "x": 1,
      "y": 6,
      "z": -5,
      "name": "Empty"
    },
    {
      "x": 1,
      "y": 7,
      "z": -5,
      "name": "Rock_DarkConcrete"
    },
    {
      "x": 1,
      "y": 0,
      "z": -4,
      "name": "Soil_Dirt_Cold"
    },
    {
      "x": 1,
      "y": 1,
      "z": -4,
      "name": "Empty"
    },
    {
      "x": 1,
      "y": 2,
      "z": -4,
      "name": "Empty"
    },
    {
      "x": 1,
      "y": 3,
      "z": -4,
      "name": "Empty"
    },
    {
      "x": 1,
      "y": 4,
      "z": -4,
      "name": "Empty"
    },
    {
      "x": 1,
      "y": 5,
      "z": -4,
      "name": "Empty"
    },
    {
      "x": 1,
      "y": 6,
      "z": -4,
      "name": "Empty"
    },
    {
      "x": 1,
      "y": 7,
      "z": -4,
      "name": "Rock_DarkConcrete"
    },
    {
      "x": 1,
      "y": 0,
      "z": -3,
      "name": "Rock_CastIron"
    },
    {
      "x": 1,
      "y": 1,
      "z": -3,
      "name": "Empty"
    },
    {
      "x": 1,
      "y": 2,
      "z": -3,
      "name": "Empty"
    },
    {
      "x": 1,
      "y": 3,
      "z": -3,
      "name": "Empty"
    },
    {
      "x": 1,
      "y": 4,
      "z": -3,
      "name": "Empty"
    },
    {
      "x": 1,
      "y": 5,
      "z": -3,
      "name": "Empty"
    },
    {
      "x": 1,
      "y": 6,
      "z": -3,
      "name": "Empty"
    },
    {
      "x": 1,
      "y": 7,
      "z": -3,
      "name": "Rock_DarkConcrete"
    },
    {
      "x": 1,
      "y": 0,
      "z": -2,
      "name": "Soil_Dirt_Cold"
    },
    {
      "x": 1,
      "y": 1,
      "z": -2,
      "name": "Plant_Flower_Bushy_Green"
    },
    {
      "x": 1,
      "y": 2,
      "z": -2,
      "name": "Empty"
    },
    {
      "x": 1,
      "y": 3,
      "z": -2,
      "name": "Empty"
    },
    {
      "x": 1,
      "y": 4,
      "z": -2,
      "name": "Empty"
    },
    {
      "x": 1,
      "y": 5,
      "z": -2,
      "name": "Empty"
    },
    {
      "x": 1,
      "y": 6,
      "z": -2,
      "name": "Plant_Leaves_Wisteria_Wild",
      "support": 15
    },
    {
      "x": 1,
      "y": 7,
      "z": -2,
      "name": "Rock_DarkConcrete"
    },
    {
      "x": 1,
      "y": 0,
      "z": -1,
      "name": "Soil_Dirt_Cold"
    },
    {
      "x": 1,
      "y": 1,
      "z": -1,
      "name": "Plant_Grass_Sharp_Tall",
      "support": 15
    },
    {
      "x": 1,
      "y": 2,
      "z": -1,
      "name": "Plant_Grass_Sharp_Tall",
      "filler": 1024
    },
    {
      "x": 1,
      "y": 3,
      "z": -1,
      "name": "Empty"
    },
    {
      "x": 1,
      "y": 4,
      "z": -1,
      "name": "Empty"
    },
    {
      "x": 1,
      "y": 5,
      "z": -1,
      "name": "Empty"
    },
    {
      "x": 1,
      "y": 6,
      "z": -1,
      "name": "Rock_DarkConcrete_Brick"
    },
    {
      "x": 1,
      "y": 7,
      "z": -1,
      "name": "Rock_DarkConcrete"
    },
    {
      "x": 1,
      "y": 0,
      "z": 0,
      "name": "Rock_CastIron"
    },
    {
      "x": 1,
      "y": 1,
      "z": 0,
      "name": "Empty"
    },
    {
      "x": 1,
      "y": 2,
      "z": 0,
      "name": "Empty"
    },
    {
      "x": 1,
      "y": 3,
      "z": 0,
      "name": "Empty"
    },
    {
      "x": 1,
      "y": 4,
      "z": 0,
      "name": "Empty"
    },
    {
      "x": 1,
      "y": 5,
      "z": 0,
      "name": "Empty"
    },
    {
      "x": 1,
      "y": 6,
      "z": 0,
      "name": "Rock_DarkConcrete_Brick"
    },
    {
      "x": 1,
      "y": 7,
      "z": 0,
      "name": "Rock_DarkConcrete"
    },
    {
      "x": 1,
      "y": 0,
      "z": 1,
      "name": "Rock_CastIron"
    },
    {
      "x": 1,
      "y": 1,
      "z": 1,
      "name": "Plant_Moss_Rug_Green_Dark",
      "support": 15
    },
    {
      "x": 1,
      "y": 2,
      "z": 1,
      "name": "Empty"
    },
    {
      "x": 1,
      "y": 3,
      "z": 1,
      "name": "Empty"
    },
    {
      "x": 1,
      "y": 4,
      "z": 1,
      "name": "Empty"
    },
    {
      "x": 1,
      "y": 5,
      "z": 1,
      "name": "Empty"
    },
    {
      "x": 1,
      "y": 6,
      "z": 1,
      "name": "Rock_DarkConcrete_Brick"
    },
    {
      "x": 1,
      "y": 7,
      "z": 1,
      "name": "Rock_DarkConcrete"
    },
    {
      "x": 1,
      "y": 0,
      "z": 2,
      "name": "Rock_CastIron"
    },
    {
      "x": 1,
      "y": 1,
      "z": 2,
      "name": "Plant_Moss_Rug_Green_Dark",
      "support": 15
    },
    {
      "x": 1,
      "y": 2,
      "z": 2,
      "name": "Empty"
    },
    {
      "x": 1,
      "y": 3,
      "z": 2,
      "name": "Empty"
    },
    {
      "x": 1,
      "y": 4,
      "z": 2,
      "name": "Empty"
    },
    {
      "x": 1,
      "y": 5,
      "z": 2,
      "name": "Empty"
    },
    {
      "x": 1,
      "y": 6,
      "z": 2,
      "name": "Empty"
    },
    {
      "x": 1,
      "y": 7,
      "z": 2,
      "name": "Rock_DarkConcrete"
    },
    {
      "x": 1,
      "y": 0,
      "z": 3,
      "name": "Rock_CastIron"
    },
    {
      "x": 1,
      "y": 1,
      "z": 3,
      "name": "Empty"
    },
    {
      "x": 1,
      "y": 2,
      "z": 3,
      "name": "Empty"
    },
    {
      "x": 1,
      "y": 3,
      "z": 3,
      "name": "Empty"
    },
    {
      "x": 1,
      "y": 4,
      "z": 3,
      "name": "Empty"
    },
    {
      "x": 1,
      "y": 5,
      "z": 3,
      "name": "Empty"
    },
    {
      "x": 1,
      "y": 6,
      "z": 3,
      "name": "Empty"
    },
    {
      "x": 1,
      "y": 7,
      "z": 3,
      "name": "Rock_DarkConcrete"
    },
    {
      "x": 1,
      "y": 0,
      "z": 4,
      "name": "Rock_CastIron"
    },
    {
      "x": 1,
      "y": 1,
      "z": 4,
      "name": "Empty"
    },
    {
      "x": 1,
      "y": 2,
      "z": 4,
      "name": "Empty"
    },
    {
      "x": 1,
      "y": 3,
      "z": 4,
      "name": "Empty"
    },
    {
      "x": 1,
      "y": 4,
      "z": 4,
      "name": "Empty"
    },
    {
      "x": 1,
      "y": 5,
      "z": 4,
      "name": "Empty"
    },
    {
      "x": 1,
      "y": 6,
      "z": 4,
      "name": "Empty"
    },
    {
      "x": 1,
      "y": 7,
      "z": 4,
      "name": "Rock_DarkConcrete"
    },
    {
      "x": 1,
      "y": 0,
      "z": 5,
      "name": "Rock_CastIron"
    },
    {
      "x": 1,
      "y": 1,
      "z": 5,
      "name": "Plant_Moss_Rug_Green_Dark",
      "support": 15
    },
    {
      "x": 1,
      "y": 2,
      "z": 5,
      "name": "Empty"
    },
    {
      "x": 1,
      "y": 3,
      "z": 5,
      "name": "Empty"
    },
    {
      "x": 1,
      "y": 4,
      "z": 5,
      "name": "Empty"
    },
    {
      "x": 1,
      "y": 5,
      "z": 5,
      "name": "Empty"
    },
    {
      "x": 1,
      "y": 6,
      "z": 5,
      "name": "Empty"
    },
    {
      "x": 1,
      "y": 7,
      "z": 5,
      "name": "Rock_DarkConcrete"
    },
    {
      "x": 1,
      "y": 0,
      "z": 6,
      "name": "Rock_CastIron"
    },
    {
      "x": 1,
      "y": 1,
      "z": 6,
      "name": "Empty"
    },
    {
      "x": 1,
      "y": 2,
      "z": 6,
      "name": "Empty"
    },
    {
      "x": 1,
      "y": 3,
      "z": 6,
      "name": "Empty"
    },
    {
      "x": 1,
      "y": 4,
      "z": 6,
      "name": "Empty"
    },
    {
      "x": 1,
      "y": 5,
      "z": 6,
      "name": "Empty"
    },
    {
      "x": 1,
      "y": 6,
      "z": 6,
      "name": "Empty"
    },
    {
      "x": 1,
      "y": 7,
      "z": 6,
      "name": "Rock_DarkConcrete"
    },
    {
      "x": 1,
      "y": 0,
      "z": 7,
      "name": "Rock_CastIron"
    },
    {
      "x": 1,
      "y": 1,
      "z": 7,
      "name": "Empty"
    },
    {
      "x": 1,
      "y": 2,
      "z": 7,
      "name": "Empty"
    },
    {
      "x": 1,
      "y": 3,
      "z": 7,
      "name": "Empty"
    },
    {
      "x": 1,
      "y": 4,
      "z": 7,
      "name": "Empty"
    },
    {
      "x": 1,
      "y": 5,
      "z": 7,
      "name": "Empty"
    },
    {
      "x": 1,
      "y": 6,
      "z": 7,
      "name": "Empty"
    },
    {
      "x": 1,
      "y": 7,
      "z": 7,
      "name": "Rock_DarkConcrete"
    },
    {
      "x": 2,
      "y": 0,
      "z": -7,
      "name": "Rock_CastIron"
    },
    {
      "x": 2,
      "y": 1,
      "z": -7,
      "name": "Empty"
    },
    {
      "x": 2,
      "y": 2,
      "z": -7,
      "name": "Empty"
    },
    {
      "x": 2,
      "y": 3,
      "z": -7,
      "name": "Empty"
    },
    {
      "x": 2,
      "y": 4,
      "z": -7,
      "name": "Empty"
    },
    {
      "x": 2,
      "y": 5,
      "z": -7,
      "name": "Empty"
    },
    {
      "x": 2,
      "y": 6,
      "z": -7,
      "name": "Empty"
    },
    {
      "x": 2,
      "y": 7,
      "z": -7,
      "name": "Rock_DarkConcrete"
    },
    {
      "x": 2,
      "y": 0,
      "z": -6,
      "name": "Rock_CastIron"
    },
    {
      "x": 2,
      "y": 1,
      "z": -6,
      "name": "Empty"
    },
    {
      "x": 2,
      "y": 2,
      "z": -6,
      "name": "Empty"
    },
    {
      "x": 2,
      "y": 3,
      "z": -6,
      "name": "Empty"
    },
    {
      "x": 2,
      "y": 4,
      "z": -6,
      "name": "Empty"
    },
    {
      "x": 2,
      "y": 5,
      "z": -6,
      "name": "Empty"
    },
    {
      "x": 2,
      "y": 6,
      "z": -6,
      "name": "Empty"
    },
    {
      "x": 2,
      "y": 7,
      "z": -6,
      "name": "Rock_DarkConcrete"
    },
    {
      "x": 2,
      "y": 0,
      "z": -5,
      "name": "Rock_CastIron"
    },
    {
      "x": 2,
      "y": 1,
      "z": -5,
      "name": "Furniture_Ancient_Crate",
      "rotation": 3
    },
    {
      "x": 2,
      "y": 2,
      "z": -5,
      "name": "Empty"
    },
    {
      "x": 2,
      "y": 3,
      "z": -5,
      "name": "Empty"
    },
    {
      "x": 2,
      "y": 4,
      "z": -5,
      "name": "Empty"
    },
    {
      "x": 2,
      "y": 5,
      "z": -5,
      "name": "Empty"
    },
    {
      "x": 2,
      "y": 6,
      "z": -5,
      "name": "Empty"
    },
    {
      "x": 2,
      "y": 7,
      "z": -5,
      "name": "Rock_DarkConcrete"
    },
    {
      "x": 2,
      "y": 0,
      "z": -4,
      "name": "Soil_Dirt_Cold"
    },
    {
      "x": 2,
      "y": 1,
      "z": -4,
      "name": "Plant_Bush_Dead_Twisted"
    },
    {
      "x": 2,
      "y": 2,
      "z": -4,
      "name": "Empty"
    },
    {
      "x": 2,
      "y": 3,
      "z": -4,
      "name": "Empty"
    },
    {
      "x": 2,
      "y": 4,
      "z": -4,
      "name": "Empty"
    },
    {
      "x": 2,
      "y": 5,
      "z": -4,
      "name": "Empty"
    },
    {
      "x": 2,
      "y": 6,
      "z": -4,
      "name": "Empty"
    },
    {
      "x": 2,
      "y": 7,
      "z": -4,
      "name": "Rock_DarkConcrete"
    },
    {
      "x": 2,
      "y": 0,
      "z": -3,
      "name": "Soil_Dirt_Cold"
    },
    {
      "x": 2,
      "y": 1,
      "z": -3,
      "name": "Rubble_Basalt_Medium"
    },
    {
      "x": 2,
      "y": 2,
      "z": -3,
      "name": "Empty"
    },
    {
      "x": 2,
      "y": 3,
      "z": -3,
      "name": "Empty"
    },
    {
      "x": 2,
      "y": 4,
      "z": -3,
      "name": "Empty"
    },
    {
      "x": 2,
      "y": 5,
      "z": -3,
      "name": "Empty"
    },
    {
      "x": 2,
      "y": 6,
      "z": -3,
      "name": "Empty"
    },
    {
      "x": 2,
      "y": 7,
      "z": -3,
      "name": "Rock_DarkConcrete"
    },
    {
      "x": 2,
      "y": 0,
      "z": -2,
      "name": "Soil_Dirt_Cold"
    },
    {
      "x": 2,
      "y": 1,
      "z": -2,
      "name": "Plant_Grass_Gnarled_Tall",
      "support": 15
    },
    {
      "x": 2,
      "y": 2,
      "z": -2,
      "name": "Plant_Grass_Gnarled_Tall",
      "filler": 1024
    },
    {
      "x": 2,
      "y": 3,
      "z": -2,
      "name": "Empty"
    },
    {
      "x": 2,
      "y": 4,
      "z": -2,
      "name": "Empty"
    },
    {
      "x": 2,
      "y": 5,
      "z": -2,
      "name": "Empty"
    },
    {
      "x": 2,
      "y": 6,
      "z": -2,
      "name": "Empty"
    },
    {
      "x": 2,
      "y": 7,
      "z": -2,
      "name": "Rock_DarkConcrete"
    },
    {
      "x": 2,
      "y": 0,
      "z": -1,
      "name": "Soil_Dirt_Cold"
    },
    {
      "x": 2,
      "y": 1,
      "z": -1,
      "name": "Empty"
    },
    {
      "x": 2,
      "y": 2,
      "z": -1,
      "name": "Empty"
    },
    {
      "x": 2,
      "y": 3,
      "z": -1,
      "name": "Empty"
    },
    {
      "x": 2,
      "y": 4,
      "z": -1,
      "name": "Empty"
    },
    {
      "x": 2,
      "y": 5,
      "z": -1,
      "name": "Rock_DarkConcrete_Brick_Half",
      "rotation": 8
    },
    {
      "x": 2,
      "y": 6,
      "z": -1,
      "name": "Rock_DarkConcrete_Brick"
    },
    {
      "x": 2,
      "y": 7,
      "z": -1,
      "name": "Rock_DarkConcrete"
    },
    {
      "x": 2,
      "y": 0,
      "z": 0,
      "name": "Rock_CastIron_Brick"
    },
    {
      "x": 2,
      "y": 1,
      "z": 0,
      "name": "Empty"
    },
    {
      "x": 2,
      "y": 2,
      "z": 0,
      "name": "Empty"
    },
    {
      "x": 2,
      "y": 3,
      "z": 0,
      "name": "Empty"
    },
    {
      "x": 2,
      "y": 4,
      "z": 0,
      "name": "Empty"
    },
    {
      "x": 2,
      "y": 5,
      "z": 0,
      "name": "Rock_DarkConcrete_Brick_Half",
      "rotation": 8
    },
    {
      "x": 2,
      "y": 6,
      "z": 0,
      "name": "Rock_DarkConcrete_Brick"
    },
    {
      "x": 2,
      "y": 7,
      "z": 0,
      "name": "Rock_DarkConcrete"
    },
    {
      "x": 2,
      "y": 0,
      "z": 1,
      "name": "Rock_CastIron_Brick"
    },
    {
      "x": 2,
      "y": 1,
      "z": 1,
      "name": "Plant_Moss_Rug_Green_Dark",
      "support": 15
    },
    {
      "x": 2,
      "y": 2,
      "z": 1,
      "name": "Empty"
    },
    {
      "x": 2,
      "y": 3,
      "z": 1,
      "name": "Empty"
    },
    {
      "x": 2,
      "y": 4,
      "z": 1,
      "name": "Empty"
    },
    {
      "x": 2,
      "y": 5,
      "z": 1,
      "name": "Rock_DarkConcrete_Brick_Half",
      "rotation": 8
    },
    {
      "x": 2,
      "y": 6,
      "z": 1,
      "name": "Rock_DarkConcrete_Brick"
    },
    {
      "x": 2,
      "y": 7,
      "z": 1,
      "name": "Rock_DarkConcrete"
    },
    {
      "x": 2,
      "y": 0,
      "z": 2,
      "name": "Soil_Dirt_Cold"
    },
    {
      "x": 2,
      "y": 1,
      "z": 2,
      "name": "Empty"
    },
    {
      "x": 2,
      "y": 2,
      "z": 2,
      "name": "Empty"
    },
    {
      "x": 2,
      "y": 3,
      "z": 2,
      "name": "Empty"
    },
    {
      "x": 2,
      "y": 4,
      "z": 2,
      "name": "Empty"
    },
    {
      "x": 2,
      "y": 5,
      "z": 2,
      "name": "Empty"
    },
    {
      "x": 2,
      "y": 6,
      "z": 2,
      "name": "Empty"
    },
    {
      "x": 2,
      "y": 7,
      "z": 2,
      "name": "Rock_DarkConcrete"
    },
    {
      "x": 2,
      "y": 0,
      "z": 3,
      "name": "Soil_Dirt_Cold"
    },
    {
      "x": 2,
      "y": 1,
      "z": 3,
      "name": "Plant_Grass_Sharp_Tall",
      "support": 15
    },
    {
      "x": 2,
      "y": 2,
      "z": 3,
      "name": "Plant_Grass_Sharp_Tall",
      "filler": 1024
    },
    {
      "x": 2,
      "y": 3,
      "z": 3,
      "name": "Empty"
    },
    {
      "x": 2,
      "y": 4,
      "z": 3,
      "name": "Empty"
    },
    {
      "x": 2,
      "y": 5,
      "z": 3,
      "name": "Empty"
    },
    {
      "x": 2,
      "y": 6,
      "z": 3,
      "name": "Empty"
    },
    {
      "x": 2,
      "y": 7,
      "z": 3,
      "name": "Rock_DarkConcrete"
    },
    {
      "x": 2,
      "y": 0,
      "z": 4,
      "name": "Rock_CastIron"
    },
    {
      "x": 2,
      "y": 1,
      "z": 4,
      "name": "Rubble_Basalt"
    },
    {
      "x": 2,
      "y": 2,
      "z": 4,
      "name": "Empty"
    },
    {
      "x": 2,
      "y": 3,
      "z": 4,
      "name": "Empty"
    },
    {
      "x": 2,
      "y": 4,
      "z": 4,
      "name": "Empty"
    },
    {
      "x": 2,
      "y": 5,
      "z": 4,
      "name": "Empty"
    },
    {
      "x": 2,
      "y": 6,
      "z": 4,
      "name": "Empty"
    },
    {
      "x": 2,
      "y": 7,
      "z": 4,
      "name": "Rock_DarkConcrete"
    },
    {
      "x": 2,
      "y": 0,
      "z": 5,
      "name": "Rock_CastIron"
    },
    {
      "x": 2,
      "y": 1,
      "z": 5,
      "name": "Plant_Moss_Rug_Green_Dark",
      "support": 15
    },
    {
      "x": 2,
      "y": 2,
      "z": 5,
      "name": "Empty"
    },
    {
      "x": 2,
      "y": 3,
      "z": 5,
      "name": "Empty"
    },
    {
      "x": 2,
      "y": 4,
      "z": 5,
      "name": "Empty"
    },
    {
      "x": 2,
      "y": 5,
      "z": 5,
      "name": "Empty"
    },
    {
      "x": 2,
      "y": 6,
      "z": 5,
      "name": "Empty"
    },
    {
      "x": 2,
      "y": 7,
      "z": 5,
      "name": "Rock_DarkConcrete"
    },
    {
      "x": 2,
      "y": 0,
      "z": 6,
      "name": "Rock_CastIron"
    },
    {
      "x": 2,
      "y": 1,
      "z": 6,
      "name": "Plant_Moss_Rug_Green_Dark",
      "support": 15
    },
    {
      "x": 2,
      "y": 2,
      "z": 6,
      "name": "Empty"
    },
    {
      "x": 2,
      "y": 3,
      "z": 6,
      "name": "Empty"
    },
    {
      "x": 2,
      "y": 4,
      "z": 6,
      "name": "Empty"
    },
    {
      "x": 2,
      "y": 5,
      "z": 6,
      "name": "Empty"
    },
    {
      "x": 2,
      "y": 6,
      "z": 6,
      "name": "Empty"
    },
    {
      "x": 2,
      "y": 7,
      "z": 6,
      "name": "Rock_DarkConcrete"
    },
    {
      "x": 2,
      "y": 0,
      "z": 7,
      "name": "Rock_CastIron"
    },
    {
      "x": 2,
      "y": 1,
      "z": 7,
      "name": "Empty"
    },
    {
      "x": 2,
      "y": 2,
      "z": 7,
      "name": "Empty"
    },
    {
      "x": 2,
      "y": 3,
      "z": 7,
      "name": "Empty"
    },
    {
      "x": 2,
      "y": 4,
      "z": 7,
      "name": "Empty"
    },
    {
      "x": 2,
      "y": 5,
      "z": 7,
      "name": "Empty"
    },
    {
      "x": 2,
      "y": 6,
      "z": 7,
      "name": "Empty"
    },
    {
      "x": 2,
      "y": 7,
      "z": 7,
      "name": "Rock_DarkConcrete"
    },
    {
      "x": 3,
      "y": 0,
      "z": -7,
      "name": "Rock_CastIron_Brick_Smooth"
    },
    {
      "x": 3,
      "y": 1,
      "z": -7,
      "name": "Empty"
    },
    {
      "x": 3,
      "y": 2,
      "z": -7,
      "name": "Empty"
    },
    {
      "x": 3,
      "y": 3,
      "z": -7,
      "name": "Empty"
    },
    {
      "x": 3,
      "y": 4,
      "z": -7,
      "name": "Empty"
    },
    {
      "x": 3,
      "y": 5,
      "z": -7,
      "name": "Empty"
    },
    {
      "x": 3,
      "y": 6,
      "z": -7,
      "name": "Rock_CastIron_Brick_Stairs",
      "rotation": 9
    },
    {
      "x": 3,
      "y": 7,
      "z": -7,
      "name": "Rock_DarkConcrete"
    },
    {
      "x": 3,
      "y": 0,
      "z": -6,
      "name": "Rock_CastIron_Brick_Smooth"
    },
    {
      "x": 3,
      "y": 1,
      "z": -6,
      "name": "Furniture_Ancient_Barrel"
    },
    {
      "x": 3,
      "y": 2,
      "z": -6,
      "name": "Empty"
    },
    {
      "x": 3,
      "y": 3,
      "z": -6,
      "name": "Empty"
    },
    {
      "x": 3,
      "y": 4,
      "z": -6,
      "name": "Empty"
    },
    {
      "x": 3,
      "y": 5,
      "z": -6,
      "name": "Empty"
    },
    {
      "x": 3,
      "y": 6,
      "z": -6,
      "name": "Empty"
    },
    {
      "x": 3,
      "y": 7,
      "z": -6,
      "name": "Rock_DarkConcrete"
    },
    {
      "x": 3,
      "y": 0,
      "z": -5,
      "name": "Rock_CastIron_Brick_Smooth"
    },
    {
      "x": 3,
      "y": 1,
      "z": -5,
      "name": "Furniture_Ancient_Barrel"
    },
    {
      "x": 3,
      "y": 2,
      "z": -5,
      "name": "Empty"
    },
    {
      "x": 3,
      "y": 3,
      "z": -5,
      "name": "Empty"
    },
    {
      "x": 3,
      "y": 4,
      "z": -5,
      "name": "Empty"
    },
    {
      "x": 3,
      "y": 5,
      "z": -5,
      "name": "Empty"
    },
    {
      "x": 3,
      "y": 6,
      "z": -5,
      "name": "Empty"
    },
    {
      "x": 3,
      "y": 7,
      "z": -5,
      "name": "Rock_DarkConcrete"
    },
    {
      "x": 3,
      "y": 0,
      "z": -4,
      "name": "Rock_CastIron_Brick_Smooth"
    },
    {
      "x": 3,
      "y": 1,
      "z": -4,
      "name": "Empty"
    },
    {
      "x": 3,
      "y": 2,
      "z": -4,
      "name": "Empty"
    },
    {
      "x": 3,
      "y": 3,
      "z": -4,
      "name": "Empty"
    },
    {
      "x": 3,
      "y": 4,
      "z": -4,
      "name": "Empty"
    },
    {
      "x": 3,
      "y": 5,
      "z": -4,
      "name": "Empty"
    },
    {
      "x": 3,
      "y": 6,
      "z": -4,
      "name": "Empty"
    },
    {
      "x": 3,
      "y": 7,
      "z": -4,
      "name": "Rock_DarkConcrete"
    },
    {
      "x": 3,
      "y": 0,
      "z": -3,
      "name": "Rock_CastIron_Brick_Smooth"
    },
    {
      "x": 3,
      "y": 1,
      "z": -3,
      "name": "Empty"
    },
    {
      "x": 3,
      "y": 2,
      "z": -3,
      "name": "Empty"
    },
    {
      "x": 3,
      "y": 3,
      "z": -3,
      "name": "Empty"
    },
    {
      "x": 3,
      "y": 4,
      "z": -3,
      "name": "Empty"
    },
    {
      "x": 3,
      "y": 5,
      "z": -3,
      "name": "Empty"
    },
    {
      "x": 3,
      "y": 6,
      "z": -3,
      "name": "Empty"
    },
    {
      "x": 3,
      "y": 7,
      "z": -3,
      "name": "Rock_DarkConcrete"
    },
    {
      "x": 3,
      "y": 0,
      "z": -2,
      "name": "Rock_CastIron_Brick_Smooth"
    },
    {
      "x": 3,
      "y": 1,
      "z": -2,
      "name": "Empty"
    },
    {
      "x": 3,
      "y": 2,
      "z": -2,
      "name": "Empty"
    },
    {
      "x": 3,
      "y": 3,
      "z": -2,
      "name": "Empty"
    },
    {
      "x": 3,
      "y": 4,
      "z": -2,
      "name": "Empty"
    },
    {
      "x": 3,
      "y": 5,
      "z": -2,
      "name": "Empty"
    },
    {
      "x": 3,
      "y": 6,
      "z": -2,
      "name": "Rock_CastIron_Brick_Stairs",
      "rotation": 9
    },
    {
      "x": 3,
      "y": 7,
      "z": -2,
      "name": "Rock_DarkConcrete"
    },
    {
      "x": 3,
      "y": 0,
      "z": -1,
      "name": "Rock_CastIron_Brick"
    },
    {
      "x": 3,
      "y": 1,
      "z": -1,
      "name": "Empty"
    },
    {
      "x": 3,
      "y": 2,
      "z": -1,
      "name": "Empty"
    },
    {
      "x": 3,
      "y": 3,
      "z": -1,
      "name": "Empty"
    },
    {
      "x": 3,
      "y": 4,
      "z": -1,
      "name": "Rock_DarkConcrete_Brick_Half",
      "rotation": 7
    },
    {
      "x": 3,
      "y": 5,
      "z": -1,
      "name": "Rock_DarkConcrete_Brick"
    },
    {
      "x": 3,
      "y": 6,
      "z": -1,
      "name": "Rock_DarkConcrete_Brick"
    },
    {
      "x": 3,
      "y": 7,
      "z": -1,
      "name": "Rock_DarkConcrete"
    },
    {
      "x": 3,
      "y": 0,
      "z": 0,
      "name": "Rock_CastIron_Brick"
    },
    {
      "x": 3,
      "y": 1,
      "z": 0,
      "name": "Rock_CastIron_Brick_Beam"
    },
    {
      "x": 3,
      "y": 2,
      "z": 0,
      "name": "Furniture_Human_Ruins_Torch",
      "rotation": 3
    },
    {
      "x": 3,
      "y": 3,
      "z": 0,
      "name": "Empty"
    },
    {
      "x": 3,
      "y": 4,
      "z": 0,
      "name": "Rock_DarkConcrete_Brick_Half",
      "rotation": 7
    },
    {
      "x": 3,
      "y": 5,
      "z": 0,
      "name": "Rock_DarkConcrete_Brick"
    },
    {
      "x": 3,
      "y": 6,
      "z": 0,
      "name": "Rock_DarkConcrete_Brick"
    },
    {
      "x": 3,
      "y": 7,
      "z": 0,
      "name": "Rock_DarkConcrete"
    },
    {
      "x": 3,
      "y": 0,
      "z": 1,
      "name": "Rock_CastIron_Brick"
    },
    {
      "x": 3,
      "y": 1,
      "z": 1,
      "name": "Empty"
    },
    {
      "x": 3,
      "y": 2,
      "z": 1,
      "name": "Empty"
    },
    {
      "x": 3,
      "y": 3,
      "z": 1,
      "name": "Empty"
    },
    {
      "x": 3,
      "y": 4,
      "z": 1,
      "name": "Rock_DarkConcrete_Brick_Half",
      "rotation": 7
    },
    {
      "x": 3,
      "y": 5,
      "z": 1,
      "name": "Rock_DarkConcrete_Brick"
    },
    {
      "x": 3,
      "y": 6,
      "z": 1,
      "name": "Rock_DarkConcrete_Brick"
    },
    {
      "x": 3,
      "y": 7,
      "z": 1,
      "name": "Rock_DarkConcrete"
    },
    {
      "x": 3,
      "y": 0,
      "z": 2,
      "name": "Soil_Dirt_Cold"
    },
    {
      "x": 3,
      "y": 1,
      "z": 2,
      "name": "Empty"
    },
    {
      "x": 3,
      "y": 2,
      "z": 2,
      "name": "Empty"
    },
    {
      "x": 3,
      "y": 3,
      "z": 2,
      "name": "Empty"
    },
    {
      "x": 3,
      "y": 4,
      "z": 2,
      "name": "Empty"
    },
    {
      "x": 3,
      "y": 5,
      "z": 2,
      "name": "Empty"
    },
    {
      "x": 3,
      "y": 6,
      "z": 2,
      "name": "Rock_CastIron_Brick_Stairs",
      "rotation": 9
    },
    {
      "x": 3,
      "y": 7,
      "z": 2,
      "name": "Rock_DarkConcrete"
    },
    {
      "x": 3,
      "y": 0,
      "z": 3,
      "name": "Soil_Dirt_Cold"
    },
    {
      "x": 3,
      "y": 1,
      "z": 3,
      "name": "Plant_Bush_Dead_Twisted"
    },
    {
      "x": 3,
      "y": 2,
      "z": 3,
      "name": "Empty"
    },
    {
      "x": 3,
      "y": 3,
      "z": 3,
      "name": "Empty"
    },
    {
      "x": 3,
      "y": 4,
      "z": 3,
      "name": "Empty"
    },
    {
      "x": 3,
      "y": 5,
      "z": 3,
      "name": "Empty"
    },
    {
      "x": 3,
      "y": 6,
      "z": 3,
      "name": "Empty"
    },
    {
      "x": 3,
      "y": 7,
      "z": 3,
      "name": "Rock_DarkConcrete"
    },
    {
      "x": 3,
      "y": 0,
      "z": 4,
      "name": "Soil_Dirt_Cold"
    },
    {
      "x": 3,
      "y": 1,
      "z": 4,
      "name": "Furniture_Ancient_Barrel"
    },
    {
      "x": 3,
      "y": 2,
      "z": 4,
      "name": "Empty"
    },
    {
      "x": 3,
      "y": 3,
      "z": 4,
      "name": "Empty"
    },
    {
      "x": 3,
      "y": 4,
      "z": 4,
      "name": "Empty"
    },
    {
      "x": 3,
      "y": 5,
      "z": 4,
      "name": "Empty"
    },
    {
      "x": 3,
      "y": 6,
      "z": 4,
      "name": "Empty"
    },
    {
      "x": 3,
      "y": 7,
      "z": 4,
      "name": "Rock_DarkConcrete"
    },
    {
      "x": 3,
      "y": 0,
      "z": 5,
      "name": "Rock_CastIron_Brick_Smooth"
    },
    {
      "x": 3,
      "y": 1,
      "z": 5,
      "name": "Plant_Leaves_Wisteria_Wild",
      "support": 15
    },
    {
      "x": 3,
      "y": 2,
      "z": 5,
      "name": "Empty"
    },
    {
      "x": 3,
      "y": 3,
      "z": 5,
      "name": "Empty"
    },
    {
      "x": 3,
      "y": 4,
      "z": 5,
      "name": "Empty"
    },
    {
      "x": 3,
      "y": 5,
      "z": 5,
      "name": "Empty"
    },
    {
      "x": 3,
      "y": 6,
      "z": 5,
      "name": "Empty"
    },
    {
      "x": 3,
      "y": 7,
      "z": 5,
      "name": "Rock_DarkConcrete"
    },
    {
      "x": 3,
      "y": 0,
      "z": 6,
      "name": "Rock_CastIron_Brick_Smooth"
    },
    {
      "x": 3,
      "y": 1,
      "z": 6,
      "name": "Empty"
    },
    {
      "x": 3,
      "y": 2,
      "z": 6,
      "name": "Empty"
    },
    {
      "x": 3,
      "y": 3,
      "z": 6,
      "name": "Empty"
    },
    {
      "x": 3,
      "y": 4,
      "z": 6,
      "name": "Empty"
    },
    {
      "x": 3,
      "y": 5,
      "z": 6,
      "name": "Empty"
    },
    {
      "x": 3,
      "y": 6,
      "z": 6,
      "name": "Empty"
    },
    {
      "x": 3,
      "y": 7,
      "z": 6,
      "name": "Rock_DarkConcrete"
    },
    {
      "x": 3,
      "y": 0,
      "z": 7,
      "name": "Rock_CastIron_Brick_Smooth"
    },
    {
      "x": 3,
      "y": 1,
      "z": 7,
      "name": "Empty"
    },
    {
      "x": 3,
      "y": 2,
      "z": 7,
      "name": "Empty"
    },
    {
      "x": 3,
      "y": 3,
      "z": 7,
      "name": "Empty"
    },
    {
      "x": 3,
      "y": 4,
      "z": 7,
      "name": "Empty"
    },
    {
      "x": 3,
      "y": 5,
      "z": 7,
      "name": "Empty"
    },
    {
      "x": 3,
      "y": 6,
      "z": 7,
      "name": "Rock_CastIron_Brick_Stairs",
      "rotation": 9
    },
    {
      "x": 3,
      "y": 7,
      "z": 7,
      "name": "Rock_DarkConcrete"
    },
    {
      "x": 4,
      "y": 0,
      "z": -7,
      "name": "Rock_CastIron_Brick_Smooth"
    },
    {
      "x": 4,
      "y": 1,
      "z": -7,
      "name": "Rock_CastIron_Brick_Smooth"
    },
    {
      "x": 4,
      "y": 2,
      "z": -7,
      "name": "Rock_CastIron_Brick_Pillar_Base"
    },
    {
      "x": 4,
      "y": 3,
      "z": -7,
      "name": "Rock_CastIron_Brick_Pillar_Middle"
    },
    {
      "x": 4,
      "y": 4,
      "z": -7,
      "name": "Rock_CastIron_Brick_Pillar_Base",
      "rotation": 8
    },
    {
      "x": 4,
      "y": 5,
      "z": -7,
      "name": "Rock_CastIron_Brick"
    },
    {
      "x": 4,
      "y": 6,
      "z": -7,
      "name": "Rock_CastIron_Brick"
    },
    {
      "x": 4,
      "y": 7,
      "z": -7,
      "name": "Rock_DarkConcrete"
    },
    {
      "x": 4,
      "y": 0,
      "z": -6,
      "name": "Rock_CastIron_Brick_Smooth"
    },
    {
      "x": 4,
      "y": 1,
      "z": -6,
      "name": "Rock_CastIron_Brick_Stairs",
      "rotation": 9
    },
    {
      "x": 4,
      "y": 2,
      "z": -6,
      "name": "Empty"
    },
    {
      "x": 4,
      "y": 3,
      "z": -6,
      "name": "Empty"
    },
    {
      "x": 4,
      "y": 4,
      "z": -6,
      "name": "Empty"
    },
    {
      "x": 4,
      "y": 5,
      "z": -6,
      "name": "Rock_CastIron_Brick_Stairs",
      "rotation": 10
    },
    {
      "x": 4,
      "y": 6,
      "z": -6,
      "name": "Rock_CastIron_Brick"
    },
    {
      "x": 4,
      "y": 7,
      "z": -6,
      "name": "Rock_DarkConcrete"
    },
    {
      "x": 4,
      "y": 0,
      "z": -5,
      "name": "Rock_CastIron_Brick_Smooth"
    },
    {
      "x": 4,
      "y": 1,
      "z": -5,
      "name": "Rock_CastIron_Brick_Stairs",
      "rotation": 9
    },
    {
      "x": 4,
      "y": 2,
      "z": -5,
      "name": "Plant_Leaves_Wisteria_Wild",
      "support": 15
    },
    {
      "x": 4,
      "y": 3,
      "z": -5,
      "name": "Plant_Leaves_Wisteria_Wild",
      "support": 15
    },
    {
      "x": 4,
      "y": 4,
      "z": -5,
      "name": "Empty"
    },
    {
      "x": 4,
      "y": 5,
      "z": -5,
      "name": "Empty"
    },
    {
      "x": 4,
      "y": 6,
      "z": -5,
      "name": "Rock_CastIron_Brick"
    },
    {
      "x": 4,
      "y": 7,
      "z": -5,
      "name": "Rock_DarkConcrete"
    },
    {
      "x": 4,
      "y": 0,
      "z": -4,
      "name": "Rock_CastIron_Brick_Smooth"
    },
    {
      "x": 4,
      "y": 1,
      "z": -4,
      "name": "Rock_CastIron_Brick_Stairs",
      "rotation": 9
    },
    {
      "x": 4,
      "y": 2,
      "z": -4,
      "name": "Plant_Leaves_Wisteria_Wild",
      "support": 15
    },
    {
      "x": 4,
      "y": 3,
      "z": -4,
      "name": "Empty"
    },
    {
      "x": 4,
      "y": 4,
      "z": -4,
      "name": "Empty"
    },
    {
      "x": 4,
      "y": 5,
      "z": -4,
      "name": "Empty"
    },
    {
      "x": 4,
      "y": 6,
      "z": -4,
      "name": "Rock_CastIron_Brick"
    },
    {
      "x": 4,
      "y": 7,
      "z": -4,
      "name": "Rock_DarkConcrete"
    },
    {
      "x": 4,
      "y": 0,
      "z": -3,
      "name": "Rock_CastIron_Brick_Smooth"
    },
    {
      "x": 4,
      "y": 1,
      "z": -3,
      "name": "Rock_CastIron_Brick_Stairs",
      "rotation": 9
    },
    {
      "x": 4,
      "y": 2,
      "z": -3,
      "name": "Empty"
    },
    {
      "x": 4,
      "y": 3,
      "z": -3,
      "name": "Plant_Vine_Wall",
      "support": 15,
      "rotation": 3
    },
    {
      "x": 4,
      "y": 4,
      "z": -3,
      "name": "Empty"
    },
    {
      "x": 4,
      "y": 5,
      "z": -3,
      "name": "Rock_CastIron_Brick_Stairs",
      "rotation": 8
    },
    {
      "x": 4,
      "y": 6,
      "z": -3,
      "name": "Rock_CastIron_Brick"
    },
    {
      "x": 4,
      "y": 7,
      "z": -3,
      "name": "Rock_DarkConcrete"
    },
    {
      "x": 4,
      "y": 0,
      "z": -2,
      "name": "Rock_CastIron_Brick_Smooth"
    },
    {
      "x": 4,
      "y": 1,
      "z": -2,
      "name": "Rock_CastIron_Brick_Smooth"
    },
    {
      "x": 4,
      "y": 2,
      "z": -2,
      "name": "Rock_CastIron_Brick_Pillar_Base"
    },
    {
      "x": 4,
      "y": 3,
      "z": -2,
      "name": "Rock_CastIron_Brick_Pillar_Middle"
    },
    {
      "x": 4,
      "y": 4,
      "z": -2,
      "name": "Rock_CastIron_Brick_Pillar_Base",
      "rotation": 8
    },
    {
      "x": 4,
      "y": 5,
      "z": -2,
      "name": "Rock_CastIron_Brick"
    },
    {
      "x": 4,
      "y": 6,
      "z": -2,
      "name": "Rock_CastIron_Brick"
    },
    {
      "x": 4,
      "y": 7,
      "z": -2,
      "name": "Rock_DarkConcrete"
    },
    {
      "x": 4,
      "y": 0,
      "z": -1,
      "name": "Rock_CastIron_Brick_Smooth"
    },
    {
      "x": 4,
      "y": 1,
      "z": -1,
      "name": "Rock_DarkConcrete_Brick"
    },
    {
      "x": 4,
      "y": 2,
      "z": -1,
      "name": "Rock_DarkConcrete_Brick"
    },
    {
      "x": 4,
      "y": 3,
      "z": -1,
      "name": "Rock_DarkConcrete_Brick"
    },
    {
      "x": 4,
      "y": 4,
      "z": -1,
      "name": "Rock_DarkConcrete_Brick"
    },
    {
      "x": 4,
      "y": 5,
      "z": -1,
      "name": "Rock_DarkConcrete_Brick"
    },
    {
      "x": 4,
      "y": 6,
      "z": -1,
      "name": "Rock_DarkConcrete_Brick"
    },
    {
      "x": 4,
      "y": 7,
      "z": -1,
      "name": "Rock_DarkConcrete"
    },
    {
      "x": 4,
      "y": 0,
      "z": 0,
      "name": "Rock_CastIron_Brick_Smooth"
    },
    {
      "x": 4,
      "y": 1,
      "z": 0,
      "name": "Rock_DarkConcrete_Brick"
    },
    {
      "x": 4,
      "y": 2,
      "z": 0,
      "name": "Rock_DarkConcrete_Brick"
    },
    {
      "x": 4,
      "y": 3,
      "z": 0,
      "name": "Rock_DarkConcrete_Brick"
    },
    {
      "x": 4,
      "y": 4,
      "z": 0,
      "name": "Rock_DarkConcrete_Brick"
    },
    {
      "x": 4,
      "y": 5,
      "z": 0,
      "name": "Rock_DarkConcrete_Brick"
    },
    {
      "x": 4,
      "y": 6,
      "z": 0,
