{
  "version": 8,
  "blockIdVersion": 11,
  "anchorX": 0,
  "anchorY": 134,
  "anchorZ": 6,
  "blocks": [
    {
      "x": -96,
      "y": 150,
      "z": -246,
      "name": "Rock_Shale"
    },
    {
      "x": -96,
      "y": 150,
      "z": -245,
      "name": "Rock_Shale"
    },
    {
      "x": -96,
      "y": 150,
      "z": -244,
      "name": "Rock_Shale"
    },
    {
      "x": -96,
      "y": 150,
      "z": -243,
      "name": "Rock_Shale"
    },
    {
      "x": -96,
      "y": 150,
      "z": -242,
      "name": "Rock_Shale"
    },
    {
      "x": -96,
      "y": 150,
      "z": -241,
      "name": "Rock_Shale"
    },
    {
      "x": -96,
      "y": 150,
      "z": -240,
      "name": "Rock_Shale"
    },
    {
      "x": -96,
      "y": 150,
      "z": -239,
      "name": "Rock_Shale"
    },
    {
      "x": -96,
      "y": 150,
      "z": -238,
      "name": "Rock_Shale"
    },
    {
      "x": -96,
      "y": 150,
      "z": -237,
      "name": "Rock_Shale"
    },
    {
      "x": -96,
      "y": 150,
      "z": -236,
      "name": "Rock_Shale"
    },
    {
      "x": -96,
      "y": 150,
      "z": -235,
      "name": "Rock_Shale"
    },
    {
      "x": -96,
      "y": 150,
      "z": -234,
      "name": "Rock_Shale"
    },
    {
      "x": -96,
      "y": 150,
      "z": -233,
      "name": "Rock_Shale"
    },
    {
      "x": -96,
      "y": 150,
      "z": -232,
      "name": "Rock_Shale"
    },
    {
      "x": -96,
      "y": 150,
      "z": -231,
      "name": "Rock_Shale"
    },
    {
      "x": -96,
      "y": 150,
      "z": -230,
      "name": "Rock_Shale"
    },
    {
      "x": -96,
      "y": 150,
      "z": -229,
      "name": "Rock_Shale"
    },
    {
      "x": -96,
      "y": 150,
      "z": -228,
      "name": "Rock_Shale"
    },
    {
      "x": -96,
      "y": 150,
      "z": -227,
      "name": "Rock_Shale"
    },
    {
      "x": -96,
      "y": 150,
      "z": -226,
      "name": "Rock_Shale"
    },
    {
      "x": -96,
      "y": 150,
      "z": -225,
      "name": "Rock_Shale"
    },
    {
      "x": -96,
      "y": 150,
      "z": -224,
      "name": "Rock_Shale"
    },
    {
      "x": -96,
      "y": 150,
      "z": -223,
      "name": "Rock_Shale"
    },
    {
      "x": -96,
      "y": 150,
      "z": -222,
      "name": "Rock_Shale"
    },
    {
      "x": -96,
      "y": 150,
      "z": -221,
      "name": "Rock_Shale"
    },
    {
      "x": -96,
      "y": 150,
      "z": -220,
      "name": "Rock_Shale"
    },
    {
      "x": -96,
      "y": 150,
      "z": -219,
      "name": "Rock_Shale"
    },
    {
      "x": -96,
      "y": 150,
      "z": -218,
      "name": "Rock_Shale"
    },
    {
      "x": -96,
      "y": 150,
      "z": -217,
      "name": "Rock_Shale"
    },
    {
      "x": -96,
      "y": 150,
      "z": -216,
      "name": "Rock_Shale"
    },
    {
      "x": -96,
      "y": 150,
      "z": -215,
      "name": "Rock_Shale"
    },
    {
      "x": -96,
      "y": 150,
      "z": -214,
      "name": "Rock_Shale"
    },
    {
      "x": -96,
      "y": 150,
      "z": -213,
      "name": "Rock_Shale"
    },
    {
      "x": -96,
      "y": 150,
      "z": -212,
      "name": "Rock_Shale"
    },
    {
      "x": -96,
      "y": 150,
      "z": -211,
      "name": "Rock_Shale"
    },
    {
      "x": -96,
      "y": 150,
      "z": -210,
      "name": "Rock_Shale"
    },
    {
      "x": -96,
      "y": 150,
      "z": -209,
      "name": "Rock_Shale"
    },
    {
      "x": -96,
      "y": 150,
      "z": -208,
      "name": "Rock_Shale"
    },
    {
      "x": -96,
      "y": 150,
      "z": -207,
      "name": "Rock_Shale"
    },
    {
      "x": -96,
      "y": 150,
      "z": -206,
      "name": "Rock_Shale"
    },
    {
      "x": -96,
      "y": 150,
      "z": -205,
      "name": "Rock_Shale"
    },
    {
      "x": -96,
      "y": 150,
      "z": -204,
      "name": "Rock_Shale"
    },
    {
      "x": -96,
      "y": 150,
      "z": -203,
      "name": "Rock_Shale"
    },
    {
      "x": -96,
      "y": 150,
      "z": -202,
      "name": "Rock_Shale"
    },
    {
      "x": -96,
      "y": 150,
      "z": -201,
      "name": "Rock_Shale"
    },
    {
      "x": -96,
      "y": 150,
      "z": -200,
      "name": "Rock_Shale"
    },
    {
      "x": -96,
      "y": 150,
      "z": -199,
      "name": "Rock_Shale"
    },
    {
      "x": -96,
      "y": 150,
      "z": -198,
      "name": "Rock_Shale"
    },
    {
      "x": -96,
      "y": 150,
      "z": -197,
      "name": "Rock_Shale"
    },
    {
      "x": -96,
      "y": 150,
      "z": -196,
      "name": "Rock_Shale"
    },
    {
      "x": -96,
      "y": 150,
      "z": -195,
      "name": "Rock_Shale"
    },
    {
      "x": -96,
      "y": 150,
      "z": -194,
      "name": "Rock_Shale"
    },
    {
      "x": -96,
      "y": 150,
      "z": -193,
      "name": "Rock_Shale"
    },
    {
      "x": -96,
      "y": 150,
      "z": -192,
      "name": "Rock_Shale"
    },
    {
      "x": -96,
      "y": 150,
      "z": -191,
      "name": "Rock_Shale"
    },
    {
      "x": -96,
      "y": 150,
      "z": -190,
      "name": "Rock_Shale"
    },
    {
      "x": -96,
      "y": 150,
      "z": -189,
      "name": "Rock_Shale"
    },
    {
      "x": -96,
      "y": 150,
      "z": -188,
      "name": "Rock_Shale"
    },
    {
      "x": -96,
      "y": 150,
      "z": -187,
      "name": "Rock_Shale"
    },
    {
      "x": -96,
      "y": 150,
      "z": -186,
      "name": "Rock_Shale"
    },
    {
      "x": -96,
      "y": 150,
      "z": -185,
      "name": "Rock_Shale"
    },
    {
      "x": -96,
      "y": 150,
      "z": -184,
      "name": "Rock_Shale"
    },
    {
      "x": -96,
      "y": 150,
      "z": -183,
      "name": "Rock_Shale"
    },
    {
      "x": -96,
      "y": 150,
      "z": -182,
      "name": "Rock_Shale"
    },
    {
      "x": -96,
      "y": 150,
      "z": -181,
      "name": "Rock_Shale"
    },
    {
      "x": -96,
      "y": 150,
      "z": -180,
      "name": "Rock_Shale"
    },
    {
      "x": -96,
      "y": 150,
      "z": -179,
      "name": "Rock_Shale"
    },
    {
      "x": -96,
      "y": 150,
      "z": -178,
      "name": "Rock_Shale"
    },
    {
      "x": -96,
      "y": 150,
      "z": -177,
      "name": "Rock_Shale"
    },
    {
      "x": -96,
      "y": 150,
      "z": -176,
      "name": "Rock_Shale"
    },
    {
      "x": -96,
      "y": 150,
      "z": -175,
      "name": "Rock_Shale"
    },
    {
      "x": -96,
      "y": 150,
      "z": -174,
      "name": "Rock_Shale"
    },
    {
      "x": -96,
      "y": 150,
      "z": -173,
      "name": "Rock_Shale"
    },
    {
      "x": -96,
      "y": 150,
      "z": -172,
      "name": "Rock_Shale"
    },
    {
      "x": -96,
      "y": 150,
      "z": -171,
      "name": "Rock_Shale"
    },
    {
      "x": -96,
      "y": 150,
      "z": -170,
      "name": "Rock_Shale"
    },
    {
      "x": -96,
      "y": 150,
      "z": -169,
      "name": "Rock_Shale"
    },
    {
      "x": -96,
      "y": 150,
      "z": -168,
      "name": "Rock_Shale"
    },
    {
      "x": -96,
      "y": 150,
      "z": -167,
      "name": "Rock_Shale"
    },
    {
      "x": -96,
      "y": 150,
      "z": -166,
      "name": "Rock_Shale"
    },
    {
      "x": -96,
      "y": 150,
      "z": -165,
      "name": "Rock_Shale"
    },
    {
      "x": -96,
      "y": 150,
      "z": -164,
      "name": "Rock_Shale"
    },
    {
      "x": -96,
      "y": 150,
      "z": -163,
      "name": "Rock_Shale"
    },
    {
      "x": -96,
      "y": 150,
      "z": -162,
      "name": "Rock_Shale"
    },
    {
      "x": -96,
      "y": 150,
      "z": -161,
      "name": "Rock_Shale"
    },
    {
      "x": -96,
      "y": 150,
      "z": -160,
      "name": "Rock_Shale"
    },
    {
      "x": -96,
      "y": 150,
      "z": -159,
      "name": "Rock_Shale"
    },
    {
      "x": -96,
      "y": 150,
      "z": -158,
      "name": "Rock_Shale"
    },
    {
      "x": -96,
      "y": 150,
      "z": -157,
      "name": "Rock_Shale"
    },
    {
      "x": -96,
      "y": 150,
      "z": -156,
      "name": "Rock_Shale"
    },
    {
      "x": -96,
      "y": 150,
      "z": -155,
      "name": "Rock_Shale"
    },
    {
      "x": -96,
      "y": 150,
      "z": -154,
      "name": "Rock_Shale"
    },
    {
      "x": -96,
      "y": 150,
      "z": -153,
      "name": "Rock_Shale"
    },
    {
      "x": -96,
      "y": 150,
      "z": -152,
      "name": "Rock_Shale"
    },
    {
      "x": -96,
      "y": 150,
      "z": -151,
      "name": "Rock_Shale"
    },
    {
      "x": -96,
      "y": 150,
      "z": -150,
      "name": "Rock_Shale"
    },
    {
      "x": -96,
      "y": 150,
      "z": -149,
      "name": "Rock_Shale"
    },
    {
      "x": -96,
      "y": 150,
      "z": -148,
      "name": "Rock_Shale"
    },
    {
      "x": -96,
      "y": 150,
      "z": -147,
      "name": "Rock_Shale"
    },
    {
      "x": -96,
      "y": 150,
      "z": -146,
      "name": "Rock_Shale"
    },
    {
      "x": -96,
      "y": 150,
      "z": -145,
      "name": "Rock_Shale"
    },
    {
      "x": -96,
      "y": 150,
      "z": -144,
      "name": "Rock_Shale"
    },
    {
      "x": -96,
      "y": 150,
      "z": -143,
      "name": "Rock_Shale"
    },
    {
      "x": -96,
      "y": 150,
      "z": -142,
      "name": "Rock_Shale"
    },
    {
      "x": -96,
      "y": 150,
      "z": -141,
      "name": "Rock_Shale"
    },
    {
      "x": -96,
      "y": 150,
      "z": -140,
      "name": "Rock_Shale"
    },
    {
      "x": -96,
      "y": 150,
      "z": -139,
      "name": "Rock_Shale"
    },
    {
      "x": -96,
      "y": 150,
      "z": -138,
      "name": "Rock_Shale"
    },
    {
      "x": -96,
      "y": 150,
      "z": -137,
      "name": "Rock_Shale"
    },
    {
      "x": -96,
      "y": 150,
      "z": -136,
      "name": "Rock_Shale"
    },
    {
      "x": -96,
      "y": 150,
      "z": -135,
      "name": "Rock_Shale"
    },
    {
      "x": -96,
      "y": 150,
      "z": -134,
      "name": "Rock_Shale"
    },
    {
      "x": -96,
      "y": 150,
      "z": -133,
      "name": "Rock_Shale"
    },
    {
      "x": -96,
      "y": 150,
      "z": -132,
      "name": "Rock_Shale"
    },
    {
      "x": -96,
      "y": 150,
      "z": -131,
      "name": "Rock_Shale"
    },
    {
      "x": -96,
      "y": 150,
      "z": -130,
      "name": "Rock_Shale"
    },
    {
      "x": -96,
      "y": 150,
      "z": -129,
      "name": "Rock_Shale"
    },
    {
      "x": -96,
      "y": 150,
      "z": -128,
      "name": "Rock_Shale"
    },
    {
      "x": -96,
      "y": 150,
      "z": -127,
      "name": "Rock_Shale"
    },
    {
      "x": -96,
      "y": 150,
      "z": -126,
      "name": "Rock_Shale"
    },
    {
      "x": -96,
      "y": 150,
      "z": -125,
      "name": "Rock_Shale"
    },
    {
      "x": -96,
      "y": 150,
      "z": -124,
      "name": "Rock_Shale"
    },
    {
      "x": -96,
      "y": 150,
      "z": -123,
      "name": "Rock_Shale"
    },
    {
      "x": -96,
      "y": 150,
      "z": -122,
      "name": "Rock_Shale"
    },
    {
      "x": -96,
      "y": 150,
      "z": -121,
      "name": "Rock_Shale"
    },
    {
      "x": -96,
      "y": 150,
      "z": -120,
      "name": "Rock_Shale"
    },
    {
      "x": -96,
      "y": 150,
      "z": -119,
      "name": "Rock_Shale"
    },
    {
      "x": -96,
      "y": 150,
      "z": -118,
      "name": "Rock_Shale"
    },
    {
      "x": -96,
      "y": 150,
      "z": -117,
      "name": "Rock_Shale"
    },
    {
      "x": -96,
      "y": 150,
      "z": -116,
      "name": "Rock_Shale"
    },
    {
      "x": -96,
      "y": 150,
      "z": -115,
      "name": "Rock_Shale"
    },
    {
      "x": -96,
      "y": 150,
      "z": -114,
      "name": "Rock_Shale"
    },
    {
      "x": -96,
      "y": 150,
      "z": -113,
      "name": "Rock_Shale"
    },
    {
      "x": -96,
      "y": 150,
      "z": -112,
      "name": "Rock_Shale"
    },
    {
      "x": -96,
      "y": 150,
      "z": -111,
      "name": "Rock_Shale"
    },
    {
      "x": -96,
      "y": 150,
      "z": -110,
      "name": "Rock_Shale"
    },
    {
      "x": -96,
      "y": 150,
      "z": -109,
      "name": "Rock_Shale"
    },
    {
      "x": -96,
      "y": 150,
      "z": -108,
      "name": "Rock_Shale"
    },
    {
      "x": -96,
      "y": 150,
      "z": -107,
      "name": "Rock_Shale"
    },
    {
      "x": -96,
      "y": 150,
      "z": -106,
      "name": "Rock_Shale"
    },
    {
      "x": -96,
      "y": 150,
      "z": -105,
      "name": "Rock_Shale"
    },
    {
      "x": -96,
      "y": 150,
      "z": -104,
      "name": "Rock_Shale"
    },
    {
      "x": -96,
      "y": 150,
      "z": -103,
      "name": "Rock_Shale"
    },
    {
      "x": -96,
      "y": 150,
      "z": -102,
      "name": "Rock_Shale"
    },
    {
      "x": -96,
      "y": 150,
      "z": -101,
      "name": "Rock_Shale"
    },
    {
      "x": -96,
      "y": 150,
      "z": -100,
      "name": "Rock_Shale"
    },
    {
      "x": -96,
      "y": 150,
      "z": -99,
      "name": "Rock_Shale"
    },
    {
      "x": -96,
      "y": 150,
      "z": -98,
      "name": "Rock_Shale"
    },
    {
      "x": -96,
      "y": 150,
      "z": -97,
      "name": "Rock_Shale"
    },
    {
      "x": -96,
      "y": 150,
      "z": -96,
      "name": "Rock_Shale"
    },
    {
      "x": -96,
      "y": 150,
      "z": -95,
      "name": "Rock_Shale"
    },
    {
      "x": -96,
      "y": 150,
      "z": -94,
      "name": "Rock_Shale"
    },
    {
      "x": -96,
      "y": 150,
      "z": -93,
      "name": "Rock_Shale"
    },
    {
      "x": -96,
      "y": 150,
      "z": -92,
      "name": "Rock_Shale"
    },
    {
      "x": -96,
      "y": 150,
      "z": -91,
      "name": "Rock_Shale"
    },
    {
      "x": -96,
      "y": 150,
      "z": -90,
      "name": "Rock_Shale"
    },
    {
      "x": -96,
      "y": 150,
      "z": -89,
      "name": "Rock_Shale"
    },
    {
      "x": -96,
      "y": 150,
      "z": -88,
      "name": "Rock_Shale"
    },
    {
      "x": -96,
      "y": 150,
      "z": -87,
      "name": "Rock_Shale"
    },
    {
      "x": -96,
      "y": 150,
      "z": -86,
      "name": "Rock_Shale"
    },
    {
      "x": -96,
      "y": 150,
      "z": -85,
      "name": "Rock_Shale"
    },
    {
      "x": -96,
      "y": 150,
      "z": -84,
      "name": "Rock_Shale"
    },
    {
      "x": -96,
      "y": 150,
      "z": -83,
      "name": "Rock_Shale"
    },
    {
      "x": -96,
      "y": 150,
      "z": -82,
      "name": "Rock_Shale"
    },
    {
      "x": -96,
      "y": 150,
      "z": -81,
      "name": "Rock_Shale"
    },
    {
      "x": -96,
      "y": 150,
      "z": -80,
      "name": "Rock_Shale"
    },
    {
      "x": -96,
      "y": 150,
      "z": -79,
      "name": "Rock_Shale"
    },
    {
      "x": -96,
      "y": 150,
      "z": -78,
      "name": "Rock_Shale"
    },
    {
      "x": -96,
      "y": 150,
      "z": -77,
      "name": "Rock_Shale"
    },
    {
      "x": -96,
      "y": 150,
      "z": -76,
      "name": "Rock_Shale"
    },
    {
      "x": -96,
      "y": 150,
      "z": -75,
      "name": "Rock_Shale"
    },
    {
      "x": -96,
      "y": 150,
      "z": -74,
      "name": "Rock_Shale"
    },
    {
      "x": -96,
      "y": 150,
      "z": -73,
      "name": "Rock_Shale"
    },
    {
      "x": -96,
      "y": 150,
      "z": -72,
      "name": "Rock_Shale"
    },
    {
      "x": -96,
      "y": 150,
      "z": -71,
      "name": "Rock_Shale"
    },
    {
      "x": -96,
      "y": 150,
      "z": -70,
      "name": "Rock_Shale"
    },
    {
      "x": -96,
      "y": 150,
      "z": -69,
      "name": "Rock_Shale"
    },
    {
      "x": -96,
      "y": 150,
      "z": -68,
      "name": "Rock_Shale"
    },
    {
      "x": -96,
      "y": 150,
      "z": -67,
      "name": "Rock_Shale"
    },
    {
      "x": -96,
      "y": 150,
      "z": -66,
      "name": "Rock_Shale"
    },
    {
      "x": -96,
      "y": 150,
      "z": -65,
      "name": "Rock_Shale"
    },
    {
      "x": -96,
      "y": 150,
      "z": -64,
      "name": "Rock_Shale"
    },
    {
      "x": -96,
      "y": 150,
      "z": -63,
      "name": "Rock_Shale"
    },
    {
      "x": -96,
      "y": 150,
      "z": -62,
      "name": "Rock_Shale"
    },
    {
      "x": -96,
      "y": 150,
      "z": -61,
      "name": "Rock_Shale"
    },
    {
      "x": -96,
      "y": 150,
      "z": -60,
      "name": "Rock_Shale"
    },
    {
      "x": -96,
      "y": 150,
      "z": -59,
      "name": "Rock_Shale"
    },
    {
      "x": -96,
      "y": 150,
      "z": -58,
      "name": "Rock_Shale"
    },
    {
      "x": -96,
      "y": 150,
      "z": -57,
      "name": "Rock_Shale"
    },
    {
      "x": -96,
      "y": 150,
      "z": -56,
      "name": "Rock_Shale"
    },
    {
      "x": -96,
      "y": 150,
      "z": -55,
      "name": "Rock_Shale"
    },
    {
      "x": -96,
      "y": 150,
      "z": -54,
      "name": "Rock_Shale"
    },
    {
      "x": -96,
      "y": 150,
      "z": -53,
      "name": "Rock_Shale"
    },
    {
      "x": -96,
      "y": 150,
      "z": -52,
      "name": "Rock_Shale"
    },
    {
      "x": -96,
      "y": 150,
      "z": -51,
      "name": "Rock_Shale"
    },
    {
      "x": -96,
      "y": 150,
      "z": -50,
      "name": "Rock_Shale"
    },
    {
      "x": -96,
      "y": 150,
      "z": -49,
      "name": "Rock_Shale"
    },
    {
      "x": -96,
      "y": 150,
      "z": -48,
      "name": "Rock_Shale"
    },
    {
      "x": -96,
      "y": 150,
      "z": -47,
      "name": "Rock_Shale"
    },
    {
      "x": -96,
      "y": 150,
      "z": -46,
      "name": "Rock_Shale"
    },
    {
      "x": -96,
      "y": 150,
      "z": -45,
      "name": "Rock_Shale"
    },
    {
      "x": -96,
      "y": 150,
      "z": -44,
      "name": "Rock_Shale"
    },
    {
      "x": -96,
      "y": 150,
      "z": -43,
      "name": "Rock_Shale"
    },
    {
      "x": -96,
      "y": 150,
      "z": -42,
      "name": "Rock_Shale"
    },
    {
      "x": -96,
      "y": 150,
      "z": -41,
      "name": "Rock_Shale"
    },
    {
      "x": -96,
      "y": 150,
      "z": -40,
      "name": "Rock_Shale"
    },
    {
      "x": -96,
      "y": 150,
      "z": -39,
      "name": "Rock_Shale"
    },
    {
      "x": -96,
      "y": 150,
      "z": -38,
      "name": "Rock_Shale"
    },
    {
      "x": -96,
      "y": 150,
      "z": -37,
      "name": "Rock_Shale"
    },
    {
      "x": -96,
      "y": 150,
      "z": -36,
      "name": "Rock_Shale"
    },
    {
      "x": -96,
      "y": 150,
      "z": -35,
      "name": "Rock_Shale"
    },
    {
      "x": -96,
      "y": 150,
      "z": -34,
      "name": "Rock_Shale"
    },
    {
      "x": -96,
      "y": 150,
      "z": -33,
      "name": "Rock_Shale"
    },
    {
      "x": -96,
      "y": 150,
      "z": -32,
      "name": "Rock_Shale"
    },
    {
      "x": -96,
      "y": 150,
      "z": -31,
      "name": "Rock_Shale"
    },
    {
      "x": -96,
      "y": 150,
      "z": -30,
      "name": "Rock_Shale"
    },
    {
      "x": -96,
      "y": 150,
      "z": -29,
      "name": "Rock_Shale"
    },
    {
      "x": -96,
      "y": 150,
      "z": -28,
      "name": "Rock_Shale"
    },
    {
      "x": -96,
      "y": 150,
      "z": -27,
      "name": "Rock_Shale"
    },
    {
      "x": -96,
      "y": 150,
      "z": -26,
      "name": "Rock_Shale"
    },
    {
      "x": -96,
      "y": 150,
      "z": -25,
      "name": "Rock_Shale"
    },
    {
      "x": -96,
      "y": 150,
      "z": -24,
      "name": "Rock_Shale"
    },
    {
      "x": -96,
      "y": 150,
      "z": -23,
      "name": "Rock_Shale"
    },
    {
      "x": -96,
      "y": 150,
      "z": -22,
      "name": "Rock_Shale"
    },
    {
      "x": -96,
      "y": 150,
      "z": -21,
      "name": "Rock_Shale"
    },
    {
      "x": -96,
      "y": 150,
      "z": -20,
      "name": "Rock_Shale"
    },
    {
      "x": -96,
      "y": 150,
      "z": -19,
      "name": "Rock_Shale"
    },
    {
      "x": -96,
      "y": 150,
      "z": -18,
      "name": "Rock_Shale"
    },
    {
      "x": -96,
      "y": 150,
      "z": -17,
      "name": "Rock_Shale"
    },
    {
      "x": -96,
      "y": 150,
      "z": -16,
      "name": "Rock_Shale"
    },
    {
      "x": -96,
      "y": 150,
      "z": -15,
      "name": "Rock_Shale"
    },
    {
      "x": -96,
      "y": 150,
      "z": -14,
      "name": "Rock_Shale"
    },
    {
      "x": -96,
      "y": 150,
      "z": -13,
      "name": "Rock_Shale"
    },
    {
      "x": -96,
      "y": 150,
      "z": -12,
      "name": "Rock_Shale"
    },
    {
      "x": -96,
      "y": 150,
      "z": -11,
      "name": "Rock_Shale"
    },
    {
      "x": -96,
      "y": 150,
      "z": -10,
      "name": "Rock_Shale"
    },
    {
      "x": -96,
      "y": 150,
      "z": -9,
      "name": "Rock_Shale"
    },
    {
      "x": -96,
      "y": 150,
      "z": -8,
      "name": "Rock_Shale"
    },
    {
      "x": -96,
      "y": 150,
      "z": -7,
      "name": "Rock_Shale"
    },
    {
      "x": -96,
      "y": 150,
      "z": -6,
      "name": "Rock_Shale"
    },
    {
      "x": -96,
      "y": 150,
      "z": -5,
      "name": "Rock_Shale"
    },
    {
      "x": -96,
      "y": 150,
      "z": -4,
      "name": "Rock_Shale"
    },
    {
      "x": -96,
      "y": 150,
      "z": -3,
      "name": "Rock_Shale"
    },
    {
      "x": -96,
      "y": 150,
      "z": -2,
      "name": "Rock_Shale"
    },
    {
      "x": -96,
      "y": 150,
      "z": -1,
      "name": "Rock_Shale"
    },
    {
      "x": -96,
      "y": 150,
      "z": 0,
      "name": "Rock_Shale"
    },
    {
      "x": -96,
      "y": 150,
      "z": 1,
      "name": "Rock_Shale"
    },
    {
      "x": -96,
      "y": 150,
      "z": 2,
      "name": "Rock_Shale"
    },
    {
      "x": -96,
      "y": 150,
      "z": 3,
      "name": "Rock_Shale"
    },
    {
      "x": -96,
      "y": 150,
      "z": 4,
      "name": "Rock_Shale"
    },
    {
      "x": -96,
      "y": 150,
      "z": 5,
      "name": "Rock_Shale"
    },
    {
      "x": -96,
      "y": 150,
      "z": 6,
      "name": "Rock_Shale"
    },
    {
      "x": -96,
      "y": 150,
      "z": 7,
      "name": "Rock_Shale"
    },
    {
      "x": -96,
      "y": 150,
      "z": 8,
      "name": "Rock_Shale"
    },
    {
      "x": -96,
      "y": 150,
      "z": 9,
      "name": "Rock_Shale"
    },
    {
      "x": -96,
      "y": 150,
      "z": 10,
      "name": "Rock_Shale"
    },
    {
      "x": -96,
      "y": 150,
      "z": 11,
      "name": "Rock_Shale"
    },
    {
      "x": -96,
      "y": 150,
      "z": 12,
      "name": "Rock_Shale"
    },
    {
      "x": -96,
      "y": 150,
      "z": 13,
      "name": "Rock_Shale"
    },
    {
      "x": -96,
      "y": 150,
      "z": 14,
      "name": "Rock_Shale"
    },
    {
      "x": -96,
      "y": 150,
      "z": 15,
      "name": "Rock_Shale"
    },
    {
      "x": -96,
      "y": 150,
      "z": 16,
      "name": "Rock_Shale"
    },
    {
      "x": -96,
      "y": 150,
      "z": 17,
      "name": "Rock_Shale"
    },
    {
      "x": -96,
      "y": 150,
      "z": 18,
      "name": "Rock_Shale"
    },
    {
      "x": -96,
      "y": 150,
      "z": 19,
      "name": "Rock_Shale"
    },
    {
      "x": -96,
      "y": 150,
      "z": 20,
      "name": "Rock_Shale"
    },
    {
      "x": -96,
      "y": 150,
      "z": 21,
      "name": "Rock_Shale"
    },
    {
      "x": -96,
      "y": 150,
      "z": 22,
      "name": "Rock_Shale"
    },
    {
      "x": -96,
      "y": 150,
      "z": 23,
      "name": "Rock_Shale"
    },
    {
      "x": -96,
      "y": 150,
      "z": 24,
      "name": "Rock_Shale"
    },
    {
      "x": -96,
      "y": 150,
      "z": 25,
      "name": "Rock_Shale"
    },
    {
      "x": -96,
      "y": 150,
      "z": 26,
      "name": "Rock_Shale"
    },
    {
      "x": -96,
      "y": 150,
      "z": 27,
      "name": "Rock_Shale"
    },
    {
      "x": -96,
      "y": 150,
      "z": 28,
      "name": "Rock_Shale"
    },
    {
      "x": -96,
      "y": 150,
      "z": 29,
      "name": "Rock_Shale"
    },
    {
      "x": -96,
      "y": 150,
      "z": 30,
      "name": "Rock_Shale"
    },
    {
      "x": -96,
      "y": 150,
      "z": 31,
      "name": "Rock_Shale"
    },
    {
      "x": -96,
      "y": 150,
      "z": 32,
      "name": "Rock_Shale"
    },
    {
      "x": -96,
      "y": 150,
      "z": 33,
      "name": "Rock_Shale"
    },
    {
      "x": -96,
      "y": 150,
      "z": 34,
      "name": "Rock_Shale"
    },
    {
      "x": -96,
      "y": 150,
      "z": 35,
      "name": "Rock_Shale"
    },
    {
      "x": -96,
      "y": 150,
      "z": 36,
      "name": "Rock_Shale"
    },
    {
      "x": -96,
      "y": 150,
      "z": 37,
      "name": "Rock_Shale"
    },
    {
      "x": -96,
      "y": 150,
      "z": 38,
      "name": "Rock_Shale"
    },
    {
      "x": -96,
      "y": 150,
      "z": 39,
      "name": "Rock_Shale"
    },
    {
      "x": -96,
      "y": 150,
      "z": 40,
      "name": "Rock_Shale"
    },
    {
      "x": -96,
      "y": 150,
      "z": 41,
      "name": "Rock_Shale"
    },
    {
      "x": -96,
      "y": 150,
      "z": 42,
      "name": "Rock_Shale"
    },
    {
      "x": -96,
      "y": 150,
      "z": 43,
      "name": "Rock_Shale"
    },
    {
      "x": -96,
      "y": 150,
      "z": 44,
      "name": "Rock_Shale"
    },
    {
      "x": -96,
      "y": 150,
      "z": 45,
      "name": "Rock_Shale"
    },
    {
      "x": -96,
      "y": 150,
      "z": 46,
      "name": "Rock_Shale"
    },
    {
      "x": -96,
      "y": 150,
      "z": 47,
      "name": "Rock_Shale"
    },
    {
      "x": -96,
      "y": 150,
      "z": 48,
      "name": "Rock_Shale"
    },
    {
      "x": -95,
      "y": 150,
      "z": -246,
      "name": "Rock_Shale"
    },
    {
      "x": -95,
      "y": 150,
      "z": 48,
      "name": "Rock_Shale"
    },
    {
      "x": -94,
      "y": 150,
      "z": -246,
      "name": "Rock_Shale"
    },
    {
      "x": -94,
      "y": 150,
      "z": 48,
      "name": "Rock_Shale"
    },
    {
      "x": -93,
      "y": 150,
      "z": -246,
      "name": "Rock_Shale"
    },
    {
      "x": -93,
      "y": 150,
      "z": 48,
      "name": "Rock_Shale"
    },
    {
      "x": -92,
      "y": 150,
      "z": -246,
      "name": "Rock_Shale"
    },
    {
      "x": -92,
      "y": 150,
      "z": 48,
      "name": "Rock_Shale"
    },
    {
      "x": -91,
      "y": 150,
      "z": -246,
      "name": "Rock_Shale"
    },
    {
      "x": -91,
      "y": 150,
      "z": 48,
      "name": "Rock_Shale"
    },
    {
      "x": -90,
      "y": 150,
      "z": -246,
      "name": "Rock_Shale"
    },
    {
      "x": -90,
      "y": 150,
      "z": 48,
      "name": "Rock_Shale"
    },
    {
      "x": -89,
      "y": 150,
      "z": -246,
      "name": "Rock_Shale"
    },
    {
      "x": -89,
      "y": 150,
      "z": 48,
      "name": "Rock_Shale"
    },
    {
      "x": -88,
      "y": 150,
      "z": -246,
      "name": "Rock_Shale"
    },
    {
      "x": -88,
      "y": 150,
      "z": 48,
      "name": "Rock_Shale"
    },
    {
      "x": -87,
      "y": 150,
      "z": -246,
      "name": "Rock_Shale"
    },
    {
      "x": -87,
      "y": 150,
      "z": 48,
      "name": "Rock_Shale"
    },
    {
      "x": -86,
      "y": 150,
      "z": -246,
      "name": "Rock_Shale"
    },
    {
      "x": -86,
      "y": 150,
      "z": 48,
      "name": "Rock_Shale"
    },
    {
      "x": -85,
      "y": 150,
      "z": -246,
      "name": "Rock_Shale"
    },
    {
      "x": -85,
      "y": 150,
      "z": 48,
      "name": "Rock_Shale"
    },
    {
      "x": -84,
      "y": 150,
      "z": -246,
      "name": "Rock_Shale"
    },
    {
      "x": -84,
      "y": 150,
      "z": 48,
      "name": "Rock_Shale"
    },
    {
      "x": -83,
      "y": 150,
      "z": -246,
      "name": "Rock_Shale"
    },
    {
      "x": -83,
      "y": 150,
      "z": 48,
      "name": "Rock_Shale"
    },
    {
      "x": -82,
      "y": 150,
      "z": -246,
      "name": "Rock_Shale"
    },
    {
      "x": -82,
      "y": 150,
      "z": 48,
      "name": "Rock_Shale"
    },
    {
      "x": -81,
      "y": 150,
      "z": -246,
      "name": "Rock_Shale"
    },
    {
      "x": -81,
      "y": 150,
      "z": 48,
      "name": "Rock_Shale"
    },
    {
      "x": -80,
      "y": 150,
      "z": -246,
      "name": "Rock_Shale"
    },
    {
      "x": -80,
      "y": 150,
      "z": 48,
      "name": "Rock_Shale"
    },
    {
      "x": -79,
      "y": 150,
      "z": -246,
      "name": "Rock_Shale"
    },
    {
      "x": -79,
      "y": 150,
      "z": 48,
      "name": "Rock_Shale"
    },
    {
      "x": -78,
      "y": 150,
      "z": -246,
      "name": "Rock_Shale"
    },
    {
      "x": -78,
      "y": 150,
      "z": 48,
      "name": "Rock_Shale"
    },
    {
      "x": -77,
      "y": 150,
      "z": -246,
      "name": "Rock_Shale"
    },
    {
      "x": -77,
      "y": 150,
      "z": 48,
      "name": "Rock_Shale"
    },
    {
      "x": -76,
      "y": 150,
      "z": -246,
      "name": "Rock_Shale"
    },
    {
      "x": -76,
      "y": 150,
      "z": 48,
      "name": "Rock_Shale"
    },
    {
      "x": -75,
      "y": 150,
      "z": -246,
      "name": "Rock_Shale"
    },
    {
      "x": -75,
      "y": 150,
      "z": 48,
      "name": "Rock_Shale"
    },
    {
      "x": -74,
      "y": 150,
      "z": -246,
      "name": "Rock_Shale"
    },
    {
      "x": -74,
      "y": 150,
      "z": 48,
      "name": "Rock_Shale"
    },
    {
      "x": -73,
      "y": 150,
      "z": -246,
      "name": "Rock_Shale"
    },
    {
      "x": -73,
      "y": 150,
      "z": 48,
      "name": "Rock_Shale"
    },
    {
      "x": -72,
      "y": 150,
      "z": -246,
      "name": "Rock_Shale"
    },
    {
      "x": -72,
      "y": 150,
      "z": 48,
      "name": "Rock_Shale"
    },
    {
      "x": -71,
      "y": 150,
      "z": -246,
      "name": "Rock_Shale"
    },
    {
      "x": -71,
      "y": 150,
      "z": 48,
      "name": "Rock_Shale"
    },
    {
      "x": -70,
      "y": 150,
      "z": -246,
      "name": "Rock_Shale"
    },
    {
      "x": -70,
      "y": 150,
      "z": 48,
      "name": "Rock_Shale"
    },
    {
      "x": -69,
      "y": 150,
      "z": -246,
      "name": "Rock_Shale"
    },
    {
      "x": -69,
      "y": 150,
      "z": 48,
      "name": "Rock_Shale"
    },
    {
      "x": -68,
      "y": 150,
      "z": -246,
      "name": "Rock_Shale"
    },
    {
      "x": -68,
      "y": 150,
      "z": 48,
      "name": "Rock_Shale"
    },
    {
      "x": -67,
      "y": 150,
      "z": -246,
      "name": "Rock_Shale"
    },
    {
      "x": -67,
      "y": 150,
      "z": 48,
      "name": "Rock_Shale"
    },
    {
      "x": -66,
      "y": 150,
      "z": -246,
      "name": "Rock_Shale"
    },
    {
      "x": -66,
      "y": 150,
      "z": 48,
      "name": "Rock_Shale"
    },
    {
      "x": -65,
      "y": 150,
      "z": -246,
      "name": "Rock_Shale"
    },
    {
      "x": -65,
      "y": 150,
      "z": 48,
      "name": "Rock_Shale"
    },
    {
      "x": -64,
      "y": 150,
      "z": -246,
      "name": "Rock_Shale"
    },
    {
      "x": -64,
      "y": 150,
      "z": 48,
      "name": "Rock_Shale"
    },
    {
      "x": -63,
      "y": 150,
      "z": -246,
      "name": "Rock_Shale"
    },
    {
      "x": -63,
      "y": 150,
      "z": 48,
      "name": "Rock_Shale"
    },
    {
      "x": -62,
      "y": 150,
      "z": -246,
      "name": "Rock_Shale"
    },
    {
      "x": -62,
      "y": 150,
      "z": 48,
      "name": "Rock_Shale"
    },
    {
      "x": -61,
      "y": 150,
      "z": -246,
      "name": "Rock_Shale"
    },
    {
      "x": -61,
      "y": 150,
      "z": 48,
      "name": "Rock_Shale"
    },
    {
      "x": -60,
      "y": 150,
      "z": -246,
      "name": "Rock_Shale"
    },
    {
      "x": -60,
      "y": 150,
      "z": 48,
      "name": "Rock_Shale"
    },
    {
      "x": -59,
      "y": 150,
      "z": -246,
      "name": "Rock_Shale"
    },
    {
      "x": -59,
      "y": 150,
      "z": 48,
      "name": "Rock_Shale"
    },
    {
      "x": -58,
      "y": 150,
      "z": -246,
      "name": "Rock_Shale"
    },
    {
      "x": -58,
      "y": 150,
      "z": 48,
      "name": "Rock_Shale"
    },
    {
      "x": -57,
      "y": 150,
      "z": -246,
      "name": "Rock_Shale"
    },
    {
      "x": -57,
      "y": 150,
      "z": 48,
      "name": "Rock_Shale"
    },
    {
      "x": -56,
      "y": 150,
      "z": -246,
      "name": "Rock_Shale"
    },
    {
      "x": -56,
      "y": 150,
      "z": 48,
      "name": "Rock_Shale"
    },
    {
      "x": -55,
      "y": 150,
      "z": -246,
      "name": "Rock_Shale"
    },
    {
      "x": -55,
      "y": 150,
      "z": 48,
      "name": "Rock_Shale"
    },
    {
      "x": -54,
      "y": 150,
      "z": -246,
      "name": "Rock_Shale"
    },
    {
      "x": -54,
      "y": 150,
      "z": 48,
      "name": "Rock_Shale"
    },
    {
      "x": -53,
      "y": 150,
      "z": -246,
      "name": "Rock_Shale"
    },
    {
      "x": -53,
      "y": 150,
      "z": 48,
      "name": "Rock_Shale"
    },
    {
      "x": -52,
      "y": 150,
      "z": -246,
      "name": "Rock_Shale"
    },
    {
      "x": -52,
      "y": 150,
      "z": 48,
      "name": "Rock_Shale"
    },
    {
      "x": -51,
      "y": 150,
      "z": -246,
      "name": "Rock_Shale"
    },
    {
      "x": -51,
      "y": 150,
      "z": 48,
      "name": "Rock_Shale"
    },
    {
      "x": -50,
      "y": 150,
      "z": -246,
      "name": "Rock_Shale"
    },
    {
      "x": -50,
      "y": 150,
      "z": 48,
      "name": "Rock_Shale"
    },
    {
      "x": -49,
      "y": 150,
      "z": -246,
      "name": "Rock_Shale"
    },
    {
      "x": -49,
      "y": 150,
      "z": 48,
      "name": "Rock_Shale"
    },
    {
      "x": -48,
      "y": 150,
      "z": -246,
      "name": "Rock_Shale"
    },
    {
      "x": -48,
      "y": 150,
      "z": 48,
      "name": "Rock_Shale"
    },
    {
      "x": -47,
      "y": 150,
      "z": -246,
      "name": "Rock_Shale"
    },
    {
      "x": -47,
      "y": 150,
      "z": 48,
      "name": "Rock_Shale"
    },
    {
      "x": -46,
      "y": 150,
      "z": -246,
      "name": "Rock_Shale"
    },
    {
      "x": -46,
      "y": 150,
      "z": 48,
      "name": "Rock_Shale"
    },
    {
      "x": -45,
      "y": 150,
      "z": -246,
      "name": "Rock_Shale"
    },
    {
      "x": -45,
      "y": 150,
      "z": 48,
      "name": "Rock_Shale"
    },
    {
      "x": -44,
      "y": 150,
      "z": -246,
      "name": "Rock_Shale"
    },
    {
      "x": -44,
      "y": 150,
      "z": 48,
      "name": "Rock_Shale"
    },
    {
      "x": -43,
      "y": 150,
      "z": -246,
      "name": "Rock_Shale"
    },
    {
      "x": -43,
      "y": 150,
      "z": 48,
      "name": "Rock_Shale"
    },
    {
      "x": -42,
      "y": 150,
      "z": -246,
      "name": "Rock_Shale"
    },
    {
      "x": -42,
      "y": 150,
      "z": 48,
      "name": "Rock_Shale"
    },
    {
      "x": -41,
      "y": 150,
      "z": -246,
      "name": "Rock_Shale"
    },
    {
      "x": -41,
      "y": 150,
      "z": 48,
      "name": "Rock_Shale"
    },
    {
      "x": -40,
      "y": 150,
      "z": -246,
      "name": "Rock_Shale"
    },
    {
      "x": -40,
      "y": 150,
      "z": 48,
      "name": "Rock_Shale"
    },
    {
      "x": -39,
      "y": 150,
      "z": -246,
      "name": "Rock_Shale"
    },
    {
      "x": -39,
      "y": 150,
      "z": 48,
      "name": "Rock_Shale"
    },
    {
      "x": -38,
      "y": 150,
      "z": -246,
      "name": "Rock_Shale"
    },
    {
      "x": -38,
      "y": 150,
      "z": 48,
      "name": "Rock_Shale"
    },
    {
      "x": -37,
      "y": 150,
      "z": -246,
      "name": "Rock_Shale"
    },
    {
      "x": -37,
      "y": 150,
      "z": 48,
      "name": "Rock_Shale"
    },
    {
      "x": -36,
      "y": 150,
      "z": -246,
      "name": "Rock_Shale"
    },
    {
      "x": -36,
      "y": 150,
      "z": 48,
      "name": "Rock_Shale"
    },
    {
      "x": -35,
      "y": 150,
      "z": -246,
      "name": "Rock_Shale"
    },
    {
      "x": -35,
      "y": 150,
      "z": 48,
      "name": "Rock_Shale"
    },
    {
      "x": -34,
      "y": 150,
      "z": -246,
      "name": "Rock_Shale"
    },
    {
      "x": -34,
      "y": 150,
      "z": 48,
      "name": "Rock_Shale"
    },
    {
      "x": -33,
      "y": 150,
      "z": -246,
      "name": "Rock_Shale"
    },
    {
      "x": -33,
      "y": 150,
      "z": 48,
      "name": "Rock_Shale"
    },
    {
      "x": -32,
      "y": 150,
      "z": -246,
      "name": "Rock_Shale"
    },
    {
      "x": -32,
      "y": 150,
      "z": 48,
      "name": "Rock_Shale"
    },
    {
      "x": -31,
      "y": 150,
      "z": -246,
      "name": "Rock_Shale"
    },
    {
      "x": -31,
      "y": 150,
      "z": 48,
      "name": "Rock_Shale"
    },
    {
      "x": -30,
      "y": 150,
      "z": -246,
      "name": "Rock_Shale"
    },
    {
      "x": -30,
      "y": 150,
      "z": 48,
      "name": "Rock_Shale"
    },
    {
      "x": -29,
      "y": 150,
      "z": -246,
      "name": "Rock_Shale"
    },
    {
      "x": -29,
      "y": 150,
      "z": 48,
      "name": "Rock_Shale"
    },
    {
      "x": -28,
      "y": 150,
      "z": -246,
      "name": "Rock_Shale"
    },
    {
      "x": -28,
      "y": 150,
      "z": 48,
      "name": "Rock_Shale"
    },
    {
      "x": -27,
      "y": 150,
      "z": -246,
      "name": "Rock_Shale"
    },
    {
      "x": -27,
      "y": 150,
      "z": 48,
      "name": "Rock_Shale"
    },
    {
      "x": -26,
      "y": 150,
      "z": -246,
      "name": "Rock_Shale"
    },
    {
      "x": -26,
      "y": 150,
      "z": 48,
      "name": "Rock_Shale"
    },
    {
      "x": -25,
      "y": 150,
      "z": -246,
      "name": "Rock_Shale"
    },
    {
      "x": -25,
      "y": 150,
      "z": 48,
      "name": "Rock_Shale"
    },
    {
      "x": -24,
      "y": 150,
      "z": -246,
      "name": "Rock_Shale"
    },
    {
      "x": -24,
      "y": 150,
      "z": 48,
      "name": "Rock_Shale"
    },
    {
      "x": -23,
      "y": 150,
      "z": -246,
      "name": "Rock_Shale"
    },
    {
      "x": -23,
      "y": 150,
      "z": 48,
      "name": "Rock_Shale"
    },
    {
      "x": -22,
      "y": 150,
      "z": -246,
      "name": "Rock_Shale"
    },
    {
      "x": -22,
      "y": 150,
      "z": 48,
      "name": "Rock_Shale"
    },
    {
      "x": -21,
      "y": 150,
      "z": -246,
      "name": "Rock_Shale"
    },
    {
      "x": -21,
      "y": 150,
      "z": 48,
      "name": "Rock_Shale"
    },
    {
      "x": -20,
      "y": 150,
      "z": -246,
      "name": "Rock_Shale"
    },
    {
      "x": -20,
      "y": 150,
      "z": 48,
      "name": "Rock_Shale"
    },
    {
      "x": -19,
      "y": 150,
      "z": -246,
      "name": "Rock_Shale"
    },
    {
      "x": -19,
      "y": 150,
      "z": 48,
      "name": "Rock_Shale"
    },
    {
      "x": -18,
      "y": 150,
      "z": -246,
      "name": "Rock_Shale"
    },
    {
      "x": -18,
      "y": 150,
      "z": 48,
      "name": "Rock_Shale"
    },
    {
      "x": -17,
      "y": 150,
      "z": -246,
      "name": "Rock_Shale"
    },
    {
      "x": -17,
      "y": 150,
      "z": 48,
      "name": "Rock_Shale"
    },
    {
      "x": -16,
      "y": 150,
      "z": -246,
      "name": "Rock_Shale"
    },
    {
      "x": -16,
      "y": 150,
      "z": 48,
      "name": "Rock_Shale"
    },
    {
      "x": -15,
      "y": 150,
      "z": -246,
      "name": "Rock_Shale"
    },
    {
      "x": -15,
      "y": 150,
      "z": 48,
      "name": "Rock_Shale"
    },
    {
      "x": -14,
      "y": 150,
      "z": -246,
      "name": "Rock_Shale"
    },
    {
      "x": -14,
      "y": 150,
      "z": 48,
      "name": "Rock_Shale"
    },
    {
      "x": -13,
      "y": 150,
      "z": -246,
      "name": "Rock_Shale"
    },
    {
      "x": -13,
      "y": 150,
      "z": 48,
      "name": "Rock_Shale"
    },
    {
      "x": -12,
      "y": 150,
      "z": -246,
      "name": "Rock_Shale"
    },
    {
      "x": -12,
      "y": 150,
      "z": 48,
      "name": "Rock_Shale"
    },
    {
      "x": -11,
      "y": 150,
      "z": -246,
      "name": "Rock_Shale"
    },
    {
      "x": -11,
      "y": 150,
      "z": 48,
      "name": "Rock_Shale"
    },
    {
      "x": -10,
      "y": 150,
      "z": -246,
      "name": "Rock_Shale"
    },
    {
      "x": -10,
      "y": 150,
      "z": 48,
      "name": "Rock_Shale"
    },
    {
      "x": -9,
      "y": 150,
      "z": -246,
      "name": "Rock_Shale"
    },
    {
      "x": -9,
      "y": 150,
      "z": 48,
      "name": "Rock_Shale"
    },
    {
      "x": -8,
      "y": 150,
      "z": -246,
      "name": "Rock_Shale"
    },
    {
      "x": -8,
      "y": 150,
      "z": 48,
      "name": "Rock_Shale"
    },
    {
      "x": -7,
      "y": 150,
      "z": -246,
      "name": "Rock_Shale"
    },
    {
      "x": -7,
      "y": 142,
      "z": -4,
      "name": "Rock_Shale"
    },
    {
      "x": -7,
      "y": 143,
      "z": -4,
      "name": "Rock_Shale"
    },
    {
      "x": -7,
      "y": 142,
      "z": -3,
      "name": "Rock_Shale"
    },
    {
      "x": -7,
      "y": 143,
      "z": -3,
      "name": "Rock_Shale"
    },
    {
      "x": -7,
      "y": 144,
      "z": -3,
      "name": "Rock_Shale"
    },
    {
      "x": -7,
      "y": 143,
      "z": -2,
      "name": "Rock_Shale"
    },
    {
      "x": -7,
      "y": 144,
      "z": -2,
      "name": "Rock_Shale"
    },
    {
      "x": -7,
      "y": 129,
      "z": 4,
      "name": "Rock_Shale"
    },
    {
      "x": -7,
      "y": 130,
      "z": 4,
      "name": "Rock_Shale"
    },
    {
      "x": -7,
      "y": 131,
      "z": 4,
      "name": "Rock_Shale"
    },
    {
      "x": -7,
      "y": 132,
      "z": 4,
      "name": "Rock_Shale"
    },
    {
      "x": -7,
      "y": 133,
      "z": 4,
      "name": "Rock_Shale"
    },
    {
      "x": -7,
      "y": 134,
      "z": 4,
      "name": "Rock_Shale"
    },
    {
      "x": -7,
      "y": 135,
      "z": 4,
      "name": "Rock_Shale"
    },
    {
      "x": -7,
      "y": 129,
      "z": 5,
      "name": "Rock_Shale"
    },
    {
      "x": -7,
      "y": 130,
      "z": 5,
      "name": "Rock_Shale"
    },
    {
      "x": -7,
      "y": 131,
      "z": 5,
      "name": "Rock_Shale"
    },
    {
      "x": -7,
      "y": 132,
      "z": 5,
      "name": "Rock_Shale"
    },
    {
      "x": -7,
      "y": 133,
      "z": 5,
      "name": "Rock_Shale"
    },
    {
      "x": -7,
      "y": 134,
      "z": 5,
      "name": "Rock_Shale"
    },
    {
      "x": -7,
      "y": 135,
      "z": 5,
      "name": "Rock_Shale"
    },
    {
      "x": -7,
      "y": 136,
      "z": 5,
      "name": "Rock_Shale"
    },
    {
      "x": -7,
      "y": 150,
      "z": 48,
      "name": "Rock_Shale"
    },
    {
      "x": -6,
      "y": 150,
      "z": -246,
      "name": "Rock_Shale"
    },
    {
      "x": -6,
      "y": 141,
      "z": -6,
      "name": "Rock_Shale_Brick"
    },
    {
      "x": -6,
      "y": 140,
      "z": -5,
      "name": "Rock_Shale_Brick_Stairs",
      "rotation": 8
    },
    {
      "x": -6,
      "y": 141,
      "z": -5,
      "name": "Rock_Shale_Brick"
    },
    {
      "x": -6,
      "y": 142,
      "z": -5,
      "name": "Rock_Shale"
    },
    {
      "x": -6,
      "y": 143,
      "z": -5,
      "name": "Rock_Shale"
    },
    {
      "x": -6,
      "y": 129,
      "z": -4,
      "name": "Rock_Shale_Brick"
    },
    {
      "x": -6,
      "y": 130,
      "z": -4,
      "name": "Rock_Shale_Brick"
    },
    {
      "x": -6,
      "y": 131,
      "z": -4,
      "name": "Rock_Shale_Brick"
    },
    {
      "x": -6,
      "y": 132,
      "z": -4,
      "name": "Rock_Shale_Brick"
    },
    {
      "x": -6,
      "y": 133,
      "z": -4,
      "name": "Rock_Shale_Brick"
    },
    {
      "x": -6,
      "y": 134,
      "z": -4,
      "name": "Rock_Shale_Brick"
    },
    {
      "x": -6,
      "y": 135,
      "z": -4,
      "name": "Rock_Shale_Brick_Pillar_Base"
    },
    {
      "x": -6,
      "y": 136,
      "z": -4,
      "name": "Rock_Shale_Brick_Pillar_Middle"
    },
    {
      "x": -6,
      "y": 137,
      "z": -4,
      "name": "Rock_Shale_Brick_Pillar_Middle"
    },
    {
      "x": -6,
      "y": 138,
      "z": -4,
      "name": "Rock_Shale_Brick_Pillar_Middle"
    },
    {
      "x": -6,
      "y": 139,
      "z": -4,
      "name": "Rock_Shale_Brick_Pillar_Base",
      "rotation": 8
    },
    {
      "x": -6,
      "y": 140,
      "z": -4,
      "name": "Rock_Shale_Brick"
    },
    {
      "x": -6,
      "y": 141,
      "z": -4,
      "name": "Rock_Shale_Brick"
    },
    {
      "x": -6,
      "y": 142,
      "z": -4,
      "name": "Rock_Shale"
    },
    {
      "x": -6,
      "y": 143,
      "z": -4,
      "name": "Rock_Shale"
    },
    {
      "x": -6,
      "y": 129,
      "z": -3,
      "name": "Rock_Shale_Brick"
    },
    {
      "x": -6,
      "y": 130,
      "z": -3,
      "name": "Rock_Shale_Brick"
    },
    {
      "x": -6,
      "y": 131,
      "z": -3,
      "name": "Rock_Shale_Brick"
    },
    {
      "x": -6,
      "y": 132,
      "z": -3,
      "name": "Rock_Shale_Brick"
    },
    {
      "x": -6,
      "y": 133,
      "z": -3,
      "name": "Rock_Shale_Brick"
    },
    {
      "x": -6,
      "y": 134,
      "z": -3,
      "name": "Rock_Shale_Brick"
    },
    {
      "x": -6,
      "y": 135,
      "z": -3,
      "name": "Rock_Shale_Brick_Pillar_Base"
    },
    {
      "x": -6,
      "y": 136,
      "z": -3,
      "name": "Rock_Shale_Brick_Pillar_Middle"
    },
    {
      "x": -6,
      "y": 137,
      "z": -3,
      "name": "Rock_Shale_Brick_Pillar_Middle"
    },
    {
      "x": -6,
      "y": 138,
      "z": -3,
      "name": "Rock_Shale_Brick_Pillar_Middle"
    },
    {
      "x": -6,
      "y": 139,
      "z": -3,
      "name": "Rock_Shale_Brick_Pillar_Base",
      "rotation": 8
    },
    {
      "x": -6,
      "y": 140,
      "z": -3,
      "name": "Rock_Shale_Brick"
    },
    {
      "x": -6,
      "y": 141,
      "z": -3,
      "name": "Rock_Shale_Brick"
    },
    {
      "x": -6,
      "y": 142,
      "z": -3,
      "name": "Rock_Shale"
    },
    {
      "x": -6,
      "y": 143,
      "z": -3,
      "name": "Rock_Shale"
    },
    {
      "x": -6,
      "y": 144,
      "z": -3,
      "name": "Rock_Shale"
    },
    {
      "x": -6,
      "y": 129,
      "z": -2,
      "name": "Rock_Shale_Brick"
    },
    {
      "x": -6,
      "y": 130,
      "z": -2,
      "name": "Rock_Shale_Brick"
    },
    {
      "x": -6,
      "y": 131,
      "z": -2,
      "name": "Rock_Shale_Brick"
    },
    {
      "x": -6,
      "y": 132,
      "z": -2,
      "name": "Rock_Shale_Brick"
    },
    {
      "x": -6,
      "y": 133,
      "z": -2,
      "name": "Rock_Shale_Brick"
    },
    {
      "x": -6,
      "y": 134,
      "z": -2,
      "name": "Rock_Shale_Brick"
    },
    {
      "x": -6,
      "y": 135,
      "z": -2,
      "name": "Rock_Shale_Brick"
    },
    {
      "x": -6,
      "y": 136,
      "z": -2,
      "name": "Deco_Bone_Pile"
    },
    {
      "x": -6,
      "y": 137,
      "z": -2,
      "name": "Rock_Shale_Brick"
    },
    {
      "x": -6,
      "y": 138,
      "z": -2,
      "name": "Deco_Bone_Skulls"
    },
    {
      "x": -6,
      "y": 140,
      "z": -2,
      "name": "Rock_Shale_Brick"
    },
    {
      "x": -6,
      "y": 141,
      "z": -2,
      "name": "Rock_Shale_Brick"
    },
    {
      "x": -6,
      "y": 142,
      "z": -2,
      "name": "Rock_Shale"
    },
    {
      "x": -6,
      "y": 143,
      "z": -2,
      "name": "Rock_Shale"
    },
    {
      "x": -6,
      "y": 144,
      "z": -2,
      "name": "Rock_Shale"
    },
    {
      "x": -6,
      "y": 129,
      "z": -1,
      "name": "Rock_Shale_Brick"
    },
    {
      "x": -6,
      "y": 130,
      "z": -1,
      "name": "Rock_Shale_Brick"
    },
    {
      "x": -6,
      "y": 131,
      "z": -1,
      "name": "Rock_Shale_Brick"
    },
    {
      "x": -6,
      "y": 132,
      "z": -1,
      "name": "Rock_Shale_Brick"
    },
    {
      "x": -6,
      "y": 133,
      "z": -1,
      "name": "Rock_Shale_Brick"
    },
    {
      "x": -6,
      "y": 134,
      "z": -1,
      "name": "Rock_Shale_Brick"
    },
    {
      "x": -6,
      "y": 135,
      "z": -1,
      "name": "Rock_Shale_Brick"
    },
    {
      "x": -6,
      "y": 136,
      "z": -1,
      "name": "Deco_Bone_Pile"
    },
    {
      "x": -6,
      "y": 137,
      "z": -1,
      "name": "Rock_Shale_Brick"
    },
    {
      "x": -6,
      "y": 138,
      "z": -1,
      "name": "Deco_Bone_Skulls"
    },
    {
      "x": -6,
      "y": 140,
      "z": -1,
      "name": "Rock_Shale_Brick"
    },
    {
      "x": -6,
      "y": 141,
      "z": -1,
      "name": "Rock_Shale_Brick"
    },
    {
      "x": -6,
      "y": 142,
      "z": -1,
      "name": "Rock_Shale_Brick_Half",
      "rotation": 7
    },
    {
      "x": -6,
      "y": 143,
      "z": -1,
      "name": "Rock_Shale_Brick_Half",
      "rotation": 7
    },
    {
      "x": -6,
      "y": 144,
      "z": -1,
      "name": "Rock_Shale_Brick_Half",
      "rotation": 7
    },
    {
      "x": -6,
      "y": 145,
      "z": -1,
      "name": "Rock_Shale_Brick_Half",
      "rotation": 7
    },
    {
      "x": -6,
      "y": 129,
      "z": 0,
      "name": "Rock_Shale_Brick"
    },
    {
      "x": -6,
      "y": 130,
      "z": 0,
      "name": "Rock_Shale_Brick"
    },
    {
      "x": -6,
      "y": 131,
      "z": 0,
      "name": "Rock_Shale_Brick"
    },
    {
      "x": -6,
      "y": 132,
      "z": 0,
      "name": "Rock_Shale_Brick"
    },
    {
      "x": -6,
      "y": 133,
      "z": 0,
      "name": "Rock_Shale_Brick"
    },
    {
      "x": -6,
      "y": 134,
      "z": 0,
      "name": "Rock_Shale_Brick"
    },
    {
      "x": -6,
      "y": 135,
      "z": 0,
      "name": "Rock_Shale_Brick"
    },
    {
      "x": -6,
      "y": 136,
      "z": 0,
      "name": "Deco_Bone_Skulls"
    },
    {
      "x": -6,
      "y": 137,
      "z": 0,
      "name": "Rock_Shale_Brick"
    },
    {
      "x": -6,
      "y": 140,
      "z": 0,
      "name": "Rock_Shale_Brick"
    },
    {
      "x": -6,
      "y": 141,
      "z": 0,
      "name": "Rock_Shale_Brick"
    },
    {
      "x": -6,
      "y": 142,
      "z": 0,
      "name": "Rock_Shale"
    },
    {
      "x": -6,
      "y": 143,
      "z": 0,
      "name": "Rock_Shale"
    },
    {
      "x": -6,
      "y": 144,
      "z": 0,
      "name": "Rock_Shale"
    },
    {
      "x": -6,
      "y": 129,
      "z": 1,
      "name": "Rock_Shale_Brick"
    },
    {
      "x": -6,
      "y": 130,
      "z": 1,
      "name": "Rock_Shale_Brick"
    },
    {
      "x": -6,
      "y": 131,
      "z": 1,
      "name": "Rock_Shale_Brick"
    },
    {
      "x": -6,
      "y": 132,
      "z": 1,
      "name": "Rock_Shale_Brick"
    },
    {
      "x": -6,
      "y": 133,
      "z": 1,
      "name": "Rock_Shale_Brick"
    },
    {
      "x": -6,
      "y": 134,
      "z": 1,
      "name": "Rock_Shale_Brick"
    },
    {
      "x": -6,
      "y": 135,
      "z": 1,
      "name": "Rock_Shale_Brick"
    },
    {
      "x": -6,
      "y": 136,
      "z": 1,
      "name": "Rock_Shale_Brick_Half",
      "rotation": 7
    },
    {
      "x": -6,
      "y": 137,
      "z": 1,
      "name": "Rock_Shale_Brick"
    },
    {
      "x": -6,
      "y": 138,
      "z": 1,
      "name": "Rock_Shale_Brick_Half",
      "rotation": 7
    },
    {
      "x": -6,
      "y": 139,
      "z": 1,
      "name": "Rock_Shale_Brick_Half",
      "rotation": 7
    },
    {
      "x": -6,
      "y": 140,
      "z": 1,
      "name": "Rock_Shale_Brick"
    },
    {
      "x": -6,
      "y": 141,
      "z": 1,
      "name": "Rock_Shale_Brick"
    },
    {
      "x": -6,
      "y": 142,
      "z": 1,
      "name": "Rock_Shale"
    },
    {
      "x": -6,
      "y": 143,
      "z": 1,
      "name": "Rock_Shale"
    },
    {
      "x": -6,
      "y": 144,
      "z": 1,
      "name": "Rock_Shale"
    },
    {
      "x": -6,
      "y": 129,
      "z": 2,
      "name": "Rock_Shale_Brick"
    },
    {
      "x": -6,
      "y": 130,
      "z": 2,
      "name": "Rock_Shale_Brick"
    },
    {
      "x": -6,
      "y": 131,
      "z": 2,
      "name": "Rock_Shale_Brick"
    },
    {
      "x": -6,
      "y": 132,
      "z": 2,
      "name": "Rock_Shale_Brick"
    },
    {
      "x": -6,
      "y": 133,
      "z": 2,
      "name": "Rock_Shale_Brick"
    },
    {
      "x": -6,
      "y": 134,
      "z": 2,
      "name": "Rock_Shale_Brick"
    },
    {
      "x": -6,
      "y": 135,
      "z": 2,
      "name": "Rock_Shale_Brick"
    },
    {
      "x": -6,
      "y": 136,
      "z": 2,
      "name": "Deco_Bone_Pile"
    },
    {
      "x": -6,
      "y": 137,
      "z": 2,
      "name": "Rock_Shale_Brick"
    },
    {
      "x": -6,
      "y": 138,
      "z": 2,
      "name": "Deco_Bone_Pile"
    },
    {
      "x": -6,
      "y": 140,
      "z": 2,
      "name": "Rock_Shale_Brick"
    },
    {
      "x": -6,
      "y": 141,
      "z": 2,
      "name": "Rock_Shale_Brick"
    },
    {
      "x": -6,
      "y": 142,
      "z": 2,
      "name": "Rock_Shale"
    },
    {
      "x": -6,
      "y": 143,
      "z": 2,
      "name": "Rock_Shale"
    },
    {
      "x": -6,
      "y": 144,
      "z": 2,
      "name": "Rock_Shale"
    },
    {
      "x": -6,
      "y": 129,
      "z": 3,
      "name": "Rock_Shale_Brick"
    },
    {
      "x": -6,
      "y": 130,
      "z": 3,
      "name": "Rock_Shale_Brick"
    },
    {
      "x": -6,
      "y": 131,
      "z": 3,
      "name": "Rock_Shale_Brick"
    },
    {
      "x": -6,
      "y": 132,
      "z": 3,
      "name": "Rock_Shale_Brick"
    },
    {
      "x": -6,
      "y": 133,
      "z": 3,
      "name": "Rock_Shale_Brick"
    },
    {
      "x": -6,
      "y": 134,
      "z": 3,
      "name": "Rock_Shale_Brick"
    },
    {
      "x": -6,
      "y": 135,
      "z": 3,
      "name": "Rock_Shale_Brick"
    },
    {
      "x": -6,
      "y": 136,
      "z": 3,
      "name": "Deco_Bone_Skulls"
    },
    {
      "x": -6,
      "y": 137,
      "z": 3,
      "name": "Rock_Shale_Brick"
    },
    {
      "x": -6,
      "y": 138,
      "z": 3,
      "name": "Deco_Bone_Pile"
    },
    {
      "x": -6,
      "y": 140,
      "z": 3,
      "name": "Rock_Shale_Brick"
    },
    {
      "x": -6,
      "y": 141,
      "z": 3,
      "name": "Rock_Shale_Brick"
    },
    {
      "x": -6,
      "y": 143,
      "z": 3,
      "name": "Rock_Shale"
    },
    {
      "x": -6,
      "y": 144,
      "z": 3,
      "name": "Rock_Shale"
    },
    {
      "x": -6,
      "y": 129,
      "z": 4,
      "name": "Rock_Shale_Brick"
    },
    {
      "x": -6,
      "y": 130,
      "z": 4,
      "name": "Rock_Shale_Brick"
    },
    {
      "x": -6,
      "y": 131,
      "z": 4,
      "name": "Rock_Shale_Brick"
    },
    {
      "x": -6,
      "y": 132,
      "z": 4,
      "name": "Rock_Shale_Brick"
    },
    {
      "x": -6,
      "y": 133,
      "z": 4,
      "name": "Rock_Shale_Brick"
    },
    {
      "x": -6,
      "y": 134,
      "z": 4,
      "name": "Rock_Shale_Brick"
    },
    {
      "x": -6,
      "y": 135,
      "z": 4,
      "name": "Rock_Shale"
    },
    {
      "x": -6,
      "y": 136,
      "z": 4,
      "name": "Rock_Shale"
    },
    {
      "x": -6,
      "y": 137,
      "z": 4,
      "name": "Rock_Shale"
    },
    {
      "x": -6,
      "y": 140,
      "z": 4,
      "name": "Rock_Shale_Brick"
    },
    {
      "x": -6,
      "y": 141,
      "z": 4,
      "name": "Rock_Shale_Brick"
    },
    {
      "x": -6,
      "y": 142,
      "z": 4,
      "name": "Rock_Shale_Brick_Half",
      "rotation": 7
    },
    {
      "x": -6,
      "y": 143,
      "z": 4,
      "name": "Rock_Shale_Brick_Half",
      "rotation": 7
    },
    {
      "x": -6,
      "y": 144,
      "z": 4,
      "name": "Rock_Shale_Brick_Half",
      "rotation": 7
    },
    {
      "x": -6,
      "y": 145,
      "z": 4,
      "name": "Rock_Shale_Brick_Half",
      "rotation": 7
    },
    {
      "x": -6,
      "y": 129,
      "z": 5,
      "name": "Rock_Shale_Brick"
    },
    {
      "x": -6,
      "y": 130,
      "z": 5,
      "name": "Rock_Shale_Brick"
    },
    {
      "x": -6,
      "y": 131,
      "z": 5,
      "name": "Rock_Shale_Brick"
    },
    {
      "x": -6,
      "y": 132,
      "z": 5,
      "name": "Rock_Shale_Brick"
    },
    {
      "x": -6,
      "y": 133,
      "z": 5,
      "name": "Rock_Shale_Brick"
    },
    {
      "x": -6,
      "y": 134,
      "z": 5,
      "name": "Rock_Shale_Brick"
    },
    {
      "x": -6,
      "y": 135,
      "z": 5,
      "name": "Rock_Shale"
    },
    {
      "x": -6,
      "y": 136,
      "z": 5,
      "name": "Rock_Shale"
    },
    {
      "x": -6,
      "y": 137,
      "z": 5,
      "name": "Rock_Shale"
    },
    {
      "x": -6,
      "y": 140,
      "z": 5,
      "name": "Rock_Shale_Brick"
    },
    {
      "x": -6,
      "y": 141,
      "z": 5,
      "name": "Rock_Shale_Brick"
    },
    {
      "x": -6,
      "y": 142,
      "z": 5,
      "name": "Rock_Shale"
    },
    {
      "x": -6,
      "y": 143,
      "z": 5,
      "name": "Rock_Shale"
    },
    {
      "x": -6,
      "y": 144,
      "z": 5,
      "name": "Rock_Shale"
    },
    {
      "x": -6,
      "y": 129,
      "z": 6,
      "name": "Rock_Shale_Brick"
    },
    {
      "x": -6,
      "y": 130,
      "z": 6,
      "name": "Rock_Shale_Brick"
    },
    {
      "x": -6,
      "y": 131,
      "z": 6,
      "name": "Rock_Shale_Brick"
    },
    {
      "x": -6,
      "y": 132,
      "z": 6,
      "name": "Rock_Shale_Brick"
    },
    {
      "x": -6,
      "y": 133,
      "z": 6,
      "name": "Rock_Shale_Brick"
    },
    {
      "x": -6,
      "y": 134,
      "z": 6,
      "name": "Rock_Shale_Brick"
    },
    {
      "x": -6,
      "y": 135,
      "z": 6,
      "name": "Rock_Shale_Brick_Pillar_Base"
    },
    {
      "x": -6,
      "y": 136,
      "z": 6,
      "name": "Rock_Shale_Brick_Pillar_Middle"
    },
    {
      "x": -6,
      "y": 137,
      "z": 6,
      "name": "Rock_Shale_Brick_Pillar_Middle"
    },
    {
      "x": -6,
      "y": 138,
      "z": 6,
      "name": "Rock_Shale_Brick_Pillar_Middle"
    },
    {
      "x": -6,
      "y": 139,
      "z": 6,
      "name": "Rock_Shale_Brick_Pillar_Base",
      "rotation": 8
    },
    {
      "x": -6,
      "y": 140,
      "z": 6,
      "name": "Rock_Shale_Brick"
    },
    {
      "x": -6,
      "y": 141,
      "z": 6,
      "name": "Rock_Shale_Brick"
    },
    {
      "x": -6,
      "y": 142,
      "z": 6,
      "name": "Rock_Shale"
    },
    {
      "x": -6,
      "y": 143,
      "z": 6,
      "name": "Rock_Shale"
    },
    {
      "x": -6,
      "y": 144,
      "z": 6,
      "name": "Rock_Shale"
    },
    {
      "x": -6,
      "y": 129,
      "z": 7,
      "name": "Rock_Shale_Brick"
    },
    {
      "x": -6,
      "y": 130,
      "z": 7,
      "name": "Rock_Shale_Brick"
    },
    {
      "x": -6,
      "y": 131,
      "z": 7,
      "name": "Rock_Shale_Brick"
    },
    {
      "x": -6,
      "y": 132,
      "z": 7,
      "name": "Rock_Shale_Brick"
    },
    {
      "x": -6,
      "y": 133,
      "z": 7,
      "name": "Rock_Shale_Brick"
    },
    {
      "x": -6,
      "y": 134,
      "z": 7,
      "name": "Rock_Shale_Brick"
    },
    {
      "x": -6,
      "y": 135,
      "z": 7,
      "name": "Rock_Shale_Brick_Pillar_Base"
    },
    {
      "x": -6,
      "y": 136,
      "z": 7,
      "name": "Rock_Shale_Brick_Pillar_Middle"
    },
    {
      "x": -6,
      "y": 137,
      "z": 7,
      "name": "Rock_Shale_Brick_Pillar_Middle"
    },
    {
      "x": -6,
      "y": 138,
      "z": 7,
      "name": "Rock_Shale_Brick_Pillar_Middle"
    },
    {
      "x": -6,
      "y": 139,
      "z": 7,
      "name": "Rock_Shale_Brick_Pillar_Base",
      "rotation": 8
    },
    {
      "x": -6,
      "y": 140,
      "z": 7,
      "name": "Rock_Shale_Brick"
    },
    {
      "x": -6,
      "y": 141,
      "z": 7,
      "name": "Rock_Shale_Brick"
    },
    {
      "x": -6,
      "y": 142,
      "z": 7,
      "name": "Rock_Shale_Brick_Half"
    },
    {
      "x": -6,
      "y": 143,
      "z": 7,
      "name": "Rock_Shale"
    },
    {
      "x": -6,
      "y": 144,
      "z": 7,
      "name": "Rock_Shale"
    },
    {
      "x": -6,
      "y": 140,
      "z": 8,
      "name": "Rock_Shale_Brick_Stairs",
      "rotation": 10
    },
    {
      "x": -6,
      "y": 141,
      "z": 8,
      "name": "Rock_Shale_Brick"
    },
    {
      "x": -6,
      "y": 144,
      "z": 8,
      "name": "Rock_Shale"
    },
    {
      "x": -6,
      "y": 141,
      "z": 9,
      "name": "Rock_Shale_Brick"
    },
    {
      "x": -6,
      "y": 150,
      "z": 48,
      "name": "Rock_Shale"
    },
    {
      "x": -5,
      "y": 150,
      "z": -246,
      "name": "Rock_Shale"
    },
    {
      "x": -5,
      "y": 124,
      "z": -8,
      "name": "Rock_Shale_Brick_Smooth"
    },
    {
      "x": -5,
      "y": 125,
      "z": -8,
      "name": "Rock_Shale"
    },
    {
      "x": -5,
      "y": 126,
      "z": -8,
      "name": "Rock_Shale"
    },
    {
      "x": -5,
      "y": 127,
      "z": -8,
      "name": "Rock_Shale"
    },
    {
      "x": -5,
      "y": 128,
      "z": -8,
      "name": "Rock_Shale"
    },
    {
      "x": -5,
      "y": 129,
      "z": -8,
      "name": "Rock_Shale"
    },
    {
      "x": -5,
      "y": 130,
      "z": -8,
      "name": "Rock_Shale"
    },
    {
      "x": -5,
      "y": 124,
      "z": -7,
      "name": "Rock_Shale_Brick_Smooth"
    },
    {
      "x": -5,
      "y": 125,
      "z": -7,
      "name": "Rock_Shale"
    },
    {
      "x": -5,
      "y": 126,
      "z": -7,
      "name": "Rock_Shale"
    },
    {
      "x": -5,
      "y": 127,
      "z": -7,
      "name": "Rock_Shale"
    },
    {
      "x": -5,
      "y": 128,
      "z": -7,
      "name": "Rock_Shale"
    },
    {
      "x": -5,
      "y": 129,
      "z": -7,
      "name": "Rock_Shale"
    },
    {
      "x": -5,
      "y": 130,
      "z": -7,
      "name": "Rock_Shale"
    },
    {
      "x": -5,
      "y": 124,
      "z": -6,
      "name": "Rock_Shale_Brick_Smooth"
    },
    {
      "x": -5,
      "y": 125,
      "z": -6,
      "name": "Rock_Shale"
    },
    {
      "x": -5,
      "y": 126,
      "z": -6,
      "name": "Rock_Shale"
    },
    {
      "x": -5,
      "y": 127,
      "z": -6,
      "name": "Rock_Shale"
    },
    {
      "x": -5,
      "y": 128,
      "z": -6,
      "name": "Rock_Shale"
    },
    {
      "x": -5,
      "y": 129,
      "z": -6,
      "name": "Rock_Shale"
    },
    {
      "x": -5,
      "y": 130,
      "z": -6,
      "name": "Rock_Shale"
    },
    {
      "x": -5,
      "y": 131,
      "z": -6,
      "name": "Rock_Shale"
    },
    {
      "x": -5,
      "y": 141,
      "z": -6,
      "name": "Rock_Shale_Brick"
    },
    {
      "x": -5,
      "y": 124,
      "z": -5,
      "name": "Rock_Shale_Brick_Smooth"
    },
    {
      "x": -5,
      "y": 125,
      "z": -5,
      "name": "Rock_Shale"
    },
    {
      "x": -5,
      "y": 126,
      "z": -5,
      "name": "Rock_Shale"
    },
    {
      "x": -5,
      "y": 127,
      "z": -5,
      "name": "Rock_Shale"
    },
    {
      "x": -5,
      "y": 128,
      "z": -5,
      "name": "Rock_Shale"
    },
    {
      "x": -5,
      "y": 129,
      "z": -5,
      "name": "Rock_Basalt"
    },
    {
      "x": -5,
      "y": 130,
      "z": -5,
      "name": "Rock_Basalt"
    },
    {
      "x": -5,
      "y": 131,
      "z": -5,
      "name": "Rock_Shale"
    },
    {
      "x": -5,
      "y": 132,
      "z": -5,
      "name": "Rock_Shale"
    },
    {
      "x": -5,
      "y": 140,
      "z": -5,
      "name": "Rock_Shale_Brick_Stairs",
      "rotation": 8
    },
    {
      "x": -5,
      "y": 141,
      "z": -5,
      "name": "Rock_Shale_Brick"
    },
    {
      "x": -5,
      "y": 142,
      "z": -5,
      "name": "Rock_Shale"
    },
    {
      "x": -5,
      "y": 143,
      "z": -5,
      "name": "Rock_Shale"
    },
    {
      "x": -5,
      "y": 145,
      "z": -5,
      "name": "Rock_Shale"
    },
    {
      "x": -5,
      "y": 125,
      "z": -4,
      "name": "Rock_Shale"
    },
    {
      "x": -5,
      "y": 126,
      "z": -4,
      "name": "Rock_Shale"
    },
    {
      "x": -5,
      "y": 127,
      "z": -4,
      "name": "Rock_Shale"
    },
    {
      "x": -5,
      "y": 128,
      "z": -4,
      "name": "Rock_Shale"
    },
    {
      "x": -5,
      "y": 129,
      "z": -4,
      "name": "Rock_Shale"
    },
    {
      "x": -5,
      "y": 130,
      "z": -4,
      "name": "Rock_Basalt"
    },
    {
      "x": -5,
      "y": 131,
      "z": -4,
      "name": "Rock_Basalt"
    },
    {
      "x": -5,
      "y": 132,
      "z": -4,
      "name": "Rock_Shale"
    },
    {
      "x": -5,
      "y": 133,
      "z": -4,
      "name": "Rock_Shale"
    },
    {
      "x": -5,
      "y": 134,
      "z": -4,
      "name": "Rock_Shale_Brick"
    },
    {
      "x": -5,
      "y": 135,
      "z": -4,
      "name": "Rock_Shale_Brick_Pillar_Base"
    },
    {
      "x": -5,
      "y": 136,
      "z": -4,
      "name": "Rock_Shale_Brick_Pillar_Middle"
    },
    {
      "x": -5,
      "y": 137,
      "z": -4,
      "name": "Rock_Shale_Brick_Pillar_Middle"
    },
    {
      "x": -5,
      "y": 138,
      "z": -4,
      "name": "Rock_Shale_Brick_Pillar_Middle"
    },
    {
      "x": -5,
      "y": 139,
      "z": -4,
      "name": "Rock_Shale_Brick_Pillar_Base",
      "rotation": 8
    },
    {
      "x": -5,
      "y": 140,
      "z": -4,
      "name": "Rock_Shale_Brick"
    },
    {
      "x": -5,
      "y": 141,
      "z": -4,
      "name": "Rock_Shale_Brick"
    },
    {
      "x": -5,
      "y": 142,
      "z": -4,
      "name": "Rock_Shale"
    },
    {
      "x": -5,
      "y": 143,
      "z": -4,
      "name": "Rock_Shale"
    },
    {
      "x": -5,
      "y": 144,
      "z": -4,
      "name": "Rock_Shale"
    },
    {
      "x": -5,
      "y": 145,
      "z": -4,
      "name": "Rock_Shale"
    },
    {
      "x": -5,
      "y": 146,
      "z": -4,
      "name": "Rock_Shale"
    },
    {
      "x": -5,
      "y": 126,
      "z": -3,
      "name": "Rock_Shale"
    },
    {
      "x": -5,
      "y": 127,
      "z": -3,
      "name": "Rock_Shale"
    },
    {
      "x": -5,
      "y": 128,
      "z": -3,
      "name": "Rock_Shale"
    },
    {
      "x": -5,
      "y": 129,
      "z": -3,
      "name": "Rock_Shale"
    },
    {
      "x": -5,
      "y": 130,
      "z": -3,
      "name": "Rock_Shale"
    },
    {
      "x": -5,
      "y": 131,
      "z": -3,
      "name": "Rock_Basalt"
    },
    {
      "x": -5,
      "y": 132,
      "z": -3,
      "name": "Rock_Basalt"
    },
    {
      "x": -5,
      "y": 133,
      "z": -3,
      "name": "Rock_Shale"
    },
    {
      "x": -5,
      "y": 134,
      "z": -3,
      "name": "Rock_Shale_Brick"
    },
    {
      "x": -5,
      "y": 135,
      "z": -3,
      "name": "Rock_Shale_Brick"
    },
    {
      "x": -5,
      "y": 136,
      "z": -3,
      "name": "Rock_Shale_Brick"
    },
    {
      "x": -5,
      "y": 137,
      "z": -3,
      "name": "Rock_Shale_Brick"
    },
    {
      "x": -5,
      "y": 138,
      "z": -3,
      "name": "Rock_Shale_Brick"
    },
    {
      "x": -5,
      "y": 139,
      "z": -3,
      "name": "Rock_Shale_Brick"
    },
    {
      "x": -5,
      "y": 140,
      "z": -3,
      "name": "Rock_Shale_Brick"
    },
    {
      "x": -5,
      "y": 141,
      "z": -3,
      "name": "Rock_Shale_Brick"
    },
    {
      "x": -5,
      "y": 142,
      "z": -3,
      "name": "Rock_Shale"
    },
    {
      "x": -5,
      "y": 143,
      "z": -3,
      "name": "Rock_Shale"
    },
    {
      "x": -5,
      "y": 144,
      "z": -3,
      "name": "Rock_Shale"
    },
    {
      "x": -5,
      "y": 145,
      "z": -3,
      "name": "Rock_Shale"
    },
    {
      "x": -5,
      "y": 146,
      "z": -3,
      "name": "Rock_Shale"
    },
    {
      "x": -5,
      "y": 127,
      "z": -2,
      "name": "Rock_Shale"
    },
    {
      "x": -5,
      "y": 128,
      "z": -2,
      "name": "Rock_Shale"
    },
    {
      "x": -5,
      "y": 129,
      "z": -2,
      "name": "Rock_Shale"
    },
    {
      "x": -5,
      "y": 130,
      "z": -2,
      "name": "Rock_Shale"
    },
    {
      "x": -5,
      "y": 131,
      "z": -2,
      "name": "Rock_Shale"
    },
    {
      "x": -5,
      "y": 132,
      "z": -2,
      "name": "Rock_Shale"
    },
    {
      "x": -5,
      "y": 133,
      "z": -2,
      "name": "Rock_Shale"
    },
    {
      "x": -5,
      "y": 134,
      "z": -2,
      "name": "Rock_Shale"
    },
    {
      "x": -5,
      "y": 135,
      "z": -2,
      "name": "Rock_Shale_Brick"
    },
    {
      "x": -5,
      "y": 136,
      "z": -2,
      "name": "Rock_Shale_Brick"
    },
    {
      "x": -5,
      "y": 137,
      "z": -2,
      "name": "Rock_Shale_Brick"
    },
    {
      "x": -5,
      "y": 138,
      "z": -2,
      "name": "Rock_Shale_Brick"
    },
    {
      "x": -5,
      "y": 139,
      "z": -2,
      "name": "Rock_Shale_Brick"
    },
    {
      "x": -5,
      "y": 140,
      "z": -2,
      "name": "Rock_Shale_Brick"
    },
    {
      "x": -5,
      "y": 141,
      "z": -2,
      "name": "Rock_Shale_Brick"
    },
    {
      "x": -5,
      "y": 142,
      "z": -2,
      "name": "Rock_Shale"
    },
    {
      "x": -5,
      "y": 143,
      "z": -2,
      "name": "Rock_Shale"
    },
    {
      "x": -5,
      "y": 144,
      "z": -2,
      "name": "Rock_Shale"
    },
    {
      "x": -5,
      "y": 145,
      "z": -2,
      "name": "Rock_Shale"
    },
    {
      "x": -5,
      "y": 146,
      "z": -2,
      "name": "Rock_Shale"
    },
    {
      "x": -5,
      "y": 128,
      "z": -1,
      "name": "Rock_Shale"
    },
    {
      "x": -5,
      "y": 129,
      "z": -1,
      "name": "Rock_Shale"
    },
    {
      "x": -5,
      "y": 130,
      "z": -1,
      "name": "Rock_Shale"
    },
    {
      "x": -5,
      "y": 131,
      "z": -1,
      "name": "Rock_Shale"
    },
    {
      "x": -5,
      "y": 132,
      "z": -1,
      "name": "Rock_Shale"
    },
    {
      "x": -5,
      "y": 133,
      "z": -1,
      "name": "Rock_Basalt"
    },
    {
      "x": -5,
      "y": 134,
      "z": -1,
      "name": "Rock_Basalt"
    },
    {
      "x": -5,
      "y": 135,
      "z": -1,
      "name": "Rock_Shale_Brick"
    },
    {
      "x": -5,
      "y": 136,
      "z": -1,
      "name": "Rock_Shale_Brick"
    },
    {
      "x": -5,
      "y": 137,
      "z": -1,
      "name": "Rock_Shale_Brick"
    },
    {
      "x": -5,
      "y": 138,
      "z": -1,
      "name": "Rock_Shale_Brick"
    },
    {
      "x": -5,
      "y": 139,
      "z": -1,
      "name": "Rock_Shale_Brick"
    },
    {
      "x": -5,
      "y": 140,
      "z": -1,
      "name": "Rock_Shale_Brick"
    },
    {
      "x": -5,
      "y": 141,
      "z": -1,
      "name": "Rock_Shale_Brick"
    },
    {
      "x": -5,
      "y": 142,
      "z": -1,
      "name": "Rock_Shale"
    },
    {
      "x": -5,
      "y": 143,
      "z": -1,
      "name": "Rock_Shale"
    },
    {
      "x": -5,
      "y": 144,
      "z": -1,
      "name": "Rock_Shale"
    },
    {
      "x": -5,
      "y": 145,
      "z": -1,
      "name": "Rock_Shale"
    },
    {
      "x": -5,
      "y": 146,
      "z": -1,
      "name": "Rock_Shale_Brick_Stairs",
      "rotation": 3
    },
    {
      "x": -5,
      "y": 129,
      "z": 0,
      "name": "Rock_Shale"
    },
    {
      "x": -5,
      "y": 130,
      "z": 0,
      "name": "Rock_Shale"
    },
    {
      "x": -5,
      "y": 131,
      "z": 0,
      "name": "Rock_Shale"
    },
    {
      "x": -5,
      "y": 132,
      "z": 0,
      "name": "Rock_Shale"
    },
    {
      "x": -5,
      "y": 133,
      "z": 0,
      "name": "Rock_Shale"
    },
    {
      "x": -5,
      "y": 134,
      "z": 0,
      "name": "Rock_Basalt"
    },
    {
      "x": -5,
      "y": 135,
      "z": 0,
      "name": "Rock_Shale_Brick"
    },
    {
      "x": -5,
      "y": 136,
      "z": 0,
      "name": "Rock_Shale_Brick"
    },
    {
      "x": -5,
      "y": 137,
      "z": 0,
      "name": "Rock_Shale_Brick"
    },
    {
      "x": -5,
      "y": 138,
      "z": 0,
      "name": "Rock_Shale_Brick"
    },
    {
      "x": -5,
      "y": 139,
      "z": 0,
      "name": "Rock_Shale_Brick"
    },
    {
      "x": -5,
      "y": 140,
      "z": 0,
      "name": "Rock_Shale_Brick"
    },
    {
      "x": -5,
      "y": 141,
      "z": 0,
      "name": "Rock_Shale_Brick"
    },
    {
      "x": -5,
      "y": 142,
      "z": 0,
      "name": "Rock_Shale"
    },
    {
      "x": -5,
      "y": 143,
      "z": 0,
      "name": "Rock_Shale"
    },
    {
      "x": -5,
      "y": 144,
      "z": 0,
      "name": "Rock_Shale"
    },
    {
      "x": -5,
      "y": 145,
      "z": 0,
      "name": "Rock_Shale"
    },
    {
      "x": -5,
      "y": 129,
      "z": 1,
      "name": "Rock_Shale_Brick"
    },
    {
      "x": -5,
      "y": 130,
      "z": 1,
      "name": "Rock_Shale"
    },
    {
      "x": -5,
      "y": 131,
      "z": 1,
      "name": "Rock_Shale"
    },
    {
      "x": -5,
      "y": 132,
      "z": 1,
      "name": "Rock_Shale"
    },
    {
      "x": -5,
      "y": 133,
      "z": 1,
      "name": "Rock_Shale"
    },
    {
      "x": -5,
      "y": 134,
      "z": 1,
      "name": "Rock_Shale"
    },
    {
      "x": -5,
      "y": 135,
      "z": 1,
      "name": "Rock_Shale_Brick"
    },
    {
      "x": -5,
      "y": 136,
      "z": 1,
      "name": "Rock_Shale_Brick"
    },
    {
      "x": -5,
      "y": 137,
      "z": 1,
      "name": "Rock_Shale_Brick"
    },
    {
      "x": -5,
      "y": 138,
      "z": 1,
      "name": "Rock_Shale_Brick"
    },
    {
      "x": -5,
      "y": 139,
      "z": 1,
      "name": "Rock_Shale_Brick"
    },
    {
      "x": -5,
      "y": 140,
      "z": 1,
      "name": "Rock_Shale_Brick"
    },
    {
      "x": -5,
      "y": 141,
      "z": 1,
      "name": "Rock_Shale_Brick"
    },
    {
      "x": -5,
      "y": 142,
      "z": 1,
      "name": "Rock_Shale"
    },
    {
      "x": -5,
      "y": 143,
      "z": 1,
      "name": "Rock_Shale"
    },
    {
      "x": -5,
      "y": 144,
      "z": 1,
      "name": "Rock_Shale"
    },
    {
      "x": -5,
      "y": 145,
      "z": 1,
      "name": "Rock_Shale"
    },
    {
      "x": -5,
      "y": 129,
      "z": 2,
      "name": "Rock_Shale_Brick"
    },
    {
      "x": -5,
      "y": 130,
      "z": 2,
      "name": "Rock_Shale_Brick"
    },
    {
      "x": -5,
      "y": 131,
      "z": 2,
      "name": "Rock_Shale"
    },
    {
      "x": -5,
      "y": 132,
      "z": 2,
      "name": "Rock_Shale"
    },
    {
      "x": -5,
      "y": 133,
      "z": 2,
      "name": "Rock_Shale"
    },
    {
      "x": -5,
      "y": 134,
      "z": 2,
      "name": "Rock_Shale"
    },
    {
      "x": -5,
      "y": 135,
      "z": 2,
      "name": "Rock_Shale_Brick"
    },
    {
      "x": -5,
      "y": 136,
      "z": 2,
      "name": "Rock_Shale_Brick"
    },
    {
      "x": -5,
      "y": 137,
      "z": 2,
      "name": "Rock_Shale_Brick"
    },
    {
      "x": -5,
      "y": 138,
      "z": 2,
      "name": "Rock_Shale_Brick"
    },
    {
      "x": -5,
      "y": 139,
      "z": 2,
      "name": "Rock_Shale_Brick"
    },
    {
      "x": -5,
      "y": 140,
      "z": 2,
      "name": "Rock_Shale_Brick"
    },
    {
      "x": -5,
      "y": 141,
      "z": 2,
      "name": "Rock_Shale_Brick"
    },
    {
      "x": -5,
      "y": 142,
      "z": 2,
      "name": "Rock_Shale"
    },
    {
      "x": -5,
      "y": 143,
      "z": 2,
      "name": "Rock_Shale"
    },
    {
      "x": -5,
      "y": 144,
      "z": 2,
      "name": "Rock_Shale"
    },
    {
      "x": -5,
      "y": 145,
      "z": 2,
      "name": "Rock_Shale"
    },
    {
      "x": -5,
      "y": 129,
      "z": 3,
      "name": "Rock_Shale_Brick"
    },
    {
      "x": -5,
      "y": 130,
      "z": 3,
      "name": "Rock_Shale_Brick"
    },
    {
      "x": -5,
      "y": 131,
      "z": 3,
      "name": "Rock_Shale_Brick"
    },
    {
      "x": -5,
      "y": 132,
      "z": 3,
      "name": "Rock_Shale"
    },
    {
      "x": -5,
      "y": 133,
      "z": 3,
      "name": "Rock_Shale"
    },
    {
      "x": -5,
      "y": 134,
      "z": 3,
      "name": "Rock_Shale"
    },
    {
      "x": -5,
      "y": 135,
      "z": 3,
      "name": "Rock_Shale_Brick"
    },
    {
      "x": -5,
      "y": 136,
      "z": 3,
      "name": "Rock_Shale_Brick"
    },
    {
      "x": -5,
      "y": 137,
      "z": 3,
      "name": "Rock_Shale_Brick"
    },
    {
      "x": -5,
      "y": 138,
      "z": 3,
      "name": "Rock_Shale_Brick"
    },
    {
      "x": -5,
      "y": 139,
      "z": 3,
      "name": "Rock_Shale_Brick"
    },
    {
      "x": -5,
      "y": 140,
      "z": 3,
      "name": "Rock_Shale_Brick"
    },
    {
      "x": -5,
      "y": 141,
      "z": 3,
      "name": "Rock_Shale_Brick"
    },
    {
      "x": -5,
      "y": 142,
      "z": 3,
      "name": "Rock_Shale"
    },
    {
      "x": -5,
      "y": 143,
      "z": 3,
      "name": "Rock_Shale"
    },
    {
      "x": -5,
      "y": 144,
      "z": 3,
      "name": "Rock_Shale"
    },
    {
      "x": -5,
      "y": 145,
      "z": 3,
      "name": "Rock_Shale"
    },
    {
      "x": -5,
      "y": 129,
      "z": 4,
      "name": "Rock_Shale_Brick"
    },
    {
      "x": -5,
      "y": 130,
      "z": 4,
      "name": "Rock_Shale_Brick"
    },
    {
      "x": -5,
      "y": 131,
      "z": 4,
      "name": "Rock_Shale_Brick"
    },
    {
      "x": -5,
      "y": 132,
      "z": 4,
      "name": "Rock_Shale_Brick"
    },
    {
      "x": -5,
      "y": 133,
      "z": 4,
      "name": "Rock_Shale"
    },
    {
      "x": -5,
      "y": 134,
      "z": 4,
      "name": "Rock_Shale"
    },
    {
      "x": -5,
      "y": 135,
      "z": 4,
      "name": "Rock_Shale_Brick"
    },
    {
      "x": -5,
      "y": 136,
      "z": 4,
      "name": "Rock_Shale_Brick"
    },
    {
      "x": -5,
      "y": 137,
      "z": 4,
      "name": "Rock_Shale_Brick"
    },
    {
      "x": -5,
      "y": 138,
      "z": 4,
      "name": "Rock_Shale_Brick"
    },
    {
      "x": -5,
      "y": 139,
      "z": 4,
      "name": "Rock_Shale_Brick"
    },
    {
      "x": -5,
      "y": 140,
      "z": 4,
      "name": "Rock_Shale_Brick"
    },
    {
      "x": -5,
      "y": 141,
      "z": 4,
      "name": "Rock_Shale_Brick"
    },
    {
      "x": -5,
      "y": 142,
      "z": 4,
      "name": "Rock_Shale"
    },
    {
      "x": -5,
      "y": 143,
      "z": 4,
      "name": "Rock_Shale"
    },
    {
      "x": -5,
      "y": 144,
      "z": 4,
      "name": "Rock_Shale"
    },
    {
      "x": -5,
      "y": 145,
      "z": 4,
      "name": "Rock_Shale"
    },
    {
      "x": -5,
      "y": 146,
      "z": 4,
      "name": "Rock_Shale_Brick_Stairs",
      "rotation": 3
    },
    {
      "x": -5,
      "y": 129,
      "z": 5,
      "name": "Rock_Shale"
    },
    {
      "x": -5,
      "y": 130,
      "z": 5,
      "name": "Rock_Shale"
    },
    {
      "x": -5,
      "y": 131,
      "z": 5,
      "name": "Rock_Shale"
    },
    {
      "x": -5,
      "y": 132,
      "z": 5,
      "name": "Rock_Shale"
    },
    {
      "x": -5,
      "y": 133,
      "z": 5,
      "name": "Rock_Shale"
    },
    {
      "x": -5,
      "y": 134,
      "z": 5,
      "name": "Rock_Shale"
    },
    {
      "x": -5,
      "y": 135,
      "z": 5,
      "name": "Rock_Shale_Brick"
    },
    {
      "x": -5,
      "y": 136,
      "z": 5,
      "name": "Rock_Shale_Brick"
    },
    {
      "x": -5,
      "y": 137,
      "z": 5,
      "name": "Rock_Shale_Brick"
    },
    {
      "x": -5,
      "y": 138,
      "z": 5,
      "name": "Rock_Shale_Brick"
    },
    {
      "x": -5,
      "y": 139,
      "z": 5,
      "name": "Rock_Shale_Brick"
    },
    {
      "x": -5,
      "y": 140,
      "z": 5,
      "name": "Rock_Shale_Brick"
    },
    {
      "x": -5,
      "y": 141,
      "z": 5,
      "name": "Rock_Shale_Brick"
    },
    {
      "x": -5,
      "y": 142,
      "z": 5,
      "name": "Rock_Shale"
    },
    {
      "x": -5,
      "y": 143,
      "z": 5,
      "name": "Rock_Shale"
    },
    {
      "x": -5,
      "y": 144,
      "z": 5,
      "name": "Rock_Shale"
    },
    {
      "x": -5,
      "y": 145,
      "z": 5,
      "name": "Rock_Shale"
    },
    {
      "x": -5,
      "y": 129,
      "z": 6,
      "name": "Rock_Shale_Brick"
    },
    {
      "x": -5,
      "y": 130,
      "z": 6,
      "name": "Rock_Shale_Brick"
    },
    {
      "x": -5,
      "y": 131,
      "z": 6,
      "name": "Rock_Shale_Brick"
    },
    {
      "x": -5,
      "y": 132,
      "z": 6,
      "name": "Rock_Shale_Brick"
    },
    {
      "x": -5,
      "y": 133,
      "z": 6,
      "name": "Rock_Shale_Brick"
    },
    {
      "x": -5,
      "y": 134,
      "z": 6,
      "name": "Rock_Shale_Brick"
    },
    {
      "x": -5,
      "y": 135,
      "z": 6,
      "name": "Rock_Shale_Brick"
    },
    {
      "x": -5,
      "y": 136,
      "z": 6,
      "name": "Rock_Shale_Brick"
    },
    {
      "x": -5,
      "y": 137,
      "z": 6,
      "name": "Rock_Shale_Brick"
    },
    {
      "x": -5,
      "y": 138,
      "z": 6,
      "name": "Rock_Shale_Brick"
    },
    {
      "x": -5,
      "y": 139,
      "z": 6,
      "name": "Rock_Shale_Brick"
    },
    {
      "x": -5,
      "y": 140,
      "z": 6,
      "name": "Rock_Shale_Brick"
    },
    {
      "x": -5,
      "y": 141,
      "z": 6,
      "name": "Rock_Shale_Brick"
    },
    {
      "x": -5,
      "y": 142,
      "z": 6,
      "name": "Rock_Shale"
    },
    {
      "x": -5,
      "y": 143,
      "z": 6,
      "name": "Rock_Shale"
    },
    {
      "x": -5,
      "y": 144,
      "z": 6,
      "name": "Rock_Shale"
    },
    {
      "x": -5,
      "y": 145,
      "z": 6,
      "name": "Rock_Shale"
    },
    {
      "x": -5,
      "y": 129,
      "z": 7,
      "name": "Rock_Shale_Brick"
    },
    {
      "x": -5,
      "y": 130,
      "z": 7,
      "name": "Rock_Shale_Brick"
    },
    {
      "x": -5,
      "y": 131,
      "z": 7,
      "name": "Rock_Shale_Brick"
    },
    {
      "x": -5,
      "y": 132,
      "z": 7,
      "name": "Rock_Shale_Brick"
    },
    {
      "x": -5,
      "y": 133,
      "z": 7,
      "name": "Rock_Shale_Brick"
    },
    {
      "x": -5,
      "y": 134,
      "z": 7,
      "name": "Rock_Shale_Brick"
    },
    {
      "x": -5,
      "y": 135,
      "z": 7,
      "name": "Rock_Shale_Brick_Pillar_Base"
    },
    {
      "x": -5,
      "y": 136,
      "z": 7,
      "name": "Rock_Shale_Brick_Pillar_Middle"
    },
    {
      "x": -5,
      "y": 137,
      "z": 7,
      "name": "Rock_Shale_Brick_Pillar_Middle"
    },
    {
      "x": -5,
      "y": 138,
      "z": 7,
      "name": "Rock_Shale_Brick_Pillar_Middle"
    },
    {
      "x": -5,
      "y": 139,
      "z": 7,
      "name": "Rock_Shale_Brick_Pillar_Base",
      "rotation": 8
    },
    {
      "x": -5,
      "y": 140,
      "z": 7,
      "name": "Rock_Shale_Brick"
    },
    {
      "x": -5,
      "y": 141,
      "z": 7,
      "name": "Rock_Shale_Brick"
    },
    {
      "x": -5,
      "y": 142,
      "z": 7,
      "name": "Rock_Shale"
    },
    {
      "x": -5,
      "y": 143,
      "z": 7,
      "name": "Rock_Shale"
    },
    {
      "x": -5,
      "y": 144,
      "z": 7,
      "name": "Rock_Shale"
    },
    {
      "x": -5,
      "y": 145,
      "z": 7,
      "name": "Rock_Shale"
    },
    {
      "x": -5,
      "y": 140,
      "z": 8,
      "name": "Rock_Shale_Brick_Stairs",
      "rotation": 10
    },
    {
      "x": -5,
      "y": 141,
      "z": 8,
      "name": "Rock_Shale_Brick"
    },
    {
      "x": -5,
      "y": 143,
      "z": 8,
      "name": "Rock_Shale"
    },
    {
      "x": -5,
      "y": 144,
      "z": 8,
      "name": "Rock_Shale"
    },
    {
      "x": -5,
      "y": 141,
      "z": 9,
      "name": "Rock_Shale_Brick"
    },
    {
      "x": -5,
      "y": 150,
      "z": 48,
      "name": "Rock_Shale"
    },
    {
      "x": -4,
      "y": 150,
      "z": -246,
      "name": "Rock_Shale"
    },
    {
      "x": -4,
      "y": 124,
      "z": -8,
      "name": "Rock_Shale_Brick_Smooth"
    },
    {
      "x": -4,
      "y": 125,
      "z": -8,
      "name": "Empty"
    },
    {
      "x": -4,
      "y": 126,
      "z": -8,
      "name": "Empty"
    },
    {
      "x": -4,
      "y": 127,
      "z": -8,
      "name": "Empty"
    },
    {
      "x": -4,
      "y": 128,
      "z": -8,
      "name": "Empty"
    },
    {
      "x": -4,
      "y": 129,
      "z": -8,
      "name": "Rock_Shale_Brick"
    },
    {
      "x": -4,
      "y": 130,
      "z": -8,
      "name": "Rock_Shale"
    },
    {
      "x": -4,
      "y": 131,
      "z": -8,
      "name": "Empty"
    },
    {
      "x": -4,
      "y": 132,
      "z": -8,
      "name": "Empty"
    },
    {
      "x": -4,
      "y": 133,
      "z": -8,
      "name": "Empty"
    },
    {
      "x": -4,
      "y": 134,
      "z": -8,
      "name": "Empty"
    },
    {
      "x": -4,
      "y": 135,
      "z": -8,
      "name": "Empty"
    },
    {
      "x": -4,
      "y": 136,
      "z": -8,
      "name": "Empty"
    },
    {
      "x": -4,
      "y": 137,
      "z": -8,
      "name": "Empty"
    },
    {
      "x": -4,
      "y": 138,
      "z": -8,
      "name": "Empty"
    },
    {
      "x": -4,
      "y": 139,
      "z": -8,
      "name": "Empty"
    },
    {
      "x": -4,
      "y": 140,
      "z": -8,
      "name": "Empty"
    },
    {
      "x": -4,
      "y": 141,
      "z": -8,
      "name": "Empty"
    },
    {
      "x": -4,
      "y": 142,
      "z": -8,
      "name": "Empty"
    },
    {
      "x": -4,
      "y": 143,
      "z": -8,
      "name": "Empty"
    },
    {
      "x": -4,
      "y": 124,
      "z": -7,
      "name": "Rock_Shale_Brick_Smooth"
    },
    {
      "x": -4,
      "y": 125,
      "z": -7,
      "name": "Empty"
    },
    {
      "x": -4,
      "y": 126,
      "z": -7,
      "name": "Empty"
    },
    {
      "x": -4,
      "y": 127,
      "z": -7,
      "name": "Empty"
    },
    {
      "x": -4,
      "y": 128,
      "z": -7,
      "name": "Rock_Shale_Brick_Stairs",
      "rotation": 8
    },
    {
      "x": -4,
      "y": 129,
      "z": -7,
      "name": "Rock_Shale_Brick"
    },
    {
      "x": -4,
      "y": 130,
      "z": -7,
      "name": "Rock_Shale"
    },
    {
      "x": -4,
      "y": 131,
      "z": -7,
      "name": "Empty"
    },
    {
      "x": -4,
      "y": 132,
      "z": -7,
      "name": "Empty"
    },
    {
      "x": -4,
      "y": 133,
      "z": -7,
      "name": "Empty"
    },
    {
      "x": -4,
      "y": 134,
      "z": -7,
      "name": "Empty"
    },
    {
      "x": -4,
      "y": 135,
      "z": -7,
      "name": "Empty"
    },
    {
      "x": -4,
      "y": 136,
      "z": -7,
      "name": "Empty"
    },
    {
      "x": -4,
      "y": 137,
      "z": -7,
      "name": "Empty"
    },
    {
      "x": -4,
      "y": 138,
      "z": -7,
      "name": "Empty"
    },
    {
      "x": -4,
      "y": 139,
      "z": -7,
      "name": "Empty"
    },
    {
      "x": -4,
      "y": 140,
      "z": -7,
      "name": "Empty"
    },
    {
      "x": -4,
      "y": 141,
      "z": -7,
      "name": "Empty"
    },
    {
      "x": -4,
      "y": 142,
      "z": -7,
      "name": "Empty"
    },
    {
      "x": -4,
      "y": 143,
      "z": -7,
      "name": "Empty"
    },
    {
      "x": -4,
      "y": 124,
      "z": -6,
      "name": "Rock_Shale_Brick_Smooth"
    },
    {
      "x": -4,
      "y": 125,
      "z": -6,
      "name": "Rock_Shale_Brick_Pillar_Base"
    },
    {
      "x": -4,
      "y": 126,
      "z": -6,
      "name": "Rock_Shale_Brick_Pillar_Middle"
    },
    {
      "x": -4,
      "y": 127,
      "z": -6,
      "name": "Rock_Shale_Brick_Pillar_Base",
      "rotation": 8
    },
    {
      "x": -4,
      "y": 128,
      "z": -6,
      "name": "Rock_Shale_Brick"
    },
    {
      "x": -4,
      "y": 129,
      "z": -6,
      "name": "Rock_Shale_Brick"
    },
    {
      "x": -4,
      "y": 130,
      "z": -6,
      "name": "Rock_Shale_Brick"
    },
    {
      "x": -4,
      "y": 131,
      "z": -6,
      "name": "Rock_Shale"
    },
    {
      "x": -4,
      "y": 132,
      "z": -6,
      "name": "Empty"
    },
    {
      "x": -4,
      "y": 133,
      "z": -6,
      "name": "Empty"
    },
    {
      "x": -4,
      "y": 134,
      "z": -6,
      "name": "Empty"
    },
    {
      "x": -4,
      "y": 135,
      "z": -6,
      "name": "Empty"
    },
    {
      "x": -4,
      "y": 136,
      "z": -6,
      "name": "Empty"
    },
    {
      "x": -4,
      "y": 137,
      "z": -6,
      "name": "Empty"
    },
    {
      "x": -4,
      "y": 138,
      "z": -6,
      "name": "Empty"
    },
    {
      "x": -4,
      "y": 139,
      "z": -6,
      "name": "Empty"
    },
    {
      "x": -4,
      "y": 140,
      "z": -6,
      "name": "Empty"
    },
    {
      "x": -4,
      "y": 141,
      "z": -6,
      "name": "Empty"
    },
    {
      "x": -4,
      "y": 142,
      "z": -6,
      "name": "Empty"
    },
    {
      "x": -4,
      "y": 143,
      "z": -6,
      "name": "Empty"
    },
    {
      "x": -4,
      "y": 124,
      "z": -5,
      "name": "Rock_Shale_Brick_Smooth"
    },
    {
      "x": -4,
      "y": 125,
      "z": -5,
      "name": "Rock_Shale_Brick"
    },
    {
      "x": -4,
      "y": 126,
      "z": -5,
      "name": "Empty"
    },
    {
      "x": -4,
      "y": 127,
      "z": -5,
      "name": "Empty"
    },
    {
      "x": -4,
      "y": 128,
      "z": -5,
      "name": "Empty"
    },
    {
      "x": -4,
      "y": 129,
      "z": -5,
      "name": "Empty"
    },
    {
      "x": -4,
      "y": 130,
      "z": -5,
      "name": "Rock_Shale_Brick_Stairs",
      "rotation": 10
    },
    {
      "x": -4,
      "y": 131,
      "z": -5,
      "name": "Rock_Shale_Brick"
    },
    {
      "x": -4,
      "y": 132,
      "z": -5,
      "name": "Rock_Shale"
    },
    {
      "x": -4,
      "y": 133,
      "z": -5,
      "name": "Empty"
    },
    {
      "x": -4,
      "y": 134,
      "z": -5,
      "name": "Empty"
    },
    {
      "x": -4,
      "y": 135,
      "z": -5,
      "name": "Empty"
    },
    {
      "x": -4,
      "y": 136,
      "z": -5,
      "name": "Empty"
    },
    {
      "x": -4,
      "y": 137,
      "z": -5,
      "name": "Empty"
    },
    {
      "x": -4,
      "y": 138,
      "z": -5,
      "name": "Empty"
    },
    {
      "x": -4,
      "y": 139,
      "z": -5,
      "name": "Empty"
    },
    {
      "x": -4,
      "y": 140,
      "z": -5,
      "name": "Empty"
    },
    {
      "x": -4,
      "y": 141,
      "z": -5,
      "name": "Rock_Shale"
    },
    {
      "x": -4,
      "y": 142,
      "z": -5,
      "name": "Rock_Shale"
    },
    {
      "x": -4,
      "y": 143,
      "z": -5,
      "name": "Rock_Shale"
    },
    {
      "x": -4,
      "y": 145,
      "z": -5,
      "name": "Rock_Shale"
    },
    {
      "x": -4,
      "y": 146,
      "z": -5,
      "name": "Rock_Shale"
    },
    {
      "x": -4,
      "y": 125,
      "z": -4,
      "name": "Rock_Shale_Brick"
    },
    {
      "x": -4,
      "y": 126,
      "z": -4,
      "name": "Rock_Shale_Brick"
    },
    {
      "x": -4,
      "y": 127,
      "z": -4,
      "name": "Empty"
    },
    {
      "x": -4,
      "y": 128,
      "z": -4,
      "name": "Empty"
    },
    {
      "x": -4,
      "y": 129,
      "z": -4,
      "name": "Empty"
    },
    {
      "x": -4,
      "y": 130,
      "z": -4,
      "name": "Empty"
    },
    {
      "x": -4,
      "y": 131,
      "z": -4,
      "name": "Rock_Shale_Brick_Stairs",
      "rotation": 10
    },
    {
      "x": -4,
      "y": 132,
      "z": -4,
      "name": "Rock_Shale_Brick"
    },
    {
      "x": -4,
      "y": 133,
      "z": -4,
      "name": "Rock_Shale"
    },
    {
      "x": -4,
      "y": 134,
      "z": -4,
      "name": "Rock_Shale_Brick"
    },
    {
      "x": -4,
      "y": 135,
      "z": -4,
      "name": "Rock_Shale_Brick"
    },
    {
      "x": -4,
      "y": 136,
      "z": -4,
      "name": "Deco_Bone_Pile"
    },
    {
      "x": -4,
      "y": 137,
      "z": -4,
      "name": "Rock_Shale_Brick"
    },
    {
      "x": -4,
      "y": 138,
      "z": -4,
      "name": "Deco_Bone_Skulls"
    },
    {
      "x": -4,
      "y": 139,
      "z": -4,
      "name": "Rock_Shale_Brick"
    },
    {
      "x": -4,
      "y": 140,
      "z": -4,
      "name": "Empty"
    },
    {
      "x": -4,
      "y": 141,
      "z": -4,
      "name": "Rock_Shale"
    },
    {
      "x": -4,
      "y": 142,
      "z": -4,
      "name": "Rock_Shale"
    },
    {
      "x": -4,
      "y": 143,
      "z": -4,
      "name": "Rock_Shale"
    },
    {
      "x": -4,
      "y": 144,
      "z": -4,
      "name": "Rock_Shale"
    },
    {
      "x": -4,
      "y": 145,
      "z": -4,
      "name": "Rock_Shale"
    },
    {
      "x": -4,
      "y": 146,
      "z": -4,
      "name": "Rock_Shale"
    },
    {
      "x": -4,
      "y": 125,
      "z": -3,
      "name": "Empty"
    },
    {
      "x": -4,
      "y": 126,
      "z": -3,
      "name": "Rock_Shale_Brick"
    },
    {
      "x": -4,
      "y": 127,
      "z": -3,
      "name": "Rock_Shale_Brick"
    },
    {
      "x": -4,
      "y": 128,
      "z": -3,
      "name": "Empty"
    },
    {
      "x": -4,
      "y": 129,
      "z": -3,
      "name": "Empty"
    },
    {
      "x": -4,
      "y": 130,
      "z": -3,
      "name": "Empty"
    },
    {
      "x": -4,
      "y": 131,
      "z": -3,
      "name": "Empty"
    },
    {
      "x": -4,
      "y": 132,
      "z": -3,
      "name": "Rock_Shale_Brick_Stairs",
      "rotation": 10
    },
    {
      "x": -4,
      "y": 133,
      "z": -3,
      "name": "Rock_Shale_Brick"
    },
    {
      "x": -4,
      "y": 134,
      "z": -3,
      "name": "Rock_Shale"
    },
    {
      "x": -4,
      "y": 135,
      "z": -3,
      "name": "Rock_Shale_Brick"
    },
    {
      "x": -4,
      "y": 136,
      "z": -3,
      "name": "Rock_Shale_Cobble"
    },
    {
      "x": -4,
      "y": 137,
      "z": -3,
      "name": "Rock_Shale_Cobble"
    },
    {
      "x": -4,
      "y": 138,
      "z": -3,
      "name": "Rock_Shale_Cobble"
    },
    {
      "x": -4,
      "y": 139,
      "z": -3,
      "name": "Rock_Shale_Cobble"
    },
    {
      "x": -4,
      "y": 140,
      "z": -3,
      "name": "Rock_Shale_Cobble"
    },
    {
      "x": -4,
      "y": 141,
      "z": -3,
      "name": "Rock_Shale_Brick"
    },
    {
      "x": -4,
      "y": 142,
      "z": -3,
      "name": "Rock_Shale"
    },
    {
      "x": -4,
      "y": 143,
      "z": -3,
      "name": "Rock_Shale"
    },
    {
      "x": -4,
      "y": 144,
      "z": -3,
      "name": "Rock_Shale"
    },
    {
      "x": -4,
      "y": 145,
      "z": -3,
      "name": "Rock_Shale"
    },
    {
      "x": -4,
      "y": 146,
      "z": -3,
      "name": "Rock_Shale"
    },
    {
      "x": -4,
      "y": 125,
      "z": -2,
      "name": "Empty"
    },
    {
      "x": -4,
      "y": 126,
      "z": -2,
      "name": "Empty"
    },
    {
      "x": -4,
      "y": 127,
      "z": -2,
      "name": "Rock_Shale_Brick"
    },
    {
      "x": -4,
      "y": 128,
      "z": -2,
      "name": "Rock_Shale_Brick_Pillar_Base"
    },
    {
      "x": -4,
      "y": 129,
      "z": -2,
      "name": "Rock_Shale_Brick_Pillar_Middle"
    },
    {
      "x": -4,
      "y": 130,
      "z": -2,
      "name": "Rock_Shale_Brick_Pillar_Middle"
    },
    {
      "x": -4,
      "y": 131,
      "z": -2,
      "name": "Rock_Shale_Brick_Pillar_Base",
      "rotation": 8
    },
    {
      "x": -4,
      "y": 132,
      "z": -2,
      "name": "Rock_Shale_Brick"
    },
    {
      "x": -4,
      "y": 133,
      "z": -2,
      "name": "Rock_Shale_Brick"
    },
    {
      "x": -4,
      "y": 134,
      "z": -2,
      "name": "Rock_Shale_Brick"
    },
    {
      "x": -4,
      "y": 135,
      "z": -2,
      "name": "Rock_Shale"
    },
    {
      "x": -4,
      "y": 136,
      "z": -2,
      "name": "Rock_Shale_Brick"
    },
    {
      "x": -4,
      "y": 137,
      "z": -2,
      "name": "Rock_Shale_Brick"
    },
    {
      "x": -4,
      "y": 138,
      "z": -2,
      "name": "Rock_Shale_Brick"
    },
    {
      "x": -4,
      "y": 139,
      "z": -2,
      "name": "Rock_Shale_Brick"
    },
    {
      "x": -4,
      "y": 140,
      "z": -2,
      "name": "Rock_Shale_Brick"
    },
    {
      "x": -4,
      "y": 141,
      "z": -2,
      "name": "Rock_Shale_Brick"
    },
    {
      "x": -4,
      "y": 142,
      "z": -2,
      "name": "Rock_Shale"
    },
    {
      "x": -4,
      "y": 143,
      "z": -2,
      "name": "Rock_Shale"
    },
    {
      "x": -4,
      "y": 144,
      "z": -2,
      "name": "Rock_Shale"
    },
    {
      "x": -4,
      "y": 145,
      "z": -2,
      "name": "Rock_Shale"
    },
    {
      "x": -4,
      "y": 146,
      "z": -2,
      "name": "Rock_Shale"
    },
    {
      "x": -4,
      "y": 125,
      "z": -1,
      "name": "Empty"
    },
    {
      "x": -4,
      "y": 126,
      "z": -1,
      "name": "Empty"
    },
    {
      "x": -4,
      "y": 127,
      "z": -1,
      "name": "Empty"
    },
    {
      "x": -4,
      "y": 128,
      "z": -1,
      "name": "Rock_Shale_Brick"
    },
    {
      "x": -4,
      "y": 129,
      "z": -1,
      "name": "Rock_Shale_Brick"
    },
    {
      "x": -4,
      "y": 130,
      "z": -1,
      "name": "Empty"
    },
    {
      "x": -4,
      "y": 131,
      "z": -1,
      "name": "Empty"
    },
    {
      "x": -4,
      "y": 132,
      "z": -1,
      "name": "Empty"
    },
    {
      "x": -4,
      "y": 133,
      "z": -1,
      "name": "Empty"
    },
    {
      "x": -4,
      "y": 134,
      "z": -1,
      "name": "Rock_Shale_Brick_Stairs",
      "rotation": 10
    },
    {
      "x": -4,
      "y": 135,
      "z": -1,
      "name": "Rock_Shale_Brick"
    },
    {
      "x": -4,
      "y": 136,
      "z": -1,
      "name": "Rock_Shale"
    },
    {
      "x": -4,
      "y": 137,
      "z": -1,
      "name": "Rock_Shale_Brick"
    },
    {
      "x": -4,
      "y": 138,
      "z": -1,
      "name": "Rock_Shale_Brick"
    },
    {
      "x": -4,
      "y": 139,
      "z": -1,
      "name": "Rock_Shale_Brick"
    },
    {
      "x": -4,
      "y": 140,
      "z": -1,
      "name": "Rock_Shale_Brick"
    },
    {
      "x": -4,
      "y": 141,
      "z": -1,
      "name": "Rock_Shale_Brick"
    },
    {
      "x": -4,
      "y": 142,
      "z": -1,
      "name": "Rock_Shale"
    },
    {
      "x": -4,
      "y": 143,
      "z": -1,
