{
  "version": 8,
  "blockIdVersion": 11,
  "anchorX": 2,
  "anchorY": 0,
  "anchorZ": 7,
  "blocks": [
    {
      "x": -7,
      "y": 0,
      "z": -7,
      "name": "Rock_Shale_Brick_Smooth"
    },
    {
      "x": -7,
      "y": 1,
      "z": -7,
      "name": "Rock_Shale_Brick"
    },
    {
      "x": -7,
      "y": 2,
      "z": -7,
      "name": "Rock_Shale_Brick"
    },
    {
      "x": -7,
      "y": 3,
      "z": -7,
      "name": "Rock_Shale_Brick"
    },
    {
      "x": -7,
      "y": 4,
      "z": -7,
      "name": "Rock_Shale_Brick"
    },
    {
      "x": -7,
      "y": 5,
      "z": -7,
      "name": "Rock_Shale_Brick"
    },
    {
      "x": -7,
      "y": 6,
      "z": -7,
      "name": "Rock_Shale_Brick"
    },
    {
      "x": -7,
      "y": 7,
      "z": -7,
      "name": "Rock_Basalt"
    },
    {
      "x": -7,
      "y": 0,
      "z": -6,
      "name": "Rock_Shale_Brick_Smooth"
    },
    {
      "x": -7,
      "y": 1,
      "z": -6,
      "name": "Rock_Shale_Brick_Smooth"
    },
    {
      "x": -7,
      "y": 2,
      "z": -6,
      "name": "Rock_Shale_Brick_Pillar_Base"
    },
    {
      "x": -7,
      "y": 3,
      "z": -6,
      "name": "Rock_Shale_Brick_Pillar_Middle"
    },
    {
      "x": -7,
      "y": 4,
      "z": -6,
      "name": "Rock_Shale_Brick_Pillar_Base",
      "rotation": 8
    },
    {
      "x": -7,
      "y": 5,
      "z": -6,
      "name": "Rock_Shale_Brick"
    },
    {
      "x": -7,
      "y": 6,
      "z": -6,
      "name": "Rock_Shale_Brick"
    },
    {
      "x": -7,
      "y": 7,
      "z": -6,
      "name": "Rock_Basalt"
    },
    {
      "x": -7,
      "y": 0,
      "z": -5,
      "name": "Rock_Shale_Brick_Smooth"
    },
    {
      "x": -7,
      "y": 6,
      "z": -5,
      "name": "Rock_Shale_Brick_Stairs",
      "rotation": 10
    },
    {
      "x": -7,
      "y": 7,
      "z": -5,
      "name": "Rock_Basalt"
    },
    {
      "x": -7,
      "y": 0,
      "z": -4,
      "name": "Soil_Dirt_Cold"
    },
    {
      "x": -7,
      "y": 7,
      "z": -4,
      "name": "Rock_Basalt"
    },
    {
      "x": -7,
      "y": 0,
      "z": -3,
      "name": "Rock_Shale"
    },
    {
      "x": -7,
      "y": 7,
      "z": -3,
      "name": "Rock_Basalt"
    },
    {
      "x": -7,
      "y": 0,
      "z": -2,
      "name": "Rock_Shale"
    },
    {
      "x": -7,
      "y": 7,
      "z": -2,
      "name": "Rock_Basalt"
    },
    {
      "x": -7,
      "y": 0,
      "z": -1,
      "name": "Rock_Shale"
    },
    {
      "x": -7,
      "y": 7,
      "z": -1,
      "name": "Rock_Basalt"
    },
    {
      "x": -7,
      "y": 0,
      "z": 0,
      "name": "Rock_Shale"
    },
    {
      "x": -7,
      "y": 6,
      "z": 0,
      "name": "Plant_Bush_Dead_Hanging"
    },
    {
      "x": -7,
      "y": 7,
      "z": 0,
      "name": "Rock_Basalt"
    },
    {
      "x": -7,
      "y": 0,
      "z": 1,
      "name": "Rock_Shale_Brick_Smooth"
    },
    {
      "x": -7,
      "y": 6,
      "z": 1,
      "name": "Rock_Shale_Brick_Stairs",
      "rotation": 8
    },
    {
      "x": -7,
      "y": 7,
      "z": 1,
      "name": "Rock_Basalt"
    },
    {
      "x": -7,
      "y": 0,
      "z": 2,
      "name": "Rock_Shale_Brick_Smooth"
    },
    {
      "x": -7,
      "y": 1,
      "z": 2,
      "name": "Rock_Shale_Brick_Smooth"
    },
    {
      "x": -7,
      "y": 2,
      "z": 2,
      "name": "Rock_Shale_Brick_Pillar_Base"
    },
    {
      "x": -7,
      "y": 3,
      "z": 2,
      "name": "Rock_Shale_Brick_Pillar_Middle"
    },
    {
      "x": -7,
      "y": 4,
      "z": 2,
      "name": "Rock_Shale_Brick_Pillar_Base",
      "rotation": 8
    },
    {
      "x": -7,
      "y": 5,
      "z": 2,
      "name": "Rock_Shale_Brick"
    },
    {
      "x": -7,
      "y": 6,
      "z": 2,
      "name": "Rock_Shale_Brick"
    },
    {
      "x": -7,
      "y": 7,
      "z": 2,
      "name": "Rock_Basalt"
    },
    {
      "x": -7,
      "y": 0,
      "z": 3,
      "name": "Rock_Shale_Brick_Smooth"
    },
    {
      "x": -7,
      "y": 1,
      "z": 3,
      "name": "Rock_Shale_Brick"
    },
    {
      "x": -7,
      "y": 2,
      "z": 3,
      "name": "Rock_Shale_Brick"
    },
    {
      "x": -7,
      "y": 3,
      "z": 3,
      "name": "Rock_Shale_Brick"
    },
    {
      "x": -7,
      "y": 4,
      "z": 3,
      "name": "Rock_Shale_Brick"
    },
    {
      "x": -7,
      "y": 5,
      "z": 3,
      "name": "Rock_Shale_Brick"
    },
    {
      "x": -7,
      "y": 6,
      "z": 3,
      "name": "Rock_Shale_Brick"
    },
    {
      "x": -7,
      "y": 7,
      "z": 3,
      "name": "Rock_Basalt"
    },
    {
      "x": -6,
      "y": 0,
      "z": -7,
      "name": "Rock_Shale_Brick_Smooth"
    },
    {
      "x": -6,
      "y": 1,
      "z": -7,
      "name": "Rock_Shale"
    },
    {
      "x": -6,
      "y": 2,
      "z": -7,
      "name": "Rock_Shale"
    },
    {
      "x": -6,
      "y": 3,
      "z": -7,
      "name": "Rock_Shale"
    },
    {
      "x": -6,
      "y": 4,
      "z": -7,
      "name": "Rock_Shale"
    },
    {
      "x": -6,
      "y": 5,
      "z": -7,
      "name": "Rock_Basalt"
    },
    {
      "x": -6,
      "y": 6,
      "z": -7,
      "name": "Rock_Basalt"
    },
    {
      "x": -6,
      "y": 7,
      "z": -7,
      "name": "Rock_Basalt"
    },
    {
      "x": -6,
      "y": 0,
      "z": -6,
      "name": "Rock_Shale_Brick_Smooth"
    },
    {
      "x": -6,
      "y": 1,
      "z": -6,
      "name": "Rock_Shale_Brick_Stairs",
      "rotation": 10
    },
    {
      "x": -6,
      "y": 2,
      "z": -6,
      "name": "Plant_Leaves_Wisteria_Wild",
      "support": 15
    },
    {
      "x": -6,
      "y": 3,
      "z": -6,
      "name": "Plant_Leaves_Wisteria_Wild",
      "support": 15
    },
    {
      "x": -6,
      "y": 5,
      "z": -6,
      "name": "Rock_Shale_Brick_Stairs",
      "rotation": 11
    },
    {
      "x": -6,
      "y": 6,
      "z": -6,
      "name": "Rock_Shale_Brick"
    },
    {
      "x": -6,
      "y": 7,
      "z": -6,
      "name": "Rock_Basalt"
    },
    {
      "x": -6,
      "y": 0,
      "z": -5,
      "name": "Rock_Shale_Brick_Smooth"
    },
    {
      "x": -6,
      "y": 7,
      "z": -5,
      "name": "Rock_Basalt"
    },
    {
      "x": -6,
      "y": 0,
      "z": -4,
      "name": "Soil_Dirt_Cold"
    },
    {
      "x": -6,
      "y": 1,
      "z": -4,
      "name": "*Plant_Crop_Berry_Winter_Block_State_Definitions_StageFinal"
    },
    {
      "x": -6,
      "y": 7,
      "z": -4,
      "name": "Rock_Basalt"
    },
    {
      "x": -6,
      "y": 0,
      "z": -3,
      "name": "Soil_Dirt_Cold"
    },
    {
      "x": -6,
      "y": 7,
      "z": -3,
      "name": "Rock_Basalt"
    },
    {
      "x": -6,
      "y": 0,
      "z": -2,
      "name": "Rock_Shale"
    },
    {
      "x": -6,
      "y": 7,
      "z": -2,
      "name": "Rock_Basalt"
    },
    {
      "x": -6,
      "y": 0,
      "z": -1,
      "name": "Rock_Shale"
    },
    {
      "x": -6,
      "y": 7,
      "z": -1,
      "name": "Rock_Basalt"
    },
    {
      "x": -6,
      "y": 0,
      "z": 0,
      "name": "Rock_Shale"
    },
    {
      "x": -6,
      "y": 7,
      "z": 0,
      "name": "Rock_Basalt"
    },
    {
      "x": -6,
      "y": 0,
      "z": 1,
      "name": "Rock_Shale_Brick_Smooth"
    },
    {
      "x": -6,
      "y": 7,
      "z": 1,
      "name": "Rock_Basalt"
    },
    {
      "x": -6,
      "y": 0,
      "z": 2,
      "name": "Rock_Shale_Brick_Smooth"
    },
    {
      "x": -6,
      "y": 1,
      "z": 2,
      "name": "Rock_Shale_Brick_Stairs",
      "rotation": 8
    },
    {
      "x": -6,
      "y": 5,
      "z": 2,
      "name": "Rock_Shale_Brick_Stairs",
      "rotation": 11
    },
    {
      "x": -6,
      "y": 6,
      "z": 2,
      "name": "Rock_Shale_Brick"
    },
    {
      "x": -6,
      "y": 7,
      "z": 2,
      "name": "Rock_Basalt"
    },
    {
      "x": -6,
      "y": 0,
      "z": 3,
      "name": "Rock_Shale_Brick_Smooth"
    },
    {
      "x": -6,
      "y": 1,
      "z": 3,
      "name": "Rock_Shale"
    },
    {
      "x": -6,
      "y": 2,
      "z": 3,
      "name": "Rock_Shale"
    },
    {
      "x": -6,
      "y": 3,
      "z": 3,
      "name": "Rock_Shale"
    },
    {
      "x": -6,
      "y": 4,
      "z": 3,
      "name": "Rock_Shale"
    },
    {
      "x": -6,
      "y": 5,
      "z": 3,
      "name": "Rock_Basalt"
    },
    {
      "x": -6,
      "y": 6,
      "z": 3,
      "name": "Rock_Basalt"
    },
    {
      "x": -6,
      "y": 7,
      "z": 3,
      "name": "Rock_Basalt"
    },
    {
      "x": -5,
      "y": 0,
      "z": -7,
      "name": "Rock_Shale_Brick_Smooth"
    },
    {
      "x": -5,
      "y": 1,
      "z": -7,
      "name": "Rock_Shale"
    },
    {
      "x": -5,
      "y": 2,
      "z": -7,
      "name": "Rock_Shale"
    },
    {
      "x": -5,
      "y": 3,
      "z": -7,
      "name": "Rock_Shale"
    },
    {
      "x": -5,
      "y": 4,
      "z": -7,
      "name": "Rock_Shale"
    },
    {
      "x": -5,
      "y": 5,
      "z": -7,
      "name": "Rock_Basalt"
    },
    {
      "x": -5,
      "y": 6,
      "z": -7,
      "name": "Rock_Basalt"
    },
    {
      "x": -5,
      "y": 7,
      "z": -7,
      "name": "Rock_Basalt"
    },
    {
      "x": -5,
      "y": 0,
      "z": -6,
      "name": "Rock_Shale_Brick_Smooth"
    },
    {
      "x": -5,
      "y": 1,
      "z": -6,
      "name": "Rock_Shale_Brick_Stairs",
      "rotation": 10
    },
    {
      "x": -5,
      "y": 2,
      "z": -6,
      "name": "Plant_Leaves_Wisteria_Wild",
      "support": 15
    },
    {
      "x": -5,
      "y": 5,
      "z": -6,
      "name": "Rock_Shale_Brick_Stairs",
      "rotation": 9
    },
    {
      "x": -5,
      "y": 6,
      "z": -6,
      "name": "Rock_Shale_Brick"
    },
    {
      "x": -5,
      "y": 7,
      "z": -6,
      "name": "Rock_Basalt"
    },
    {
      "x": -5,
      "y": 0,
      "z": -5,
      "name": "Rock_Shale_Brick_Smooth"
    },
    {
      "x": -5,
      "y": 7,
      "z": -5,
      "name": "Rock_Basalt"
    },
    {
      "x": -5,
      "y": 0,
      "z": -4,
      "name": "Soil_Dirt_Cold"
    },
    {
      "x": -5,
      "y": 1,
      "z": -4,
      "name": "Plant_Bush_Dead_Twisted"
    },
    {
      "x": -5,
      "y": 7,
      "z": -4,
      "name": "Rock_Basalt"
    },
    {
      "x": -5,
      "y": 0,
      "z": -3,
      "name": "Soil_Dirt_Cold"
    },
    {
      "x": -5,
      "y": 1,
      "z": -3,
      "name": "Rubble_Basalt"
    },
    {
      "x": -5,
      "y": 7,
      "z": -3,
      "name": "Rock_Basalt"
    },
    {
      "x": -5,
      "y": 0,
      "z": -2,
      "name": "Rock_Shale"
    },
    {
      "x": -5,
      "y": 7,
      "z": -2,
      "name": "Rock_Basalt"
    },
    {
      "x": -5,
      "y": 0,
      "z": -1,
      "name": "Rock_Shale"
    },
    {
      "x": -5,
      "y": 7,
      "z": -1,
      "name": "Rock_Basalt"
    },
    {
      "x": -5,
      "y": 0,
      "z": 0,
      "name": "Soil_Dirt_Cold"
    },
    {
      "x": -5,
      "y": 7,
      "z": 0,
      "name": "Rock_Basalt"
    },
    {
      "x": -5,
      "y": 0,
      "z": 1,
      "name": "Rock_Shale_Brick_Smooth"
    },
    {
      "x": -5,
      "y": 1,
      "z": 1,
      "name": "Plant_Leaves_Wisteria_Wild",
      "support": 15
    },
    {
      "x": -5,
      "y": 7,
      "z": 1,
      "name": "Rock_Basalt"
    },
    {
      "x": -5,
      "y": 0,
      "z": 2,
      "name": "Rock_Shale_Brick_Smooth"
    },
    {
      "x": -5,
      "y": 1,
      "z": 2,
      "name": "Rock_Shale_Brick_Stairs",
      "rotation": 8
    },
    {
      "x": -5,
      "y": 5,
      "z": 2,
      "name": "Rock_Shale_Brick_Stairs",
      "rotation": 9
    },
    {
      "x": -5,
      "y": 6,
      "z": 2,
      "name": "Rock_Shale_Brick"
    },
    {
      "x": -5,
      "y": 7,
      "z": 2,
      "name": "Rock_Basalt"
    },
    {
      "x": -5,
      "y": 0,
      "z": 3,
      "name": "Rock_Shale_Brick_Smooth"
    },
    {
      "x": -5,
      "y": 1,
      "z": 3,
      "name": "Rock_Shale"
    },
    {
      "x": -5,
      "y": 2,
      "z": 3,
      "name": "Rock_Shale"
    },
    {
      "x": -5,
      "y": 3,
      "z": 3,
      "name": "Rock_Shale"
    },
    {
      "x": -5,
      "y": 4,
      "z": 3,
      "name": "Rock_Shale"
    },
    {
      "x": -5,
      "y": 5,
      "z": 3,
      "name": "Rock_Basalt"
    },
    {
      "x": -5,
      "y": 6,
      "z": 3,
      "name": "Rock_Basalt"
    },
    {
      "x": -5,
      "y": 7,
      "z": 3,
      "name": "Rock_Basalt"
    },
    {
      "x": -4,
      "y": 0,
      "z": -7,
      "name": "Rock_Shale_Brick_Smooth"
    },
    {
      "x": -4,
      "y": 1,
      "z": -7,
      "name": "Rock_Shale_Brick"
    },
    {
      "x": -4,
      "y": 2,
      "z": -7,
      "name": "Rock_Shale_Brick"
    },
    {
      "x": -4,
      "y": 3,
      "z": -7,
      "name": "Rock_Shale_Brick"
    },
    {
      "x": -4,
      "y": 4,
      "z": -7,
      "name": "Rock_Shale_Brick"
    },
    {
      "x": -4,
      "y": 5,
      "z": -7,
      "name": "Rock_Shale_Brick"
    },
    {
      "x": -4,
      "y": 6,
      "z": -7,
      "name": "Rock_Shale_Brick"
    },
    {
      "x": -4,
      "y": 7,
      "z": -7,
      "name": "Rock_Basalt"
    },
    {
      "x": -4,
      "y": 0,
      "z": -6,
      "name": "Rock_Shale_Brick_Smooth"
    },
    {
      "x": -4,
      "y": 1,
      "z": -6,
      "name": "Rock_Shale_Brick_Smooth"
    },
    {
      "x": -4,
      "y": 2,
      "z": -6,
      "name": "Rock_Shale_Brick_Pillar_Base"
    },
    {
      "x": -4,
      "y": 3,
      "z": -6,
      "name": "Rock_Shale_Brick_Pillar_Middle"
    },
    {
      "x": -4,
      "y": 4,
      "z": -6,
      "name": "Rock_Shale_Brick_Pillar_Base",
      "rotation": 8
    },
    {
      "x": -4,
      "y": 5,
      "z": -6,
      "name": "Rock_Shale_Brick"
    },
    {
      "x": -4,
      "y": 6,
      "z": -6,
      "name": "Rock_Shale_Brick"
    },
    {
      "x": -4,
      "y": 7,
      "z": -6,
      "name": "Rock_Basalt"
    },
    {
      "x": -4,
      "y": 0,
      "z": -5,
      "name": "Rock_Shale_Brick_Smooth"
    },
    {
      "x": -4,
      "y": 6,
      "z": -5,
      "name": "Rock_Shale_Brick_Stairs",
      "rotation": 10
    },
    {
      "x": -4,
      "y": 7,
      "z": -5,
      "name": "Rock_Basalt"
    },
    {
      "x": -4,
      "y": 0,
      "z": -4,
      "name": "Rock_Shale"
    },
    {
      "x": -4,
      "y": 1,
      "z": -4,
      "name": "Plant_Moss_Rug_Green_Dark",
      "support": 15
    },
    {
      "x": -4,
      "y": 6,
      "z": -4,
      "name": "Plant_Bush_Dead_Hanging"
    },
    {
      "x": -4,
      "y": 7,
      "z": -4,
      "name": "Rock_Basalt"
    },
    {
      "x": -4,
      "y": 0,
      "z": -3,
      "name": "Rock_Shale"
    },
    {
      "x": -4,
      "y": 1,
      "z": -3,
      "name": "Plant_Moss_Rug_Green_Dark",
      "support": 15
    },
    {
      "x": -4,
      "y": 7,
      "z": -3,
      "name": "Rock_Basalt"
    },
    {
      "x": -4,
      "y": 0,
      "z": -2,
      "name": "Rock_Shale"
    },
    {
      "x": -4,
      "y": 1,
      "z": -2,
      "name": "Plant_Moss_Rug_Green_Dark",
      "support": 15
    },
    {
      "x": -4,
      "y": 7,
      "z": -2,
      "name": "Rock_Basalt"
    },
    {
      "x": -4,
      "y": 0,
      "z": -1,
      "name": "Rock_Shale"
    },
    {
      "x": -4,
      "y": 7,
      "z": -1,
      "name": "Rock_Basalt"
    },
    {
      "x": -4,
      "y": 0,
      "z": 0,
      "name": "Soil_Dirt_Cold"
    },
    {
      "x": -4,
      "y": 1,
      "z": 0,
      "name": "Plant_Flower_Bushy_Green"
    },
    {
      "x": -4,
      "y": 7,
      "z": 0,
      "name": "Rock_Basalt"
    },
    {
      "x": -4,
      "y": 0,
      "z": 1,
      "name": "Soil_Dirt_Cold"
    },
    {
      "x": -4,
      "y": 6,
      "z": 1,
      "name": "Rock_Shale_Brick_Stairs",
      "rotation": 8
    },
    {
      "x": -4,
      "y": 7,
      "z": 1,
      "name": "Rock_Basalt"
    },
    {
      "x": -4,
      "y": 0,
      "z": 2,
      "name": "Rock_Shale_Brick_Smooth"
    },
    {
      "x": -4,
      "y": 1,
      "z": 2,
      "name": "Rock_Shale_Brick_Smooth"
    },
    {
      "x": -4,
      "y": 2,
      "z": 2,
      "name": "Rock_Shale_Brick_Pillar_Base"
    },
    {
      "x": -4,
      "y": 3,
      "z": 2,
      "name": "Rock_Shale_Brick_Pillar_Middle"
    },
    {
      "x": -4,
      "y": 4,
      "z": 2,
      "name": "Rock_Shale_Brick_Pillar_Base",
      "rotation": 8
    },
    {
      "x": -4,
      "y": 5,
      "z": 2,
      "name": "Rock_Shale_Brick"
    },
    {
      "x": -4,
      "y": 6,
      "z": 2,
      "name": "Rock_Shale_Brick"
    },
    {
      "x": -4,
      "y": 7,
      "z": 2,
      "name": "Rock_Basalt"
    },
    {
      "x": -4,
      "y": 0,
      "z": 3,
      "name": "Rock_Shale_Brick_Smooth"
    },
    {
      "x": -4,
      "y": 1,
      "z": 3,
      "name": "Rock_Shale_Brick"
    },
    {
      "x": -4,
      "y": 2,
      "z": 3,
      "name": "Rock_Shale_Brick"
    },
    {
      "x": -4,
      "y": 3,
      "z": 3,
      "name": "Rock_Shale_Brick"
    },
    {
      "x": -4,
      "y": 4,
      "z": 3,
      "name": "Rock_Shale_Brick"
    },
    {
      "x": -4,
      "y": 5,
      "z": 3,
      "name": "Rock_Shale_Brick"
    },
    {
      "x": -4,
      "y": 6,
      "z": 3,
      "name": "Rock_Shale_Brick"
    },
    {
      "x": -4,
      "y": 7,
      "z": 3,
      "name": "Rock_Basalt"
    },
    {
      "x": -3,
      "y": 0,
      "z": -7,
      "name": "Rock_Shale_Brick_Smooth"
    },
    {
      "x": -3,
      "y": 1,
      "z": -7,
      "name": "Rock_Shale"
    },
    {
      "x": -3,
      "y": 2,
      "z": -7,
      "name": "Rock_Shale"
    },
    {
      "x": -3,
      "y": 3,
      "z": -7,
      "name": "Rock_Shale"
    },
    {
      "x": -3,
      "y": 4,
      "z": -7,
      "name": "Rock_Shale"
    },
    {
      "x": -3,
      "y": 5,
      "z": -7,
      "name": "Rock_Shale"
    },
    {
      "x": -3,
      "y": 6,
      "z": -7,
      "name": "Rock_Shale"
    },
    {
      "x": -3,
      "y": 7,
      "z": -7,
      "name": "Rock_Basalt"
    },
    {
      "x": -3,
      "y": 0,
      "z": -6,
      "name": "Rock_Shale_Brick_Smooth"
    },
    {
      "x": -3,
      "y": 1,
      "z": -6,
      "name": "Rock_Basalt_Brick"
    },
    {
      "x": -3,
      "y": 2,
      "z": -6,
      "name": "Rock_Basalt_Brick"
    },
    {
      "x": -3,
      "y": 3,
      "z": -6,
      "name": "Rock_Basalt_Brick"
    },
    {
      "x": -3,
      "y": 4,
      "z": -6,
      "name": "Rock_Basalt_Brick"
    },
    {
      "x": -3,
      "y": 5,
      "z": -6,
      "name": "Rock_Basalt_Brick"
    },
    {
      "x": -3,
      "y": 6,
      "z": -6,
      "name": "Rock_Basalt_Brick"
    },
    {
      "x": -3,
      "y": 7,
      "z": -6,
      "name": "Rock_Basalt"
    },
    {
      "x": -3,
      "y": 0,
      "z": -5,
      "name": "Rock_Shale_Brick_Smooth"
    },
    {
      "x": -3,
      "y": 4,
      "z": -5,
      "name": "Plant_Vine_Wall",
      "support": 15
    },
    {
      "x": -3,
      "y": 6,
      "z": -5,
      "name": "Rock_Basalt_Brick"
    },
    {
      "x": -3,
      "y": 7,
      "z": -5,
      "name": "Rock_Basalt"
    },
    {
      "x": -3,
      "y": 0,
      "z": -4,
      "name": "Rock_Shale"
    },
    {
      "x": -3,
      "y": 1,
      "z": -4,
      "name": "Plant_Moss_Rug_Green_Dark",
      "support": 15
    },
    {
      "x": -3,
      "y": 6,
      "z": -4,
      "name": "Rock_Basalt_Brick"
    },
    {
      "x": -3,
      "y": 7,
      "z": -4,
      "name": "Rock_Basalt"
    },
    {
      "x": -3,
      "y": 0,
      "z": -3,
      "name": "Rock_Shale"
    },
    {
      "x": -3,
      "y": 6,
      "z": -3,
      "name": "Rock_Basalt_Brick"
    },
    {
      "x": -3,
      "y": 7,
      "z": -3,
      "name": "Rock_Basalt"
    },
    {
      "x": -3,
      "y": 0,
      "z": -2,
      "name": "Rock_Shale"
    },
    {
      "x": -3,
      "y": 6,
      "z": -2,
      "name": "Rock_Basalt_Brick"
    },
    {
      "x": -3,
      "y": 7,
      "z": -2,
      "name": "Rock_Basalt"
    },
    {
      "x": -3,
      "y": 0,
      "z": -1,
      "name": "Rock_Shale"
    },
    {
      "x": -3,
      "y": 6,
      "z": -1,
      "name": "Rock_Basalt_Brick"
    },
    {
      "x": -3,
      "y": 7,
      "z": -1,
      "name": "Rock_Basalt"
    },
    {
      "x": -3,
      "y": 0,
      "z": 0,
      "name": "Soil_Dirt_Cold"
    },
    {
      "x": -3,
      "y": 6,
      "z": 0,
      "name": "Rock_Basalt_Brick"
    },
    {
      "x": -3,
      "y": 7,
      "z": 0,
      "name": "Rock_Basalt"
    },
    {
      "x": -3,
      "y": 0,
      "z": 1,
      "name": "Soil_Dirt_Cold"
    },
    {
      "x": -3,
      "y": 1,
      "z": 1,
      "name": "Plant_Grass_Sharp_Tall",
      "support": 15
    },
    {
      "x": -3,
      "y": 2,
      "z": 1,
      "name": "Plant_Grass_Sharp_Tall",
      "filler": 1024
    },
    {
      "x": -3,
      "y": 6,
      "z": 1,
      "name": "Rock_Basalt_Brick"
    },
    {
      "x": -3,
      "y": 7,
      "z": 1,
      "name": "Rock_Basalt"
    },
    {
      "x": -3,
      "y": 0,
      "z": 2,
      "name": "Rock_Shale_Brick_Smooth"
    },
    {
      "x": -3,
      "y": 1,
      "z": 2,
      "name": "Rock_Basalt_Brick"
    },
    {
      "x": -3,
      "y": 2,
      "z": 2,
      "name": "Rock_Basalt_Brick"
    },
    {
      "x": -3,
      "y": 3,
      "z": 2,
      "name": "Rock_Basalt_Brick"
    },
    {
      "x": -3,
      "y": 4,
      "z": 2,
      "name": "Rock_Basalt_Brick"
    },
    {
      "x": -3,
      "y": 5,
      "z": 2,
      "name": "Rock_Basalt_Brick"
    },
    {
      "x": -3,
      "y": 6,
      "z": 2,
      "name": "Rock_Basalt_Brick"
    },
    {
      "x": -3,
      "y": 7,
      "z": 2,
      "name": "Rock_Basalt"
    },
    {
      "x": -3,
      "y": 0,
      "z": 3,
      "name": "Rock_Shale_Brick_Smooth"
    },
    {
      "x": -3,
      "y": 1,
      "z": 3,
      "name": "Rock_Shale"
    },
    {
      "x": -3,
      "y": 2,
      "z": 3,
      "name": "Rock_Shale"
    },
    {
      "x": -3,
      "y": 3,
      "z": 3,
      "name": "Rock_Shale"
    },
    {
      "x": -3,
      "y": 4,
      "z": 3,
      "name": "Rock_Shale"
    },
    {
      "x": -3,
      "y": 5,
      "z": 3,
      "name": "Rock_Shale"
    },
    {
      "x": -3,
      "y": 6,
      "z": 3,
      "name": "Rock_Shale"
    },
    {
      "x": -3,
      "y": 7,
      "z": 3,
      "name": "Rock_Basalt"
    },
    {
      "x": -3,
      "y": 0,
      "z": 4,
      "name": "Rock_Shale_Brick_Smooth"
    },
    {
      "x": -3,
      "y": 1,
      "z": 4,
      "name": "Rock_Shale_Brick"
    },
    {
      "x": -3,
      "y": 2,
      "z": 4,
      "name": "Rock_Shale_Brick"
    },
    {
      "x": -3,
      "y": 3,
      "z": 4,
      "name": "Rock_Shale_Brick"
    },
    {
      "x": -3,
      "y": 4,
      "z": 4,
      "name": "Rock_Shale_Brick"
    },
    {
      "x": -3,
      "y": 5,
      "z": 4,
      "name": "Rock_Shale_Brick"
    },
    {
      "x": -3,
      "y": 6,
      "z": 4,
      "name": "Rock_Shale_Brick"
    },
    {
      "x": -3,
      "y": 7,
      "z": 4,
      "name": "Rock_Basalt"
    },
    {
      "x": -3,
      "y": 0,
      "z": 5,
      "name": "Rock_Shale_Brick_Smooth"
    },
    {
      "x": -3,
      "y": 1,
      "z": 5,
      "name": "Rock_Shale"
    },
    {
      "x": -3,
      "y": 2,
      "z": 5,
      "name": "Rock_Shale"
    },
    {
      "x": -3,
      "y": 3,
      "z": 5,
      "name": "Rock_Shale"
    },
    {
      "x": -3,
      "y": 4,
      "z": 5,
      "name": "Rock_Shale"
    },
    {
      "x": -3,
      "y": 5,
      "z": 5,
      "name": "Rock_Basalt"
    },
    {
      "x": -3,
      "y": 6,
      "z": 5,
      "name": "Rock_Basalt"
    },
    {
      "x": -3,
      "y": 7,
      "z": 5,
      "name": "Rock_Basalt"
    },
    {
      "x": -3,
      "y": 0,
      "z": 6,
      "name": "Rock_Shale_Brick_Smooth"
    },
    {
      "x": -3,
      "y": 1,
      "z": 6,
      "name": "Rock_Shale"
    },
    {
      "x": -3,
      "y": 2,
      "z": 6,
      "name": "Rock_Shale"
    },
    {
      "x": -3,
      "y": 3,
      "z": 6,
      "name": "Rock_Shale"
    },
    {
      "x": -3,
      "y": 4,
      "z": 6,
      "name": "Rock_Shale"
    },
    {
      "x": -3,
      "y": 5,
      "z": 6,
      "name": "Rock_Basalt"
    },
    {
      "x": -3,
      "y": 6,
      "z": 6,
      "name": "Rock_Basalt"
    },
    {
      "x": -3,
      "y": 7,
      "z": 6,
      "name": "Rock_Basalt"
    },
    {
      "x": -3,
      "y": 0,
      "z": 7,
      "name": "Rock_Shale_Brick_Smooth"
    },
    {
      "x": -3,
      "y": 1,
      "z": 7,
      "name": "Rock_Shale_Brick"
    },
    {
      "x": -3,
      "y": 2,
      "z": 7,
      "name": "Rock_Shale_Brick"
    },
    {
      "x": -3,
      "y": 3,
      "z": 7,
      "name": "Rock_Shale_Brick"
    },
    {
      "x": -3,
      "y": 4,
      "z": 7,
      "name": "Rock_Shale_Brick"
    },
    {
      "x": -3,
      "y": 5,
      "z": 7,
      "name": "Rock_Shale_Brick"
    },
    {
      "x": -3,
      "y": 6,
      "z": 7,
      "name": "Rock_Shale_Brick"
    },
    {
      "x": -3,
      "y": 7,
      "z": 7,
      "name": "Rock_Basalt"
    },
    {
      "x": -2,
      "y": 0,
      "z": -7,
      "name": "Rock_Shale_Brick_Smooth"
    },
    {
      "x": -2,
      "y": 1,
      "z": -7,
      "name": "Rock_Shale"
    },
    {
      "x": -2,
      "y": 2,
      "z": -7,
      "name": "Rock_Shale"
    },
    {
      "x": -2,
      "y": 3,
      "z": -7,
      "name": "Rock_Shale"
    },
    {
      "x": -2,
      "y": 4,
      "z": -7,
      "name": "Rock_Shale"
    },
    {
      "x": -2,
      "y": 5,
      "z": -7,
      "name": "Rock_Shale"
    },
    {
      "x": -2,
      "y": 6,
      "z": -7,
      "name": "Rock_Shale"
    },
    {
      "x": -2,
      "y": 7,
      "z": -7,
      "name": "Rock_Basalt"
    },
    {
      "x": -2,
      "y": 0,
      "z": -6,
      "name": "Rock_Shale_Brick_Smooth"
    },
    {
      "x": -2,
      "y": 1,
      "z": -6,
      "name": "Rock_Basalt_Brick"
    },
    {
      "x": -2,
      "y": 2,
      "z": -6,
      "name": "Rock_Basalt_Brick"
    },
    {
      "x": -2,
      "y": 3,
      "z": -6,
      "name": "Rock_Basalt_Brick"
    },
    {
      "x": -2,
      "y": 4,
      "z": -6,
      "name": "Rock_Basalt_Brick"
    },
    {
      "x": -2,
      "y": 5,
      "z": -6,
      "name": "Rock_Basalt_Brick"
    },
    {
      "x": -2,
      "y": 6,
      "z": -6,
      "name": "Rock_Basalt_Brick"
    },
    {
      "x": -2,
      "y": 7,
      "z": -6,
      "name": "Rock_Basalt"
    },
    {
      "x": -2,
      "y": 0,
      "z": -5,
      "name": "Rock_Shale_Brick_Smooth"
    },
    {
      "x": -2,
      "y": 1,
      "z": -5,
      "name": "Plant_Moss_Rug_Green_Dark",
      "support": 15
    },
    {
      "x": -2,
      "y": 6,
      "z": -5,
      "name": "Rock_Basalt_Brick"
    },
    {
      "x": -2,
      "y": 7,
      "z": -5,
      "name": "Rock_Basalt"
    },
    {
      "x": -2,
      "y": 0,
      "z": -4,
      "name": "Rock_Shale_Brick"
    },
    {
      "x": -2,
      "y": 6,
      "z": -4,
      "name": "Rock_Basalt_Brick"
    },
    {
      "x": -2,
      "y": 7,
      "z": -4,
      "name": "Rock_Basalt"
    },
    {
      "x": -2,
      "y": 0,
      "z": -3,
      "name": "Soil_Dirt_Cold"
    },
    {
      "x": -2,
      "y": 1,
      "z": -3,
      "name": "Plant_Grass_Sharp_Tall",
      "support": 15
    },
    {
      "x": -2,
      "y": 2,
      "z": -3,
      "name": "Plant_Grass_Sharp_Tall",
      "filler": 1024
    },
    {
      "x": -2,
      "y": 6,
      "z": -3,
      "name": "Rock_Basalt_Brick"
    },
    {
      "x": -2,
      "y": 7,
      "z": -3,
      "name": "Rock_Basalt"
    },
    {
      "x": -2,
      "y": 0,
      "z": -2,
      "name": "Rock_Shale"
    },
    {
      "x": -2,
      "y": 6,
      "z": -2,
      "name": "Rock_Basalt_Brick"
    },
    {
      "x": -2,
      "y": 7,
      "z": -2,
      "name": "Rock_Basalt"
    },
    {
      "x": -2,
      "y": 0,
      "z": -1,
      "name": "Rock_Shale"
    },
    {
      "x": -2,
      "y": 1,
      "z": -1,
      "name": "Plant_Moss_Rug_Green_Dark",
      "support": 15
    },
    {
      "x": -2,
      "y": 6,
      "z": -1,
      "name": "Rock_Basalt_Brick"
    },
    {
      "x": -2,
      "y": 7,
      "z": -1,
      "name": "Rock_Basalt"
    },
    {
      "x": -2,
      "y": 0,
      "z": 0,
      "name": "Rock_Shale"
    },
    {
      "x": -2,
      "y": 6,
      "z": 0,
      "name": "Rock_Basalt_Brick"
    },
    {
      "x": -2,
      "y": 7,
      "z": 0,
      "name": "Rock_Basalt"
    },
    {
      "x": -2,
      "y": 0,
      "z": 1,
      "name": "Rock_Shale_Brick_Smooth"
    },
    {
      "x": -2,
      "y": 6,
      "z": 1,
      "name": "Rock_Basalt_Brick"
    },
    {
      "x": -2,
      "y": 7,
      "z": 1,
      "name": "Rock_Basalt"
    },
    {
      "x": -2,
      "y": 0,
      "z": 2,
      "name": "Rock_Shale_Brick_Smooth"
    },
    {
      "x": -2,
      "y": 1,
      "z": 2,
      "name": "Rock_Basalt_Brick"
    },
    {
      "x": -2,
      "y": 2,
      "z": 2,
      "name": "Rock_Basalt_Brick"
    },
    {
      "x": -2,
      "y": 3,
      "z": 2,
      "name": "Rock_Basalt_Brick"
    },
    {
      "x": -2,
      "y": 4,
      "z": 2,
      "name": "Rock_Basalt_Brick"
    },
    {
      "x": -2,
      "y": 5,
      "z": 2,
      "name": "Rock_Basalt_Brick"
    },
    {
      "x": -2,
      "y": 6,
      "z": 2,
      "name": "Rock_Basalt_Brick"
    },
    {
      "x": -2,
      "y": 7,
      "z": 2,
      "name": "Rock_Basalt"
    },
    {
      "x": -2,
      "y": 0,
      "z": 3,
      "name": "Rock_Shale_Brick_Smooth"
    },
    {
      "x": -2,
      "y": 1,
      "z": 3,
      "name": "Rock_Basalt_Brick"
    },
    {
      "x": -2,
      "y": 2,
      "z": 3,
      "name": "Rock_Basalt_Brick"
    },
    {
      "x": -2,
      "y": 3,
      "z": 3,
      "name": "Rock_Basalt_Brick"
    },
    {
      "x": -2,
      "y": 4,
      "z": 3,
      "name": "Rock_Basalt_Brick"
    },
    {
      "x": -2,
      "y": 5,
      "z": 3,
      "name": "Rock_Basalt_Brick"
    },
    {
      "x": -2,
      "y": 6,
      "z": 3,
      "name": "Rock_Basalt_Brick"
    },
    {
      "x": -2,
      "y": 7,
      "z": 3,
      "name": "Rock_Basalt"
    },
    {
      "x": -2,
      "y": 0,
      "z": 4,
      "name": "Rock_Shale_Brick_Smooth"
    },
    {
      "x": -2,
      "y": 1,
      "z": 4,
      "name": "Rock_Shale_Brick_Smooth"
    },
    {
      "x": -2,
      "y": 2,
      "z": 4,
      "name": "Rock_Shale_Brick_Pillar_Base"
    },
    {
      "x": -2,
      "y": 3,
      "z": 4,
      "name": "Rock_Shale_Brick_Pillar_Middle"
    },
    {
      "x": -2,
      "y": 4,
      "z": 4,
      "name": "Rock_Shale_Brick_Pillar_Base",
      "rotation": 8
    },
    {
      "x": -2,
      "y": 5,
      "z": 4,
      "name": "Rock_Shale_Brick"
    },
    {
      "x": -2,
      "y": 6,
      "z": 4,
      "name": "Rock_Shale_Brick"
    },
    {
      "x": -2,
      "y": 7,
      "z": 4,
      "name": "Rock_Basalt"
    },
    {
      "x": -2,
      "y": 0,
      "z": 5,
      "name": "Rock_Shale_Brick_Smooth"
    },
    {
      "x": -2,
      "y": 1,
      "z": 5,
      "name": "Rock_Shale_Brick_Stairs",
      "rotation": 11
    },
    {
      "x": -2,
      "y": 5,
      "z": 5,
      "name": "Rock_Shale_Brick_Stairs",
      "rotation": 10
    },
    {
      "x": -2,
      "y": 6,
      "z": 5,
      "name": "Rock_Shale_Brick"
    },
    {
      "x": -2,
      "y": 7,
      "z": 5,
      "name": "Rock_Basalt"
    },
    {
      "x": -2,
      "y": 0,
      "z": 6,
      "name": "Rock_Shale_Brick_Smooth"
    },
    {
      "x": -2,
      "y": 1,
      "z": 6,
      "name": "Rock_Shale_Brick_Stairs",
      "rotation": 11
    },
    {
      "x": -2,
      "y": 5,
      "z": 6,
      "name": "Rock_Shale_Brick_Stairs",
      "rotation": 8
    },
    {
      "x": -2,
      "y": 6,
      "z": 6,
      "name": "Rock_Shale_Brick"
    },
    {
      "x": -2,
      "y": 7,
      "z": 6,
      "name": "Rock_Basalt"
    },
    {
      "x": -2,
      "y": 0,
      "z": 7,
      "name": "Rock_Shale_Brick_Smooth"
    },
    {
      "x": -2,
      "y": 1,
      "z": 7,
      "name": "Rock_Shale_Brick_Smooth"
    },
    {
      "x": -2,
      "y": 2,
      "z": 7,
      "name": "Rock_Shale_Brick_Pillar_Base"
    },
    {
      "x": -2,
      "y": 3,
      "z": 7,
      "name": "Rock_Shale_Brick_Pillar_Middle"
    },
    {
      "x": -2,
      "y": 4,
      "z": 7,
      "name": "Rock_Shale_Brick_Pillar_Base",
      "rotation": 8
    },
    {
      "x": -2,
      "y": 5,
      "z": 7,
      "name": "Rock_Shale_Brick"
    },
    {
      "x": -2,
      "y": 6,
      "z": 7,
      "name": "Rock_Shale_Brick"
    },
    {
      "x": -2,
      "y": 7,
      "z": 7,
      "name": "Rock_Basalt"
    },
    {
      "x": -1,
      "y": 0,
      "z": -7,
      "name": "Rock_Shale_Brick_Smooth"
    },
    {
      "x": -1,
      "y": 1,
      "z": -7,
      "name": "Rock_Shale"
    },
    {
      "x": -1,
      "y": 2,
      "z": -7,
      "name": "Rock_Shale"
    },
    {
      "x": -1,
      "y": 3,
      "z": -7,
      "name": "Rock_Shale"
    },
    {
      "x": -1,
      "y": 4,
      "z": -7,
      "name": "Rock_Shale"
    },
    {
      "x": -1,
      "y": 5,
      "z": -7,
      "name": "Rock_Shale"
    },
    {
      "x": -1,
      "y": 6,
      "z": -7,
      "name": "Rock_Shale"
    },
    {
      "x": -1,
      "y": 7,
      "z": -7,
      "name": "Rock_Basalt"
    },
    {
      "x": -1,
      "y": 0,
      "z": -6,
      "name": "Rock_Shale_Brick_Smooth"
    },
    {
      "x": -1,
      "y": 1,
      "z": -6,
      "name": "Rock_Shale_Brick_Smooth"
    },
    {
      "x": -1,
      "y": 2,
      "z": -6,
      "name": "Rock_Shale_Brick_Pillar_Base"
    },
    {
      "x": -1,
      "y": 3,
      "z": -6,
      "name": "Rock_Shale_Brick_Pillar_Middle"
    },
    {
      "x": -1,
      "y": 4,
      "z": -6,
      "name": "Rock_Shale_Brick_Pillar_Base",
      "rotation": 8
    },
    {
      "x": -1,
      "y": 5,
      "z": -6,
      "name": "Rock_Shale_Brick"
    },
    {
      "x": -1,
      "y": 6,
      "z": -6,
      "name": "Rock_Shale_Brick"
    },
    {
      "x": -1,
      "y": 7,
      "z": -6,
      "name": "Rock_Basalt"
    },
    {
      "x": -1,
      "y": 0,
      "z": -5,
      "name": "Rock_Shale_Brick_Smooth"
    },
    {
      "x": -1,
      "y": 1,
      "z": -5,
      "name": "Rock_Shale_Brick_Beam"
    },
    {
      "x": -1,
      "y": 2,
      "z": -5,
      "name": "Furniture_Human_Ruins_Torch"
    },
    {
      "x": -1,
      "y": 6,
      "z": -5,
      "name": "Rock_Shale_Brick_Stairs",
      "rotation": 10
    },
    {
      "x": -1,
      "y": 7,
      "z": -5,
      "name": "Rock_Basalt"
    },
    {
      "x": -1,
      "y": 0,
      "z": -4,
      "name": "Rock_Shale_Brick"
    },
    {
      "x": -1,
      "y": 6,
      "z": -4,
      "name": "Plant_Bush_Dead_Hanging"
    },
    {
      "x": -1,
      "y": 7,
      "z": -4,
      "name": "Rock_Basalt"
    },
    {
      "x": -1,
      "y": 0,
      "z": -3,
      "name": "Soil_Dirt_Cold"
    },
    {
      "x": -1,
      "y": 7,
      "z": -3,
      "name": "Rock_Basalt"
    },
    {
      "x": -1,
      "y": 0,
      "z": -2,
      "name": "Rock_Shale"
    },
    {
      "x": -1,
      "y": 7,
      "z": -2,
      "name": "Rock_Basalt"
    },
    {
      "x": -1,
      "y": 0,
      "z": -1,
      "name": "Rock_Shale"
    },
    {
      "x": -1,
      "y": 7,
      "z": -1,
      "name": "Rock_Basalt"
    },
    {
      "x": -1,
      "y": 0,
      "z": 0,
      "name": "Rock_Shale"
    },
    {
      "x": -1,
      "y": 1,
      "z": 0,
      "name": "Plant_Moss_Rug_Green_Dark",
      "support": 15
    },
    {
      "x": -1,
      "y": 7,
      "z": 0,
      "name": "Rock_Basalt"
    },
    {
      "x": -1,
      "y": 0,
      "z": 1,
      "name": "Rock_Shale_Brick_Smooth"
    },
    {
      "x": -1,
      "y": 7,
      "z": 1,
      "name": "Rock_Basalt"
    },
    {
      "x": -1,
      "y": 0,
      "z": 2,
      "name": "Rock_Shale_Brick_Smooth"
    },
    {
      "x": -1,
      "y": 6,
      "z": 2,
      "name": "Rock_Basalt_Brick"
    },
    {
      "x": -1,
      "y": 7,
      "z": 2,
      "name": "Rock_Basalt"
    },
    {
      "x": -1,
      "y": 0,
      "z": 3,
      "name": "Rock_Shale_Brick_Smooth"
    },
    {
      "x": -1,
      "y": 1,
      "z": 3,
      "name": "Plant_Leaves_Wisteria_Wild",
      "support": 15
    },
    {
      "x": -1,
      "y": 6,
      "z": 3,
      "name": "Rock_Basalt_Brick"
    },
    {
      "x": -1,
      "y": 7,
      "z": 3,
      "name": "Rock_Basalt"
    },
    {
      "x": -1,
      "y": 0,
      "z": 4,
      "name": "Rock_Shale_Brick_Smooth"
    },
    {
      "x": -1,
      "y": 6,
      "z": 4,
      "name": "Rock_Shale_Brick_Stairs",
      "rotation": 11
    },
    {
      "x": -1,
      "y": 7,
      "z": 4,
      "name": "Rock_Basalt"
    },
    {
      "x": -1,
      "y": 0,
      "z": 5,
      "name": "Rock_Shale_Brick_Smooth"
    },
    {
      "x": -1,
      "y": 7,
      "z": 5,
      "name": "Rock_Basalt"
    },
    {
      "x": -1,
      "y": 0,
      "z": 6,
      "name": "Rock_Shale_Brick_Smooth"
    },
    {
      "x": -1,
      "y": 6,
      "z": 6,
      "name": "Plant_Bush_Dead_Hanging"
    },
    {
      "x": -1,
      "y": 7,
      "z": 6,
      "name": "Rock_Basalt"
    },
    {
      "x": -1,
      "y": 0,
      "z": 7,
      "name": "Rock_Shale_Brick_Smooth"
    },
    {
      "x": -1,
      "y": 1,
      "z": 7,
      "name": "Rubble_Basalt"
    },
    {
      "x": -1,
      "y": 6,
      "z": 7,
      "name": "Rock_Shale_Brick_Stairs",
      "rotation": 11
    },
    {
      "x": -1,
      "y": 7,
      "z": 7,
      "name": "Rock_Basalt"
    },
    {
      "x": 0,
      "y": 0,
      "z": -7,
      "name": "Rock_Shale_Brick_Smooth"
    },
    {
      "x": 0,
      "y": 1,
      "z": -7,
      "name": "Rock_Shale"
    },
    {
      "x": 0,
      "y": 2,
      "z": -7,
      "name": "Rock_Shale"
    },
    {
      "x": 0,
      "y": 3,
      "z": -7,
      "name": "Rock_Shale"
    },
    {
      "x": 0,
      "y": 4,
      "z": -7,
      "name": "Rock_Shale"
    },
    {
      "x": 0,
      "y": 5,
      "z": -7,
      "name": "Rock_Shale"
    },
    {
      "x": 0,
      "y": 6,
      "z": -7,
      "name": "Rock_Shale"
    },
    {
      "x": 0,
      "y": 7,
      "z": -7,
      "name": "Rock_Basalt"
    },
    {
      "x": 0,
      "y": 0,
      "z": -6,
      "name": "Rock_Shale_Brick_Smooth"
    },
    {
      "x": 0,
      "y": 1,
      "z": -6,
      "name": "Rock_Shale_Brick_Stairs",
      "rotation": 10
    },
    {
      "x": 0,
      "y": 5,
      "z": -6,
      "name": "Rock_Shale_Brick_Stairs",
      "rotation": 11
    },
    {
      "x": 0,
      "y": 6,
      "z": -6,
      "name": "Rock_Shale_Brick"
    },
    {
      "x": 0,
      "y": 7,
      "z": -6,
      "name": "Rock_Basalt"
    },
    {
      "x": 0,
      "y": 0,
      "z": -5,
      "name": "Rock_Shale_Brick_Smooth"
    },
    {
      "x": 0,
      "y": 7,
      "z": -5,
      "name": "Rock_Basalt"
    },
    {
      "x": 0,
      "y": 0,
      "z": -4,
      "name": "Rock_Shale_Brick"
    },
    {
      "x": 0,
      "y": 7,
      "z": -4,
      "name": "Rock_Basalt"
    },
    {
      "x": 0,
      "y": 0,
      "z": -3,
      "name": "Soil_Dirt_Cold"
    },
    {
      "x": 0,
      "y": 1,
      "z": -3,
      "name": "Plant_Flower_Bushy_Green"
    },
    {
      "x": 0,
      "y": 7,
      "z": -3,
      "name": "Rock_Basalt"
    },
    {
      "x": 0,
      "y": 0,
      "z": -2,
      "name": "Soil_Dirt_Cold"
    },
    {
      "x": 0,
      "y": 1,
      "z": -2,
      "name": "Plant_Grass_Gnarled_Tall",
      "support": 15
    },
    {
      "x": 0,
      "y": 2,
      "z": -2,
      "name": "Plant_Grass_Gnarled_Tall",
      "filler": 1024
    },
    {
      "x": 0,
      "y": 7,
      "z": -2,
      "name": "Rock_Basalt"
    },
    {
      "x": 0,
      "y": 0,
      "z": -1,
      "name": "Rock_Shale"
    },
    {
      "x": 0,
      "y": 1,
      "z": -1,
      "name": "Plant_Leaves_Wisteria_Wild",
      "support": 15
    },
    {
      "x": 0,
      "y": 7,
      "z": -1,
      "name": "Rock_Basalt"
    },
    {
      "x": 0,
      "y": 0,
      "z": 0,
      "name": "Rock_Shale"
    },
    {
      "x": 0,
      "y": 1,
      "z": 0,
      "name": "Plant_Moss_Rug_Green_Dark",
      "support": 15
    },
    {
      "x": 0,
      "y": 7,
      "z": 0,
      "name": "Rock_Basalt"
    },
    {
      "x": 0,
      "y": 0,
      "z": 1,
      "name": "Rock_Shale"
    },
    {
      "x": 0,
      "y": 1,
      "z": 1,
      "name": "Plant_Moss_Rug_Green_Dark",
      "support": 15
    },
    {
      "x": 0,
      "y": 7,
      "z": 1,
      "name": "Rock_Basalt"
    },
    {
      "x": 0,
      "y": 0,
      "z": 2,
      "name": "Rock_Shale"
    },
    {
      "x": 0,
      "y": 6,
      "z": 2,
      "name": "Rock_Basalt_Brick"
    },
    {
      "x": 0,
      "y": 7,
      "z": 2,
      "name": "Rock_Basalt"
    },
    {
      "x": 0,
      "y": 0,
      "z": 3,
      "name": "Rock_Shale"
    },
    {
      "x": 0,
      "y": 6,
      "z": 3,
      "name": "Rock_Basalt_Brick"
    },
    {
      "x": 0,
      "y": 7,
      "z": 3,
      "name": "Rock_Basalt"
    },
    {
      "x": 0,
      "y": 0,
      "z": 4,
      "name": "Soil_Dirt_Cold"
    },
    {
      "x": 0,
      "y": 1,
      "z": 4,
      "name": "Plant_Moss_Rug_Green_Dark",
      "support": 15
    },
    {
      "x": 0,
      "y": 6,
      "z": 4,
      "name": "Plant_Bush_Dead_Hanging"
    },
    {
      "x": 0,
      "y": 7,
      "z": 4,
      "name": "Rock_Basalt"
    },
    {
      "x": 0,
      "y": 0,
      "z": 5,
      "name": "Soil_Dirt_Cold"
    },
    {
      "x": 0,
      "y": 7,
      "z": 5,
      "name": "Rock_Basalt"
    },
    {
      "x": 0,
      "y": 0,
      "z": 6,
      "name": "Soil_Dirt_Cold"
    },
    {
      "x": 0,
      "y": 1,
      "z": 6,
      "name": "Plant_Bush_Dead_Twisted"
    },
    {
      "x": 0,
      "y": 7,
      "z": 6,
      "name": "Rock_Basalt"
    },
    {
      "x": 0,
      "y": 0,
      "z": 7,
      "name": "Soil_Dirt_Cold"
    },
    {
      "x": 0,
      "y": 7,
      "z": 7,
      "name": "Rock_Basalt"
    },
    {
      "x": 1,
      "y": 0,
      "z": -7,
      "name": "Rock_Shale_Brick_Smooth"
    },
    {
      "x": 1,
      "y": 1,
      "z": -7,
      "name": "Rock_Shale"
    },
    {
      "x": 1,
      "y": 2,
      "z": -7,
      "name": "Rock_Shale"
    },
    {
      "x": 1,
      "y": 3,
      "z": -7,
      "name": "Rock_Shale"
    },
    {
      "x": 1,
      "y": 4,
      "z": -7,
      "name": "Rock_Shale"
    },
    {
      "x": 1,
      "y": 5,
      "z": -7,
      "name": "Rock_Shale"
    },
    {
      "x": 1,
      "y": 6,
      "z": -7,
      "name": "Rock_Shale"
    },
    {
      "x": 1,
      "y": 7,
      "z": -7,
      "name": "Rock_Basalt"
    },
    {
      "x": 1,
      "y": 0,
      "z": -6,
      "name": "Rock_Shale_Brick_Smooth"
    },
    {
      "x": 1,
      "y": 1,
      "z": -6,
      "name": "Rock_Shale_Brick_Stairs",
      "rotation": 10
    },
    {
      "x": 1,
      "y": 5,
      "z": -6,
      "name": "Plant_Leaves_Wisteria_Wild",
      "support": 15
    },
    {
      "x": 1,
      "y": 6,
      "z": -6,
      "name": "Rock_Shale_Brick"
    },
    {
      "x": 1,
      "y": 7,
      "z": -6,
      "name": "Rock_Basalt"
    },
    {
      "x": 1,
      "y": 0,
      "z": -5,
      "name": "Rock_Shale_Brick_Smooth"
    },
    {
      "x": 1,
      "y": 1,
      "z": -5,
      "name": "Plant_Moss_Rug_Green_Dark",
      "support": 15
    },
    {
      "x": 1,
      "y": 7,
      "z": -5,
      "name": "Rock_Basalt"
    },
    {
      "x": 1,
      "y": 0,
      "z": -4,
      "name": "Rock_Shale"
    },
    {
      "x": 1,
      "y": 7,
      "z": -4,
      "name": "Rock_Basalt"
    },
    {
      "x": 1,
      "y": 0,
      "z": -3,
      "name": "Rock_Shale"
    },
    {
      "x": 1,
      "y": 7,
      "z": -3,
      "name": "Rock_Basalt"
    },
    {
      "x": 1,
      "y": 0,
      "z": -2,
      "name": "Rock_Shale"
    },
    {
      "x": 1,
      "y": 7,
      "z": -2,
      "name": "Rock_Basalt"
    },
    {
      "x": 1,
      "y": 0,
      "z": -1,
      "name": "Rock_Shale"
    },
    {
      "x": 1,
      "y": 1,
      "z": -1,
      "name": "Plant_Moss_Rug_Green_Dark",
      "support": 15
    },
    {
      "x": 1,
      "y": 7,
      "z": -1,
      "name": "Rock_Basalt"
    },
    {
      "x": 1,
      "y": 0,
      "z": 0,
      "name": "Rock_Shale"
    },
    {
      "x": 1,
      "y": 7,
      "z": 0,
      "name": "Rock_Basalt"
    },
    {
      "x": 1,
      "y": 0,
      "z": 1,
      "name": "Rock_Shale"
    },
    {
      "x": 1,
      "y": 1,
      "z": 1,
      "name": "Plant_Moss_Rug_Green_Dark",
      "support": 15
    },
    {
      "x": 1,
      "y": 6,
      "z": 1,
      "name": "Plant_Bush_Dead_Hanging"
    },
    {
      "x": 1,
      "y": 7,
      "z": 1,
      "name": "Rock_Basalt"
    },
    {
      "x": 1,
      "y": 0,
      "z": 2,
      "name": "Rock_Shale"
    },
    {
      "x": 1,
      "y": 6,
      "z": 2,
      "name": "Rock_Basalt_Brick"
    },
    {
      "x": 1,
      "y": 7,
      "z": 2,
      "name": "Rock_Basalt"
    },
    {
      "x": 1,
      "y": 0,
      "z": 3,
      "name": "Rock_Shale"
    },
    {
      "x": 1,
      "y": 1,
      "z": 3,
      "name": "Plant_Moss_Rug_Green_Dark",
      "support": 15
    },
    {
      "x": 1,
      "y": 6,
      "z": 3,
      "name": "Rock_Basalt_Brick"
    },
    {
      "x": 1,
      "y": 7,
      "z": 3,
      "name": "Rock_Basalt"
    },
    {
      "x": 1,
      "y": 0,
      "z": 4,
      "name": "Rock_Shale"
    },
    {
      "x": 1,
      "y": 7,
      "z": 4,
      "name": "Rock_Basalt"
    },
    {
      "x": 1,
      "y": 0,
      "z": 5,
      "name": "Rock_Shale"
    },
    {
      "x": 1,
      "y": 1,
      "z": 5,
      "name": "Plant_Moss_Rug_Green_Dark",
      "support": 15
    },
    {
      "x": 1,
      "y": 7,
      "z": 5,
      "name": "Rock_Basalt"
    },
    {
      "x": 1,
      "y": 0,
      "z": 6,
      "name": "Soil_Dirt_Cold"
    },
    {
      "x": 1,
      "y": 7,
      "z": 6,
      "name": "Rock_Basalt"
    },
    {
      "x": 1,
      "y": 0,
      "z": 7,
      "name": "Soil_Dirt_Cold"
    },
    {
      "x": 1,
      "y": 1,
      "z": 7,
      "name": "Plant_Flower_Bushy_Green"
    },
    {
      "x": 1,
      "y": 7,
      "z": 7,
      "name": "Rock_Basalt"
    },
    {
      "x": 2,
      "y": 0,
      "z": -7,
      "name": "Rock_Shale_Brick_Smooth"
    },
    {
      "x": 2,
      "y": 1,
      "z": -7,
      "name": "Rock_Shale"
    },
    {
      "x": 2,
      "y": 2,
      "z": -7,
      "name": "Rock_Shale"
    },
    {
      "x": 2,
      "y": 3,
      "z": -7,
      "name": "Rock_Shale"
    },
    {
      "x": 2,
      "y": 4,
      "z": -7,
      "name": "Rock_Shale"
    },
    {
      "x": 2,
      "y": 5,
      "z": -7,
      "name": "Rock_Shale"
    },
    {
      "x": 2,
      "y": 6,
      "z": -7,
      "name": "Rock_Shale"
    },
    {
      "x": 2,
      "y": 7,
      "z": -7,
      "name": "Rock_Basalt"
    },
    {
      "x": 2,
      "y": 0,
      "z": -6,
      "name": "Rock_Shale_Brick_Smooth"
    },
    {
      "x": 2,
      "y": 1,
      "z": -6,
      "name": "Rock_Shale_Brick_Stairs",
      "rotation": 10
    },
    {
      "x": 2,
      "y": 3,
      "z": -6,
      "name": "Plant_Leaves_Wisteria_Wild",
      "support": 15
    },
    {
      "x": 2,
      "y": 4,
      "z": -6,
      "name": "Plant_Leaves_Wisteria_Wild",
      "support": 15
    },
    {
      "x": 2,
      "y": 5,
      "z": -6,
      "name": "Plant_Leaves_Wisteria_Wild",
      "support": 15
    },
    {
      "x": 2,
      "y": 6,
      "z": -6,
      "name": "Rock_Shale_Brick"
    },
    {
      "x": 2,
      "y": 7,
      "z": -6,
      "name": "Rock_Basalt"
    },
    {
      "x": 2,
      "y": 0,
      "z": -5,
      "name": "Rock_Shale_Brick_Smooth"
    },
    {
      "x": 2,
      "y": 7,
      "z": -5,
      "name": "Rock_Basalt"
    },
    {
      "x": 2,
      "y": 0,
      "z": -4,
      "name": "Rock_Shale"
    },
    {
      "x": 2,
      "y": 7,
      "z": -4,
      "name": "Rock_Basalt"
    },
    {
      "x": 2,
      "y": 0,
      "z": -3,
      "name": "Rock_Shale"
    },
    {
      "x": 2,
      "y": 7,
      "z": -3,
      "name": "Rock_Basalt"
    },
    {
      "x": 2,
      "y": 0,
      "z": -2,
      "name": "Rock_Shale"
    },
    {
      "x": 2,
      "y": 7,
      "z": -2,
      "name": "Rock_Basalt"
    },
    {
      "x": 2,
      "y": 0,
      "z": -1,
      "name": "Rock_Shale"
    },
    {
      "x": 2,
      "y": 7,
      "z": -1,
      "name": "Rock_Basalt"
    },
    {
      "x": 2,
      "y": 0,
      "z": 0,
      "name": "Rock_Shale"
    },
    {
      "x": 2,
      "y": 7,
      "z": 0,
      "name": "Rock_Basalt"
    },
    {
      "x": 2,
      "y": 0,
      "z": 1,
      "name": "Rock_Shale"
    },
    {
      "x": 2,
      "y": 7,
      "z": 1,
      "name": "Rock_Basalt"
    },
    {
      "x": 2,
      "y": 0,
      "z": 2,
      "name": "Rock_Shale"
    },
    {
      "x": 2,
      "y": 1,
      "z": 2,
      "name": "Plant_Moss_Rug_Green_Dark",
      "support": 15
    },
    {
      "x": 2,
      "y": 6,
      "z": 2,
      "name": "Rock_Basalt_Brick"
    },
    {
      "x": 2,
      "y": 7,
      "z": 2,
      "name": "Rock_Basalt"
    },
    {
      "x": 2,
      "y": 0,
      "z": 3,
      "name": "Rock_Shale"
    },
    {
      "x": 2,
      "y": 6,
      "z": 3,
      "name": "Rock_Basalt_Brick"
    },
    {
      "x": 2,
      "y": 7,
      "z": 3,
      "name": "Rock_Basalt"
    },
    {
      "x": 2,
      "y": 0,
      "z": 4,
      "name": "Rock_Shale"
    },
    {
      "x": 2,
      "y": 7,
      "z": 4,
      "name": "Rock_Basalt"
    },
    {
      "x": 2,
      "y": 0,
      "z": 5,
      "name": "Rock_Shale"
    },
    {
      "x": 2,
      "y": 7,
      "z": 5,
      "name": "Rock_Basalt"
    },
    {
      "x": 2,
      "y": 0,
      "z": 6,
      "name": "Rock_Shale"
    },
    {
      "x": 2,
      "y": 7,
      "z": 6,
      "name": "Rock_Basalt"
    },
    {
      "x": 2,
      "y": 0,
      "z": 7,
      "name": "Rock_Shale"
    },
    {
      "x": 2,
      "y": 7,
      "z": 7,
      "name": "Rock_Basalt"
    },
    {
      "x": 3,
      "y": 0,
      "z": -7,
      "name": "Rock_Shale_Brick_Smooth"
    },
    {
      "x": 3,
      "y": 1,
      "z": -7,
      "name": "Rock_Shale"
    },
    {
      "x": 3,
      "y": 2,
      "z": -7,
      "name": "Rock_Shale"
    },
    {
      "x": 3,
      "y": 3,
      "z": -7,
      "name": "Rock_Shale"
    },
    {
      "x": 3,
      "y": 4,
      "z": -7,
      "name": "Rock_Shale"
    },
    {
      "x": 3,
      "y": 5,
      "z": -7,
      "name": "Rock_Shale"
    },
    {
      "x": 3,
      "y": 6,
      "z": -7,
      "name": "Rock_Shale"
    },
    {
      "x": 3,
      "y": 7,
      "z": -7,
      "name": "Rock_Basalt"
    },
    {
      "x": 3,
      "y": 0,
      "z": -6,
      "name": "Rock_Shale_Brick_Smooth"
    },
    {
      "x": 3,
      "y": 1,
      "z": -6,
      "name": "Rock_Shale_Brick_Stairs",
      "rotation": 10
    },
    {
      "x": 3,
      "y": 4,
      "z": -6,
      "name": "Plant_Leaves_Wisteria_Wild",
      "support": 15
    },
    {
      "x": 3,
      "y": 5,
      "z": -6,
      "name": "Rock_Shale_Brick_Stairs",
      "rotation": 9
    },
    {
      "x": 3,
      "y": 6,
      "z": -6,
      "name": "Rock_Shale_Brick"
    },
    {
      "x": 3,
      "y": 7,
      "z": -6,
      "name": "Rock_Basalt"
    },
    {
      "x": 3,
      "y": 0,
      "z": -5,
      "name": "Rock_Shale_Brick_Smooth"
    },
    {
      "x": 3,
      "y": 1,
      "z": -5,
      "name": "Plant_Leaves_Wisteria_Wild",
      "support": 15
    },
    {
      "x": 3,
      "y": 7,
      "z": -5,
      "name": "Rock_Basalt"
    },
    {
      "x": 3,
      "y": 0,
      "z": -4,
      "name": "Rock_Shale"
    },
    {
      "x": 3,
      "y": 1,
      "z": -4,
      "name": "Plant_Moss_Rug_Green_Dark",
      "support": 15
    },
    {
      "x": 3,
      "y": 7,
      "z": -4,
      "name": "Rock_Basalt"
    },
    {
      "x": 3,
      "y": 0,
      "z": -3,
      "name": "Soil_Dirt_Cold"
    },
    {
      "x": 3,
      "y": 7,
      "z": -3,
      "name": "Rock_Basalt"
    },
    {
      "x": 3,
      "y": 0,
      "z": -2,
      "name": "Rock_Shale"
    },
    {
      "x": 3,
      "y": 1,
      "z": -2,
      "name": "Plant_Moss_Rug_Green_Dark",
      "support": 15
    },
    {
      "x": 3,
      "y": 7,
      "z": -2,
      "name": "Rock_Basalt"
    },
    {
      "x": 3,
      "y": 0,
      "z": -1,
      "name": "Rock_Shale"
    },
    {
      "x": 3,
      "y": 1,
      "z": -1,
      "name": "Plant_Moss_Rug_Green_Dark",
      "support": 15
    },
    {
      "x": 3,
      "y": 7,
      "z": -1,
      "name": "Rock_Basalt"
    },
    {
      "x": 3,
      "y": 0,
      "z": 0,
      "name": "Rock_Shale"
    },
    {
      "x": 3,
      "y": 7,
      "z": 0,
      "name": "Rock_Basalt"
    },
    {
      "x": 3,
      "y": 0,
      "z": 1,
      "name": "Soil_Dirt_Cold"
    },
    {
      "x": 3,
      "y": 1,
      "z": 1,
      "name": "Plant_Flower_Bushy_Green"
    },
    {
      "x": 3,
      "y": 7,
      "z": 1,
      "name": "Rock_Basalt"
    },
    {
      "x": 3,
      "y": 0,
      "z": 2,
      "name": "Soil_Dirt_Cold"
    },
    {
      "x": 3,
      "y": 1,
      "z": 2,
      "name": "*Plant_Crop_Berry_Winter_Block_State_Definitions_StageFinal"
    },
    {
      "x": 3,
      "y": 6,
      "z": 2,
      "name": "Rock_Basalt_Brick"
    },
    {
      "x": 3,
      "y": 7,
      "z": 2,
      "name": "Rock_Basalt"
    },
    {
      "x": 3,
      "y": 0,
      "z": 3,
      "name": "Soil_Dirt_Cold"
    },
    {
      "x": 3,
      "y": 6,
      "z": 3,
      "name": "Rock_Basalt_Brick"
    },
    {
      "x": 3,
      "y": 7,
      "z": 3,
      "name": "Rock_Basalt"
    },
    {
      "x": 3,
      "y": 0,
      "z": 4,
      "name": "Soil_Dirt_Cold"
    },
    {
      "x": 3,
      "y": 1,
      "z": 4,
      "name": "Plant_Grass_Sharp_Tall",
      "support": 15
    },
    {
      "x": 3,
      "y": 2,
      "z": 4,
      "name": "Plant_Grass_Sharp_Tall",
      "filler": 1024
    },
    {
      "x": 3,
      "y": 7,
      "z": 4,
      "name": "Rock_Basalt"
    },
    {
      "x": 3,
      "y": 0,
      "z": 5,
      "name": "Rock_Shale"
    },
    {
      "x": 3,
      "y": 7,
      "z": 5,
      "name": "Rock_Basalt"
    },
    {
      "x": 3,
      "y": 0,
      "z": 6,
      "name": "Rock_Shale"
    },
    {
      "x": 3,
      "y": 7,
      "z": 6,
      "name": "Rock_Basalt"
    },
    {
      "x": 3,
      "y": 0,
      "z": 7,
      "name": "Rock_Shale"
    },
    {
      "x": 3,
      "y": 7,
      "z": 7,
      "name": "Rock_Basalt"
    },
    {
      "x": 4,
      "y": 0,
      "z": -7,
      "name": "Rock_Shale_Brick_Smooth"
    },
    {
      "x": 4,
      "y": 1,
      "z": -7,
      "name": "Rock_Shale"
    },
    {
      "x": 4,
      "y": 2,
      "z": -7,
      "name": "Rock_Shale"
    },
    {
      "x": 4,
      "y": 3,
      "z": -7,
      "name": "Rock_Shale"
    },
    {
      "x": 4,
      "y": 4,
      "z": -7,
      "name": "Rock_Shale"
    },
    {
      "x": 4,
      "y": 5,
      "z": -7,
      "name": "Rock_Shale"
    },
    {
      "x": 4,
      "y": 6,
      "z": -7,
      "name": "Rock_Shale"
    },
    {
      "x": 4,
      "y": 7,
      "z": -7,
      "name": "Rock_Basalt"
    },
    {
      "x": 4,
      "y": 0,
      "z": -6,
      "name": "Rock_Shale_Brick_Smooth"
    },
    {
      "x": 4,
      "y": 1,
      "z": -6,
      "name": "Rock_Shale_Brick_Smooth"
    },
    {
      "x": 4,
      "y": 2,
      "z": -6,
      "name": "Rock_Shale_Brick_Pillar_Base"
    },
    {
      "x": 4,
      "y": 3,
      "z": -6,
      "name": "Rock_Shale_Brick_Pillar_Middle"
    },
    {
      "x": 4,
      "y": 4,
      "z": -6,
      "name": "Rock_Shale_Brick_Pillar_Base",
      "rotation": 8
    },
    {
      "x": 4,
      "y": 5,
      "z": -6,
      "name": "Rock_Shale_Brick"
    },
    {
      "x": 4,
      "y": 6,
      "z": -6,
      "name": "Rock_Shale_Brick"
    },
    {
      "x": 4,
      "y": 7,
      "z": -6,
      "name": "Rock_Basalt"
    },
    {
      "x": 4,
      "y": 0,
      "z": -5,
      "name": "Rock_Shale_Brick_Smooth"
    },
    {
      "x": 4,
      "y": 4,
      "z": -5,
      "name": "Plant_Vine_Wall",
      "support": 15,
      "rotation": 3
    },
    {
      "x": 4,
      "y": 6,
      "z": -5,
      "name": "Rock_Shale_Brick_Stairs",
      "rotation": 10
    },
    {
      "x": 4,
      "y": 7,
      "z": -5,
      "name": "Rock_Basalt"
    },
    {
      "x": 4,
      "y": 0,
      "z": -4,
      "name": "Rock_Shale"
    },
    {
      "x": 4,
      "y": 7,
      "z": -4,
      "name": "Rock_Basalt"
    },
    {
      "x": 4,
      "y": 0,
      "z": -3,
      "name": "Soil_Dirt_Cold"
    },
    {
      "x": 4,
      "y": 1,
      "z": -3,
      "name": "Plant_Flower_Bushy_Green"
    },
    {
      "x": 4,
      "y": 7,
      "z": -3,
      "name": "Rock_Basalt"
    },
    {
      "x": 4,
      "y": 0,
      "z": -2,
      "name": "Soil_Dirt_Cold"
    },
    {
      "x": 4,
      "y": 7,
      "z": -2,
      "name": "Rock_Basalt"
    },
    {
      "x": 4,
      "y": 0,
      "z": -1,
      "name": "Rock_Shale"
    },
    {
      "x": 4,
      "y": 7,
      "z": -1,
      "name": "Rock_Basalt"
    },
    {
      "x": 4,
      "y": 0,
      "z": 0,
      "name": "Rock_Shale_Brick"
    },
    {
      "x": 4,
      "y": 7,
      "z": 0,
      "name": "Rock_Basalt"
    },
    {
      "x": 4,
      "y": 0,
      "z": 1,
      "name": "Rock_Shale_Brick"
    },
    {
      "x": 4,
      "y": 7,
      "z": 1,
      "name": "Rock_Basalt"
    },
    {
      "x": 4,
      "y": 0,
      "z": 2,
      "name": "Rock_Shale_Brick"
    },
    {
      "x": 4,
      "y": 1,
      "z": 2,
      "name": "Rubble_Basalt_Medium"
    },
    {
      "x": 4,
      "y": 6,
      "z": 2,
      "name": "Rock_Basalt_Brick"
    },
    {
      "x": 4,
      "y": 7,
      "z": 2,
      "name": "Rock_Basalt"
    },
    {
      "x": 4,
      "y": 0,
      "z": 3,
      "name": "Soil_Dirt_Cold"
    },
    {
      "x": 4,
      "y": 1,
      "z": 3,
      "name": "Plant_Bush_Dead_Twisted"
    },
    {
      "x": 4,
      "y": 6,
      "z": 3,
      "name": "Rock_Basalt_Brick"
    },
    {
      "x": 4,
      "y": 7,
      "z": 3,
      "name": "Rock_Basalt"
    },
    {
      "x": 4,
      "y": 0,
      "z": 4,
      "name": "Soil_Dirt_Cold"
    },
    {
      "x": 4,
      "y": 7,
      "z": 4,
      "name": "Rock_Basalt"
    },
    {
      "x": 4,
      "y": 0,
      "z": 5,
      "name": "Rock_Shale"
    },
    {
      "x": 4,
      "y": 6,
      "z": 5,
      "name": "Plant_Bush_Dead_Hanging"
    },
    {
      "x": 4,
      "y": 7,
      "z": 5,
      "name": "Rock_Basalt"
    },
    {
      "x": 4,
      "y": 0,
      "z": 6,
      "name": "Rock_Shale"
    },
    {
      "x": 4,
      "y": 1,
      "z": 6,
      "name": "Plant_Moss_Rug_Green_Dark",
      "support": 15
    },
    {
      "x": 4,
      "y": 7,
      "z": 6,
      "name": "Rock_Basalt"
    },
    {
      "x": 4,
      "y": 0,
      "z": 7,
      "name": "Rock_Shale"
    },
    {
      "x": 4,
      "y": 7,
      "z": 7,
      "name": "Rock_Basalt"
    },
    {
      "x": 5,
      "y": 0,
      "z": -7,
      "name": "Rock_Shale_Brick_Smooth"
    },
    {
      "x": 5,
      "y": 1,
      "z": -7,
      "name": "Rock_Shale"
    },
    {
      "x": 5,
      "y": 2,
      "z": -7,
      "name": "Rock_Shale"
    },
    {
      "x": 5,
      "y": 3,
      "z": -7,
      "name": "Rock_Shale"
    },
    {
      "x": 5,
      "y": 4,
      "z": -7,
      "name": "Rock_Shale"
    },
    {
      "x": 5,
      "y": 5,
      "z": -7,
      "name": "Rock_Shale"
    },
    {
      "x": 5,
      "y": 6,
      "z": -7,
      "name": "Rock_Shale"
    },
    {
      "x": 5,
      "y": 7,
      "z": -7,
      "name": "Rock_Basalt"
    },
    {
      "x": 5,
      "y": 0,
      "z": -6,
      "name": "Rock_Shale_Brick_Smooth"
    },
    {
      "x": 5,
      "y": 1,
      "z": -6,
      "name": "Rock_Basalt_Brick"
    },
    {
      "x": 5,
      "y": 2,
      "z": -6,
      "name": "Rock_Basalt_Brick"
    },
    {
      "x": 5,
      "y": 3,
      "z": -6,
      "name": "Rock_Basalt_Brick"
    },
    {
      "x": 5,
      "y": 4,
      "z": -6,
      "name": "Rock_Basalt_Brick"
    },
    {
      "x": 5,
      "y": 5,
      "z": -6,
      "name": "Rock_Basalt_Brick"
    },
    {
      "x": 5,
      "y": 6,
      "z": -6,
      "name": "Rock_Basalt_Brick"
    },
    {
      "x": 5,
      "y": 7,
      "z": -6,
      "name": "Rock_Basalt"
    },
    {
      "x": 5,
      "y": 0,
      "z": -5,
      "name": "Rock_Shale_Brick_Smooth"
    },
    {
      "x": 5,
      "y": 1,
      "z": -5,
      "name": "Rock_Basalt_Brick"
    },
    {
      "x": 5,
      "y": 2,
      "z": -5,
      "name": "Rock_Basalt_Brick"
    },
    {
      "x": 5,
      "y": 3,
      "z": -5,
      "name": "Rock_Basalt_Brick"
    },
    {
      "x": 5,
      "y": 4,
      "z": -5,
      "name": "Rock_Basalt_Brick"
    },
    {
      "x": 5,
      "y": 5,
      "z": -5,
      "name": "Rock_Basalt_Brick"
    },
    {
      "x": 5,
      "y": 6,
      "z": -5,
      "name": "Rock_Basalt_Brick"
    },
    {
      "x": 5,
      "y": 7,
      "z": -5,
      "name": "Rock_Basalt"
    },
    {
      "x": 5,
      "y": 0,
      "z": -4,
      "name": "Rock_Shale_Brick_Smooth"
    },
    {
      "x": 5,
      "y": 6,
      "z": -4,
      "name": "Rock_Shale_Brick_Stairs",
      "rotation": 9
    },
    {
      "x": 5,
      "y": 7,
      "z": -4,
      "name": "Rock_Basalt"
    },
    {
      "x": 5,
      "y": 0,
      "z": -3,
      "name": "Rock_Shale_Brick_Smooth"
    },
    {
      "x": 5,
      "y": 7,
      "z": -3,
      "name": "Rock_Basalt"
    },
    {
      "x": 5,
      "y": 0,
      "z": -2,
      "name": "Rock_Shale_Brick_Smooth"
    },
    {
      "x": 5,
      "y": 7,
      "z": -2,
      "name": "Rock_Basalt"
    },
    {
      "x": 5,
      "y": 0,
      "z": -1,
      "name": "Rock_Shale_Brick_Smooth"
    },
    {
      "x": 5,
      "y": 1,
      "z": -1,
      "name": "Plant_Leaves_Wisteria_Wild",
      "support": 15
    },
    {
      "x": 5,
      "y": 6,
      "z": -1,
      "name": "Plant_Bush_Dead_Hanging"
    },
    {
      "x": 5,
      "y": 7,
      "z": -1,
      "name": "Rock_Basalt"
    },
    {
      "x": 5,
      "y": 0,
      "z": 0,
      "name": "Rock_Shale_Brick_Smooth"
    },
    {
      "x": 5,
      "y": 1,
      "z": 0,
      "name": "Plant_Leaves_Wisteria_Wild",
      "support": 15
    },
    {
      "x": 5,
      "y": 7,
      "z": 0,
      "name": "Rock_Basalt"
    },
    {
      "x": 5,
      "y": 0,
      "z": 1,
      "name": "Rock_Shale_Brick_Smooth"
    },
    {
      "x": 5,
      "y": 1,
      "z": 1,
      "name": "Rock_Shale_Brick_Beam"
    },
    {
      "x": 5,
      "y": 2,
      "z": 1,
      "name": "Furniture_Human_Ruins_Torch",
      "rotation": 3
    },
    {
      "x": 5,
      "y": 6,
      "z": 1,
      "name": "Rock_Shale_Brick_Stairs",
      "rotation": 9
    },
    {
      "x": 5,
      "y": 7,
      "z": 1,
      "name": "Rock_Basalt"
    },
    {
      "x": 5,
      "y": 0,
      "z": 2,
      "name": "Rock_Shale_Brick_Smooth"
    },
    {
      "x": 5,
      "y": 6,
      "z": 2,
      "name": "Rock_Basalt_Brick"
    },
    {
      "x": 5,
      "y": 7,
      "z": 2,
      "name": "Rock_Basalt"
    },
    {
      "x": 5,
      "y": 0,
      "z": 3,
      "name": "Rock_Shale_Brick_Smooth"
    },
    {
      "x": 5,
      "y": 6,
      "z": 3,
      "name": "Rock_Basalt_Brick"
    },
    {
      "x": 5,
      "y": 7,
      "z": 3,
      "name": "Rock_Basalt"
    },
    {
      "x": 5,
      "y": 0,
      "z": 4,
      "name": "Rock_Shale_Brick_Smooth"
    },
    {
      "x": 5,
      "y": 6,
      "z": 4,
      "name": "Rock_Shale_Brick_Stairs",
      "rotation": 9
    },
    {
      "x": 5,
      "y": 7,
      "z": 4,
      "name": "Rock_Basalt"
    },
    {
      "x": 5,
      "y": 0,
      "z": 5,
      "name": "Rock_Shale_Brick_Smooth"
    },
    {
      "x": 5,
      "y": 7,
      "z": 5,
      "name": "Rock_Basalt"
    },
    {
      "x": 5,
      "y": 0,
      "z": 6,
      "name": "Rock_Shale_Brick_Smooth"
    },
    {
      "x": 5,
      "y": 7,
      "z": 6,
      "name": "Rock_Basalt"
    },
    {
      "x": 5,
      "y": 0,
      "z": 7,
      "name": "Rock_Shale_Brick_Smooth"
    },
    {
      "x": 5,
      "y": 6,
      "z": 7,
      "name": "Rock_Shale_Brick_Stairs",
      "rotation": 9
    },
    {
      "x": 5,
      "y": 7,
      "z": 7,
      "name": "Rock_Basalt"
    },
    {
      "x": 6,
      "y": 0,
      "z": -7,
      "name": "Rock_Shale_Brick_Smooth"
    },
    {
      "x": 6,
      "y": 1,
      "z": -7,
      "name": "Rock_Shale"
    },
    {
      "x": 6,
      "y": 2,
      "z": -7,
      "name": "Rock_Shale"
    },
    {
      "x": 6,
      "y": 3,
      "z": -7,
      "name": "Rock_Shale"
    },
    {
      "x": 6,
      "y": 4,
      "z": -7,
      "name": "Rock_Shale"
    },
    {
      "x": 6,
      "y": 5,
      "z": -7,
      "name": "Rock_Shale"
    },
    {
      "x": 6,
      "y": 6,
      "z": -7,
      "name": "Rock_Shale"
    },
    {
      "x": 6,
      "y": 7,
      "z": -7,
      "name": "Rock_Basalt"
    },
    {
      "x": 6,
      "y": 0,
      "z": -6,
      "name": "Rock_Shale_Brick_Smooth"
    },
    {
      "x": 6,
      "y": 1,
      "z": -6,
      "name": "Rock_Basalt_Brick"
    },
    {
      "x": 6,
      "y": 2,
      "z": -6,
      "name": "Rock_Basalt_Brick"
    },
    {
      "x": 6,
      "y": 3,
      "z": -6,
      "name": "Rock_Basalt_Brick"
    },
    {
      "x": 6,
      "y": 4,
      "z": -6,
      "name": "Rock_Basalt_Brick"
    },
    {
      "x": 6,
      "y": 5,
      "z": -6,
      "name": "Rock_Basalt_Brick"
    },
    {
      "x": 6,
      "y": 6,
      "z": -6,
      "name": "Rock_Basalt_Brick"
    },
    {
      "x": 6,
      "y": 7,
      "z": -6,
      "name": "Rock_Basalt"
    },
    {
      "x": 6,
      "y": 0,
      "z": -5,
      "name": "Rock_Shale_Brick_Smooth"
    },
    {
      "x": 6,
      "y": 1,
      "z": -5,
      "name": "Rock_Basalt_Brick"
    },
    {
      "x": 6,
      "y": 2,
      "z": -5,
      "name": "Rock_Basalt_Brick"
    },
    {
      "x": 6,
      "y": 3,
      "z": -5,
      "name": "Rock_Basalt_Brick"
    },
    {
      "x": 6,
      "y": 4,
      "z": -5,
      "name": "Rock_Basalt_Brick"
    },
    {
      "x": 6,
      "y": 5,
      "z": -5,
      "name": "Rock_Basalt_Brick"
    },
    {
      "x": 6,
      "y": 6,
      "z": -5,
      "name": "Rock_Basalt_Brick"
    },
    {
      "x": 6,
      "y": 7,
      "z": -5,
      "name": "Rock_Basalt"
    },
    {
      "x": 6,
      "y": 0,
      "z": -4,
      "name": "Rock_Shale_Brick_Smooth"
    },
    {
      "x": 6,
      "y": 1,
      "z": -4,
      "name": "Rock_Shale_Brick_Smooth"
    },
    {
      "x": 6,
      "y": 2,
      "z": -4,
      "name": "Rock_Shale_Brick_Pillar_Base"
    },
    {
      "x": 6,
      "y": 3,
      "z": -4,
      "name": "Rock_Shale_Brick_Pillar_Middle"
    },
    {
      "x": 6,
      "y": 4,
      "z": -4,
      "name": "Rock_Shale_Brick_Pillar_Base",
      "rotation": 8
    },
    {
      "x": 6,
      "y": 5,
      "z": -4,
      "name": "Rock_Shale_Brick"
    },
    {
      "x": 6,
      "y": 6,
      "z": -4,
      "name": "Rock_Shale_Brick"
    },
    {
      "x": 6,
      "y": 7,
      "z": -4,
      "name": "Rock_Basalt"
    },
    {
      "x": 6,
      "y": 0,
      "z": -3,
      "name": "Rock_Shale_Brick_Smooth"
    },
    {
      "x": 6,
      "y": 1,
      "z": -3,
      "name": "Rock_Shale_Brick_Stairs",
      "rotation": 9
    },
    {
      "x": 6,
      "y": 5,
      "z": -3,
      "name": "Rock_Shale_Brick_Stairs",
      "rotation": 10
    },
    {
      "x": 6,
      "y": 6,
      "z": -3,
      "name": "Rock_Shale_Brick"
    },
    {
      "x": 6,
      "y": 7,
      "z": -3,
      "name": "Rock_Basalt"
    },
    {
      "x": 6,
      "y": 0,
      "z": -2,
      "name": "Rock_Shale_Brick_Smooth"
    },
    {
      "x": 6,
      "y": 1,
      "z": -2,
      "name": "Rock_Shale_Brick_Stairs",
      "rotation": 9
    },
    {
      "x": 6,
      "y": 4,
      "z": -2,
      "name": "Plant_Vine_Wall",
      "support": 15,
      "rotation": 3
    },
    {
      "x": 6,
      "y": 6,
      "z": -2,
      "name": "Rock_Shale_Brick"
    },
    {
      "x": 6,
      "y": 7,
      "z": -2,
      "name": "Rock_Basalt"
    },
    {
      "x": 6,
      "y": 0,
      "z": -1,
      "name": "Rock_Shale_Brick_Smooth"
    },
    {
      "x": 6,
      "y": 1,
      "z": -1,
      "name": "Rock_Shale_Brick_Stairs",
      "rotation": 9
    },
    {
      "x": 6,
      "y": 2,
      "z": -1,
      "name": "Plant_Leaves_Wisteria_Wild",
      "support": 15
    },
    {
      "x": 6,
      "y": 3,
      "z": -1,
      "name": "Plant_Leaves_Wisteria_Wild",
      "support": 15
    },
    {
      "x": 6,
      "y": 6,
      "z": -1,
      "name": "Rock_Shale_Brick"
    },
    {
      "x": 6,
      "y": 7,
      "z": -1,
      "name": "Rock_Basalt"
    },
    {
      "x": 6,
      "y": 0,
      "z": 0,
      "name": "Rock_Shale_Brick_Smooth"
    },
    {
      "x": 6,
      "y": 1,
      "z": 0,
      "name": "Rock_Shale_Brick_Stairs",
      "rotation": 9
    },
    {
      "x": 6,
      "y": 2,
      "z": 0,
      "name": "Plant_Leaves_Wisteria_Wild",
      "support": 15
    },
    {
      "x": 6,
      "y": 3,
      "z": 0,
      "name": "Plant_Leaves_Wisteria_Wild",
      "support": 15
    },
    {
      "x": 6,
      "y": 5,
      "z": 0,
      "name": "Rock_Shale_Brick_Stairs",
      "rotation": 8
    },
    {
      "x": 6,
      "y": 6,
      "z": 0,
      "name": "Rock_Shale_Brick"
    },
    {
      "x": 6,
      "y": 7,
      "z": 0,
      "name": "Rock_Basalt"
    },
    {
      "x": 6,
      "y": 0,
      "z": 1,
      "name": "Rock_Shale_Brick_Smooth"
    },
    {
      "x": 6,
      "y": 1,
      "z": 1,
      "name": "Rock_Shale_Brick_Smooth"
    },
    {
      "x": 6,
      "y": 2,
      "z": 1,
      "name": "Rock_Shale_Brick_Pillar_Base"
    },
    {
      "x": 6,
      "y": 3,
      "z": 1,
      "name": "Rock_Shale_Brick_Pillar_Middle"
    },
    {
      "x": 6,
      "y": 4,
      "z": 1,
      "name": "Rock_Shale_Brick_Pillar_Base",
      "rotation": 8
    },
    {
      "x": 6,
      "y": 5,
      "z": 1,
      "name": "Rock_Shale_Brick"
    },
    {
      "x": 6,
      "y": 6,
      "z": 1,
      "name": "Rock_Shale_Brick"
    },
    {
      "x": 6,
      "y": 7,
      "z": 1,
      "name": "Rock_Basalt"
    },
    {
      "x": 6,
      "y": 0,
      "z": 2,
      "name": "Rock_Shale_Brick_Smooth"
    },
    {
      "x": 6,
      "y": 1,
      "z": 2,
      "name": "Rock_Basalt_Brick"
    },
    {
      "x": 6,
      "y": 2,
      "z": 2,
      "name": "Rock_Basalt_Brick"
    },
    {
      "x": 6,
      "y": 3,
      "z": 2,
      "name": "Rock_Basalt_Brick"
    },
    {
      "x": 6,
      "y": 4,
      "z": 2,
      "name": "Rock_Basalt_Brick"
    },
    {
      "x": 6,
      "y": 5,
      "z": 2,
      "name": "Rock_Basalt_Brick"
    },
    {
      "x": 6,
      "y": 6,
      "z": 2,
      "name": "Rock_Basalt_Brick"
    },
    {
      "x": 6,
      "y": 7,
      "z": 2,
      "name": "Rock_Basalt"
    },
    {
      "x": 6,
      "y": 0,
      "z": 3,
      "name": "Rock_Shale_Brick_Smooth"
    },
    {
      "x": 6,
      "y": 1,
      "z": 3,
      "name": "Rock_Basalt_Brick"
    },
    {
      "x": 6,
      "y": 2,
      "z": 3,
      "name": "Rock_Basalt_Brick"
    },
    {
      "x": 6,
      "y": 3,
      "z": 3,
      "name": "Rock_Basalt_Brick"
    },
    {
      "x": 6,
      "y": 4,
      "z": 3,
      "name": "Rock_Basalt_Brick"
    },
    {
      "x": 6,
      "y": 5,
      "z": 3,
      "name": "Rock_Basalt_Brick"
    },
    {
      "x": 6,
      "y": 6,
      "z": 3,
      "name": "Rock_Basalt_Brick"
    },
    {
      "x": 6,
      "y": 7,
      "z": 3,
      "name": "Rock_Basalt"
    },
    {
      "x": 6,
      "y": 0,
      "z": 4,
      "name": "Rock_Shale_Brick_Smooth"
    },
    {
      "x": 6,
      "y": 1,
      "z": 4,
      "name": "Rock_Shale_Brick_Smooth"
    },
    {
      "x": 6,
      "y": 2,
      "z": 4,
      "name": "Rock_Shale_Brick_Pillar_Base"
    },
    {
      "x": 6,
      "y": 3,
      "z": 4,
      "name": "Rock_Shale_Brick_Pillar_Middle"
    },
    {
      "x": 6,
      "y": 4,
      "z": 4,
      "name": "Rock_Shale_Brick_Pillar_Base",
      "rotation": 8
    },
    {
      "x": 6,
      "y": 5,
      "z": 4,
      "name": "Rock_Shale_Brick"
    },
    {
      "x": 6,
      "y": 6,
      "z": 4,
      "name": "Rock_Shale_Brick"
    },
    {
      "x": 6,
      "y": 7,
      "z": 4,
      "name": "Rock_Basalt"
    },
    {
      "x": 6,
      "y": 0,
      "z": 5,
      "name": "Rock_Shale_Brick_Smooth"
    },
    {
      "x": 6,
      "y": 1,
      "z": 5,
      "name": "Rock_Shale_Brick_Stairs",
      "rotation": 9
    },
    {
      "x": 6,
      "y": 5,
      "z": 5,
      "name": "Rock_Shale_Brick_Stairs",
      "rotation": 10
    },
    {
      "x": 6,
      "y": 6,
      "z": 5,
      "name": "Rock_Shale_Brick"
    },
    {
      "x": 6,
      "y": 7,
      "z": 5,
      "name": "Rock_Basalt"
    },
    {
      "x": 6,
      "y": 0,
      "z": 6,
      "name": "Rock_Shale_Brick_Smooth"
    },
    {
      "x": 6,
      "y": 1,
      "z": 6,
      "name": "Rock_Shale_Brick_Stairs",
      "rotation": 9
    },
    {
      "x": 6,
      "y": 5,
      "z": 6,
      "name": "Rock_Shale_Brick_Stairs",
      "rotation": 8
    },
    {
      "x": 6,
      "y": 6,
      "z": 6,
      "name": "Rock_Shale_Brick"
    },
    {
      "x": 6,
      "y": 7,
      "z": 6,
      "name": "Rock_Basalt"
    },
    {
      "x": 6,
      "y": 0,
      "z": 7,
      "name": "Rock_Shale_Brick_Smooth"
    },
    {
      "x": 6,
      "y": 1,
      "z": 7,
      "name": "Rock_Shale_Brick_Smooth"
    },
    {
      "x": 6,
      "y": 2,
      "z": 7,
      "name": "Rock_Shale_Brick_Pillar_Base"
    },
    {
      "x": 6,
      "y": 3,
      "z": 7,
      "name": "Rock_Shale_Brick_Pillar_Middle"
    },
    {
      "x": 6,
      "y": 4,
      "z": 7,
      "name": "Rock_Shale_Brick_Pillar_Base",
      "rotation": 8
    },
    {
      "x": 6,
      "y": 5,
      "z": 7,
      "name": "Rock_Shale_Brick"
    },
    {
      "x": 6,
      "y": 6,
      "z": 7,
      "name": "Rock_Shale_Brick"
    },
    {
      "x": 6,
      "y": 7,
      "z": 7,
      "name": "Rock_Basalt"
    },
    {
      "x": 7,
      "y": 0,
      "z": -7,
      "name": "Rock_Shale_Brick_Smooth"
    },
    {
      "x": 7,
      "y": 1,
      "z": -7,
      "name": "Rock_Shale"
    },
    {
      "x": 7,
      "y": 2,
      "z": -7,
      "name": "Rock_Shale"
    },
    {
      "x": 7,
      "y": 3,
      "z": -7,
      "name": "Rock_Shale"
    },
    {
      "x": 7,
      "y": 4,
      "z": -7,
      "name": "Rock_Shale"
    },
    {
      "x": 7,
      "y": 5,
      "z": -7,
      "name": "Rock_Shale"
    },
    {
      "x": 7,
      "y": 6,
      "z": -7,
      "name": "Rock_Shale"
    },
    {
      "x": 7,
      "y": 7,
      "z": -7,
      "name": "Rock_Basalt"
    },
    {
      "x": 7,
      "y": 0,
      "z": -6,
      "name": "Rock_Shale_Brick_Smooth"
    },
    {
      "x": 7,
      "y": 1,
      "z": -6,
      "name": "Rock_Shale"
    },
    {
      "x": 7,
      "y": 2,
      "z": -6,
      "name": "Rock_Shale"
    },
    {
      "x": 7,
      "y": 3,
      "z": -6,
      "name": "Rock_Shale"
    },
    {
      "x": 7,
      "y": 4,
      "z": -6,
      "name": "Rock_Shale"
    },
    {
      "x": 7,
      "y": 5,
      "z": -6,
      "name": "Rock_Shale"
    },
    {
      "x": 7,
      "y": 6,
      "z": -6,
      "name": "Rock_Shale"
    },
    {
      "x": 7,
      "y": 7,
      "z": -6,
      "name": "Rock_Basalt"
    },
    {
      "x": 7,
      "y": 0,
      "z": -5,
      "name": "Rock_Shale_Brick_Smooth"
    },
    {
      "x": 7,
      "y": 1,
      "z": -5,
      "name": "Rock_Shale"
    },
    {
      "x": 7,
      "y": 2,
      "z": -5,
      "name": "Rock_Shale"
    },
    {
      "x": 7,
      "y": 3,
      "z": -5,
      "name": "Rock_Shale"
    },
    {
      "x": 7,
      "y": 4,
      "z": -5,
      "name": "Rock_Shale"
    },
    {
      "x": 7,
      "y": 5,
      "z": -5,
      "name": "Rock_Shale"
    },
    {
      "x": 7,
      "y": 6,
      "z": -5,
      "name": "Rock_Shale"
    },
    {
      "x": 7,
      "y": 7,
      "z": -5,
      "name": "Rock_Basalt"
    },
    {
      "x": 7,
      "y": 0,
      "z": -4,
      "name": "Rock_Shale_Brick_Smooth"
    },
    {
      "x": 7,
      "y": 1,
      "z": -4,
      "name": "Rock_Shale"
    },
    {
      "x": 7,
      "y": 2,
      "z": -4,
      "name": "Rock_Shale"
    },
    {
      "x": 7,
      "y": 3,
      "z": -4,
      "name": "Rock_Shale"
    },
    {
      "x": 7,
      "y": 4,
      "z": -4,
      "name": "Rock_Shale"
    },
    {
      "x": 7,
      "y": 5,
      "z": -4,
      "name": "Rock_Shale"
    },
    {
      "x": 7,
      "y": 6,
      "z": -4,
      "name": "Rock_Shale"
    },
    {
      "x": 7,
      "y": 7,
      "z": -4,
      "name": "Rock_Basalt"
    },
    {
      "x": 7,
      "y": 0,
      "z": -3,
      "name": "Rock_Shale_Brick_Smooth"
    },
    {
      "x": 7,
      "y": 1,
      "z": -3,
      "name": "Rock_Shale"
    },
    {
      "x": 7,
      "y": 2,
      "z": -3,
      "name": "Rock_Shale"
    },
    {
      "x": 7,
      "y": 3,
      "z": -3,
      "name": "Rock_Shale"
    },
    {
      "x": 7,
      "y": 4,
      "z": -3,
      "name": "Rock_Shale"
    },
    {
      "x": 7,
      "y": 5,
      "z": -3,
      "name": "Rock_Shale"
    },
    {
      "x": 7,
      "y": 6,
      "z": -3,
      "name": "Rock_Shale"
    },
    {
      "x": 7,
      "y": 7,
      "z": -3,
      "name": "Rock_Basalt"
    },
    {
      "x": 7,
      "y": 0,
      "z": -2,
      "name": "Rock_Shale_Brick_Smooth"
    },
    {
      "x": 7,
      "y": 1,
      "z": -2,
      "name": "Rock_Shale"
    },
    {
      "x": 7,
      "y": 2,
      "z": -2,
      "name": "Rock_Shale"
    },
    {
      "x": 7,
      "y": 3,
      "z": -2,
      "name": "Rock_Shale"
    },
    {
      "x": 7,
      "y": 4,
      "z": -2,
      "name": "Rock_Shale"
    },
    {
      "x": 7,
      "y": 5,
      "z": -2,
      "name": "Rock_Shale"
    },
    {
      "x": 7,
      "y": 6,
      "z": -2,
      "name": "Rock_Shale"
    },
    {
      "x": 7,
      "y": 7,
      "z": -2,
      "name": "Rock_Basalt"
    },
    {
      "x": 7,
      "y": 0,
      "z": -1,
      "name": "Rock_Shale_Brick_Smooth"
    },
    {
      "x": 7,
      "y": 1,
      "z": -1,
      "name": "Rock_Shale"
    },
    {
      "x": 7,
      "y": 2,
      "z": -1,
      "name": "Rock_Shale"
    },
    {
      "x": 7,
      "y": 3,
      "z": -1,
      "name": "Rock_Shale"
    },
    {
      "x": 7,
      "y": 4,
      "z": -1,
      "name": "Rock_Shale"
    },
    {
      "x": 7,
      "y": 5,
      "z": -1,
      "name": "Rock_Shale"
    },
    {
      "x": 7,
      "y": 6,
      "z": -1,
      "name": "Rock_Shale"
    },
    {
      "x": 7,
      "y": 7,
      "z": -1,
      "name": "Rock_Basalt"
    },
    {
      "x": 7,
      "y": 0,
      "z": 0,
      "name": "Rock_Shale_Brick_Smooth"
    },
    {
      "x": 7,
      "y": 1,
      "z": 0,
      "name": "Rock_Shale"
    },
    {
      "x": 7,
      "y": 2,
      "z": 0,
      "name": "Rock_Shale"
    },
    {
      "x": 7,
      "y": 3,
      "z": 0,
      "name": "Rock_Shale"
    },
    {
      "x": 7,
      "y": 4,
      "z": 0,
      "name": "Rock_Shale"
    },
    {
      "x": 7,
      "y": 5,
      "z": 0,
      "name": "Rock_Shale"
    },
    {
      "x": 7,
      "y": 6,
      "z": 0,
      "name": "Rock_Shale"
    },
    {
      "x": 7,
      "y": 7,
      "z": 0,
      "name": "Rock_Basalt"
    },
    {
      "x": 7,
      "y": 0,
      "z": 1,
      "name": "Rock_Shale_Brick_Smooth"
    },
    {
      "x": 7,
      "y": 1,
      "z": 1,
      "name": "Rock_Shale"
    },
    {
      "x": 7,
      "y": 2,
      "z": 1,
      "name": "Rock_Shale"
    },
    {
      "x": 7,
      "y": 3,
      "z": 1,
      "name": "Rock_Shale"
    },
    {
      "x": 7,
      "y": 4,
      "z": 1,
      "name": "Rock_Shale"
    },
    {
      "x": 7,
      "y": 5,
      "z": 1,
      "name": "Rock_Shale"
    },
    {
      "x": 7,
      "y": 6,
      "z": 1,
      "name": "Rock_Shale"
    },
    {
      "x": 7,
      "y": 7,
      "z": 1,
      "name": "Rock_Basalt"
    },
    {
      "x": 7,
      "y": 0,
      "z": 2,
      "name": "Rock_Shale_Brick_Smooth"
    },
    {
      "x": 7,
      "y": 1,
      "z": 2,
      "name": "Rock_Shale"
    },
    {
      "x": 7,
      "y": 2,
      "z": 2,
      "name": "Rock_Shale"
    },
    {
      "x": 7,
      "y": 3,
      "z": 2,
      "name": "Rock_Shale"
    },
    {
      "x": 7,
      "y": 4,
      "z": 2,
      "name": "Rock_Shale"
    },
    {
      "x": 7,
      "y": 5,
      "z": 2,
      "name": "Rock_Shale"
    },
    {
      "x": 7,
      "y": 6,
      "z": 2,
      "name": "Rock_Shale"
    },
    {
      "x": 7,
      "y": 7,
      "z": 2,
      "name": "Rock_Basalt"
    },
    {
      "x": 7,
      "y": 0,
      "z": 3,
      "name": "Rock_Shale_Brick_Smooth"
    },
    {
      "x": 7,
      "y": 1,
      "z": 3,
      "name": "Rock_Shale"
    },
    {
      "x": 7,
      "y": 2,
      "z": 3,
      "name": "Rock_Shale"
    },
    {
      "x": 7,
      "y": 3,
      "z": 3,
      "name": "Rock_Shale"
    },
    {
      "x": 7,
      "y": 4,
      "z": 3,
      "name": "Rock_Shale"
    },
    {
      "x": 7,
      "y": 5,
      "z": 3,
      "name": "Rock_Shale"
    },
    {
      "x": 7,
      "y": 6,
      "z": 3,
      "name": "Rock_Shale"
    },
    {
      "x": 7,
      "y": 7,
      "z": 3,
      "name": "Rock_Basalt"
    },
    {
      "x": 7,
      "y": 0,
      "z": 4,
      "name": "Rock_Shale_Brick_Smooth"
    },
    {
      "x": 7,
      "y": 1,
      "z": 4,
      "name": "Rock_Shale_Brick"
    },
    {
      "x": 7,
      "y": 2,
      "z": 4,
      "name": "Rock_Shale_Brick"
    },
    {
      "x": 7,
      "y": 3,
      "z": 4,
      "name": "Rock_Shale_Brick"
    },
    {
      "x": 7,
      "y": 4,
      "z": 4,
      "name": "Rock_Shale_Brick"
    },
    {
      "x": 7,
      "y": 5,
      "z": 4,
      "name": "Rock_Shale_Brick"
    },
    {
      "x": 7,
      "y": 6,
      "z": 4,
      "name": "Rock_Shale_Brick"
    },
    {
      "x": 7,
      "y": 7,
      "z": 4,
      "name": "Rock_Basalt"
    },
    {
      "x": 7,
      "y": 0,
      "z": 5,
      "name": "Rock_Shale_Brick_Smooth"
    },
    {
      "x": 7,
      "y": 1,
      "z": 5,
      "name": "Rock_Shale"
    },
    {
      "x": 7,
      "y": 2,
      "z": 5,
      "name": "Rock_Shale"
    },
    {
      "x": 7,
      "y": 3,
      "z": 5,
      "name": "Rock_Shale"
    },
    {
      "x": 7,
      "y": 4,
      "z": 5,
      "name": "Rock_Shale"
    },
    {
      "x": 7,
      "y": 5,
      "z": 5,
      "name": "Rock_Basalt"
    },
    {
      "x": 7,
      "y": 6,
      "z": 5,
      "name": "Rock_Basalt"
    },
    {
      "x": 7,
      "y": 7,
      "z": 5,
      "name": "Rock_Basalt"
    },
    {
      "x": 7,
      "y": 0,
      "z": 6,
      "name": "Rock_Shale_Brick_Smooth"
    },
    {
      "x": 7,
      "y": 1,
      "z": 6,
      "name": "Rock_Shale"
    },
    {
      "x": 7,
      "y": 2,
      "z": 6,
      "name": "Rock_Shale"
    },
    {
      "x": 7,
      "y": 3,
      "z": 6,
      "name": "Rock_Shale"
    },
    {
      "x": 7,
      "y": 4,
      "z": 6,
      "name": "Rock_Shale"
    },
    {
      "x": 7,
      "y": 5,
      "z": 6,
      "name": "Rock_Basalt"
    },
    {
      "x": 7,
      "y": 6,
      "z": 6,
      "name": "Rock_Basalt"
    },
    {
      "x": 7,
      "y": 7,
      "z": 6,
      "name": "Rock_Basalt"
    },
    {
      "x": 7,
      "y": 0,
      "z": 7,
      "name": "Rock_Shale_Brick_Smooth"
    },
    {
      "x": 7,
      "y": 1,
      "z": 7,
      "name": "Rock_Shale_Brick"
    },
    {
      "x": 7,
      "y": 2,
      "z": 7,
      "name": "Rock_Shale_Brick"
    },
    {
      "x": 7,
      "y": 3,
      "z": 7,
      "name": "Rock_Shale_Brick"
    },
    {
      "x": 7,
      "y": 4,
      "z": 7,
      "name": "Rock_Shale_Brick"
    },
    {
      "x": 7,
      "y": 5,
      "z": 7,
      "name": "Rock_Shale_Brick"
    },
    {
      "x": 7,
      "y": 6,
      "z": 7,
      "name": "Rock_Shale_Brick"
    },
    {
      "x": 7,
      "y": 7,
      "z": 7,
      "name": "Rock_Basalt"
    }
  ],
  "entities": [
    {
      "Components": {
        "Nameplate": {
          "Text": "Outlander_Berserker"
        },
        "HiddenFromAdventurePlayer": {},
        "SpawnMarkerComponent": {
          "SpawnMarker": "Outlander_Berserker",
          "RespawnTime": 0.0,
          "SpawnCount": 0,
          "NPCReferences": [],
          "PersistedFlock": {},
          "SpawnPosition": {
            "X": 0.0,
            "Y": 0.0,
            "Z": 0.0
          }
        },
        "Transform": {
          "Position": {
            "X": 3.4512790527343213,
            "Y": 1.000700134277281,
            "Z": -1.5046829010009901
          },
          "Rotation": {
            "Pitch": 0.0,
            "Yaw": -10.05677318572998,
            "Roll": 0.0
          }
        },
        "Intangible": {},
        "PrefabCopyable": {},
        "Model": {
          "Model": {
            "Id": "NPC_Spawn_Marker",
            "Scale": 1.0,
            "Static": false
          }
        },
        "UUID": {
          "UUID": {
            "$binary": "H1djR+6pO1mqmnXcOFod7w==",
            "$type": "04"
          }
        },
        "HeadRotation": {
          "Rotation": {
            "Pitch": 0.0,
            "Yaw": -13.198366165161133,
            "Roll": 0.0
          }
        }
      }
    }
  ]
}