{
  "version": 8,
  "blockIdVersion": 11,
  "anchorX": 0,
  "anchorY": 13,
  "anchorZ": 9,
  "blocks": [
    {
      "x": -5,
      "y": 0,
      "z": -8,
      "name": "Rock_Shale_Brick_Smooth"
    },
    {
      "x": -5,
      "y": 1,
      "z": -8,
      "name": "Rock_Shale"
    },
    {
      "x": -5,
      "y": 2,
      "z": -8,
      "name": "Rock_Shale"
    },
    {
      "x": -5,
      "y": 3,
      "z": -8,
      "name": "Rock_Shale"
    },
    {
      "x": -5,
      "y": 4,
      "z": -8,
      "name": "Rock_Shale"
    },
    {
      "x": -5,
      "y": 5,
      "z": -8,
      "name": "Rock_Shale"
    },
    {
      "x": -5,
      "y": 6,
      "z": -8,
      "name": "Rock_Shale"
    },
    {
      "x": -5,
      "y": 0,
      "z": -7,
      "name": "Rock_Shale_Brick_Smooth"
    },
    {
      "x": -5,
      "y": 1,
      "z": -7,
      "name": "Rock_Shale"
    },
    {
      "x": -5,
      "y": 2,
      "z": -7,
      "name": "Rock_Shale"
    },
    {
      "x": -5,
      "y": 3,
      "z": -7,
      "name": "Rock_Shale"
    },
    {
      "x": -5,
      "y": 4,
      "z": -7,
      "name": "Rock_Shale"
    },
    {
      "x": -5,
      "y": 5,
      "z": -7,
      "name": "Rock_Shale"
    },
    {
      "x": -5,
      "y": 6,
      "z": -7,
      "name": "Rock_Shale"
    },
    {
      "x": -5,
      "y": 0,
      "z": -6,
      "name": "Rock_Shale_Brick_Smooth"
    },
    {
      "x": -5,
      "y": 1,
      "z": -6,
      "name": "Rock_Shale"
    },
    {
      "x": -5,
      "y": 2,
      "z": -6,
      "name": "Rock_Shale"
    },
    {
      "x": -5,
      "y": 3,
      "z": -6,
      "name": "Rock_Shale"
    },
    {
      "x": -5,
      "y": 4,
      "z": -6,
      "name": "Rock_Shale"
    },
    {
      "x": -5,
      "y": 5,
      "z": -6,
      "name": "Rock_Shale"
    },
    {
      "x": -5,
      "y": 6,
      "z": -6,
      "name": "Rock_Shale"
    },
    {
      "x": -5,
      "y": 7,
      "z": -6,
      "name": "Rock_Shale"
    },
    {
      "x": -5,
      "y": 0,
      "z": -5,
      "name": "Rock_Shale_Brick_Smooth"
    },
    {
      "x": -5,
      "y": 1,
      "z": -5,
      "name": "Rock_Shale"
    },
    {
      "x": -5,
      "y": 2,
      "z": -5,
      "name": "Rock_Shale"
    },
    {
      "x": -5,
      "y": 3,
      "z": -5,
      "name": "Rock_Shale"
    },
    {
      "x": -5,
      "y": 4,
      "z": -5,
      "name": "Rock_Shale"
    },
    {
      "x": -5,
      "y": 5,
      "z": -5,
      "name": "Rock_Basalt"
    },
    {
      "x": -5,
      "y": 6,
      "z": -5,
      "name": "Rock_Basalt"
    },
    {
      "x": -5,
      "y": 7,
      "z": -5,
      "name": "Rock_Shale"
    },
    {
      "x": -5,
      "y": 8,
      "z": -5,
      "name": "Rock_Shale"
    },
    {
      "x": -5,
      "y": 1,
      "z": -4,
      "name": "Rock_Shale"
    },
    {
      "x": -5,
      "y": 2,
      "z": -4,
      "name": "Rock_Shale"
    },
    {
      "x": -5,
      "y": 3,
      "z": -4,
      "name": "Rock_Shale"
    },
    {
      "x": -5,
      "y": 4,
      "z": -4,
      "name": "Rock_Shale"
    },
    {
      "x": -5,
      "y": 5,
      "z": -4,
      "name": "Rock_Shale"
    },
    {
      "x": -5,
      "y": 6,
      "z": -4,
      "name": "Rock_Shale"
    },
    {
      "x": -5,
      "y": 7,
      "z": -4,
      "name": "Rock_Shale"
    },
    {
      "x": -5,
      "y": 8,
      "z": -4,
      "name": "Rock_Shale"
    },
    {
      "x": -5,
      "y": 9,
      "z": -4,
      "name": "Rock_Shale"
    },
    {
      "x": -5,
      "y": 2,
      "z": -3,
      "name": "Rock_Shale"
    },
    {
      "x": -5,
      "y": 3,
      "z": -3,
      "name": "Rock_Shale"
    },
    {
      "x": -5,
      "y": 4,
      "z": -3,
      "name": "Rock_Shale"
    },
    {
      "x": -5,
      "y": 5,
      "z": -3,
      "name": "Rock_Shale"
    },
    {
      "x": -5,
      "y": 6,
      "z": -3,
      "name": "Rock_Shale"
    },
    {
      "x": -5,
      "y": 7,
      "z": -3,
      "name": "Rock_Shale"
    },
    {
      "x": -5,
      "y": 8,
      "z": -3,
      "name": "Rock_Shale"
    },
    {
      "x": -5,
      "y": 9,
      "z": -3,
      "name": "Rock_Shale"
    },
    {
      "x": -5,
      "y": 10,
      "z": -3,
      "name": "Rock_Shale"
    },
    {
      "x": -5,
      "y": 3,
      "z": -2,
      "name": "Rock_Shale"
    },
    {
      "x": -5,
      "y": 4,
      "z": -2,
      "name": "Rock_Shale"
    },
    {
      "x": -5,
      "y": 5,
      "z": -2,
      "name": "Rock_Shale"
    },
    {
      "x": -5,
      "y": 6,
      "z": -2,
      "name": "Rock_Shale"
    },
    {
      "x": -5,
      "y": 7,
      "z": -2,
      "name": "Rock_Shale"
    },
    {
      "x": -5,
      "y": 8,
      "z": -2,
      "name": "Rock_Shale"
    },
    {
      "x": -5,
      "y": 9,
      "z": -2,
      "name": "Rock_Shale"
    },
    {
      "x": -5,
      "y": 10,
      "z": -2,
      "name": "Rock_Shale"
    },
    {
      "x": -5,
      "y": 11,
      "z": -2,
      "name": "Rock_Shale"
    },
    {
      "x": -5,
      "y": 4,
      "z": -1,
      "name": "Rock_Shale"
    },
    {
      "x": -5,
      "y": 5,
      "z": -1,
      "name": "Rock_Shale"
    },
    {
      "x": -5,
      "y": 6,
      "z": -1,
      "name": "Rock_Shale"
    },
    {
      "x": -5,
      "y": 7,
      "z": -1,
      "name": "Rock_Shale"
    },
    {
      "x": -5,
      "y": 8,
      "z": -1,
      "name": "Rock_Shale"
    },
    {
      "x": -5,
      "y": 9,
      "z": -1,
      "name": "Rock_Basalt"
    },
    {
      "x": -5,
      "y": 10,
      "z": -1,
      "name": "Rock_Basalt"
    },
    {
      "x": -5,
      "y": 11,
      "z": -1,
      "name": "Rock_Shale"
    },
    {
      "x": -5,
      "y": 12,
      "z": -1,
      "name": "Rock_Shale"
    },
    {
      "x": -5,
      "y": 5,
      "z": 0,
      "name": "Rock_Shale"
    },
    {
      "x": -5,
      "y": 6,
      "z": 0,
      "name": "Rock_Shale"
    },
    {
      "x": -5,
      "y": 7,
      "z": 0,
      "name": "Rock_Shale"
    },
    {
      "x": -5,
      "y": 8,
      "z": 0,
      "name": "Rock_Shale"
    },
    {
      "x": -5,
      "y": 9,
      "z": 0,
      "name": "Rock_Shale"
    },
    {
      "x": -5,
      "y": 10,
      "z": 0,
      "name": "Rock_Basalt"
    },
    {
      "x": -5,
      "y": 11,
      "z": 0,
      "name": "Rock_Basalt"
    },
    {
      "x": -5,
      "y": 12,
      "z": 0,
      "name": "Rock_Shale"
    },
    {
      "x": -5,
      "y": 13,
      "z": 0,
      "name": "Rock_Shale"
    },
    {
      "x": -5,
      "y": 6,
      "z": 1,
      "name": "Rock_Shale"
    },
    {
      "x": -5,
      "y": 7,
      "z": 1,
      "name": "Rock_Shale"
    },
    {
      "x": -5,
      "y": 8,
      "z": 1,
      "name": "Rock_Shale"
    },
    {
      "x": -5,
      "y": 9,
      "z": 1,
      "name": "Rock_Shale"
    },
    {
      "x": -5,
      "y": 10,
      "z": 1,
      "name": "Rock_Shale"
    },
    {
      "x": -5,
      "y": 11,
      "z": 1,
      "name": "Rock_Shale"
    },
    {
      "x": -5,
      "y": 12,
      "z": 1,
      "name": "Rock_Shale"
    },
    {
      "x": -5,
      "y": 13,
      "z": 1,
      "name": "Rock_Shale"
    },
    {
      "x": -5,
      "y": 14,
      "z": 1,
      "name": "Rock_Shale"
    },
    {
      "x": -5,
      "y": 7,
      "z": 2,
      "name": "Rock_Shale"
    },
    {
      "x": -5,
      "y": 8,
      "z": 2,
      "name": "Rock_Shale"
    },
    {
      "x": -5,
      "y": 9,
      "z": 2,
      "name": "Rock_Shale"
    },
    {
      "x": -5,
      "y": 10,
      "z": 2,
      "name": "Rock_Shale"
    },
    {
      "x": -5,
      "y": 11,
      "z": 2,
      "name": "Rock_Shale"
    },
    {
      "x": -5,
      "y": 12,
      "z": 2,
      "name": "Rock_Basalt"
    },
    {
      "x": -5,
      "y": 13,
      "z": 2,
      "name": "Rock_Basalt"
    },
    {
      "x": -5,
      "y": 14,
      "z": 2,
      "name": "Rock_Shale"
    },
    {
      "x": -5,
      "y": 15,
      "z": 2,
      "name": "Rock_Shale"
    },
    {
      "x": -5,
      "y": 8,
      "z": 3,
      "name": "Rock_Shale"
    },
    {
      "x": -5,
      "y": 9,
      "z": 3,
      "name": "Rock_Shale"
    },
    {
      "x": -5,
      "y": 10,
      "z": 3,
      "name": "Rock_Shale"
    },
    {
      "x": -5,
      "y": 11,
      "z": 3,
      "name": "Rock_Shale"
    },
    {
      "x": -5,
      "y": 12,
      "z": 3,
      "name": "Rock_Shale"
    },
    {
      "x": -5,
      "y": 13,
      "z": 3,
      "name": "Rock_Basalt"
    },
    {
      "x": -5,
      "y": 14,
      "z": 3,
      "name": "Rock_Basalt"
    },
    {
      "x": -5,
      "y": 15,
      "z": 3,
      "name": "Rock_Basalt"
    },
    {
      "x": -5,
      "y": 16,
      "z": 3,
      "name": "Rock_Shale"
    },
    {
      "x": -5,
      "y": 9,
      "z": 4,
      "name": "Rock_Shale"
    },
    {
      "x": -5,
      "y": 10,
      "z": 4,
      "name": "Rock_Shale"
    },
    {
      "x": -5,
      "y": 11,
      "z": 4,
      "name": "Rock_Shale"
    },
    {
      "x": -5,
      "y": 12,
      "z": 4,
      "name": "Rock_Shale"
    },
    {
      "x": -5,
      "y": 13,
      "z": 4,
      "name": "Rock_Shale"
    },
    {
      "x": -5,
      "y": 14,
      "z": 4,
      "name": "Rock_Basalt"
    },
    {
      "x": -5,
      "y": 15,
      "z": 4,
      "name": "Rock_Basalt"
    },
    {
      "x": -5,
      "y": 16,
      "z": 4,
      "name": "Rock_Shale"
    },
    {
      "x": -5,
      "y": 17,
      "z": 4,
      "name": "Rock_Shale"
    },
    {
      "x": -5,
      "y": 10,
      "z": 5,
      "name": "Rock_Shale"
    },
    {
      "x": -5,
      "y": 11,
      "z": 5,
      "name": "Rock_Shale"
    },
    {
      "x": -5,
      "y": 12,
      "z": 5,
      "name": "Rock_Shale"
    },
    {
      "x": -5,
      "y": 13,
      "z": 5,
      "name": "Rock_Shale"
    },
    {
      "x": -5,
      "y": 14,
      "z": 5,
      "name": "Rock_Shale"
    },
    {
      "x": -5,
      "y": 15,
      "z": 5,
      "name": "Rock_Shale"
    },
    {
      "x": -5,
      "y": 16,
      "z": 5,
      "name": "Rock_Shale"
    },
    {
      "x": -5,
      "y": 17,
      "z": 5,
      "name": "Rock_Shale"
    },
    {
      "x": -5,
      "y": 18,
      "z": 5,
      "name": "Rock_Shale"
    },
    {
      "x": -5,
      "y": 11,
      "z": 6,
      "name": "Rock_Shale"
    },
    {
      "x": -5,
      "y": 12,
      "z": 6,
      "name": "Rock_Shale"
    },
    {
      "x": -5,
      "y": 13,
      "z": 6,
      "name": "Rock_Shale"
    },
    {
      "x": -5,
      "y": 14,
      "z": 6,
      "name": "Rock_Shale"
    },
    {
      "x": -5,
      "y": 15,
      "z": 6,
      "name": "Rock_Shale"
    },
    {
      "x": -5,
      "y": 16,
      "z": 6,
      "name": "Rock_Basalt"
    },
    {
      "x": -5,
      "y": 17,
      "z": 6,
      "name": "Rock_Basalt"
    },
    {
      "x": -5,
      "y": 18,
      "z": 6,
      "name": "Rock_Shale"
    },
    {
      "x": -5,
      "y": 19,
      "z": 6,
      "name": "Rock_Shale"
    },
    {
      "x": -5,
      "y": 12,
      "z": 7,
      "name": "Rock_Shale"
    },
    {
      "x": -5,
      "y": 13,
      "z": 7,
      "name": "Rock_Shale"
    },
    {
      "x": -5,
      "y": 14,
      "z": 7,
      "name": "Rock_Shale"
    },
    {
      "x": -5,
      "y": 15,
      "z": 7,
      "name": "Rock_Shale"
    },
    {
      "x": -5,
      "y": 16,
      "z": 7,
      "name": "Rock_Shale"
    },
    {
      "x": -5,
      "y": 17,
      "z": 7,
      "name": "Rock_Basalt"
    },
    {
      "x": -5,
      "y": 18,
      "z": 7,
      "name": "Rock_Basalt"
    },
    {
      "x": -5,
      "y": 19,
      "z": 7,
      "name": "Rock_Shale"
    },
    {
      "x": -5,
      "y": 20,
      "z": 7,
      "name": "Rock_Shale"
    },
    {
      "x": -5,
      "y": 13,
      "z": 8,
      "name": "Rock_Shale"
    },
    {
      "x": -5,
      "y": 14,
      "z": 8,
      "name": "Rock_Shale"
    },
    {
      "x": -5,
      "y": 15,
      "z": 8,
      "name": "Rock_Shale"
    },
    {
      "x": -5,
      "y": 16,
      "z": 8,
      "name": "Rock_Shale"
    },
    {
      "x": -5,
      "y": 17,
      "z": 8,
      "name": "Rock_Shale"
    },
    {
      "x": -5,
      "y": 18,
      "z": 8,
      "name": "Rock_Basalt"
    },
    {
      "x": -5,
      "y": 19,
      "z": 8,
      "name": "Rock_Shale"
    },
    {
      "x": -5,
      "y": 20,
      "z": 8,
      "name": "Rock_Shale"
    },
    {
      "x": -5,
      "y": 13,
      "z": 9,
      "name": "Rock_Shale"
    },
    {
      "x": -5,
      "y": 14,
      "z": 9,
      "name": "Rock_Shale"
    },
    {
      "x": -5,
      "y": 15,
      "z": 9,
      "name": "Rock_Shale"
    },
    {
      "x": -5,
      "y": 16,
      "z": 9,
      "name": "Rock_Shale"
    },
    {
      "x": -5,
      "y": 17,
      "z": 9,
      "name": "Rock_Shale"
    },
    {
      "x": -5,
      "y": 18,
      "z": 9,
      "name": "Rock_Shale"
    },
    {
      "x": -5,
      "y": 19,
      "z": 9,
      "name": "Rock_Shale"
    },
    {
      "x": -5,
      "y": 20,
      "z": 9,
      "name": "Rock_Shale"
    },
    {
      "x": -4,
      "y": 0,
      "z": -8,
      "name": "Rock_Shale_Brick_Smooth"
    },
    {
      "x": -4,
      "y": 5,
      "z": -8,
      "name": "Rock_Shale_Brick"
    },
    {
      "x": -4,
      "y": 6,
      "z": -8,
      "name": "Rock_Shale"
    },
    {
      "x": -4,
      "y": 0,
      "z": -7,
      "name": "Rock_Shale_Brick_Smooth"
    },
    {
      "x": -4,
      "y": 4,
      "z": -7,
      "name": "Rock_Shale_Brick_Stairs",
      "rotation": 8
    },
    {
      "x": -4,
      "y": 5,
      "z": -7,
      "name": "Rock_Shale_Brick"
    },
    {
      "x": -4,
      "y": 6,
      "z": -7,
      "name": "Rock_Shale"
    },
    {
      "x": -4,
      "y": 0,
      "z": -6,
      "name": "Rock_Shale_Brick_Smooth"
    },
    {
      "x": -4,
      "y": 1,
      "z": -6,
      "name": "Rock_Shale_Brick_Pillar_Base"
    },
    {
      "x": -4,
      "y": 2,
      "z": -6,
      "name": "Rock_Shale_Brick_Pillar_Middle"
    },
    {
      "x": -4,
      "y": 3,
      "z": -6,
      "name": "Rock_Shale_Brick_Pillar_Base",
      "rotation": 8
    },
    {
      "x": -4,
      "y": 4,
      "z": -6,
      "name": "Rock_Shale_Brick"
    },
    {
      "x": -4,
      "y": 5,
      "z": -6,
      "name": "Rock_Shale_Brick"
    },
    {
      "x": -4,
      "y": 6,
      "z": -6,
      "name": "Rock_Shale_Brick"
    },
    {
      "x": -4,
      "y": 7,
      "z": -6,
      "name": "Rock_Shale"
    },
    {
      "x": -4,
      "y": 0,
      "z": -5,
      "name": "Rock_Shale_Brick_Smooth"
    },
    {
      "x": -4,
      "y": 1,
      "z": -5,
      "name": "Rock_Shale_Brick"
    },
    {
      "x": -4,
      "y": 6,
      "z": -5,
      "name": "Rock_Shale_Brick_Stairs",
      "rotation": 10
    },
    {
      "x": -4,
      "y": 7,
      "z": -5,
      "name": "Rock_Shale_Brick"
    },
    {
      "x": -4,
      "y": 8,
      "z": -5,
      "name": "Rock_Shale"
    },
    {
      "x": -4,
      "y": 1,
      "z": -4,
      "name": "Rock_Shale_Brick"
    },
    {
      "x": -4,
      "y": 2,
      "z": -4,
      "name": "Rock_Shale_Brick"
    },
    {
      "x": -4,
      "y": 4,
      "z": -4,
      "name": "Plant_Leaves_Wisteria_Wild",
      "support": 15
    },
    {
      "x": -4,
      "y": 7,
      "z": -4,
      "name": "Rock_Shale_Brick_Stairs",
      "rotation": 10
    },
    {
      "x": -4,
      "y": 8,
      "z": -4,
      "name": "Rock_Shale_Brick"
    },
    {
      "x": -4,
      "y": 9,
      "z": -4,
      "name": "Rock_Shale"
    },
    {
      "x": -4,
      "y": 2,
      "z": -3,
      "name": "Rock_Shale_Brick"
    },
    {
      "x": -4,
      "y": 3,
      "z": -3,
      "name": "Rock_Shale_Brick"
    },
    {
      "x": -4,
      "y": 4,
      "z": -3,
      "name": "Plant_Leaves_Wisteria_Wild",
      "support": 15
    },
    {
      "x": -4,
      "y": 5,
      "z": -3,
      "name": "Plant_Leaves_Wisteria_Wild",
      "support": 15
    },
    {
      "x": -4,
      "y": 8,
      "z": -3,
      "name": "Rock_Shale_Brick_Stairs",
      "rotation": 10
    },
    {
      "x": -4,
      "y": 9,
      "z": -3,
      "name": "Rock_Shale_Brick"
    },
    {
      "x": -4,
      "y": 10,
      "z": -3,
      "name": "Rock_Shale"
    },
    {
      "x": -4,
      "y": 3,
      "z": -2,
      "name": "Rock_Shale_Brick"
    },
    {
      "x": -4,
      "y": 4,
      "z": -2,
      "name": "Rock_Shale_Brick"
    },
    {
      "x": -4,
      "y": 5,
      "z": -2,
      "name": "Plant_Leaves_Wisteria_Wild",
      "support": 15
    },
    {
      "x": -4,
      "y": 9,
      "z": -2,
      "name": "Rock_Shale_Brick_Stairs",
      "rotation": 10
    },
    {
      "x": -4,
      "y": 10,
      "z": -2,
      "name": "Rock_Shale_Brick"
    },
    {
      "x": -4,
      "y": 11,
      "z": -2,
      "name": "Rock_Shale"
    },
    {
      "x": -4,
      "y": 4,
      "z": -1,
      "name": "Rock_Shale_Brick"
    },
    {
      "x": -4,
      "y": 5,
      "z": -1,
      "name": "Rock_Shale_Brick"
    },
    {
      "x": -4,
      "y": 10,
      "z": -1,
      "name": "Rock_Shale_Brick_Stairs",
      "rotation": 10
    },
    {
      "x": -4,
      "y": 11,
      "z": -1,
      "name": "Rock_Shale_Brick"
    },
    {
      "x": -4,
      "y": 12,
      "z": -1,
      "name": "Rock_Shale"
    },
    {
      "x": -4,
      "y": 5,
      "z": 0,
      "name": "Rock_Shale_Brick"
    },
    {
      "x": -4,
      "y": 6,
      "z": 0,
      "name": "Rock_Shale_Brick"
    },
    {
      "x": -4,
      "y": 11,
      "z": 0,
      "name": "Rock_Shale_Brick_Stairs",
      "rotation": 10
    },
    {
      "x": -4,
      "y": 12,
      "z": 0,
      "name": "Rock_Shale_Brick"
    },
    {
      "x": -4,
      "y": 13,
      "z": 0,
      "name": "Rock_Shale"
    },
    {
      "x": -4,
      "y": 6,
      "z": 1,
      "name": "Rock_Shale_Brick"
    },
    {
      "x": -4,
      "y": 7,
      "z": 1,
      "name": "Rock_Shale_Brick_Pillar_Base"
    },
    {
      "x": -4,
      "y": 8,
      "z": 1,
      "name": "Rock_Shale_Brick_Pillar_Middle"
    },
    {
      "x": -4,
      "y": 9,
      "z": 1,
      "name": "Rock_Shale_Brick_Pillar_Middle"
    },
    {
      "x": -4,
      "y": 10,
      "z": 1,
      "name": "Rock_Shale_Brick_Pillar_Base",
      "rotation": 8
    },
    {
      "x": -4,
      "y": 11,
      "z": 1,
      "name": "Rock_Shale_Brick"
    },
    {
      "x": -4,
      "y": 12,
      "z": 1,
      "name": "Rock_Shale_Brick"
    },
    {
      "x": -4,
      "y": 13,
      "z": 1,
      "name": "Rock_Shale_Brick"
    },
    {
      "x": -4,
      "y": 14,
      "z": 1,
      "name": "Rock_Shale"
    },
    {
      "x": -4,
      "y": 7,
      "z": 2,
      "name": "Rock_Shale_Brick"
    },
    {
      "x": -4,
      "y": 8,
      "z": 2,
      "name": "Rock_Shale_Brick"
    },
    {
      "x": -4,
      "y": 13,
      "z": 2,
      "name": "Rock_Shale_Brick_Stairs",
      "rotation": 10
    },
    {
      "x": -4,
      "y": 14,
      "z": 2,
      "name": "Rock_Shale_Brick"
    },
    {
      "x": -4,
      "y": 15,
      "z": 2,
      "name": "Rock_Shale"
    },
    {
      "x": -4,
      "y": 8,
      "z": 3,
      "name": "Rock_Shale_Brick"
    },
    {
      "x": -4,
      "y": 9,
      "z": 3,
      "name": "Rock_Shale_Brick"
    },
    {
      "x": -4,
      "y": 10,
      "z": 3,
      "name": "Plant_Leaves_Wisteria_Wild",
      "support": 15
    },
    {
      "x": -4,
      "y": 14,
      "z": 3,
      "name": "Rock_Shale_Brick_Stairs",
      "rotation": 10
    },
    {
      "x": -4,
      "y": 15,
      "z": 3,
      "name": "Rock_Shale_Brick"
    },
    {
      "x": -4,
      "y": 16,
      "z": 3,
      "name": "Rock_Shale"
    },
    {
      "x": -4,
      "y": 9,
      "z": 4,
      "name": "Rock_Shale_Brick"
    },
    {
      "x": -4,
      "y": 10,
      "z": 4,
      "name": "Rock_Shale_Brick"
    },
    {
      "x": -4,
      "y": 15,
      "z": 4,
      "name": "Rock_Shale_Brick_Stairs",
      "rotation": 10
    },
    {
      "x": -4,
      "y": 16,
      "z": 4,
      "name": "Rock_Shale_Brick"
    },
    {
      "x": -4,
      "y": 17,
      "z": 4,
      "name": "Rock_Shale"
    },
    {
      "x": -4,
      "y": 10,
      "z": 5,
      "name": "Rock_Shale_Brick"
    },
    {
      "x": -4,
      "y": 11,
      "z": 5,
      "name": "Rock_Shale_Brick_Pillar_Base"
    },
    {
      "x": -4,
      "y": 12,
      "z": 5,
      "name": "Rock_Shale_Brick_Pillar_Middle"
    },
    {
      "x": -4,
      "y": 13,
      "z": 5,
      "name": "Rock_Shale_Brick_Pillar_Middle"
    },
    {
      "x": -4,
      "y": 14,
      "z": 5,
      "name": "Rock_Shale_Brick_Pillar_Base",
      "rotation": 8
    },
    {
      "x": -4,
      "y": 15,
      "z": 5,
      "name": "Rock_Shale_Brick"
    },
    {
      "x": -4,
      "y": 16,
      "z": 5,
      "name": "Rock_Shale_Brick"
    },
    {
      "x": -4,
      "y": 17,
      "z": 5,
      "name": "Rock_Shale_Brick"
    },
    {
      "x": -4,
      "y": 18,
      "z": 5,
      "name": "Rock_Shale"
    },
    {
      "x": -4,
      "y": 11,
      "z": 6,
      "name": "Rock_Shale_Brick"
    },
    {
      "x": -4,
      "y": 12,
      "z": 6,
      "name": "Rock_Shale_Brick"
    },
    {
      "x": -4,
      "y": 17,
      "z": 6,
      "name": "Rock_Shale_Brick_Stairs",
      "rotation": 10
    },
    {
      "x": -4,
      "y": 18,
      "z": 6,
      "name": "Rock_Shale_Brick"
    },
    {
      "x": -4,
      "y": 19,
      "z": 6,
      "name": "Rock_Shale"
    },
    {
      "x": -4,
      "y": 12,
      "z": 7,
      "name": "Rock_Shale_Brick"
    },
    {
      "x": -4,
      "y": 13,
      "z": 7,
      "name": "Rock_Shale_Brick"
    },
    {
      "x": -4,
      "y": 18,
      "z": 7,
      "name": "Rock_Shale_Brick_Stairs",
      "rotation": 10
    },
    {
      "x": -4,
      "y": 19,
      "z": 7,
      "name": "Rock_Shale_Brick"
    },
    {
      "x": -4,
      "y": 20,
      "z": 7,
      "name": "Rock_Shale"
    },
    {
      "x": -4,
      "y": 13,
      "z": 8,
      "name": "Rock_Shale_Brick"
    },
    {
      "x": -4,
      "y": 14,
      "z": 8,
      "name": "Rock_Shale_Brick"
    },
    {
      "x": -4,
      "y": 19,
      "z": 8,
      "name": "Rock_Shale_Brick"
    },
    {
      "x": -4,
      "y": 20,
      "z": 8,
      "name": "Rock_Shale"
    },
    {
      "x": -4,
      "y": 13,
      "z": 9,
      "name": "Rock_Shale_Brick_Smooth"
    },
    {
      "x": -4,
      "y": 14,
      "z": 9,
      "name": "Rock_Shale_Brick_Pillar_Base"
    },
    {
      "x": -4,
      "y": 15,
      "z": 9,
      "name": "Rock_Shale_Brick_Pillar_Middle"
    },
    {
      "x": -4,
      "y": 16,
      "z": 9,
      "name": "Rock_Shale_Brick_Pillar_Middle"
    },
    {
      "x": -4,
      "y": 17,
      "z": 9,
      "name": "Rock_Shale_Brick_Pillar_Base",
      "rotation": 8
    },
    {
      "x": -4,
      "y": 18,
      "z": 9,
      "name": "Rock_Shale_Brick"
    },
    {
      "x": -4,
      "y": 19,
      "z": 9,
      "name": "Rock_Shale_Brick"
    },
    {
      "x": -4,
      "y": 20,
      "z": 9,
      "name": "Rock_Shale"
    },
    {
      "x": -3,
      "y": 0,
      "z": -8,
      "name": "Rock_Shale_Brick_Smooth"
    },
    {
      "x": -3,
      "y": 6,
      "z": -8,
      "name": "Rock_Shale"
    },
    {
      "x": -3,
      "y": 0,
      "z": -7,
      "name": "Rock_Shale_Brick_Smooth"
    },
    {
      "x": -3,
      "y": 6,
      "z": -7,
      "name": "Rock_Shale"
    },
    {
      "x": -3,
      "y": 0,
      "z": -6,
      "name": "Soil_Dirt_Cold"
    },
    {
      "x": -3,
      "y": 1,
      "z": -6,
      "name": "Plant_Crop_Mushroom_Glowing_Violet"
    },
    {
      "x": -3,
      "y": 6,
      "z": -6,
      "name": "Rock_Shale_Brick_Stairs",
      "rotation": 11
    },
    {
      "x": -3,
      "y": 7,
      "z": -6,
      "name": "Rock_Shale"
    },
    {
      "x": -3,
      "y": 0,
      "z": -5,
      "name": "Soil_Dirt_Cold"
    },
    {
      "x": -3,
      "y": 1,
      "z": -5,
      "name": "Rubble_Basalt"
    },
    {
      "x": -3,
      "y": 7,
      "z": -5,
      "name": "Plant_Leaves_Wisteria_Wild",
      "support": 15
    },
    {
      "x": -3,
      "y": 8,
      "z": -5,
      "name": "Rock_Shale"
    },
    {
      "x": -3,
      "y": 1,
      "z": -4,
      "name": "Rock_Shale_Brick_Stairs",
      "rotation": 2
    },
    {
      "x": -3,
      "y": 9,
      "z": -4,
      "name": "Rock_Shale"
    },
    {
      "x": -3,
      "y": 2,
      "z": -3,
      "name": "Rock_Shale_Brick_Stairs",
      "rotation": 2
    },
    {
      "x": -3,
      "y": 10,
      "z": -3,
      "name": "Rock_Shale"
    },
    {
      "x": -3,
      "y": 3,
      "z": -2,
      "name": "Rock_Shale_Brick_Stairs",
      "rotation": 2
    },
    {
      "x": -3,
      "y": 10,
      "z": -2,
      "name": "Plant_Bush_Dead_Hanging"
    },
    {
      "x": -3,
      "y": 11,
      "z": -2,
      "name": "Rock_Shale"
    },
    {
      "x": -3,
      "y": 4,
      "z": -1,
      "name": "Soil_Dirt_Cold"
    },
    {
      "x": -3,
      "y": 5,
      "z": -1,
      "name": "Soil_Dirt_Cold"
    },
    {
      "x": -3,
      "y": 6,
      "z": -1,
      "name": "*Plant_Crop_Berry_Winter_Block_State_Definitions_StageFinal"
    },
    {
      "x": -3,
      "y": 12,
      "z": -1,
      "name": "Rock_Shale"
    },
    {
      "x": -3,
      "y": 5,
      "z": 0,
      "name": "Soil_Dirt_Cold"
    },
    {
      "x": -3,
      "y": 6,
      "z": 0,
      "name": "Soil_Dirt_Cold"
    },
    {
      "x": -3,
      "y": 13,
      "z": 0,
      "name": "Rock_Shale"
    },
    {
      "x": -3,
      "y": 6,
      "z": 1,
      "name": "Rock_Shale_Brick_Stairs",
      "rotation": 2
    },
    {
      "x": -3,
      "y": 13,
      "z": 1,
      "name": "Rock_Shale_Brick_Stairs",
      "rotation": 11
    },
    {
      "x": -3,
      "y": 14,
      "z": 1,
      "name": "Rock_Shale"
    },
    {
      "x": -3,
      "y": 7,
      "z": 2,
      "name": "Rock_Shale_Brick_Stairs",
      "rotation": 2
    },
    {
      "x": -3,
      "y": 14,
      "z": 2,
      "name": "Plant_Vine_Wall",
      "support": 15,
      "rotation": 1
    },
    {
      "x": -3,
      "y": 15,
      "z": 2,
      "name": "Rock_Shale"
    },
    {
      "x": -3,
      "y": 8,
      "z": 3,
      "name": "Rock_Shale_Brick_Stairs",
      "rotation": 2
    },
    {
      "x": -3,
      "y": 16,
      "z": 3,
      "name": "Rock_Shale"
    },
    {
      "x": -3,
      "y": 9,
      "z": 4,
      "name": "Rock_Shale_Brick_Stairs",
      "rotation": 2
    },
    {
      "x": -3,
      "y": 17,
      "z": 4,
      "name": "Rock_Shale"
    },
    {
      "x": -3,
      "y": 10,
      "z": 5,
      "name": "Soil_Dirt_Cold"
    },
    {
      "x": -3,
      "y": 11,
      "z": 5,
      "name": "Rubble_Basalt_Medium"
    },
    {
      "x": -3,
      "y": 17,
      "z": 5,
      "name": "Rock_Shale_Brick_Stairs",
      "rotation": 11
    },
    {
      "x": -3,
      "y": 18,
      "z": 5,
      "name": "Rock_Shale"
    },
    {
      "x": -3,
      "y": 11,
      "z": 6,
      "name": "Soil_Dirt_Cold"
    },
    {
      "x": -3,
      "y": 12,
      "z": 6,
      "name": "Plant_Grass_Sharp_Tall",
      "support": 15
    },
    {
      "x": -3,
      "y": 13,
      "z": 6,
      "name": "Plant_Grass_Sharp_Tall",
      "filler": 1024
    },
    {
      "x": -3,
      "y": 19,
      "z": 6,
      "name": "Rock_Shale"
    },
    {
      "x": -3,
      "y": 12,
      "z": 7,
      "name": "Soil_Dirt_Cold"
    },
    {
      "x": -3,
      "y": 13,
      "z": 7,
      "name": "Plant_Bush_Dead_Twisted"
    },
    {
      "x": -3,
      "y": 20,
      "z": 7,
      "name": "Rock_Shale"
    },
    {
      "x": -3,
      "y": 13,
      "z": 8,
      "name": "Soil_Dirt_Cold"
    },
    {
      "x": -3,
      "y": 14,
      "z": 8,
      "name": "*Plant_Crop_Berry_Winter_Block_State_Definitions_StageFinal"
    },
    {
      "x": -3,
      "y": 19,
      "z": 8,
      "name": "Plant_Bush_Dead_Hanging"
    },
    {
      "x": -3,
      "y": 20,
      "z": 8,
      "name": "Rock_Shale"
    },
    {
      "x": -3,
      "y": 13,
      "z": 9,
      "name": "Soil_Dirt_Cold"
    },
    {
      "x": -3,
      "y": 14,
      "z": 9,
      "name": "Rock_Shale_Brick_Beam"
    },
    {
      "x": -3,
      "y": 15,
      "z": 9,
      "name": "Furniture_Human_Ruins_Torch"
    },
    {
      "x": -3,
      "y": 19,
      "z": 9,
      "name": "Rock_Shale_Brick_Stairs",
      "rotation": 11
    },
    {
      "x": -3,
      "y": 20,
      "z": 9,
      "name": "Rock_Shale"
    },
    {
      "x": -2,
      "y": 0,
      "z": -8,
      "name": "Rock_Shale"
    },
    {
      "x": -2,
      "y": 6,
      "z": -8,
      "name": "Rock_Basalt"
    },
    {
      "x": -2,
      "y": 0,
      "z": -7,
      "name": "Rock_Shale"
    },
    {
      "x": -2,
      "y": 6,
      "z": -7,
      "name": "Rock_Basalt"
    },
    {
      "x": -2,
      "y": 0,
      "z": -6,
      "name": "Soil_Dirt_Cold"
    },
    {
      "x": -2,
      "y": 6,
      "z": -6,
      "name": "Plant_Vine_Wall",
      "support": 15
    },
    {
      "x": -2,
      "y": 7,
      "z": -6,
      "name": "Rock_Basalt"
    },
    {
      "x": -2,
      "y": 0,
      "z": -5,
      "name": "Soil_Dirt_Cold"
    },
    {
      "x": -2,
      "y": 8,
      "z": -5,
      "name": "Rock_Basalt"
    },
    {
      "x": -2,
      "y": 1,
      "z": -4,
      "name": "Rock_Shale_Brick_Stairs",
      "rotation": 2
    },
    {
      "x": -2,
      "y": 9,
      "z": -4,
      "name": "Rock_Basalt"
    },
    {
      "x": -2,
      "y": 2,
      "z": -3,
      "name": "Rock_Shale_Brick_Stairs",
      "rotation": 2
    },
    {
      "x": -2,
      "y": 10,
      "z": -3,
      "name": "Rock_Basalt"
    },
    {
      "x": -2,
      "y": 3,
      "z": -2,
      "name": "Rock_Shale_Brick_Stairs",
      "rotation": 2
    },
    {
      "x": -2,
      "y": 11,
      "z": -2,
      "name": "Rock_Basalt"
    },
    {
      "x": -2,
      "y": 4,
      "z": -1,
      "name": "Soil_Dirt_Cold"
    },
    {
      "x": -2,
      "y": 5,
      "z": -1,
      "name": "Soil_Dirt_Cold"
    },
    {
      "x": -2,
      "y": 12,
      "z": -1,
      "name": "Rock_Basalt"
    },
    {
      "x": -2,
      "y": 5,
      "z": 0,
      "name": "Soil_Dirt_Cold"
    },
    {
      "x": -2,
      "y": 6,
      "z": 0,
      "name": "Plant_Bush_Dead_Twisted"
    },
    {
      "x": -2,
      "y": 13,
      "z": 0,
      "name": "Rock_Basalt"
    },
    {
      "x": -2,
      "y": 6,
      "z": 1,
      "name": "Rock_Shale_Brick_Stairs",
      "rotation": 2
    },
    {
      "x": -2,
      "y": 13,
      "z": 1,
      "name": "Plant_Vine_Wall",
      "support": 15
    },
    {
      "x": -2,
      "y": 14,
      "z": 1,
      "name": "Rock_Basalt"
    },
    {
      "x": -2,
      "y": 7,
      "z": 2,
      "name": "Rock_Shale_Brick_Stairs",
      "rotation": 2
    },
    {
      "x": -2,
      "y": 15,
      "z": 2,
      "name": "Rock_Basalt"
    },
    {
      "x": -2,
      "y": 8,
      "z": 3,
      "name": "Rock_Shale_Brick_Stairs",
      "rotation": 2
    },
    {
      "x": -2,
      "y": 16,
      "z": 3,
      "name": "Rock_Basalt"
    },
    {
      "x": -2,
      "y": 9,
      "z": 4,
      "name": "Soil_Dirt_Cold"
    },
    {
      "x": -2,
      "y": 10,
      "z": 4,
      "name": "Plant_Grass_Gnarled_Tall",
      "support": 15
    },
    {
      "x": -2,
      "y": 11,
      "z": 4,
      "name": "Plant_Grass_Gnarled_Tall",
      "filler": 1024
    },
    {
      "x": -2,
      "y": 17,
      "z": 4,
      "name": "Rock_Basalt"
    },
    {
      "x": -2,
      "y": 10,
      "z": 5,
      "name": "Rock_Shale_Brick_Stairs",
      "rotation": 2
    },
    {
      "x": -2,
      "y": 18,
      "z": 5,
      "name": "Rock_Basalt"
    },
    {
      "x": -2,
      "y": 11,
      "z": 6,
      "name": "Rock_Shale_Brick_Stairs",
      "rotation": 2
    },
    {
      "x": -2,
      "y": 18,
      "z": 6,
      "name": "Plant_Vine_Wall",
      "support": 15
    },
    {
      "x": -2,
      "y": 19,
      "z": 6,
      "name": "Rock_Basalt"
    },
    {
      "x": -2,
      "y": 12,
      "z": 7,
      "name": "Soil_Dirt_Cold"
    },
    {
      "x": -2,
      "y": 20,
      "z": 7,
      "name": "Rock_Basalt"
    },
    {
      "x": -2,
      "y": 13,
      "z": 8,
      "name": "Soil_Dirt_Cold"
    },
    {
      "x": -2,
      "y": 20,
      "z": 8,
      "name": "Rock_Basalt"
    },
    {
      "x": -2,
      "y": 13,
      "z": 9,
      "name": "Soil_Dirt_Cold"
    },
    {
      "x": -2,
      "y": 20,
      "z": 9,
      "name": "Rock_Basalt"
    },
    {
      "x": -1,
      "y": 0,
      "z": -8,
      "name": "Rock_Shale"
    },
    {
      "x": -1,
      "y": 6,
      "z": -8,
      "name": "Rock_Basalt"
    },
    {
      "x": -1,
      "y": 0,
      "z": -7,
      "name": "Rock_Shale"
    },
    {
      "x": -1,
      "y": 6,
      "z": -7,
      "name": "Rock_Basalt"
    },
    {
      "x": -1,
      "y": 0,
      "z": -6,
      "name": "Soil_Dirt_Cold"
    },
    {
      "x": -1,
      "y": 7,
      "z": -6,
      "name": "Rock_Basalt"
    },
    {
      "x": -1,
      "y": 0,
      "z": -5,
      "name": "Soil_Dirt_Cold"
    },
    {
      "x": -1,
      "y": 8,
      "z": -5,
      "name": "Rock_Basalt"
    },
    {
      "x": -1,
      "y": 1,
      "z": -4,
      "name": "Rock_Shale_Brick_Stairs",
      "rotation": 2
    },
    {
      "x": -1,
      "y": 8,
      "z": -4,
      "name": "Plant_Vine_Wall",
      "support": 15
    },
    {
      "x": -1,
      "y": 9,
      "z": -4,
      "name": "Rock_Basalt"
    },
    {
      "x": -1,
      "y": 2,
      "z": -3,
      "name": "Rock_Shale_Brick_Stairs",
      "rotation": 2
    },
    {
      "x": -1,
      "y": 10,
      "z": -3,
      "name": "Rock_Basalt"
    },
    {
      "x": -1,
      "y": 3,
      "z": -2,
      "name": "Rock_Shale_Brick_Stairs",
      "rotation": 2
    },
    {
      "x": -1,
      "y": 11,
      "z": -2,
      "name": "Rock_Basalt"
    },
    {
      "x": -1,
      "y": 4,
      "z": -1,
      "name": "Soil_Dirt_Cold"
    },
    {
      "x": -1,
      "y": 5,
      "z": -1,
      "name": "Rubble_Basalt"
    },
    {
      "x": -1,
      "y": 12,
      "z": -1,
      "name": "Rock_Basalt"
    },
    {
      "x": -1,
      "y": 5,
      "z": 0,
      "name": "Rock_Shale_Brick_Stairs",
      "rotation": 2
    },
    {
      "x": -1,
      "y": 12,
      "z": 0,
      "name": "Plant_Vine_Wall",
      "support": 15
    },
    {
      "x": -1,
      "y": 13,
      "z": 0,
      "name": "Rock_Basalt"
    },
    {
      "x": -1,
      "y": 6,
      "z": 1,
      "name": "Rock_Shale_Brick_Stairs",
      "rotation": 2
    },
    {
      "x": -1,
      "y": 14,
      "z": 1,
      "name": "Rock_Basalt"
    },
    {
      "x": -1,
      "y": 7,
      "z": 2,
      "name": "Rock_Shale_Brick_Stairs",
      "rotation": 2
    },
    {
      "x": -1,
      "y": 15,
      "z": 2,
      "name": "Rock_Basalt"
    },
    {
      "x": -1,
      "y": 8,
      "z": 3,
      "name": "Rock_Shale_Brick_Stairs",
      "rotation": 2
    },
    {
      "x": -1,
      "y": 16,
      "z": 3,
      "name": "Rock_Basalt"
    },
    {
      "x": -1,
      "y": 9,
      "z": 4,
      "name": "Rock_Shale_Brick_Stairs",
      "rotation": 2
    },
    {
      "x": -1,
      "y": 16,
      "z": 4,
      "name": "Plant_Bush_Dead_Hanging"
    },
    {
      "x": -1,
      "y": 17,
      "z": 4,
      "name": "Rock_Basalt"
    },
    {
      "x": -1,
      "y": 10,
      "z": 5,
      "name": "Rock_Shale_Brick_Stairs",
      "rotation": 2
    },
    {
      "x": -1,
      "y": 18,
      "z": 5,
      "name": "Rock_Basalt"
    },
    {
      "x": -1,
      "y": 11,
      "z": 6,
      "name": "Rock_Shale_Brick_Stairs",
      "rotation": 2
    },
    {
      "x": -1,
      "y": 16,
      "z": 6,
      "name": "Plant_Leaves_Wisteria_Wild",
      "support": 15
    },
    {
      "x": -1,
      "y": 17,
      "z": 6,
      "name": "Plant_Leaves_Wisteria_Wild",
      "support": 15
    },
    {
      "x": -1,
      "y": 18,
      "z": 6,
      "name": "Plant_Leaves_Wisteria_Wild",
      "support": 15
    },
    {
      "x": -1,
      "y": 19,
      "z": 6,
      "name": "Rock_Basalt"
    },
    {
      "x": -1,
      "y": 12,
      "z": 7,
      "name": "Rock_Shale_Brick_Stairs",
      "rotation": 2
    },
    {
      "x": -1,
      "y": 20,
      "z": 7,
      "name": "Rock_Basalt"
    },
    {
      "x": -1,
      "y": 13,
      "z": 8,
      "name": "Rock_Shale_Brick_Stairs",
      "rotation": 2
    },
    {
      "x": -1,
      "y": 20,
      "z": 8,
      "name": "Rock_Basalt"
    },
    {
      "x": -1,
      "y": 13,
      "z": 9,
      "name": "Rock_Shale"
    },
    {
      "x": -1,
      "y": 20,
      "z": 9,
      "name": "Rock_Basalt"
    },
    {
      "x": 0,
      "y": 0,
      "z": -8,
      "name": "Rock_Shale"
    },
    {
      "x": 0,
      "y": 6,
      "z": -8,
      "name": "Rock_Basalt"
    },
    {
      "x": 0,
      "y": 0,
      "z": -7,
      "name": "Rock_Shale"
    },
    {
      "x": 0,
      "y": 6,
      "z": -7,
      "name": "Rock_Basalt"
    },
    {
      "x": 0,
      "y": 0,
      "z": -6,
      "name": "Soil_Dirt_Cold"
    },
    {
      "x": 0,
      "y": 7,
      "z": -6,
      "name": "Rock_Basalt"
    },
    {
      "x": 0,
      "y": 0,
      "z": -5,
      "name": "Soil_Dirt_Cold"
    },
    {
      "x": 0,
      "y": 8,
      "z": -5,
      "name": "Rock_Basalt"
    },
    {
      "x": 0,
      "y": 1,
      "z": -4,
      "name": "Rock_Shale_Brick_Stairs",
      "rotation": 2
    },
    {
      "x": 0,
      "y": 9,
      "z": -4,
      "name": "Rock_Basalt"
    },
    {
      "x": 0,
      "y": 2,
      "z": -3,
      "name": "Rock_Shale_Brick_Stairs",
      "rotation": 2
    },
    {
      "x": 0,
      "y": 10,
      "z": -3,
      "name": "Rock_Basalt"
    },
    {
      "x": 0,
      "y": 3,
      "z": -2,
      "name": "Rock_Shale_Brick_Stairs",
      "rotation": 2
    },
    {
      "x": 0,
      "y": 10,
      "z": -2,
      "name": "Plant_Vine_Wall",
      "support": 15
    },
    {
      "x": 0,
      "y": 11,
      "z": -2,
      "name": "Rock_Basalt"
    },
    {
      "x": 0,
      "y": 4,
      "z": -1,
      "name": "Rock_Shale_Brick_Stairs",
      "rotation": 2
    },
    {
      "x": 0,
      "y": 12,
      "z": -1,
      "name": "Rock_Basalt"
    },
    {
      "x": 0,
      "y": 5,
      "z": 0,
      "name": "Rock_Shale_Brick_Stairs",
      "rotation": 2
    },
    {
      "x": 0,
      "y": 11,
      "z": 0,
      "name": "Plant_Leaves_Wisteria_Wild",
      "support": 15
    },
    {
      "x": 0,
      "y": 12,
      "z": 0,
      "name": "Plant_Leaves_Wisteria_Wild",
      "support": 15
    },
    {
      "x": 0,
      "y": 13,
      "z": 0,
      "name": "Rock_Basalt"
    },
    {
      "x": 0,
      "y": 6,
      "z": 1,
      "name": "Rock_Shale_Brick_Stairs",
      "rotation": 2
    },
    {
      "x": 0,
      "y": 13,
      "z": 1,
      "name": "Plant_Leaves_Wisteria_Wild",
      "support": 15
    },
    {
      "x": 0,
      "y": 14,
      "z": 1,
      "name": "Rock_Basalt"
    },
    {
      "x": 0,
      "y": 7,
      "z": 2,
      "name": "Rock_Shale_Brick_Stairs",
      "rotation": 2
    },
    {
      "x": 0,
      "y": 15,
      "z": 2,
      "name": "Rock_Basalt"
    },
    {
      "x": 0,
      "y": 8,
      "z": 3,
      "name": "Rock_Shale_Brick_Stairs",
      "rotation": 2
    },
    {
      "x": 0,
      "y": 16,
      "z": 3,
      "name": "Rock_Basalt"
    },
    {
      "x": 0,
      "y": 9,
      "z": 4,
      "name": "Rock_Shale_Brick_Stairs",
      "rotation": 2
    },
    {
      "x": 0,
      "y": 16,
      "z": 4,
      "name": "Plant_Vine_Wall",
      "support": 15
    },
    {
      "x": 0,
      "y": 17,
      "z": 4,
      "name": "Rock_Basalt"
    },
    {
      "x": 0,
      "y": 10,
      "z": 5,
      "name": "Rock_Shale_Brick_Stairs",
      "rotation": 2
    },
    {
      "x": 0,
      "y": 17,
      "z": 5,
      "name": "Plant_Vine_Wall",
      "support": 15
    },
    {
      "x": 0,
      "y": 18,
      "z": 5,
      "name": "Rock_Basalt"
    },
    {
      "x": 0,
      "y": 11,
      "z": 6,
      "name": "Rock_Shale_Brick_Stairs",
      "rotation": 2
    },
    {
      "x": 0,
      "y": 19,
      "z": 6,
      "name": "Rock_Basalt"
    },
    {
      "x": 0,
      "y": 12,
      "z": 7,
      "name": "Rock_Shale_Brick_Stairs",
      "rotation": 2
    },
    {
      "x": 0,
      "y": 20,
      "z": 7,
      "name": "Rock_Basalt"
    },
    {
      "x": 0,
      "y": 13,
      "z": 8,
      "name": "Rock_Shale_Brick_Stairs",
      "rotation": 2
    },
    {
      "x": 0,
      "y": 20,
      "z": 8,
      "name": "Rock_Basalt"
    },
    {
      "x": 0,
      "y": 13,
      "z": 9,
      "name": "Rock_Shale_Brick_Stairs",
      "rotation": 2
    },
    {
      "x": 0,
      "y": 20,
      "z": 9,
      "name": "Rock_Basalt"
    },
    {
      "x": 1,
      "y": 0,
      "z": -8,
      "name": "Rock_Shale"
    },
    {
      "x": 1,
      "y": 6,
      "z": -8,
      "name": "Rock_Basalt"
    },
    {
      "x": 1,
      "y": 0,
      "z": -7,
      "name": "Rock_Shale"
    },
    {
      "x": 1,
      "y": 6,
      "z": -7,
      "name": "Rock_Basalt"
    },
    {
      "x": 1,
      "y": 0,
      "z": -6,
      "name": "Rock_Shale"
    },
    {
      "x": 1,
      "y": 7,
      "z": -6,
      "name": "Rock_Basalt"
    },
    {
      "x": 1,
      "y": 0,
      "z": -5,
      "name": "Soil_Dirt_Cold"
    },
    {
      "x": 1,
      "y": 7,
      "z": -5,
      "name": "Plant_Vine_Wall",
      "support": 15
    },
    {
      "x": 1,
      "y": 8,
      "z": -5,
      "name": "Rock_Basalt"
    },
    {
      "x": 1,
      "y": 1,
      "z": -4,
      "name": "Rock_Shale_Brick_Stairs",
      "rotation": 2
    },
    {
      "x": 1,
      "y": 8,
      "z": -4,
      "name": "Plant_Leaves_Wisteria_Wild",
      "support": 15
    },
    {
      "x": 1,
      "y": 9,
      "z": -4,
      "name": "Rock_Basalt"
    },
    {
      "x": 1,
      "y": 2,
      "z": -3,
      "name": "Rock_Shale_Brick_Stairs",
      "rotation": 2
    },
    {
      "x": 1,
      "y": 9,
      "z": -3,
      "name": "Plant_Leaves_Wisteria_Wild",
      "support": 15
    },
    {
      "x": 1,
      "y": 10,
      "z": -3,
      "name": "Rock_Basalt"
    },
    {
      "x": 1,
      "y": 3,
      "z": -2,
      "name": "Rock_Shale_Brick_Stairs",
      "rotation": 2
    },
    {
      "x": 1,
      "y": 11,
      "z": -2,
      "name": "Rock_Basalt"
    },
    {
      "x": 1,
      "y": 4,
      "z": -1,
      "name": "Rock_Shale_Brick_Stairs",
      "rotation": 2
    },
    {
      "x": 1,
      "y": 12,
      "z": -1,
      "name": "Rock_Basalt"
    },
    {
      "x": 1,
      "y": 5,
      "z": 0,
      "name": "Rock_Shale_Brick_Stairs",
      "rotation": 2
    },
    {
      "x": 1,
      "y": 13,
      "z": 0,
      "name": "Rock_Basalt"
    },
    {
      "x": 1,
      "y": 6,
      "z": 1,
      "name": "Rock_Shale_Brick_Stairs",
      "rotation": 2
    },
    {
      "x": 1,
      "y": 14,
      "z": 1,
      "name": "Rock_Basalt"
    },
    {
      "x": 1,
      "y": 7,
      "z": 2,
      "name": "Rock_Shale_Brick_Stairs",
      "rotation": 2
    },
    {
      "x": 1,
      "y": 14,
      "z": 2,
      "name": "Plant_Bush_Dead_Hanging"
    },
    {
      "x": 1,
      "y": 15,
      "z": 2,
      "name": "Rock_Basalt"
    },
    {
      "x": 1,
      "y": 8,
      "z": 3,
      "name": "Rock_Shale_Brick_Stairs",
      "rotation": 2
    },
    {
      "x": 1,
      "y": 15,
      "z": 3,
      "name": "Plant_Leaves_Wisteria_Wild",
      "support": 15
    },
    {
      "x": 1,
      "y": 16,
      "z": 3,
      "name": "Rock_Basalt"
    },
    {
      "x": 1,
      "y": 9,
      "z": 4,
      "name": "Rock_Shale_Brick_Stairs",
      "rotation": 2
    },
    {
      "x": 1,
      "y": 17,
      "z": 4,
      "name": "Rock_Basalt"
    },
    {
      "x": 1,
      "y": 10,
      "z": 5,
      "name": "Rock_Shale_Brick_Stairs",
      "rotation": 2
    },
    {
      "x": 1,
      "y": 18,
      "z": 5,
      "name": "Rock_Basalt"
    },
    {
      "x": 1,
      "y": 11,
      "z": 6,
      "name": "Rock_Shale_Brick_Stairs",
      "rotation": 2
    },
    {
      "x": 1,
      "y": 19,
      "z": 6,
      "name": "Rock_Basalt"
    },
    {
      "x": 1,
      "y": 12,
      "z": 7,
      "name": "Rock_Shale_Brick_Stairs",
      "rotation": 2
    },
    {
      "x": 1,
      "y": 20,
      "z": 7,
      "name": "Rock_Basalt"
    },
    {
      "x": 1,
      "y": 13,
      "z": 8,
      "name": "Rock_Shale_Brick_Stairs",
      "rotation": 2
    },
    {
      "x": 1,
      "y": 20,
      "z": 8,
      "name": "Rock_Basalt"
    },
    {
      "x": 1,
      "y": 13,
      "z": 9,
      "name": "Rock_Shale"
    },
    {
      "x": 1,
      "y": 20,
      "z": 9,
      "name": "Rock_Basalt"
    },
    {
      "x": 2,
      "y": 0,
      "z": -8,
      "name": "Soil_Dirt_Cold"
    },
    {
      "x": 2,
      "y": 6,
      "z": -8,
      "name": "Rock_Basalt"
    },
    {
      "x": 2,
      "y": 0,
      "z": -7,
      "name": "Rock_Shale"
    },
    {
      "x": 2,
      "y": 6,
      "z": -7,
      "name": "Rock_Basalt"
    },
    {
      "x": 2,
      "y": 0,
      "z": -6,
      "name": "Rock_Shale"
    },
    {
      "x": 2,
      "y": 7,
      "z": -6,
      "name": "Rock_Basalt"
    },
    {
      "x": 2,
      "y": 0,
      "z": -5,
      "name": "Rock_Shale"
    },
    {
      "x": 2,
      "y": 8,
      "z": -5,
      "name": "Rock_Basalt"
    },
    {
      "x": 2,
      "y": 1,
      "z": -4,
      "name": "Rock_Shale_Brick_Stairs",
      "rotation": 2
    },
    {
      "x": 2,
      "y": 9,
      "z": -4,
      "name": "Rock_Basalt"
    },
    {
      "x": 2,
      "y": 2,
      "z": -3,
      "name": "Soil_Dirt_Cold"
    },
    {
      "x": 2,
      "y": 10,
      "z": -3,
      "name": "Rock_Basalt"
    },
    {
      "x": 2,
      "y": 3,
      "z": -2,
      "name": "Rock_Shale_Brick_Stairs",
      "rotation": 2
    },
    {
      "x": 2,
      "y": 11,
      "z": -2,
      "name": "Rock_Basalt"
    },
    {
      "x": 2,
      "y": 4,
      "z": -1,
      "name": "Rock_Shale_Brick_Stairs",
      "rotation": 2
    },
    {
      "x": 2,
      "y": 11,
      "z": -1,
      "name": "Plant_Vine_Wall",
      "support": 15
    },
    {
      "x": 2,
      "y": 12,
      "z": -1,
      "name": "Rock_Basalt"
    },
    {
      "x": 2,
      "y": 5,
      "z": 0,
      "name": "Rock_Shale_Brick_Stairs",
      "rotation": 2
    },
    {
      "x": 2,
      "y": 12,
      "z": 0,
      "name": "Plant_Vine_Wall",
      "support": 15
    },
    {
      "x": 2,
      "y": 13,
      "z": 0,
      "name": "Rock_Basalt"
    },
    {
      "x": 2,
      "y": 6,
      "z": 1,
      "name": "Rock_Shale_Brick_Stairs",
      "rotation": 2
    },
    {
      "x": 2,
      "y": 14,
      "z": 1,
      "name": "Rock_Basalt"
    },
    {
      "x": 2,
      "y": 7,
      "z": 2,
      "name": "Rock_Shale_Brick_Stairs",
      "rotation": 2
    },
    {
      "x": 2,
      "y": 14,
      "z": 2,
      "name": "Plant_Leaves_Wisteria_Wild",
      "support": 15
    },
    {
      "x": 2,
      "y": 15,
      "z": 2,
      "name": "Rock_Basalt"
    },
    {
      "x": 2,
      "y": 8,
      "z": 3,
      "name": "Soil_Dirt_Cold"
    },
    {
      "x": 2,
      "y": 9,
      "z": 3,
      "name": "Plant_Flower_Bushy_Green"
    },
    {
      "x": 2,
      "y": 15,
      "z": 3,
      "name": "Plant_Leaves_Wisteria_Wild",
      "support": 15
    },
    {
      "x": 2,
      "y": 16,
      "z": 3,
      "name": "Rock_Basalt"
    },
    {
      "x": 2,
      "y": 9,
      "z": 4,
      "name": "Soil_Dirt_Cold"
    },
    {
      "x": 2,
      "y": 10,
      "z": 4,
      "name": "Plant_Grass_Gnarled_Tall",
      "support": 15
    },
    {
      "x": 2,
      "y": 11,
      "z": 4,
      "name": "Plant_Grass_Gnarled_Tall",
      "filler": 1024
    },
    {
      "x": 2,
      "y": 17,
      "z": 4,
      "name": "Rock_Basalt"
    },
    {
      "x": 2,
      "y": 10,
      "z": 5,
      "name": "Rock_Shale_Brick_Stairs",
      "rotation": 2
    },
    {
      "x": 2,
      "y": 18,
      "z": 5,
      "name": "Rock_Basalt"
    },
    {
      "x": 2,
      "y": 11,
      "z": 6,
      "name": "Rock_Shale_Brick_Stairs",
      "rotation": 2
    },
    {
      "x": 2,
      "y": 19,
      "z": 6,
      "name": "Rock_Basalt"
    },
    {
      "x": 2,
      "y": 12,
      "z": 7,
      "name": "Rock_Shale_Brick_Stairs",
      "rotation": 2
    },
    {
      "x": 2,
      "y": 20,
      "z": 7,
      "name": "Rock_Basalt"
    },
    {
      "x": 2,
      "y": 13,
      "z": 8,
      "name": "Rock_Shale_Brick_Stairs",
      "rotation": 2
    },
    {
      "x": 2,
      "y": 20,
      "z": 8,
      "name": "Rock_Basalt"
    },
    {
      "x": 2,
      "y": 13,
      "z": 9,
      "name": "Rock_Shale"
    },
    {
      "x": 2,
      "y": 20,
      "z": 9,
      "name": "Rock_Basalt"
    },
    {
      "x": 3,
      "y": 0,
      "z": -8,
      "name": "Soil_Dirt_Cold"
    },
    {
      "x": 3,
      "y": 1,
      "z": -8,
      "name": "Rubble_Basalt"
    },
    {
      "x": 3,
      "y": 6,
      "z": -8,
      "name": "Rock_Shale"
    },
    {
      "x": 3,
      "y": 0,
      "z": -7,
      "name": "Soil_Dirt_Cold"
    },
    {
      "x": 3,
      "y": 5,
      "z": -7,
      "name": "Plant_Bush_Dead_Hanging"
    },
    {
      "x": 3,
      "y": 6,
      "z": -7,
      "name": "Rock_Shale"
    },
    {
      "x": 3,
      "y": 0,
      "z": -6,
      "name": "Rock_Shale_Brick_Smooth"
    },
    {
      "x": 3,
      "y": 1,
      "z": -6,
      "name": "Rock_Shale_Brick_Beam"
    },
    {
      "x": 3,
      "y": 6,
      "z": -6,
      "name": "Rock_Shale_Brick_Stairs",
      "rotation": 9
    },
    {
      "x": 3,
      "y": 7,
      "z": -6,
      "name": "Rock_Shale"
    },
    {
      "x": 3,
      "y": 0,
      "z": -5,
      "name": "Rock_Shale_Brick_Smooth"
    },
    {
      "x": 3,
      "y": 8,
      "z": -5,
      "name": "Rock_Shale"
    },
    {
      "x": 3,
      "y": 1,
      "z": -4,
      "name": "Rock_Shale_Brick_Stairs",
      "rotation": 2
    },
    {
      "x": 3,
      "y": 9,
      "z": -4,
      "name": "Rock_Shale"
    },
    {
      "x": 3,
      "y": 2,
      "z": -3,
      "name": "Soil_Dirt_Cold"
    },
    {
      "x": 3,
      "y": 10,
      "z": -3,
      "name": "Rock_Shale"
    },
    {
      "x": 3,
      "y": 3,
      "z": -2,
      "name": "Rock_Shale_Brick_Stairs",
      "rotation": 2
    },
    {
      "x": 3,
      "y": 11,
      "z": -2,
      "name": "Rock_Shale"
    },
    {
      "x": 3,
      "y": 4,
      "z": -1,
      "name": "Rock_Shale_Brick_Stairs",
      "rotation": 2
    },
    {
      "x": 3,
      "y": 12,
      "z": -1,
      "name": "Rock_Shale"
    },
    {
      "x": 3,
      "y": 5,
      "z": 0,
      "name": "Rock_Shale_Brick_Stairs",
      "rotation": 2
    },
    {
      "x": 3,
      "y": 13,
      "z": 0,
      "name": "Rock_Shale"
    },
    {
      "x": 3,
      "y": 6,
      "z": 1,
      "name": "Rock_Shale_Brick_Stairs",
      "rotation": 2
    },
    {
      "x": 3,
      "y": 13,
      "z": 1,
      "name": "Rock_Shale_Brick_Stairs",
      "rotation": 9
    },
    {
      "x": 3,
      "y": 14,
      "z": 1,
      "name": "Rock_Shale"
    },
    {
      "x": 3,
      "y": 7,
      "z": 2,
      "name": "Soil_Dirt_Cold"
    },
    {
      "x": 3,
      "y": 8,
      "z": 2,
      "name": "Rubble_Basalt"
    },
    {
      "x": 3,
      "y": 15,
      "z": 2,
      "name": "Rock_Shale"
    },
    {
      "x": 3,
      "y": 8,
      "z": 3,
      "name": "Soil_Dirt_Cold"
    },
    {
      "x": 3,
      "y": 9,
      "z": 3,
      "name": "Plant_Bush_Dead_Twisted"
    },
    {
      "x": 3,
      "y": 15,
      "z": 3,
      "name": "Plant_Leaves_Wisteria_Wild",
      "support": 15
    },
    {
      "x": 3,
      "y": 16,
      "z": 3,
      "name": "Rock_Shale"
    },
    {
      "x": 3,
      "y": 9,
      "z": 4,
      "name": "Soil_Dirt_Cold"
    },
    {
      "x": 3,
      "y": 10,
      "z": 4,
      "name": "Plant_Grass_Sharp_Tall",
      "support": 15
    },
    {
      "x": 3,
      "y": 11,
      "z": 4,
      "name": "Plant_Grass_Sharp_Tall",
      "filler": 1024
    },
    {
      "x": 3,
      "y": 17,
      "z": 4,
      "name": "Rock_Shale"
    },
    {
      "x": 3,
      "y": 10,
      "z": 5,
      "name": "Soil_Dirt_Cold"
    },
    {
      "x": 3,
      "y": 11,
      "z": 5,
      "name": "Plant_Grass_Sharp_Tall",
      "support": 15
    },
    {
      "x": 3,
      "y": 12,
      "z": 5,
      "name": "Plant_Grass_Sharp_Tall",
      "filler": 1024
    },
    {
      "x": 3,
      "y": 17,
      "z": 5,
      "name": "Rock_Shale_Brick_Stairs",
      "rotation": 9
    },
    {
      "x": 3,
      "y": 18,
      "z": 5,
      "name": "Rock_Shale"
    },
    {
      "x": 3,
      "y": 11,
      "z": 6,
      "name": "Soil_Dirt_Cold"
    },
    {
      "x": 3,
      "y": 18,
      "z": 6,
      "name": "Plant_Bush_Dead_Hanging"
    },
    {
      "x": 3,
      "y": 19,
      "z": 6,
      "name": "Rock_Shale"
    },
    {
      "x": 3,
      "y": 12,
      "z": 7,
      "name": "Rock_Shale_Brick_Stairs",
      "rotation": 2
    },
    {
      "x": 3,
      "y": 20,
      "z": 7,
      "name": "Rock_Shale"
    },
    {
      "x": 3,
      "y": 13,
      "z": 8,
      "name": "Rock_Shale_Brick_Stairs",
      "rotation": 2
    },
    {
      "x": 3,
      "y": 20,
      "z": 8,
      "name": "Rock_Shale"
    },
    {
      "x": 3,
      "y": 13,
      "z": 9,
      "name": "Rock_Shale_Brick_Smooth"
    },
    {
      "x": 3,
      "y": 14,
      "z": 9,
      "name": "Rock_Shale_Brick_Beam"
    },
    {
      "x": 3,
      "y": 15,
      "z": 9,
      "name": "Furniture_Human_Ruins_Torch",
      "rotation": 3
    },
    {
      "x": 3,
      "y": 19,
      "z": 9,
      "name": "Rock_Shale_Brick_Stairs",
      "rotation": 9
    },
    {
      "x": 3,
      "y": 20,
      "z": 9,
      "name": "Rock_Shale"
    },
    {
      "x": 4,
      "y": 0,
      "z": -8,
      "name": "Soil_Dirt_Cold"
    },
    {
      "x": 4,
      "y": 1,
      "z": -8,
      "name": "Plant_Bush_Dead_Twisted"
    },
    {
      "x": 4,
      "y": 5,
      "z": -8,
      "name": "Rock_Shale_Brick"
    },
    {
      "x": 4,
      "y": 6,
      "z": -8,
      "name": "Rock_Shale"
    },
    {
      "x": 4,
      "y": 0,
      "z": -7,
      "name": "Soil_Dirt_Cold"
    },
    {
      "x": 4,
      "y": 1,
      "z": -7,
      "name": "Rubble_Basalt_Medium"
    },
    {
      "x": 4,
      "y": 4,
      "z": -7,
      "name": "Rock_Shale_Brick_Stairs",
      "rotation": 8
    },
    {
      "x": 4,
      "y": 5,
      "z": -7,
      "name": "Rock_Shale_Brick"
    },
    {
      "x": 4,
      "y": 6,
      "z": -7,
      "name": "Rock_Shale"
    },
    {
      "x": 4,
      "y": 0,
      "z": -6,
      "name": "Rock_Shale_Brick_Smooth"
    },
    {
      "x": 4,
      "y": 1,
      "z": -6,
      "name": "Rock_Shale_Brick_Pillar_Base"
    },
    {
      "x": 4,
      "y": 2,
      "z": -6,
      "name": "Rock_Shale_Brick_Pillar_Middle"
    },
    {
      "x": 4,
      "y": 3,
      "z": -6,
      "name": "Rock_Shale_Brick_Pillar_Base",
      "rotation": 8
    },
    {
      "x": 4,
      "y": 4,
      "z": -6,
      "name": "Rock_Shale_Brick"
    },
    {
      "x": 4,
      "y": 5,
      "z": -6,
      "name": "Rock_Shale_Brick"
    },
    {
      "x": 4,
      "y": 6,
      "z": -6,
      "name": "Rock_Shale_Brick"
    },
    {
      "x": 4,
      "y": 7,
      "z": -6,
      "name": "Rock_Shale"
    },
    {
      "x": 4,
      "y": 0,
      "z": -5,
      "name": "Rock_Shale_Brick_Smooth"
    },
    {
      "x": 4,
      "y": 1,
      "z": -5,
      "name": "Rock_Shale_Brick"
    },
    {
      "x": 4,
      "y": 2,
      "z": -5,
      "name": "Soil_Dirt_Cold"
    },
    {
      "x": 4,
      "y": 3,
      "z": -5,
      "name": "Plant_Flower_Bushy_Green"
    },
    {
      "x": 4,
      "y": 6,
      "z": -5,
      "name": "Rock_Shale_Brick_Stairs",
      "rotation": 10
    },
    {
      "x": 4,
      "y": 7,
      "z": -5,
      "name": "Rock_Shale_Brick"
    },
    {
      "x": 4,
      "y": 8,
      "z": -5,
      "name": "Rock_Shale"
    },
    {
      "x": 4,
      "y": 1,
      "z": -4,
      "name": "Rock_Shale_Brick"
    },
    {
      "x": 4,
      "y": 2,
      "z": -4,
      "name": "Rock_Shale_Brick"
    },
    {
      "x": 4,
      "y": 3,
      "z": -4,
      "name": "Soil_Dirt_Cold"
    },
    {
      "x": 4,
      "y": 4,
      "z": -4,
      "name": "Plant_Flower_Bushy_Green"
    },
    {
      "x": 4,
      "y": 7,
      "z": -4,
      "name": "Rock_Shale_Brick_Stairs",
      "rotation": 10
    },
    {
      "x": 4,
      "y": 8,
      "z": -4,
      "name": "Rock_Shale_Brick"
    },
    {
      "x": 4,
      "y": 9,
      "z": -4,
      "name": "Rock_Shale"
    },
    {
      "x": 4,
      "y": 2,
      "z": -3,
      "name": "Rock_Shale_Brick"
    },
    {
      "x": 4,
      "y": 3,
      "z": -3,
      "name": "Rock_Shale_Brick"
    },
    {
      "x": 4,
      "y": 8,
      "z": -3,
      "name": "Rock_Shale_Brick_Stairs",
      "rotation": 10
    },
    {
      "x": 4,
      "y": 9,
      "z": -3,
      "name": "Rock_Shale_Brick"
    },
    {
      "x": 4,
      "y": 10,
      "z": -3,
      "name": "Rock_Shale"
    },
    {
      "x": 4,
      "y": 3,
      "z": -2,
      "name": "Rock_Shale_Brick"
    },
    {
      "x": 4,
      "y": 4,
      "z": -2,
      "name": "Rock_Shale_Brick"
    },
    {
      "x": 4,
      "y": 5,
      "z": -2,
      "name": "Plant_Leaves_Wisteria_Wild",
      "support": 15
    },
    {
      "x": 4,
      "y": 6,
      "z": -2,
      "name": "Plant_Leaves_Wisteria_Wild",
      "support": 15
    },
    {
      "x": 4,
      "y": 9,
      "z": -2,
      "name": "Rock_Shale_Brick_Stairs",
      "rotation": 10
    },
    {
      "x": 4,
      "y": 10,
      "z": -2,
      "name": "Rock_Shale_Brick"
    },
    {
      "x": 4,
      "y": 11,
      "z": -2,
      "name": "Rock_Shale"
    },
    {
      "x": 4,
      "y": 4,
      "z": -1,
      "name": "Rock_Shale_Brick"
    },
    {
      "x": 4,
      "y": 5,
      "z": -1,
      "name": "Rock_Shale_Brick"
    },
    {
      "x": 4,
      "y": 6,
      "z": -1,
      "name": "Plant_Leaves_Wisteria_Wild",
      "support": 15
    },
    {
      "x": 4,
      "y": 10,
      "z": -1,
      "name": "Rock_Shale_Brick_Stairs",
      "rotation": 10
    },
    {
      "x": 4,
      "y": 11,
      "z": -1,
      "name": "Rock_Shale_Brick"
    },
    {
      "x": 4,
      "y": 12,
      "z": -1,
      "name": "Rock_Shale"
    },
    {
      "x": 4,
      "y": 5,
      "z": 0,
      "name": "Rock_Shale_Brick"
    },
    {
      "x": 4,
      "y": 6,
      "z": 0,
      "name": "Rock_Shale_Brick"
    },
    {
      "x": 4,
      "y": 7,
      "z": 0,
      "name": "Plant_Leaves_Wisteria_Wild",
      "support": 15
    },
    {
      "x": 4,
      "y": 8,
      "z": 0,
      "name": "Plant_Leaves_Wisteria_Wild",
      "support": 15
    },
    {
      "x": 4,
      "y": 11,
      "z": 0,
      "name": "Rock_Shale_Brick_Stairs",
      "rotation": 10
    },
    {
      "x": 4,
      "y": 12,
      "z": 0,
      "name": "Rock_Shale_Brick"
    },
    {
      "x": 4,
      "y": 13,
      "z": 0,
      "name": "Rock_Shale"
    },
    {
      "x": 4,
      "y": 6,
      "z": 1,
      "name": "Rock_Shale_Brick"
    },
    {
      "x": 4,
      "y": 7,
      "z": 1,
      "name": "Rock_Shale_Brick_Pillar_Base"
    },
    {
      "x": 4,
      "y": 8,
      "z": 1,
      "name": "Rock_Shale_Brick_Pillar_Middle"
    },
    {
      "x": 4,
      "y": 9,
      "z": 1,
      "name": "Rock_Shale_Brick_Pillar_Middle"
    },
    {
      "x": 4,
      "y": 10,
      "z": 1,
      "name": "Rock_Shale_Brick_Pillar_Base",
      "rotation": 8
    },
    {
      "x": 4,
      "y": 11,
      "z": 1,
      "name": "Rock_Shale_Brick"
    },
    {
      "x": 4,
      "y": 12,
      "z": 1,
      "name": "Rock_Shale_Brick"
    },
    {
      "x": 4,
      "y": 13,
      "z": 1,
      "name": "Rock_Shale_Brick"
    },
    {
      "x": 4,
      "y": 14,
      "z": 1,
      "name": "Rock_Shale"
    },
    {
      "x": 4,
      "y": 7,
      "z": 2,
      "name": "Rock_Shale_Brick"
    },
    {
      "x": 4,
      "y": 8,
      "z": 2,
      "name": "Rock_Shale_Brick"
    },
    {
      "x": 4,
      "y": 13,
      "z": 2,
      "name": "Rock_Shale_Brick_Stairs",
      "rotation": 10
    },
    {
      "x": 4,
      "y": 14,
      "z": 2,
      "name": "Rock_Shale_Brick"
    },
    {
      "x": 4,
      "y": 15,
      "z": 2,
      "name": "Rock_Shale"
    },
    {
      "x": 4,
      "y": 8,
      "z": 3,
      "name": "Rock_Shale_Brick"
    },
    {
      "x": 4,
      "y": 9,
      "z": 3,
      "name": "Rock_Shale_Brick"
    },
    {
      "x": 4,
      "y": 14,
      "z": 3,
      "name": "Rock_Shale_Brick_Stairs",
      "rotation": 10
    },
    {
      "x": 4,
      "y": 15,
      "z": 3,
      "name": "Rock_Shale_Brick"
    },
    {
      "x": 4,
      "y": 16,
      "z": 3,
      "name": "Rock_Shale"
    },
    {
      "x": 4,
      "y": 9,
      "z": 4,
      "name": "Rock_Shale_Brick"
    },
    {
      "x": 4,
      "y": 10,
      "z": 4,
      "name": "Rock_Shale_Brick"
    },
    {
      "x": 4,
      "y": 15,
      "z": 4,
      "name": "Rock_Shale_Brick_Stairs",
      "rotation": 10
    },
    {
      "x": 4,
      "y": 16,
      "z": 4,
      "name": "Rock_Shale_Brick"
    },
    {
      "x": 4,
      "y": 17,
      "z": 4,
      "name": "Rock_Shale"
    },
    {
      "x": 4,
      "y": 10,
      "z": 5,
      "name": "Rock_Shale_Brick"
    },
    {
      "x": 4,
      "y": 11,
      "z": 5,
      "name": "Rock_Shale_Brick_Pillar_Base"
    },
    {
      "x": 4,
      "y": 12,
      "z": 5,
      "name": "Rock_Shale_Brick_Pillar_Middle"
    },
    {
      "x": 4,
      "y": 13,
      "z": 5,
      "name": "Rock_Shale_Brick_Pillar_Middle"
    },
    {
      "x": 4,
      "y": 14,
      "z": 5,
      "name": "Rock_Shale_Brick_Pillar_Base",
      "rotation": 8
    },
    {
      "x": 4,
      "y": 15,
      "z": 5,
      "name": "Rock_Shale_Brick"
    },
    {
      "x": 4,
      "y": 16,
      "z": 5,
      "name": "Rock_Shale_Brick"
    },
    {
      "x": 4,
      "y": 17,
      "z": 5,
      "name": "Rock_Shale_Brick"
    },
    {
      "x": 4,
      "y": 18,
      "z": 5,
      "name": "Rock_Shale"
    },
    {
      "x": 4,
      "y": 11,
      "z": 6,
      "name": "Rock_Shale_Brick"
    },
    {
      "x": 4,
      "y": 12,
      "z": 6,
      "name": "Rock_Shale_Brick"
    },
    {
      "x": 4,
      "y": 17,
      "z": 6,
      "name": "Rock_Shale_Brick_Stairs",
      "rotation": 10
    },
    {
      "x": 4,
      "y": 18,
      "z": 6,
      "name": "Rock_Shale_Brick"
    },
    {
      "x": 4,
      "y": 19,
      "z": 6,
      "name": "Rock_Shale"
    },
    {
      "x": 4,
      "y": 12,
      "z": 7,
      "name": "Rock_Shale_Brick"
    },
    {
      "x": 4,
      "y": 13,
      "z": 7,
      "name": "Rock_Shale_Brick"
    },
    {
      "x": 4,
      "y": 18,
      "z": 7,
      "name": "Rock_Shale_Brick_Stairs",
      "rotation": 10
    },
    {
      "x": 4,
      "y": 19,
      "z": 7,
      "name": "Rock_Shale_Brick"
    },
    {
      "x": 4,
      "y": 20,
      "z": 7,
      "name": "Rock_Shale"
    },
    {
      "x": 4,
      "y": 13,
      "z": 8,
      "name": "Rock_Shale_Brick"
    },
    {
      "x": 4,
      "y": 14,
      "z": 8,
      "name": "Rock_Shale_Brick"
    },
    {
      "x": 4,
      "y": 19,
      "z": 8,
      "name": "Rock_Shale_Brick"
    },
    {
      "x": 4,
      "y": 20,
      "z": 8,
      "name": "Rock_Shale"
    },
    {
      "x": 4,
      "y": 13,
      "z": 9,
      "name": "Rock_Shale_Brick_Smooth"
    },
    {
      "x": 4,
      "y": 14,
      "z": 9,
      "name": "Rock_Shale_Brick_Pillar_Base"
    },
    {
      "x": 4,
      "y": 15,
      "z": 9,
      "name": "Rock_Shale_Brick_Pillar_Middle"
    },
    {
      "x": 4,
      "y": 16,
      "z": 9,
      "name": "Rock_Shale_Brick_Pillar_Middle"
    },
    {
      "x": 4,
      "y": 17,
      "z": 9,
      "name": "Rock_Shale_Brick_Pillar_Base",
      "rotation": 8
    },
    {
      "x": 4,
      "y": 18,
      "z": 9,
      "name": "Rock_Shale_Brick"
    },
    {
      "x": 4,
      "y": 19,
      "z": 9,
      "name": "Rock_Shale_Brick"
    },
    {
      "x": 4,
      "y": 20,
      "z": 9,
      "name": "Rock_Shale"
    },
    {
      "x": 5,
      "y": 0,
      "z": -8,
      "name": "Rock_Shale_Brick_Smooth"
    },
    {
      "x": 5,
      "y": 1,
      "z": -8,
      "name": "Rock_Shale"
    },
    {
      "x": 5,
      "y": 2,
      "z": -8,
      "name": "Rock_Shale"
    },
    {
      "x": 5,
      "y": 3,
      "z": -8,
      "name": "Rock_Shale"
    },
    {
      "x": 5,
      "y": 4,
      "z": -8,
      "name": "Rock_Shale"
    },
    {
      "x": 5,
      "y": 5,
      "z": -8,
      "name": "Rock_Shale"
    },
    {
      "x": 5,
      "y": 6,
      "z": -8,
      "name": "Rock_Shale"
    },
    {
      "x": 5,
      "y": 0,
      "z": -7,
      "name": "Rock_Shale_Brick_Smooth"
    },
    {
      "x": 5,
      "y": 1,
      "z": -7,
      "name": "Rock_Shale"
    },
    {
      "x": 5,
      "y": 2,
      "z": -7,
      "name": "Rock_Shale"
    },
    {
      "x": 5,
      "y": 3,
      "z": -7,
      "name": "Rock_Shale"
    },
    {
      "x": 5,
      "y": 4,
      "z": -7,
      "name": "Rock_Shale"
    },
    {
      "x": 5,
      "y": 5,
      "z": -7,
      "name": "Rock_Shale"
    },
    {
      "x": 5,
      "y": 6,
      "z": -7,
      "name": "Rock_Shale"
    },
    {
      "x": 5,
      "y": 0,
      "z": -6,
      "name": "Rock_Shale_Brick_Smooth"
    },
    {
      "x": 5,
      "y": 1,
      "z": -6,
      "name": "Rock_Shale"
    },
    {
      "x": 5,
      "y": 2,
      "z": -6,
      "name": "Rock_Shale"
    },
    {
      "x": 5,
      "y": 3,
      "z": -6,
      "name": "Rock_Shale"
    },
    {
      "x": 5,
      "y": 4,
      "z": -6,
      "name": "Rock_Shale"
    },
    {
      "x": 5,
      "y": 5,
      "z": -6,
      "name": "Rock_Shale"
    },
    {
      "x": 5,
      "y": 6,
      "z": -6,
      "name": "Rock_Shale"
    },
    {
      "x": 5,
      "y": 7,
      "z": -6,
      "name": "Rock_Shale"
    },
    {
      "x": 5,
      "y": 0,
      "z": -5,
      "name": "Rock_Shale_Brick_Smooth"
    },
    {
      "x": 5,
      "y": 1,
      "z": -5,
      "name": "Rock_Shale"
    },
    {
      "x": 5,
      "y": 2,
      "z": -5,
      "name": "Rock_Shale"
    },
    {
      "x": 5,
      "y": 3,
      "z": -5,
      "name": "Rock_Shale"
    },
    {
      "x": 5,
      "y": 4,
      "z": -5,
      "name": "Rock_Shale"
    },
    {
      "x": 5,
      "y": 5,
      "z": -5,
      "name": "Rock_Basalt"
    },
    {
      "x": 5,
      "y": 6,
      "z": -5,
      "name": "Rock_Basalt"
    },
    {
      "x": 5,
      "y": 7,
      "z": -5,
      "name": "Rock_Shale"
    },
    {
      "x": 5,
      "y": 8,
      "z": -5,
      "name": "Rock_Shale"
    },
    {
      "x": 5,
      "y": 1,
      "z": -4,
      "name": "Rock_Shale"
    },
    {
      "x": 5,
      "y": 2,
      "z": -4,
      "name": "Rock_Shale"
    },
    {
      "x": 5,
      "y": 3,
      "z": -4,
      "name": "Rock_Shale"
    },
    {
      "x": 5,
      "y": 4,
      "z": -4,
      "name": "Rock_Shale"
    },
    {
      "x": 5,
      "y": 5,
      "z": -4,
      "name": "Rock_Basalt"
    },
    {
      "x": 5,
      "y": 6,
      "z": -4,
      "name": "Rock_Basalt"
    },
    {
      "x": 5,
      "y": 7,
      "z": -4,
      "name": "Rock_Shale"
    },
    {
      "x": 5,
      "y": 8,
      "z": -4,
      "name": "Rock_Shale"
    },
    {
      "x": 5,
      "y": 9,
      "z": -4,
      "name": "Rock_Shale"
    },
    {
      "x": 5,
      "y": 2,
      "z": -3,
      "name": "Rock_Shale"
    },
    {
      "x": 5,
      "y": 3,
      "z": -3,
      "name": "Rock_Shale"
    },
    {
      "x": 5,
      "y": 4,
      "z": -3,
      "name": "Rock_Shale"
    },
    {
      "x": 5,
      "y": 5,
      "z": -3,
      "name": "Rock_Shale"
    },
    {
      "x": 5,
      "y": 6,
      "z": -3,
      "name": "Rock_Basalt"
    },
    {
      "x": 5,
      "y": 7,
      "z": -3,
      "name": "Rock_Shale"
    },
    {
      "x": 5,
      "y": 8,
      "z": -3,
      "name": "Rock_Shale"
    },
    {
      "x": 5,
      "y": 9,
      "z": -3,
      "name": "Rock_Shale"
    },
    {
      "x": 5,
      "y": 10,
      "z": -3,
      "name": "Rock_Shale"
    },
    {
      "x": 5,
      "y": 3,
      "z": -2,
      "name": "Rock_Shale"
    },
    {
      "x": 5,
      "y": 4,
      "z": -2,
      "name": "Rock_Shale"
    },
    {
      "x": 5,
      "y": 5,
      "z": -2,
      "name": "Rock_Shale"
    },
    {
      "x": 5,
      "y": 6,
      "z": -2,
      "name": "Rock_Shale"
    },
    {
      "x": 5,
      "y": 7,
      "z": -2,
      "name": "Rock_Shale"
    },
    {
      "x": 5,
      "y": 8,
      "z": -2,
      "name": "Rock_Shale"
    },
    {
      "x": 5,
      "y": 9,
      "z": -2,
      "name": "Rock_Shale"
    },
    {
      "x": 5,
      "y": 10,
      "z": -2,
      "name": "Rock_Shale"
    },
    {
      "x": 5,
      "y": 11,
      "z": -2,
      "name": "Rock_Shale"
    },
    {
      "x": 5,
      "y": 4,
      "z": -1,
      "name": "Rock_Shale"
    },
    {
      "x": 5,
      "y": 5,
      "z": -1,
      "name": "Rock_Shale"
    },
    {
      "x": 5,
      "y": 6,
      "z": -1,
      "name": "Rock_Shale"
    },
    {
      "x": 5,
      "y": 7,
      "z": -1,
      "name": "Rock_Shale"
    },
    {
      "x": 5,
      "y": 8,
      "z": -1,
      "name": "Rock_Shale"
    },
    {
      "x": 5,
      "y": 9,
      "z": -1,
      "name": "Rock_Basalt"
    },
    {
      "x": 5,
      "y": 10,
      "z": -1,
      "name": "Rock_Basalt"
    },
    {
      "x": 5,
      "y": 11,
      "z": -1,
      "name": "Rock_Shale"
    },
    {
      "x": 5,
      "y": 12,
      "z": -1,
      "name": "Rock_Shale"
    },
    {
      "x": 5,
      "y": 5,
      "z": 0,
      "name": "Rock_Shale"
    },
    {
      "x": 5,
      "y": 6,
      "z": 0,
      "name": "Rock_Shale"
    },
    {
      "x": 5,
      "y": 7,
      "z": 0,
      "name": "Rock_Shale"
    },
    {
      "x": 5,
      "y": 8,
      "z": 0,
      "name": "Rock_Shale"
    },
    {
      "x": 5,
      "y": 9,
      "z": 0,
      "name": "Rock_Shale"
    },
    {
      "x": 5,
      "y": 10,
      "z": 0,
      "name": "Rock_Basalt"
    },
    {
      "x": 5,
      "y": 11,
      "z": 0,
      "name": "Rock_Basalt"
    },
    {
      "x": 5,
      "y": 12,
      "z": 0,
      "name": "Rock_Shale"
    },
    {
      "x": 5,
      "y": 13,
      "z": 0,
      "name": "Rock_Shale"
    },
    {
      "x": 5,
      "y": 6,
      "z": 1,
      "name": "Rock_Shale"
    },
    {
      "x": 5,
      "y": 7,
      "z": 1,
      "name": "Rock_Shale"
    },
    {
      "x": 5,
      "y": 8,
      "z": 1,
      "name": "Rock_Shale"
    },
    {
      "x": 5,
      "y": 9,
      "z": 1,
      "name": "Rock_Shale"
    },
    {
      "x": 5,
      "y": 10,
      "z": 1,
      "name": "Rock_Shale"
    },
    {
      "x": 5,
      "y": 11,
      "z": 1,
      "name": "Rock_Shale"
    },
    {
      "x": 5,
      "y": 12,
      "z": 1,
      "name": "Rock_Shale"
    },
    {
      "x": 5,
      "y": 13,
      "z": 1,
      "name": "Rock_Shale"
    },
    {
      "x": 5,
      "y": 14,
      "z": 1,
      "name": "Rock_Shale"
    },
    {
      "x": 5,
      "y": 7,
      "z": 2,
      "name": "Rock_Shale"
    },
    {
      "x": 5,
      "y": 8,
      "z": 2,
      "name": "Rock_Shale"
    },
    {
      "x": 5,
      "y": 9,
      "z": 2,
      "name": "Rock_Shale"
    },
    {
      "x": 5,
      "y": 10,
      "z": 2,
      "name": "Rock_Shale"
    },
    {
      "x": 5,
      "y": 11,
      "z": 2,
      "name": "Rock_Shale"
    },
    {
      "x": 5,
      "y": 12,
      "z": 2,
      "name": "Rock_Basalt"
    },
    {
      "x": 5,
      "y": 13,
      "z": 2,
      "name": "Rock_Basalt"
    },
    {
      "x": 5,
      "y": 14,
      "z": 2,
      "name": "Rock_Shale"
    },
    {
      "x": 5,
      "y": 15,
      "z": 2,
      "name": "Rock_Shale"
    },
    {
      "x": 5,
      "y": 8,
      "z": 3,
      "name": "Rock_Shale"
    },
    {
      "x": 5,
      "y": 9,
      "z": 3,
      "name": "Rock_Shale"
    },
    {
      "x": 5,
      "y": 10,
      "z": 3,
      "name": "Rock_Shale"
    },
    {
      "x": 5,
      "y": 11,
      "z": 3,
      "name": "Rock_Shale"
    },
    {
      "x": 5,
      "y": 12,
      "z": 3,
      "name": "Rock_Shale"
    },
    {
      "x": 5,
      "y": 13,
      "z": 3,
      "name": "Rock_Basalt"
    },
    {
      "x": 5,
      "y": 14,
      "z": 3,
      "name": "Rock_Basalt"
    },
    {
      "x": 5,
      "y": 15,
      "z": 3,
      "name": "Rock_Shale"
    },
    {
      "x": 5,
      "y": 16,
      "z": 3,
      "name": "Rock_Shale"
    },
    {
      "x": 5,
      "y": 9,
      "z": 4,
      "name": "Rock_Shale"
    },
    {
      "x": 5,
      "y": 10,
      "z": 4,
      "name": "Rock_Shale"
    },
    {
      "x": 5,
      "y": 11,
      "z": 4,
      "name": "Rock_Shale"
    },
    {
      "x": 5,
      "y": 12,
      "z": 4,
      "name": "Rock_Shale"
    },
    {
      "x": 5,
      "y": 13,
      "z": 4,
      "name": "Rock_Shale"
    },
    {
      "x": 5,
      "y": 14,
      "z": 4,
      "name": "Rock_Basalt"
    },
    {
      "x": 5,
      "y": 15,
      "z": 4,
      "name": "Rock_Basalt"
    },
    {
      "x": 5,
      "y": 16,
      "z": 4,
      "name": "Rock_Shale"
    },
    {
      "x": 5,
      "y": 17,
      "z": 4,
      "name": "Rock_Shale"
    },
    {
      "x": 5,
      "y": 10,
      "z": 5,
      "name": "Rock_Shale"
    },
    {
      "x": 5,
      "y": 11,
      "z": 5,
      "name": "Rock_Shale"
    },
    {
      "x": 5,
      "y": 12,
      "z": 5,
      "name": "Rock_Shale"
    },
    {
      "x": 5,
      "y": 13,
      "z": 5,
      "name": "Rock_Shale"
    },
    {
      "x": 5,
      "y": 14,
      "z": 5,
      "name": "Rock_Shale"
    },
    {
      "x": 5,
      "y": 15,
      "z": 5,
      "name": "Rock_Shale"
    },
    {
      "x": 5,
      "y": 16,
      "z": 5,
      "name": "Rock_Shale"
    },
    {
      "x": 5,
      "y": 17,
      "z": 5,
      "name": "Rock_Shale"
    },
    {
      "x": 5,
      "y": 18,
      "z": 5,
      "name": "Rock_Shale"
    },
    {
      "x": 5,
      "y": 11,
      "z": 6,
      "name": "Rock_Shale"
    },
    {
      "x": 5,
      "y": 12,
      "z": 6,
      "name": "Rock_Shale"
    },
    {
      "x": 5,
      "y": 13,
      "z": 6,
      "name": "Rock_Shale"
    },
    {
      "x": 5,
      "y": 14,
      "z": 6,
      "name": "Rock_Shale"
    },
    {
      "x": 5,
      "y": 15,
      "z": 6,
      "name": "Rock_Shale"
    },
    {
      "x": 5,
      "y": 16,
      "z": 6,
      "name": "Rock_Basalt"
    },
    {
      "x": 5,
      "y": 17,
      "z": 6,
      "name": "Rock_Basalt"
    },
    {
      "x": 5,
      "y": 18,
      "z": 6,
      "name": "Rock_Shale"
    },
    {
      "x": 5,
      "y": 19,
      "z": 6,
      "name": "Rock_Shale"
    },
    {
      "x": 5,
      "y": 12,
      "z": 7,
      "name": "Rock_Shale"
    },
    {
      "x": 5,
      "y": 13,
      "z": 7,
      "name": "Rock_Shale"
    },
    {
      "x": 5,
      "y": 14,
      "z": 7,
      "name": "Rock_Shale"
    },
    {
      "x": 5,
      "y": 15,
      "z": 7,
      "name": "Rock_Shale"
    },
    {
      "x": 5,
      "y": 16,
      "z": 7,
      "name": "Rock_Shale"
    },
    {
      "x": 5,
      "y": 17,
      "z": 7,
      "name": "Rock_Basalt"
    },
    {
      "x": 5,
      "y": 18,
      "z": 7,
      "name": "Rock_Basalt"
    },
    {
      "x": 5,
      "y": 19,
      "z": 7,
      "name": "Rock_Shale"
    },
    {
      "x": 5,
      "y": 20,
      "z": 7,
      "name": "Rock_Shale"
    },
    {
      "x": 5,
      "y": 13,
      "z": 8,
      "name": "Rock_Shale"
    },
    {
      "x": 5,
      "y": 14,
      "z": 8,
      "name": "Rock_Shale"
    },
    {
      "x": 5,
      "y": 15,
      "z": 8,
      "name": "Rock_Shale"
    },
    {
      "x": 5,
      "y": 16,
      "z": 8,
      "name": "Rock_Shale"
    },
    {
      "x": 5,
      "y": 17,
      "z": 8,
      "name": "Rock_Shale"
    },
    {
      "x": 5,
      "y": 18,
      "z": 8,
      "name": "Rock_Basalt"
    },
    {
      "x": 5,
      "y": 19,
      "z": 8,
      "name": "Rock_Shale"
    },
    {
      "x": 5,
      "y": 20,
      "z": 8,
      "name": "Rock_Shale"
    },
    {
      "x": 5,
      "y": 13,
      "z": 9,
      "name": "Rock_Shale"
    },
    {
      "x": 5,
      "y": 14,
      "z": 9,
      "name": "Rock_Shale"
    },
    {
      "x": 5,
      "y": 15,
      "z": 9,
      "name": "Rock_Shale"
    },
    {
      "x": 5,
      "y": 16,
      "z": 9,
      "name": "Rock_Shale"
    },
    {
      "x": 5,
      "y": 17,
      "z": 9,
      "name": "Rock_Shale"
    },
    {
      "x": 5,
      "y": 18,
      "z": 9,
      "name": "Rock_Shale"
    },
    {
      "x": 5,
      "y": 19,
      "z": 9,
      "name": "Rock_Shale"
    },
    {
      "x": 5,
      "y": 20,
      "z": 9,
      "name": "Rock_Shale"
    }
  ]
}