{
  "version": 8,
  "blockIdVersion": 11,
  "anchorX": 0,
  "anchorY": 134,
  "anchorZ": 6,
  "blocks": [
    {
      "x": -7,
      "y": 142,
      "z": -4,
      "name": "Rock_CastIron"
    },
    {
      "x": -7,
      "y": 143,
      "z": -4,
      "name": "Rock_CastIron"
    },
    {
      "x": -7,
      "y": 142,
      "z": -3,
      "name": "Rock_CastIron"
    },
    {
      "x": -7,
      "y": 143,
      "z": -3,
      "name": "Rock_CastIron"
    },
    {
      "x": -7,
      "y": 144,
      "z": -3,
      "name": "Rock_CastIron"
    },
    {
      "x": -7,
      "y": 143,
      "z": -2,
      "name": "Rock_CastIron"
    },
    {
      "x": -7,
      "y": 144,
      "z": -2,
      "name": "Rock_CastIron"
    },
    {
      "x": -7,
      "y": 129,
      "z": 4,
      "name": "Rock_CastIron"
    },
    {
      "x": -7,
      "y": 130,
      "z": 4,
      "name": "Rock_CastIron"
    },
    {
      "x": -7,
      "y": 131,
      "z": 4,
      "name": "Rock_CastIron"
    },
    {
      "x": -7,
      "y": 132,
      "z": 4,
      "name": "Rock_CastIron"
    },
    {
      "x": -7,
      "y": 133,
      "z": 4,
      "name": "Rock_CastIron"
    },
    {
      "x": -7,
      "y": 134,
      "z": 4,
      "name": "Rock_CastIron"
    },
    {
      "x": -7,
      "y": 135,
      "z": 4,
      "name": "Rock_CastIron"
    },
    {
      "x": -7,
      "y": 129,
      "z": 5,
      "name": "Rock_CastIron"
    },
    {
      "x": -7,
      "y": 130,
      "z": 5,
      "name": "Rock_CastIron"
    },
    {
      "x": -7,
      "y": 131,
      "z": 5,
      "name": "Rock_CastIron"
    },
    {
      "x": -7,
      "y": 132,
      "z": 5,
      "name": "Rock_CastIron"
    },
    {
      "x": -7,
      "y": 133,
      "z": 5,
      "name": "Rock_CastIron"
    },
    {
      "x": -7,
      "y": 134,
      "z": 5,
      "name": "Rock_CastIron"
    },
    {
      "x": -7,
      "y": 135,
      "z": 5,
      "name": "Rock_CastIron"
    },
    {
      "x": -7,
      "y": 136,
      "z": 5,
      "name": "Rock_CastIron"
    },
    {
      "x": -6,
      "y": 141,
      "z": -6,
      "name": "Rock_CastIron_Brick"
    },
    {
      "x": -6,
      "y": 140,
      "z": -5,
      "name": "Rock_Shale_Brick_Stairs",
      "rotation": 8
    },
    {
      "x": -6,
      "y": 141,
      "z": -5,
      "name": "Rock_CastIron_Brick"
    },
    {
      "x": -6,
      "y": 142,
      "z": -5,
      "name": "Rock_CastIron"
    },
    {
      "x": -6,
      "y": 143,
      "z": -5,
      "name": "Rock_CastIron"
    },
    {
      "x": -6,
      "y": 129,
      "z": -4,
      "name": "Rock_CastIron_Brick"
    },
    {
      "x": -6,
      "y": 130,
      "z": -4,
      "name": "Rock_CastIron_Brick"
    },
    {
      "x": -6,
      "y": 131,
      "z": -4,
      "name": "Rock_CastIron_Brick"
    },
    {
      "x": -6,
      "y": 132,
      "z": -4,
      "name": "Rock_CastIron_Brick"
    },
    {
      "x": -6,
      "y": 133,
      "z": -4,
      "name": "Rock_CastIron_Brick"
    },
    {
      "x": -6,
      "y": 134,
      "z": -4,
      "name": "Rock_CastIron_Brick"
    },
    {
      "x": -6,
      "y": 135,
      "z": -4,
      "name": "Rock_Shale_Brick_Pillar_Base"
    },
    {
      "x": -6,
      "y": 136,
      "z": -4,
      "name": "Rock_Shale_Brick_Pillar_Middle"
    },
    {
      "x": -6,
      "y": 137,
      "z": -4,
      "name": "Rock_Shale_Brick_Pillar_Middle"
    },
    {
      "x": -6,
      "y": 138,
      "z": -4,
      "name": "Rock_Shale_Brick_Pillar_Middle"
    },
    {
      "x": -6,
      "y": 139,
      "z": -4,
      "name": "Rock_Shale_Brick_Pillar_Base",
      "rotation": 8
    },
    {
      "x": -6,
      "y": 140,
      "z": -4,
      "name": "Rock_CastIron_Brick"
    },
    {
      "x": -6,
      "y": 141,
      "z": -4,
      "name": "Rock_CastIron_Brick"
    },
    {
      "x": -6,
      "y": 142,
      "z": -4,
      "name": "Rock_CastIron"
    },
    {
      "x": -6,
      "y": 143,
      "z": -4,
      "name": "Rock_CastIron"
    },
    {
      "x": -6,
      "y": 129,
      "z": -3,
      "name": "Rock_CastIron_Brick"
    },
    {
      "x": -6,
      "y": 130,
      "z": -3,
      "name": "Rock_CastIron_Brick"
    },
    {
      "x": -6,
      "y": 131,
      "z": -3,
      "name": "Rock_CastIron_Brick"
    },
    {
      "x": -6,
      "y": 132,
      "z": -3,
      "name": "Rock_CastIron_Brick"
    },
    {
      "x": -6,
      "y": 133,
      "z": -3,
      "name": "Rock_CastIron_Brick"
    },
    {
      "x": -6,
      "y": 134,
      "z": -3,
      "name": "Rock_CastIron_Brick"
    },
    {
      "x": -6,
      "y": 135,
      "z": -3,
      "name": "Rock_Shale_Brick_Pillar_Base"
    },
    {
      "x": -6,
      "y": 136,
      "z": -3,
      "name": "Rock_Shale_Brick_Pillar_Middle"
    },
    {
      "x": -6,
      "y": 137,
      "z": -3,
      "name": "Rock_Shale_Brick_Pillar_Middle"
    },
    {
      "x": -6,
      "y": 138,
      "z": -3,
      "name": "Rock_Shale_Brick_Pillar_Middle"
    },
    {
      "x": -6,
      "y": 139,
      "z": -3,
      "name": "Rock_Shale_Brick_Pillar_Base",
      "rotation": 8
    },
    {
      "x": -6,
      "y": 140,
      "z": -3,
      "name": "Rock_CastIron_Brick"
    },
    {
      "x": -6,
      "y": 141,
      "z": -3,
      "name": "Rock_CastIron_Brick"
    },
    {
      "x": -6,
      "y": 142,
      "z": -3,
      "name": "Rock_CastIron"
    },
    {
      "x": -6,
      "y": 143,
      "z": -3,
      "name": "Rock_CastIron"
    },
    {
      "x": -6,
      "y": 144,
      "z": -3,
      "name": "Rock_CastIron"
    },
    {
      "x": -6,
      "y": 129,
      "z": -2,
      "name": "Rock_CastIron_Brick"
    },
    {
      "x": -6,
      "y": 130,
      "z": -2,
      "name": "Rock_CastIron_Brick"
    },
    {
      "x": -6,
      "y": 131,
      "z": -2,
      "name": "Rock_CastIron_Brick"
    },
    {
      "x": -6,
      "y": 132,
      "z": -2,
      "name": "Rock_CastIron_Brick"
    },
    {
      "x": -6,
      "y": 133,
      "z": -2,
      "name": "Rock_CastIron_Brick"
    },
    {
      "x": -6,
      "y": 134,
      "z": -2,
      "name": "Rock_CastIron_Brick"
    },
    {
      "x": -6,
      "y": 135,
      "z": -2,
      "name": "Rock_CastIron_Brick"
    },
    {
      "x": -6,
      "y": 136,
      "z": -2,
      "name": "Deco_Bone_Pile"
    },
    {
      "x": -6,
      "y": 137,
      "z": -2,
      "name": "Rock_CastIron_Brick"
    },
    {
      "x": -6,
      "y": 138,
      "z": -2,
      "name": "Deco_Bone_Skulls"
    },
    {
      "x": -6,
      "y": 140,
      "z": -2,
      "name": "Rock_CastIron_Brick"
    },
    {
      "x": -6,
      "y": 141,
      "z": -2,
      "name": "Rock_CastIron_Brick"
    },
    {
      "x": -6,
      "y": 142,
      "z": -2,
      "name": "Rock_CastIron"
    },
    {
      "x": -6,
      "y": 143,
      "z": -2,
      "name": "Rock_CastIron"
    },
    {
      "x": -6,
      "y": 144,
      "z": -2,
      "name": "Rock_CastIron"
    },
    {
      "x": -6,
      "y": 129,
      "z": -1,
      "name": "Rock_CastIron_Brick"
    },
    {
      "x": -6,
      "y": 130,
      "z": -1,
      "name": "Rock_CastIron_Brick"
    },
    {
      "x": -6,
      "y": 131,
      "z": -1,
      "name": "Rock_CastIron_Brick"
    },
    {
      "x": -6,
      "y": 132,
      "z": -1,
      "name": "Rock_CastIron_Brick"
    },
    {
      "x": -6,
      "y": 133,
      "z": -1,
      "name": "Rock_CastIron_Brick"
    },
    {
      "x": -6,
      "y": 134,
      "z": -1,
      "name": "Rock_CastIron_Brick"
    },
    {
      "x": -6,
      "y": 135,
      "z": -1,
      "name": "Rock_CastIron_Brick"
    },
    {
      "x": -6,
      "y": 136,
      "z": -1,
      "name": "Deco_Bone_Pile"
    },
    {
      "x": -6,
      "y": 137,
      "z": -1,
      "name": "Rock_CastIron_Brick"
    },
    {
      "x": -6,
      "y": 138,
      "z": -1,
      "name": "Deco_Bone_Skulls"
    },
    {
      "x": -6,
      "y": 140,
      "z": -1,
      "name": "Rock_CastIron_Brick"
    },
    {
      "x": -6,
      "y": 141,
      "z": -1,
      "name": "Rock_CastIron_Brick"
    },
    {
      "x": -6,
      "y": 142,
      "z": -1,
      "name": "Rock_Shale_Brick_Half",
      "rotation": 7
    },
    {
      "x": -6,
      "y": 143,
      "z": -1,
      "name": "Rock_Shale_Brick_Half",
      "rotation": 7
    },
    {
      "x": -6,
      "y": 144,
      "z": -1,
      "name": "Rock_Shale_Brick_Half",
      "rotation": 7
    },
    {
      "x": -6,
      "y": 145,
      "z": -1,
      "name": "Rock_Shale_Brick_Half",
      "rotation": 7
    },
    {
      "x": -6,
      "y": 129,
      "z": 0,
      "name": "Rock_CastIron_Brick"
    },
    {
      "x": -6,
      "y": 130,
      "z": 0,
      "name": "Rock_CastIron_Brick"
    },
    {
      "x": -6,
      "y": 131,
      "z": 0,
      "name": "Rock_CastIron_Brick"
    },
    {
      "x": -6,
      "y": 132,
      "z": 0,
      "name": "Rock_CastIron_Brick"
    },
    {
      "x": -6,
      "y": 133,
      "z": 0,
      "name": "Rock_CastIron_Brick"
    },
    {
      "x": -6,
      "y": 134,
      "z": 0,
      "name": "Rock_CastIron_Brick"
    },
    {
      "x": -6,
      "y": 135,
      "z": 0,
      "name": "Rock_CastIron_Brick"
    },
    {
      "x": -6,
      "y": 136,
      "z": 0,
      "name": "Deco_Bone_Skulls"
    },
    {
      "x": -6,
      "y": 137,
      "z": 0,
      "name": "Rock_CastIron_Brick"
    },
    {
      "x": -6,
      "y": 140,
      "z": 0,
      "name": "Rock_CastIron_Brick"
    },
    {
      "x": -6,
      "y": 141,
      "z": 0,
      "name": "Rock_CastIron_Brick"
    },
    {
      "x": -6,
      "y": 142,
      "z": 0,
      "name": "Rock_CastIron"
    },
    {
      "x": -6,
      "y": 143,
      "z": 0,
      "name": "Rock_CastIron"
    },
    {
      "x": -6,
      "y": 144,
      "z": 0,
      "name": "Rock_CastIron"
    },
    {
      "x": -6,
      "y": 129,
      "z": 1,
      "name": "Rock_CastIron_Brick"
    },
    {
      "x": -6,
      "y": 130,
      "z": 1,
      "name": "Rock_CastIron_Brick"
    },
    {
      "x": -6,
      "y": 131,
      "z": 1,
      "name": "Rock_CastIron_Brick"
    },
    {
      "x": -6,
      "y": 132,
      "z": 1,
      "name": "Rock_CastIron_Brick"
    },
    {
      "x": -6,
      "y": 133,
      "z": 1,
      "name": "Rock_CastIron_Brick"
    },
    {
      "x": -6,
      "y": 134,
      "z": 1,
      "name": "Rock_CastIron_Brick"
    },
    {
      "x": -6,
      "y": 135,
      "z": 1,
      "name": "Rock_CastIron_Brick"
    },
    {
      "x": -6,
      "y": 136,
      "z": 1,
      "name": "Rock_Shale_Brick_Half",
      "rotation": 7
    },
    {
      "x": -6,
      "y": 137,
      "z": 1,
      "name": "Rock_CastIron_Brick"
    },
    {
      "x": -6,
      "y": 138,
      "z": 1,
      "name": "Rock_Shale_Brick_Half",
      "rotation": 7
    },
    {
      "x": -6,
      "y": 139,
      "z": 1,
      "name": "Rock_Shale_Brick_Half",
      "rotation": 7
    },
    {
      "x": -6,
      "y": 140,
      "z": 1,
      "name": "Rock_CastIron_Brick"
    },
    {
      "x": -6,
      "y": 141,
      "z": 1,
      "name": "Rock_CastIron_Brick"
    },
    {
      "x": -6,
      "y": 142,
      "z": 1,
      "name": "Rock_CastIron"
    },
    {
      "x": -6,
      "y": 143,
      "z": 1,
      "name": "Rock_CastIron"
    },
    {
      "x": -6,
      "y": 144,
      "z": 1,
      "name": "Rock_CastIron"
    },
    {
      "x": -6,
      "y": 129,
      "z": 2,
      "name": "Rock_CastIron_Brick"
    },
    {
      "x": -6,
      "y": 130,
      "z": 2,
      "name": "Rock_CastIron_Brick"
    },
    {
      "x": -6,
      "y": 131,
      "z": 2,
      "name": "Rock_CastIron_Brick"
    },
    {
      "x": -6,
      "y": 132,
      "z": 2,
      "name": "Rock_CastIron_Brick"
    },
    {
      "x": -6,
      "y": 133,
      "z": 2,
      "name": "Rock_CastIron_Brick"
    },
    {
      "x": -6,
      "y": 134,
      "z": 2,
      "name": "Rock_CastIron_Brick"
    },
    {
      "x": -6,
      "y": 135,
      "z": 2,
      "name": "Rock_CastIron_Brick"
    },
    {
      "x": -6,
      "y": 136,
      "z": 2,
      "name": "Deco_Bone_Pile"
    },
    {
      "x": -6,
      "y": 137,
      "z": 2,
      "name": "Rock_CastIron_Brick"
    },
    {
      "x": -6,
      "y": 138,
      "z": 2,
      "name": "Deco_Bone_Pile"
    },
    {
      "x": -6,
      "y": 140,
      "z": 2,
      "name": "Rock_CastIron_Brick"
    },
    {
      "x": -6,
      "y": 141,
      "z": 2,
      "name": "Rock_CastIron_Brick"
    },
    {
      "x": -6,
      "y": 142,
      "z": 2,
      "name": "Rock_CastIron"
    },
    {
      "x": -6,
      "y": 143,
      "z": 2,
      "name": "Rock_CastIron"
    },
    {
      "x": -6,
      "y": 144,
      "z": 2,
      "name": "Rock_CastIron"
    },
    {
      "x": -6,
      "y": 129,
      "z": 3,
      "name": "Rock_CastIron_Brick"
    },
    {
      "x": -6,
      "y": 130,
      "z": 3,
      "name": "Rock_CastIron_Brick"
    },
    {
      "x": -6,
      "y": 131,
      "z": 3,
      "name": "Rock_CastIron_Brick"
    },
    {
      "x": -6,
      "y": 132,
      "z": 3,
      "name": "Rock_CastIron_Brick"
    },
    {
      "x": -6,
      "y": 133,
      "z": 3,
      "name": "Rock_CastIron_Brick"
    },
    {
      "x": -6,
      "y": 134,
      "z": 3,
      "name": "Rock_CastIron_Brick"
    },
    {
      "x": -6,
      "y": 135,
      "z": 3,
      "name": "Rock_CastIron_Brick"
    },
    {
      "x": -6,
      "y": 136,
      "z": 3,
      "name": "Deco_Bone_Skulls"
    },
    {
      "x": -6,
      "y": 137,
      "z": 3,
      "name": "Rock_CastIron_Brick"
    },
    {
      "x": -6,
      "y": 138,
      "z": 3,
      "name": "Deco_Bone_Pile"
    },
    {
      "x": -6,
      "y": 140,
      "z": 3,
      "name": "Rock_CastIron_Brick"
    },
    {
      "x": -6,
      "y": 141,
      "z": 3,
      "name": "Rock_CastIron_Brick"
    },
    {
      "x": -6,
      "y": 143,
      "z": 3,
      "name": "Rock_CastIron"
    },
    {
      "x": -6,
      "y": 144,
      "z": 3,
      "name": "Rock_CastIron"
    },
    {
      "x": -6,
      "y": 129,
      "z": 4,
      "name": "Rock_CastIron_Brick"
    },
    {
      "x": -6,
      "y": 130,
      "z": 4,
      "name": "Rock_CastIron_Brick"
    },
    {
      "x": -6,
      "y": 131,
      "z": 4,
      "name": "Rock_CastIron_Brick"
    },
    {
      "x": -6,
      "y": 132,
      "z": 4,
      "name": "Rock_CastIron_Brick"
    },
    {
      "x": -6,
      "y": 133,
      "z": 4,
      "name": "Rock_CastIron_Brick"
    },
    {
      "x": -6,
      "y": 134,
      "z": 4,
      "name": "Rock_CastIron_Brick"
    },
    {
      "x": -6,
      "y": 135,
      "z": 4,
      "name": "Rock_CastIron"
    },
    {
      "x": -6,
      "y": 136,
      "z": 4,
      "name": "Rock_CastIron"
    },
    {
      "x": -6,
      "y": 137,
      "z": 4,
      "name": "Rock_CastIron"
    },
    {
      "x": -6,
      "y": 140,
      "z": 4,
      "name": "Rock_CastIron_Brick"
    },
    {
      "x": -6,
      "y": 141,
      "z": 4,
      "name": "Rock_CastIron_Brick"
    },
    {
      "x": -6,
      "y": 142,
      "z": 4,
      "name": "Rock_Shale_Brick_Half",
      "rotation": 7
    },
    {
      "x": -6,
      "y": 143,
      "z": 4,
      "name": "Rock_Shale_Brick_Half",
      "rotation": 7
    },
    {
      "x": -6,
      "y": 144,
      "z": 4,
      "name": "Rock_Shale_Brick_Half",
      "rotation": 7
    },
    {
      "x": -6,
      "y": 145,
      "z": 4,
      "name": "Rock_Shale_Brick_Half",
      "rotation": 7
    },
    {
      "x": -6,
      "y": 129,
      "z": 5,
      "name": "Rock_CastIron_Brick"
    },
    {
      "x": -6,
      "y": 130,
      "z": 5,
      "name": "Rock_CastIron_Brick"
    },
    {
      "x": -6,
      "y": 131,
      "z": 5,
      "name": "Rock_CastIron_Brick"
    },
    {
      "x": -6,
      "y": 132,
      "z": 5,
      "name": "Rock_CastIron_Brick"
    },
    {
      "x": -6,
      "y": 133,
      "z": 5,
      "name": "Rock_CastIron_Brick"
    },
    {
      "x": -6,
      "y": 134,
      "z": 5,
      "name": "Rock_CastIron_Brick"
    },
    {
      "x": -6,
      "y": 135,
      "z": 5,
      "name": "Rock_CastIron"
    },
    {
      "x": -6,
      "y": 136,
      "z": 5,
      "name": "Rock_CastIron"
    },
    {
      "x": -6,
      "y": 137,
      "z": 5,
      "name": "Rock_CastIron"
    },
    {
      "x": -6,
      "y": 140,
      "z": 5,
      "name": "Rock_CastIron_Brick"
    },
    {
      "x": -6,
      "y": 141,
      "z": 5,
      "name": "Rock_CastIron_Brick"
    },
    {
      "x": -6,
      "y": 142,
      "z": 5,
      "name": "Rock_CastIron"
    },
    {
      "x": -6,
      "y": 143,
      "z": 5,
      "name": "Rock_CastIron"
    },
    {
      "x": -6,
      "y": 144,
      "z": 5,
      "name": "Rock_CastIron"
    },
    {
      "x": -6,
      "y": 129,
      "z": 6,
      "name": "Rock_CastIron_Brick"
    },
    {
      "x": -6,
      "y": 130,
      "z": 6,
      "name": "Rock_CastIron_Brick"
    },
    {
      "x": -6,
      "y": 131,
      "z": 6,
      "name": "Rock_CastIron_Brick"
    },
    {
      "x": -6,
      "y": 132,
      "z": 6,
      "name": "Rock_CastIron_Brick"
    },
    {
      "x": -6,
      "y": 133,
      "z": 6,
      "name": "Rock_CastIron_Brick"
    },
    {
      "x": -6,
      "y": 134,
      "z": 6,
      "name": "Rock_CastIron_Brick"
    },
    {
      "x": -6,
      "y": 135,
      "z": 6,
      "name": "Rock_Shale_Brick_Pillar_Base"
    },
    {
      "x": -6,
      "y": 136,
      "z": 6,
      "name": "Rock_Shale_Brick_Pillar_Middle"
    },
    {
      "x": -6,
      "y": 137,
      "z": 6,
      "name": "Rock_Shale_Brick_Pillar_Middle"
    },
    {
      "x": -6,
      "y": 138,
      "z": 6,
      "name": "Rock_Shale_Brick_Pillar_Middle"
    },
    {
      "x": -6,
      "y": 139,
      "z": 6,
      "name": "Rock_Shale_Brick_Pillar_Base",
      "rotation": 8
    },
    {
      "x": -6,
      "y": 140,
      "z": 6,
      "name": "Rock_CastIron_Brick"
    },
    {
      "x": -6,
      "y": 141,
      "z": 6,
      "name": "Rock_CastIron_Brick"
    },
    {
      "x": -6,
      "y": 142,
      "z": 6,
      "name": "Rock_CastIron"
    },
    {
      "x": -6,
      "y": 143,
      "z": 6,
      "name": "Rock_CastIron"
    },
    {
      "x": -6,
      "y": 144,
      "z": 6,
      "name": "Rock_CastIron"
    },
    {
      "x": -6,
      "y": 129,
      "z": 7,
      "name": "Rock_CastIron_Brick"
    },
    {
      "x": -6,
      "y": 130,
      "z": 7,
      "name": "Rock_CastIron_Brick"
    },
    {
      "x": -6,
      "y": 131,
      "z": 7,
      "name": "Rock_CastIron_Brick"
    },
    {
      "x": -6,
      "y": 132,
      "z": 7,
      "name": "Rock_CastIron_Brick"
    },
    {
      "x": -6,
      "y": 133,
      "z": 7,
      "name": "Rock_CastIron_Brick"
    },
    {
      "x": -6,
      "y": 134,
      "z": 7,
      "name": "Rock_CastIron_Brick"
    },
    {
      "x": -6,
      "y": 135,
      "z": 7,
      "name": "Rock_Shale_Brick_Pillar_Base"
    },
    {
      "x": -6,
      "y": 136,
      "z": 7,
      "name": "Rock_Shale_Brick_Pillar_Middle"
    },
    {
      "x": -6,
      "y": 137,
      "z": 7,
      "name": "Rock_Shale_Brick_Pillar_Middle"
    },
    {
      "x": -6,
      "y": 138,
      "z": 7,
      "name": "Rock_Shale_Brick_Pillar_Middle"
    },
    {
      "x": -6,
      "y": 139,
      "z": 7,
      "name": "Rock_Shale_Brick_Pillar_Base",
      "rotation": 8
    },
    {
      "x": -6,
      "y": 140,
      "z": 7,
      "name": "Rock_CastIron_Brick"
    },
    {
      "x": -6,
      "y": 141,
      "z": 7,
      "name": "Rock_CastIron_Brick"
    },
    {
      "x": -6,
      "y": 142,
      "z": 7,
      "name": "Rock_Shale_Brick_Half"
    },
    {
      "x": -6,
      "y": 143,
      "z": 7,
      "name": "Rock_CastIron"
    },
    {
      "x": -6,
      "y": 144,
      "z": 7,
      "name": "Rock_CastIron"
    },
    {
      "x": -6,
      "y": 140,
      "z": 8,
      "name": "Rock_Shale_Brick_Stairs",
      "rotation": 10
    },
    {
      "x": -6,
      "y": 141,
      "z": 8,
      "name": "Rock_CastIron_Brick"
    },
    {
      "x": -6,
      "y": 144,
      "z": 8,
      "name": "Rock_CastIron"
    },
    {
      "x": -6,
      "y": 141,
      "z": 9,
      "name": "Rock_CastIron_Brick"
    },
    {
      "x": -5,
      "y": 124,
      "z": -8,
      "name": "Rock_CastIron_Brick_Smooth"
    },
    {
      "x": -5,
      "y": 125,
      "z": -8,
      "name": "Rock_CastIron"
    },
    {
      "x": -5,
      "y": 126,
      "z": -8,
      "name": "Rock_CastIron"
    },
    {
      "x": -5,
      "y": 127,
      "z": -8,
      "name": "Rock_CastIron"
    },
    {
      "x": -5,
      "y": 128,
      "z": -8,
      "name": "Rock_CastIron"
    },
    {
      "x": -5,
      "y": 129,
      "z": -8,
      "name": "Rock_CastIron"
    },
    {
      "x": -5,
      "y": 130,
      "z": -8,
      "name": "Rock_CastIron"
    },
    {
      "x": -5,
      "y": 124,
      "z": -7,
      "name": "Rock_CastIron_Brick_Smooth"
    },
    {
      "x": -5,
      "y": 125,
      "z": -7,
      "name": "Rock_CastIron"
    },
    {
      "x": -5,
      "y": 126,
      "z": -7,
      "name": "Rock_CastIron"
    },
    {
      "x": -5,
      "y": 127,
      "z": -7,
      "name": "Rock_CastIron"
    },
    {
      "x": -5,
      "y": 128,
      "z": -7,
      "name": "Rock_CastIron"
    },
    {
      "x": -5,
      "y": 129,
      "z": -7,
      "name": "Rock_CastIron"
    },
    {
      "x": -5,
      "y": 130,
      "z": -7,
      "name": "Rock_CastIron"
    },
    {
      "x": -5,
      "y": 124,
      "z": -6,
      "name": "Rock_CastIron_Brick_Smooth"
    },
    {
      "x": -5,
      "y": 125,
      "z": -6,
      "name": "Rock_CastIron"
    },
    {
      "x": -5,
      "y": 126,
      "z": -6,
      "name": "Rock_CastIron"
    },
    {
      "x": -5,
      "y": 127,
      "z": -6,
      "name": "Rock_CastIron"
    },
    {
      "x": -5,
      "y": 128,
      "z": -6,
      "name": "Rock_CastIron"
    },
    {
      "x": -5,
      "y": 129,
      "z": -6,
      "name": "Rock_CastIron"
    },
    {
      "x": -5,
      "y": 130,
      "z": -6,
      "name": "Rock_CastIron"
    },
    {
      "x": -5,
      "y": 131,
      "z": -6,
      "name": "Rock_CastIron"
    },
    {
      "x": -5,
      "y": 141,
      "z": -6,
      "name": "Rock_CastIron_Brick"
    },
    {
      "x": -5,
      "y": 124,
      "z": -5,
      "name": "Rock_CastIron_Brick_Smooth"
    },
    {
      "x": -5,
      "y": 125,
      "z": -5,
      "name": "Rock_CastIron"
    },
    {
      "x": -5,
      "y": 126,
      "z": -5,
      "name": "Rock_CastIron"
    },
    {
      "x": -5,
      "y": 127,
      "z": -5,
      "name": "Rock_CastIron"
    },
    {
      "x": -5,
      "y": 128,
      "z": -5,
      "name": "Rock_CastIron"
    },
    {
      "x": -5,
      "y": 129,
      "z": -5,
      "name": "Rock_Basalt"
    },
    {
      "x": -5,
      "y": 130,
      "z": -5,
      "name": "Rock_Basalt"
    },
    {
      "x": -5,
      "y": 131,
      "z": -5,
      "name": "Rock_CastIron"
    },
    {
      "x": -5,
      "y": 132,
      "z": -5,
      "name": "Rock_CastIron"
    },
    {
      "x": -5,
      "y": 140,
      "z": -5,
      "name": "Rock_Shale_Brick_Stairs",
      "rotation": 8
    },
    {
      "x": -5,
      "y": 141,
      "z": -5,
      "name": "Rock_CastIron_Brick"
    },
    {
      "x": -5,
      "y": 142,
      "z": -5,
      "name": "Rock_CastIron"
    },
    {
      "x": -5,
      "y": 143,
      "z": -5,
      "name": "Rock_CastIron"
    },
    {
      "x": -5,
      "y": 145,
      "z": -5,
      "name": "Rock_CastIron"
    },
    {
      "x": -5,
      "y": 125,
      "z": -4,
      "name": "Rock_CastIron"
    },
    {
      "x": -5,
      "y": 126,
      "z": -4,
      "name": "Rock_CastIron"
    },
    {
      "x": -5,
      "y": 127,
      "z": -4,
      "name": "Rock_CastIron"
    },
    {
      "x": -5,
      "y": 128,
      "z": -4,
      "name": "Rock_CastIron"
    },
    {
      "x": -5,
      "y": 129,
      "z": -4,
      "name": "Rock_CastIron"
    },
    {
      "x": -5,
      "y": 130,
      "z": -4,
      "name": "Rock_Basalt"
    },
    {
      "x": -5,
      "y": 131,
      "z": -4,
      "name": "Rock_Basalt"
    },
    {
      "x": -5,
      "y": 132,
      "z": -4,
      "name": "Rock_CastIron"
    },
    {
      "x": -5,
      "y": 133,
      "z": -4,
      "name": "Rock_CastIron"
    },
    {
      "x": -5,
      "y": 134,
      "z": -4,
      "name": "Rock_CastIron_Brick"
    },
    {
      "x": -5,
      "y": 135,
      "z": -4,
      "name": "Rock_Shale_Brick_Pillar_Base"
    },
    {
      "x": -5,
      "y": 136,
      "z": -4,
      "name": "Rock_Shale_Brick_Pillar_Middle"
    },
    {
      "x": -5,
      "y": 137,
      "z": -4,
      "name": "Rock_Shale_Brick_Pillar_Middle"
    },
    {
      "x": -5,
      "y": 138,
      "z": -4,
      "name": "Rock_Shale_Brick_Pillar_Middle"
    },
    {
      "x": -5,
      "y": 139,
      "z": -4,
      "name": "Rock_Shale_Brick_Pillar_Base",
      "rotation": 8
    },
    {
      "x": -5,
      "y": 140,
      "z": -4,
      "name": "Rock_CastIron_Brick"
    },
    {
      "x": -5,
      "y": 141,
      "z": -4,
      "name": "Rock_CastIron_Brick"
    },
    {
      "x": -5,
      "y": 142,
      "z": -4,
      "name": "Rock_CastIron"
    },
    {
      "x": -5,
      "y": 143,
      "z": -4,
      "name": "Rock_CastIron"
    },
    {
      "x": -5,
      "y": 144,
      "z": -4,
      "name": "Rock_CastIron"
    },
    {
      "x": -5,
      "y": 145,
      "z": -4,
      "name": "Rock_CastIron"
    },
    {
      "x": -5,
      "y": 146,
      "z": -4,
      "name": "Rock_CastIron"
    },
    {
      "x": -5,
      "y": 126,
      "z": -3,
      "name": "Rock_CastIron"
    },
    {
      "x": -5,
      "y": 127,
      "z": -3,
      "name": "Rock_CastIron"
    },
    {
      "x": -5,
      "y": 128,
      "z": -3,
      "name": "Rock_CastIron"
    },
    {
      "x": -5,
      "y": 129,
      "z": -3,
      "name": "Rock_CastIron"
    },
    {
      "x": -5,
      "y": 130,
      "z": -3,
      "name": "Rock_CastIron"
    },
    {
      "x": -5,
      "y": 131,
      "z": -3,
      "name": "Rock_Basalt"
    },
    {
      "x": -5,
      "y": 132,
      "z": -3,
      "name": "Rock_Basalt"
    },
    {
      "x": -5,
      "y": 133,
      "z": -3,
      "name": "Rock_CastIron"
    },
    {
      "x": -5,
      "y": 134,
      "z": -3,
      "name": "Rock_CastIron_Brick"
    },
    {
      "x": -5,
      "y": 135,
      "z": -3,
      "name": "Rock_CastIron_Brick"
    },
    {
      "x": -5,
      "y": 136,
      "z": -3,
      "name": "Rock_CastIron_Brick"
    },
    {
      "x": -5,
      "y": 137,
      "z": -3,
      "name": "Rock_CastIron_Brick"
    },
    {
      "x": -5,
      "y": 138,
      "z": -3,
      "name": "Rock_CastIron_Brick"
    },
    {
      "x": -5,
      "y": 139,
      "z": -3,
      "name": "Rock_CastIron_Brick"
    },
    {
      "x": -5,
      "y": 140,
      "z": -3,
      "name": "Rock_CastIron_Brick"
    },
    {
      "x": -5,
      "y": 141,
      "z": -3,
      "name": "Rock_CastIron_Brick"
    },
    {
      "x": -5,
      "y": 142,
      "z": -3,
      "name": "Rock_CastIron"
    },
    {
      "x": -5,
      "y": 143,
      "z": -3,
      "name": "Rock_CastIron"
    },
    {
      "x": -5,
      "y": 144,
      "z": -3,
      "name": "Rock_CastIron"
    },
    {
      "x": -5,
      "y": 145,
      "z": -3,
      "name": "Rock_CastIron"
    },
    {
      "x": -5,
      "y": 146,
      "z": -3,
      "name": "Rock_CastIron"
    },
    {
      "x": -5,
      "y": 127,
      "z": -2,
      "name": "Rock_CastIron"
    },
    {
      "x": -5,
      "y": 128,
      "z": -2,
      "name": "Rock_CastIron"
    },
    {
      "x": -5,
      "y": 129,
      "z": -2,
      "name": "Rock_CastIron"
    },
    {
      "x": -5,
      "y": 130,
      "z": -2,
      "name": "Rock_CastIron"
    },
    {
      "x": -5,
      "y": 131,
      "z": -2,
      "name": "Rock_CastIron"
    },
    {
      "x": -5,
      "y": 132,
      "z": -2,
      "name": "Rock_CastIron"
    },
    {
      "x": -5,
      "y": 133,
      "z": -2,
      "name": "Rock_CastIron"
    },
    {
      "x": -5,
      "y": 134,
      "z": -2,
      "name": "Rock_CastIron"
    },
    {
      "x": -5,
      "y": 135,
      "z": -2,
      "name": "Rock_CastIron_Brick"
    },
    {
      "x": -5,
      "y": 136,
      "z": -2,
      "name": "Rock_CastIron_Brick"
    },
    {
      "x": -5,
      "y": 137,
      "z": -2,
      "name": "Rock_CastIron_Brick"
    },
    {
      "x": -5,
      "y": 138,
      "z": -2,
      "name": "Rock_CastIron_Brick"
    },
    {
      "x": -5,
      "y": 139,
      "z": -2,
      "name": "Rock_CastIron_Brick"
    },
    {
      "x": -5,
      "y": 140,
      "z": -2,
      "name": "Rock_CastIron_Brick"
    },
    {
      "x": -5,
      "y": 141,
      "z": -2,
      "name": "Rock_CastIron_Brick"
    },
    {
      "x": -5,
      "y": 142,
      "z": -2,
      "name": "Rock_CastIron"
    },
    {
      "x": -5,
      "y": 143,
      "z": -2,
      "name": "Rock_CastIron"
    },
    {
      "x": -5,
      "y": 144,
      "z": -2,
      "name": "Rock_CastIron"
    },
    {
      "x": -5,
      "y": 145,
      "z": -2,
      "name": "Rock_CastIron"
    },
    {
      "x": -5,
      "y": 146,
      "z": -2,
      "name": "Rock_CastIron"
    },
    {
      "x": -5,
      "y": 128,
      "z": -1,
      "name": "Rock_CastIron"
    },
    {
      "x": -5,
      "y": 129,
      "z": -1,
      "name": "Rock_CastIron"
    },
    {
      "x": -5,
      "y": 130,
      "z": -1,
      "name": "Rock_CastIron"
    },
    {
      "x": -5,
      "y": 131,
      "z": -1,
      "name": "Rock_CastIron"
    },
    {
      "x": -5,
      "y": 132,
      "z": -1,
      "name": "Rock_CastIron"
    },
    {
      "x": -5,
      "y": 133,
      "z": -1,
      "name": "Rock_Basalt"
    },
    {
      "x": -5,
      "y": 134,
      "z": -1,
      "name": "Rock_Basalt"
    },
    {
      "x": -5,
      "y": 135,
      "z": -1,
      "name": "Rock_CastIron_Brick"
    },
    {
      "x": -5,
      "y": 136,
      "z": -1,
      "name": "Rock_CastIron_Brick"
    },
    {
      "x": -5,
      "y": 137,
      "z": -1,
      "name": "Rock_CastIron_Brick"
    },
    {
      "x": -5,
      "y": 138,
      "z": -1,
      "name": "Rock_CastIron_Brick"
    },
    {
      "x": -5,
      "y": 139,
      "z": -1,
      "name": "Rock_CastIron_Brick"
    },
    {
      "x": -5,
      "y": 140,
      "z": -1,
      "name": "Rock_CastIron_Brick"
    },
    {
      "x": -5,
      "y": 141,
      "z": -1,
      "name": "Rock_CastIron_Brick"
    },
    {
      "x": -5,
      "y": 142,
      "z": -1,
      "name": "Rock_CastIron"
    },
    {
      "x": -5,
      "y": 143,
      "z": -1,
      "name": "Rock_CastIron"
    },
    {
      "x": -5,
      "y": 144,
      "z": -1,
      "name": "Rock_CastIron"
    },
    {
      "x": -5,
      "y": 145,
      "z": -1,
      "name": "Rock_CastIron"
    },
    {
      "x": -5,
      "y": 146,
      "z": -1,
      "name": "Rock_Shale_Brick_Stairs",
      "rotation": 3
    },
    {
      "x": -5,
      "y": 129,
      "z": 0,
      "name": "Rock_CastIron"
    },
    {
      "x": -5,
      "y": 130,
      "z": 0,
      "name": "Rock_CastIron"
    },
    {
      "x": -5,
      "y": 131,
      "z": 0,
      "name": "Rock_CastIron"
    },
    {
      "x": -5,
      "y": 132,
      "z": 0,
      "name": "Rock_CastIron"
    },
    {
      "x": -5,
      "y": 133,
      "z": 0,
      "name": "Rock_CastIron"
    },
    {
      "x": -5,
      "y": 134,
      "z": 0,
      "name": "Rock_Basalt"
    },
    {
      "x": -5,
      "y": 135,
      "z": 0,
      "name": "Rock_CastIron_Brick"
    },
    {
      "x": -5,
      "y": 136,
      "z": 0,
      "name": "Rock_CastIron_Brick"
    },
    {
      "x": -5,
      "y": 137,
      "z": 0,
      "name": "Rock_CastIron_Brick"
    },
    {
      "x": -5,
      "y": 138,
      "z": 0,
      "name": "Rock_CastIron_Brick"
    },
    {
      "x": -5,
      "y": 139,
      "z": 0,
      "name": "Rock_CastIron_Brick"
    },
    {
      "x": -5,
      "y": 140,
      "z": 0,
      "name": "Rock_CastIron_Brick"
    },
    {
      "x": -5,
      "y": 141,
      "z": 0,
      "name": "Rock_CastIron_Brick"
    },
    {
      "x": -5,
      "y": 142,
      "z": 0,
      "name": "Rock_CastIron"
    },
    {
      "x": -5,
      "y": 143,
      "z": 0,
      "name": "Rock_CastIron"
    },
    {
      "x": -5,
      "y": 144,
      "z": 0,
      "name": "Rock_CastIron"
    },
    {
      "x": -5,
      "y": 145,
      "z": 0,
      "name": "Rock_CastIron"
    },
    {
      "x": -5,
      "y": 129,
      "z": 1,
      "name": "Rock_CastIron_Brick"
    },
    {
      "x": -5,
      "y": 130,
      "z": 1,
      "name": "Rock_CastIron"
    },
    {
      "x": -5,
      "y": 131,
      "z": 1,
      "name": "Rock_CastIron"
    },
    {
      "x": -5,
      "y": 132,
      "z": 1,
      "name": "Rock_CastIron"
    },
    {
      "x": -5,
      "y": 133,
      "z": 1,
      "name": "Rock_CastIron"
    },
    {
      "x": -5,
      "y": 134,
      "z": 1,
      "name": "Rock_CastIron"
    },
    {
      "x": -5,
      "y": 135,
      "z": 1,
      "name": "Rock_CastIron_Brick"
    },
    {
      "x": -5,
      "y": 136,
      "z": 1,
      "name": "Rock_CastIron_Brick"
    },
    {
      "x": -5,
      "y": 137,
      "z": 1,
      "name": "Rock_CastIron_Brick"
    },
    {
      "x": -5,
      "y": 138,
      "z": 1,
      "name": "Rock_CastIron_Brick"
    },
    {
      "x": -5,
      "y": 139,
      "z": 1,
      "name": "Rock_CastIron_Brick"
    },
    {
      "x": -5,
      "y": 140,
      "z": 1,
      "name": "Rock_CastIron_Brick"
    },
    {
      "x": -5,
      "y": 141,
      "z": 1,
      "name": "Rock_CastIron_Brick"
    },
    {
      "x": -5,
      "y": 142,
      "z": 1,
      "name": "Rock_CastIron"
    },
    {
      "x": -5,
      "y": 143,
      "z": 1,
      "name": "Rock_CastIron"
    },
    {
      "x": -5,
      "y": 144,
      "z": 1,
      "name": "Rock_CastIron"
    },
    {
      "x": -5,
      "y": 145,
      "z": 1,
      "name": "Rock_CastIron"
    },
    {
      "x": -5,
      "y": 129,
      "z": 2,
      "name": "Rock_CastIron_Brick"
    },
    {
      "x": -5,
      "y": 130,
      "z": 2,
      "name": "Rock_CastIron_Brick"
    },
    {
      "x": -5,
      "y": 131,
      "z": 2,
      "name": "Rock_CastIron"
    },
    {
      "x": -5,
      "y": 132,
      "z": 2,
      "name": "Rock_CastIron"
    },
    {
      "x": -5,
      "y": 133,
      "z": 2,
      "name": "Rock_CastIron"
    },
    {
      "x": -5,
      "y": 134,
      "z": 2,
      "name": "Rock_CastIron"
    },
    {
      "x": -5,
      "y": 135,
      "z": 2,
      "name": "Rock_CastIron_Brick"
    },
    {
      "x": -5,
      "y": 136,
      "z": 2,
      "name": "Rock_CastIron_Brick"
    },
    {
      "x": -5,
      "y": 137,
      "z": 2,
      "name": "Rock_CastIron_Brick"
    },
    {
      "x": -5,
      "y": 138,
      "z": 2,
      "name": "Rock_CastIron_Brick"
    },
    {
      "x": -5,
      "y": 139,
      "z": 2,
      "name": "Rock_CastIron_Brick"
    },
    {
      "x": -5,
      "y": 140,
      "z": 2,
      "name": "Rock_CastIron_Brick"
    },
    {
      "x": -5,
      "y": 141,
      "z": 2,
      "name": "Rock_CastIron_Brick"
    },
    {
      "x": -5,
      "y": 142,
      "z": 2,
      "name": "Rock_CastIron"
    },
    {
      "x": -5,
      "y": 143,
      "z": 2,
      "name": "Rock_CastIron"
    },
    {
      "x": -5,
      "y": 144,
      "z": 2,
      "name": "Rock_CastIron"
    },
    {
      "x": -5,
      "y": 145,
      "z": 2,
      "name": "Rock_CastIron"
    },
    {
      "x": -5,
      "y": 129,
      "z": 3,
      "name": "Rock_CastIron_Brick"
    },
    {
      "x": -5,
      "y": 130,
      "z": 3,
      "name": "Rock_CastIron_Brick"
    },
    {
      "x": -5,
      "y": 131,
      "z": 3,
      "name": "Rock_CastIron_Brick"
    },
    {
      "x": -5,
      "y": 132,
      "z": 3,
      "name": "Rock_CastIron"
    },
    {
      "x": -5,
      "y": 133,
      "z": 3,
      "name": "Rock_CastIron"
    },
    {
      "x": -5,
      "y": 134,
      "z": 3,
      "name": "Rock_CastIron"
    },
    {
      "x": -5,
      "y": 135,
      "z": 3,
      "name": "Rock_CastIron_Brick"
    },
    {
      "x": -5,
      "y": 136,
      "z": 3,
      "name": "Rock_CastIron_Brick"
    },
    {
      "x": -5,
      "y": 137,
      "z": 3,
      "name": "Rock_CastIron_Brick"
    },
    {
      "x": -5,
      "y": 138,
      "z": 3,
      "name": "Rock_CastIron_Brick"
    },
    {
      "x": -5,
      "y": 139,
      "z": 3,
      "name": "Rock_CastIron_Brick"
    },
    {
      "x": -5,
      "y": 140,
      "z": 3,
      "name": "Rock_CastIron_Brick"
    },
    {
      "x": -5,
      "y": 141,
      "z": 3,
      "name": "Rock_CastIron_Brick"
    },
    {
      "x": -5,
      "y": 142,
      "z": 3,
      "name": "Rock_CastIron"
    },
    {
      "x": -5,
      "y": 143,
      "z": 3,
      "name": "Rock_CastIron"
    },
    {
      "x": -5,
      "y": 144,
      "z": 3,
      "name": "Rock_CastIron"
    },
    {
      "x": -5,
      "y": 145,
      "z": 3,
      "name": "Rock_CastIron"
    },
    {
      "x": -5,
      "y": 129,
      "z": 4,
      "name": "Rock_CastIron_Brick"
    },
    {
      "x": -5,
      "y": 130,
      "z": 4,
      "name": "Rock_CastIron_Brick"
    },
    {
      "x": -5,
      "y": 131,
      "z": 4,
      "name": "Rock_CastIron_Brick"
    },
    {
      "x": -5,
      "y": 132,
      "z": 4,
      "name": "Rock_CastIron_Brick"
    },
    {
      "x": -5,
      "y": 133,
      "z": 4,
      "name": "Rock_CastIron"
    },
    {
      "x": -5,
      "y": 134,
      "z": 4,
      "name": "Rock_CastIron"
    },
    {
      "x": -5,
      "y": 135,
      "z": 4,
      "name": "Rock_CastIron_Brick"
    },
    {
      "x": -5,
      "y": 136,
      "z": 4,
      "name": "Rock_CastIron_Brick"
    },
    {
      "x": -5,
      "y": 137,
      "z": 4,
      "name": "Rock_CastIron_Brick"
    },
    {
      "x": -5,
      "y": 138,
      "z": 4,
      "name": "Rock_CastIron_Brick"
    },
    {
      "x": -5,
      "y": 139,
      "z": 4,
      "name": "Rock_CastIron_Brick"
    },
    {
      "x": -5,
      "y": 140,
      "z": 4,
      "name": "Rock_CastIron_Brick"
    },
    {
      "x": -5,
      "y": 141,
      "z": 4,
      "name": "Rock_CastIron_Brick"
    },
    {
      "x": -5,
      "y": 142,
      "z": 4,
      "name": "Rock_CastIron"
    },
    {
      "x": -5,
      "y": 143,
      "z": 4,
      "name": "Rock_CastIron"
    },
    {
      "x": -5,
      "y": 144,
      "z": 4,
      "name": "Rock_CastIron"
    },
    {
      "x": -5,
      "y": 145,
      "z": 4,
      "name": "Rock_CastIron"
    },
    {
      "x": -5,
      "y": 146,
      "z": 4,
      "name": "Rock_Shale_Brick_Stairs",
      "rotation": 3
    },
    {
      "x": -5,
      "y": 129,
      "z": 5,
      "name": "Rock_CastIron"
    },
    {
      "x": -5,
      "y": 130,
      "z": 5,
      "name": "Rock_CastIron"
    },
    {
      "x": -5,
      "y": 131,
      "z": 5,
      "name": "Rock_CastIron"
    },
    {
      "x": -5,
      "y": 132,
      "z": 5,
      "name": "Rock_CastIron"
    },
    {
      "x": -5,
      "y": 133,
      "z": 5,
      "name": "Rock_CastIron"
    },
    {
      "x": -5,
      "y": 134,
      "z": 5,
      "name": "Rock_CastIron"
    },
    {
      "x": -5,
      "y": 135,
      "z": 5,
      "name": "Rock_CastIron_Brick"
    },
    {
      "x": -5,
      "y": 136,
      "z": 5,
      "name": "Rock_CastIron_Brick"
    },
    {
      "x": -5,
      "y": 137,
      "z": 5,
      "name": "Rock_CastIron_Brick"
    },
    {
      "x": -5,
      "y": 138,
      "z": 5,
      "name": "Rock_CastIron_Brick"
    },
    {
      "x": -5,
      "y": 139,
      "z": 5,
      "name": "Rock_CastIron_Brick"
    },
    {
      "x": -5,
      "y": 140,
      "z": 5,
      "name": "Rock_CastIron_Brick"
    },
    {
      "x": -5,
      "y": 141,
      "z": 5,
      "name": "Rock_CastIron_Brick"
    },
    {
      "x": -5,
      "y": 142,
      "z": 5,
      "name": "Rock_CastIron"
    },
    {
      "x": -5,
      "y": 143,
      "z": 5,
      "name": "Rock_CastIron"
    },
    {
      "x": -5,
      "y": 144,
      "z": 5,
      "name": "Rock_CastIron"
    },
    {
      "x": -5,
      "y": 145,
      "z": 5,
      "name": "Rock_CastIron"
    },
    {
      "x": -5,
      "y": 129,
      "z": 6,
      "name": "Rock_CastIron_Brick"
    },
    {
      "x": -5,
      "y": 130,
      "z": 6,
      "name": "Rock_CastIron_Brick"
    },
    {
      "x": -5,
      "y": 131,
      "z": 6,
      "name": "Rock_CastIron_Brick"
    },
    {
      "x": -5,
      "y": 132,
      "z": 6,
      "name": "Rock_CastIron_Brick"
    },
    {
      "x": -5,
      "y": 133,
      "z": 6,
      "name": "Rock_CastIron_Brick"
    },
    {
      "x": -5,
      "y": 134,
      "z": 6,
      "name": "Rock_CastIron_Brick"
    },
    {
      "x": -5,
      "y": 135,
      "z": 6,
      "name": "Rock_CastIron_Brick"
    },
    {
      "x": -5,
      "y": 136,
      "z": 6,
      "name": "Rock_CastIron_Brick"
    },
    {
      "x": -5,
      "y": 137,
      "z": 6,
      "name": "Rock_CastIron_Brick"
    },
    {
      "x": -5,
      "y": 138,
      "z": 6,
      "name": "Rock_CastIron_Brick"
    },
    {
      "x": -5,
      "y": 139,
      "z": 6,
      "name": "Rock_CastIron_Brick"
    },
    {
      "x": -5,
      "y": 140,
      "z": 6,
      "name": "Rock_CastIron_Brick"
    },
    {
      "x": -5,
      "y": 141,
      "z": 6,
      "name": "Rock_CastIron_Brick"
    },
    {
      "x": -5,
      "y": 142,
      "z": 6,
      "name": "Rock_CastIron"
    },
    {
      "x": -5,
      "y": 143,
      "z": 6,
      "name": "Rock_CastIron"
    },
    {
      "x": -5,
      "y": 144,
      "z": 6,
      "name": "Rock_CastIron"
    },
    {
      "x": -5,
      "y": 145,
      "z": 6,
      "name": "Rock_CastIron"
    },
    {
      "x": -5,
      "y": 129,
      "z": 7,
      "name": "Rock_CastIron_Brick"
    },
    {
      "x": -5,
      "y": 130,
      "z": 7,
      "name": "Rock_CastIron_Brick"
    },
    {
      "x": -5,
      "y": 131,
      "z": 7,
      "name": "Rock_CastIron_Brick"
    },
    {
      "x": -5,
      "y": 132,
      "z": 7,
      "name": "Rock_CastIron_Brick"
    },
    {
      "x": -5,
      "y": 133,
      "z": 7,
      "name": "Rock_CastIron_Brick"
    },
    {
      "x": -5,
      "y": 134,
      "z": 7,
      "name": "Rock_CastIron_Brick"
    },
    {
      "x": -5,
      "y": 135,
      "z": 7,
      "name": "Rock_Shale_Brick_Pillar_Base"
    },
    {
      "x": -5,
      "y": 136,
      "z": 7,
      "name": "Rock_Shale_Brick_Pillar_Middle"
    },
    {
      "x": -5,
      "y": 137,
      "z": 7,
      "name": "Rock_Shale_Brick_Pillar_Middle"
    },
    {
      "x": -5,
      "y": 138,
      "z": 7,
      "name": "Rock_Shale_Brick_Pillar_Middle"
    },
    {
      "x": -5,
      "y": 139,
      "z": 7,
      "name": "Rock_Shale_Brick_Pillar_Base",
      "rotation": 8
    },
    {
      "x": -5,
      "y": 140,
      "z": 7,
      "name": "Rock_CastIron_Brick"
    },
    {
      "x": -5,
      "y": 141,
      "z": 7,
      "name": "Rock_CastIron_Brick"
    },
    {
      "x": -5,
      "y": 142,
      "z": 7,
      "name": "Rock_CastIron"
    },
    {
      "x": -5,
      "y": 143,
      "z": 7,
      "name": "Rock_CastIron"
    },
    {
      "x": -5,
      "y": 144,
      "z": 7,
      "name": "Rock_CastIron"
    },
    {
      "x": -5,
      "y": 145,
      "z": 7,
      "name": "Rock_CastIron"
    },
    {
      "x": -5,
      "y": 140,
      "z": 8,
      "name": "Rock_Shale_Brick_Stairs",
      "rotation": 10
    },
    {
      "x": -5,
      "y": 141,
      "z": 8,
      "name": "Rock_CastIron_Brick"
    },
    {
      "x": -5,
      "y": 143,
      "z": 8,
      "name": "Rock_CastIron"
    },
    {
      "x": -5,
      "y": 144,
      "z": 8,
      "name": "Rock_CastIron"
    },
    {
      "x": -5,
      "y": 141,
      "z": 9,
      "name": "Rock_CastIron_Brick"
    },
    {
      "x": -4,
      "y": 124,
      "z": -8,
      "name": "Rock_CastIron_Brick_Smooth"
    },
    {
      "x": -4,
      "y": 125,
      "z": -8,
      "name": "Empty"
    },
    {
      "x": -4,
      "y": 126,
      "z": -8,
      "name": "Empty"
    },
    {
      "x": -4,
      "y": 127,
      "z": -8,
      "name": "Empty"
    },
    {
      "x": -4,
      "y": 128,
      "z": -8,
      "name": "Empty"
    },
    {
      "x": -4,
      "y": 129,
      "z": -8,
      "name": "Rock_CastIron_Brick"
    },
    {
      "x": -4,
      "y": 130,
      "z": -8,
      "name": "Rock_CastIron"
    },
    {
      "x": -4,
      "y": 131,
      "z": -8,
      "name": "Empty"
    },
    {
      "x": -4,
      "y": 132,
      "z": -8,
      "name": "Empty"
    },
    {
      "x": -4,
      "y": 133,
      "z": -8,
      "name": "Empty"
    },
    {
      "x": -4,
      "y": 134,
      "z": -8,
      "name": "Empty"
    },
    {
      "x": -4,
      "y": 135,
      "z": -8,
      "name": "Empty"
    },
    {
      "x": -4,
      "y": 136,
      "z": -8,
      "name": "Empty"
    },
    {
      "x": -4,
      "y": 137,
      "z": -8,
      "name": "Empty"
    },
    {
      "x": -4,
      "y": 138,
      "z": -8,
      "name": "Empty"
    },
    {
      "x": -4,
      "y": 139,
      "z": -8,
      "name": "Empty"
    },
    {
      "x": -4,
      "y": 140,
      "z": -8,
      "name": "Empty"
    },
    {
      "x": -4,
      "y": 141,
      "z": -8,
      "name": "Empty"
    },
    {
      "x": -4,
      "y": 142,
      "z": -8,
      "name": "Empty"
    },
    {
      "x": -4,
      "y": 143,
      "z": -8,
      "name": "Empty"
    },
    {
      "x": -4,
      "y": 124,
      "z": -7,
      "name": "Rock_CastIron_Brick_Smooth"
    },
    {
      "x": -4,
      "y": 125,
      "z": -7,
      "name": "Empty"
    },
    {
      "x": -4,
      "y": 126,
      "z": -7,
      "name": "Empty"
    },
    {
      "x": -4,
      "y": 127,
      "z": -7,
      "name": "Empty"
    },
    {
      "x": -4,
      "y": 128,
      "z": -7,
      "name": "Rock_Shale_Brick_Stairs",
      "rotation": 8
    },
    {
      "x": -4,
      "y": 129,
      "z": -7,
      "name": "Rock_CastIron_Brick"
    },
    {
      "x": -4,
      "y": 130,
      "z": -7,
      "name": "Rock_CastIron"
    },
    {
      "x": -4,
      "y": 131,
      "z": -7,
      "name": "Empty"
    },
    {
      "x": -4,
      "y": 132,
      "z": -7,
      "name": "Empty"
    },
    {
      "x": -4,
      "y": 133,
      "z": -7,
      "name": "Empty"
    },
    {
      "x": -4,
      "y": 134,
      "z": -7,
      "name": "Empty"
    },
    {
      "x": -4,
      "y": 135,
      "z": -7,
      "name": "Empty"
    },
    {
      "x": -4,
      "y": 136,
      "z": -7,
      "name": "Empty"
    },
    {
      "x": -4,
      "y": 137,
      "z": -7,
      "name": "Empty"
    },
    {
      "x": -4,
      "y": 138,
      "z": -7,
      "name": "Empty"
    },
    {
      "x": -4,
      "y": 139,
      "z": -7,
      "name": "Empty"
    },
    {
      "x": -4,
      "y": 140,
      "z": -7,
      "name": "Empty"
    },
    {
      "x": -4,
      "y": 141,
      "z": -7,
      "name": "Empty"
    },
    {
      "x": -4,
      "y": 142,
      "z": -7,
      "name": "Empty"
    },
    {
      "x": -4,
      "y": 143,
      "z": -7,
      "name": "Empty"
    },
    {
      "x": -4,
      "y": 124,
      "z": -6,
      "name": "Rock_CastIron_Brick_Smooth"
    },
    {
      "x": -4,
      "y": 125,
      "z": -6,
      "name": "Rock_Shale_Brick_Pillar_Base"
    },
    {
      "x": -4,
      "y": 126,
      "z": -6,
      "name": "Rock_Shale_Brick_Pillar_Middle"
    },
    {
      "x": -4,
      "y": 127,
      "z": -6,
      "name": "Rock_Shale_Brick_Pillar_Base",
      "rotation": 8
    },
    {
      "x": -4,
      "y": 128,
      "z": -6,
      "name": "Rock_CastIron_Brick"
    },
    {
      "x": -4,
      "y": 129,
      "z": -6,
      "name": "Rock_CastIron_Brick"
    },
    {
      "x": -4,
      "y": 130,
      "z": -6,
      "name": "Rock_CastIron_Brick"
    },
    {
      "x": -4,
      "y": 131,
      "z": -6,
      "name": "Rock_CastIron"
    },
    {
      "x": -4,
      "y": 132,
      "z": -6,
      "name": "Empty"
    },
    {
      "x": -4,
      "y": 133,
      "z": -6,
      "name": "Empty"
    },
    {
      "x": -4,
      "y": 134,
      "z": -6,
      "name": "Empty"
    },
    {
      "x": -4,
      "y": 135,
      "z": -6,
      "name": "Empty"
    },
    {
      "x": -4,
      "y": 136,
      "z": -6,
      "name": "Empty"
    },
    {
      "x": -4,
      "y": 137,
      "z": -6,
      "name": "Empty"
    },
    {
      "x": -4,
      "y": 138,
      "z": -6,
      "name": "Empty"
    },
    {
      "x": -4,
      "y": 139,
      "z": -6,
      "name": "Empty"
    },
    {
      "x": -4,
      "y": 140,
      "z": -6,
      "name": "Empty"
    },
    {
      "x": -4,
      "y": 141,
      "z": -6,
      "name": "Empty"
    },
    {
      "x": -4,
      "y": 142,
      "z": -6,
      "name": "Empty"
    },
    {
      "x": -4,
      "y": 143,
      "z": -6,
      "name": "Empty"
    },
    {
      "x": -4,
      "y": 124,
      "z": -5,
      "name": "Rock_CastIron_Brick_Smooth"
    },
    {
      "x": -4,
      "y": 125,
      "z": -5,
      "name": "Rock_CastIron_Brick"
    },
    {
      "x": -4,
      "y": 126,
      "z": -5,
      "name": "Empty"
    },
    {
      "x": -4,
      "y": 127,
      "z": -5,
      "name": "Empty"
    },
    {
      "x": -4,
      "y": 128,
      "z": -5,
      "name": "Empty"
    },
    {
      "x": -4,
      "y": 129,
      "z": -5,
      "name": "Empty"
    },
    {
      "x": -4,
      "y": 130,
      "z": -5,
      "name": "Rock_Shale_Brick_Stairs",
      "rotation": 10
    },
    {
      "x": -4,
      "y": 131,
      "z": -5,
      "name": "Rock_CastIron_Brick"
    },
    {
      "x": -4,
      "y": 132,
      "z": -5,
      "name": "Rock_CastIron"
    },
    {
      "x": -4,
      "y": 133,
      "z": -5,
      "name": "Empty"
    },
    {
      "x": -4,
      "y": 134,
      "z": -5,
      "name": "Empty"
    },
    {
      "x": -4,
      "y": 135,
      "z": -5,
      "name": "Empty"
    },
    {
      "x": -4,
      "y": 136,
      "z": -5,
      "name": "Empty"
    },
    {
      "x": -4,
      "y": 137,
      "z": -5,
      "name": "Empty"
    },
    {
      "x": -4,
      "y": 138,
      "z": -5,
      "name": "Empty"
    },
    {
      "x": -4,
      "y": 139,
      "z": -5,
      "name": "Empty"
    },
    {
      "x": -4,
      "y": 140,
      "z": -5,
      "name": "Empty"
    },
    {
      "x": -4,
      "y": 141,
      "z": -5,
      "name": "Rock_CastIron"
    },
    {
      "x": -4,
      "y": 142,
      "z": -5,
      "name": "Rock_CastIron"
    },
    {
      "x": -4,
      "y": 143,
      "z": -5,
      "name": "Rock_CastIron"
    },
    {
      "x": -4,
      "y": 145,
      "z": -5,
      "name": "Rock_CastIron"
    },
    {
      "x": -4,
      "y": 146,
      "z": -5,
      "name": "Rock_CastIron"
    },
    {
      "x": -4,
      "y": 125,
      "z": -4,
      "name": "Rock_CastIron_Brick"
    },
    {
      "x": -4,
      "y": 126,
      "z": -4,
      "name": "Rock_CastIron_Brick"
    },
    {
      "x": -4,
      "y": 127,
      "z": -4,
      "name": "Empty"
    },
    {
      "x": -4,
      "y": 128,
      "z": -4,
      "name": "Empty"
    },
    {
      "x": -4,
      "y": 129,
      "z": -4,
      "name": "Empty"
    },
    {
      "x": -4,
      "y": 130,
      "z": -4,
      "name": "Empty"
    },
    {
      "x": -4,
      "y": 131,
      "z": -4,
      "name": "Rock_Shale_Brick_Stairs",
      "rotation": 10
    },
    {
      "x": -4,
      "y": 132,
      "z": -4,
      "name": "Rock_CastIron_Brick"
    },
    {
      "x": -4,
      "y": 133,
      "z": -4,
      "name": "Rock_CastIron"
    },
    {
      "x": -4,
      "y": 134,
      "z": -4,
      "name": "Rock_CastIron_Brick"
    },
    {
      "x": -4,
      "y": 135,
      "z": -4,
      "name": "Rock_CastIron_Brick"
    },
    {
      "x": -4,
      "y": 136,
      "z": -4,
      "name": "Deco_Bone_Pile"
    },
    {
      "x": -4,
      "y": 137,
      "z": -4,
      "name": "Rock_CastIron_Brick"
    },
    {
      "x": -4,
      "y": 138,
      "z": -4,
      "name": "Deco_Bone_Skulls"
    },
    {
      "x": -4,
      "y": 139,
      "z": -4,
      "name": "Rock_CastIron_Brick"
    },
    {
      "x": -4,
      "y": 140,
      "z": -4,
      "name": "Empty"
    },
    {
      "x": -4,
      "y": 141,
      "z": -4,
      "name": "Rock_CastIron"
    },
    {
      "x": -4,
      "y": 142,
      "z": -4,
      "name": "Rock_CastIron"
    },
    {
      "x": -4,
      "y": 143,
      "z": -4,
      "name": "Rock_CastIron"
    },
    {
      "x": -4,
      "y": 144,
      "z": -4,
      "name": "Rock_CastIron"
    },
    {
      "x": -4,
      "y": 145,
      "z": -4,
      "name": "Rock_CastIron"
    },
    {
      "x": -4,
      "y": 146,
      "z": -4,
      "name": "Rock_CastIron"
    },
    {
      "x": -4,
      "y": 125,
      "z": -3,
      "name": "Empty"
    },
    {
      "x": -4,
      "y": 126,
      "z": -3,
      "name": "Rock_CastIron_Brick"
    },
    {
      "x": -4,
      "y": 127,
      "z": -3,
      "name": "Rock_CastIron_Brick"
    },
    {
      "x": -4,
      "y": 128,
      "z": -3,
      "name": "Empty"
    },
    {
      "x": -4,
      "y": 129,
      "z": -3,
      "name": "Empty"
    },
    {
      "x": -4,
      "y": 130,
      "z": -3,
      "name": "Empty"
    },
    {
      "x": -4,
      "y": 131,
      "z": -3,
      "name": "Empty"
    },
    {
      "x": -4,
      "y": 132,
      "z": -3,
      "name": "Rock_Shale_Brick_Stairs",
      "rotation": 10
    },
    {
      "x": -4,
      "y": 133,
      "z": -3,
      "name": "Rock_CastIron_Brick"
    },
    {
      "x": -4,
      "y": 134,
      "z": -3,
      "name": "Rock_CastIron"
    },
    {
      "x": -4,
      "y": 135,
      "z": -3,
      "name": "Rock_CastIron_Brick"
    },
    {
      "x": -4,
      "y": 136,
      "z": -3,
      "name": "Rock_CastIron_Cobble"
    },
    {
      "x": -4,
      "y": 137,
      "z": -3,
      "name": "Rock_CastIron_Cobble"
    },
    {
      "x": -4,
      "y": 138,
      "z": -3,
      "name": "Rock_CastIron_Cobble"
    },
    {
      "x": -4,
      "y": 139,
      "z": -3,
      "name": "Rock_CastIron_Cobble"
    },
    {
      "x": -4,
      "y": 140,
      "z": -3,
      "name": "Rock_CastIron_Cobble"
    },
    {
      "x": -4,
      "y": 141,
      "z": -3,
      "name": "Rock_CastIron_Brick"
    },
    {
      "x": -4,
      "y": 142,
      "z": -3,
      "name": "Rock_CastIron"
    },
    {
      "x": -4,
      "y": 143,
      "z": -3,
      "name": "Rock_CastIron"
    },
    {
      "x": -4,
      "y": 144,
      "z": -3,
      "name": "Rock_CastIron"
    },
    {
      "x": -4,
      "y": 145,
      "z": -3,
      "name": "Rock_CastIron"
    },
    {
      "x": -4,
      "y": 146,
      "z": -3,
      "name": "Rock_CastIron"
    },
    {
      "x": -4,
      "y": 125,
      "z": -2,
      "name": "Empty"
    },
    {
      "x": -4,
      "y": 126,
      "z": -2,
      "name": "Empty"
    },
    {
      "x": -4,
      "y": 127,
      "z": -2,
      "name": "Rock_CastIron_Brick"
    },
    {
      "x": -4,
      "y": 128,
      "z": -2,
      "name": "Rock_Shale_Brick_Pillar_Base"
    },
    {
      "x": -4,
      "y": 129,
      "z": -2,
      "name": "Rock_Shale_Brick_Pillar_Middle"
    },
    {
      "x": -4,
      "y": 130,
      "z": -2,
      "name": "Rock_Shale_Brick_Pillar_Middle"
    },
    {
      "x": -4,
      "y": 131,
      "z": -2,
      "name": "Rock_Shale_Brick_Pillar_Base",
      "rotation": 8
    },
    {
      "x": -4,
      "y": 132,
      "z": -2,
      "name": "Rock_CastIron_Brick"
    },
    {
      "x": -4,
      "y": 133,
      "z": -2,
      "name": "Rock_CastIron_Brick"
    },
    {
      "x": -4,
      "y": 134,
      "z": -2,
      "name": "Rock_CastIron_Brick"
    },
    {
      "x": -4,
      "y": 135,
      "z": -2,
      "name": "Rock_CastIron"
    },
    {
      "x": -4,
      "y": 136,
      "z": -2,
      "name": "Rock_CastIron_Brick"
    },
    {
      "x": -4,
      "y": 137,
      "z": -2,
      "name": "Rock_CastIron_Brick"
    },
    {
      "x": -4,
      "y": 138,
      "z": -2,
      "name": "Rock_CastIron_Brick"
    },
    {
      "x": -4,
      "y": 139,
      "z": -2,
      "name": "Rock_CastIron_Brick"
    },
    {
      "x": -4,
      "y": 140,
      "z": -2,
      "name": "Rock_CastIron_Brick"
    },
    {
      "x": -4,
      "y": 141,
      "z": -2,
      "name": "Rock_CastIron_Brick"
    },
    {
      "x": -4,
      "y": 142,
      "z": -2,
      "name": "Rock_CastIron"
    },
    {
      "x": -4,
      "y": 143,
      "z": -2,
      "name": "Rock_CastIron"
    },
    {
      "x": -4,
      "y": 144,
      "z": -2,
      "name": "Rock_CastIron"
    },
    {
      "x": -4,
      "y": 145,
      "z": -2,
      "name": "Rock_CastIron"
    },
    {
      "x": -4,
      "y": 146,
      "z": -2,
      "name": "Rock_CastIron"
    },
    {
      "x": -4,
      "y": 125,
      "z": -1,
      "name": "Empty"
    },
    {
      "x": -4,
      "y": 126,
      "z": -1,
      "name": "Empty"
    },
    {
      "x": -4,
      "y": 127,
      "z": -1,
      "name": "Empty"
    },
    {
      "x": -4,
      "y": 128,
      "z": -1,
      "name": "Rock_CastIron_Brick"
    },
    {
      "x": -4,
      "y": 129,
      "z": -1,
      "name": "Rock_CastIron_Brick"
    },
    {
      "x": -4,
      "y": 130,
      "z": -1,
      "name": "Empty"
    },
    {
      "x": -4,
      "y": 131,
      "z": -1,
      "name": "Empty"
    },
    {
      "x": -4,
      "y": 132,
      "z": -1,
      "name": "Empty"
    },
    {
      "x": -4,
      "y": 133,
      "z": -1,
      "name": "Empty"
    },
    {
      "x": -4,
      "y": 134,
      "z": -1,
      "name": "Rock_Shale_Brick_Stairs",
      "rotation": 10
    },
    {
      "x": -4,
      "y": 135,
      "z": -1,
      "name": "Rock_CastIron_Brick"
    },
    {
      "x": -4,
      "y": 136,
      "z": -1,
      "name": "Rock_CastIron"
    },
    {
      "x": -4,
      "y": 137,
      "z": -1,
      "name": "Rock_CastIron_Brick"
    },
    {
      "x": -4,
      "y": 138,
      "z": -1,
      "name": "Rock_CastIron_Brick"
    },
    {
      "x": -4,
      "y": 139,
      "z": -1,
      "name": "Rock_CastIron_Brick"
    },
    {
      "x": -4,
      "y": 140,
      "z": -1,
      "name": "Rock_CastIron_Brick"
    },
    {
      "x": -4,
      "y": 141,
      "z": -1,
      "name": "Rock_CastIron_Brick"
    },
    {
      "x": -4,
      "y": 142,
      "z": -1,
      "name": "Rock_CastIron"
    },
    {
      "x": -4,
      "y": 143,
      "z": -1,
      "name": "Rock_CastIron"
    },
    {
      "x": -4,
      "y": 144,
      "z": -1,
      "name": "Rock_CastIron"
    },
    {
      "x": -4,
      "y": 145,
      "z": -1,
      "name": "Rock_CastIron"
    },
    {
      "x": -4,
      "y": 146,
      "z": -1,
      "name": "Rock_CastIron"
    },
    {
      "x": -4,
      "y": 147,
      "z": -1,
      "name": "Rock_Shale_Brick_Stairs",
      "rotation": 3
    },
    {
      "x": -4,
      "y": 125,
      "z": 0,
      "name": "Empty"
    },
    {
      "x": -4,
      "y": 126,
      "z": 0,
      "name": "Empty"
    },
    {
      "x": -4,
      "y": 127,
      "z": 0,
      "name": "Empty"
    },
    {
      "x": -4,
      "y": 128,
      "z": 0,
      "name": "Empty"
    },
    {
      "x": -4,
      "y": 129,
      "z": 0,
      "name": "Rock_CastIron_Brick"
    },
    {
      "x": -4,
      "y": 130,
      "z": 0,
      "name": "Rock_CastIron_Brick"
    },
    {
      "x": -4,
      "y": 131,
      "z": 0,
      "name": "Empty"
    },
    {
      "x": -4,
      "y": 132,
      "z": 0,
      "name": "Empty"
    },
    {
      "x": -4,
      "y": 133,
      "z": 0,
      "name": "Empty"
    },
    {
      "x": -4,
      "y": 134,
      "z": 0,
      "name": "Empty"
    },
    {
      "x": -4,
      "y": 135,
      "z": 0,
      "name": "Rock_Shale_Brick_Stairs",
      "rotation": 10
    },
    {
      "x": -4,
      "y": 136,
      "z": 0,
      "name": "Rock_CastIron_Brick"
    },
    {
      "x": -4,
      "y": 137,
      "z": 0,
      "name": "Rock_CastIron"
    },
    {
      "x": -4,
      "y": 138,
      "z": 0,
      "name": "Rock_CastIron_Brick"
    },
    {
      "x": -4,
      "y": 139,
      "z": 0,
      "name": "Rock_CastIron_Brick"
    },
    {
      "x": -4,
      "y": 140,
      "z": 0,
      "name": "Rock_CastIron_Brick"
    },
    {
      "x": -4,
      "y": 141,
      "z": 0,
      "name": "Rock_CastIron_Brick"
    },
    {
      "x": -4,
      "y": 142,
      "z": 0,
      "name": "Rock_CastIron"
    },
    {
      "x": -4,
      "y": 143,
      "z": 0,
      "name": "Rock_CastIron"
    },
    {
      "x": -4,
      "y": 144,
      "z": 0,
      "name": "Rock_CastIron"
    },
    {
      "x": -4,
      "y": 145,
      "z": 0,
      "name": "Rock_CastIron"
    },
    {
      "x": -4,
      "y": 146,
      "z": 0,
      "name": "Rock_CastIron"
    },
    {
      "x": -4,
      "y": 125,
      "z": 1,
      "name": "Empty"
    },
    {
      "x": -4,
      "y": 126,
      "z": 1,
      "name": "Empty"
    },
    {
      "x": -4,
      "y": 127,
      "z": 1,
      "name": "Empty"
    },
    {
      "x": -4,
      "y": 128,
      "z": 1,
      "name": "Empty"
    },
    {
      "x": -4,
      "y": 129,
      "z": 1,
      "name": "Rock_CastIron_Brick"
    },
    {
      "x": -4,
      "y": 130,
      "z": 1,
      "name": "Rock_CastIron_Brick"
    },
    {
      "x": -4,
      "y": 131,
      "z": 1,
      "name": "Rock_CastIron_Brick"
    },
    {
      "x": -4,
      "y": 132,
      "z": 1,
      "name": "Empty"
    },
    {
      "x": -4,
      "y": 133,
      "z": 1,
      "name": "Empty"
    },
    {
      "x": -4,
      "y": 134,
      "z": 1,
      "name": "Plant_Moss_Wall_Blue",
      "rotation": 1
    },
    {
      "x": -4,
      "y": 135,
      "z": 1,
      "name": "Empty"
    },
    {
      "x": -4,
      "y": 136,
      "z": 1,
      "name": "Rock_Shale_Brick_Stairs",
      "rotation": 10
    },
    {
      "x": -4,
      "y": 137,
      "z": 1,
      "name": "Rock_CastIron_Brick"
    },
    {
      "x": -4,
      "y": 138,
      "z": 1,
      "name": "Rock_CastIron"
    },
    {
      "x": -4,
      "y": 139,
      "z": 1,
      "name": "Rock_CastIron_Brick"
    },
    {
      "x": -4,
      "y": 140,
      "z": 1,
      "name": "Rock_CastIron_Brick"
    },
    {
      "x": -4,
      "y": 141,
      "z": 1,
      "name": "Rock_CastIron_Brick"
    },
    {
      "x": -4,
      "y": 142,
      "z": 1,
      "name": "Rock_CastIron"
    },
    {
      "x": -4,
      "y": 143,
      "z": 1,
      "name": "Rock_CastIron"
    },
    {
      "x": -4,
      "y": 144,
      "z": 1,
      "name": "Rock_CastIron"
    },
    {
      "x": -4,
      "y": 145,
      "z": 1,
      "name": "Rock_CastIron"
    },
    {
      "x": -4,
      "y": 146,
      "z": 1,
      "name": "Rock_CastIron"
    },
    {
      "x": -4,
      "y": 125,
      "z": 2,
      "name": "Empty"
    },
    {
      "x": -4,
      "y": 126,
      "z": 2,
      "name": "Empty"
    },
    {
      "x": -4,
      "y": 127,
      "z": 2,
      "name": "Empty"
    },
    {
      "x": -4,
      "y": 128,
      "z": 2,
      "name": "Empty"
    },
    {
      "x": -4,
      "y": 129,
      "z": 2,
      "name": "Rock_CastIron_Brick"
    },
    {
      "x": -4,
      "y": 130,
      "z": 2,
      "name": "Rock_CastIron_Brick"
    },
    {
      "x": -4,
      "y": 131,
      "z": 2,
      "name": "Rock_CastIron_Brick"
    },
    {
      "x": -4,
      "y": 132,
      "z": 2,
      "name": "Rock_Shale_Brick_Pillar_Base"
    },
    {
      "x": -4,
      "y": 133,
      "z": 2,
      "name": "Rock_Shale_Brick_Pillar_Middle"
    },
    {
      "x": -4,
      "y": 134,
      "z": 2,
      "name": "Rock_Shale_Brick_Pillar_Middle"
    },
    {
      "x": -4,
      "y": 135,
      "z": 2,
      "name": "Rock_Shale_Brick_Pillar_Base",
      "rotation": 8
    },
    {
      "x": -4,
      "y": 136,
      "z": 2,
      "name": "Rock_CastIron_Brick"
    },
    {
      "x": -4,
      "y": 137,
      "z": 2,
      "name": "Rock_CastIron_Brick"
    },
    {
      "x": -4,
      "y": 138,
      "z": 2,
      "name": "Rock_CastIron_Brick"
    },
    {
      "x": -4,
      "y": 139,
      "z": 2,
      "name": "Rock_CastIron"
    },
    {
      "x": -4,
      "y": 140,
      "z": 2,
      "name": "Rock_CastIron_Brick"
    },
    {
      "x": -4,
      "y": 141,
      "z": 2,
      "name": "Rock_CastIron_Brick"
    },
    {
      "x": -4,
      "y": 142,
      "z": 2,
      "name": "Rock_CastIron"
    },
    {
      "x": -4,
      "y": 143,
      "z": 2,
      "name": "Rock_CastIron"
    },
    {
      "x": -4,
      "y": 144,
      "z": 2,
      "name": "Rock_CastIron"
    },
    {
      "x": -4,
      "y": 145,
      "z": 2,
      "name": "Rock_CastIron"
    },
    {
      "x": -4,
      "y": 146,
      "z": 2,
      "name": "Rock_CastIron"
    },
    {
      "x": -4,
      "y": 125,
      "z": 3,
      "name": "Empty"
    },
    {
      "x": -4,
      "y": 126,
      "z": 3,
      "name": "Empty"
    },
    {
      "x": -4,
      "y": 127,
      "z": 3,
      "name": "Empty"
    },
    {
      "x": -4,
      "y": 128,
      "z": 3,
      "name": "Empty"
    },
    {
      "x": -4,
      "y": 129,
      "z": 3,
      "name": "Rock_CastIron_Brick"
    },
    {
      "x": -4,
      "y": 130,
      "z": 3,
      "name": "Rock_CastIron_Brick"
    },
    {
      "x": -4,
      "y": 131,
      "z": 3,
      "name": "Rock_CastIron_Brick"
    },
    {
      "x": -4,
      "y": 132,
      "z": 3,
      "name": "Rock_CastIron_Brick"
    },
    {
      "x": -4,
      "y": 133,
      "z": 3,
      "name": "Rock_CastIron_Brick"
    },
    {
      "x": -4,
      "y": 134,
      "z": 3,
      "name": "Empty"
    },
    {
      "x": -4,
      "y": 135,
      "z": 3,
      "name": "Empty"
    },
    {
      "x": -4,
      "y": 136,
      "z": 3,
      "name": "Empty"
    },
    {
      "x": -4,
      "y": 137,
      "z": 3,
      "name": "Plant_Moss_Wall_Blue",
      "rotation": 1
    },
    {
      "x": -4,
      "y": 138,
      "z": 3,
      "name": "Rock_Shale_Brick_Stairs",
      "rotation": 10
    },
    {
      "x": -4,
      "y": 139,
      "z": 3,
      "name": "Rock_CastIron_Brick"
    },
    {
      "x": -4,
      "y": 140,
      "z": 3,
      "name": "Rock_CastIron"
    },
    {
      "x": -4,
      "y": 141,
      "z": 3,
      "name": "Rock_CastIron_Brick"
    },
    {
      "x": -4,
      "y": 142,
      "z": 3,
      "name": "Rock_CastIron"
    },
    {
      "x": -4,
      "y": 143,
      "z": 3,
      "name": "Rock_CastIron"
    },
    {
      "x": -4,
      "y": 144,
      "z": 3,
      "name": "Rock_CastIron"
    },
    {
      "x": -4,
      "y": 145,
      "z": 3,
      "name": "Rock_CastIron"
    },
    {
      "x": -4,
      "y": 146,
      "z": 3,
      "name": "Rock_CastIron"
    },
    {
      "x": -4,
      "y": 125,
      "z": 4,
      "name": "Empty"
    },
    {
      "x": -4,
      "y": 126,
      "z": 4,
      "name": "Empty"
    },
    {
      "x": -4,
      "y": 127,
      "z": 4,
      "name": "Empty"
    },
    {
      "x": -4,
      "y": 128,
      "z": 4,
      "name": "Empty"
    },
    {
      "x": -4,
      "y": 129,
      "z": 4,
      "name": "Rock_CastIron_Brick"
    },
    {
      "x": -4,
      "y": 130,
      "z": 4,
      "name": "Rock_CastIron_Brick"
    },
    {
      "x": -4,
      "y": 131,
      "z": 4,
      "name": "Rock_CastIron_Brick"
    },
    {
      "x": -4,
      "y": 132,
      "z": 4,
      "name": "Rock_CastIron_Brick"
    },
    {
      "x": -4,
      "y": 133,
      "z": 4,
      "name": "Rock_CastIron_Brick"
    },
    {
      "x": -4,
      "y": 134,
      "z": 4,
      "name": "Rock_CastIron_Brick"
    },
    {
      "x": -4,
      "y": 135,
      "z": 4,
      "name": "Furniture_Human_Ruins_Brazier"
    },
    {
      "x": -4,
      "y": 136,
      "z": 4,
      "name": "Empty"
    },
    {
      "x": -4,
      "y": 137,
      "z": 4,
      "name": "Empty"
    },
    {
      "x": -4,
      "y": 138,
      "z": 4,
      "name": "Plant_Moss_Wall_Blue",
      "rotation": 1
    },
    {
      "x": -4,
      "y": 139,
      "z": 4,
      "name": "Rock_Shale_Brick_Stairs",
      "rotation": 10
    },
    {
      "x": -4,
      "y": 140,
      "z": 4,
      "name": "Rock_CastIron_Brick"
    },
    {
      "x": -4,
      "y": 141,
      "z": 4,
      "name": "Rock_CastIron"
    },
    {
      "x": -4,
      "y": 142,
      "z": 4,
      "name": "Rock_CastIron"
    },
    {
      "x": -4,
      "y": 143,
      "z": 4,
      "name": "Rock_CastIron"
    },
    {
      "x": -4,
      "y": 144,
      "z": 4,
      "name": "Rock_CastIron"
    },
    {
      "x": -4,
      "y": 145,
      "z": 4,
      "name": "Rock_CastIron"
    },
    {
      "x": -4,
      "y": 146,
      "z": 4,
      "name": "Rock_CastIron"
    },
    {
      "x": -4,
      "y": 147,
      "z": 4,
      "name": "Rock_Shale_Brick_Stairs",
      "rotation": 3
    },
    {
      "x": -4,
      "y": 125,
      "z": 5,
      "name": "Empty"
    },
    {
      "x": -4,
      "y": 126,
      "z": 5,
      "name": "Empty"
    },
    {
      "x": -4,
      "y": 127,
      "z": 5,
      "name": "Empty"
    },
    {
      "x": -4,
      "y": 128,
      "z": 5,
      "name": "Empty"
    },
    {
      "x": -4,
      "y": 129,
      "z": 5,
      "name": "Rock_CastIron_Brick"
    },
    {
      "x": -4,
      "y": 130,
      "z": 5,
      "name": "Rock_CastIron_Brick"
    },
    {
      "x": -4,
      "y": 131,
      "z": 5,
      "name": "Rock_CastIron_Brick"
    },
    {
      "x": -4,
      "y": 132,
      "z": 5,
      "name": "Rock_CastIron_Brick"
    },
    {
      "x": -4,
      "y": 133,
      "z": 5,
      "name": "Rock_CastIron_Brick"
    },
    {
      "x": -4,
      "y": 134,
      "z": 5,
      "name": "Rock_CastIron_Brick"
    },
    {
      "x": -4,
      "y": 135,
      "z": 5,
      "name": "Rock_CastIron_Brick"
    },
    {
      "x": -4,
      "y": 136,
      "z": 5,
      "name": "Empty"
    },
    {
      "x": -4,
      "y": 137,
      "z": 5,
      "name": "Empty"
    },
    {
      "x": -4,
      "y": 138,
      "z": 5,
      "name": "Empty"
    },
    {
      "x": -4,
      "y": 139,
      "z": 5,
      "name": "Empty"
    },
    {
      "x": -4,
      "y": 140,
      "z": 5,
      "name": "Rock_CastIron_Brick"
    },
    {
      "x": -4,
      "y": 141,
      "z": 5,
      "name": "Rock_CastIron"
    },
    {
      "x": -4,
      "y": 142,
      "z": 5,
      "name": "Rock_CastIron"
    },
    {
      "x": -4,
      "y": 143,
      "z": 5,
      "name": "Rock_CastIron"
    },
    {
      "x": -4,
      "y": 144,
      "z": 5,
      "name": "Rock_CastIron"
    },
    {
      "x": -4,
      "y": 145,
      "z": 5,
      "name": "Rock_CastIron"
    },
    {
      "x": -4,
      "y": 146,
      "z": 5,
      "name": "Rock_CastIron"
    },
    {
      "x": -4,
      "y": 125,
      "z": 6,
      "name": "Empty"
    },
    {
      "x": -4,
      "y": 126,
      "z": 6,
      "name": "Empty"
    },
    {
      "x": -4,
      "y": 127,
      "z": 6,
      "name": "Empty"
    },
    {
      "x": -4,
      "y": 128,
      "z": 6,
      "name": "Empty"
    },
    {
      "x": -4,
      "y": 129,
      "z": 6,
      "name": "Rock_CastIron"
    },
    {
      "x": -4,
      "y": 130,
      "z": 6,
      "name": "Rock_CastIron"
    },
    {
      "x": -4,
      "y": 131,
      "z": 6,
      "name": "Rock_CastIron"
    },
    {
      "x": -4,
      "y": 132,
      "z": 6,
      "name": "Rock_CastIron"
    },
    {
      "x": -4,
      "y": 133,
      "z": 6,
      "name": "Rock_CastIron"
    },
    {
      "x": -4,
      "y": 134,
      "z": 6,
      "name": "Rock_CastIron"
    },
    {
      "x": -4,
      "y": 135,
      "z": 6,
      "name": "Rock_CastIron"
    },
    {
      "x": -4,
      "y": 136,
      "z": 6,
      "name": "Rock_CastIron"
    },
    {
      "x": -4,
      "y": 137,
      "z": 6,
      "name": "Rock_CastIron"
    },
    {
      "x": -4,
      "y": 138,
      "z": 6,
      "name": "Rock_CastIron"
    },
    {
      "x": -4,
      "y": 139,
      "z": 6,
      "name": "Rock_CastIron"
    },
    {
      "x": -4,
      "y": 140,
      "z": 6,
      "name": "Rock_CastIron"
    },
    {
      "x": -4,
      "y": 141,
      "z": 6,
      "name": "Rock_CastIron_Brick"
    },
    {
      "x": -4,
      "y": 142,
      "z": 6,
      "name": "Rock_CastIron"
    },
    {
      "x": -4,
      "y": 143,
      "z": 6,
      "name": "Rock_CastIron"
    },
    {
      "x": -4,
      "y": 144,
      "z": 6,
      "name": "Rock_CastIron"
    },
    {
      "x": -4,
      "y": 145,
      "z": 6,
      "name": "Rock_CastIron"
    },
    {
      "x": -4,
      "y": 146,
      "z": 6,
      "name": "Rock_CastIron"
    },
    {
      "x": -4,
      "y": 125,
      "z": 7,
      "name": "Empty"
    },
    {
      "x": -4,
      "y": 126,
      "z": 7,
      "name": "Empty"
    },
    {
      "x": -4,
      "y": 127,
      "z": 7,
      "name": "Empty"
    },
    {
      "x": -4,
      "y": 128,
      "z": 7,
      "name": "Empty"
    },
    {
      "x": -4,
      "y": 129,
      "z": 7,
      "name": "Rock_CastIron"
    },
    {
      "x": -4,
      "y": 130,
      "z": 7,
      "name": "Rock_CastIron"
    },
    {
      "x": -4,
      "y": 131,
      "z": 7,
      "name": "Rock_CastIron"
    },
    {
      "x": -4,
      "y": 132,
      "z": 7,
      "name": "Rock_CastIron"
    },
    {
      "x": -4,
      "y": 133,
      "z": 7,
      "name": "Rock_CastIron"
    },
    {
      "x": -4,
      "y": 134,
      "z": 7,
      "name": "Rock_CastIron"
    },
    {
      "x": -4,
      "y": 135,
      "z": 7,
      "name": "Rock_CastIron"
    },
    {
      "x": -4,
      "y": 136,
      "z": 7,
      "name": "Rock_CastIron"
    },
    {
      "x": -4,
      "y": 137,
      "z": 7,
      "name": "Rock_CastIron"
    },
    {
      "x": -4,
      "y": 138,
      "z": 7,
      "name": "Rock_CastIron"
    },
    {
      "x": -4,
      "y": 139,
      "z": 7,
      "name": "Rock_CastIron"
    },
    {
      "x": -4,
      "y": 140,
      "z": 7,
      "name": "Rock_CastIron"
    },
    {
      "x": -4,
      "y": 141,
      "z": 7,
      "name": "Rock_CastIron"
    },
    {
      "x": -4,
      "y": 142,
      "z": 7,
      "name": "Rock_CastIron"
    },
    {
      "x": -4,
      "y": 143,
      "z": 7,
      "name": "Rock_CastIron"
    },
    {
      "x": -4,
      "y": 144,
      "z": 7,
      "name": "Rock_CastIron"
    },
    {
      "x": -4,
      "y": 145,
      "z": 7,
      "name": "Rock_CastIron"
    },
    {
      "x": -4,
      "y": 146,
      "z": 7,
      "name": "Rock_CastIron"
    },
    {
      "x": -4,
      "y": 125,
      "z": 8,
      "name": "Empty"
    },
    {
      "x": -4,
      "y": 126,
      "z": 8,
      "name": "Empty"
    },
    {
      "x": -4,
      "y": 127,
      "z": 8,
      "name": "Empty"
    },
    {
      "x": -4,
      "y": 128,
      "z": 8,
      "name": "Empty"
    },
    {
      "x": -4,
      "y": 129,
      "z": 8,
      "name": "Empty"
    },
    {
      "x": -4,
      "y": 130,
      "z": 8,
      "name": "Empty"
    },
    {
      "x": -4,
      "y": 131,
      "z": 8,
      "name": "Empty"
    },
    {
      "x": -4,
      "y": 132,
      "z": 8,
      "name": "Rock_CastIron"
    },
    {
      "x": -4,
      "y": 133,
      "z": 8,
      "name": "Empty"
    },
    {
      "x": -4,
      "y": 134,
      "z": 8,
      "name": "Empty"
    },
    {
      "x": -4,
      "y": 135,
      "z": 8,
      "name": "Rock_CastIron"
    },
    {
      "x": -4,
      "y": 136,
      "z": 8,
      "name": "Rock_CastIron"
    },
    {
      "x": -4,
      "y": 137,
      "z": 8,
      "name": "Rock_CastIron"
    },
    {
      "x": -4,
      "y": 138,
      "z": 8,
      "name": "Rock_CastIron"
    },
    {
      "x": -4,
      "y": 139,
      "z": 8,
      "name": "Rock_CastIron"
    },
    {
      "x": -4,
      "y": 140,
      "z": 8,
      "name": "Rock_CastIron"
    },
    {
      "x": -4,
      "y": 141,
      "z": 8,
      "name": "Rock_CastIron"
    },
    {
      "x": -4,
      "y": 142,
      "z": 8,
      "name": "Rock_CastIron"
    },
    {
      "x": -4,
      "y": 143,
      "z": 8,
      "name": "Rock_CastIron"
    },
    {
      "x": -4,
      "y": 144,
      "z": 8,
      "name": "Rock_CastIron"
    },
    {
      "x": -4,
      "y": 125,
      "z": 9,
      "name": "Empty"
    },
    {
      "x": -4,
      "y": 126,
      "z": 9,
      "name": "Empty"
    },
    {
      "x": -4,
      "y": 127,
      "z": 9,
      "name": "Empty"
    },
    {
      "x": -4,
      "y": 128,
      "z": 9,
      "name": "Empty"
    },
    {
      "x": -4,
      "y": 129,
      "z": 9,
      "name": "Empty"
    },
    {
      "x": -4,
      "y": 130,
      "z": 9,
      "name": "Empty"
    },
    {
      "x": -4,
      "y": 131,
      "z": 9,
      "name": "Empty"
    },
    {
      "x": -4,
      "y": 132,
      "z": 9,
      "name": "Empty"
    },
    {
      "x": -4,
      "y": 133,
      "z": 9,
      "name": "Empty"
    },
    {
      "x": -4,
      "y": 134,
      "z": 9,
      "name": "Empty"
    },
    {
      "x": -4,
      "y": 135,
      "z": 9,
      "name": "Rock_CastIron"
    },
    {
      "x": -4,
      "y": 136,
      "z": 9,
      "name": "Rock_CastIron"
    },
    {
      "x": -4,
      "y": 137,
      "z": 9,
      "name": "Rock_CastIron"
    },
    {
      "x": -4,
      "y": 138,
      "z": 9,
      "name": "Empty"
    },
    {
      "x": -4,
      "y": 139,
      "z": 9,
      "name": "Empty"
    },
    {
      "x": -4,
      "y": 140,
      "z": 9,
      "name": "Empty"
    },
    {
      "x": -4,
      "y": 141,
      "z": 9,
      "name": "Empty"
    },
    {
      "x": -4,
      "y": 142,
      "z": 9,
      "name": "Empty"
    },
    {
      "x": -4,
      "y": 143,
      "z": 9,
      "name": "Empty"
    },
    {
      "x": -4,
      "y": 125,
      "z": 10,
      "name": "Empty"
    },
    {
      "x": -4,
      "y": 126,
      "z": 10,
      "name": "Empty"
    },
    {
      "x": -4,
      "y": 127,
      "z": 10,
      "name": "Empty"
    },
    {
      "x": -4,
      "y": 128,
      "z": 10,
      "name": "Empty"
    },
    {
      "x": -4,
      "y": 129,
      "z": 10,
      "name": "Empty"
    },
    {
      "x": -4,
      "y": 130,
      "z": 10,
      "name": "Empty"
    },
    {
      "x": -4,
      "y": 131,
      "z": 10,
      "name": "Empty"
    },
    {
      "x": -4,
      "y": 132,
      "z": 10,
      "name": "Empty"
    },
    {
      "x": -4,
      "y": 133,
      "z": 10,
      "name": "Empty"
    },
    {
      "x": -4,
      "y": 134,
      "z": 10,
      "name": "Empty"
    },
    {
      "x": -4,
      "y": 135,
      "z": 10,
      "name": "Rock_CastIron"
    },
    {
      "x": -4,
      "y": 136,
      "z": 10,
      "name": "Rock_CastIron"
    },
    {
      "x": -4,
      "y": 137,
      "z": 10,
      "name": "Rock_CastIron"
    },
    {
      "x": -4,
      "y": 138,
      "z": 10,
      "name": "Empty"
    },
    {
      "x": -4,
      "y": 139,
      "z": 10,
      "name": "Empty"
    },
    {
      "x": -4,
      "y": 140,
      "z": 10,
      "name": "Empty"
    },
    {
      "x": -4,
      "y": 141,
      "z": 10,
      "name": "Empty"
    },
    {
      "x": -4,
      "y": 142,
      "z": 10,
      "name": "Empty"
    },
    {
      "x": -4,
      "y": 143,
      "z": 10,
      "name": "Empty"
    },
    {
      "x": -4,
      "y": 125,
      "z": 11,
      "name": "Empty"
    },
    {
      "x": -4,
      "y": 126,
      "z": 11,
      "name": "Empty"
    },
    {
      "x": -4,
      "y": 127,
      "z": 11,
      "name": "Empty"
    },
    {
      "x": -4,
      "y": 128,
      "z": 11,
      "name": "Empty"
    },
    {
      "x": -4,
      "y": 129,
      "z": 11,
      "name": "Empty"
    },
    {
      "x": -4,
      "y": 130,
      "z": 11,
      "name": "Empty"
    },
    {
      "x": -4,
      "y": 131,
      "z": 11,
      "name": "Empty"
    },
    {
      "x": -4,
      "y": 132,
      "z": 11,
      "name": "Empty"
    },
    {
      "x": -4,
      "y": 133,
      "z": 11,
      "name": "Empty"
    },
    {
      "x": -4,
      "y": 134,
      "z": 11,
      "name": "Empty"
    },
    {
      "x": -4,
      "y": 135,
      "z": 11,
      "name": "Rock_CastIron"
    },
    {
      "x": -4,
      "y": 136,
      "z": 11,
      "name": "Rock_CastIron"
    },
    {
      "x": -4,
      "y": 137,
      "z": 11,
      "name": "Empty"
    },
    {
      "x": -4,
      "y": 138,
      "z": 11,
      "name": "Empty"
    },
    {
      "x": -4,
      "y": 139,
      "z": 11,
      "name": "Empty"
    },
    {
      "x": -4,
      "y": 140,
      "z": 11,
      "name": "Empty"
    },
    {
      "x": -4,
      "y": 141,
      "z": 11,
      "name": "Empty"
    },
    {
      "x": -4,
      "y": 142,
      "z": 11,
      "name": "Empty"
    },
    {
      "x": -4,
      "y": 143,
      "z": 11,
      "name": "Empty"
    },
    {
      "x": -4,
      "y": 135,
      "z": 12,
      "name": "Rock_CastIron"
    },
    {
      "x": -4,
      "y": 136,
      "z": 12,
      "name": "Rock_CastIron"
    },
    {
      "x": -3,
      "y": 124,
      "z": -8,
      "name": "Rock_CastIron_Brick_Smooth"
    },
    {
      "x": -3,
      "y": 125,
      "z": -8,
      "name": "Empty"
    },
    {
      "x": -3,
      "y": 126,
      "z": -8,
      "name": "Empty"
    },
    {
      "x": -3,
      "y": 127,
      "z": -8,
      "name": "Empty"
    },
    {
      "x": -3,
      "y": 128,
      "z": -8,
      "name": "Empty"
    },
    {
      "x": -3,
      "y": 129,
      "z": -8,
      "name": "Empty"
    },
    {
      "x": -3,
      "y": 130,
      "z": -8,
      "name": "Rock_CastIron"
    },
    {
      "x": -3,
      "y": 131,
      "z": -8,
      "name": "Empty"
    },
    {
      "x": -3,
      "y": 132,
      "z": -8,
      "name": "Empty"
    },
    {
      "x": -3,
      "y": 133,
      "z": -8,
      "name": "Empty"
    },
    {
      "x": -3,
      "y": 134,
      "z": -8,
      "name": "Empty"
    },
    {
      "x": -3,
      "y": 135,
      "z": -8,
      "name": "Empty"
    },
    {
      "x": -3,
      "y": 136,
      "z": -8,
      "name": "Empty"
    },
    {
      "x": -3,
      "y": 137,
      "z": -8,
      "name": "Empty"
    },
    {
      "x": -3,
      "y": 138,
      "z": -8,
      "name": "Empty"
    },
    {
      "x": -3,
      "y": 139,
      "z": -8,
      "name": "Empty"
    },
    {
      "x": -3,
      "y": 140,
      "z": -8,
      "name": "Empty"
    },
    {
      "x": -3,
      "y": 141,
      "z": -8,
      "name": "Empty"
    },
    {
      "x": -3,
      "y": 142,
      "z": -8,
      "name": "Empty"
    },
    {
      "x": -3,
      "y": 143,
      "z": -8,
      "name": "Empty"
    },
    {
      "x": -3,
      "y": 124,
      "z": -7,
      "name": "Soil_Dirt_Cold"
    },
    {
      "x": -3,
      "y": 125,
      "z": -7,
      "name": "Empty"
    },
    {
      "x": -3,
      "y": 126,
      "z": -7,
      "name": "Empty"
    },
    {
      "x": -3,
      "y": 127,
      "z": -7,
      "name": "Empty"
    },
    {
      "x": -3,
      "y": 128,
      "z": -7,
      "name": "Empty"
    },
    {
      "x": -3,
      "y": 129,
      "z": -7,
      "name": "Wood_Redwood_Beam",
      "rotation": 5
    },
    {
      "x": -3,
      "y": 130,
      "z": -7,
      "name": "Rock_CastIron"
    },
    {
      "x": -3,
      "y": 131,
      "z": -7,
      "name": "Empty"
    },
    {
      "x": -3,
      "y": 132,
      "z": -7,
      "name": "Empty"
    },
    {
      "x": -3,
      "y": 133,
      "z": -7,
      "name": "Empty"
    },
    {
      "x": -3,
      "y": 134,
      "z": -7,
      "name": "Empty"
    },
    {
      "x": -3,
      "y": 135,
      "z": -7,
      "name": "Empty"
    },
    {
      "x": -3,
      "y": 136,
      "z": -7,
      "name": "Empty"
    },
    {
      "x": -3,
      "y": 137,
      "z": -7,
      "name": "Empty"
    },
    {
      "x": -3,
      "y": 138,
      "z": -7,
      "name": "Empty"
    },
    {
      "x": -3,
      "y": 139,
      "z": -7,
      "name": "Empty"
    },
    {
      "x": -3,
      "y": 140,
      "z": -7,
      "name": "Empty"
    },
    {
      "x": -3,
      "y": 141,
      "z": -7,
      "name": "Empty"
    },
    {
      "x": -3,
      "y": 142,
      "z": -7,
      "name": "Empty"
    },
    {
      "x": -3,
      "y": 143,
      "z": -7,
      "name": "Empty"
    },
    {
      "x": -3,
      "y": 124,
      "z": -6,
      "name": "Soil_Dirt_Cold"
    },
    {
      "x": -3,
      "y": 125,
      "z": -6,
      "name": "Rock_Shale_Brick_Beam"
    },
    {
      "x": -3,
      "y": 126,
      "z": -6,
      "name": "Furniture_Human_Ruins_Torch",
      "rotation": 1
    },
    {
      "x": -3,
      "y": 127,
      "z": -6,
      "name": "Empty"
    },
    {
      "x": -3,
      "y": 128,
      "z": -6,
      "name": "Empty"
    },
    {
      "x": -3,
      "y": 129,
      "z": -6,
      "name": "Empty"
    },
    {
      "x": -3,
      "y": 130,
      "z": -6,
      "name": "Rock_Shale_Brick_Stairs",
      "rotation": 11
    },
    {
      "x": -3,
      "y": 131,
      "z": -6,
      "name": "Rock_CastIron"
    },
    {
      "x": -3,
      "y": 132,
      "z": -6,
      "name": "Empty"
    },
    {
      "x": -3,
      "y": 133,
      "z": -6,
      "name": "Empty"
    },
    {
      "x": -3,
      "y": 134,
      "z": -6,
      "name": "Empty"
    },
    {
      "x": -3,
      "y": 135,
      "z": -6,
      "name": "Empty"
    },
    {
      "x": -3,
      "y": 136,
      "z": -6,
      "name": "Empty"
    },
    {
      "x": -3,
      "y": 137,
      "z": -6,
      "name": "Empty"
    },
    {
      "x": -3,
      "y": 138,
      "z": -6,
      "name": "Empty"
    },
    {
      "x": -3,
      "y": 139,
      "z": -6,
      "name": "Empty"
    },
    {
      "x": -3,
      "y": 140,
      "z": -6,
      "name": "Empty"
    },
    {
      "x": -3,
      "y": 141,
      "z": -6,
      "name": "Empty"
    },
    {
      "x": -3,
      "y": 142,
      "z": -6,
      "name": "Empty"
    },
    {
      "x": -3,
      "y": 143,
      "z": -6,
      "name": "Empty"
    },
    {
      "x": -3,
      "y": 124,
      "z": -5,
      "name": "Soil_Dirt_Cold"
    },
    {
      "x": -3,
      "y": 125,
      "z": -5,
      "name": "Soil_Dirt_Cold"
    },
    {
      "x": -3,
      "y": 126,
      "z": -5,
      "name": "Empty"
    },
    {
      "x": -3,
      "y": 127,
      "z": -5,
      "name": "Empty"
    },
    {
      "x": -3,
      "y": 128,
      "z": -5,
      "name": "Empty"
    },
    {
      "x": -3,
      "y": 129,
      "z": -5,
      "name": "Empty"
    },
    {
      "x": -3,
      "y": 130,
      "z": -5,
      "name": "Empty"
    },
    {
      "x": -3,
      "y": 131,
      "z": -5,
      "name": "Empty"
    },
    {
      "x": -3,
      "y": 132,
      "z": -5,
      "name": "Rock_CastIron"
    },
    {
      "x": -3,
      "y": 133,
      "z": -5,
      "name": "Empty"
    },
    {
      "x": -3,
      "y": 134,
      "z": -5,
      "name": "Empty"
    },
    {
      "x": -3,
      "y": 135,
      "z": -5,
      "name": "Empty"
    },
    {
      "x": -3,
      "y": 136,
      "z": -5,
      "name": "Empty"
    },
    {
      "x": -3,
      "y": 137,
      "z": -5,
      "name": "Empty"
    },
    {
      "x": -3,
      "y": 138,
      "z": -5,
      "name": "Empty"
    },
    {
      "x": -3,
      "y": 139,
      "z": -5,
      "name": "Empty"
    },
    {
      "x": -3,
      "y": 140,
      "z": -5,
      "name": "Empty"
    },
    {
      "x": -3,
      "y": 141,
      "z": -5,
      "name": "Rock_CastIron"
    },
    {
      "x": -3,
      "y": 142,
      "z": -5,
      "name": "Rock_CastIron"
    },
    {
      "x": -3,
      "y": 143,
      "z": -5,
      "name": "Rock_CastIron"
    },
    {
      "x": -3,
      "y": 147,
      "z": -5,
      "name": "Rock_CastIron"
    },
    {
      "x": -3,
      "y": 148,
      "z": -5,
      "name": "Rock_CastIron"
    },
    {
      "x": -3,
      "y": 125,
      "z": -4,
      "name": "Soil_Dirt_Cold"
    },
    {
      "x": -3,
      "y": 126,
      "z": -4,
      "name": "Empty"
    },
    {
      "x": -3,
      "y": 127,
      "z": -4,
      "name": "Empty"
    },
    {
      "x": -3,
      "y": 128,
      "z": -4,
      "name": "Empty"
    },
    {
      "x": -3,
      "y": 129,
      "z": -4,
      "name": "Empty"
    },
    {
      "x": -3,
      "y": 130,
      "z": -4,
      "name": "Empty"
    },
    {
      "x": -3,
      "y": 131,
      "z": -4,
      "name": "Empty"
    },
    {
      "x": -3,
      "y": 132,
      "z": -4,
      "name": "Plant_Bush_Dead_Hanging"
    },
    {
      "x": -3,
      "y": 133,
      "z": -4,
      "name": "Rock_CastIron"
    },
    {
      "x": -3,
      "y": 134,
      "z": -4,
      "name": "Rock_CastIron_Brick"
    },
    {
      "x": -3,
      "y": 135,
      "z": -4,
      "name": "Rock_CastIron_Brick"
    },
    {
      "x": -3,
      "y": 136,
      "z": -4,
      "name": "Deco_Bone_Pile"
    },
    {
      "x": -3,
      "y": 137,
      "z": -4,
      "name": "Rock_CastIron_Brick"
    },
    {
      "x": -3,
      "y": 138,
      "z": -4,
      "name": "Deco_Bone_Skulls"
    },
    {
      "x": -3,
      "y": 139,
      "z": -4,
      "name": "Rock_CastIron_Brick"
    },
    {
      "x": -3,
      "y": 140,
      "z": -4,
      "name": "Deco_Bone_Pile"
    },
    {
      "x": -3,
      "y": 141,
      "z": -4,
      "name": "Rock_CastIron"
    },
    {
      "x": -3,
      "y": 142,
      "z": -4,
      "name": "Rock_CastIron"
    },
    {
      "x": -3,
      "y": 143,
      "z": -4,
      "name": "Rock_CastIron"
    },
    {
      "x": -3,
      "y": 144,
      "z": -4,
      "name": "Rock_CastIron"
    },
    {
      "x": -3,
      "y": 145,
      "z": -4,
      "name": "Rock_CastIron"
    },
    {
      "x": -3,
      "y": 146,
      "z": -4,
      "name": "Rock_CastIron"
    },
    {
      "x": -3,
      "y": 147,
      "z": -4,
      "name": "Rock_CastIron"
    },
    {
      "x": -3,
      "y": 148,
      "z": -4,
      "name": "Rock_CastIron"
    },
    {
      "x": -3,
      "y": 125,
      "z": -3,
      "name": "Empty"
    },
    {
      "x": -3,
      "y": 126,
      "z": -3,
      "name": "Rock_Shale_Brick_Stairs",
      "rotation": 2
    },
    {
      "x": -3,
      "y": 127,
      "z": -3,
      "name": "Empty"
    },
    {
      "x": -3,
      "y": 128,
      "z": -3,
      "name": "Empty"
    },
    {
      "x": -3,
      "y": 129,
      "z": -3,
      "name": "Empty"
    },
    {
      "x": -3,
      "y": 130,
      "z": -3,
      "name": "Empty"
    },
    {
      "x": -3,
      "y": 131,
      "z": -3,
      "name": "Empty"
    },
    {
      "x": -3,
      "y": 132,
      "z": -3,
      "name": "Empty"
    },
    {
      "x": -3,
      "y": 133,
      "z": -3,
      "name": "Empty"
    },
    {
      "x": -3,
      "y": 134,
      "z": -3,
      "name": "Rock_CastIron"
    },
    {
      "x": -3,
      "y": 135,
      "z": -3,
      "name": "Rock_CastIron_Brick"
    },
    {
      "x": -3,
      "y": 136,
      "z": -3,
      "name": "Rock_CastIron_Cobble"
    },
    {
      "x": -3,
      "y": 137,
      "z": -3,
      "name": "Rock_CastIron_Cobble"
    },
    {
      "x": -3,
      "y": 138,
      "z": -3,
      "name": "Rock_CastIron_Cobble"
    },
    {
      "x": -3,
      "y": 139,
      "z": -3,
      "name": "Rock_CastIron_Cobble"
    },
    {
      "x": -3,
      "y": 140,
      "z": -3,
      "name": "Rock_CastIron_Cobble"
    },
    {
      "x": -3,
      "y": 141,
      "z": -3,
      "name": "Rock_CastIron_Brick"
    },
    {
      "x": -3,
      "y": 142,
      "z": -3,
      "name": "Rock_CastIron"
    },
    {
      "x": -3,
      "y": 143,
      "z": -3,
      "name": "Rock_CastIron"
    },
    {
      "x": -3,
      "y": 144,
      "z": -3,
      "name": "Rock_CastIron"
    },
    {
      "x": -3,
      "y": 145,
      "z": -3,
      "name": "Rock_CastIron"
    },
    {
      "x": -3,
      "y": 146,
      "z": -3,
      "name": "Rock_CastIron"
    },
    {
      "x": -3,
      "y": 147,
      "z": -3,
      "name": "Rock_CastIron"
    },
    {
      "x": -3,
      "y": 125,
      "z": -2,
      "name": "Empty"
    },
    {
      "x": -3,
      "y": 126,
      "z": -2,
      "name": "Empty"
    },
    {
      "x": -3,
      "y": 127,
      "z": -2,
      "name": "Rock_Shale_Brick_Stairs",
      "rotation": 2
    },
    {
      "x": -3,
      "y": 128,
      "z": -2,
      "name": "Empty"
    },
    {
      "x": -3,
      "y": 129,
      "z": -2,
      "name": "Empty"
    },
    {
      "x": -3,
      "y": 130,
      "z": -2,
      "name": "Empty"
    },
    {
      "x": -3,
      "y": 131,
      "z": -2,
      "name": "Empty"
    },
    {
      "x": -3,
      "y": 132,
      "z": -2,
      "name": "Empty"
    },
    {
      "x": -3,
      "y": 133,
      "z": -2,
      "name": "Empty"
    },
    {
      "x": -3,
      "y": 134,
      "z": -2,
      "name": "Rock_Shale_Brick_Stairs",
      "rotation": 11
    },
    {
      "x": -3,
      "y": 135,
      "z": -2,
      "name": "Rock_CastIron"
    },
    {
      "x": -3,
      "y": 136,
      "z": -2,
      "name": "Rock_CastIron_Brick"
    },
    {
      "x": -3,
      "y": 137,
      "z": -2,
      "name": "Rock_CastIron_Brick"
    },
    {
      "x": -3,
      "y": 138,
      "z": -2,
      "name": "Rock_CastIron_Brick"
    },
    {
      "x": -3,
      "y": 139,
      "z": -2,
      "name": "Rock_CastIron_Brick"
    },
    {
      "x": -3,
      "y": 140,
      "z": -2,
      "name": "Rock_CastIron_Brick"
    },
    {
      "x": -3,
      "y": 141,
      "z": -2,
      "name": "Rock_CastIron_Brick"
    },
    {
      "x": -3,
      "y": 142,
      "z": -2,
      "name": "Rock_CastIron"
    },
    {
      "x": -3,
      "y": 143,
      "z": -2,
      "name": "Rock_CastIron"
    },
    {
      "x": -3,
      "y": 144,
      "z": -2,
      "name": "Rock_CastIron"
    },
    {
      "x": -3,
      "y": 145,
      "z": -2,
      "name": "Rock_CastIron"
    },
    {
      "x": -3,
      "y": 146,
      "z": -2,
      "name": "Rock_CastIron"
    },
    {
      "x": -3,
      "y": 147,
      "z": -2,
      "name": "Rock_CastIron"
    },
    {
      "x": -3,
      "y": 125,
      "z": -1,
      "name": "Empty"
    },
    {
      "x": -3,
      "y": 126,
      "z": -1,
      "name": "Empty"
    },
    {
      "x": -3,
      "y": 127,
      "z": -1,
      "name": "Empty"
    },
    {
      "x": -3,
      "y": 128,
      "z": -1,
      "name": "Soil_Dirt_Cold"
    },
    {
      "x": -3,
      "y": 129,
      "z": -1,
      "name": "Empty"
    },
    {
      "x": -3,
      "y": 130,
      "z": -1,
      "name": "Empty"
    },
    {
      "x": -3,
      "y": 131,
      "z": -1,
      "name": "Empty"
    },
    {
      "x": -3,
      "y": 132,
      "z": -1,
      "name": "Empty"
    },
    {
      "x": -3,
      "y": 133,
      "z": -1,
      "name": "Empty"
    },
    {
      "x": -3,
      "y": 134,
      "z": -1,
      "name": "Empty"
    },
    {
      "x": -3,
      "y": 135,
      "z": -1,
      "name": "Empty"
    },
    {
      "x": -3,
      "y": 136,
      "z": -1,
      "name": "Rock_CastIron"
    },
    {
      "x": -3,
      "y": 137,
      "z": -1,
      "name": "Rock_CastIron_Brick"
    },
    {
      "x": -3,
      "y": 138,
      "z": -1,
      "name": "Rock_CastIron_Brick"
    },
    {
      "x": -3,
      "y": 139,
      "z": -1,
      "name": "Rock_CastIron_Brick"
    },
    {
      "x": -3,
      "y": 140,
      "z": -1,
      "name": "Rock_CastIron_Brick"
    },
    {
      "x": -3,
      "y": 141,
      "z": -1,
      "name": "Rock_CastIron_Brick"
    },
    {
      "x": -3,
      "y": 142,
      "z": -1,
      "name": "Rock_CastIron"
    },
    {
      "x": -3,
      "y": 143,
      "z": -1,
      "name": "Rock_CastIron"
    },
    {
      "x": -3,
      "y": 144,
      "z": -1,
      "name": "Rock_CastIron"
    },
    {
      "x": -3,
      "y": 145,
      "z": -1,
      "name": "Rock_CastIron"
    },
    {
      "x": -3,
      "y": 146,
      "z": -1,
      "name": "Rock_CastIron"
    },
    {
      "x": -3,
      "y": 147,
      "z": -1,
      "name": "Rock_CastIron"
    },
    {
      "x": -3,
      "y": 148,
      "z": -1,
      "name": "Rock_Shale_Brick_Stairs",
      "rotation": 3
    },
    {
      "x": -3,
      "y": 125,
      "z": 0,
      "name": "Empty"
    },
    {
      "x": -3,
      "y": 126,
      "z": 0,
      "name": "Empty"
    },
    {
      "x": -3,
      "y": 127,
      "z": 0,
      "name": "Empty"
    },
    {
      "x": -3,
      "y": 128,
      "z": 0,
      "name": "Empty"
    },
    {
      "x": -3,
      "y": 129,
      "z": 0,
      "name": "Soil_Dirt_Cold"
    },
    {
      "x": -3,
      "y": 130,
      "z": 0,
      "name": "Plant_Bush_Dead_Twisted"
    },
    {
      "x": -3,
      "y": 131,
      "z": 0,
      "name": "Empty"
    },
    {
      "x": -3,
      "y": 132,
      "z": 0,
      "name": "Empty"
    },
    {
      "x": -3,
      "y": 133,
      "z": 0,
      "name": "Empty"
    },
    {
      "x": -3,
      "y": 134,
      "z": 0,
      "name": "Empty"
    },
    {
      "x": -3,
      "y": 135,
      "z": 0,
      "name": "Empty"
    },
    {
      "x": -3,
      "y": 136,
      "z": 0,
      "name": "Empty"
    },
    {
      "x": -3,
      "y": 137,
      "z": 0,
      "name": "Rock_CastIron"
    },
    {
      "x": -3,
      "y": 138,
      "z": 0,
      "name": "Rock_CastIron_Brick"
    },
    {
      "x": -3,
      "y": 139,
      "z": 0,
      "name": "Rock_CastIron_Brick"
    },
    {
      "x": -3,
      "y": 140,
      "z": 0,
      "name": "Rock_CastIron_Brick"
    },
    {
      "x": -3,
      "y": 141,
      "z": 0,
      "name": "Rock_CastIron_Brick"
    },
    {
      "x": -3,
      "y": 142,
      "z": 0,
      "name": "Rock_CastIron"
    },
    {
      "x": -3,
      "y": 143,
      "z": 0,
      "name": "Rock_CastIron"
    },
    {
      "x": -3,
      "y": 144,
      "z": 0,
      "name": "Rock_CastIron"
    },
    {
      "x": -3,
      "y": 145,
      "z": 0,
      "name": "Rock_CastIron"
    },
    {
      "x": -3,
      "y": 146,
      "z": 0,
      "name": "Rock_CastIron"
    },
    {
      "x": -3,
      "y": 147,
      "z": 0,
      "name": "Rock_CastIron"
    },
    {
      "x": -3,
      "y": 125,
      "z": 1,
      "name": "Empty"
    },
    {
      "x": -3,
      "y": 126,
      "z": 1,
      "name": "Empty"
    },
    {
      "x": -3,
      "y": 127,
      "z": 1,
      "name": "Empty"
    },
    {
      "x": -3,
      "y": 128,
      "z": 1,
      "name": "Empty"
    },
    {
      "x": -3,
      "y": 129,
      "z": 1,
      "name": "Rock_CastIron_Brick"
    },
    {
      "x": -3,
      "y": 130,
      "z": 1,
      "name": "Rock_Basalt"
    },
    {
      "x": -3,
      "y": 131,
      "z": 1,
      "name": "Rubble_Basalt"
    },
    {
      "x": -3,
      "y": 132,
      "z": 1,
