{
  "version": 8,
  "blockIdVersion": 11,
  "anchorX": 0,
  "anchorY": 0,
  "anchorZ": 12,
  "blocks": [
    {
      "x": -12,
      "y": 0,
      "z": -12,
      "name": "Rock_CastIron"
    },
    {
      "x": -12,
      "y": 1,
      "z": -12,
      "name": "Rock_CastIron"
    },
    {
      "x": -12,
      "y": 2,
      "z": -12,
      "name": "Rock_CastIron"
    },
    {
      "x": -12,
      "y": 3,
      "z": -12,
      "name": "Rock_CastIron"
    },
    {
      "x": -12,
      "y": 4,
      "z": -12,
      "name": "Rock_CastIron"
    },
    {
      "x": -12,
      "y": 5,
      "z": -12,
      "name": "Rock_CastIron"
    },
    {
      "x": -12,
      "y": 6,
      "z": -12,
      "name": "Rock_CastIron"
    },
    {
      "x": -12,
      "y": 7,
      "z": -12,
      "name": "Rock_CastIron"
    },
    {
      "x": -12,
      "y": 8,
      "z": -12,
      "name": "Rock_CastIron"
    },
    {
      "x": -12,
      "y": 9,
      "z": -12,
      "name": "Rock_CastIron"
    },
    {
      "x": -12,
      "y": 0,
      "z": -11,
      "name": "Rock_CastIron"
    },
    {
      "x": -12,
      "y": 1,
      "z": -11,
      "name": "Rock_CastIron"
    },
    {
      "x": -12,
      "y": 2,
      "z": -11,
      "name": "Rock_CastIron"
    },
    {
      "x": -12,
      "y": 3,
      "z": -11,
      "name": "Rock_CastIron"
    },
    {
      "x": -12,
      "y": 4,
      "z": -11,
      "name": "Rock_CastIron"
    },
    {
      "x": -12,
      "y": 5,
      "z": -11,
      "name": "Rock_CastIron"
    },
    {
      "x": -12,
      "y": 6,
      "z": -11,
      "name": "Rock_CastIron"
    },
    {
      "x": -12,
      "y": 7,
      "z": -11,
      "name": "Rock_CastIron"
    },
    {
      "x": -12,
      "y": 8,
      "z": -11,
      "name": "Rock_CastIron"
    },
    {
      "x": -12,
      "y": 9,
      "z": -11,
      "name": "Rock_CastIron"
    },
    {
      "x": -12,
      "y": 0,
      "z": -10,
      "name": "Rock_CastIron"
    },
    {
      "x": -12,
      "y": 1,
      "z": -10,
      "name": "Rock_CastIron"
    },
    {
      "x": -12,
      "y": 2,
      "z": -10,
      "name": "Rock_CastIron"
    },
    {
      "x": -12,
      "y": 3,
      "z": -10,
      "name": "Rock_CastIron"
    },
    {
      "x": -12,
      "y": 4,
      "z": -10,
      "name": "Rock_CastIron_Brick"
    },
    {
      "x": -12,
      "y": 5,
      "z": -10,
      "name": "Rock_CastIron_Brick"
    },
    {
      "x": -12,
      "y": 6,
      "z": -10,
      "name": "Rock_CastIron"
    },
    {
      "x": -12,
      "y": 7,
      "z": -10,
      "name": "Rock_CastIron"
    },
    {
      "x": -12,
      "y": 8,
      "z": -10,
      "name": "Rock_CastIron"
    },
    {
      "x": -12,
      "y": 9,
      "z": -10,
      "name": "Rock_CastIron"
    },
    {
      "x": -12,
      "y": 0,
      "z": -9,
      "name": "Rock_CastIron"
    },
    {
      "x": -12,
      "y": 1,
      "z": -9,
      "name": "Rock_CastIron"
    },
    {
      "x": -12,
      "y": 2,
      "z": -9,
      "name": "Rock_CastIron"
    },
    {
      "x": -12,
      "y": 3,
      "z": -9,
      "name": "Rock_CastIron"
    },
    {
      "x": -12,
      "y": 4,
      "z": -9,
      "name": "Rock_CastIron_Brick"
    },
    {
      "x": -12,
      "y": 5,
      "z": -9,
      "name": "Rock_CastIron_Brick"
    },
    {
      "x": -12,
      "y": 6,
      "z": -9,
      "name": "Rock_CastIron"
    },
    {
      "x": -12,
      "y": 7,
      "z": -9,
      "name": "Rock_CastIron"
    },
    {
      "x": -12,
      "y": 8,
      "z": -9,
      "name": "Rock_CastIron"
    },
    {
      "x": -12,
      "y": 9,
      "z": -9,
      "name": "Rock_CastIron"
    },
    {
      "x": -12,
      "y": 0,
      "z": -8,
      "name": "Rock_CastIron"
    },
    {
      "x": -12,
      "y": 1,
      "z": -8,
      "name": "Rock_CastIron"
    },
    {
      "x": -12,
      "y": 2,
      "z": -8,
      "name": "Rock_CastIron"
    },
    {
      "x": -12,
      "y": 3,
      "z": -8,
      "name": "Rock_CastIron"
    },
    {
      "x": -12,
      "y": 4,
      "z": -8,
      "name": "Rock_CastIron_Brick"
    },
    {
      "x": -12,
      "y": 5,
      "z": -8,
      "name": "Rock_CastIron_Brick"
    },
    {
      "x": -12,
      "y": 6,
      "z": -8,
      "name": "Rock_CastIron"
    },
    {
      "x": -12,
      "y": 7,
      "z": -8,
      "name": "Rock_CastIron"
    },
    {
      "x": -12,
      "y": 8,
      "z": -8,
      "name": "Rock_CastIron"
    },
    {
      "x": -12,
      "y": 9,
      "z": -8,
      "name": "Rock_CastIron"
    },
    {
      "x": -12,
      "y": 0,
      "z": -7,
      "name": "Rock_CastIron"
    },
    {
      "x": -12,
      "y": 1,
      "z": -7,
      "name": "Rock_CastIron"
    },
    {
      "x": -12,
      "y": 2,
      "z": -7,
      "name": "Rock_CastIron"
    },
    {
      "x": -12,
      "y": 3,
      "z": -7,
      "name": "Rock_CastIron"
    },
    {
      "x": -12,
      "y": 4,
      "z": -7,
      "name": "Rock_CastIron"
    },
    {
      "x": -12,
      "y": 5,
      "z": -7,
      "name": "Rock_CastIron"
    },
    {
      "x": -12,
      "y": 6,
      "z": -7,
      "name": "Rock_CastIron"
    },
    {
      "x": -12,
      "y": 7,
      "z": -7,
      "name": "Rock_CastIron"
    },
    {
      "x": -12,
      "y": 8,
      "z": -7,
      "name": "Rock_CastIron"
    },
    {
      "x": -12,
      "y": 9,
      "z": -7,
      "name": "Rock_CastIron"
    },
    {
      "x": -12,
      "y": 0,
      "z": -6,
      "name": "Rock_CastIron"
    },
    {
      "x": -12,
      "y": 1,
      "z": -6,
      "name": "Rock_CastIron"
    },
    {
      "x": -12,
      "y": 2,
      "z": -6,
      "name": "Rock_CastIron"
    },
    {
      "x": -12,
      "y": 3,
      "z": -6,
      "name": "Rock_Basalt_Brick"
    },
    {
      "x": -12,
      "y": 4,
      "z": -6,
      "name": "Rock_Basalt_Brick"
    },
    {
      "x": -12,
      "y": 5,
      "z": -6,
      "name": "Rock_Basalt_Brick"
    },
    {
      "x": -12,
      "y": 6,
      "z": -6,
      "name": "Rock_Basalt_Brick"
    },
    {
      "x": -12,
      "y": 7,
      "z": -6,
      "name": "Rock_Basalt_Brick"
    },
    {
      "x": -12,
      "y": 8,
      "z": -6,
      "name": "Rock_Basalt_Brick"
    },
    {
      "x": -12,
      "y": 9,
      "z": -6,
      "name": "Rock_CastIron"
    },
    {
      "x": -12,
      "y": 0,
      "z": -5,
      "name": "Rock_CastIron"
    },
    {
      "x": -12,
      "y": 1,
      "z": -5,
      "name": "Rock_CastIron"
    },
    {
      "x": -12,
      "y": 2,
      "z": -5,
      "name": "Rock_CastIron"
    },
    {
      "x": -12,
      "y": 3,
      "z": -5,
      "name": "Rock_Basalt_Brick"
    },
    {
      "x": -12,
      "y": 4,
      "z": -5,
      "name": "Rock_Basalt_Brick"
    },
    {
      "x": -12,
      "y": 5,
      "z": -5,
      "name": "Rock_Basalt_Brick"
    },
    {
      "x": -12,
      "y": 6,
      "z": -5,
      "name": "Rock_Basalt_Brick"
    },
    {
      "x": -12,
      "y": 7,
      "z": -5,
      "name": "Rock_Basalt_Brick"
    },
    {
      "x": -12,
      "y": 8,
      "z": -5,
      "name": "Rock_Basalt_Brick"
    },
    {
      "x": -12,
      "y": 9,
      "z": -5,
      "name": "Rock_CastIron"
    },
    {
      "x": -12,
      "y": 0,
      "z": -4,
      "name": "Rock_CastIron"
    },
    {
      "x": -12,
      "y": 1,
      "z": -4,
      "name": "Rock_CastIron"
    },
    {
      "x": -12,
      "y": 2,
      "z": -4,
      "name": "Rock_CastIron"
    },
    {
      "x": -12,
      "y": 3,
      "z": -4,
      "name": "Rock_Basalt_Brick"
    },
    {
      "x": -12,
      "y": 4,
      "z": -4,
      "name": "Rock_Basalt_Brick"
    },
    {
      "x": -12,
      "y": 5,
      "z": -4,
      "name": "Rock_Basalt_Brick"
    },
    {
      "x": -12,
      "y": 6,
      "z": -4,
      "name": "Rock_Basalt_Brick"
    },
    {
      "x": -12,
      "y": 7,
      "z": -4,
      "name": "Rock_Basalt_Brick"
    },
    {
      "x": -12,
      "y": 8,
      "z": -4,
      "name": "Rock_Basalt_Brick"
    },
    {
      "x": -12,
      "y": 9,
      "z": -4,
      "name": "Rock_CastIron"
    },
    {
      "x": -12,
      "y": 0,
      "z": -3,
      "name": "Rock_CastIron"
    },
    {
      "x": -12,
      "y": 1,
      "z": -3,
      "name": "Rock_CastIron"
    },
    {
      "x": -12,
      "y": 2,
      "z": -3,
      "name": "Rock_CastIron"
    },
    {
      "x": -12,
      "y": 3,
      "z": -3,
      "name": "Rock_Basalt_Brick"
    },
    {
      "x": -12,
      "y": 4,
      "z": -3,
      "name": "Rock_Basalt_Brick"
    },
    {
      "x": -12,
      "y": 5,
      "z": -3,
      "name": "Rock_Basalt_Brick"
    },
    {
      "x": -12,
      "y": 6,
      "z": -3,
      "name": "Rock_Basalt_Brick"
    },
    {
      "x": -12,
      "y": 7,
      "z": -3,
      "name": "Rock_Basalt_Brick"
    },
    {
      "x": -12,
      "y": 8,
      "z": -3,
      "name": "Rock_Basalt_Brick"
    },
    {
      "x": -12,
      "y": 9,
      "z": -3,
      "name": "Rock_CastIron"
    },
    {
      "x": -12,
      "y": 0,
      "z": -2,
      "name": "Rock_CastIron"
    },
    {
      "x": -12,
      "y": 1,
      "z": -2,
      "name": "Rock_CastIron"
    },
    {
      "x": -12,
      "y": 2,
      "z": -2,
      "name": "Rock_CastIron"
    },
    {
      "x": -12,
      "y": 3,
      "z": -2,
      "name": "Rock_Basalt_Brick"
    },
    {
      "x": -12,
      "y": 4,
      "z": -2,
      "name": "Rock_Basalt_Brick"
    },
    {
      "x": -12,
      "y": 5,
      "z": -2,
      "name": "Rock_Basalt_Brick"
    },
    {
      "x": -12,
      "y": 6,
      "z": -2,
      "name": "Rock_Basalt_Brick"
    },
    {
      "x": -12,
      "y": 7,
      "z": -2,
      "name": "Rock_Basalt_Brick"
    },
    {
      "x": -12,
      "y": 8,
      "z": -2,
      "name": "Rock_Basalt_Brick"
    },
    {
      "x": -12,
      "y": 9,
      "z": -2,
      "name": "Rock_CastIron"
    },
    {
      "x": -12,
      "y": 0,
      "z": -1,
      "name": "Rock_CastIron"
    },
    {
      "x": -12,
      "y": 1,
      "z": -1,
      "name": "Rock_CastIron"
    },
    {
      "x": -12,
      "y": 2,
      "z": -1,
      "name": "Rock_CastIron"
    },
    {
      "x": -12,
      "y": 3,
      "z": -1,
      "name": "Rock_CastIron"
    },
    {
      "x": -12,
      "y": 4,
      "z": -1,
      "name": "Rock_CastIron"
    },
    {
      "x": -12,
      "y": 5,
      "z": -1,
      "name": "Rock_CastIron"
    },
    {
      "x": -12,
      "y": 6,
      "z": -1,
      "name": "Rock_CastIron"
    },
    {
      "x": -12,
      "y": 7,
      "z": -1,
      "name": "Rock_CastIron"
    },
    {
      "x": -12,
      "y": 8,
      "z": -1,
      "name": "Rock_CastIron"
    },
    {
      "x": -12,
      "y": 9,
      "z": -1,
      "name": "Rock_CastIron"
    },
    {
      "x": -12,
      "y": 0,
      "z": 0,
      "name": "Rock_CastIron"
    },
    {
      "x": -12,
      "y": 1,
      "z": 0,
      "name": "Rock_CastIron"
    },
    {
      "x": -12,
      "y": 2,
      "z": 0,
      "name": "Rock_CastIron"
    },
    {
      "x": -12,
      "y": 3,
      "z": 0,
      "name": "Rock_Basalt_Brick"
    },
    {
      "x": -12,
      "y": 4,
      "z": 0,
      "name": "Rock_Basalt_Brick"
    },
    {
      "x": -12,
      "y": 5,
      "z": 0,
      "name": "Rock_Basalt_Brick"
    },
    {
      "x": -12,
      "y": 6,
      "z": 0,
      "name": "Rock_Basalt_Brick"
    },
    {
      "x": -12,
      "y": 7,
      "z": 0,
      "name": "Rock_Basalt_Brick"
    },
    {
      "x": -12,
      "y": 8,
      "z": 0,
      "name": "Rock_Basalt_Brick"
    },
    {
      "x": -12,
      "y": 9,
      "z": 0,
      "name": "Rock_CastIron"
    },
    {
      "x": -12,
      "y": 0,
      "z": 1,
      "name": "Rock_CastIron"
    },
    {
      "x": -12,
      "y": 1,
      "z": 1,
      "name": "Rock_CastIron"
    },
    {
      "x": -12,
      "y": 2,
      "z": 1,
      "name": "Rock_CastIron"
    },
    {
      "x": -12,
      "y": 3,
      "z": 1,
      "name": "Rock_Basalt_Brick"
    },
    {
      "x": -12,
      "y": 4,
      "z": 1,
      "name": "Rock_Basalt_Brick"
    },
    {
      "x": -12,
      "y": 5,
      "z": 1,
      "name": "Rock_Basalt_Brick"
    },
    {
      "x": -12,
      "y": 6,
      "z": 1,
      "name": "Rock_Basalt_Brick"
    },
    {
      "x": -12,
      "y": 7,
      "z": 1,
      "name": "Rock_Basalt_Brick"
    },
    {
      "x": -12,
      "y": 8,
      "z": 1,
      "name": "Rock_Basalt_Brick"
    },
    {
      "x": -12,
      "y": 9,
      "z": 1,
      "name": "Rock_CastIron"
    },
    {
      "x": -12,
      "y": 0,
      "z": 2,
      "name": "Rock_CastIron"
    },
    {
      "x": -12,
      "y": 1,
      "z": 2,
      "name": "Rock_CastIron"
    },
    {
      "x": -12,
      "y": 2,
      "z": 2,
      "name": "Rock_CastIron"
    },
    {
      "x": -12,
      "y": 3,
      "z": 2,
      "name": "Rock_Basalt_Brick"
    },
    {
      "x": -12,
      "y": 4,
      "z": 2,
      "name": "Rock_Basalt_Brick"
    },
    {
      "x": -12,
      "y": 5,
      "z": 2,
      "name": "Rock_Basalt_Brick"
    },
    {
      "x": -12,
      "y": 6,
      "z": 2,
      "name": "Rock_Basalt_Brick"
    },
    {
      "x": -12,
      "y": 7,
      "z": 2,
      "name": "Rock_Basalt_Brick"
    },
    {
      "x": -12,
      "y": 8,
      "z": 2,
      "name": "Rock_Basalt_Brick"
    },
    {
      "x": -12,
      "y": 9,
      "z": 2,
      "name": "Rock_CastIron"
    },
    {
      "x": -12,
      "y": 0,
      "z": 3,
      "name": "Rock_CastIron"
    },
    {
      "x": -12,
      "y": 1,
      "z": 3,
      "name": "Rock_CastIron"
    },
    {
      "x": -12,
      "y": 2,
      "z": 3,
      "name": "Rock_CastIron"
    },
    {
      "x": -12,
      "y": 3,
      "z": 3,
      "name": "Rock_Basalt_Brick"
    },
    {
      "x": -12,
      "y": 4,
      "z": 3,
      "name": "Rock_Basalt_Brick"
    },
    {
      "x": -12,
      "y": 5,
      "z": 3,
      "name": "Rock_Basalt_Brick"
    },
    {
      "x": -12,
      "y": 6,
      "z": 3,
      "name": "Rock_Basalt_Brick"
    },
    {
      "x": -12,
      "y": 7,
      "z": 3,
      "name": "Rock_Basalt_Brick"
    },
    {
      "x": -12,
      "y": 8,
      "z": 3,
      "name": "Rock_Basalt_Brick"
    },
    {
      "x": -12,
      "y": 9,
      "z": 3,
      "name": "Rock_CastIron"
    },
    {
      "x": -12,
      "y": 0,
      "z": 4,
      "name": "Rock_CastIron"
    },
    {
      "x": -12,
      "y": 1,
      "z": 4,
      "name": "Rock_CastIron"
    },
    {
      "x": -12,
      "y": 2,
      "z": 4,
      "name": "Rock_CastIron"
    },
    {
      "x": -12,
      "y": 3,
      "z": 4,
      "name": "Rock_Basalt_Brick"
    },
    {
      "x": -12,
      "y": 4,
      "z": 4,
      "name": "Rock_Basalt_Brick"
    },
    {
      "x": -12,
      "y": 5,
      "z": 4,
      "name": "Rock_Basalt_Brick"
    },
    {
      "x": -12,
      "y": 6,
      "z": 4,
      "name": "Rock_Basalt_Brick"
    },
    {
      "x": -12,
      "y": 7,
      "z": 4,
      "name": "Rock_Basalt_Brick"
    },
    {
      "x": -12,
      "y": 8,
      "z": 4,
      "name": "Rock_Basalt_Brick"
    },
    {
      "x": -12,
      "y": 9,
      "z": 4,
      "name": "Rock_CastIron"
    },
    {
      "x": -12,
      "y": 0,
      "z": 5,
      "name": "Rock_CastIron"
    },
    {
      "x": -12,
      "y": 1,
      "z": 5,
      "name": "Rock_CastIron"
    },
    {
      "x": -12,
      "y": 2,
      "z": 5,
      "name": "Rock_CastIron"
    },
    {
      "x": -12,
      "y": 3,
      "z": 5,
      "name": "Rock_CastIron"
    },
    {
      "x": -12,
      "y": 4,
      "z": 5,
      "name": "Rock_CastIron"
    },
    {
      "x": -12,
      "y": 5,
      "z": 5,
      "name": "Rock_CastIron"
    },
    {
      "x": -12,
      "y": 6,
      "z": 5,
      "name": "Rock_CastIron"
    },
    {
      "x": -12,
      "y": 7,
      "z": 5,
      "name": "Rock_CastIron"
    },
    {
      "x": -12,
      "y": 8,
      "z": 5,
      "name": "Rock_CastIron"
    },
    {
      "x": -12,
      "y": 9,
      "z": 5,
      "name": "Rock_CastIron"
    },
    {
      "x": -12,
      "y": 0,
      "z": 6,
      "name": "Rock_CastIron"
    },
    {
      "x": -12,
      "y": 1,
      "z": 6,
      "name": "Rock_CastIron"
    },
    {
      "x": -12,
      "y": 2,
      "z": 6,
      "name": "Rock_CastIron"
    },
    {
      "x": -12,
      "y": 3,
      "z": 6,
      "name": "Rock_CastIron"
    },
    {
      "x": -12,
      "y": 4,
      "z": 6,
      "name": "Rock_CastIron_Brick"
    },
    {
      "x": -12,
      "y": 5,
      "z": 6,
      "name": "Rock_CastIron_Brick"
    },
    {
      "x": -12,
      "y": 6,
      "z": 6,
      "name": "Rock_CastIron"
    },
    {
      "x": -12,
      "y": 7,
      "z": 6,
      "name": "Rock_CastIron"
    },
    {
      "x": -12,
      "y": 8,
      "z": 6,
      "name": "Rock_CastIron"
    },
    {
      "x": -12,
      "y": 9,
      "z": 6,
      "name": "Rock_CastIron"
    },
    {
      "x": -12,
      "y": 0,
      "z": 7,
      "name": "Rock_CastIron"
    },
    {
      "x": -12,
      "y": 1,
      "z": 7,
      "name": "Rock_CastIron"
    },
    {
      "x": -12,
      "y": 2,
      "z": 7,
      "name": "Rock_CastIron"
    },
    {
      "x": -12,
      "y": 3,
      "z": 7,
      "name": "Rock_CastIron"
    },
    {
      "x": -12,
      "y": 4,
      "z": 7,
      "name": "Rock_CastIron_Brick"
    },
    {
      "x": -12,
      "y": 5,
      "z": 7,
      "name": "Rock_CastIron_Brick"
    },
    {
      "x": -12,
      "y": 6,
      "z": 7,
      "name": "Rock_CastIron"
    },
    {
      "x": -12,
      "y": 7,
      "z": 7,
      "name": "Rock_CastIron"
    },
    {
      "x": -12,
      "y": 8,
      "z": 7,
      "name": "Rock_CastIron"
    },
    {
      "x": -12,
      "y": 9,
      "z": 7,
      "name": "Rock_CastIron"
    },
    {
      "x": -12,
      "y": 0,
      "z": 8,
      "name": "Rock_CastIron"
    },
    {
      "x": -12,
      "y": 1,
      "z": 8,
      "name": "Rock_CastIron"
    },
    {
      "x": -12,
      "y": 2,
      "z": 8,
      "name": "Rock_CastIron"
    },
    {
      "x": -12,
      "y": 3,
      "z": 8,
      "name": "Rock_CastIron"
    },
    {
      "x": -12,
      "y": 4,
      "z": 8,
      "name": "Rock_CastIron_Brick"
    },
    {
      "x": -12,
      "y": 5,
      "z": 8,
      "name": "Rock_CastIron_Brick"
    },
    {
      "x": -12,
      "y": 6,
      "z": 8,
      "name": "Rock_CastIron"
    },
    {
      "x": -12,
      "y": 7,
      "z": 8,
      "name": "Rock_CastIron"
    },
    {
      "x": -12,
      "y": 8,
      "z": 8,
      "name": "Rock_CastIron"
    },
    {
      "x": -12,
      "y": 9,
      "z": 8,
      "name": "Rock_CastIron"
    },
    {
      "x": -12,
      "y": 0,
      "z": 9,
      "name": "Rock_CastIron"
    },
    {
      "x": -12,
      "y": 1,
      "z": 9,
      "name": "Rock_CastIron"
    },
    {
      "x": -12,
      "y": 2,
      "z": 9,
      "name": "Rock_CastIron"
    },
    {
      "x": -12,
      "y": 3,
      "z": 9,
      "name": "Rock_CastIron"
    },
    {
      "x": -12,
      "y": 4,
      "z": 9,
      "name": "Rock_CastIron_Brick"
    },
    {
      "x": -12,
      "y": 5,
      "z": 9,
      "name": "Rock_CastIron_Brick"
    },
    {
      "x": -12,
      "y": 6,
      "z": 9,
      "name": "Rock_CastIron"
    },
    {
      "x": -12,
      "y": 7,
      "z": 9,
      "name": "Rock_CastIron"
    },
    {
      "x": -12,
      "y": 8,
      "z": 9,
      "name": "Rock_CastIron"
    },
    {
      "x": -12,
      "y": 9,
      "z": 9,
      "name": "Rock_CastIron"
    },
    {
      "x": -12,
      "y": 0,
      "z": 10,
      "name": "Rock_CastIron"
    },
    {
      "x": -12,
      "y": 1,
      "z": 10,
      "name": "Rock_CastIron"
    },
    {
      "x": -12,
      "y": 2,
      "z": 10,
      "name": "Rock_CastIron"
    },
    {
      "x": -12,
      "y": 3,
      "z": 10,
      "name": "Rock_CastIron"
    },
    {
      "x": -12,
      "y": 4,
      "z": 10,
      "name": "Rock_CastIron_Brick"
    },
    {
      "x": -12,
      "y": 5,
      "z": 10,
      "name": "Rock_CastIron_Brick"
    },
    {
      "x": -12,
      "y": 6,
      "z": 10,
      "name": "Rock_CastIron"
    },
    {
      "x": -12,
      "y": 7,
      "z": 10,
      "name": "Rock_CastIron"
    },
    {
      "x": -12,
      "y": 8,
      "z": 10,
      "name": "Rock_CastIron"
    },
    {
      "x": -12,
      "y": 9,
      "z": 10,
      "name": "Rock_CastIron"
    },
    {
      "x": -12,
      "y": 0,
      "z": 11,
      "name": "Rock_CastIron"
    },
    {
      "x": -12,
      "y": 1,
      "z": 11,
      "name": "Rock_CastIron"
    },
    {
      "x": -12,
      "y": 2,
      "z": 11,
      "name": "Rock_CastIron"
    },
    {
      "x": -12,
      "y": 3,
      "z": 11,
      "name": "Rock_CastIron"
    },
    {
      "x": -12,
      "y": 4,
      "z": 11,
      "name": "Rock_CastIron"
    },
    {
      "x": -12,
      "y": 5,
      "z": 11,
      "name": "Rock_CastIron"
    },
    {
      "x": -12,
      "y": 6,
      "z": 11,
      "name": "Rock_CastIron"
    },
    {
      "x": -12,
      "y": 7,
      "z": 11,
      "name": "Rock_CastIron"
    },
    {
      "x": -12,
      "y": 8,
      "z": 11,
      "name": "Rock_CastIron"
    },
    {
      "x": -12,
      "y": 9,
      "z": 11,
      "name": "Rock_CastIron"
    },
    {
      "x": -12,
      "y": 0,
      "z": 12,
      "name": "Rock_CastIron"
    },
    {
      "x": -12,
      "y": 1,
      "z": 12,
      "name": "Rock_CastIron"
    },
    {
      "x": -12,
      "y": 2,
      "z": 12,
      "name": "Rock_CastIron"
    },
    {
      "x": -12,
      "y": 3,
      "z": 12,
      "name": "Rock_CastIron"
    },
    {
      "x": -12,
      "y": 4,
      "z": 12,
      "name": "Rock_CastIron"
    },
    {
      "x": -12,
      "y": 5,
      "z": 12,
      "name": "Rock_CastIron"
    },
    {
      "x": -12,
      "y": 6,
      "z": 12,
      "name": "Rock_CastIron"
    },
    {
      "x": -12,
      "y": 7,
      "z": 12,
      "name": "Rock_CastIron"
    },
    {
      "x": -12,
      "y": 8,
      "z": 12,
      "name": "Rock_CastIron"
    },
    {
      "x": -12,
      "y": 9,
      "z": 12,
      "name": "Rock_CastIron"
    },
    {
      "x": -11,
      "y": 0,
      "z": -12,
      "name": "Rock_CastIron"
    },
    {
      "x": -11,
      "y": 1,
      "z": -12,
      "name": "Rock_CastIron"
    },
    {
      "x": -11,
      "y": 2,
      "z": -12,
      "name": "Rock_CastIron"
    },
    {
      "x": -11,
      "y": 3,
      "z": -12,
      "name": "Rock_CastIron"
    },
    {
      "x": -11,
      "y": 4,
      "z": -12,
      "name": "Rock_CastIron"
    },
    {
      "x": -11,
      "y": 5,
      "z": -12,
      "name": "Rock_CastIron"
    },
    {
      "x": -11,
      "y": 6,
      "z": -12,
      "name": "Rock_CastIron"
    },
    {
      "x": -11,
      "y": 7,
      "z": -12,
      "name": "Rock_CastIron"
    },
    {
      "x": -11,
      "y": 8,
      "z": -12,
      "name": "Rock_CastIron"
    },
    {
      "x": -11,
      "y": 9,
      "z": -12,
      "name": "Rock_CastIron"
    },
    {
      "x": -11,
      "y": 0,
      "z": -11,
      "name": "Rock_CastIron_Brick"
    },
    {
      "x": -11,
      "y": 1,
      "z": -11,
      "name": "Rock_CastIron_Brick"
    },
    {
      "x": -11,
      "y": 2,
      "z": -11,
      "name": "Rock_CastIron_Brick"
    },
    {
      "x": -11,
      "y": 3,
      "z": -11,
      "name": "Rock_CastIron_Brick"
    },
    {
      "x": -11,
      "y": 4,
      "z": -11,
      "name": "Rock_CastIron"
    },
    {
      "x": -11,
      "y": 5,
      "z": -11,
      "name": "Rock_CastIron"
    },
    {
      "x": -11,
      "y": 6,
      "z": -11,
      "name": "Rock_CastIron"
    },
    {
      "x": -11,
      "y": 7,
      "z": -11,
      "name": "Rock_Basalt"
    },
    {
      "x": -11,
      "y": 8,
      "z": -11,
      "name": "Rock_Basalt"
    },
    {
      "x": -11,
      "y": 9,
      "z": -11,
      "name": "Rock_CastIron"
    },
    {
      "x": -11,
      "y": 0,
      "z": -10,
      "name": "Rock_CastIron_Brick"
    },
    {
      "x": -11,
      "y": 1,
      "z": -10,
      "name": "Rock_CastIron_Brick"
    },
    {
      "x": -11,
      "y": 2,
      "z": -10,
      "name": "Rock_CastIron_Brick"
    },
    {
      "x": -11,
      "y": 3,
      "z": -10,
      "name": "Rock_CastIron_Brick"
    },
    {
      "x": -11,
      "y": 4,
      "z": -10,
      "name": "Rock_Shale_Brick_Stairs",
      "rotation": 2
    },
    {
      "x": -11,
      "y": 5,
      "z": -10,
      "name": "Empty"
    },
    {
      "x": -11,
      "y": 6,
      "z": -10,
      "name": "Empty"
    },
    {
      "x": -11,
      "y": 7,
      "z": -10,
      "name": "Empty"
    },
    {
      "x": -11,
      "y": 8,
      "z": -10,
      "name": "Empty"
    },
    {
      "x": -11,
      "y": 9,
      "z": -10,
      "name": "Rock_CastIron"
    },
    {
      "x": -11,
      "y": 0,
      "z": -9,
      "name": "Rock_CastIron_Brick"
    },
    {
      "x": -11,
      "y": 1,
      "z": -9,
      "name": "Rock_CastIron_Brick"
    },
    {
      "x": -11,
      "y": 2,
      "z": -9,
      "name": "Rock_CastIron_Brick"
    },
    {
      "x": -11,
      "y": 3,
      "z": -9,
      "name": "Rock_CastIron_Brick"
    },
    {
      "x": -11,
      "y": 4,
      "z": -9,
      "name": "Wood_Burnt_Trunk",
      "support": 15
    },
    {
      "x": -11,
      "y": 5,
      "z": -9,
      "name": "Deco_Fire"
    },
    {
      "x": -11,
      "y": 6,
      "z": -9,
      "name": "Empty"
    },
    {
      "x": -11,
      "y": 7,
      "z": -9,
      "name": "Empty"
    },
    {
      "x": -11,
      "y": 8,
      "z": -9,
      "name": "Empty"
    },
    {
      "x": -11,
      "y": 9,
      "z": -9,
      "name": "Rock_CastIron"
    },
    {
      "x": -11,
      "y": 0,
      "z": -8,
      "name": "Rock_CastIron_Brick"
    },
    {
      "x": -11,
      "y": 1,
      "z": -8,
      "name": "Rock_CastIron_Brick"
    },
    {
      "x": -11,
      "y": 2,
      "z": -8,
      "name": "Rock_CastIron_Brick"
    },
    {
      "x": -11,
      "y": 3,
      "z": -8,
      "name": "Rock_CastIron_Brick"
    },
    {
      "x": -11,
      "y": 4,
      "z": -8,
      "name": "Rock_Shale_Brick_Stairs"
    },
    {
      "x": -11,
      "y": 5,
      "z": -8,
      "name": "Empty"
    },
    {
      "x": -11,
      "y": 6,
      "z": -8,
      "name": "Empty"
    },
    {
      "x": -11,
      "y": 7,
      "z": -8,
      "name": "Empty"
    },
    {
      "x": -11,
      "y": 8,
      "z": -8,
      "name": "Empty"
    },
    {
      "x": -11,
      "y": 9,
      "z": -8,
      "name": "Rock_CastIron"
    },
    {
      "x": -11,
      "y": 0,
      "z": -7,
      "name": "Rock_CastIron_Brick"
    },
    {
      "x": -11,
      "y": 1,
      "z": -7,
      "name": "Rock_CastIron_Brick"
    },
    {
      "x": -11,
      "y": 2,
      "z": -7,
      "name": "Rock_CastIron_Brick"
    },
    {
      "x": -11,
      "y": 3,
      "z": -7,
      "name": "Rock_CastIron_Brick"
    },
    {
      "x": -11,
      "y": 4,
      "z": -7,
      "name": "Rock_CastIron_Brick"
    },
    {
      "x": -11,
      "y": 5,
      "z": -7,
      "name": "Rock_CastIron_Brick"
    },
    {
      "x": -11,
      "y": 6,
      "z": -7,
      "name": "Rock_CastIron_Brick"
    },
    {
      "x": -11,
      "y": 7,
      "z": -7,
      "name": "Rock_CastIron_Brick"
    },
    {
      "x": -11,
      "y": 8,
      "z": -7,
      "name": "Rock_CastIron_Brick"
    },
    {
      "x": -11,
      "y": 9,
      "z": -7,
      "name": "Rock_CastIron"
    },
    {
      "x": -11,
      "y": 0,
      "z": -6,
      "name": "Rock_CastIron_Brick"
    },
    {
      "x": -11,
      "y": 1,
      "z": -6,
      "name": "Rock_CastIron_Brick"
    },
    {
      "x": -11,
      "y": 2,
      "z": -6,
      "name": "Rock_CastIron_Brick"
    },
    {
      "x": -11,
      "y": 3,
      "z": -6,
      "name": "Rock_Basalt_Brick"
    },
    {
      "x": -11,
      "y": 4,
      "z": -6,
      "name": "Rock_Basalt_Brick"
    },
    {
      "x": -11,
      "y": 5,
      "z": -6,
      "name": "Plant_Moss_Rug_Green_Dark"
    },
    {
      "x": -11,
      "y": 6,
      "z": -6,
      "name": "Rock_Basalt_Brick"
    },
    {
      "x": -11,
      "y": 7,
      "z": -6,
      "name": "Plant_Moss_Rug_Green_Dark"
    },
    {
      "x": -11,
      "y": 8,
      "z": -6,
      "name": "Rock_Basalt_Brick"
    },
    {
      "x": -11,
      "y": 9,
      "z": -6,
      "name": "Rock_CastIron"
    },
    {
      "x": -11,
      "y": 0,
      "z": -5,
      "name": "Rock_CastIron_Brick"
    },
    {
      "x": -11,
      "y": 1,
      "z": -5,
      "name": "Rock_CastIron_Brick"
    },
    {
      "x": -11,
      "y": 2,
      "z": -5,
      "name": "Rock_CastIron_Brick"
    },
    {
      "x": -11,
      "y": 3,
      "z": -5,
      "name": "Rock_Basalt_Brick"
    },
    {
      "x": -11,
      "y": 4,
      "z": -5,
      "name": "Rock_Basalt_Brick"
    },
    {
      "x": -11,
      "y": 5,
      "z": -5,
      "name": "Plant_Moss_Rug_Green_Dark"
    },
    {
      "x": -11,
      "y": 6,
      "z": -5,
      "name": "Rock_Basalt_Brick"
    },
    {
      "x": -11,
      "y": 7,
      "z": -5,
      "name": "Empty"
    },
    {
      "x": -11,
      "y": 8,
      "z": -5,
      "name": "Rock_Basalt_Brick"
    },
    {
      "x": -11,
      "y": 9,
      "z": -5,
      "name": "Rock_CastIron"
    },
    {
      "x": -11,
      "y": 0,
      "z": -4,
      "name": "Rock_CastIron_Brick"
    },
    {
      "x": -11,
      "y": 1,
      "z": -4,
      "name": "Rock_CastIron_Brick"
    },
    {
      "x": -11,
      "y": 2,
      "z": -4,
      "name": "Rock_CastIron_Brick"
    },
    {
      "x": -11,
      "y": 3,
      "z": -4,
      "name": "Rock_Basalt_Brick"
    },
    {
      "x": -11,
      "y": 4,
      "z": -4,
      "name": "Rock_Basalt_Brick"
    },
    {
      "x": -11,
      "y": 5,
      "z": -4,
      "name": "Plant_Moss_Rug_Green_Dark"
    },
    {
      "x": -11,
      "y": 6,
      "z": -4,
      "name": "Rock_Basalt_Brick"
    },
    {
      "x": -11,
      "y": 7,
      "z": -4,
      "name": "Plant_Moss_Rug_Green_Dark"
    },
    {
      "x": -11,
      "y": 8,
      "z": -4,
      "name": "Rock_Basalt_Brick"
    },
    {
      "x": -11,
      "y": 9,
      "z": -4,
      "name": "Rock_CastIron"
    },
    {
      "x": -11,
      "y": 0,
      "z": -3,
      "name": "Rock_CastIron_Brick"
    },
    {
      "x": -11,
      "y": 1,
      "z": -3,
      "name": "Rock_CastIron_Brick"
    },
    {
      "x": -11,
      "y": 2,
      "z": -3,
      "name": "Rock_CastIron_Brick"
    },
    {
      "x": -11,
      "y": 3,
      "z": -3,
      "name": "Rock_Basalt_Brick"
    },
    {
      "x": -11,
      "y": 4,
      "z": -3,
      "name": "Rock_Basalt_Brick"
    },
    {
      "x": -11,
      "y": 5,
      "z": -3,
      "name": "Empty"
    },
    {
      "x": -11,
      "y": 6,
      "z": -3,
      "name": "Rock_Basalt_Brick"
    },
    {
      "x": -11,
      "y": 7,
      "z": -3,
      "name": "Plant_Moss_Rug_Green_Dark"
    },
    {
      "x": -11,
      "y": 8,
      "z": -3,
      "name": "Rock_Basalt_Brick"
    },
    {
      "x": -11,
      "y": 9,
      "z": -3,
      "name": "Rock_CastIron"
    },
    {
      "x": -11,
      "y": 0,
      "z": -2,
      "name": "Rock_CastIron_Brick"
    },
    {
      "x": -11,
      "y": 1,
      "z": -2,
      "name": "Rock_CastIron_Brick"
    },
    {
      "x": -11,
      "y": 2,
      "z": -2,
      "name": "Rock_CastIron_Brick"
    },
    {
      "x": -11,
      "y": 3,
      "z": -2,
      "name": "Rock_Basalt_Brick"
    },
    {
      "x": -11,
      "y": 4,
      "z": -2,
      "name": "Rock_Basalt_Brick"
    },
    {
      "x": -11,
      "y": 5,
      "z": -2,
      "name": "Plant_Moss_Rug_Green_Dark"
    },
    {
      "x": -11,
      "y": 6,
      "z": -2,
      "name": "Rock_Basalt_Brick"
    },
    {
      "x": -11,
      "y": 7,
      "z": -2,
      "name": "Empty"
    },
    {
      "x": -11,
      "y": 8,
      "z": -2,
      "name": "Rock_Basalt_Brick"
    },
    {
      "x": -11,
      "y": 9,
      "z": -2,
      "name": "Rock_CastIron"
    },
    {
      "x": -11,
      "y": 0,
      "z": -1,
      "name": "Rock_CastIron_Brick"
    },
    {
      "x": -11,
      "y": 1,
      "z": -1,
      "name": "Rock_CastIron_Brick"
    },
    {
      "x": -11,
      "y": 2,
      "z": -1,
      "name": "Rock_CastIron_Brick"
    },
    {
      "x": -11,
      "y": 3,
      "z": -1,
      "name": "Rock_CastIron_Brick"
    },
    {
      "x": -11,
      "y": 4,
      "z": -1,
      "name": "Rock_CastIron_Brick"
    },
    {
      "x": -11,
      "y": 5,
      "z": -1,
      "name": "Rock_CastIron_Brick"
    },
    {
      "x": -11,
      "y": 6,
      "z": -1,
      "name": "Rock_CastIron_Brick"
    },
    {
      "x": -11,
      "y": 7,
      "z": -1,
      "name": "Rock_CastIron_Brick"
    },
    {
      "x": -11,
      "y": 8,
      "z": -1,
      "name": "Rock_CastIron_Brick"
    },
    {
      "x": -11,
      "y": 9,
      "z": -1,
      "name": "Rock_CastIron"
    },
    {
      "x": -11,
      "y": 0,
      "z": 0,
      "name": "Rock_CastIron_Brick"
    },
    {
      "x": -11,
      "y": 1,
      "z": 0,
      "name": "Rock_CastIron_Brick"
    },
    {
      "x": -11,
      "y": 2,
      "z": 0,
      "name": "Rock_CastIron_Brick"
    },
    {
      "x": -11,
      "y": 3,
      "z": 0,
      "name": "Rock_Basalt_Brick"
    },
    {
      "x": -11,
      "y": 4,
      "z": 0,
      "name": "Rock_Basalt_Brick"
    },
    {
      "x": -11,
      "y": 5,
      "z": 0,
      "name": "Plant_Moss_Rug_Green_Dark"
    },
    {
      "x": -11,
      "y": 6,
      "z": 0,
      "name": "Rock_Basalt_Brick"
    },
    {
      "x": -11,
      "y": 7,
      "z": 0,
      "name": "Plant_Moss_Rug_Green_Dark"
    },
    {
      "x": -11,
      "y": 8,
      "z": 0,
      "name": "Rock_Basalt_Brick"
    },
    {
      "x": -11,
      "y": 9,
      "z": 0,
      "name": "Rock_CastIron"
    },
    {
      "x": -11,
      "y": 0,
      "z": 1,
      "name": "Rock_CastIron_Brick"
    },
    {
      "x": -11,
      "y": 1,
      "z": 1,
      "name": "Rock_CastIron_Brick"
    },
    {
      "x": -11,
      "y": 2,
      "z": 1,
      "name": "Rock_CastIron_Brick"
    },
    {
      "x": -11,
      "y": 3,
      "z": 1,
      "name": "Rock_Basalt_Brick"
    },
    {
      "x": -11,
      "y": 4,
      "z": 1,
      "name": "Rock_Basalt_Brick"
    },
    {
      "x": -11,
      "y": 5,
      "z": 1,
      "name": "Plant_Moss_Rug_Green_Dark"
    },
    {
      "x": -11,
      "y": 6,
      "z": 1,
      "name": "Rock_Basalt_Brick"
    },
    {
      "x": -11,
      "y": 7,
      "z": 1,
      "name": "Plant_Moss_Rug_Green_Dark"
    },
    {
      "x": -11,
      "y": 8,
      "z": 1,
      "name": "Rock_Basalt_Brick"
    },
    {
      "x": -11,
      "y": 9,
      "z": 1,
      "name": "Rock_CastIron"
    },
    {
      "x": -11,
      "y": 0,
      "z": 2,
      "name": "Rock_CastIron_Brick"
    },
    {
      "x": -11,
      "y": 1,
      "z": 2,
      "name": "Rock_CastIron_Brick"
    },
    {
      "x": -11,
      "y": 2,
      "z": 2,
      "name": "Rock_CastIron_Brick"
    },
    {
      "x": -11,
      "y": 3,
      "z": 2,
      "name": "Rock_Basalt_Brick"
    },
    {
      "x": -11,
      "y": 4,
      "z": 2,
      "name": "Rock_Basalt_Brick"
    },
    {
      "x": -11,
      "y": 5,
      "z": 2,
      "name": "Empty"
    },
    {
      "x": -11,
      "y": 6,
      "z": 2,
      "name": "Rock_Basalt_Brick"
    },
    {
      "x": -11,
      "y": 7,
      "z": 2,
      "name": "Plant_Moss_Rug_Green_Dark"
    },
    {
      "x": -11,
      "y": 8,
      "z": 2,
      "name": "Rock_Basalt_Brick"
    },
    {
      "x": -11,
      "y": 9,
      "z": 2,
      "name": "Rock_CastIron"
    },
    {
      "x": -11,
      "y": 0,
      "z": 3,
      "name": "Rock_CastIron_Brick"
    },
    {
      "x": -11,
      "y": 1,
      "z": 3,
      "name": "Rock_CastIron_Brick"
    },
    {
      "x": -11,
      "y": 2,
      "z": 3,
      "name": "Rock_CastIron_Brick"
    },
    {
      "x": -11,
      "y": 3,
      "z": 3,
      "name": "Rock_Basalt_Brick"
    },
    {
      "x": -11,
      "y": 4,
      "z": 3,
      "name": "Rock_Basalt_Brick"
    },
    {
      "x": -11,
      "y": 5,
      "z": 3,
      "name": "Plant_Moss_Rug_Green_Dark"
    },
    {
      "x": -11,
      "y": 6,
      "z": 3,
      "name": "Rock_Basalt_Brick"
    },
    {
      "x": -11,
      "y": 7,
      "z": 3,
      "name": "Empty"
    },
    {
      "x": -11,
      "y": 8,
      "z": 3,
      "name": "Rock_Basalt_Brick"
    },
    {
      "x": -11,
      "y": 9,
      "z": 3,
      "name": "Rock_CastIron"
    },
    {
      "x": -11,
      "y": 0,
      "z": 4,
      "name": "Rock_CastIron_Brick"
    },
    {
      "x": -11,
      "y": 1,
      "z": 4,
      "name": "Rock_CastIron_Brick"
    },
    {
      "x": -11,
      "y": 2,
      "z": 4,
      "name": "Rock_CastIron_Brick"
    },
    {
      "x": -11,
      "y": 3,
      "z": 4,
      "name": "Rock_Basalt_Brick"
    },
    {
      "x": -11,
      "y": 4,
      "z": 4,
      "name": "Rock_Basalt_Brick"
    },
    {
      "x": -11,
      "y": 5,
      "z": 4,
      "name": "Plant_Moss_Rug_Green_Dark"
    },
    {
      "x": -11,
      "y": 6,
      "z": 4,
      "name": "Rock_Basalt_Brick"
    },
    {
      "x": -11,
      "y": 7,
      "z": 4,
      "name": "Plant_Moss_Rug_Green_Dark"
    },
    {
      "x": -11,
      "y": 8,
      "z": 4,
      "name": "Rock_Basalt_Brick"
    },
    {
      "x": -11,
      "y": 9,
      "z": 4,
      "name": "Rock_CastIron"
    },
    {
      "x": -11,
      "y": 0,
      "z": 5,
      "name": "Rock_CastIron_Brick"
    },
    {
      "x": -11,
      "y": 1,
      "z": 5,
      "name": "Rock_CastIron_Brick"
    },
    {
      "x": -11,
      "y": 2,
      "z": 5,
      "name": "Rock_CastIron_Brick"
    },
    {
      "x": -11,
      "y": 3,
      "z": 5,
      "name": "Rock_CastIron_Brick"
    },
    {
      "x": -11,
      "y": 4,
      "z": 5,
      "name": "Rock_CastIron_Brick"
    },
    {
      "x": -11,
      "y": 5,
      "z": 5,
      "name": "Rock_CastIron_Brick"
    },
    {
      "x": -11,
      "y": 6,
      "z": 5,
      "name": "Rock_CastIron_Brick"
    },
    {
      "x": -11,
      "y": 7,
      "z": 5,
      "name": "Rock_CastIron_Brick"
    },
    {
      "x": -11,
      "y": 8,
      "z": 5,
      "name": "Rock_CastIron_Brick"
    },
    {
      "x": -11,
      "y": 9,
      "z": 5,
      "name": "Rock_CastIron"
    },
    {
      "x": -11,
      "y": 0,
      "z": 6,
      "name": "Rock_CastIron_Brick"
    },
    {
      "x": -11,
      "y": 1,
      "z": 6,
      "name": "Rock_CastIron_Brick"
    },
    {
      "x": -11,
      "y": 2,
      "z": 6,
      "name": "Rock_CastIron_Brick"
    },
    {
      "x": -11,
      "y": 3,
      "z": 6,
      "name": "Soil_Dirt_Cold"
    },
    {
      "x": -11,
      "y": 4,
      "z": 6,
      "name": "*Plant_Crop_Berry_Winter_Block_State_Definitions_StageFinal"
    },
    {
      "x": -11,
      "y": 5,
      "z": 6,
      "name": "Empty"
    },
    {
      "x": -11,
      "y": 6,
      "z": 6,
      "name": "Empty"
    },
    {
      "x": -11,
      "y": 7,
      "z": 6,
      "name": "Empty"
    },
    {
      "x": -11,
      "y": 8,
      "z": 6,
      "name": "Plant_Bush_Dead_Hanging"
    },
    {
      "x": -11,
      "y": 9,
      "z": 6,
      "name": "Rock_CastIron"
    },
    {
      "x": -11,
      "y": 0,
      "z": 7,
      "name": "Rock_CastIron_Brick"
    },
    {
      "x": -11,
      "y": 1,
      "z": 7,
      "name": "Rock_CastIron_Brick"
    },
    {
      "x": -11,
      "y": 2,
      "z": 7,
      "name": "Rock_CastIron_Brick"
    },
    {
      "x": -11,
      "y": 3,
      "z": 7,
      "name": "Rock_CastIron_Brick"
    },
    {
      "x": -11,
      "y": 4,
      "z": 7,
      "name": "Rock_Shale_Brick_Stairs",
      "rotation": 2
    },
    {
      "x": -11,
      "y": 5,
      "z": 7,
      "name": "Empty"
    },
    {
      "x": -11,
      "y": 6,
      "z": 7,
      "name": "Empty"
    },
    {
      "x": -11,
      "y": 7,
      "z": 7,
      "name": "Empty"
    },
    {
      "x": -11,
      "y": 8,
      "z": 7,
      "name": "Empty"
    },
    {
      "x": -11,
      "y": 9,
      "z": 7,
      "name": "Rock_CastIron"
    },
    {
      "x": -11,
      "y": 0,
      "z": 8,
      "name": "Rock_CastIron_Brick"
    },
    {
      "x": -11,
      "y": 1,
      "z": 8,
      "name": "Rock_CastIron_Brick"
    },
    {
      "x": -11,
      "y": 2,
      "z": 8,
      "name": "Rock_CastIron_Brick"
    },
    {
      "x": -11,
      "y": 3,
      "z": 8,
      "name": "Rock_CastIron_Brick"
    },
    {
      "x": -11,
      "y": 4,
      "z": 8,
      "name": "Wood_Burnt_Trunk",
      "support": 15
    },
    {
      "x": -11,
      "y": 5,
      "z": 8,
      "name": "Deco_Fire"
    },
    {
      "x": -11,
      "y": 6,
      "z": 8,
      "name": "Empty"
    },
    {
      "x": -11,
      "y": 7,
      "z": 8,
      "name": "Empty"
    },
    {
      "x": -11,
      "y": 8,
      "z": 8,
      "name": "Empty"
    },
    {
      "x": -11,
      "y": 9,
      "z": 8,
      "name": "Rock_CastIron"
    },
    {
      "x": -11,
      "y": 0,
      "z": 9,
      "name": "Rock_CastIron_Brick"
    },
    {
      "x": -11,
      "y": 1,
      "z": 9,
      "name": "Rock_CastIron_Brick"
    },
    {
      "x": -11,
      "y": 2,
      "z": 9,
      "name": "Rock_CastIron_Brick"
    },
    {
      "x": -11,
      "y": 3,
      "z": 9,
      "name": "Rock_CastIron_Brick"
    },
    {
      "x": -11,
      "y": 4,
      "z": 9,
      "name": "Rock_Shale_Brick_Stairs"
    },
    {
      "x": -11,
      "y": 5,
      "z": 9,
      "name": "Empty"
    },
    {
      "x": -11,
      "y": 6,
      "z": 9,
      "name": "Empty"
    },
    {
      "x": -11,
      "y": 7,
      "z": 9,
      "name": "Empty"
    },
    {
      "x": -11,
      "y": 8,
      "z": 9,
      "name": "Empty"
    },
    {
      "x": -11,
      "y": 9,
      "z": 9,
      "name": "Rock_CastIron"
    },
    {
      "x": -11,
      "y": 0,
      "z": 10,
      "name": "Rock_CastIron_Brick"
    },
    {
      "x": -11,
      "y": 1,
      "z": 10,
      "name": "Rock_CastIron_Brick"
    },
    {
      "x": -11,
      "y": 2,
      "z": 10,
      "name": "Rock_CastIron_Brick"
    },
    {
      "x": -11,
      "y": 3,
      "z": 10,
      "name": "Rock_CastIron_Brick"
    },
    {
      "x": -11,
      "y": 4,
      "z": 10,
      "name": "Empty"
    },
    {
      "x": -11,
      "y": 5,
      "z": 10,
      "name": "Empty"
    },
    {
      "x": -11,
      "y": 6,
      "z": 10,
      "name": "Empty"
    },
    {
      "x": -11,
      "y": 7,
      "z": 10,
      "name": "Plant_Vine_Wall",
      "support": 15,
      "rotation": 1
    },
    {
      "x": -11,
      "y": 8,
      "z": 10,
      "name": "Empty"
    },
    {
      "x": -11,
      "y": 9,
      "z": 10,
      "name": "Rock_CastIron"
    },
    {
      "x": -11,
      "y": 0,
      "z": 11,
      "name": "Rock_Basalt_Brick"
    },
    {
      "x": -11,
      "y": 1,
      "z": 11,
      "name": "Rock_Basalt_Brick"
    },
    {
      "x": -11,
      "y": 2,
      "z": 11,
      "name": "Rock_Basalt_Brick"
    },
    {
      "x": -11,
      "y": 3,
      "z": 11,
      "name": "Rock_Basalt_Brick"
    },
    {
      "x": -11,
      "y": 4,
      "z": 11,
      "name": "Rock_CastIron_Brick"
    },
    {
      "x": -11,
      "y": 5,
      "z": 11,
      "name": "Rock_CastIron_Brick"
    },
    {
      "x": -11,
      "y": 6,
      "z": 11,
      "name": "Rock_CastIron_Brick"
    },
    {
      "x": -11,
      "y": 7,
      "z": 11,
      "name": "Rock_CastIron_Brick"
    },
    {
      "x": -11,
      "y": 8,
      "z": 11,
      "name": "Rock_CastIron_Brick"
    },
    {
      "x": -11,
      "y": 9,
      "z": 11,
      "name": "Rock_CastIron"
    },
    {
      "x": -11,
      "y": 0,
      "z": 12,
      "name": "Rock_CastIron"
    },
    {
      "x": -11,
      "y": 1,
      "z": 12,
      "name": "Rock_CastIron"
    },
    {
      "x": -11,
      "y": 2,
      "z": 12,
      "name": "Rock_CastIron"
    },
    {
      "x": -11,
      "y": 3,
      "z": 12,
      "name": "Rock_CastIron"
    },
    {
      "x": -11,
      "y": 4,
      "z": 12,
      "name": "Rock_CastIron"
    },
    {
      "x": -11,
      "y": 5,
      "z": 12,
      "name": "Rock_CastIron"
    },
    {
      "x": -11,
      "y": 6,
      "z": 12,
      "name": "Rock_CastIron"
    },
    {
      "x": -11,
      "y": 7,
      "z": 12,
      "name": "Rock_CastIron"
    },
    {
      "x": -11,
      "y": 8,
      "z": 12,
      "name": "Rock_CastIron"
    },
    {
      "x": -11,
      "y": 9,
      "z": 12,
      "name": "Rock_CastIron"
    },
    {
      "x": -10,
      "y": 0,
      "z": -12,
      "name": "Rock_CastIron"
    },
    {
      "x": -10,
      "y": 1,
      "z": -12,
      "name": "Rock_CastIron"
    },
    {
      "x": -10,
      "y": 2,
      "z": -12,
      "name": "Rock_CastIron"
    },
    {
      "x": -10,
      "y": 3,
      "z": -12,
      "name": "Rock_CastIron"
    },
    {
      "x": -10,
      "y": 4,
      "z": -12,
      "name": "Rock_CastIron"
    },
    {
      "x": -10,
      "y": 5,
      "z": -12,
      "name": "Rock_CastIron"
    },
    {
      "x": -10,
      "y": 6,
      "z": -12,
      "name": "Rock_CastIron"
    },
    {
      "x": -10,
      "y": 7,
      "z": -12,
      "name": "Rock_CastIron"
    },
    {
      "x": -10,
      "y": 8,
      "z": -12,
      "name": "Rock_CastIron"
    },
    {
      "x": -10,
      "y": 9,
      "z": -12,
      "name": "Rock_CastIron"
    },
    {
      "x": -10,
      "y": 0,
      "z": -11,
      "name": "Rock_CastIron_Brick"
    },
    {
      "x": -10,
      "y": 1,
      "z": -11,
      "name": "Rock_CastIron_Brick"
    },
    {
      "x": -10,
      "y": 2,
      "z": -11,
      "name": "Rock_CastIron_Brick"
    },
    {
      "x": -10,
      "y": 3,
      "z": -11,
      "name": "Rock_CastIron_Brick"
    },
    {
      "x": -10,
      "y": 4,
      "z": -11,
      "name": "Rock_CastIron"
    },
    {
      "x": -10,
      "y": 5,
      "z": -11,
      "name": "Rock_CastIron"
    },
    {
      "x": -10,
      "y": 6,
      "z": -11,
      "name": "Rock_Basalt"
    },
    {
      "x": -10,
      "y": 7,
      "z": -11,
      "name": "Rock_Basalt"
    },
    {
      "x": -10,
      "y": 8,
      "z": -11,
      "name": "Rock_Basalt"
    },
    {
      "x": -10,
      "y": 9,
      "z": -11,
      "name": "Rock_CastIron"
    },
    {
      "x": -10,
      "y": 0,
      "z": -10,
      "name": "Rock_CastIron_Brick"
    },
    {
      "x": -10,
      "y": 1,
      "z": -10,
      "name": "Rock_CastIron_Brick"
    },
    {
      "x": -10,
      "y": 2,
      "z": -10,
      "name": "Rock_CastIron_Brick"
    },
    {
      "x": -10,
      "y": 3,
      "z": -10,
      "name": "Rock_CastIron_Brick"
    },
    {
      "x": -10,
      "y": 4,
      "z": -10,
      "name": "Rock_CastIron"
    },
    {
      "x": -10,
      "y": 5,
      "z": -10,
      "name": "Rock_CastIron"
    },
    {
      "x": -10,
      "y": 6,
      "z": -10,
      "name": "Empty"
    },
    {
      "x": -10,
      "y": 7,
      "z": -10,
      "name": "Empty"
    },
    {
      "x": -10,
      "y": 8,
      "z": -10,
      "name": "Empty"
    },
    {
      "x": -10,
      "y": 9,
      "z": -10,
      "name": "Rock_CastIron"
    },
    {
      "x": -10,
      "y": 0,
      "z": -9,
      "name": "Rock_CastIron_Brick"
    },
    {
      "x": -10,
      "y": 1,
      "z": -9,
      "name": "Rock_CastIron_Brick"
    },
    {
      "x": -10,
      "y": 2,
      "z": -9,
      "name": "Rock_CastIron_Brick"
    },
    {
      "x": -10,
      "y": 3,
      "z": -9,
      "name": "Rock_CastIron_Brick"
    },
    {
      "x": -10,
      "y": 4,
      "z": -9,
      "name": "Rock_Shale_Brick_Half",
      "rotation": 5
    },
    {
      "x": -10,
      "y": 5,
      "z": -9,
      "name": "Empty"
    },
    {
      "x": -10,
      "y": 6,
      "z": -9,
      "name": "Empty"
    },
    {
      "x": -10,
      "y": 7,
      "z": -9,
      "name": "Empty"
    },
    {
      "x": -10,
      "y": 8,
      "z": -9,
      "name": "Empty"
    },
    {
      "x": -10,
      "y": 9,
      "z": -9,
      "name": "Rock_CastIron"
    },
    {
      "x": -10,
      "y": 0,
      "z": -8,
      "name": "Rock_CastIron_Brick"
    },
    {
      "x": -10,
      "y": 1,
      "z": -8,
      "name": "Rock_CastIron_Brick"
    },
    {
      "x": -10,
      "y": 2,
      "z": -8,
      "name": "Rock_CastIron_Brick"
    },
    {
      "x": -10,
      "y": 3,
      "z": -8,
      "name": "Soil_Dirt_Cold"
    },
    {
      "x": -10,
      "y": 4,
      "z": -8,
      "name": "Rubble_Basalt"
    },
    {
      "x": -10,
      "y": 5,
      "z": -8,
      "name": "Empty"
    },
    {
      "x": -10,
      "y": 6,
      "z": -8,
      "name": "Empty"
    },
    {
      "x": -10,
      "y": 7,
      "z": -8,
      "name": "Empty"
    },
    {
      "x": -10,
      "y": 8,
      "z": -8,
      "name": "Empty"
    },
    {
      "x": -10,
      "y": 9,
      "z": -8,
      "name": "Rock_CastIron"
    },
    {
      "x": -10,
      "y": 0,
      "z": -7,
      "name": "Rock_CastIron_Brick"
    },
    {
      "x": -10,
      "y": 1,
      "z": -7,
      "name": "Rock_CastIron_Brick"
    },
    {
      "x": -10,
      "y": 2,
      "z": -7,
      "name": "Rock_CastIron_Brick"
    },
    {
      "x": -10,
      "y": 3,
      "z": -7,
      "name": "Soil_Dirt_Cold"
    },
    {
      "x": -10,
      "y": 4,
      "z": -7,
      "name": "Empty"
    },
    {
      "x": -10,
      "y": 5,
      "z": -7,
      "name": "Empty"
    },
    {
      "x": -10,
      "y": 6,
      "z": -7,
      "name": "Empty"
    },
    {
      "x": -10,
      "y": 7,
      "z": -7,
      "name": "Empty"
    },
    {
      "x": -10,
      "y": 8,
      "z": -7,
      "name": "Empty"
    },
    {
      "x": -10,
      "y": 9,
      "z": -7,
      "name": "Rock_CastIron"
    },
    {
      "x": -10,
      "y": 0,
      "z": -6,
      "name": "Rock_CastIron_Brick"
    },
    {
      "x": -10,
      "y": 1,
      "z": -6,
      "name": "Rock_CastIron_Brick"
    },
    {
      "x": -10,
      "y": 2,
      "z": -6,
      "name": "Rock_CastIron_Brick"
    },
    {
      "x": -10,
      "y": 3,
      "z": -6,
      "name": "Soil_Dirt_Cold"
    },
    {
      "x": -10,
      "y": 4,
      "z": -6,
      "name": "Empty"
    },
    {
      "x": -10,
      "y": 5,
      "z": -6,
      "name": "Empty"
    },
    {
      "x": -10,
      "y": 6,
      "z": -6,
      "name": "Empty"
    },
    {
      "x": -10,
      "y": 7,
      "z": -6,
      "name": "Empty"
    },
    {
      "x": -10,
      "y": 8,
      "z": -6,
      "name": "Plant_Bush_Dead_Hanging"
    },
    {
      "x": -10,
      "y": 9,
      "z": -6,
      "name": "Rock_CastIron"
    },
    {
      "x": -10,
      "y": 0,
      "z": -5,
      "name": "Rock_CastIron_Brick"
    },
    {
      "x": -10,
      "y": 1,
      "z": -5,
      "name": "Rock_CastIron_Brick"
    },
    {
      "x": -10,
      "y": 2,
      "z": -5,
      "name": "Rock_CastIron_Brick"
    },
    {
      "x": -10,
      "y": 3,
      "z": -5,
      "name": "Soil_Dirt_Cold"
    },
    {
      "x": -10,
      "y": 4,
      "z": -5,
      "name": "Empty"
    },
    {
      "x": -10,
      "y": 5,
      "z": -5,
      "name": "Empty"
    },
    {
      "x": -10,
      "y": 6,
      "z": -5,
      "name": "Empty"
    },
    {
      "x": -10,
      "y": 7,
      "z": -5,
      "name": "Empty"
    },
    {
      "x": -10,
      "y": 8,
      "z": -5,
      "name": "Empty"
    },
    {
      "x": -10,
      "y": 9,
      "z": -5,
      "name": "Rock_CastIron"
    },
    {
      "x": -10,
      "y": 0,
      "z": -4,
      "name": "Rock_CastIron_Brick"
    },
    {
      "x": -10,
      "y": 1,
      "z": -4,
      "name": "Rock_CastIron_Brick"
    },
    {
      "x": -10,
      "y": 2,
      "z": -4,
      "name": "Rock_CastIron_Brick"
    },
    {
      "x": -10,
      "y": 3,
      "z": -4,
      "name": "Rock_CastIron_Brick"
    },
    {
      "x": -10,
      "y": 4,
      "z": -4,
      "name": "Empty"
    },
    {
      "x": -10,
      "y": 5,
      "z": -4,
      "name": "Empty"
    },
    {
      "x": -10,
      "y": 6,
      "z": -4,
      "name": "Empty"
    },
    {
      "x": -10,
      "y": 7,
      "z": -4,
      "name": "Empty"
    },
    {
      "x": -10,
      "y": 8,
      "z": -4,
      "name": "Empty"
    },
    {
      "x": -10,
      "y": 9,
      "z": -4,
      "name": "Rock_CastIron"
    },
    {
      "x": -10,
      "y": 0,
      "z": -3,
      "name": "Rock_CastIron_Brick"
    },
    {
      "x": -10,
      "y": 1,
      "z": -3,
      "name": "Rock_CastIron_Brick"
    },
    {
      "x": -10,
      "y": 2,
      "z": -3,
      "name": "Rock_CastIron_Brick"
    },
    {
      "x": -10,
      "y": 3,
      "z": -3,
      "name": "Rock_CastIron_Brick"
    },
    {
      "x": -10,
      "y": 4,
      "z": -3,
      "name": "Empty"
    },
    {
      "x": -10,
      "y": 5,
      "z": -3,
      "name": "Empty"
    },
    {
      "x": -10,
      "y": 6,
      "z": -3,
      "name": "Empty"
    },
    {
      "x": -10,
      "y": 7,
      "z": -3,
      "name": "Empty"
    },
    {
      "x": -10,
      "y": 8,
      "z": -3,
      "name": "Plant_Vine_Wall",
      "support": 15,
      "rotation": 1
    },
    {
      "x": -10,
      "y": 9,
      "z": -3,
      "name": "Rock_CastIron"
    },
    {
      "x": -10,
      "y": 0,
      "z": -2,
      "name": "Rock_CastIron_Brick"
    },
    {
      "x": -10,
      "y": 1,
      "z": -2,
      "name": "Rock_CastIron_Brick"
    },
    {
      "x": -10,
      "y": 2,
      "z": -2,
      "name": "Rock_CastIron_Brick"
    },
    {
      "x": -10,
      "y": 3,
      "z": -2,
      "name": "Rock_CastIron_Brick"
    },
    {
      "x": -10,
      "y": 4,
      "z": -2,
      "name": "Empty"
    },
    {
      "x": -10,
      "y": 5,
      "z": -2,
      "name": "Empty"
    },
    {
      "x": -10,
      "y": 6,
      "z": -2,
      "name": "Empty"
    },
    {
      "x": -10,
      "y": 7,
      "z": -2,
      "name": "Empty"
    },
    {
      "x": -10,
      "y": 8,
      "z": -2,
      "name": "Empty"
    },
    {
      "x": -10,
      "y": 9,
      "z": -2,
      "name": "Rock_CastIron"
    },
    {
      "x": -10,
      "y": 0,
      "z": -1,
      "name": "Rock_CastIron_Brick"
    },
    {
      "x": -10,
      "y": 1,
      "z": -1,
      "name": "Rock_CastIron_Brick"
    },
    {
      "x": -10,
      "y": 2,
      "z": -1,
      "name": "Rock_CastIron_Brick"
    },
    {
      "x": -10,
      "y": 3,
      "z": -1,
      "name": "Rock_CastIron_Brick"
    },
    {
      "x": -10,
      "y": 4,
      "z": -1,
      "name": "Empty"
    },
    {
      "x": -10,
      "y": 5,
      "z": -1,
      "name": "Empty"
    },
    {
      "x": -10,
      "y": 6,
      "z": -1,
      "name": "Empty"
    },
    {
      "x": -10,
      "y": 7,
      "z": -1,
      "name": "Empty"
    },
    {
      "x": -10,
      "y": 8,
      "z": -1,
      "name": "Empty"
    },
    {
      "x": -10,
      "y": 9,
      "z": -1,
      "name": "Rock_CastIron"
    },
    {
      "x": -10,
      "y": 0,
      "z": 0,
      "name": "Rock_CastIron_Brick"
    },
    {
      "x": -10,
      "y": 1,
      "z": 0,
      "name": "Rock_CastIron_Brick"
    },
    {
      "x": -10,
      "y": 2,
      "z": 0,
      "name": "Rock_CastIron_Brick"
    },
    {
      "x": -10,
      "y": 3,
      "z": 0,
      "name": "Rock_CastIron_Brick"
    },
    {
      "x": -10,
      "y": 4,
      "z": 0,
      "name": "Empty"
    },
    {
      "x": -10,
      "y": 5,
      "z": 0,
      "name": "Empty"
    },
    {
      "x": -10,
      "y": 6,
      "z": 0,
      "name": "Empty"
    },
    {
      "x": -10,
      "y": 7,
      "z": 0,
      "name": "Empty"
    },
    {
      "x": -10,
      "y": 8,
      "z": 0,
      "name": "Empty"
    },
    {
      "x": -10,
      "y": 9,
      "z": 0,
      "name": "Rock_CastIron"
    },
    {
      "x": -10,
      "y": 0,
      "z": 1,
      "name": "Rock_CastIron_Brick"
    },
    {
      "x": -10,
      "y": 1,
      "z": 1,
      "name": "Rock_CastIron_Brick"
    },
    {
      "x": -10,
      "y": 2,
      "z": 1,
      "name": "Rock_CastIron_Brick"
    },
    {
      "x": -10,
      "y": 3,
      "z": 1,
      "name": "Rock_CastIron_Brick"
    },
    {
      "x": -10,
      "y": 4,
      "z": 1,
      "name": "Empty"
    },
    {
      "x": -10,
      "y": 5,
      "z": 1,
      "name": "Empty"
    },
    {
      "x": -10,
      "y": 6,
      "z": 1,
      "name": "Empty"
    },
    {
      "x": -10,
      "y": 7,
      "z": 1,
      "name": "Empty"
    },
    {
      "x": -10,
      "y": 8,
      "z": 1,
      "name": "Empty"
    },
    {
      "x": -10,
      "y": 9,
      "z": 1,
      "name": "Rock_CastIron"
    },
    {
      "x": -10,
      "y": 0,
      "z": 2,
      "name": "Rock_CastIron_Brick"
    },
    {
      "x": -10,
      "y": 1,
      "z": 2,
      "name": "Rock_CastIron_Brick"
    },
    {
      "x": -10,
      "y": 2,
      "z": 2,
      "name": "Rock_CastIron_Brick"
    },
    {
      "x": -10,
      "y": 3,
      "z": 2,
      "name": "Rock_CastIron_Brick"
    },
    {
      "x": -10,
      "y": 4,
      "z": 2,
      "name": "Empty"
    },
    {
      "x": -10,
      "y": 5,
      "z": 2,
      "name": "Empty"
    },
    {
      "x": -10,
      "y": 6,
      "z": 2,
      "name": "Empty"
    },
    {
      "x": -10,
      "y": 7,
      "z": 2,
      "name": "Empty"
    },
    {
      "x": -10,
      "y": 8,
      "z": 2,
      "name": "Plant_Bush_Dead_Hanging"
    },
    {
      "x": -10,
      "y": 9,
      "z": 2,
      "name": "Rock_CastIron"
    },
    {
      "x": -10,
      "y": 0,
      "z": 3,
      "name": "Rock_CastIron_Brick"
    },
    {
      "x": -10,
      "y": 1,
      "z": 3,
      "name": "Rock_CastIron_Brick"
    },
    {
      "x": -10,
      "y": 2,
      "z": 3,
      "name": "Rock_CastIron_Brick"
    },
    {
      "x": -10,
      "y": 3,
      "z": 3,
      "name": "Rock_CastIron_Brick"
    },
    {
      "x": -10,
      "y": 4,
      "z": 3,
      "name": "Empty"
    },
    {
      "x": -10,
      "y": 5,
      "z": 3,
      "name": "Empty"
    },
    {
      "x": -10,
      "y": 6,
      "z": 3,
      "name": "Empty"
    },
    {
      "x": -10,
      "y": 7,
      "z": 3,
      "name": "Empty"
    },
    {
      "x": -10,
      "y": 8,
      "z": 3,
      "name": "Empty"
    },
    {
      "x": -10,
      "y": 9,
      "z": 3,
      "name": "Rock_CastIron"
    },
    {
      "x": -10,
      "y": 0,
      "z": 4,
      "name": "Rock_CastIron_Brick"
    },
    {
      "x": -10,
      "y": 1,
      "z": 4,
      "name": "Rock_CastIron_Brick"
    },
    {
      "x": -10,
      "y": 2,
      "z": 4,
      "name": "Rock_CastIron_Brick"
    },
    {
      "x": -10,
      "y": 3,
      "z": 4,
      "name": "Rock_CastIron_Brick"
    },
    {
      "x": -10,
      "y": 4,
      "z": 4,
      "name": "Empty"
    },
    {
      "x": -10,
      "y": 5,
      "z": 4,
      "name": "Empty"
    },
    {
      "x": -10,
      "y": 6,
      "z": 4,
      "name": "Empty"
    },
    {
      "x": -10,
      "y": 7,
      "z": 4,
      "name": "Empty"
    },
    {
      "x": -10,
      "y": 8,
      "z": 4,
      "name": "Empty"
    },
    {
      "x": -10,
      "y": 9,
      "z": 4,
      "name": "Rock_CastIron"
    },
    {
      "x": -10,
      "y": 0,
      "z": 5,
      "name": "Rock_CastIron_Brick"
    },
    {
      "x": -10,
      "y": 1,
      "z": 5,
      "name": "Rock_CastIron_Brick"
    },
    {
      "x": -10,
      "y": 2,
      "z": 5,
      "name": "Rock_CastIron_Brick"
    },
    {
      "x": -10,
      "y": 3,
      "z": 5,
      "name": "Soil_Dirt_Cold"
    },
    {
      "x": -10,
      "y": 4,
      "z": 5,
      "name": "Plant_Bush_Dead_Twisted"
    },
    {
      "x": -10,
      "y": 5,
      "z": 5,
      "name": "Empty"
    },
    {
      "x": -10,
      "y": 6,
      "z": 5,
      "name": "Empty"
    },
    {
      "x": -10,
      "y": 7,
      "z": 5,
      "name": "Empty"
    },
    {
      "x": -10,
      "y": 8,
      "z": 5,
      "name": "Empty"
    },
    {
      "x": -10,
      "y": 9,
      "z": 5,
      "name": "Rock_CastIron"
    },
    {
      "x": -10,
      "y": 0,
      "z": 6,
      "name": "Rock_CastIron_Brick"
    },
    {
      "x": -10,
      "y": 1,
      "z": 6,
      "name": "Rock_CastIron_Brick"
    },
    {
      "x": -10,
      "y": 2,
      "z": 6,
      "name": "Rock_CastIron_Brick"
    },
    {
      "x": -10,
      "y": 3,
      "z": 6,
      "name": "Soil_Dirt_Cold"
    },
    {
      "x": -10,
      "y": 4,
      "z": 6,
      "name": "Empty"
    },
    {
      "x": -10,
      "y": 5,
      "z": 6,
      "name": "Empty"
    },
    {
      "x": -10,
      "y": 6,
      "z": 6,
      "name": "Empty"
    },
    {
      "x": -10,
      "y": 7,
      "z": 6,
      "name": "Empty"
    },
    {
      "x": -10,
      "y": 8,
      "z": 6,
      "name": "Empty"
    },
    {
      "x": -10,
      "y": 9,
      "z": 6,
      "name": "Rock_CastIron"
    },
    {
      "x": -10,
      "y": 0,
      "z": 7,
      "name": "Rock_CastIron_Brick"
    },
    {
      "x": -10,
      "y": 1,
      "z": 7,
      "name": "Rock_CastIron_Brick"
    },
    {
      "x": -10,
      "y": 2,
      "z": 7,
      "name": "Rock_CastIron_Brick"
    },
    {
      "x": -10,
      "y": 3,
      "z": 7,
      "name": "Rock_CastIron_Brick"
    },
    {
      "x": -10,
      "y": 4,
      "z": 7,
      "name": "Empty"
    },
    {
      "x": -10,
      "y": 5,
      "z": 7,
      "name": "Empty"
    },
    {
      "x": -10,
      "y": 6,
      "z": 7,
      "name": "Empty"
    },
    {
      "x": -10,
      "y": 7,
      "z": 7,
      "name": "Empty"
    },
    {
      "x": -10,
      "y": 8,
      "z": 7,
      "name": "Empty"
    },
    {
      "x": -10,
      "y": 9,
      "z": 7,
      "name": "Rock_CastIron"
    },
    {
      "x": -10,
      "y": 0,
      "z": 8,
      "name": "Rock_CastIron_Brick"
    },
    {
      "x": -10,
      "y": 1,
      "z": 8,
      "name": "Rock_CastIron_Brick"
    },
    {
      "x": -10,
      "y": 2,
      "z": 8,
      "name": "Rock_CastIron_Brick"
    },
    {
      "x": -10,
      "y": 3,
      "z": 8,
      "name": "Rock_CastIron_Brick"
    },
    {
      "x": -10,
      "y": 4,
      "z": 8,
      "name": "Rock_Shale_Brick_Half",
      "rotation": 5
    },
    {
      "x": -10,
      "y": 5,
      "z": 8,
      "name": "Empty"
    },
    {
      "x": -10,
      "y": 6,
      "z": 8,
      "name": "Empty"
    },
    {
      "x": -10,
      "y": 7,
      "z": 8,
      "name": "Empty"
    },
    {
      "x": -10,
      "y": 8,
      "z": 8,
      "name": "Empty"
    },
    {
      "x": -10,
      "y": 9,
      "z": 8,
      "name": "Rock_CastIron"
    },
    {
      "x": -10,
      "y": 0,
      "z": 9,
      "name": "Rock_CastIron_Brick"
    },
    {
      "x": -10,
      "y": 1,
      "z": 9,
      "name": "Rock_CastIron_Brick"
    },
    {
      "x": -10,
      "y": 2,
      "z": 9,
      "name": "Rock_CastIron_Brick"
    },
    {
      "x": -10,
      "y": 3,
      "z": 9,
      "name": "Rock_CastIron_Brick"
    },
    {
      "x": -10,
      "y": 4,
      "z": 9,
      "name": "Empty"
    },
    {
      "x": -10,
      "y": 5,
      "z": 9,
      "name": "Empty"
    },
    {
      "x": -10,
      "y": 6,
      "z": 9,
      "name": "Empty"
    },
    {
      "x": -10,
      "y": 7,
      "z": 9,
      "name": "Empty"
    },
    {
      "x": -10,
      "y": 8,
      "z": 9,
      "name": "Empty"
    },
    {
      "x": -10,
      "y": 9,
      "z": 9,
      "name": "Rock_CastIron"
    },
    {
      "x": -10,
      "y": 0,
      "z": 10,
      "name": "Rock_CastIron_Brick"
    },
    {
      "x": -10,
      "y": 1,
      "z": 10,
      "name": "Rock_CastIron_Brick"
    },
    {
      "x": -10,
      "y": 2,
      "z": 10,
      "name": "Rock_CastIron_Brick"
    },
    {
      "x": -10,
      "y": 3,
      "z": 10,
      "name": "Rock_CastIron_Brick"
    },
    {
      "x": -10,
      "y": 4,
      "z": 10,
      "name": "Empty"
    },
    {
      "x": -10,
      "y": 5,
      "z": 10,
      "name": "Empty"
    },
    {
      "x": -10,
      "y": 6,
      "z": 10,
      "name": "Empty"
    },
    {
      "x": -10,
      "y": 7,
      "z": 10,
      "name": "Empty"
    },
    {
      "x": -10,
      "y": 8,
      "z": 10,
      "name": "Empty"
    },
    {
      "x": -10,
      "y": 9,
      "z": 10,
      "name": "Rock_CastIron"
    },
    {
      "x": -10,
      "y": 0,
      "z": 11,
      "name": "Rock_Basalt_Brick"
    },
    {
      "x": -10,
      "y": 1,
      "z": 11,
      "name": "Rock_Basalt_Brick"
    },
    {
      "x": -10,
      "y": 2,
      "z": 11,
      "name": "Rock_Basalt_Brick"
    },
    {
      "x": -10,
      "y": 3,
      "z": 11,
      "name": "Rock_Basalt_Brick"
    },
    {
      "x": -10,
      "y": 4,
      "z": 11,
      "name": "Rock_Basalt_Brick"
    },
    {
      "x": -10,
      "y": 5,
      "z": 11,
      "name": "Empty"
    },
    {
      "x": -10,
      "y": 6,
      "z": 11,
      "name": "Empty"
    },
    {
      "x": -10,
      "y": 7,
      "z": 11,
      "name": "Empty"
    },
    {
      "x": -10,
      "y": 8,
      "z": 11,
      "name": "Rock_CastIron_Brick"
    },
    {
      "x": -10,
      "y": 9,
      "z": 11,
      "name": "Rock_CastIron"
    },
    {
      "x": -10,
      "y": 0,
      "z": 12,
      "name": "Rock_CastIron"
    },
    {
      "x": -10,
      "y": 1,
      "z": 12,
      "name": "Rock_CastIron"
    },
    {
      "x": -10,
      "y": 2,
      "z": 12,
      "name": "Rock_CastIron"
    },
    {
      "x": -10,
      "y": 3,
      "z": 12,
      "name": "Rock_CastIron"
    },
    {
      "x": -10,
      "y": 4,
      "z": 12,
      "name": "Rock_CastIron"
    },
    {
      "x": -10,
      "y": 5,
      "z": 12,
      "name": "Rock_CastIron"
    },
    {
      "x": -10,
      "y": 6,
      "z": 12,
      "name": "Rock_CastIron"
    },
    {
      "x": -10,
      "y": 7,
      "z": 12,
      "name": "Rock_CastIron"
    },
    {
      "x": -10,
      "y": 8,
      "z": 12,
      "name": "Rock_CastIron"
    },
    {
      "x": -10,
      "y": 9,
      "z": 12,
      "name": "Rock_CastIron"
    },
    {
      "x": -9,
      "y": 0,
      "z": -12,
      "name": "Rock_CastIron"
    },
    {
      "x": -9,
      "y": 1,
      "z": -12,
      "name": "Rock_CastIron"
    },
    {
      "x": -9,
      "y": 2,
      "z": -12,
      "name": "Rock_CastIron"
    },
    {
      "x": -9,
      "y": 3,
      "z": -12,
      "name": "Rock_CastIron"
    },
    {
      "x": -9,
      "y": 4,
      "z": -12,
      "name": "Rock_CastIron"
    },
    {
      "x": -9,
      "y": 5,
      "z": -12,
      "name": "Rock_CastIron"
    },
    {
      "x": -9,
      "y": 6,
      "z": -12,
      "name": "Rock_CastIron"
    },
    {
      "x": -9,
      "y": 7,
      "z": -12,
      "name": "Rock_CastIron"
    },
    {
      "x": -9,
      "y": 8,
      "z": -12,
      "name": "Rock_CastIron"
    },
    {
      "x": -9,
      "y": 9,
      "z": -12,
      "name": "Rock_CastIron"
    },
    {
      "x": -9,
      "y": 0,
      "z": -11,
      "name": "Rock_CastIron_Brick"
    },
    {
      "x": -9,
      "y": 1,
      "z": -11,
      "name": "Rock_Basalt"
    },
    {
      "x": -9,
      "y": 2,
      "z": -11,
      "name": "Rock_Basalt"
    },
    {
      "x": -9,
      "y": 3,
      "z": -11,
      "name": "Rock_Basalt"
    },
    {
      "x": -9,
      "y": 4,
      "z": -11,
      "name": "Rock_Basalt"
    },
    {
      "x": -9,
      "y": 5,
      "z": -11,
      "name": "Rock_Basalt"
    },
    {
      "x": -9,
      "y": 6,
      "z": -11,
      "name": "Rock_Basalt"
    },
    {
      "x": -9,
      "y": 7,
      "z": -11,
      "name": "Rock_Basalt"
    },
    {
      "x": -9,
      "y": 8,
      "z": -11,
      "name": "Rock_Basalt"
    },
    {
      "x": -9,
      "y": 9,
      "z": -11,
      "name": "Rock_CastIron"
    },
    {
      "x": -9,
      "y": 0,
      "z": -10,
      "name": "Rock_CastIron_Brick"
    },
    {
      "x": -9,
      "y": 1,
      "z": -10,
      "name": "Rock_CastIron_Brick"
    },
    {
      "x": -9,
      "y": 2,
      "z": -10,
      "name": "Rock_CastIron"
    },
    {
      "x": -9,
      "y": 3,
      "z": -10,
      "name": "Rock_CastIron"
    },
    {
      "x": -9,
      "y": 4,
      "z": -10,
      "name": "Rock_CastIron"
    },
    {
      "x": -9,
      "y": 5,
      "z": -10,
      "name": "Rock_CastIron"
    },
    {
      "x": -9,
      "y": 6,
      "z": -10,
      "name": "Rock_CastIron"
    },
    {
      "x": -9,
      "y": 7,
      "z": -10,
      "name": "Rock_CastIron"
    },
    {
      "x": -9,
      "y": 8,
      "z": -10,
      "name": "Rock_CastIron"
    },
    {
      "x": -9,
      "y": 9,
      "z": -10,
      "name": "Rock_CastIron"
    },
    {
      "x": -9,
      "y": 0,
      "z": -9,
      "name": "Rock_CastIron_Brick"
    },
    {
      "x": -9,
      "y": 1,
      "z": -9,
      "name": "Rock_CastIron_Brick"
    },
    {
      "x": -9,
      "y": 2,
      "z": -9,
      "name": "Rock_CastIron"
    },
    {
      "x": -9,
      "y": 3,
      "z": -9,
      "name": "Rock_CastIron"
    },
    {
      "x": -9,
      "y": 4,
      "z": -9,
      "name": "Rock_CastIron"
    },
    {
      "x": -9,
      "y": 5,
      "z": -9,
      "name": "Rock_CastIron"
    },
    {
      "x": -9,
      "y": 6,
      "z": -9,
      "name": "Rock_CastIron"
    },
    {
      "x": -9,
      "y": 7,
      "z": -9,
      "name": "Rock_CastIron"
    },
    {
      "x": -9,
      "y": 8,
      "z": -9,
      "name": "Rock_CastIron"
    },
    {
      "x": -9,
      "y": 9,
      "z": -9,
      "name": "Rock_CastIron"
    },
    {
      "x": -9,
      "y": 0,
      "z": -8,
      "name": "Rock_CastIron_Brick"
    },
    {
      "x": -9,
      "y": 1,
      "z": -8,
      "name": "Rock_CastIron_Brick"
    },
    {
      "x": -9,
      "y": 2,
      "z": -8,
      "name": "Rock_CastIron_Brick"
    },
    {
      "x": -9,
      "y": 3,
      "z": -8,
      "name": "Rock_CastIron_Brick"
    },
    {
      "x": -9,
      "y": 4,
      "z": -8,
      "name": "Rock_CastIron"
    },
    {
      "x": -9,
      "y": 5,
      "z": -8,
      "name": "Rock_CastIron"
    },
    {
      "x": -9,
      "y": 6,
      "z": -8,
      "name": "Rock_CastIron"
    },
    {
      "x": -9,
      "y": 7,
      "z": -8,
      "name": "Rock_Shale_Stalactites_Large"
    },
    {
      "x": -9,
      "y": 8,
      "z": -8,
      "name": "Rock_Shale_Stalactites_Large",
      "filler": 1024
    },
    {
      "x": -9,
      "y": 9,
      "z": -8,
      "name": "Rock_CastIron"
    },
    {
      "x": -9,
      "y": 0,
      "z": -7,
      "name": "Rock_CastIron_Brick"
    },
    {
      "x": -9,
      "y": 1,
      "z": -7,
      "name": "Rock_CastIron_Brick"
    },
    {
      "x": -9,
      "y": 2,
      "z": -7,
      "name": "Rock_CastIron_Brick"
    },
    {
      "x": -9,
      "y": 3,
      "z": -7,
      "name": "Rock_CastIron_Brick"
    },
    {
      "x": -9,
      "y": 4,
      "z": -7,
      "name": "Rock_CastIron"
    },
    {
      "x": -9,
      "y": 5,
      "z": -7,
      "name": "Empty"
    },
    {
      "x": -9,
      "y": 6,
      "z": -7,
      "name": "Empty"
    },
    {
      "x": -9,
      "y": 7,
      "z": -7,
      "name": "Empty"
    },
    {
      "x": -9,
      "y": 8,
      "z": -7,
      "name": "Empty"
    },
    {
      "x": -9,
      "y": 9,
      "z": -7,
      "name": "Rock_CastIron"
    },
    {
      "x": -9,
      "y": 0,
      "z": -6,
      "name": "Rock_CastIron_Brick"
    },
    {
      "x": -9,
      "y": 1,
      "z": -6,
      "name": "Rock_CastIron_Brick"
    },
    {
      "x": -9,
      "y": 2,
      "z": -6,
      "name": "Rock_CastIron_Brick"
    },
    {
      "x": -9,
      "y": 3,
      "z": -6,
      "name": "Soil_Dirt_Cold"
    },
    {
      "x": -9,
      "y": 4,
      "z": -6,
      "name": "Plant_Bush_Dead_Twisted"
    },
    {
      "x": -9,
      "y": 5,
      "z": -6,
      "name": "Empty"
    },
    {
      "x": -9,
      "y": 6,
      "z": -6,
      "name": "Empty"
    },
    {
      "x": -9,
      "y": 7,
      "z": -6,
      "name": "Empty"
    },
    {
      "x": -9,
      "y": 8,
      "z": -6,
      "name": "Empty"
    },
    {
      "x": -9,
      "y": 9,
      "z": -6,
      "name": "Rock_CastIron"
    },
    {
      "x": -9,
      "y": 0,
      "z": -5,
      "name": "Rock_CastIron_Brick"
    },
    {
      "x": -9,
      "y": 1,
      "z": -5,
      "name": "Rock_CastIron_Brick"
    },
    {
      "x": -9,
      "y": 2,
      "z": -5,
      "name": "Rock_CastIron_Brick"
    },
    {
      "x": -9,
      "y": 3,
      "z": -5,
      "name": "Soil_Dirt_Cold"
    },
    {
      "x": -9,
      "y": 4,
      "z": -5,
      "name": "Empty"
    },
    {
      "x": -9,
      "y": 5,
      "z": -5,
      "name": "Empty"
    },
    {
      "x": -9,
      "y": 6,
      "z": -5,
      "name": "Empty"
    },
    {
      "x": -9,
      "y": 7,
      "z": -5,
      "name": "Empty"
    },
    {
      "x": -9,
      "y": 8,
      "z": -5,
      "name": "Empty"
    },
    {
      "x": -9,
      "y": 9,
      "z": -5,
      "name": "Rock_CastIron"
    },
    {
      "x": -9,
      "y": 0,
      "z": -4,
      "name": "Rock_CastIron_Brick"
    },
    {
      "x": -9,
      "y": 1,
      "z": -4,
      "name": "Rock_CastIron_Brick"
    },
    {
      "x": -9,
      "y": 2,
      "z": -4,
      "name": "Rock_CastIron_Brick"
    },
    {
      "x": -9,
      "y": 3,
      "z": -4,
      "name": "Rock_CastIron_Brick"
    },
    {
      "x": -9,
      "y": 4,
      "z": -4,
      "name": "Empty"
    },
    {
      "x": -9,
      "y": 5,
      "z": -4,
      "name": "Empty"
    },
    {
      "x": -9,
      "y": 6,
      "z": -4,
      "name": "Empty"
    },
    {
      "x": -9,
      "y": 7,
      "z": -4,
      "name": "Empty"
    },
    {
      "x": -9,
      "y": 8,
      "z": -4,
      "name": "Empty"
    },
    {
      "x": -9,
      "y": 9,
      "z": -4,
      "name": "Rock_CastIron"
    },
    {
      "x": -9,
      "y": 0,
      "z": -3,
      "name": "Rock_CastIron_Brick"
    },
    {
      "x": -9,
      "y": 1,
      "z": -3,
      "name": "Rock_CastIron_Brick"
    },
    {
      "x": -9,
      "y": 2,
      "z": -3,
      "name": "Rock_CastIron_Brick"
    },
    {
      "x": -9,
      "y": 3,
      "z": -3,
      "name": "Rock_CastIron_Brick"
    },
    {
      "x": -9,
      "y": 4,
      "z": -3,
      "name": "Empty"
    },
    {
      "x": -9,
      "y": 5,
      "z": -3,
      "name": "Empty"
    },
    {
      "x": -9,
      "y": 6,
      "z": -3,
      "name": "Empty"
    },
    {
      "x": -9,
      "y": 7,
      "z": -3,
      "name": "Empty"
    },
    {
      "x": -9,
      "y": 8,
      "z": -3,
      "name": "Plant_Leaves_Wisteria_Wild",
      "support": 15
    },
    {
      "x": -9,
      "y": 9,
      "z": -3,
      "name": "Rock_CastIron"
    },
    {
      "x": -9,
      "y": 0,
      "z": -2,
      "name": "Rock_CastIron_Brick"
    },
    {
      "x": -9,
      "y": 1,
      "z": -2,
      "name": "Rock_CastIron_Brick"
    },
    {
      "x": -9,
      "y": 2,
      "z": -2,
      "name": "Rock_CastIron_Brick"
    },
    {
      "x": -9,
      "y": 3,
      "z": -2,
      "name": "Rock_CastIron_Brick"
    },
    {
      "x": -9,
      "y": 4,
      "z": -2,
      "name": "Empty"
    },
    {
      "x": -9,
      "y": 5,
      "z": -2,
      "name": "Empty"
    },
    {
      "x": -9,
      "y": 6,
      "z": -2,
      "name": "Empty"
    },
    {
      "x": -9,
      "y": 7,
      "z": -2,
      "name": "Empty"
    },
    {
      "x": -9,
      "y": 8,
      "z": -2,
      "name": "Empty"
    },
    {
      "x": -9,
      "y": 9,
      "z": -2,
      "name": "Rock_CastIron"
    },
    {
      "x": -9,
      "y": 0,
      "z": -1,
      "name": "Rock_CastIron_Brick"
    },
    {
      "x": -9,
      "y": 1,
      "z": -1,
      "name": "Rock_CastIron_Brick"
    },
    {
      "x": -9,
      "y": 2,
      "z": -1,
      "name": "Rock_CastIron_Brick"
    },
    {
      "x": -9,
      "y": 3,
      "z": -1,
      "name": "Rock_CastIron_Brick"
    },
    {
      "x": -9,
      "y": 4,
      "z": -1,
      "name": "Empty"
    },
    {
      "x": -9,
      "y": 5,
      "z": -1,
      "name": "Empty"
    },
    {
      "x": -9,
      "y": 6,
      "z": -1,
      "name": "Empty"
    },
    {
      "x": -9,
      "y": 7,
      "z": -1,
      "name": "Empty"
    },
    {
      "x": -9,
      "y": 8,
      "z": -1,
      "name": "Empty"
    },
    {
      "x": -9,
      "y": 9,
      "z": -1,
      "name": "Rock_CastIron"
    },
    {
      "x": -9,
      "y": 0,
      "z": 0,
      "name": "Rock_CastIron_Brick"
    },
    {
      "x": -9,
      "y": 1,
      "z": 0,
      "name": "Rock_CastIron_Brick"
    },
    {
      "x": -9,
      "y": 2,
      "z": 0,
      "name": "Rock_CastIron_Brick"
    },
    {
      "x": -9,
      "y": 3,
      "z": 0,
      "name": "Rock_CastIron_Brick"
    },
    {
      "x": -9,
      "y": 4,
      "z": 0,
      "name": "Empty"
    },
    {
      "x": -9,
      "y": 5,
      "z": 0,
      "name": "Empty"
    },
    {
      "x": -9,
      "y": 6,
      "z": 0,
      "name": "Empty"
    },
    {
      "x": -9,
      "y": 7,
      "z": 0,
      "name": "Empty"
    },
    {
      "x": -9,
      "y": 8,
      "z": 0,
      "name": "Empty"
    },
    {
      "x": -9,
      "y": 9,
      "z": 0,
      "name": "Rock_CastIron"
    },
    {
      "x": -9,
      "y": 0,
      "z": 1,
      "name": "Rock_CastIron_Brick"
    },
    {
      "x": -9,
      "y": 1,
      "z": 1,
      "name": "Rock_CastIron_Brick"
    },
    {
      "x": -9,
      "y": 2,
      "z": 1,
      "name": "Rock_CastIron_Brick"
    },
    {
      "x": -9,
      "y": 3,
      "z": 1,
      "name": "Rock_CastIron_Brick"
    },
    {
      "x": -9,
      "y": 4,
      "z": 1,
      "name": "Empty"
    },
    {
      "x": -9,
      "y": 5,
      "z": 1,
      "name": "Empty"
    },
    {
      "x": -9,
      "y": 6,
      "z": 1,
      "name": "Empty"
    },
    {
      "x": -9,
      "y": 7,
      "z": 1,
      "name": "Empty"
    },
    {
      "x": -9,
      "y": 8,
      "z": 1,
      "name": "Empty"
    },
    {
      "x": -9,
      "y": 9,
      "z": 1,
      "name": "Rock_CastIron"
    },
    {
      "x": -9,
      "y": 0,
      "z": 2,
      "name": "Rock_CastIron_Brick"
    },
    {
      "x": -9,
      "y": 1,
      "z": 2,
      "name": "Rock_CastIron_Brick"
    },
    {
      "x": -9,
      "y": 2,
      "z": 2,
      "name": "Rock_CastIron_Brick"
    },
    {
      "x": -9,
      "y": 3,
      "z": 2,
      "name": "Rock_CastIron_Brick"
    },
    {
      "x": -9,
      "y": 4,
      "z": 2,
      "name": "Empty"
    },
    {
      "x": -9,
      "y": 5,
      "z": 2,
      "name": "Empty"
    },
    {
      "x": -9,
      "y": 6,
      "z": 2,
      "name": "Empty"
    },
    {
      "x": -9,
      "y": 7,
      "z": 2,
      "name": "Empty"
    },
    {
      "x": -9,
      "y": 8,
      "z": 2,
      "name": "Empty"
    },
    {
      "x": -9,
      "y": 9,
      "z": 2,
      "name": "Rock_CastIron"
    },
    {
      "x": -9,
      "y": 0,
      "z": 3,
      "name": "Rock_CastIron_Brick"
    },
    {
      "x": -9,
      "y": 1,
      "z": 3,
      "name": "Rock_CastIron_Brick"
    },
    {
      "x": -9,
      "y": 2,
      "z": 3,
      "name": "Rock_CastIron_Brick"
    },
    {
      "x": -9,
      "y": 3,
      "z": 3,
      "name": "Rock_CastIron_Brick"
    },
    {
      "x": -9,
      "y": 4,
      "z": 3,
      "name": "Empty"
    },
    {
      "x": -9,
      "y": 5,
      "z": 3,
      "name": "Empty"
    },
    {
      "x": -9,
      "y": 6,
      "z": 3,
      "name": "Empty"
    },
    {
      "x": -9,
      "y": 7,
      "z": 3,
      "name": "Empty"
    },
    {
      "x": -9,
      "y": 8,
      "z": 3,
      "name": "Empty"
    },
    {
      "x": -9,
      "y": 9,
      "z": 3,
      "name": "Rock_CastIron"
    },
    {
      "x": -9,
      "y": 0,
      "z": 4,
      "name": "Rock_CastIron_Brick"
    },
    {
      "x": -9,
      "y": 1,
      "z": 4,
      "name": "Rock_CastIron_Brick"
    },
    {
      "x": -9,
      "y": 2,
      "z": 4,
      "name": "Rock_CastIron_Brick"
    },
    {
      "x": -9,
      "y": 3,
      "z": 4,
      "name": "Rock_CastIron_Brick"
    },
    {
      "x": -9,
      "y": 4,
      "z": 4,
      "name": "Empty"
    },
    {
      "x": -9,
      "y": 5,
      "z": 4,
      "name": "Empty"
    },
    {
      "x": -9,
      "y": 6,
      "z": 4,
      "name": "Empty"
    },
    {
      "x": -9,
      "y": 7,
      "z": 4,
      "name": "Empty"
    },
    {
      "x": -9,
      "y": 8,
      "z": 4,
      "name": "Empty"
    },
    {
      "x": -9,
      "y": 9,
      "z": 4,
      "name": "Rock_CastIron"
    },
    {
      "x": -9,
      "y": 0,
      "z": 5,
      "name": "Rock_CastIron_Brick"
    },
    {
      "x": -9,
      "y": 1,
      "z": 5,
      "name": "Rock_CastIron_Brick"
    },
    {
      "x": -9,
      "y": 2,
      "z": 5,
      "name": "Rock_CastIron_Brick"
    },
    {
      "x": -9,
      "y": 3,
      "z": 5,
      "name": "Rock_CastIron_Brick"
    },
    {
      "x": -9,
      "y": 4,
      "z": 5,
      "name": "Empty"
    },
    {
      "x": -9,
      "y": 5,
      "z": 5,
      "name": "Empty"
    },
    {
      "x": -9,
      "y": 6,
      "z": 5,
      "name": "Empty"
    },
    {
      "x": -9,
      "y": 7,
      "z": 5,
      "name": "Empty"
    },
    {
      "x": -9,
      "y": 8,
      "z": 5,
      "name": "Empty"
    },
    {
      "x": -9,
      "y": 9,
      "z": 5,
      "name": "Rock_CastIron"
    },
    {
      "x": -9,
      "y": 0,
      "z": 6,
      "name": "Rock_CastIron_Brick"
    },
    {
      "x": -9,
      "y": 1,
      "z": 6,
      "name": "Rock_CastIron_Brick"
    },
    {
      "x": -9,
      "y": 2,
      "z": 6,
      "name": "Rock_CastIron_Brick"
    },
    {
      "x": -9,
      "y": 3,
      "z": 6,
      "name": "Rock_CastIron_Brick"
    },
    {
      "x": -9,
      "y": 4,
      "z": 6,
      "name": "Empty"
    },
    {
      "x": -9,
      "y": 5,
      "z": 6,
      "name": "Empty"
    },
    {
      "x": -9,
      "y": 6,
      "z": 6,
      "name": "Empty"
    },
    {
      "x": -9,
      "y": 7,
      "z": 6,
      "name": "Empty"
    },
    {
      "x": -9,
      "y": 8,
      "z": 6,
      "name": "Empty"
    },
    {
      "x": -9,
      "y": 9,
      "z": 6,
      "name": "Rock_CastIron"
    },
    {
      "x": -9,
      "y": 0,
      "z": 7,
      "name": "Rock_CastIron_Brick"
    },
    {
      "x": -9,
      "y": 1,
      "z": 7,
      "name": "Rock_CastIron_Brick"
    },
    {
      "x": -9,
      "y": 2,
      "z": 7,
      "name": "Rock_CastIron_Brick"
    },
    {
      "x": -9,
      "y": 3,
      "z": 7,
      "name": "Rock_CastIron_Brick"
    },
    {
      "x": -9,
      "y": 4,
      "z": 7,
      "name": "Empty"
    },
    {
      "x": -9,
      "y": 5,
      "z": 7,
      "name": "Empty"
    },
    {
      "x": -9,
      "y": 6,
      "z": 7,
      "name": "Empty"
    },
    {
      "x": -9,
      "y": 7,
      "z": 7,
      "name": "Empty"
    },
    {
      "x": -9,
      "y": 8,
      "z": 7,
      "name": "Empty"
    },
    {
      "x": -9,
      "y": 9,
      "z": 7,
      "name": "Rock_CastIron"
    },
    {
      "x": -9,
      "y": 0,
      "z": 8,
      "name": "Rock_CastIron_Brick"
    },
    {
      "x": -9,
      "y": 1,
      "z": 8,
      "name": "Rock_CastIron_Brick"
    },
    {
      "x": -9,
      "y": 2,
      "z": 8,
      "name": "Rock_CastIron_Brick"
    },
    {
      "x": -9,
      "y": 3,
      "z": 8,
      "name": "Soil_Dirt_Cold"
    },
    {
      "x": -9,
      "y": 4,
      "z": 8,
      "name": "Empty"
    },
    {
      "x": -9,
      "y": 5,
      "z": 8,
      "name": "Empty"
    },
    {
      "x": -9,
      "y": 6,
      "z": 8,
      "name": "Empty"
    },
    {
      "x": -9,
      "y": 7,
      "z": 8,
      "name": "Empty"
    },
    {
      "x": -9,
      "y": 8,
      "z": 8,
      "name": "Empty"
    },
    {
      "x": -9,
      "y": 9,
      "z": 8,
      "name": "Rock_CastIron"
    },
    {
      "x": -9,
      "y": 0,
      "z": 9,
      "name": "Rock_CastIron_Brick"
    },
    {
      "x": -9,
      "y": 1,
      "z": 9,
      "name": "Rock_CastIron_Brick"
    },
    {
      "x": -9,
      "y": 2,
      "z": 9,
      "name": "Rock_CastIron_Brick"
    },
    {
      "x": -9,
      "y": 3,
      "z": 9,
      "name": "Soil_Dirt_Cold"
    },
    {
      "x": -9,
      "y": 4,
      "z": 9,
      "name": "Empty"
    },
    {
      "x": -9,
      "y": 5,
      "z": 9,
      "name": "Empty"
    },
    {
      "x": -9,
      "y": 6,
      "z": 9,
      "name": "Empty"
    },
    {
      "x": -9,
      "y": 7,
      "z": 9,
      "name": "Empty"
    },
    {
      "x": -9,
      "y": 8,
      "z": 9,
      "name": "Empty"
    },
    {
      "x": -9,
      "y": 9,
      "z": 9,
      "name": "Rock_CastIron"
    },
    {
      "x": -9,
      "y": 0,
      "z": 10,
      "name": "Rock_CastIron_Brick"
    },
    {
      "x": -9,
      "y": 1,
      "z": 10,
      "name": "Rock_CastIron_Brick"
    },
    {
      "x": -9,
      "y": 2,
      "z": 10,
      "name": "Rock_CastIron_Brick"
    },
    {
      "x": -9,
      "y": 3,
      "z": 10,
      "name": "Rock_CastIron_Brick"
    },
    {
      "x": -9,
      "y": 4,
      "z": 10,
      "name": "Empty"
    },
    {
      "x": -9,
      "y": 5,
      "z": 10,
      "name": "Empty"
    },
    {
      "x": -9,
      "y": 6,
      "z": 10,
      "name": "Empty"
    },
    {
      "x": -9,
      "y": 7,
      "z": 10,
      "name": "Empty"
    },
    {
      "x": -9,
      "y": 8,
      "z": 10,
      "name": "Empty"
    },
    {
      "x": -9,
      "y": 9,
      "z": 10,
      "name": "Rock_CastIron"
    },
    {
      "x": -9,
      "y": 0,
      "z": 11,
      "name": "Rock_Basalt_Brick"
    },
    {
      "x": -9,
      "y": 1,
      "z": 11,
      "name": "Rock_Basalt_Brick"
    },
    {
      "x": -9,
      "y": 2,
      "z": 11,
      "name": "Rock_Basalt_Brick"
    },
    {
      "x": -9,
      "y": 3,
      "z": 11,
      "name": "Rock_Basalt_Brick"
    },
    {
      "x": -9,
      "y": 4,
      "z": 11,
      "name": "Rock_Basalt_Brick"
    },
    {
      "x": -9,
      "y": 5,
      "z": 11,
      "name": "Empty"
    },
    {
      "x": -9,
      "y": 6,
      "z": 11,
      "name": "Empty"
    },
    {
      "x": -9,
      "y": 7,
      "z": 11,
      "name": "Empty"
    },
    {
      "x": -9,
      "y": 8,
      "z": 11,
      "name": "Rock_CastIron_Brick"
    },
    {
      "x": -9,
      "y": 9,
      "z": 11,
      "name": "Rock_CastIron"
    },
    {
      "x": -9,
      "y": 0,
      "z": 12,
      "name": "Rock_CastIron"
    },
    {
      "x": -9,
      "y": 1,
      "z": 12,
      "name": "Rock_CastIron"
    },
    {
      "x": -9,
      "y": 2,
      "z": 12,
      "name": "Rock_CastIron"
    },
    {
      "x": -9,
      "y": 3,
      "z": 12,
      "name": "Rock_CastIron"
    },
    {
      "x": -9,
      "y": 4,
      "z": 12,
      "name": "Rock_CastIron"
    },
    {
      "x": -9,
      "y": 5,
      "z": 12,
      "name": "Rock_CastIron"
    },
    {
      "x": -9,
      "y": 6,
      "z": 12,
      "name": "Rock_CastIron"
    },
    {
      "x": -9,
      "y": 7,
      "z": 12,
      "name": "Rock_CastIron"
    },
    {
      "x": -9,
      "y": 8,
      "z": 12,
      "name": "Rock_CastIron"
    },
    {
      "x": -9,
      "y": 9,
      "z": 12,
      "name": "Rock_CastIron"
    },
    {
      "x": -8,
      "y": 0,
      "z": -12,
      "name": "Rock_CastIron"
    },
    {
      "x": -8,
      "y": 1,
      "z": -12,
      "name": "Rock_CastIron"
    },
    {
      "x": -8,
      "y": 2,
      "z": -12,
      "name": "Rock_CastIron"
    },
    {
      "x": -8,
      "y": 3,
      "z": -12,
      "name": "Rock_CastIron"
    },
    {
      "x": -8,
      "y": 4,
      "z": -12,
      "name": "Rock_CastIron"
    },
    {
      "x": -8,
      "y": 5,
      "z": -12,
      "name": "Rock_CastIron"
    },
    {
      "x": -8,
      "y": 6,
      "z": -12,
      "name": "Rock_CastIron"
    },
    {
      "x": -8,
      "y": 7,
      "z": -12,
      "name": "Rock_CastIron"
    },
    {
      "x": -8,
      "y": 8,
      "z": -12,
      "name": "Rock_CastIron"
    },
    {
      "x": -8,
      "y": 9,
      "z": -12,
      "name": "Rock_CastIron"
    },
    {
      "x": -8,
      "y": 0,
      "z": -11,
      "name": "Rock_Basalt"
    },
    {
      "x": -8,
      "y": 1,
      "z": -11,
      "name": "Rock_Basalt"
    },
    {
      "x": -8,
      "y": 2,
      "z": -11,
      "name": "Rock_Basalt"
    },
    {
      "x": -8,
      "y": 3,
      "z": -11,
      "name": "Rock_Basalt"
    },
    {
      "x": -8,
      "y": 4,
      "z": -11,
      "name": "Rock_Basalt"
    },
    {
      "x": -8,
      "y": 5,
      "z": -11,
      "name": "Rock_Basalt"
    },
    {
      "x": -8,
      "y": 6,
      "z": -11,
      "name": "Rock_Basalt"
    },
    {
      "x": -8,
      "y": 7,
      "z": -11,
      "name": "Rock_Basalt"
    },
    {
      "x": -8,
      "y": 8,
      "z": -11,
      "name": "Rock_Basalt"
    },
    {
      "x": -8,
      "y": 9,
      "z": -11,
      "name": "Rock_CastIron"
    },
    {
      "x": -8,
      "y": 0,
      "z": -10,
      "name": "Rock_CastIron"
    },
    {
      "x": -8,
      "y": 1,
      "z": -10,
      "name": "Rock_CastIron"
    },
    {
      "x": -8,
      "y": 2,
      "z": -10,
      "name": "Rock_CastIron"
    },
    {
      "x": -8,
      "y": 3,
      "z": -10,
      "name": "Rock_CastIron"
    },
    {
      "x": -8,
      "y": 4,
      "z": -10,
      "name": "Rock_CastIron"
    },
    {
      "x": -8,
      "y": 5,
      "z": -10,
      "name": "Rock_CastIron"
    },
    {
      "x": -8,
      "y": 6,
      "z": -10,
      "name": "Rock_CastIron"
    },
    {
      "x": -8,
      "y": 7,
      "z": -10,
      "name": "Rock_CastIron"
    },
    {
      "x": -8,
      "y": 8,
      "z": -10,
      "name": "Rock_CastIron"
    },
    {
      "x": -8,
      "y": 9,
      "z": -10,
      "name": "Rock_CastIron"
    },
    {
      "x": -8,
      "y": 0,
      "z": -9,
      "name": "Rock_CastIron"
    },
    {
      "x": -8,
      "y": 1,
      "z": -9,
      "name": "Rock_CastIron"
    },
    {
      "x": -8,
      "y": 2,
      "z": -9,
      "name": "Rock_CastIron"
    },
    {
      "x": -8,
      "y": 3,
      "z": -9,
      "name": "Rock_CastIron"
    },
    {
      "x": -8,
      "y": 4,
      "z": -9,
      "name": "Rock_CastIron"
    },
    {
      "x": -8,
      "y": 5,
      "z": -9,
      "name": "Rock_CastIron"
    },
    {
      "x": -8,
      "y": 6,
      "z": -9,
      "name": "Rock_CastIron"
    },
    {
      "x": -8,
      "y": 7,
      "z": -9,
      "name": "Rock_CastIron"
    },
    {
      "x": -8,
      "y": 8,
      "z": -9,
      "name": "Rock_CastIron"
    },
    {
      "x": -8,
      "y": 9,
      "z": -9,
      "name": "Rock_CastIron"
    },
    {
      "x": -8,
      "y": 0,
      "z": -8,
      "name": "Rock_CastIron"
    },
    {
      "x": -8,
      "y": 1,
      "z": -8,
      "name": "Rock_CastIron"
    },
    {
      "x": -8,
      "y": 2,
      "z": -8,
      "name": "Rock_CastIron"
    },
    {
      "x": -8,
      "y": 3,
      "z": -8,
      "name": "Rock_CastIron"
    },
    {
      "x": -8,
      "y": 4,
      "z": -8,
      "name": "Rock_CastIron"
    },
    {
      "x": -8,
      "y": 5,
      "z": -8,
      "name": "Rock_CastIron"
    },
    {
      "x": -8,
      "y": 6,
      "z": -8,
      "name": "Rock_Shale_Stalactites_Small"
    },
    {
      "x": -8,
      "y": 7,
      "z": -8,
      "name": "Empty"
    },
    {
      "x": -8,
      "y": 8,
      "z": -8,
      "name": "Empty"
    },
    {
      "x": -8,
      "y": 9,
      "z": -8,
      "name": "Rock_CastIron"
    },
    {
      "x": -8,
      "y": 0,
      "z": -7,
      "name": "Rock_CastIron"
    },
    {
      "x": -8,
      "y": 1,
      "z": -7,
      "name": "Rock_CastIron"
    },
    {
      "x": -8,
      "y": 2,
      "z": -7,
      "name": "Rock_CastIron"
    },
    {
      "x": -8,
      "y": 3,
      "z": -7,
      "name": "Empty"
    },
    {
      "x": -8,
      "y": 4,
      "z": -7,
      "name": "Empty"
    },
    {
      "x": -8,
      "y": 5,
      "z": -7,
      "name": "Empty"
    },
    {
      "x": -8,
      "y": 6,
      "z": -7,
      "name": "Empty"
    },
    {
      "x": -8,
      "y": 7,
      "z": -7,
      "name": "Empty"
    },
    {
      "x": -8,
      "y": 8,
      "z": -7,
      "name": "Empty"
    },
    {
      "x": -8,
      "y": 9,
      "z": -7,
      "name": "Rock_CastIron"
    },
    {
      "x": -8,
      "y": 0,
      "z": -6,
      "name": "Rock_CastIron_Brick"
    },
    {
      "x": -8,
      "y": 1,
      "z": -6,
      "name": "Rock_CastIron_Brick"
    },
    {
      "x": -8,
      "y": 2,
      "z": -6,
      "name": "Rock_CastIron_Brick"
    },
    {
      "x": -8,
      "y": 3,
      "z": -6,
      "name": "Rock_CastIron_Brick"
    },
    {
      "x": -8,
      "y": 4,
      "z": -6,
      "name": "Rock_Shale_Cobble_Wall",
      "rotation": 1
    },
    {
      "x": -8,
      "y": 5,
      "z": -6,
      "name": "Empty"
    },
    {
      "x": -8,
      "y": 6,
      "z": -6,
      "name": "Empty"
    },
    {
      "x": -8,
      "y": 7,
      "z": -6,
      "name": "Empty"
    },
    {
      "x": -8,
      "y": 8,
      "z": -6,
      "name": "Empty"
    },
    {
      "x": -8,
      "y": 9,
      "z": -6,
      "name": "Rock_CastIron"
    },
    {
      "x": -8,
      "y": 0,
      "z": -5,
      "name": "Rock_CastIron_Brick"
    },
    {
      "x": -8,
      "y": 1,
      "z": -5,
      "name": "Rock_CastIron_Brick"
    },
    {
      "x": -8,
      "y": 2,
      "z": -5,
      "name": "Rock_CastIron_Brick"
    },
    {
      "x": -8,
      "y": 3,
      "z": -5,
      "name": "Rock_CastIron_Brick"
    },
    {
      "x": -8,
      "y": 4,
      "z": -5,
      "name": "Rock_Shale_Cobble_Wall",
      "rotation": 1
    },
    {
      "x": -8,
      "y": 5,
      "z": -5,
      "name": "Empty"
    },
    {
      "x": -8,
      "y": 6,
      "z": -5,
      "name": "Empty"
    },
    {
      "x": -8,
      "y": 7,
      "z": -5,
      "name": "Empty"
    },
    {
      "x": -8,
      "y": 8,
      "z": -5,
      "name": "Empty"
    },
    {
      "x": -8,
      "y": 9,
      "z": -5,
      "name": "Rock_CastIron"
    },
    {
      "x": -8,
      "y": 0,
      "z": -4,
      "name": "Rock_CastIron_Brick"
    },
    {
      "x": -8,
      "y": 1,
      "z": -4,
      "name": "Rock_CastIron_Brick"
    },
    {
      "x": -8,
      "y": 2,
      "z": -4,
      "name": "Rock_CastIron_Brick"
    },
    {
      "x": -8,
      "y": 3,
      "z": -4,
      "name": "Rock_CastIron_Brick"
    },
    {
      "x": -8,
      "y": 4,
      "z": -4,
      "name": "Rock_Shale_Cobble_Wall",
      "rotation": 1
    },
    {
      "x": -8,
      "y": 5,
      "z": -4,
      "name": "Empty"
    },
    {
      "x": -8,
      "y": 6,
      "z": -4,
      "name": "Empty"
    },
    {
      "x": -8,
      "y": 7,
      "z": -4,
      "name": "Empty"
    },
    {
      "x": -8,
      "y": 8,
      "z": -4,
      "name": "Empty"
    },
    {
      "x": -8,
      "y": 9,
      "z": -4,
      "name": "Rock_CastIron"
    },
    {
      "x": -8,
      "y": 0,
      "z": -3,
      "name": "Rock_CastIron_Brick"
    },
    {
      "x": -8,
      "y": 1,
      "z": -3,
      "name": "Rock_CastIron_Brick"
    },
    {
      "x": -8,
      "y": 2,
      "z": -3,
      "name": "Rock_CastIron_Brick"
    },
    {
      "x": -8,
      "y": 3,
      "z": -3,
      "name": "Rock_CastIron_Brick"
    },
    {
      "x": -8,
      "y": 4,
      "z": -3,
      "name": "Rock_Shale_Cobble_Wall",
      "rotation": 1
    },
    {
      "x": -8,
      "y": 5,
      "z": -3,
      "name": "Empty"
    },
    {
      "x": -8,
      "y": 6,
      "z": -3,
      "name": "Empty"
    },
    {
      "x": -8,
      "y": 7,
      "z": -3,
      "name": "Plant_Leaves_Wisteria_Wild",
      "support": 15
    },
    {
      "x": -8,
      "y": 8,
      "z": -3,
      "name": "Empty"
    },
    {
      "x": -8,
      "y": 9,
      "z": -3,
      "name": "Rock_CastIron"
    },
    {
      "x": -8,
      "y": 0,
      "z": -2,
      "name": "Rock_CastIron_Brick"
    },
    {
      "x": -8,
      "y": 1,
      "z": -2,
      "name": "Rock_CastIron_Brick"
    },
    {
      "x": -8,
      "y": 2,
      "z": -2,
      "name": "Rock_CastIron_Brick"
    },
    {
      "x": -8,
      "y": 3,
      "z": -2,
      "name": "Rock_CastIron_Brick"
    },
    {
      "x": -8,
      "y": 4,
      "z": -2,
      "name": "Rock_Shale_Cobble_Wall",
      "rotation": 1
    },
    {
      "x": -8,
      "y": 5,
      "z": -2,
      "name": "Empty"
    },
    {
      "x": -8,
      "y": 6,
      "z": -2,
      "name": "Empty"
    },
    {
      "x": -8,
      "y": 7,
      "z": -2,
      "name": "Plant_Leaves_Wisteria_Wild",
      "support": 15
    },
    {
      "x": -8,
      "y": 8,
      "z": -2,
      "name": "Plant_Leaves_Wisteria_Wild",
      "support": 15
    },
    {
      "x": -8,
      "y": 9,
      "z": -2,
      "name": "Rock_CastIron"
    },
    {
      "x": -8,
      "y": 0,
      "z": -1,
      "name": "Rock_CastIron_Brick"
    },
    {
      "x": -8,
      "y": 1,
      "z": -1,
      "name": "Rock_CastIron_Brick"
    },
    {
      "x": -8,
      "y": 2,
      "z": -1,
      "name": "Rock_CastIron_Brick"
    },
    {
      "x": -8,
      "y": 3,
      "z": -1,
      "name": "Rock_CastIron_Brick"
    },
    {
      "x": -8,
      "y": 4,
      "z": -1,
      "name": "Rock_Shale_Cobble_Wall",
      "rotation": 1
    },
    {
      "x": -8,
      "y": 5,
      "z": -1,
      "name": "Empty"
    },
    {
      "x": -8,
      "y": 6,
      "z": -1,
      "name": "Empty"
    },
    {
      "x": -8,
      "y": 7,
      "z": -1,
      "name": "Empty"
    },
    {
      "x": -8,
      "y": 8,
      "z": -1,
      "name": "Empty"
    },
    {
      "x": -8,
      "y": 9,
      "z": -1,
      "name": "Rock_CastIron"
    },
    {
      "x": -8,
      "y": 0,
      "z": 0,
      "name": "Rock_CastIron_Brick"
    },
    {
      "x": -8,
      "y": 1,
      "z": 0,
      "name": "Rock_CastIron_Brick"
    },
    {
      "x": -8,
      "y": 2,
      "z": 0,
      "name": "Rock_CastIron_Brick"
    },
    {
      "x": -8,
      "y": 3,
      "z": 0,
      "name": "Rock_CastIron_Brick"
    },
    {
      "x": -8,
      "y": 4,
      "z": 0,
      "name": "Rock_Shale_Cobble_Wall",
      "rotation": 1
    },
    {
      "x": -8,
      "y": 5,
      "z": 0,
      "name": "Empty"
    },
    {
      "x": -8,
      "y": 6,
      "z": 0,
      "name": "Empty"
    },
    {
      "x": -8,
      "y": 7,
      "z": 0,
      "name": "Empty"
    },
    {
      "x": -8,
      "y": 8,
      "z": 0,
      "name": "Empty"
    },
    {
      "x": -8,
      "y": 9,
