{
  "version": 8,
  "blockIdVersion": 11,
  "anchorX": 0,
  "anchorY": 0,
  "anchorZ": 0,
  "blocks": [
    {
      "x": -26,
      "y": 0,
      "z": -22,
      "name": "Rock_CastIron_Cobble"
    },
    {
      "x": -26,
      "y": 1,
      "z": -22,
      "name": "Rock_CastIron_Brick_Smooth"
    },
    {
      "x": -26,
      "y": 2,
      "z": -22,
      "name": "Rock_CastIron_Brick_Smooth"
    },
    {
      "x": -26,
      "y": 3,
      "z": -22,
      "name": "Rock_CastIron_Brick_Smooth"
    },
    {
      "x": -26,
      "y": 4,
      "z": -22,
      "name": "Rock_CastIron_Brick_Smooth"
    },
    {
      "x": -26,
      "y": 5,
      "z": -22,
      "name": "Rock_CastIron_Brick_Ornate"
    },
    {
      "x": -26,
      "y": 6,
      "z": -22,
      "name": "Rock_CastIron_Brick_Smooth"
    },
    {
      "x": -26,
      "y": 7,
      "z": -22,
      "name": "Rock_CastIron_Brick_Smooth"
    },
    {
      "x": -26,
      "y": 8,
      "z": -22,
      "name": "Rock_CastIron_Brick_Smooth"
    },
    {
      "x": -26,
      "y": 9,
      "z": -22,
      "name": "Rock_CastIron_Brick_Smooth"
    },
    {
      "x": -26,
      "y": 10,
      "z": -22,
      "name": "Rock_CastIron_Brick_Smooth"
    },
    {
      "x": -26,
      "y": 11,
      "z": -22,
      "name": "Rock_CastIron_Brick_Smooth"
    },
    {
      "x": -26,
      "y": 12,
      "z": -22,
      "name": "Rock_CastIron_Brick_Smooth"
    },
    {
      "x": -26,
      "y": 13,
      "z": -22,
      "name": "Rock_CastIron_Brick_Smooth"
    },
    {
      "x": -26,
      "y": 14,
      "z": -22,
      "name": "Rock_CastIron_Brick_Ornate"
    },
    {
      "x": -26,
      "y": 0,
      "z": -21,
      "name": "Rock_CastIron_Cobble"
    },
    {
      "x": -26,
      "y": 1,
      "z": -21,
      "name": "Rock_CastIron_Brick_Smooth"
    },
    {
      "x": -26,
      "y": 2,
      "z": -21,
      "name": "Rock_CastIron_Brick_Smooth"
    },
    {
      "x": -26,
      "y": 3,
      "z": -21,
      "name": "Rock_CastIron_Brick_Smooth"
    },
    {
      "x": -26,
      "y": 4,
      "z": -21,
      "name": "Rock_CastIron_Brick_Smooth"
    },
    {
      "x": -26,
      "y": 5,
      "z": -21,
      "name": "Rock_CastIron_Brick_Decorative"
    },
    {
      "x": -26,
      "y": 6,
      "z": -21,
      "name": "Rock_CastIron_Brick_Smooth"
    },
    {
      "x": -26,
      "y": 7,
      "z": -21,
      "name": "Rock_CastIron_Brick_Smooth"
    },
    {
      "x": -26,
      "y": 8,
      "z": -21,
      "name": "Rock_CastIron_Brick_Smooth"
    },
    {
      "x": -26,
      "y": 9,
      "z": -21,
      "name": "Rock_CastIron_Brick_Smooth"
    },
    {
      "x": -26,
      "y": 10,
      "z": -21,
      "name": "Rock_CastIron_Brick_Smooth"
    },
    {
      "x": -26,
      "y": 11,
      "z": -21,
      "name": "Rock_CastIron_Brick_Smooth"
    },
    {
      "x": -26,
      "y": 12,
      "z": -21,
      "name": "Rock_CastIron_Brick_Smooth"
    },
    {
      "x": -26,
      "y": 13,
      "z": -21,
      "name": "Rock_CastIron_Brick_Smooth"
    },
    {
      "x": -26,
      "y": 14,
      "z": -21,
      "name": "Rock_CastIron_Brick_Decorative"
    },
    {
      "x": -26,
      "y": 0,
      "z": -20,
      "name": "Rock_CastIron_Cobble"
    },
    {
      "x": -26,
      "y": 1,
      "z": -20,
      "name": "Rock_CastIron_Brick_Smooth"
    },
    {
      "x": -26,
      "y": 2,
      "z": -20,
      "name": "Rock_CastIron_Brick_Smooth"
    },
    {
      "x": -26,
      "y": 3,
      "z": -20,
      "name": "Rock_CastIron_Brick_Smooth"
    },
    {
      "x": -26,
      "y": 4,
      "z": -20,
      "name": "Rock_CastIron_Brick_Smooth"
    },
    {
      "x": -26,
      "y": 5,
      "z": -20,
      "name": "Rock_CastIron_Brick_Decorative"
    },
    {
      "x": -26,
      "y": 6,
      "z": -20,
      "name": "Rock_CastIron_Brick_Smooth"
    },
    {
      "x": -26,
      "y": 7,
      "z": -20,
      "name": "Rock_CastIron_Brick_Smooth"
    },
    {
      "x": -26,
      "y": 8,
      "z": -20,
      "name": "Rock_CastIron_Brick_Smooth"
    },
    {
      "x": -26,
      "y": 9,
      "z": -20,
      "name": "Rock_CastIron_Brick_Smooth"
    },
    {
      "x": -26,
      "y": 10,
      "z": -20,
      "name": "Rock_CastIron_Brick_Smooth"
    },
    {
      "x": -26,
      "y": 11,
      "z": -20,
      "name": "Rock_CastIron_Brick_Smooth"
    },
    {
      "x": -26,
      "y": 12,
      "z": -20,
      "name": "Rock_CastIron_Brick_Smooth"
    },
    {
      "x": -26,
      "y": 13,
      "z": -20,
      "name": "Rock_CastIron_Brick_Smooth"
    },
    {
      "x": -26,
      "y": 14,
      "z": -20,
      "name": "Rock_CastIron_Brick_Decorative"
    },
    {
      "x": -26,
      "y": 0,
      "z": -19,
      "name": "Rock_CastIron_Cobble"
    },
    {
      "x": -26,
      "y": 1,
      "z": -19,
      "name": "Rock_CastIron_Brick_Smooth"
    },
    {
      "x": -26,
      "y": 2,
      "z": -19,
      "name": "Rock_CastIron_Brick_Smooth"
    },
    {
      "x": -26,
      "y": 3,
      "z": -19,
      "name": "Rock_CastIron_Brick_Smooth"
    },
    {
      "x": -26,
      "y": 4,
      "z": -19,
      "name": "Rock_CastIron_Brick_Smooth"
    },
    {
      "x": -26,
      "y": 5,
      "z": -19,
      "name": "Rock_CastIron_Brick_Decorative"
    },
    {
      "x": -26,
      "y": 6,
      "z": -19,
      "name": "Rock_CastIron_Brick_Smooth"
    },
    {
      "x": -26,
      "y": 7,
      "z": -19,
      "name": "Rock_CastIron_Brick_Smooth"
    },
    {
      "x": -26,
      "y": 8,
      "z": -19,
      "name": "Rock_CastIron_Brick_Smooth"
    },
    {
      "x": -26,
      "y": 9,
      "z": -19,
      "name": "Rock_CastIron_Brick_Smooth"
    },
    {
      "x": -26,
      "y": 10,
      "z": -19,
      "name": "Rock_CastIron_Brick_Smooth"
    },
    {
      "x": -26,
      "y": 11,
      "z": -19,
      "name": "Rock_CastIron_Brick_Smooth"
    },
    {
      "x": -26,
      "y": 12,
      "z": -19,
      "name": "Rock_CastIron_Brick_Smooth"
    },
    {
      "x": -26,
      "y": 13,
      "z": -19,
      "name": "Rock_CastIron_Brick_Smooth"
    },
    {
      "x": -26,
      "y": 14,
      "z": -19,
      "name": "Rock_CastIron_Brick_Decorative"
    },
    {
      "x": -26,
      "y": 0,
      "z": -18,
      "name": "Rock_CastIron_Cobble"
    },
    {
      "x": -26,
      "y": 1,
      "z": -18,
      "name": "Rock_CastIron_Brick_Smooth"
    },
    {
      "x": -26,
      "y": 2,
      "z": -18,
      "name": "Rock_CastIron_Brick_Smooth"
    },
    {
      "x": -26,
      "y": 3,
      "z": -18,
      "name": "Rock_CastIron_Brick_Smooth"
    },
    {
      "x": -26,
      "y": 4,
      "z": -18,
      "name": "Rock_CastIron_Brick_Smooth"
    },
    {
      "x": -26,
      "y": 5,
      "z": -18,
      "name": "Rock_CastIron_Brick_Decorative"
    },
    {
      "x": -26,
      "y": 6,
      "z": -18,
      "name": "Rock_CastIron_Brick_Smooth"
    },
    {
      "x": -26,
      "y": 7,
      "z": -18,
      "name": "Rock_CastIron_Brick_Smooth"
    },
    {
      "x": -26,
      "y": 8,
      "z": -18,
      "name": "Rock_CastIron_Brick_Smooth"
    },
    {
      "x": -26,
      "y": 9,
      "z": -18,
      "name": "Rock_CastIron_Brick_Smooth"
    },
    {
      "x": -26,
      "y": 10,
      "z": -18,
      "name": "Rock_CastIron_Brick_Smooth"
    },
    {
      "x": -26,
      "y": 11,
      "z": -18,
      "name": "Rock_CastIron_Brick_Smooth"
    },
    {
      "x": -26,
      "y": 12,
      "z": -18,
      "name": "Rock_CastIron_Brick_Smooth"
    },
    {
      "x": -26,
      "y": 13,
      "z": -18,
      "name": "Rock_CastIron_Brick_Smooth"
    },
    {
      "x": -26,
      "y": 14,
      "z": -18,
      "name": "Rock_CastIron_Brick_Decorative"
    },
    {
      "x": -26,
      "y": 0,
      "z": -17,
      "name": "Rock_CastIron_Cobble"
    },
    {
      "x": -26,
      "y": 1,
      "z": -17,
      "name": "Rock_CastIron_Brick_Smooth"
    },
    {
      "x": -26,
      "y": 2,
      "z": -17,
      "name": "Rock_CastIron_Brick_Smooth"
    },
    {
      "x": -26,
      "y": 3,
      "z": -17,
      "name": "Rock_CastIron_Brick_Smooth"
    },
    {
      "x": -26,
      "y": 4,
      "z": -17,
      "name": "Rock_CastIron_Brick_Smooth"
    },
    {
      "x": -26,
      "y": 5,
      "z": -17,
      "name": "Rock_CastIron_Brick_Decorative"
    },
    {
      "x": -26,
      "y": 6,
      "z": -17,
      "name": "Rock_CastIron_Brick_Smooth"
    },
    {
      "x": -26,
      "y": 7,
      "z": -17,
      "name": "Rock_CastIron_Brick_Smooth"
    },
    {
      "x": -26,
      "y": 8,
      "z": -17,
      "name": "Rock_CastIron_Brick_Smooth"
    },
    {
      "x": -26,
      "y": 9,
      "z": -17,
      "name": "Rock_CastIron_Brick_Smooth"
    },
    {
      "x": -26,
      "y": 10,
      "z": -17,
      "name": "Rock_CastIron_Brick_Smooth"
    },
    {
      "x": -26,
      "y": 11,
      "z": -17,
      "name": "Rock_CastIron_Brick_Smooth"
    },
    {
      "x": -26,
      "y": 12,
      "z": -17,
      "name": "Rock_CastIron_Brick_Smooth"
    },
    {
      "x": -26,
      "y": 13,
      "z": -17,
      "name": "Rock_CastIron_Brick_Smooth"
    },
    {
      "x": -26,
      "y": 14,
      "z": -17,
      "name": "Rock_CastIron_Brick_Decorative"
    },
    {
      "x": -26,
      "y": 0,
      "z": -16,
      "name": "Rock_CastIron_Cobble"
    },
    {
      "x": -26,
      "y": 1,
      "z": -16,
      "name": "Rock_CastIron_Brick_Smooth"
    },
    {
      "x": -26,
      "y": 2,
      "z": -16,
      "name": "Rock_CastIron_Brick_Smooth"
    },
    {
      "x": -26,
      "y": 3,
      "z": -16,
      "name": "Rock_CastIron_Brick_Smooth"
    },
    {
      "x": -26,
      "y": 4,
      "z": -16,
      "name": "Rock_CastIron_Brick_Smooth"
    },
    {
      "x": -26,
      "y": 5,
      "z": -16,
      "name": "Rock_CastIron_Brick_Decorative"
    },
    {
      "x": -26,
      "y": 6,
      "z": -16,
      "name": "Rock_CastIron_Brick_Smooth"
    },
    {
      "x": -26,
      "y": 7,
      "z": -16,
      "name": "Rock_CastIron_Brick_Smooth"
    },
    {
      "x": -26,
      "y": 8,
      "z": -16,
      "name": "Rock_CastIron_Brick_Smooth"
    },
    {
      "x": -26,
      "y": 9,
      "z": -16,
      "name": "Rock_CastIron_Brick_Smooth"
    },
    {
      "x": -26,
      "y": 10,
      "z": -16,
      "name": "Rock_CastIron_Brick_Smooth"
    },
    {
      "x": -26,
      "y": 11,
      "z": -16,
      "name": "Rock_CastIron_Brick_Smooth"
    },
    {
      "x": -26,
      "y": 12,
      "z": -16,
      "name": "Rock_CastIron_Brick_Smooth"
    },
    {
      "x": -26,
      "y": 13,
      "z": -16,
      "name": "Rock_CastIron_Brick_Smooth"
    },
    {
      "x": -26,
      "y": 14,
      "z": -16,
      "name": "Rock_CastIron_Brick_Decorative"
    },
    {
      "x": -26,
      "y": 0,
      "z": -15,
      "name": "Rock_CastIron_Cobble"
    },
    {
      "x": -26,
      "y": 1,
      "z": -15,
      "name": "Rock_CastIron_Brick_Smooth"
    },
    {
      "x": -26,
      "y": 2,
      "z": -15,
      "name": "Rock_CastIron_Brick_Smooth"
    },
    {
      "x": -26,
      "y": 3,
      "z": -15,
      "name": "Rock_CastIron_Brick_Smooth"
    },
    {
      "x": -26,
      "y": 4,
      "z": -15,
      "name": "Rock_CastIron_Brick_Smooth"
    },
    {
      "x": -26,
      "y": 5,
      "z": -15,
      "name": "Rock_CastIron_Brick_Decorative"
    },
    {
      "x": -26,
      "y": 6,
      "z": -15,
      "name": "Rock_CastIron_Brick_Smooth"
    },
    {
      "x": -26,
      "y": 7,
      "z": -15,
      "name": "Rock_CastIron_Brick_Smooth"
    },
    {
      "x": -26,
      "y": 8,
      "z": -15,
      "name": "Rock_CastIron_Brick_Smooth"
    },
    {
      "x": -26,
      "y": 9,
      "z": -15,
      "name": "Rock_CastIron_Brick_Smooth"
    },
    {
      "x": -26,
      "y": 10,
      "z": -15,
      "name": "Rock_CastIron_Brick_Smooth"
    },
    {
      "x": -26,
      "y": 11,
      "z": -15,
      "name": "Rock_CastIron_Brick_Smooth"
    },
    {
      "x": -26,
      "y": 12,
      "z": -15,
      "name": "Rock_CastIron_Brick_Smooth"
    },
    {
      "x": -26,
      "y": 13,
      "z": -15,
      "name": "Rock_CastIron_Brick_Smooth"
    },
    {
      "x": -26,
      "y": 14,
      "z": -15,
      "name": "Rock_CastIron_Brick_Decorative"
    },
    {
      "x": -26,
      "y": 0,
      "z": -14,
      "name": "Rock_CastIron_Cobble"
    },
    {
      "x": -26,
      "y": 1,
      "z": -14,
      "name": "Rock_CastIron_Brick_Smooth"
    },
    {
      "x": -26,
      "y": 2,
      "z": -14,
      "name": "Rock_CastIron_Brick_Smooth"
    },
    {
      "x": -26,
      "y": 3,
      "z": -14,
      "name": "Rock_CastIron_Brick_Smooth"
    },
    {
      "x": -26,
      "y": 4,
      "z": -14,
      "name": "Rock_CastIron_Brick_Smooth"
    },
    {
      "x": -26,
      "y": 5,
      "z": -14,
      "name": "Rock_CastIron_Brick_Decorative"
    },
    {
      "x": -26,
      "y": 6,
      "z": -14,
      "name": "Rock_CastIron_Brick_Smooth"
    },
    {
      "x": -26,
      "y": 7,
      "z": -14,
      "name": "Rock_CastIron_Brick_Smooth"
    },
    {
      "x": -26,
      "y": 8,
      "z": -14,
      "name": "Rock_CastIron_Brick_Smooth"
    },
    {
      "x": -26,
      "y": 9,
      "z": -14,
      "name": "Rock_CastIron_Brick_Smooth"
    },
    {
      "x": -26,
      "y": 10,
      "z": -14,
      "name": "Rock_CastIron_Brick_Smooth"
    },
    {
      "x": -26,
      "y": 11,
      "z": -14,
      "name": "Rock_CastIron_Brick_Smooth"
    },
    {
      "x": -26,
      "y": 12,
      "z": -14,
      "name": "Rock_CastIron_Brick_Smooth"
    },
    {
      "x": -26,
      "y": 13,
      "z": -14,
      "name": "Rock_CastIron_Brick_Smooth"
    },
    {
      "x": -26,
      "y": 14,
      "z": -14,
      "name": "Rock_CastIron_Brick_Decorative"
    },
    {
      "x": -26,
      "y": 0,
      "z": -13,
      "name": "Rock_CastIron_Cobble"
    },
    {
      "x": -26,
      "y": 1,
      "z": -13,
      "name": "Rock_CastIron_Brick_Smooth"
    },
    {
      "x": -26,
      "y": 2,
      "z": -13,
      "name": "Rock_CastIron_Brick_Smooth"
    },
    {
      "x": -26,
      "y": 3,
      "z": -13,
      "name": "Rock_CastIron_Brick_Smooth"
    },
    {
      "x": -26,
      "y": 4,
      "z": -13,
      "name": "Rock_CastIron_Brick_Smooth"
    },
    {
      "x": -26,
      "y": 5,
      "z": -13,
      "name": "Rock_CastIron_Brick_Decorative"
    },
    {
      "x": -26,
      "y": 6,
      "z": -13,
      "name": "Rock_CastIron_Brick_Smooth"
    },
    {
      "x": -26,
      "y": 7,
      "z": -13,
      "name": "Rock_CastIron_Brick_Smooth"
    },
    {
      "x": -26,
      "y": 8,
      "z": -13,
      "name": "Rock_CastIron_Brick_Smooth"
    },
    {
      "x": -26,
      "y": 9,
      "z": -13,
      "name": "Rock_CastIron_Brick_Smooth"
    },
    {
      "x": -26,
      "y": 10,
      "z": -13,
      "name": "Rock_CastIron_Brick_Smooth"
    },
    {
      "x": -26,
      "y": 11,
      "z": -13,
      "name": "Rock_CastIron_Brick_Smooth"
    },
    {
      "x": -26,
      "y": 12,
      "z": -13,
      "name": "Rock_CastIron_Brick_Smooth"
    },
    {
      "x": -26,
      "y": 13,
      "z": -13,
      "name": "Rock_CastIron_Brick_Smooth"
    },
    {
      "x": -26,
      "y": 14,
      "z": -13,
      "name": "Rock_CastIron_Brick_Decorative"
    },
    {
      "x": -26,
      "y": 0,
      "z": -12,
      "name": "Rock_CastIron_Cobble"
    },
    {
      "x": -26,
      "y": 1,
      "z": -12,
      "name": "Rock_CastIron_Brick_Smooth"
    },
    {
      "x": -26,
      "y": 2,
      "z": -12,
      "name": "Rock_CastIron_Brick_Smooth"
    },
    {
      "x": -26,
      "y": 3,
      "z": -12,
      "name": "Rock_CastIron_Brick_Smooth"
    },
    {
      "x": -26,
      "y": 4,
      "z": -12,
      "name": "Rock_CastIron_Brick_Smooth"
    },
    {
      "x": -26,
      "y": 5,
      "z": -12,
      "name": "Rock_CastIron_Brick_Decorative"
    },
    {
      "x": -26,
      "y": 6,
      "z": -12,
      "name": "Rock_CastIron_Brick_Smooth"
    },
    {
      "x": -26,
      "y": 7,
      "z": -12,
      "name": "Rock_CastIron_Brick_Smooth"
    },
    {
      "x": -26,
      "y": 8,
      "z": -12,
      "name": "Rock_CastIron_Brick_Smooth"
    },
    {
      "x": -26,
      "y": 9,
      "z": -12,
      "name": "Rock_CastIron_Brick_Smooth"
    },
    {
      "x": -26,
      "y": 10,
      "z": -12,
      "name": "Rock_CastIron_Brick_Smooth"
    },
    {
      "x": -26,
      "y": 11,
      "z": -12,
      "name": "Rock_CastIron_Brick_Smooth"
    },
    {
      "x": -26,
      "y": 12,
      "z": -12,
      "name": "Rock_CastIron_Brick_Smooth"
    },
    {
      "x": -26,
      "y": 13,
      "z": -12,
      "name": "Rock_CastIron_Brick_Smooth"
    },
    {
      "x": -26,
      "y": 14,
      "z": -12,
      "name": "Rock_CastIron_Brick_Decorative"
    },
    {
      "x": -26,
      "y": 0,
      "z": -11,
      "name": "Rock_CastIron_Cobble"
    },
    {
      "x": -26,
      "y": 1,
      "z": -11,
      "name": "Rock_CastIron_Brick_Smooth"
    },
    {
      "x": -26,
      "y": 2,
      "z": -11,
      "name": "Rock_CastIron_Brick_Smooth"
    },
    {
      "x": -26,
      "y": 3,
      "z": -11,
      "name": "Rock_CastIron_Brick_Smooth"
    },
    {
      "x": -26,
      "y": 4,
      "z": -11,
      "name": "Rock_CastIron_Brick_Smooth"
    },
    {
      "x": -26,
      "y": 5,
      "z": -11,
      "name": "Rock_CastIron_Brick_Decorative"
    },
    {
      "x": -26,
      "y": 6,
      "z": -11,
      "name": "Rock_CastIron_Brick_Smooth"
    },
    {
      "x": -26,
      "y": 7,
      "z": -11,
      "name": "Rock_CastIron_Brick_Smooth"
    },
    {
      "x": -26,
      "y": 8,
      "z": -11,
      "name": "Rock_CastIron_Brick_Smooth"
    },
    {
      "x": -26,
      "y": 9,
      "z": -11,
      "name": "Rock_CastIron_Brick_Smooth"
    },
    {
      "x": -26,
      "y": 10,
      "z": -11,
      "name": "Rock_CastIron_Brick_Smooth"
    },
    {
      "x": -26,
      "y": 11,
      "z": -11,
      "name": "Rock_CastIron_Brick_Smooth"
    },
    {
      "x": -26,
      "y": 12,
      "z": -11,
      "name": "Rock_CastIron_Brick_Smooth"
    },
    {
      "x": -26,
      "y": 13,
      "z": -11,
      "name": "Rock_CastIron_Brick_Smooth"
    },
    {
      "x": -26,
      "y": 14,
      "z": -11,
      "name": "Rock_CastIron_Brick_Decorative"
    },
    {
      "x": -26,
      "y": 0,
      "z": -10,
      "name": "Rock_CastIron_Cobble"
    },
    {
      "x": -26,
      "y": 1,
      "z": -10,
      "name": "Rock_CastIron_Brick_Smooth"
    },
    {
      "x": -26,
      "y": 2,
      "z": -10,
      "name": "Rock_CastIron_Brick_Smooth"
    },
    {
      "x": -26,
      "y": 3,
      "z": -10,
      "name": "Rock_CastIron_Brick_Smooth"
    },
    {
      "x": -26,
      "y": 4,
      "z": -10,
      "name": "Rock_CastIron_Brick_Smooth"
    },
    {
      "x": -26,
      "y": 5,
      "z": -10,
      "name": "Rock_CastIron_Brick_Decorative"
    },
    {
      "x": -26,
      "y": 6,
      "z": -10,
      "name": "Rock_CastIron_Brick_Smooth"
    },
    {
      "x": -26,
      "y": 7,
      "z": -10,
      "name": "Rock_CastIron_Brick_Smooth"
    },
    {
      "x": -26,
      "y": 8,
      "z": -10,
      "name": "Rock_CastIron_Brick_Smooth"
    },
    {
      "x": -26,
      "y": 9,
      "z": -10,
      "name": "Rock_CastIron_Brick_Smooth"
    },
    {
      "x": -26,
      "y": 10,
      "z": -10,
      "name": "Rock_CastIron_Brick_Smooth"
    },
    {
      "x": -26,
      "y": 11,
      "z": -10,
      "name": "Rock_CastIron_Brick_Smooth"
    },
    {
      "x": -26,
      "y": 12,
      "z": -10,
      "name": "Rock_CastIron_Brick_Smooth"
    },
    {
      "x": -26,
      "y": 13,
      "z": -10,
      "name": "Rock_CastIron_Brick_Smooth"
    },
    {
      "x": -26,
      "y": 14,
      "z": -10,
      "name": "Rock_CastIron_Brick_Decorative"
    },
    {
      "x": -26,
      "y": 0,
      "z": -9,
      "name": "Rock_CastIron_Cobble"
    },
    {
      "x": -26,
      "y": 1,
      "z": -9,
      "name": "Rock_CastIron_Brick_Smooth"
    },
    {
      "x": -26,
      "y": 2,
      "z": -9,
      "name": "Rock_CastIron_Brick_Smooth"
    },
    {
      "x": -26,
      "y": 3,
      "z": -9,
      "name": "Rock_CastIron_Brick_Smooth"
    },
    {
      "x": -26,
      "y": 4,
      "z": -9,
      "name": "Rock_CastIron_Brick_Smooth"
    },
    {
      "x": -26,
      "y": 5,
      "z": -9,
      "name": "Rock_CastIron_Brick_Decorative"
    },
    {
      "x": -26,
      "y": 6,
      "z": -9,
      "name": "Rock_CastIron_Brick_Smooth"
    },
    {
      "x": -26,
      "y": 7,
      "z": -9,
      "name": "Rock_CastIron_Brick_Smooth"
    },
    {
      "x": -26,
      "y": 8,
      "z": -9,
      "name": "Rock_CastIron_Brick_Smooth"
    },
    {
      "x": -26,
      "y": 9,
      "z": -9,
      "name": "Rock_CastIron_Brick_Smooth"
    },
    {
      "x": -26,
      "y": 10,
      "z": -9,
      "name": "Rock_CastIron_Brick_Smooth"
    },
    {
      "x": -26,
      "y": 11,
      "z": -9,
      "name": "Rock_CastIron_Brick_Smooth"
    },
    {
      "x": -26,
      "y": 12,
      "z": -9,
      "name": "Rock_CastIron_Brick_Smooth"
    },
    {
      "x": -26,
      "y": 13,
      "z": -9,
      "name": "Rock_CastIron_Brick_Smooth"
    },
    {
      "x": -26,
      "y": 14,
      "z": -9,
      "name": "Rock_CastIron_Brick_Decorative"
    },
    {
      "x": -26,
      "y": 0,
      "z": -8,
      "name": "Rock_CastIron_Cobble"
    },
    {
      "x": -26,
      "y": 1,
      "z": -8,
      "name": "Rock_CastIron_Brick_Smooth"
    },
    {
      "x": -26,
      "y": 2,
      "z": -8,
      "name": "Rock_CastIron_Brick_Smooth"
    },
    {
      "x": -26,
      "y": 3,
      "z": -8,
      "name": "Rock_CastIron_Brick_Smooth"
    },
    {
      "x": -26,
      "y": 4,
      "z": -8,
      "name": "Rock_CastIron_Brick_Smooth"
    },
    {
      "x": -26,
      "y": 5,
      "z": -8,
      "name": "Rock_CastIron_Brick_Decorative"
    },
    {
      "x": -26,
      "y": 6,
      "z": -8,
      "name": "Rock_CastIron_Brick_Smooth"
    },
    {
      "x": -26,
      "y": 7,
      "z": -8,
      "name": "Rock_CastIron_Brick_Smooth"
    },
    {
      "x": -26,
      "y": 8,
      "z": -8,
      "name": "Rock_CastIron_Brick_Smooth"
    },
    {
      "x": -26,
      "y": 9,
      "z": -8,
      "name": "Rock_CastIron_Brick_Smooth"
    },
    {
      "x": -26,
      "y": 10,
      "z": -8,
      "name": "Rock_CastIron_Brick_Smooth"
    },
    {
      "x": -26,
      "y": 11,
      "z": -8,
      "name": "Rock_CastIron_Brick_Smooth"
    },
    {
      "x": -26,
      "y": 12,
      "z": -8,
      "name": "*Rock_Shale_Brick_Smooth_Half_State_Definitions_Block",
      "rotation": 8
    },
    {
      "x": -26,
      "y": 13,
      "z": -8,
      "name": "Rock_CastIron_Brick_Smooth"
    },
    {
      "x": -26,
      "y": 14,
      "z": -8,
      "name": "Rock_CastIron_Brick_Decorative"
    },
    {
      "x": -26,
      "y": 0,
      "z": -7,
      "name": "Rock_CastIron_Cobble"
    },
    {
      "x": -26,
      "y": 1,
      "z": -7,
      "name": "Rock_Shale_Brick_Pillar_Base"
    },
    {
      "x": -26,
      "y": 2,
      "z": -7,
      "name": "Rock_Shale_Brick_Pillar_Middle"
    },
    {
      "x": -26,
      "y": 3,
      "z": -7,
      "name": "Rock_Shale_Brick_Pillar_Middle"
    },
    {
      "x": -26,
      "y": 4,
      "z": -7,
      "name": "Rock_Shale_Brick_Pillar_Base",
      "rotation": 8
    },
    {
      "x": -26,
      "y": 5,
      "z": -7,
      "name": "Rock_CastIron_Brick_Ornate"
    },
    {
      "x": -26,
      "y": 6,
      "z": -7,
      "name": "Rock_Shale_Brick_Pillar_Base"
    },
    {
      "x": -26,
      "y": 7,
      "z": -7,
      "name": "Rock_Shale_Brick_Pillar_Middle"
    },
    {
      "x": -26,
      "y": 8,
      "z": -7,
      "name": "Rock_Shale_Brick_Pillar_Middle"
    },
    {
      "x": -26,
      "y": 9,
      "z": -7,
      "name": "Rock_Shale_Brick_Pillar_Middle"
    },
    {
      "x": -26,
      "y": 10,
      "z": -7,
      "name": "Rock_Shale_Brick_Pillar_Middle"
    },
    {
      "x": -26,
      "y": 11,
      "z": -7,
      "name": "Rock_Shale_Brick_Pillar_Base",
      "rotation": 8
    },
    {
      "x": -26,
      "y": 12,
      "z": -7,
      "name": "Rock_CastIron_Brick_Smooth"
    },
    {
      "x": -26,
      "y": 13,
      "z": -7,
      "name": "Rock_CastIron_Brick_Smooth"
    },
    {
      "x": -26,
      "y": 14,
      "z": -7,
      "name": "Rock_CastIron_Brick_Decorative"
    },
    {
      "x": -26,
      "y": 0,
      "z": -6,
      "name": "Rock_CastIron_Cobble"
    },
    {
      "x": -26,
      "y": 5,
      "z": -6,
      "name": "Rock_CastIron_Brick_Smooth"
    },
    {
      "x": -26,
      "y": 6,
      "z": -6,
      "name": "Rock_CastIron_Brick_Wall",
      "rotation": 1
    },
    {
      "x": -26,
      "y": 13,
      "z": -6,
      "name": "Rock_CastIron_Brick_Smooth"
    },
    {
      "x": -26,
      "y": 14,
      "z": -6,
      "name": "Rock_CastIron_Brick_Decorative"
    },
    {
      "x": -26,
      "y": 0,
      "z": -5,
      "name": "Rock_CastIron_Brick"
    },
    {
      "x": -26,
      "y": 5,
      "z": -5,
      "name": "Rock_Shale_Brick_Smooth_Half",
      "rotation": 8
    },
    {
      "x": -26,
      "y": 6,
      "z": -5,
      "name": "Rock_CastIron_Brick_Wall",
      "rotation": 1
    },
    {
      "x": -26,
      "y": 13,
      "z": -5,
      "name": "Rock_Shale_Brick_Smooth_Half",
      "rotation": 8
    },
    {
      "x": -26,
      "y": 14,
      "z": -5,
      "name": "Rock_CastIron_Brick_Decorative"
    },
    {
      "x": -26,
      "y": 0,
      "z": -4,
      "name": "Rock_CastIron_Brick"
    },
    {
      "x": -26,
      "y": 5,
      "z": -4,
      "name": "Rock_CastIron_Brick_Smooth"
    },
    {
      "x": -26,
      "y": 6,
      "z": -4,
      "name": "Rock_CastIron_Brick_Wall",
      "rotation": 1
    },
    {
      "x": -26,
      "y": 13,
      "z": -4,
      "name": "Rock_CastIron_Brick_Smooth"
    },
    {
      "x": -26,
      "y": 14,
      "z": -4,
      "name": "Rock_CastIron_Brick_Decorative"
    },
    {
      "x": -26,
      "y": 0,
      "z": -3,
      "name": "Rock_CastIron_Brick"
    },
    {
      "x": -26,
      "y": 1,
      "z": -3,
      "name": "Rock_Shale_Brick_Pillar_Base"
    },
    {
      "x": -26,
      "y": 2,
      "z": -3,
      "name": "Rock_Shale_Brick_Pillar_Middle"
    },
    {
      "x": -26,
      "y": 3,
      "z": -3,
      "name": "Rock_Shale_Brick_Pillar_Middle"
    },
    {
      "x": -26,
      "y": 4,
      "z": -3,
      "name": "Rock_Shale_Brick_Pillar_Base",
      "rotation": 8
    },
    {
      "x": -26,
      "y": 5,
      "z": -3,
      "name": "Rock_CastIron_Brick_Ornate"
    },
    {
      "x": -26,
      "y": 6,
      "z": -3,
      "name": "Rock_Shale_Brick_Pillar_Base"
    },
    {
      "x": -26,
      "y": 7,
      "z": -3,
      "name": "Rock_Shale_Brick_Pillar_Middle"
    },
    {
      "x": -26,
      "y": 8,
      "z": -3,
      "name": "Rock_Shale_Brick_Pillar_Middle"
    },
    {
      "x": -26,
      "y": 9,
      "z": -3,
      "name": "Rock_Shale_Brick_Pillar_Middle"
    },
    {
      "x": -26,
      "y": 10,
      "z": -3,
      "name": "Rock_Shale_Brick_Pillar_Middle"
    },
    {
      "x": -26,
      "y": 11,
      "z": -3,
      "name": "Rock_Shale_Brick_Pillar_Base",
      "rotation": 8
    },
    {
      "x": -26,
      "y": 12,
      "z": -3,
      "name": "Rock_CastIron_Brick_Smooth"
    },
    {
      "x": -26,
      "y": 13,
      "z": -3,
      "name": "Rock_CastIron_Brick_Smooth"
    },
    {
      "x": -26,
      "y": 14,
      "z": -3,
      "name": "Rock_CastIron_Brick_Decorative"
    },
    {
      "x": -26,
      "y": 0,
      "z": -2,
      "name": "Rock_CastIron_Cobble"
    },
    {
      "x": -26,
      "y": 1,
      "z": -2,
      "name": "Rock_CastIron_Brick_Smooth"
    },
    {
      "x": -26,
      "y": 2,
      "z": -2,
      "name": "Rock_CastIron_Brick_Smooth"
    },
    {
      "x": -26,
      "y": 3,
      "z": -2,
      "name": "Rock_CastIron_Brick_Smooth"
    },
    {
      "x": -26,
      "y": 4,
      "z": -2,
      "name": "Rock_CastIron_Brick_Smooth"
    },
    {
      "x": -26,
      "y": 5,
      "z": -2,
      "name": "Rock_CastIron_Brick_Decorative"
    },
    {
      "x": -26,
      "y": 6,
      "z": -2,
      "name": "Rock_CastIron_Brick_Smooth"
    },
    {
      "x": -26,
      "y": 7,
      "z": -2,
      "name": "Rock_CastIron_Brick_Smooth"
    },
    {
      "x": -26,
      "y": 8,
      "z": -2,
      "name": "Rock_CastIron_Brick_Smooth"
    },
    {
      "x": -26,
      "y": 9,
      "z": -2,
      "name": "Rock_CastIron_Brick_Smooth"
    },
    {
      "x": -26,
      "y": 10,
      "z": -2,
      "name": "Rock_CastIron_Brick_Smooth"
    },
    {
      "x": -26,
      "y": 11,
      "z": -2,
      "name": "Rock_CastIron_Brick_Smooth"
    },
    {
      "x": -26,
      "y": 12,
      "z": -2,
      "name": "*Rock_Shale_Brick_Smooth_Half_State_Definitions_Block",
      "rotation": 8
    },
    {
      "x": -26,
      "y": 13,
      "z": -2,
      "name": "Rock_CastIron_Brick_Smooth"
    },
    {
      "x": -26,
      "y": 14,
      "z": -2,
      "name": "Rock_CastIron_Brick_Decorative"
    },
    {
      "x": -26,
      "y": 0,
      "z": -1,
      "name": "Rock_CastIron_Cobble"
    },
    {
      "x": -26,
      "y": 1,
      "z": -1,
      "name": "Rock_CastIron_Brick_Smooth"
    },
    {
      "x": -26,
      "y": 2,
      "z": -1,
      "name": "Rock_CastIron_Brick_Smooth"
    },
    {
      "x": -26,
      "y": 3,
      "z": -1,
      "name": "Rock_CastIron_Brick_Smooth"
    },
    {
      "x": -26,
      "y": 4,
      "z": -1,
      "name": "Rock_CastIron_Brick_Smooth"
    },
    {
      "x": -26,
      "y": 5,
      "z": -1,
      "name": "Rock_CastIron_Brick_Decorative"
    },
    {
      "x": -26,
      "y": 6,
      "z": -1,
      "name": "Rock_CastIron_Brick_Smooth"
    },
    {
      "x": -26,
      "y": 7,
      "z": -1,
      "name": "Rock_CastIron_Brick_Smooth"
    },
    {
      "x": -26,
      "y": 8,
      "z": -1,
      "name": "Rock_CastIron_Brick_Smooth"
    },
    {
      "x": -26,
      "y": 9,
      "z": -1,
      "name": "Rock_CastIron_Brick_Smooth"
    },
    {
      "x": -26,
      "y": 10,
      "z": -1,
      "name": "Rock_CastIron_Brick_Smooth"
    },
    {
      "x": -26,
      "y": 11,
      "z": -1,
      "name": "Rock_CastIron_Brick_Smooth"
    },
    {
      "x": -26,
      "y": 12,
      "z": -1,
      "name": "Rock_CastIron_Brick_Smooth"
    },
    {
      "x": -26,
      "y": 13,
      "z": -1,
      "name": "Rock_CastIron_Brick_Smooth"
    },
    {
      "x": -26,
      "y": 14,
      "z": -1,
      "name": "Rock_CastIron_Brick_Decorative"
    },
    {
      "x": -26,
      "y": 0,
      "z": 0,
      "name": "Rock_CastIron_Cobble"
    },
    {
      "x": -26,
      "y": 1,
      "z": 0,
      "name": "Rock_CastIron_Brick_Smooth"
    },
    {
      "x": -26,
      "y": 2,
      "z": 0,
      "name": "Rock_CastIron_Brick_Smooth"
    },
    {
      "x": -26,
      "y": 3,
      "z": 0,
      "name": "Rock_CastIron_Brick_Smooth"
    },
    {
      "x": -26,
      "y": 4,
      "z": 0,
      "name": "Rock_CastIron_Brick_Smooth"
    },
    {
      "x": -26,
      "y": 5,
      "z": 0,
      "name": "Rock_CastIron_Brick_Ornate"
    },
    {
      "x": -26,
      "y": 6,
      "z": 0,
      "name": "Rock_CastIron_Brick_Smooth"
    },
    {
      "x": -26,
      "y": 7,
      "z": 0,
      "name": "Rock_CastIron_Brick_Smooth"
    },
    {
      "x": -26,
      "y": 8,
      "z": 0,
      "name": "Rock_CastIron_Brick_Smooth"
    },
    {
      "x": -26,
      "y": 9,
      "z": 0,
      "name": "Rock_CastIron_Brick_Smooth"
    },
    {
      "x": -26,
      "y": 10,
      "z": 0,
      "name": "Rock_CastIron_Brick_Smooth"
    },
    {
      "x": -26,
      "y": 11,
      "z": 0,
      "name": "Rock_CastIron_Brick_Smooth"
    },
    {
      "x": -26,
      "y": 12,
      "z": 0,
      "name": "Rock_CastIron_Brick_Smooth"
    },
    {
      "x": -26,
      "y": 13,
      "z": 0,
      "name": "Rock_CastIron_Brick_Smooth"
    },
    {
      "x": -26,
      "y": 14,
      "z": 0,
      "name": "Rock_CastIron_Brick_Ornate"
    },
    {
      "x": -25,
      "y": 0,
      "z": -22,
      "name": "Rock_CastIron_Cobble"
    },
    {
      "x": -25,
      "y": 1,
      "z": -22,
      "name": "Rock_CastIron_Brick_Smooth"
    },
    {
      "x": -25,
      "y": 2,
      "z": -22,
      "name": "Rock_CastIron_Brick_Smooth"
    },
    {
      "x": -25,
      "y": 3,
      "z": -22,
      "name": "Rock_CastIron_Brick_Smooth"
    },
    {
      "x": -25,
      "y": 4,
      "z": -22,
      "name": "Rock_CastIron_Brick_Smooth"
    },
    {
      "x": -25,
      "y": 5,
      "z": -22,
      "name": "Rock_CastIron_Brick_Decorative"
    },
    {
      "x": -25,
      "y": 6,
      "z": -22,
      "name": "Rock_CastIron_Brick_Smooth"
    },
    {
      "x": -25,
      "y": 7,
      "z": -22,
      "name": "Rock_CastIron_Brick_Smooth"
    },
    {
      "x": -25,
      "y": 8,
      "z": -22,
      "name": "Rock_CastIron_Brick_Smooth"
    },
    {
      "x": -25,
      "y": 9,
      "z": -22,
      "name": "Rock_CastIron_Brick_Smooth"
    },
    {
      "x": -25,
      "y": 10,
      "z": -22,
      "name": "Rock_CastIron_Brick_Smooth"
    },
    {
      "x": -25,
      "y": 11,
      "z": -22,
      "name": "Rock_CastIron_Brick_Smooth"
    },
    {
      "x": -25,
      "y": 12,
      "z": -22,
      "name": "Rock_CastIron_Brick_Smooth"
    },
    {
      "x": -25,
      "y": 13,
      "z": -22,
      "name": "Rock_CastIron_Brick_Smooth"
    },
    {
      "x": -25,
      "y": 14,
      "z": -22,
      "name": "Rock_CastIron_Brick_Decorative"
    },
    {
      "x": -25,
      "y": 0,
      "z": -21,
      "name": "Rock_CastIron_Cobble"
    },
    {
      "x": -25,
      "y": 1,
      "z": -21,
      "name": "Rock_CastIron_Brick"
    },
    {
      "x": -25,
      "y": 2,
      "z": -21,
      "name": "Rock_CastIron_Brick"
    },
    {
      "x": -25,
      "y": 3,
      "z": -21,
      "name": "Rock_CastIron_Brick"
    },
    {
      "x": -25,
      "y": 4,
      "z": -21,
      "name": "Rock_CastIron_Brick"
    },
    {
      "x": -25,
      "y": 5,
      "z": -21,
      "name": "Rock_CastIron_Brick"
    },
    {
      "x": -25,
      "y": 6,
      "z": -21,
      "name": "Rock_CastIron_Brick_Smooth"
    },
    {
      "x": -25,
      "y": 7,
      "z": -21,
      "name": "Rock_CastIron_Brick_Smooth"
    },
    {
      "x": -25,
      "y": 8,
      "z": -21,
      "name": "Rock_CastIron_Brick_Smooth"
    },
    {
      "x": -25,
      "y": 9,
      "z": -21,
      "name": "Rock_CastIron_Brick_Smooth"
    },
    {
      "x": -25,
      "y": 10,
      "z": -21,
      "name": "Rock_CastIron_Brick_Smooth"
    },
    {
      "x": -25,
      "y": 11,
      "z": -21,
      "name": "Rock_CastIron_Brick_Smooth"
    },
    {
      "x": -25,
      "y": 12,
      "z": -21,
      "name": "Rock_CastIron_Brick_Smooth"
    },
    {
      "x": -25,
      "y": 13,
      "z": -21,
      "name": "Rock_CastIron_Brick_Smooth"
    },
    {
      "x": -25,
      "y": 14,
      "z": -21,
      "name": "Rock_CastIron_Brick"
    },
    {
      "x": -25,
      "y": 0,
      "z": -20,
      "name": "Rock_CastIron_Cobble"
    },
    {
      "x": -25,
      "y": 1,
      "z": -20,
      "name": "Rock_CastIron_Brick"
    },
    {
      "x": -25,
      "y": 2,
      "z": -20,
      "name": "Rock_CastIron_Brick"
    },
    {
      "x": -25,
      "y": 3,
      "z": -20,
      "name": "Rock_CastIron_Brick"
    },
    {
      "x": -25,
      "y": 4,
      "z": -20,
      "name": "Rock_CastIron_Brick"
    },
    {
      "x": -25,
      "y": 5,
      "z": -20,
      "name": "Rock_CastIron_Brick"
    },
    {
      "x": -25,
      "y": 6,
      "z": -20,
      "name": "Furniture_Human_Ruins_Desk",
      "rotation": 1
    },
    {
      "x": -25,
      "y": 7,
      "z": -20,
      "name": "Furniture_Human_Ruins_Desk",
      "rotation": 1
    },
    {
      "x": -25,
      "y": 9,
      "z": -20,
      "name": "Rock_CastIron_Brick_Smooth"
    },
    {
      "x": -25,
      "y": 10,
      "z": -20,
      "name": "Rock_CastIron_Brick_Smooth"
    },
    {
      "x": -25,
      "y": 11,
      "z": -20,
      "name": "Rock_CastIron_Brick_Smooth"
    },
    {
      "x": -25,
      "y": 12,
      "z": -20,
      "name": "Rock_CastIron_Brick_Smooth"
    },
    {
      "x": -25,
      "y": 13,
      "z": -20,
      "name": "Rock_CastIron_Brick_Smooth"
    },
    {
      "x": -25,
      "y": 14,
      "z": -20,
      "name": "Rock_CastIron_Brick"
    },
    {
      "x": -25,
      "y": 0,
      "z": -19,
      "name": "Rock_CastIron_Cobble"
    },
    {
      "x": -25,
      "y": 1,
      "z": -19,
      "name": "Rock_CastIron_Brick"
    },
    {
      "x": -25,
      "y": 2,
      "z": -19,
      "name": "Rock_CastIron_Brick"
    },
    {
      "x": -25,
      "y": 3,
      "z": -19,
      "name": "Rock_CastIron_Brick"
    },
    {
      "x": -25,
      "y": 4,
      "z": -19,
      "name": "Rock_CastIron_Brick"
    },
    {
      "x": -25,
      "y": 5,
      "z": -19,
      "name": "Rock_CastIron_Brick"
    },
    {
      "x": -25,
      "y": 6,
      "z": -19,
      "name": "Furniture_Human_Ruins_Desk",
      "filler": 32,
      "rotation": 1
    },
    {
      "x": -25,
      "y": 7,
      "z": -19,
      "name": "Furniture_Human_Ruins_Desk",
      "filler": 32,
      "rotation": 1
    },
    {
      "x": -25,
      "y": 8,
      "z": -19,
      "name": "Furniture_Human_Ruins_Pot_Small"
    },
    {
      "x": -25,
      "y": 9,
      "z": -19,
      "name": "Rock_Shale_Brick_Smooth_Half",
      "rotation": 5
    },
    {
      "x": -25,
      "y": 10,
      "z": -19,
      "name": "Rock_Shale_Brick_Smooth_Half",
      "rotation": 5
    },
    {
      "x": -25,
      "y": 11,
      "z": -19,
      "name": "Rock_CastIron_Brick_Smooth"
    },
    {
      "x": -25,
      "y": 12,
      "z": -19,
      "name": "Rock_CastIron_Brick_Smooth"
    },
    {
      "x": -25,
      "y": 13,
      "z": -19,
      "name": "Rock_CastIron_Brick_Smooth"
    },
    {
      "x": -25,
      "y": 14,
      "z": -19,
      "name": "Rock_CastIron_Brick"
    },
    {
      "x": -25,
      "y": 0,
      "z": -18,
      "name": "Rock_CastIron_Cobble"
    },
    {
      "x": -25,
      "y": 1,
      "z": -18,
      "name": "Rock_CastIron_Brick"
    },
    {
      "x": -25,
      "y": 2,
      "z": -18,
      "name": "Rock_CastIron_Brick"
    },
    {
      "x": -25,
      "y": 3,
      "z": -18,
      "name": "Rock_CastIron_Brick"
    },
    {
      "x": -25,
      "y": 4,
      "z": -18,
      "name": "Rock_CastIron_Brick"
    },
    {
      "x": -25,
      "y": 5,
      "z": -18,
      "name": "Rock_CastIron_Brick"
    },
    {
      "x": -25,
      "y": 6,
      "z": -18,
      "name": "Furniture_Human_Ruins_Desk",
      "rotation": 1
    },
    {
      "x": -25,
      "y": 10,
      "z": -18,
      "name": "Rock_Shale_Brick_Smooth_Half",
      "rotation": 5
    },
    {
      "x": -25,
      "y": 11,
      "z": -18,
      "name": "Rock_Shale_Brick_Smooth_Half",
      "rotation": 5
    },
    {
      "x": -25,
      "y": 12,
      "z": -18,
      "name": "Rock_CastIron_Brick_Smooth"
    },
    {
      "x": -25,
      "y": 13,
      "z": -18,
      "name": "Rock_CastIron_Brick_Smooth"
    },
    {
      "x": -25,
      "y": 14,
      "z": -18,
      "name": "Rock_CastIron_Brick"
    },
    {
      "x": -25,
      "y": 0,
      "z": -17,
      "name": "Rock_CastIron_Cobble"
    },
    {
      "x": -25,
      "y": 1,
      "z": -17,
      "name": "Rock_CastIron_Brick"
    },
    {
      "x": -25,
      "y": 2,
      "z": -17,
      "name": "Rock_CastIron_Brick"
    },
    {
      "x": -25,
      "y": 3,
      "z": -17,
      "name": "Rock_CastIron_Brick"
    },
    {
      "x": -25,
      "y": 4,
      "z": -17,
      "name": "Rock_CastIron_Brick"
    },
    {
      "x": -25,
      "y": 5,
      "z": -17,
      "name": "Rock_CastIron_Brick"
    },
    {
      "x": -25,
      "y": 6,
      "z": -17,
      "name": "Furniture_Human_Ruins_Desk",
      "filler": 32,
      "rotation": 1
    },
    {
      "x": -25,
      "y": 11,
      "z": -17,
      "name": "Rock_Shale_Brick_Smooth_Half",
      "rotation": 5
    },
    {
      "x": -25,
      "y": 12,
      "z": -17,
      "name": "Rock_CastIron_Brick_Smooth"
    },
    {
      "x": -25,
      "y": 13,
      "z": -17,
      "name": "Rock_CastIron_Brick_Smooth"
    },
    {
      "x": -25,
      "y": 14,
      "z": -17,
      "name": "Rock_CastIron_Brick"
    },
    {
      "x": -25,
      "y": 0,
      "z": -16,
      "name": "Rock_CastIron_Cobble"
    },
    {
      "x": -25,
      "y": 1,
      "z": -16,
      "name": "Rock_CastIron_Brick"
    },
    {
      "x": -25,
      "y": 2,
      "z": -16,
      "name": "Rock_CastIron_Brick"
    },
    {
      "x": -25,
      "y": 3,
      "z": -16,
      "name": "Rock_CastIron_Brick"
    },
    {
      "x": -25,
      "y": 4,
      "z": -16,
      "name": "Rock_CastIron_Brick"
    },
    {
      "x": -25,
      "y": 5,
      "z": -16,
      "name": "Rock_CastIron_Brick"
    },
    {
      "x": -25,
      "y": 6,
      "z": -16,
      "name": "*Rock_Shale_Brick_Wall_State_Definitions_Corner",
      "rotation": 1
    },
    {
      "x": -25,
      "y": 7,
      "z": -16,
      "name": "Rock_Shale_Brick_Beam"
    },
    {
      "x": -25,
      "y": 8,
      "z": -16,
      "name": "Rock_Shale_Brick_Beam"
    },
    {
      "x": -25,
      "y": 9,
      "z": -16,
      "name": "Rock_Shale_Brick_Beam"
    },
    {
      "x": -25,
      "y": 10,
      "z": -16,
      "name": "*Rock_Shale_Brick_Wall_State_Definitions_Corner",
      "rotation": 1
    },
    {
      "x": -25,
      "y": 11,
      "z": -16,
      "name": "Rock_Shale_Brick_Roof",
      "rotation": 3
    },
    {
      "x": -25,
      "y": 14,
      "z": -16,
      "name": "Rock_CastIron_Brick"
    },
    {
      "x": -25,
      "y": 0,
      "z": -15,
      "name": "Rock_CastIron_Cobble"
    },
    {
      "x": -25,
      "y": 1,
      "z": -15,
      "name": "Rock_CastIron_Brick"
    },
    {
      "x": -25,
      "y": 2,
      "z": -15,
      "name": "Rock_CastIron_Brick"
    },
    {
      "x": -25,
      "y": 3,
      "z": -15,
      "name": "Rock_CastIron_Brick"
    },
    {
      "x": -25,
      "y": 4,
      "z": -15,
      "name": "Rock_CastIron_Brick"
    },
    {
      "x": -25,
      "y": 5,
      "z": -15,
      "name": "Rock_CastIron_Brick"
    },
    {
      "x": -25,
      "y": 6,
      "z": -15,
      "name": "Rock_CastIron_Brick_Wall",
      "rotation": 1
    },
    {
      "x": -25,
      "y": 11,
      "z": -15,
      "name": "Rock_Shale_Brick_Roof",
      "rotation": 3
    },
    {
      "x": -25,
      "y": 14,
      "z": -15,
      "name": "Rock_CastIron_Brick"
    },
    {
      "x": -25,
      "y": 0,
      "z": -14,
      "name": "Rock_CastIron_Cobble"
    },
    {
      "x": -25,
      "y": 1,
      "z": -14,
      "name": "Rock_CastIron_Brick"
    },
    {
      "x": -25,
      "y": 2,
      "z": -14,
      "name": "Rock_CastIron_Brick"
    },
    {
      "x": -25,
      "y": 3,
      "z": -14,
      "name": "Rock_CastIron_Brick"
    },
    {
      "x": -25,
      "y": 4,
      "z": -14,
      "name": "Rock_CastIron_Brick"
    },
    {
      "x": -25,
      "y": 5,
      "z": -14,
      "name": "Rock_CastIron_Brick"
    },
    {
      "x": -25,
      "y": 6,
      "z": -14,
      "name": "Rock_CastIron_Brick_Wall",
      "rotation": 1
    },
    {
      "x": -25,
      "y": 11,
      "z": -14,
      "name": "Rock_Shale_Brick_Roof",
      "rotation": 3
    },
    {
      "x": -25,
      "y": 14,
      "z": -14,
      "name": "Rock_CastIron_Brick"
    },
    {
      "x": -25,
      "y": 0,
      "z": -13,
      "name": "Rock_CastIron_Cobble"
    },
    {
      "x": -25,
      "y": 1,
      "z": -13,
      "name": "Rock_CastIron_Brick"
    },
    {
      "x": -25,
      "y": 2,
      "z": -13,
      "name": "Rock_CastIron_Brick"
    },
    {
      "x": -25,
      "y": 3,
      "z": -13,
      "name": "Rock_CastIron_Brick"
    },
    {
      "x": -25,
      "y": 4,
      "z": -13,
      "name": "Rock_CastIron_Brick"
    },
    {
      "x": -25,
      "y": 5,
      "z": -13,
      "name": "Rock_CastIron_Brick"
    },
    {
      "x": -25,
      "y": 6,
      "z": -13,
      "name": "Rock_CastIron_Brick_Wall",
      "rotation": 1
    },
    {
      "x": -25,
      "y": 11,
      "z": -13,
      "name": "Rock_Shale_Brick_Roof",
      "rotation": 3
    },
    {
      "x": -25,
      "y": 14,
      "z": -13,
      "name": "Rock_CastIron_Brick"
    },
    {
      "x": -25,
      "y": 0,
      "z": -12,
      "name": "Rock_CastIron_Cobble"
    },
    {
      "x": -25,
      "y": 1,
      "z": -12,
      "name": "Rock_CastIron_Brick"
    },
    {
      "x": -25,
      "y": 2,
      "z": -12,
      "name": "Rock_CastIron_Brick"
    },
    {
      "x": -25,
      "y": 3,
      "z": -12,
      "name": "Rock_CastIron_Brick"
    },
    {
      "x": -25,
      "y": 4,
      "z": -12,
      "name": "Rock_CastIron_Brick"
    },
    {
      "x": -25,
      "y": 5,
      "z": -12,
      "name": "Rock_CastIron_Brick"
    },
    {
      "x": -25,
      "y": 6,
      "z": -12,
      "name": "*Rock_Shale_Brick_Wall_State_Definitions_Corner",
      "rotation": 2
    },
    {
      "x": -25,
      "y": 7,
      "z": -12,
      "name": "Rock_Shale_Brick_Beam"
    },
    {
      "x": -25,
      "y": 8,
      "z": -12,
      "name": "Rock_Shale_Brick_Beam"
    },
    {
      "x": -25,
      "y": 9,
      "z": -12,
      "name": "Rock_Shale_Brick_Beam"
    },
    {
      "x": -25,
      "y": 10,
      "z": -12,
      "name": "*Rock_Shale_Brick_Wall_State_Definitions_Corner",
      "rotation": 2
    },
    {
      "x": -25,
      "y": 11,
      "z": -12,
      "name": "Rock_Shale_Brick_Roof",
      "rotation": 3
    },
    {
      "x": -25,
      "y": 14,
      "z": -12,
      "name": "Rock_CastIron_Brick"
    },
    {
      "x": -25,
      "y": 0,
      "z": -11,
      "name": "Rock_CastIron_Cobble"
    },
    {
      "x": -25,
      "y": 1,
      "z": -11,
      "name": "Rock_CastIron_Brick"
    },
    {
      "x": -25,
      "y": 2,
      "z": -11,
      "name": "Rock_CastIron_Brick"
    },
    {
      "x": -25,
      "y": 3,
      "z": -11,
      "name": "Rock_CastIron_Brick"
    },
    {
      "x": -25,
      "y": 4,
      "z": -11,
      "name": "Rock_CastIron_Brick"
    },
    {
      "x": -25,
      "y": 5,
      "z": -11,
      "name": "Rock_CastIron_Brick"
    },
    {
      "x": -25,
      "y": 14,
      "z": -11,
      "name": "Rock_CastIron_Brick"
    },
    {
      "x": -25,
      "y": 0,
      "z": -10,
      "name": "Rock_CastIron_Cobble"
    },
    {
      "x": -25,
      "y": 1,
      "z": -10,
      "name": "Rock_CastIron_Brick"
    },
    {
      "x": -25,
      "y": 2,
      "z": -10,
      "name": "Rock_CastIron_Brick"
    },
    {
      "x": -25,
      "y": 3,
      "z": -10,
      "name": "Rock_CastIron_Brick"
    },
    {
      "x": -25,
      "y": 4,
      "z": -10,
      "name": "Rock_CastIron_Brick"
    },
    {
      "x": -25,
      "y": 5,
      "z": -10,
      "name": "Rock_CastIron_Brick"
    },
    {
      "x": -25,
      "y": 14,
      "z": -10,
      "name": "Rock_CastIron_Brick"
    },
    {
      "x": -25,
      "y": 0,
      "z": -9,
      "name": "Rock_CastIron_Cobble"
    },
    {
      "x": -25,
      "y": 1,
      "z": -9,
      "name": "Rock_CastIron_Brick_Smooth"
    },
    {
      "x": -25,
      "y": 2,
      "z": -9,
      "name": "Rock_CastIron_Brick_Smooth"
    },
    {
      "x": -25,
      "y": 3,
      "z": -9,
      "name": "Rock_CastIron_Brick_Smooth"
    },
    {
      "x": -25,
      "y": 4,
      "z": -9,
      "name": "Rock_CastIron_Brick_Smooth"
    },
    {
      "x": -25,
      "y": 5,
      "z": -9,
      "name": "Rock_CastIron_Cobble"
    },
    {
      "x": -25,
      "y": 6,
      "z": -9,
      "name": "Rock_CastIron_Brick_Ornate"
    },
    {
      "x": -25,
      "y": 7,
      "z": -9,
      "name": "Rock_Shale_Brick_Pillar_Base"
    },
    {
      "x": -25,
      "y": 8,
      "z": -9,
      "name": "Rock_Shale_Brick_Pillar_Middle"
    },
    {
      "x": -25,
      "y": 9,
      "z": -9,
      "name": "Rock_Shale_Brick_Pillar_Middle"
    },
    {
      "x": -25,
      "y": 10,
      "z": -9,
      "name": "Rock_Shale_Brick_Pillar_Middle"
    },
    {
      "x": -25,
      "y": 11,
      "z": -9,
      "name": "Rock_Shale_Brick_Pillar_Base",
      "rotation": 8
    },
    {
      "x": -25,
      "y": 12,
      "z": -9,
      "name": "Rock_CastIron_Brick_Smooth"
    },
    {
      "x": -25,
      "y": 13,
      "z": -9,
      "name": "Rock_CastIron_Brick_Smooth"
    },
    {
      "x": -25,
      "y": 14,
      "z": -9,
      "name": "Rock_CastIron_Brick_Decorative"
    },
    {
      "x": -25,
      "y": 0,
      "z": -8,
      "name": "Rock_CastIron_Cobble"
    },
    {
      "x": -25,
      "y": 1,
      "z": -8,
      "name": "Rock_Volcanic_Cobble"
    },
    {
      "x": -25,
      "y": 2,
      "z": -8,
      "name": "Rock_Volcanic_Cobble"
    },
    {
      "x": -25,
      "y": 3,
      "z": -8,
      "name": "Rock_Volcanic_Cobble"
    },
    {
      "x": -25,
      "y": 4,
      "z": -8,
      "name": "Rock_Volcanic_Cobble"
    },
    {
      "x": -25,
      "y": 5,
      "z": -8,
      "name": "Rock_Volcanic_Cobble"
    },
    {
      "x": -25,
      "y": 6,
      "z": -8,
      "name": "Rock_CastIron_Brick_Smooth"
    },
    {
      "x": -25,
      "y": 7,
      "z": -8,
      "name": "Rock_CastIron_Brick_Smooth"
    },
    {
      "x": -25,
      "y": 8,
      "z": -8,
      "name": "Rock_CastIron_Brick_Smooth"
    },
    {
      "x": -25,
      "y": 9,
      "z": -8,
      "name": "Rock_CastIron_Brick_Smooth"
    },
    {
      "x": -25,
      "y": 10,
      "z": -8,
      "name": "Rock_CastIron_Brick_Smooth"
    },
    {
      "x": -25,
      "y": 11,
      "z": -8,
      "name": "Rock_CastIron_Brick_Smooth"
    },
    {
      "x": -25,
      "y": 12,
      "z": -8,
      "name": "Rock_Volcanic_Cobble"
    },
    {
      "x": -25,
      "y": 13,
      "z": -8,
      "name": "Rock_Volcanic_Cobble"
    },
    {
      "x": -25,
      "y": 14,
      "z": -8,
      "name": "Rock_CastIron_Brick"
    },
    {
      "x": -25,
      "y": 0,
      "z": -7,
      "name": "Rock_CastIron_Cobble"
    },
    {
      "x": -25,
      "y": 1,
      "z": -7,
      "name": "Rock_CastIron_Brick_Smooth"
    },
    {
      "x": -25,
      "y": 2,
      "z": -7,
      "name": "Rock_CastIron_Brick_Smooth"
    },
    {
      "x": -25,
      "y": 3,
      "z": -7,
      "name": "Rock_CastIron_Brick_Smooth"
    },
    {
      "x": -25,
      "y": 4,
      "z": -7,
      "name": "Rock_CastIron_Brick_Smooth"
    },
    {
      "x": -25,
      "y": 5,
      "z": -7,
      "name": "Rock_CastIron_Brick_Smooth"
    },
    {
      "x": -25,
      "y": 6,
      "z": -7,
      "name": "Rock_CastIron_Brick_Smooth"
    },
    {
      "x": -25,
      "y": 7,
      "z": -7,
      "name": "Rock_CastIron_Brick_Smooth"
    },
    {
      "x": -25,
      "y": 8,
      "z": -7,
      "name": "Rock_CastIron_Brick_Smooth"
    },
    {
      "x": -25,
      "y": 9,
      "z": -7,
      "name": "Rock_CastIron_Brick_Smooth"
    },
    {
      "x": -25,
      "y": 10,
      "z": -7,
      "name": "Rock_CastIron_Brick_Smooth"
    },
    {
      "x": -25,
      "y": 11,
      "z": -7,
      "name": "Rock_CastIron_Brick_Smooth"
    },
    {
      "x": -25,
      "y": 12,
      "z": -7,
      "name": "Rock_CastIron_Brick_Smooth"
    },
    {
      "x": -25,
      "y": 13,
      "z": -7,
      "name": "Rock_CastIron_Brick_Smooth"
    },
    {
      "x": -25,
      "y": 14,
      "z": -7,
      "name": "Rock_CastIron_Brick"
    },
    {
      "x": -25,
      "y": 0,
      "z": -6,
      "name": "Rock_CastIron_Brick"
    },
    {
      "x": -25,
      "y": 1,
      "z": -6,
      "name": "Rock_Shale_Brick_Smooth_Half",
      "rotation": 4
    },
    {
      "x": -25,
      "y": 2,
      "z": -6,
      "name": "Rock_Shale_Brick_Smooth_Half",
      "rotation": 4
    },
    {
      "x": -25,
      "y": 3,
      "z": -6,
      "name": "Rock_Shale_Brick_Smooth_Half",
      "rotation": 4
    },
    {
      "x": -25,
      "y": 4,
      "z": -6,
      "name": "Rock_CastIron_Brick_Smooth"
    },
    {
      "x": -25,
      "y": 5,
      "z": -6,
      "name": "Rock_CastIron_Brick_Smooth"
    },
    {
      "x": -25,
      "y": 6,
      "z": -6,
      "name": "Rock_CastIron_Brick_Smooth"
    },
    {
      "x": -25,
      "y": 7,
      "z": -6,
      "name": "Rock_Shale_Brick_Smooth_Half",
      "rotation": 4
    },
    {
      "x": -25,
      "y": 8,
      "z": -6,
      "name": "Rock_Shale_Brick_Smooth_Half",
      "rotation": 4
    },
    {
      "x": -25,
      "y": 9,
      "z": -6,
      "name": "Rock_Shale_Brick_Smooth_Half",
      "rotation": 4
    },
    {
      "x": -25,
      "y": 10,
      "z": -6,
      "name": "Rock_Shale_Brick_Smooth_Half",
      "rotation": 4
    },
    {
      "x": -25,
      "y": 11,
      "z": -6,
      "name": "Rock_CastIron_Brick_Smooth"
    },
    {
      "x": -25,
      "y": 12,
      "z": -6,
      "name": "Rock_CastIron_Brick_Smooth"
    },
    {
      "x": -25,
      "y": 13,
      "z": -6,
      "name": "Rock_CastIron_Brick_Smooth"
    },
    {
      "x": -25,
      "y": 14,
      "z": -6,
      "name": "Rock_CastIron_Brick"
    },
    {
      "x": -25,
      "y": 0,
      "z": -5,
      "name": "Rock_CastIron_Brick"
    },
    {
      "x": -25,
      "y": 4,
      "z": -5,
      "name": "Rock_Shale_Brick_Smooth_Half",
      "rotation": 8
    },
    {
      "x": -25,
      "y": 5,
      "z": -5,
      "name": "Rock_CastIron_Brick_Smooth"
    },
    {
      "x": -25,
      "y": 6,
      "z": -5,
      "name": "Rock_CastIron_Brick_Smooth"
    },
    {
      "x": -25,
      "y": 11,
      "z": -5,
      "name": "Rock_Shale_Brick_Smooth_Half",
      "rotation": 8
    },
    {
      "x": -25,
      "y": 12,
      "z": -5,
      "name": "Rock_CastIron_Brick_Smooth"
    },
    {
      "x": -25,
      "y": 13,
      "z": -5,
      "name": "Rock_CastIron_Brick_Smooth"
    },
    {
      "x": -25,
      "y": 14,
      "z": -5,
      "name": "Rock_CastIron_Brick"
    },
    {
      "x": -25,
      "y": 0,
      "z": -4,
      "name": "Rock_CastIron_Brick"
    },
    {
      "x": -25,
      "y": 1,
      "z": -4,
      "name": "Rock_Shale_Brick_Smooth_Half",
      "rotation": 6
    },
    {
      "x": -25,
      "y": 2,
      "z": -4,
      "name": "Rock_Shale_Brick_Smooth_Half",
      "rotation": 6
    },
    {
      "x": -25,
      "y": 3,
      "z": -4,
      "name": "Rock_Shale_Brick_Smooth_Half",
      "rotation": 6
    },
    {
      "x": -25,
      "y": 4,
      "z": -4,
      "name": "Rock_CastIron_Brick_Smooth"
    },
    {
      "x": -25,
      "y": 5,
      "z": -4,
      "name": "Rock_CastIron_Brick_Smooth"
    },
    {
      "x": -25,
      "y": 6,
      "z": -4,
      "name": "Rock_CastIron_Brick_Smooth"
    },
    {
      "x": -25,
      "y": 7,
      "z": -4,
      "name": "Rock_Shale_Brick_Smooth_Half",
      "rotation": 6
    },
    {
      "x": -25,
      "y": 8,
      "z": -4,
      "name": "Rock_Shale_Brick_Smooth_Half",
      "rotation": 6
    },
    {
      "x": -25,
      "y": 9,
      "z": -4,
      "name": "Rock_Shale_Brick_Smooth_Half",
      "rotation": 6
    },
    {
      "x": -25,
      "y": 10,
      "z": -4,
      "name": "Rock_Shale_Brick_Smooth_Half",
      "rotation": 6
    },
    {
      "x": -25,
      "y": 11,
      "z": -4,
      "name": "Rock_CastIron_Brick_Smooth"
    },
    {
      "x": -25,
      "y": 12,
      "z": -4,
      "name": "Rock_CastIron_Brick_Smooth"
    },
    {
      "x": -25,
      "y": 13,
      "z": -4,
      "name": "Rock_CastIron_Brick_Smooth"
    },
    {
      "x": -25,
      "y": 14,
      "z": -4,
      "name": "Rock_CastIron_Brick"
    },
    {
      "x": -25,
      "y": 0,
      "z": -3,
      "name": "Rock_CastIron_Brick"
    },
    {
      "x": -25,
      "y": 1,
      "z": -3,
      "name": "Rock_CastIron_Brick_Smooth"
    },
    {
      "x": -25,
      "y": 2,
      "z": -3,
      "name": "Rock_CastIron_Brick_Smooth"
    },
    {
      "x": -25,
      "y": 3,
      "z": -3,
      "name": "Rock_CastIron_Brick_Smooth"
    },
    {
      "x": -25,
      "y": 4,
      "z": -3,
      "name": "Rock_CastIron_Brick_Smooth"
    },
    {
      "x": -25,
      "y": 5,
      "z": -3,
      "name": "Rock_CastIron_Brick_Smooth"
    },
    {
      "x": -25,
      "y": 6,
      "z": -3,
      "name": "Rock_CastIron_Brick_Smooth"
    },
    {
      "x": -25,
      "y": 7,
      "z": -3,
      "name": "Rock_CastIron_Brick_Smooth"
    },
    {
      "x": -25,
      "y": 8,
      "z": -3,
      "name": "Rock_CastIron_Brick_Smooth"
    },
    {
      "x": -25,
      "y": 9,
      "z": -3,
      "name": "Rock_CastIron_Brick_Smooth"
    },
    {
      "x": -25,
      "y": 10,
      "z": -3,
      "name": "Rock_CastIron_Brick_Smooth"
    },
    {
      "x": -25,
      "y": 11,
      "z": -3,
      "name": "Rock_CastIron_Brick_Smooth"
    },
    {
      "x": -25,
      "y": 12,
      "z": -3,
      "name": "Rock_CastIron_Brick_Smooth"
    },
    {
      "x": -25,
      "y": 13,
      "z": -3,
      "name": "Rock_CastIron_Brick_Smooth"
    },
    {
      "x": -25,
      "y": 14,
      "z": -3,
      "name": "Rock_CastIron_Brick"
    },
    {
      "x": -25,
      "y": 0,
      "z": -2,
      "name": "Rock_CastIron_Cobble"
    },
    {
      "x": -25,
      "y": 1,
      "z": -2,
      "name": "Rock_Volcanic_Cobble"
    },
    {
      "x": -25,
      "y": 2,
      "z": -2,
      "name": "Rock_Volcanic_Cobble"
    },
    {
      "x": -25,
      "y": 3,
      "z": -2,
      "name": "Rock_Volcanic_Cobble"
    },
    {
      "x": -25,
      "y": 4,
      "z": -2,
      "name": "Rock_Volcanic_Cobble"
    },
    {
      "x": -25,
      "y": 5,
      "z": -2,
      "name": "Rock_Volcanic_Cobble"
    },
    {
      "x": -25,
      "y": 6,
      "z": -2,
      "name": "Rock_Volcanic_Cobble"
    },
    {
      "x": -25,
      "y": 7,
      "z": -2,
      "name": "Rock_Volcanic_Cobble"
    },
    {
      "x": -25,
      "y": 8,
      "z": -2,
      "name": "Rock_Volcanic_Cobble"
    },
    {
      "x": -25,
      "y": 9,
      "z": -2,
      "name": "Rock_Volcanic_Cobble"
    },
    {
      "x": -25,
      "y": 10,
      "z": -2,
      "name": "Rock_Volcanic_Cobble"
    },
    {
      "x": -25,
      "y": 11,
      "z": -2,
      "name": "Rock_Volcanic_Cobble"
    },
    {
      "x": -25,
      "y": 12,
      "z": -2,
      "name": "Rock_Volcanic_Cobble"
    },
    {
      "x": -25,
      "y": 13,
      "z": -2,
      "name": "Rock_Volcanic_Cobble"
    },
    {
      "x": -25,
      "y": 14,
      "z": -2,
      "name": "Rock_CastIron_Brick"
    },
    {
      "x": -25,
      "y": 0,
      "z": -1,
      "name": "Rock_CastIron_Cobble"
    },
    {
      "x": -25,
      "y": 1,
      "z": -1,
      "name": "Rock_CastIron_Cobble"
    },
    {
      "x": -25,
      "y": 2,
      "z": -1,
      "name": "Rock_CastIron_Brick_Smooth"
    },
    {
      "x": -25,
      "y": 3,
      "z": -1,
      "name": "Rock_CastIron_Brick_Smooth"
    },
    {
      "x": -25,
      "y": 4,
      "z": -1,
      "name": "Rock_CastIron_Brick_Smooth"
    },
    {
      "x": -25,
      "y": 5,
      "z": -1,
      "name": "Rock_CastIron_Brick_Decorative"
    },
    {
      "x": -25,
      "y": 6,
      "z": -1,
      "name": "Rock_CastIron_Brick_Smooth"
    },
    {
      "x": -25,
      "y": 7,
      "z": -1,
      "name": "Rock_CastIron_Brick_Smooth"
    },
    {
      "x": -25,
      "y": 8,
      "z": -1,
      "name": "Rock_CastIron_Brick_Smooth"
    },
    {
      "x": -25,
      "y": 9,
      "z": -1,
      "name": "Rock_CastIron_Brick_Smooth"
    },
    {
      "x": -25,
      "y": 10,
      "z": -1,
      "name": "Rock_CastIron_Brick_Smooth"
    },
    {
      "x": -25,
      "y": 11,
      "z": -1,
      "name": "Rock_CastIron_Brick_Smooth"
    },
    {
      "x": -25,
      "y": 12,
      "z": -1,
      "name": "Rock_CastIron_Brick_Smooth"
    },
    {
      "x": -25,
      "y": 13,
      "z": -1,
      "name": "Rock_CastIron_Brick_Smooth"
    },
    {
      "x": -25,
      "y": 14,
      "z": -1,
      "name": "Rock_CastIron_Brick_Decorative"
    },
    {
      "x": -25,
      "y": 0,
      "z": 0,
      "name": "Rock_CastIron_Cobble"
    },
    {
      "x": -25,
      "y": 1,
      "z": 0,
      "name": "Rock_CastIron_Brick_Smooth"
    },
    {
      "x": -25,
      "y": 2,
      "z": 0,
      "name": "Rock_CastIron_Brick_Smooth"
    },
    {
      "x": -25,
      "y": 3,
      "z": 0,
      "name": "Rock_CastIron_Brick_Smooth"
    },
    {
      "x": -25,
      "y": 4,
      "z": 0,
      "name": "Rock_CastIron_Brick_Smooth"
    },
    {
      "x": -25,
      "y": 5,
      "z": 0,
      "name": "Rock_CastIron_Brick_Decorative"
    },
    {
      "x": -25,
      "y": 6,
      "z": 0,
      "name": "Rock_CastIron_Brick_Smooth"
    },
    {
      "x": -25,
      "y": 7,
      "z": 0,
      "name": "Rock_CastIron_Brick_Smooth"
    },
    {
      "x": -25,
      "y": 8,
      "z": 0,
      "name": "Rock_CastIron_Brick_Smooth"
    },
    {
      "x": -25,
      "y": 9,
      "z": 0,
      "name": "Rock_CastIron_Brick_Smooth"
    },
    {
      "x": -25,
      "y": 10,
      "z": 0,
      "name": "Rock_CastIron_Brick_Smooth"
    },
    {
      "x": -25,
      "y": 11,
      "z": 0,
      "name": "Rock_CastIron_Brick_Smooth"
    },
    {
      "x": -25,
      "y": 12,
      "z": 0,
      "name": "Rock_CastIron_Brick_Smooth"
    },
    {
      "x": -25,
      "y": 13,
      "z": 0,
      "name": "Rock_CastIron_Brick_Smooth"
    },
    {
      "x": -25,
      "y": 14,
      "z": 0,
      "name": "Rock_CastIron_Brick_Decorative"
    },
    {
      "x": -24,
      "y": 0,
      "z": -22,
      "name": "Rock_CastIron_Cobble"
    },
    {
      "x": -24,
      "y": 1,
      "z": -22,
      "name": "Rock_CastIron_Brick_Smooth"
    },
    {
      "x": -24,
      "y": 2,
      "z": -22,
      "name": "Rock_CastIron_Brick_Smooth"
    },
    {
      "x": -24,
      "y": 3,
      "z": -22,
      "name": "Rock_CastIron_Brick_Smooth"
    },
    {
      "x": -24,
      "y": 4,
      "z": -22,
      "name": "Rock_CastIron_Brick_Smooth"
    },
    {
      "x": -24,
      "y": 5,
      "z": -22,
      "name": "Rock_CastIron_Brick_Decorative"
    },
    {
      "x": -24,
      "y": 6,
      "z": -22,
      "name": "Rock_CastIron_Brick_Smooth"
    },
    {
      "x": -24,
      "y": 7,
      "z": -22,
      "name": "Rock_CastIron_Brick_Smooth"
    },
    {
      "x": -24,
      "y": 8,
      "z": -22,
      "name": "Rock_CastIron_Brick_Smooth"
    },
    {
      "x": -24,
      "y": 9,
      "z": -22,
      "name": "Rock_CastIron_Brick_Smooth"
    },
    {
      "x": -24,
      "y": 10,
      "z": -22,
      "name": "Rock_CastIron_Brick_Smooth"
    },
    {
      "x": -24,
      "y": 11,
      "z": -22,
      "name": "Rock_CastIron_Brick_Smooth"
    },
    {
      "x": -24,
      "y": 12,
      "z": -22,
      "name": "Rock_CastIron_Brick_Smooth"
    },
    {
      "x": -24,
      "y": 13,
      "z": -22,
      "name": "Rock_CastIron_Brick_Smooth"
    },
    {
      "x": -24,
      "y": 14,
      "z": -22,
      "name": "Rock_CastIron_Brick_Decorative"
    },
    {
      "x": -24,
      "y": 0,
      "z": -21,
      "name": "Rock_CastIron_Cobble"
    },
    {
      "x": -24,
      "y": 1,
      "z": -21,
      "name": "Rock_CastIron_Brick"
    },
    {
      "x": -24,
      "y": 2,
      "z": -21,
      "name": "Rock_CastIron_Brick"
    },
    {
      "x": -24,
      "y": 3,
      "z": -21,
      "name": "Rock_CastIron_Brick"
    },
    {
      "x": -24,
      "y": 4,
      "z": -21,
      "name": "Rock_CastIron_Brick"
    },
    {
      "x": -24,
      "y": 5,
      "z": -21,
      "name": "Rock_CastIron_Brick"
    },
    {
      "x": -24,
      "y": 6,
      "z": -21,
      "name": "Furniture_Human_Ruins_Desk",
      "filler": 31
    },
    {
      "x": -24,
      "y": 7,
      "z": -21,
      "name": "Furniture_Human_Ruins_Desk",
      "filler": 31
    },
    {
      "x": -24,
      "y": 8,
      "z": -21,
      "name": "Rock_Shale_Brick_Smooth_Half",
      "rotation": 4
    },
    {
      "x": -24,
      "y": 9,
      "z": -21,
      "name": "Rock_Shale_Brick_Smooth_Half",
      "rotation": 4
    },
    {
      "x": -24,
      "y": 10,
      "z": -21,
      "name": "Rock_CastIron_Brick_Smooth"
    },
    {
      "x": -24,
      "y": 11,
      "z": -21,
      "name": "Rock_CastIron_Brick_Smooth"
    },
    {
      "x": -24,
      "y": 12,
      "z": -21,
      "name": "Rock_CastIron_Brick_Smooth"
    },
    {
      "x": -24,
      "y": 13,
      "z": -21,
      "name": "Rock_CastIron_Brick_Smooth"
    },
    {
      "x": -24,
      "y": 14,
      "z": -21,
      "name": "Rock_CastIron_Brick"
    },
    {
      "x": -24,
      "y": 0,
      "z": -20,
      "name": "Rock_CastIron_Cobble"
    },
    {
      "x": -24,
      "y": 1,
      "z": -20,
      "name": "Rock_CastIron_Brick"
    },
    {
      "x": -24,
      "y": 2,
      "z": -20,
      "name": "Rock_CastIron_Brick"
    },
    {
      "x": -24,
      "y": 3,
      "z": -20,
      "name": "Rock_CastIron_Brick"
    },
    {
      "x": -24,
      "y": 4,
      "z": -20,
      "name": "Rock_CastIron_Brick"
    },
    {
      "x": -24,
      "y": 5,
      "z": -20,
      "name": "Rock_CastIron_Brick"
    },
    {
      "x": -24,
      "y": 12,
      "z": -20,
      "name": "Rock_CastIron_Brick_Smooth"
    },
    {
      "x": -24,
      "y": 13,
      "z": -20,
      "name": "Rock_CastIron_Brick_Smooth"
    },
    {
      "x": -24,
      "y": 14,
      "z": -20,
      "name": "Rock_CastIron_Brick"
    },
    {
      "x": -24,
      "y": 0,
      "z": -19,
      "name": "Rock_CastIron_Cobble"
    },
    {
      "x": -24,
      "y": 5,
      "z": -19,
      "name": "Rock_CastIron_Cobble"
    },
    {
      "x": -24,
      "y": 12,
      "z": -19,
      "name": "Rock_Shale_Brick_Smooth_Half",
      "rotation": 5
    },
    {
      "x": -24,
      "y": 13,
      "z": -19,
      "name": "Rock_CastIron_Brick_Smooth"
    },
    {
      "x": -24,
      "y": 14,
      "z": -19,
      "name": "Rock_CastIron_Brick"
    },
    {
      "x": -24,
      "y": 0,
      "z": -18,
      "name": "Rock_CastIron_Cobble"
    },
    {
      "x": -24,
      "y": 5,
      "z": -18,
      "name": "Rock_CastIron_Cobble"
    },
    {
      "x": -24,
      "y": 6,
      "z": -18,
      "name": "Block_Spawner_Block",
      "components": {
        "Components": {
          "BlockSpawner": {
            "BlockSpawnerId": "Zone1_Encounters_Tier3"
          }
        }
      },
      "rotation": 2
    },
    {
      "x": -24,
      "y": 7,
      "z": -18,
      "name": "Furniture_Ancient_Crate",
      "rotation": 1
    },
    {
      "x": -24,
      "y": 13,
      "z": -18,
      "name": "Rock_Shale_Brick_Smooth_Half",
      "rotation": 5
    },
    {
      "x": -24,
      "y": 14,
      "z": -18,
      "name": "Rock_CastIron_Brick"
    },
    {
      "x": -24,
      "y": 0,
      "z": -17,
      "name": "Rock_CastIron_Cobble"
    },
    {
      "x": -24,
      "y": 5,
      "z": -17,
      "name": "Rock_CastIron_Cobble"
    },
    {
      "x": -24,
      "y": 6,
      "z": -17,
      "name": "Furniture_Ancient_Crate",
      "rotation": 2
    },
    {
      "x": -24,
      "y": 7,
      "z": -17,
      "name": "Furniture_Ancient_Crate",
      "rotation": 2
    },
    {
      "x": -24,
      "y": 14,
      "z": -17,
      "name": "Rock_CastIron_Brick"
    },
    {
      "x": -24,
      "y": 0,
      "z": -16,
      "name": "Rock_CastIron_Cobble"
    },
    {
      "x": -24,
      "y": 5,
      "z": -16,
      "name": "Rock_CastIron_Brick"
    },
    {
      "x": -24,
      "y": 6,
      "z": -16,
      "name": "Rock_CastIron_Brick_Wall"
    },
    {
      "x": -24,
      "y": 11,
      "z": -16,
      "name": "Rock_Shale_Brick_Half",
      "rotation": 8
    },
    {
      "x": -24,
      "y": 12,
      "z": -16,
      "name": "Rock_Shale_Brick_Roof",
      "rotation": 3
    },
    {
      "x": -24,
      "y": 14,
      "z": -16,
      "name": "Rock_CastIron_Brick"
    },
    {
      "x": -24,
      "y": 0,
      "z": -15,
      "name": "Rock_CastIron_Cobble"
    },
    {
      "x": -24,
      "y": 1,
      "z": -15,
      "name": "Rock_Shale_Brick_Stairs",
      "rotation": 2
    },
    {
      "x": -24,
      "y": 12,
      "z": -15,
      "name": "Rock_Shale_Brick_Roof_Hollow",
      "rotation": 3
    },
    {
      "x": -24,
      "y": 14,
      "z": -15,
      "name": "Rock_CastIron_Brick"
    },
    {
      "x": -24,
      "y": 0,
      "z": -14,
      "name": "Rock_CastIron_Cobble"
    },
    {
      "x": -24,
      "y": 1,
      "z": -14,
      "name": "Rock_CastIron_Brick"
    },
    {
      "x": -24,
      "y": 2,
      "z": -14,
      "name": "Rock_Shale_Brick_Stairs",
      "rotation": 2
    },
    {
      "x": -24,
      "y": 12,
      "z": -14,
      "name": "Rock_Shale_Brick_Roof_Hollow",
      "rotation": 3
    },
    {
      "x": -24,
      "y": 14,
      "z": -14,
      "name": "Rock_CastIron_Brick"
    },
    {
      "x": -24,
      "y": 0,
      "z": -13,
      "name": "Rock_CastIron_Cobble"
    },
    {
      "x": -24,
      "y": 1,
      "z": -13,
      "name": "Rock_CastIron_Brick"
    },
    {
      "x": -24,
      "y": 2,
      "z": -13,
      "name": "Rock_CastIron_Brick"
    },
    {
      "x": -24,
      "y": 3,
      "z": -13,
      "name": "Rock_Shale_Brick_Stairs",
      "rotation": 2
    },
    {
      "x": -24,
      "y": 12,
      "z": -13,
      "name": "Rock_Shale_Brick_Roof_Hollow",
      "rotation": 3
    },
    {
      "x": -24,
      "y": 14,
      "z": -13,
      "name": "Rock_CastIron_Brick"
    },
    {
      "x": -24,
      "y": 0,
      "z": -12,
      "name": "Rock_CastIron_Cobble"
    },
    {
      "x": -24,
      "y": 1,
      "z": -12,
      "name": "Rock_CastIron_Brick"
    },
    {
      "x": -24,
      "y": 2,
      "z": -12,
      "name": "Rock_CastIron_Brick"
    },
    {
      "x": -24,
      "y": 3,
      "z": -12,
      "name": "Rock_CastIron_Brick"
    },
    {
      "x": -24,
      "y": 4,
      "z": -12,
      "name": "Rock_Shale_Brick_Stairs",
      "rotation": 2
    },
    {
      "x": -24,
      "y": 11,
      "z": -12,
      "name": "Rock_Shale_Brick_Half",
      "rotation": 8
    },
    {
      "x": -24,
      "y": 12,
      "z": -12,
      "name": "Rock_Shale_Brick_Roof",
      "rotation": 3
    },
    {
      "x": -24,
      "y": 14,
      "z": -12,
      "name": "Rock_CastIron_Brick"
    },
    {
      "x": -24,
      "y": 0,
      "z": -11,
      "name": "Rock_CastIron_Cobble"
    },
    {
      "x": -24,
      "y": 1,
      "z": -11,
      "name": "Rock_CastIron_Brick"
    },
    {
      "x": -24,
      "y": 2,
      "z": -11,
      "name": "Rock_CastIron_Brick"
    },
    {
      "x": -24,
      "y": 3,
      "z": -11,
      "name": "Rock_CastIron_Brick"
    },
    {
      "x": -24,
      "y": 4,
      "z": -11,
      "name": "Rock_CastIron_Brick"
    },
    {
      "x": -24,
      "y": 5,
      "z": -11,
      "name": "Rock_Shale_Brick_Stairs",
      "rotation": 2
    },
    {
      "x": -24,
      "y": 14,
      "z": -11,
      "name": "Rock_CastIron_Brick"
    },
    {
      "x": -24,
      "y": 0,
      "z": -10,
      "name": "Rock_CastIron_Cobble"
    },
    {
      "x": -24,
      "y": 1,
      "z": -10,
      "name": "Rock_CastIron_Brick"
    },
    {
      "x": -24,
      "y": 2,
      "z": -10,
      "name": "Rock_CastIron_Brick"
    },
    {
      "x": -24,
      "y": 3,
      "z": -10,
      "name": "Rock_CastIron_Brick"
    },
    {
      "x": -24,
      "y": 4,
      "z": -10,
      "name": "Rock_CastIron_Brick"
    },
    {
      "x": -24,
      "y": 5,
      "z": -10,
      "name": "Rock_CastIron_Brick"
    },
    {
      "x": -24,
      "y": 6,
      "z": -10,
      "name": "Plant_Moss_Rug_Green_Dark",
      "support": 15
    },
    {
      "x": -24,
      "y": 14,
      "z": -10,
      "name": "Rock_CastIron_Brick"
    },
    {
      "x": -24,
      "y": 0,
      "z": -9,
      "name": "Rock_CastIron_Brick_Smooth"
    },
    {
      "x": -24,
      "y": 1,
      "z": -9,
      "name": "Rock_CastIron_Brick_Smooth"
    },
    {
      "x": -24,
      "y": 2,
      "z": -9,
      "name": "Rock_CastIron_Brick_Smooth"
    },
    {
      "x": -24,
      "y": 3,
      "z": -9,
      "name": "Rock_CastIron_Brick_Smooth"
    },
    {
      "x": -24,
      "y": 4,
      "z": -9,
      "name": "Rock_CastIron_Brick_Smooth"
    },
    {
      "x": -24,
      "y": 5,
      "z": -9,
      "name": "Rock_CastIron_Cobble"
    },
    {
      "x": -24,
      "y": 12,
      "z": -9,
      "name": "Rock_CastIron_Brick_Smooth"
    },
    {
      "x": -24,
      "y": 13,
      "z": -9,
      "name": "Rock_CastIron_Brick_Smooth"
    },
    {
      "x": -24,
      "y": 14,
      "z": -9,
      "name": "Rock_CastIron_Brick_Decorative"
    },
    {
      "x": -24,
      "y": 0,
      "z": -8,
      "name": "Rock_CastIron_Cobble"
    },
    {
      "x": -24,
      "y": 1,
      "z": -8,
      "name": "Rock_CastIron_Brick_Smooth"
    },
    {
      "x": -24,
      "y": 2,
      "z": -8,
      "name": "Rock_CastIron_Brick_Smooth"
    },
    {
      "x": -24,
      "y": 3,
      "z": -8,
      "name": "Rock_CastIron_Brick_Smooth"
    },
    {
      "x": -24,
      "y": 4,
      "z": -8,
      "name": "Rock_CastIron_Brick_Smooth"
    },
    {
      "x": -24,
      "y": 5,
      "z": -8,
      "name": "Rock_CastIron_Cobble"
    },
    {
      "x": -24,
      "y": 6,
      "z": -8,
      "name": "Rock_CastIron_Brick_Smooth"
    },
    {
      "x": -24,
      "y": 7,
      "z": -8,
      "name": "Rock_CastIron_Brick_Smooth"
    },
    {
      "x": -24,
      "y": 8,
      "z": -8,
      "name": "Rock_CastIron_Brick_Smooth"
    },
    {
      "x": -24,
      "y": 9,
      "z": -8,
      "name": "Rock_CastIron_Brick_Smooth"
    },
    {
      "x": -24,
      "y": 10,
      "z": -8,
      "name": "Rock_CastIron_Brick_Smooth"
    },
    {
      "x": -24,
      "y": 11,
      "z": -8,
      "name": "Rock_CastIron_Brick_Smooth"
    },
    {
      "x": -24,
      "y": 12,
      "z": -8,
      "name": "*Rock_Shale_Brick_Smooth_Half_State_Definitions_Block",
      "rotation": 8
    },
    {
      "x": -24,
      "y": 13,
      "z": -8,
      "name": "Rock_CastIron_Brick_Smooth"
    },
    {
      "x": -24,
      "y": 14,
      "z": -8,
      "name": "Rock_CastIron_Brick_Decorative"
    },
    {
      "x": -24,
      "y": 0,
      "z": -7,
      "name": "Rock_CastIron_Brick"
    },
    {
      "x": -24,
      "y": 1,
      "z": -7,
      "name": "Rock_Shale_Brick_Smooth_Half",
      "rotation": 4
    },
    {
      "x": -24,
      "y": 2,
      "z": -7,
      "name": "Rock_Shale_Brick_Smooth_Half",
      "rotation": 4
    },
    {
      "x": -24,
      "y": 3,
      "z": -7,
      "name": "Rock_Shale_Brick_Smooth_Half",
      "rotation": 4
    },
    {
      "x": -24,
      "y": 4,
      "z": -7,
      "name": "Rock_CastIron_Brick_Smooth"
    },
    {
      "x": -24,
      "y": 5,
      "z": -7,
      "name": "Rock_CastIron_Brick_Ornate"
    },
    {
      "x": -24,
      "y": 6,
      "z": -7,
      "name": "Rock_CastIron_Brick_Smooth"
    },
    {
      "x": -24,
      "y": 7,
      "z": -7,
      "name": "Rock_Shale_Brick_Smooth_Half",
      "rotation": 4
    },
    {
      "x": -24,
      "y": 8,
      "z": -7,
      "name": "Rock_Shale_Brick_Smooth_Half",
      "rotation": 4
    },
    {
      "x": -24,
      "y": 9,
      "z": -7,
      "name": "Rock_Shale_Brick_Smooth_Half",
      "rotation": 4
    },
    {
      "x": -24,
      "y": 10,
      "z": -7,
      "name": "Rock_Shale_Brick_Smooth_Half",
      "rotation": 4
    },
    {
      "x": -24,
      "y": 11,
      "z": -7,
      "name": "Rock_CastIron_Brick_Smooth"
    },
    {
      "x": -24,
      "y": 12,
      "z": -7,
      "name": "Rock_CastIron_Brick_Smooth"
    },
    {
      "x": -24,
      "y": 13,
      "z": -7,
      "name": "Rock_CastIron_Brick_Smooth"
    },
    {
      "x": -24,
      "y": 14,
      "z": -7,
      "name": "Rock_CastIron_Brick_Decorative"
    },
    {
      "x": -24,
      "y": 0,
      "z": -6,
      "name": "Rock_CastIron_Brick"
    },
    {
      "x": -24,
      "y": 5,
      "z": -6,
      "name": "Rock_CastIron_Brick_Smooth"
    },
    {
      "x": -24,
      "y": 6,
      "z": -6,
      "name": "Rock_Shale_Brick_Smooth_Half",
      "rotation": 5
    },
    {
      "x": -24,
      "y": 12,
      "z": -6,
      "name": "Rock_CastIron_Brick_Smooth"
    },
    {
      "x": -24,
      "y": 13,
      "z": -6,
      "name": "Rock_CastIron_Brick_Smooth"
    },
    {
      "x": -24,
      "y": 14,
      "z": -6,
      "name": "Rock_CastIron_Brick_Decorative"
    },
    {
      "x": -24,
      "y": 0,
      "z": -5,
      "name": "Rock_CastIron_Brick"
    },
    {
      "x": -24,
      "y": 5,
      "z": -5,
      "name": "Rock_Shale_Brick_Smooth_Half",
      "rotation": 8
    },
    {
      "x": -24,
      "y": 6,
      "z": -5,
      "name": "Rock_Shale_Brick_Smooth_Half",
      "rotation": 5
    },
    {
      "x": -24,
      "y": 12,
      "z": -5,
      "name": "Rock_CastIron_Brick_Smooth"
    },
    {
      "x": -24,
      "y": 13,
      "z": -5,
      "name": "Rock_CastIron_Brick_Smooth"
    },
    {
      "x": -24,
      "y": 14,
      "z": -5,
      "name": "Rock_CastIron_Brick_Decorative"
    },
    {
      "x": -24,
      "y": 0,
      "z": -4,
      "name": "Rock_CastIron_Brick"
    },
    {
      "x": -24,
      "y": 1,
      "z": -4,
      "name": "Plant_Moss_Rug_Green_Dark",
      "support": 15
    },
    {
      "x": -24,
      "y": 5,
      "z": -4,
      "name": "Rock_CastIron_Brick_Smooth"
    },
    {
      "x": -24,
      "y": 6,
      "z": -4,
      "name": "Rock_Shale_Brick_Smooth_Half",
      "rotation": 5
    },
    {
      "x": -24,
      "y": 12,
      "z": -4,
      "name": "Rock_CastIron_Brick_Smooth"
    },
    {
      "x": -24,
      "y": 13,
      "z": -4,
      "name": "Rock_CastIron_Brick_Smooth"
    },
    {
      "x": -24,
      "y": 14,
      "z": -4,
      "name": "Rock_CastIron_Brick_Decorative"
    },
    {
      "x": -24,
      "y": 0,
      "z": -3,
      "name": "Rock_CastIron_Brick"
    },
    {
      "x": -24,
      "y": 1,
      "z": -3,
      "name": "Rock_Shale_Brick_Smooth_Half",
      "rotation": 6
    },
    {
      "x": -24,
      "y": 2,
      "z": -3,
      "name": "Rock_Shale_Brick_Smooth_Half",
      "rotation": 6
    },
    {
      "x": -24,
      "y": 3,
      "z": -3,
      "name": "Rock_Shale_Brick_Smooth_Half",
      "rotation": 6
    },
    {
      "x": -24,
      "y": 4,
      "z": -3,
      "name": "Rock_CastIron_Brick_Smooth"
    },
    {
      "x": -24,
      "y": 5,
      "z": -3,
      "name": "Rock_CastIron_Brick_Ornate"
    },
    {
      "x": -24,
      "y": 6,
      "z": -3,
      "name": "Rock_CastIron_Brick_Smooth"
    },
    {
      "x": -24,
      "y": 7,
      "z": -3,
      "name": "Rock_Shale_Brick_Smooth_Half",
      "rotation": 6
    },
    {
      "x": -24,
      "y": 8,
      "z": -3,
      "name": "Rock_Shale_Brick_Smooth_Half",
      "rotation": 6
    },
    {
      "x": -24,
      "y": 9,
      "z": -3,
      "name": "Rock_Shale_Brick_Smooth_Half",
      "rotation": 6
    },
    {
      "x": -24,
      "y": 10,
      "z": -3,
      "name": "Rock_Shale_Brick_Smooth_Half",
      "rotation": 6
    },
    {
      "x": -24,
      "y": 11,
      "z": -3,
      "name": "Rock_CastIron_Brick_Smooth"
    },
    {
      "x": -24,
      "y": 12,
      "z": -3,
      "name": "Rock_CastIron_Brick_Smooth"
    },
    {
      "x": -24,
      "y": 13,
      "z": -3,
      "name": "Rock_CastIron_Brick_Smooth"
    },
    {
      "x": -24,
      "y": 14,
      "z": -3,
      "name": "Rock_CastIron_Brick_Decorative"
    },
    {
      "x": -24,
      "y": 0,
      "z": -2,
      "name": "Rock_CastIron_Cobble"
    },
    {
      "x": -24,
      "y": 1,
      "z": -2,
      "name": "Rock_CastIron_Brick_Smooth"
    },
    {
      "x": -24,
      "y": 2,
      "z": -2,
      "name": "Rock_CastIron_Brick_Smooth"
    },
    {
      "x": -24,
      "y": 3,
      "z": -2,
      "name": "Rock_CastIron_Brick_Smooth"
    },
    {
      "x": -24,
      "y": 4,
      "z": -2,
      "name": "Rock_CastIron_Brick_Smooth"
    },
    {
      "x": -24,
      "y": 5,
      "z": -2,
      "name": "Rock_CastIron_Brick_Decorative"
    },
    {
      "x": -24,
      "y": 6,
      "z": -2,
      "name": "Rock_CastIron_Brick_Smooth"
    },
    {
      "x": -24,
      "y": 7,
      "z": -2,
      "name": "Rock_CastIron_Brick_Smooth"
    },
    {
      "x": -24,
      "y": 8,
      "z": -2,
      "name": "Rock_CastIron_Brick_Smooth"
    },
    {
      "x": -24,
      "y": 9,
      "z": -2,
      "name": "Rock_CastIron_Brick_Smooth"
    },
    {
      "x": -24,
      "y": 10,
      "z": -2,
      "name": "Rock_CastIron_Brick_Smooth"
    },
    {
      "x": -24,
      "y": 11,
      "z": -2,
      "name": "Rock_CastIron_Brick_Smooth"
    },
    {
      "x": -24,
      "y": 12,
      "z": -2,
      "name": "*Rock_Shale_Brick_Smooth_Half_State_Definitions_Block",
      "rotation": 8
    },
    {
      "x": -24,
      "y": 13,
      "z": -2,
      "name": "Rock_CastIron_Brick_Smooth"
    },
    {
      "x": -24,
      "y": 14,
      "z": -2,
      "name": "Rock_CastIron_Brick_Decorative"
    },
    {
      "x": -24,
      "y": 0,
      "z": -1,
      "name": "Rock_CastIron_Cobble"
    },
    {
      "x": -24,
      "y": 1,
      "z": -1,
      "name": "Rock_CastIron_Brick_Smooth"
    },
    {
      "x": -24,
      "y": 2,
      "z": -1,
      "name": "Rock_CastIron_Brick_Smooth"
    },
    {
      "x": -24,
      "y": 3,
      "z": -1,
      "name": "Rock_CastIron_Brick_Smooth"
    },
    {
      "x": -24,
      "y": 4,
      "z": -1,
      "name": "Rock_CastIron_Brick_Smooth"
    },
    {
      "x": -24,
      "y": 5,
      "z": -1,
      "name": "Rock_CastIron_Brick_Decorative"
    },
    {
      "x": -24,
      "y": 6,
      "z": -1,
      "name": "Rock_CastIron_Brick_Smooth"
    },
    {
      "x": -24,
      "y": 7,
      "z": -1,
      "name": "Rock_CastIron_Brick_Smooth"
    },
    {
      "x": -24,
      "y": 8,
      "z": -1,
      "name": "Rock_CastIron_Brick_Smooth"
    },
    {
      "x": -24,
      "y": 9,
      "z": -1,
      "name": "Rock_CastIron_Brick_Smooth"
    },
    {
      "x": -24,
      "y": 10,
      "z": -1,
      "name": "Rock_CastIron_Brick_Smooth"
    },
    {
      "x": -24,
      "y": 11,
      "z": -1,
      "name": "Rock_CastIron_Brick_Smooth"
    },
    {
      "x": -24,
      "y": 12,
      "z": -1,
      "name": "Rock_CastIron_Brick_Smooth"
    },
    {
      "x": -24,
      "y": 13,
      "z": -1,
      "name": "Rock_CastIron_Brick_Smooth"
    },
    {
      "x": -24,
      "y": 14,
      "z": -1,
      "name": "Rock_CastIron_Brick_Decorative"
    },
    {
      "x": -24,
      "y": 0,
      "z": 0,
      "name": "Rock_CastIron_Cobble"
    },
    {
      "x": -24,
      "y": 1,
      "z": 0,
      "name": "Rock_CastIron_Brick_Smooth"
    },
    {
      "x": -24,
      "y": 2,
      "z": 0,
      "name": "Rock_CastIron_Brick_Smooth"
    },
    {
      "x": -24,
      "y": 3,
      "z": 0,
      "name": "Rock_CastIron_Brick_Smooth"
    },
    {
      "x": -24,
      "y": 4,
      "z": 0,
      "name": "Rock_CastIron_Brick_Smooth"
    },
    {
      "x": -24,
      "y": 5,
      "z": 0,
      "name": "Rock_CastIron_Brick_Decorative"
    },
    {
      "x": -24,
      "y": 6,
      "z": 0,
      "name": "Rock_CastIron_Brick_Smooth"
    },
    {
      "x": -24,
      "y": 7,
      "z": 0,
      "name": "Rock_CastIron_Brick_Smooth"
    },
    {
      "x": -24,
      "y": 8,
      "z": 0,
      "name": "Rock_CastIron_Brick_Smooth"
    },
    {
      "x": -24,
      "y": 9,
      "z": 0,
      "name": "Rock_CastIron_Brick_Smooth"
    },
    {
      "x": -24,
      "y": 10,
      "z": 0,
      "name": "Rock_CastIron_Brick_Smooth"
    },
    {
      "x": -24,
      "y": 11,
      "z": 0,
      "name": "Rock_CastIron_Brick_Smooth"
    },
    {
      "x": -24,
      "y": 12,
      "z": 0,
      "name": "Rock_CastIron_Brick_Smooth"
    },
    {
      "x": -24,
      "y": 13,
      "z": 0,
      "name": "Rock_CastIron_Brick_Smooth"
    },
    {
      "x": -24,
      "y": 14,
      "z": 0,
      "name": "Rock_CastIron_Brick_Decorative"
    },
    {
      "x": -23,
      "y": 0,
      "z": -22,
      "name": "Rock_CastIron_Cobble"
    },
    {
      "x": -23,
      "y": 1,
      "z": -22,
      "name": "Rock_CastIron_Brick_Smooth"
    },
    {
      "x": -23,
      "y": 2,
      "z": -22,
      "name": "Rock_CastIron_Brick_Smooth"
    },
    {
      "x": -23,
      "y": 3,
      "z": -22,
      "name": "Rock_CastIron_Brick_Smooth"
    },
    {
      "x": -23,
      "y": 4,
      "z": -22,
      "name": "Rock_CastIron_Brick_Smooth"
    },
    {
      "x": -23,
      "y": 5,
      "z": -22,
      "name": "Rock_CastIron_Brick_Decorative"
    },
    {
      "x": -23,
      "y": 6,
      "z": -22,
      "name": "Rock_CastIron_Brick_Smooth"
    },
    {
      "x": -23,
      "y": 7,
      "z": -22,
      "name": "Rock_CastIron_Brick_Smooth"
    },
    {
      "x": -23,
      "y": 8,
      "z": -22,
      "name": "Rock_CastIron_Brick_Smooth"
    },
    {
      "x": -23,
      "y": 9,
      "z": -22,
      "name": "Rock_CastIron_Brick_Smooth"
    },
    {
      "x": -23,
      "y": 10,
      "z": -22,
      "name": "Rock_CastIron_Brick_Smooth"
    },
    {
      "x": -23,
      "y": 11,
      "z": -22,
      "name": "Rock_CastIron_Brick_Smooth"
    },
    {
      "x": -23,
      "y": 12,
      "z": -22,
      "name": "Rock_CastIron_Brick_Smooth"
    },
    {
      "x": -23,
      "y": 13,
      "z": -22,
      "name": "Rock_CastIron_Brick_Smooth"
    },
    {
      "x": -23,
      "y": 14,
      "z": -22,
      "name": "Rock_CastIron_Brick_Decorative"
    },
    {
      "x": -23,
      "y": 0,
      "z": -21,
      "name": "Rock_CastIron_Cobble"
    },
    {
      "x": -23,
      "y": 1,
      "z": -21,
      "name": "Rock_CastIron_Brick"
    },
    {
      "x": -23,
      "y": 2,
      "z": -21,
      "name": "Rock_CastIron_Brick"
    },
    {
      "x": -23,
      "y": 3,
      "z": -21,
      "name": "Rock_CastIron_Brick"
    },
    {
      "x": -23,
      "y": 4,
      "z": -21,
      "name": "Rock_CastIron_Brick"
    },
    {
      "x": -23,
      "y": 5,
      "z": -21,
      "name": "Rock_CastIron_Brick"
    },
    {
      "x": -23,
      "y": 6,
      "z": -21,
      "name": "Furniture_Human_Ruins_Desk"
    },
    {
      "x": -23,
      "y": 7,
      "z": -21,
      "name": "Furniture_Human_Ruins_Desk"
    },
    {
      "x": -23,
      "y": 9,
      "z": -21,
      "name": "Rock_Shale_Brick_Smooth_Half",
      "rotation": 4
    },
    {
      "x": -23,
      "y": 10,
      "z": -21,
      "name": "Rock_Shale_Brick_Smooth_Half",
      "rotation": 4
    },
    {
      "x": -23,
      "y": 11,
      "z": -21,
      "name": "Rock_CastIron_Brick_Smooth"
    },
    {
      "x": -23,
      "y": 12,
      "z": -21,
      "name": "Rock_CastIron_Brick_Smooth"
    },
    {
      "x": -23,
      "y": 13,
      "z": -21,
      "name": "Rock_CastIron_Brick_Smooth"
    },
    {
      "x": -23,
      "y": 14,
      "z": -21,
      "name": "Rock_CastIron_Brick"
    },
    {
      "x": -23,
      "y": 0,
      "z": -20,
      "name": "Rock_CastIron_Cobble"
    },
    {
      "x": -23,
      "y": 1,
      "z": -20,
      "name": "Rock_CastIron_Brick"
    },
    {
      "x": -23,
      "y": 2,
      "z": -20,
      "name": "Rock_CastIron_Brick"
    },
    {
      "x": -23,
      "y": 3,
      "z": -20,
      "name": "Rock_CastIron_Brick"
    },
    {
      "x": -23,
      "y": 4,
      "z": -20,
      "name": "Rock_CastIron_Brick"
    },
    {
      "x": -23,
      "y": 5,
      "z": -20,
      "name": "Rock_CastIron_Brick"
    },
    {
      "x": -23,
      "y": 6,
      "z": -20,
      "name": "Furniture_Human_Ruins_Pot"
    },
    {
      "x": -23,
      "y": 7,
      "z": -20,
      "name": "Plant_Flower_Orchid_Blue"
    },
    {
      "x": -23,
      "y": 14,
      "z": -20,
      "name": "Rock_CastIron_Brick"
    },
    {
      "x": -23,
      "y": 0,
      "z": -19,
      "name": "Rock_CastIron_Cobble"
    },
    {
      "x": -23,
      "y": 5,
      "z": -19,
      "name": "Rock_CastIron_Cobble"
    },
    {
      "x": -23,
      "y": 14,
      "z": -19,
      "name": "Rock_CastIron_Brick"
    },
    {
      "x": -23,
      "y": 0,
      "z": -18,
      "name": "Rock_CastIron_Cobble"
    },
    {
      "x": -23,
      "y": 5,
      "z": -18,
      "name": "Rock_CastIron_Cobble"
    },
    {
      "x": -23,
      "y": 6,
      "z": -18,
      "name": "Furniture_Ancient_Crate",
      "rotation": 2
    },
    {
      "x": -23,
      "y": 14,
      "z": -18,
      "name": "Rock_CastIron_Brick"
    },
    {
      "x": -23,
      "y": 0,
      "z": -17,
      "name": "Rock_CastIron_Cobble"
    },
    {
      "x": -23,
      "y": 5,
      "z": -17,
      "name": "Rock_CastIron_Cobble"
    },
    {
      "x": -23,
      "y": 6,
      "z": -17,
      "name": "Furniture_Ancient_Crate",
      "rotation": 1
    },
    {
      "x": -23,
      "y": 7,
      "z": -17,
      "name": "Furniture_Ancient_Crate",
      "rotation": 1
    },
    {
      "x": -23,
      "y": 14,
      "z": -17,
      "name": "Rock_CastIron_Brick"
    },
    {
      "x": -23,
      "y": 0,
      "z": -16,
      "name": "Rock_CastIron_Cobble"
    },
    {
      "x": -23,
      "y": 5,
      "z": -16,
      "name": "Rock_CastIron_Brick"
    },
    {
      "x": -23,
      "y": 6,
      "z": -16,
      "name": "Rock_CastIron_Brick_Wall"
    },
    {
      "x": -23,
      "y": 12,
      "z": -16,
      "name": "Rock_CastIron_Brick"
    },
    {
      "x": -23,
      "y": 13,
      "z": -16,
      "name": "Rock_Shale_Brick_Roof_Flat"
    },
    {
      "x": -23,
      "y": 14,
      "z": -16,
      "name": "Rock_CastIron_Brick"
    },
    {
      "x": -23,
      "y": 0,
      "z": -15,
      "name": "Rock_CastIron_Cobble"
    },
    {
      "x": -23,
      "y": 1,
      "z": -15,
      "name": "Rock_Shale_Brick_Stairs",
      "rotation": 2
    },
    {
      "x": -23,
      "y": 13,
      "z": -15,
      "name": "Rock_Shale_Brick_Roof_Flat"
    },
    {
      "x": -23,
      "y": 14,
      "z": -15,
      "name": "Rock_CastIron_Brick"
    },
    {
      "x": -23,
      "y": 0,
      "z": -14,
      "name": "Rock_CastIron_Cobble"
    },
    {
      "x": -23,
      "y": 1,
      "z": -14,
      "name": "Rock_CastIron_Brick"
    },
    {
      "x": -23,
      "y": 2,
      "z": -14,
      "name": "Rock_Shale_Brick_Stairs",
      "rotation": 2
    },
    {
      "x": -23,
      "y": 13,
      "z": -14,
      "name": "Rock_Shale_Brick_Roof_Flat"
    },
    {
      "x": -23,
      "y": 14,
      "z": -14,
      "name": "Rock_CastIron_Brick"
    },
    {
      "x": -23,
      "y": 0,
      "z": -13,
      "name": "Rock_CastIron_Cobble"
    },
    {
      "x": -23,
      "y": 1,
      "z": -13,
      "name": "Rock_CastIron_Brick"
    },
    {
      "x": -23,
      "y": 2,
      "z": -13,
      "name": "Rock_CastIron_Brick"
    },
    {
      "x": -23,
      "y": 3,
      "z": -13,
      "name": "Rock_Shale_Brick_Stairs",
      "rotation": 2
    },
    {
      "x": -23,
      "y": 13,
      "z": -13,
      "name": "Rock_Shale_Brick_Roof_Flat"
    },
    {
      "x": -23,
      "y": 14,
      "z": -13,
      "name": "Rock_CastIron_Brick"
    },
    {
      "x": -23,
      "y": 0,
      "z": -12,
      "name": "Rock_CastIron_Cobble"
    },
    {
      "x": -23,
      "y": 1,
      "z": -12,
      "name": "Rock_CastIron_Brick"
    },
    {
      "x": -23,
      "y": 2,
      "z": -12,
      "name": "Rock_CastIron_Brick"
    },
    {
      "x": -23,
      "y": 3,
      "z": -12,
      "name": "Rock_CastIron_Brick"
    },
    {
      "x": -23,
      "y": 4,
      "z": -12,
      "name": "Rock_Shale_Brick_Stairs",
      "rotation": 2
    },
    {
      "x": -23,
      "y": 12,
      "z": -12,
      "name": "Rock_CastIron_Brick"
    },
    {
      "x": -23,
      "y": 13,
      "z": -12,
      "name": "Rock_Shale_Brick_Roof_Flat"
    },
    {
      "x": -23,
      "y": 14,
      "z": -12,
      "name": "Rock_CastIron_Brick"
    },
    {
      "x": -23,
      "y": 0,
      "z": -11,
      "name": "Rock_CastIron_Cobble"
    },
    {
      "x": -23,
      "y": 1,
      "z": -11,
      "name": "Rock_CastIron_Brick"
    },
    {
      "x": -23,
      "y": 2,
      "z": -11,
      "name": "Rock_CastIron_Brick"
    },
    {
      "x": -23,
      "y": 3,
      "z": -11,
      "name": "Rock_CastIron_Brick"
    },
    {
      "x": -23,
      "y": 4,
      "z": -11,
      "name": "Rock_CastIron_Brick"
    },
    {
      "x": -23,
      "y": 5,
      "z": -11,
      "name": "Rock_Shale_Brick_Stairs",
      "rotation": 2
    },
    {
      "x": -23,
      "y": 14,
      "z": -11,
      "name": "Rock_CastIron_Brick"
    },
    {
      "x": -23,
      "y": 0,
      "z": -10,
      "name": "Rock_CastIron_Cobble"
    },
    {
      "x": -23,
      "y": 1,
      "z": -10,
      "name": "Rock_CastIron_Brick"
    },
    {
      "x": -23,
      "y": 2,
      "z": -10,
      "name": "Rock_CastIron_Brick"
    },
    {
      "x": -23,
      "y": 3,
      "z": -10,
      "name": "Rock_CastIron_Brick"
    },
    {
      "x": -23,
      "y": 4,
      "z": -10,
      "name": "Rock_CastIron_Brick"
    },
    {
      "x": -23,
      "y": 5,
      "z": -10,
      "name": "Rock_CastIron_Brick"
    },
    {
      "x": -23,
      "y": 14,
      "z": -10,
      "name": "Rock_CastIron_Brick"
    },
    {
      "x": -23,
      "y": 0,
      "z": -9,
      "name": "Rock_CastIron_Cobble"
    },
    {
      "x": -23,
      "y": 1,
      "z": -9,
      "name": "Rock_CastIron_Brick"
    },
    {
      "x": -23,
      "y": 2,
      "z": -9,
      "name": "Rock_CastIron_Brick"
    },
    {
      "x": -23,
      "y": 3,
      "z": -9,
      "name": "Rock_CastIron_Brick"
    },
    {
      "x": -23,
      "y": 4,
      "z": -9,
      "name": "Rock_CastIron_Brick"
    },
    {
      "x": -23,
      "y": 5,
      "z": -9,
      "name": "Rock_CastIron_Brick"
    },
    {
      "x": -23,
      "y": 12,
      "z": -9,
      "name": "Rock_CastIron_Brick_Smooth"
    },
    {
      "x": -23,
      "y": 13,
      "z": -9,
      "name": "Rock_CastIron_Brick_Smooth"
    },
    {
      "x": -23,
      "y": 14,
      "z": -9,
      "name": "Rock_CastIron_Brick"
    },
    {
      "x": -23,
      "y": 0,
      "z": -8,
      "name": "Rock_CastIron_Cobble"
    },
    {
      "x": -23,
      "y": 1,
      "z": -8,
      "name": "Rock_CastIron_Brick_Smooth"
    },
    {
      "x": -23,
      "y": 2,
      "z": -8,
      "name": "Rock_CastIron_Brick_Smooth"
    },
    {
      "x": -23,
      "y": 3,
      "z": -8,
      "name": "Rock_CastIron_Brick_Smooth"
    },
    {
      "x": -23,
      "y": 4,
      "z": -8,
      "name": "Rock_CastIron_Brick_Smooth"
    },
    {
      "x": -23,
      "y": 5,
      "z": -8,
      "name": "Rock_CastIron_Brick"
    },
    {
      "x": -23,
      "y": 6,
      "z": -8,
      "name": "Rock_Shale_Brick_Smooth_Half",
      "rotation": 5
    },
    {
      "x": -23,
      "y": 7,
      "z": -8,
      "name": "Rock_Shale_Brick_Smooth_Half",
      "rotation": 5
    },
    {
      "x": -23,
      "y": 8,
      "z": -8,
      "name": "Rock_Shale_Brick_Smooth_Half",
      "rotation": 5
    },
    {
      "x": -23,
      "y": 9,
      "z": -8,
      "name": "Rock_Shale_Brick_Smooth_Half",
      "rotation": 5
    },
    {
      "x": -23,
      "y": 10,
      "z": -8,
      "name": "Rock_CastIron_Brick_Smooth"
    },
    {
      "x": -23,
      "y": 11,
      "z": -8,
      "name": "Rock_CastIron_Brick_Smooth"
    },
    {
      "x": -23,
      "y": 12,
      "z": -8,
      "name": "Rock_CastIron_Brick_Smooth"
    },
    {
      "x": -23,
      "y": 13,
      "z": -8,
      "name": "Rock_CastIron_Brick_Smooth"
    },
    {
      "x": -23,
      "y": 14,
      "z": -8,
      "name": "Rock_CastIron_Brick"
    },
    {
      "x": -23,
      "y": 0,
      "z": -7,
      "name": "Rock_CastIron_Cobble"
    },
    {
      "x": -23,
      "y": 3,
      "z": -7,
      "name": "Plant_Vine_Wall",
      "support": 15
    },
    {
      "x": -23,
      "y": 5,
      "z": -7,
      "name": "Rock_CastIron_Cobble"
    },
    {
      "x": -23,
      "y": 6,
      "z": -7,
      "name": "Plant_Moss_Rug_Green_Dark",
      "support": 15
    },
    {
      "x": -23,
      "y": 12,
      "z": -7,
      "name": "Rock_Shale_Brick_Roof",
      "rotation": 1
    },
    {
      "x": -23,
      "y": 13,
      "z": -7,
      "name": "Rock_CastIron_Brick_Smooth"
    },
    {
      "x": -23,
      "y": 14,
      "z": -7,
      "name": "Rock_CastIron_Brick"
    },
    {
      "x": -23,
      "y": 0,
      "z": -6,
      "name": "Rock_CastIron_Cobble"
    },
    {
      "x": -23,
      "y": 1,
      "z": -6,
      "name": "Plant_Moss_Rug_Green_Dark",
      "support": 15
    },
    {
      "x": -23,
      "y": 5,
      "z": -6,
      "name": "Rock_CastIron_Cobble"
    },
    {
      "x": -23,
      "y": 6,
      "z": -6,
      "name": "Cloth_Roof_Blue_Flat"
    },
    {
      "x": -23,
      "y": 12,
      "z": -6,
      "name": "Rock_Shale_Brick_Roof",
      "rotation": 1
    },
    {
      "x": -23,
      "y": 14,
      "z": -6,
      "name": "Rock_CastIron_Brick"
    },
    {
      "x": -23,
      "y": 0,
      "z": -5,
      "name": "Rock_CastIron_Brick"
    },
    {
      "x": -23,
      "y": 5,
      "z": -5,
      "name": "Rock_CastIron_Cobble"
    },
    {
      "x": -23,
      "y": 6,
      "z": -5,
      "name": "Cloth_Roof_Blue_Flat"
    },
    {
      "x": -23,
      "y": 12,
      "z": -5,
      "name": "Rock_Shale_Brick_Roof",
      "rotation": 1
    },
    {
      "x": -23,
      "y": 14,
      "z": -5,
      "name": "Rock_CastIron_Brick"
    },
    {
      "x": -23,
      "y": 0,
      "z": -4,
      "name": "Rock_CastIron_Brick"
    },
    {
      "x": -23,
      "y": 5,
      "z": -4,
      "name": "Rock_CastIron_Cobble"
    },
    {
      "x": -23,
      "y": 12,
      "z": -4,
      "name": "Rock_Shale_Brick_Roof",
      "rotation": 1
    },
    {
      "x": -23,
      "y": 14,
      "z": -4,
      "name": "Rock_CastIron_Brick"
    },
    {
      "x": -23,
      "y": 0,
      "z": -3,
      "name": "Rock_CastIron_Cobble"
    },
    {
      "x": -23,
      "y": 5,
      "z": -3,
      "name": "Rock_CastIron_Cobble"
    },
    {
      "x": -23,
      "y": 12,
      "z": -3,
      "name": "Rock_Shale_Brick_Roof",
      "rotation": 1
    },
    {
      "x": -23,
      "y": 14,
      "z": -3,
      "name": "Rock_CastIron_Brick"
    },
    {
      "x": -23,
      "y": 0,
      "z": -2,
      "name": "Rock_CastIron_Cobble"
    },
    {
      "x": -23,
      "y": 3,
      "z": -2,
      "name": "Plant_Vine_Wall",
      "support": 15,
      "rotation": 1
    },
    {
      "x": -23,
