{
  "version": 8,
  "blockIdVersion": 11,
  "anchorX": 0,
  "anchorY": 11,
  "anchorZ": 7,
  "blocks": [
    {
      "x": -7,
      "y": 19,
      "z": -4,
      "name": "Rock_Shale"
    },
    {
      "x": -7,
      "y": 20,
      "z": -4,
      "name": "Rock_Shale"
    },
    {
      "x": -7,
      "y": 19,
      "z": -3,
      "name": "Rock_Shale"
    },
    {
      "x": -7,
      "y": 20,
      "z": -3,
      "name": "Rock_Shale"
    },
    {
      "x": -7,
      "y": 21,
      "z": -3,
      "name": "Rock_Shale"
    },
    {
      "x": -7,
      "y": 20,
      "z": -2,
      "name": "Rock_Shale"
    },
    {
      "x": -7,
      "y": 21,
      "z": -2,
      "name": "Rock_Shale"
    },
    {
      "x": -7,
      "y": 6,
      "z": 4,
      "name": "Rock_Shale"
    },
    {
      "x": -7,
      "y": 7,
      "z": 4,
      "name": "Rock_Shale"
    },
    {
      "x": -7,
      "y": 8,
      "z": 4,
      "name": "Rock_Shale"
    },
    {
      "x": -7,
      "y": 9,
      "z": 4,
      "name": "Rock_Shale"
    },
    {
      "x": -7,
      "y": 10,
      "z": 4,
      "name": "Rock_Shale"
    },
    {
      "x": -7,
      "y": 11,
      "z": 4,
      "name": "Rock_Shale"
    },
    {
      "x": -7,
      "y": 12,
      "z": 4,
      "name": "Rock_Shale"
    },
    {
      "x": -7,
      "y": 6,
      "z": 5,
      "name": "Rock_Shale"
    },
    {
      "x": -7,
      "y": 7,
      "z": 5,
      "name": "Rock_Shale"
    },
    {
      "x": -7,
      "y": 8,
      "z": 5,
      "name": "Rock_Shale"
    },
    {
      "x": -7,
      "y": 9,
      "z": 5,
      "name": "Rock_Shale"
    },
    {
      "x": -7,
      "y": 10,
      "z": 5,
      "name": "Rock_Shale"
    },
    {
      "x": -7,
      "y": 11,
      "z": 5,
      "name": "Rock_Shale"
    },
    {
      "x": -7,
      "y": 12,
      "z": 5,
      "name": "Rock_Shale"
    },
    {
      "x": -7,
      "y": 13,
      "z": 5,
      "name": "Rock_Shale"
    },
    {
      "x": -6,
      "y": 18,
      "z": -6,
      "name": "Rock_Shale_Brick"
    },
    {
      "x": -6,
      "y": 17,
      "z": -5,
      "name": "Rock_Shale_Brick_Stairs",
      "rotation": 8
    },
    {
      "x": -6,
      "y": 18,
      "z": -5,
      "name": "Rock_Shale_Brick"
    },
    {
      "x": -6,
      "y": 19,
      "z": -5,
      "name": "Rock_Shale"
    },
    {
      "x": -6,
      "y": 20,
      "z": -5,
      "name": "Rock_Shale"
    },
    {
      "x": -6,
      "y": 6,
      "z": -4,
      "name": "Rock_Shale_Brick"
    },
    {
      "x": -6,
      "y": 7,
      "z": -4,
      "name": "Rock_Shale_Brick"
    },
    {
      "x": -6,
      "y": 8,
      "z": -4,
      "name": "Rock_Shale_Brick"
    },
    {
      "x": -6,
      "y": 9,
      "z": -4,
      "name": "Rock_Shale_Brick"
    },
    {
      "x": -6,
      "y": 10,
      "z": -4,
      "name": "Rock_Shale_Brick"
    },
    {
      "x": -6,
      "y": 11,
      "z": -4,
      "name": "Rock_Shale_Brick"
    },
    {
      "x": -6,
      "y": 12,
      "z": -4,
      "name": "Rock_Shale_Brick_Pillar_Base"
    },
    {
      "x": -6,
      "y": 13,
      "z": -4,
      "name": "Rock_Shale_Brick_Pillar_Middle"
    },
    {
      "x": -6,
      "y": 14,
      "z": -4,
      "name": "Rock_Shale_Brick_Pillar_Middle"
    },
    {
      "x": -6,
      "y": 15,
      "z": -4,
      "name": "Rock_Shale_Brick_Pillar_Middle"
    },
    {
      "x": -6,
      "y": 16,
      "z": -4,
      "name": "Rock_Shale_Brick_Pillar_Base",
      "rotation": 8
    },
    {
      "x": -6,
      "y": 17,
      "z": -4,
      "name": "Rock_Shale_Brick"
    },
    {
      "x": -6,
      "y": 18,
      "z": -4,
      "name": "Rock_Shale_Brick"
    },
    {
      "x": -6,
      "y": 19,
      "z": -4,
      "name": "Rock_Shale"
    },
    {
      "x": -6,
      "y": 20,
      "z": -4,
      "name": "Rock_Shale"
    },
    {
      "x": -6,
      "y": 6,
      "z": -3,
      "name": "Rock_Shale_Brick"
    },
    {
      "x": -6,
      "y": 7,
      "z": -3,
      "name": "Rock_Shale_Brick"
    },
    {
      "x": -6,
      "y": 8,
      "z": -3,
      "name": "Rock_Shale_Brick"
    },
    {
      "x": -6,
      "y": 9,
      "z": -3,
      "name": "Rock_Shale_Brick"
    },
    {
      "x": -6,
      "y": 10,
      "z": -3,
      "name": "Rock_Shale_Brick"
    },
    {
      "x": -6,
      "y": 11,
      "z": -3,
      "name": "Rock_Shale_Brick"
    },
    {
      "x": -6,
      "y": 12,
      "z": -3,
      "name": "Rock_Shale_Brick_Pillar_Base"
    },
    {
      "x": -6,
      "y": 13,
      "z": -3,
      "name": "Rock_Shale_Brick_Pillar_Middle"
    },
    {
      "x": -6,
      "y": 14,
      "z": -3,
      "name": "Rock_Shale_Brick_Pillar_Middle"
    },
    {
      "x": -6,
      "y": 15,
      "z": -3,
      "name": "Rock_Shale_Brick_Pillar_Middle"
    },
    {
      "x": -6,
      "y": 16,
      "z": -3,
      "name": "Rock_Shale_Brick_Pillar_Base",
      "rotation": 8
    },
    {
      "x": -6,
      "y": 17,
      "z": -3,
      "name": "Rock_Shale_Brick"
    },
    {
      "x": -6,
      "y": 18,
      "z": -3,
      "name": "Rock_Shale_Brick"
    },
    {
      "x": -6,
      "y": 19,
      "z": -3,
      "name": "Rock_Shale"
    },
    {
      "x": -6,
      "y": 20,
      "z": -3,
      "name": "Rock_Shale"
    },
    {
      "x": -6,
      "y": 21,
      "z": -3,
      "name": "Rock_Shale"
    },
    {
      "x": -6,
      "y": 6,
      "z": -2,
      "name": "Rock_Shale_Brick"
    },
    {
      "x": -6,
      "y": 7,
      "z": -2,
      "name": "Rock_Shale_Brick"
    },
    {
      "x": -6,
      "y": 8,
      "z": -2,
      "name": "Rock_Shale_Brick"
    },
    {
      "x": -6,
      "y": 9,
      "z": -2,
      "name": "Rock_Shale_Brick"
    },
    {
      "x": -6,
      "y": 10,
      "z": -2,
      "name": "Rock_Shale_Brick"
    },
    {
      "x": -6,
      "y": 11,
      "z": -2,
      "name": "Rock_Shale_Brick"
    },
    {
      "x": -6,
      "y": 12,
      "z": -2,
      "name": "Rock_Shale_Brick"
    },
    {
      "x": -6,
      "y": 13,
      "z": -2,
      "name": "Deco_Bone_Pile"
    },
    {
      "x": -6,
      "y": 14,
      "z": -2,
      "name": "Rock_Shale_Brick"
    },
    {
      "x": -6,
      "y": 15,
      "z": -2,
      "name": "Deco_Bone_Skulls"
    },
    {
      "x": -6,
      "y": 17,
      "z": -2,
      "name": "Rock_Shale_Brick"
    },
    {
      "x": -6,
      "y": 18,
      "z": -2,
      "name": "Rock_Shale_Brick"
    },
    {
      "x": -6,
      "y": 19,
      "z": -2,
      "name": "Rock_Shale"
    },
    {
      "x": -6,
      "y": 20,
      "z": -2,
      "name": "Rock_Shale"
    },
    {
      "x": -6,
      "y": 21,
      "z": -2,
      "name": "Rock_Shale"
    },
    {
      "x": -6,
      "y": 6,
      "z": -1,
      "name": "Rock_Shale_Brick"
    },
    {
      "x": -6,
      "y": 7,
      "z": -1,
      "name": "Rock_Shale_Brick"
    },
    {
      "x": -6,
      "y": 8,
      "z": -1,
      "name": "Rock_Shale_Brick"
    },
    {
      "x": -6,
      "y": 9,
      "z": -1,
      "name": "Rock_Shale_Brick"
    },
    {
      "x": -6,
      "y": 10,
      "z": -1,
      "name": "Rock_Shale_Brick"
    },
    {
      "x": -6,
      "y": 11,
      "z": -1,
      "name": "Rock_Shale_Brick"
    },
    {
      "x": -6,
      "y": 12,
      "z": -1,
      "name": "Rock_Shale_Brick"
    },
    {
      "x": -6,
      "y": 13,
      "z": -1,
      "name": "Deco_Bone_Pile"
    },
    {
      "x": -6,
      "y": 14,
      "z": -1,
      "name": "Rock_Shale_Brick"
    },
    {
      "x": -6,
      "y": 15,
      "z": -1,
      "name": "Deco_Bone_Skulls"
    },
    {
      "x": -6,
      "y": 17,
      "z": -1,
      "name": "Rock_Shale_Brick"
    },
    {
      "x": -6,
      "y": 18,
      "z": -1,
      "name": "Rock_Shale_Brick"
    },
    {
      "x": -6,
      "y": 19,
      "z": -1,
      "name": "Rock_Shale_Brick_Half",
      "rotation": 7
    },
    {
      "x": -6,
      "y": 20,
      "z": -1,
      "name": "Rock_Shale_Brick_Half",
      "rotation": 7
    },
    {
      "x": -6,
      "y": 21,
      "z": -1,
      "name": "Rock_Shale_Brick_Half",
      "rotation": 7
    },
    {
      "x": -6,
      "y": 22,
      "z": -1,
      "name": "Rock_Shale_Brick_Half",
      "rotation": 7
    },
    {
      "x": -6,
      "y": 6,
      "z": 0,
      "name": "Rock_Shale_Brick"
    },
    {
      "x": -6,
      "y": 7,
      "z": 0,
      "name": "Rock_Shale_Brick"
    },
    {
      "x": -6,
      "y": 8,
      "z": 0,
      "name": "Rock_Shale_Brick"
    },
    {
      "x": -6,
      "y": 9,
      "z": 0,
      "name": "Rock_Shale_Brick"
    },
    {
      "x": -6,
      "y": 10,
      "z": 0,
      "name": "Rock_Shale_Brick"
    },
    {
      "x": -6,
      "y": 11,
      "z": 0,
      "name": "Rock_Shale_Brick"
    },
    {
      "x": -6,
      "y": 12,
      "z": 0,
      "name": "Rock_Shale_Brick"
    },
    {
      "x": -6,
      "y": 13,
      "z": 0,
      "name": "Deco_Bone_Skulls"
    },
    {
      "x": -6,
      "y": 14,
      "z": 0,
      "name": "Rock_Shale_Brick"
    },
    {
      "x": -6,
      "y": 17,
      "z": 0,
      "name": "Rock_Shale_Brick"
    },
    {
      "x": -6,
      "y": 18,
      "z": 0,
      "name": "Rock_Shale_Brick"
    },
    {
      "x": -6,
      "y": 19,
      "z": 0,
      "name": "Rock_Shale"
    },
    {
      "x": -6,
      "y": 20,
      "z": 0,
      "name": "Rock_Shale"
    },
    {
      "x": -6,
      "y": 21,
      "z": 0,
      "name": "Rock_Shale"
    },
    {
      "x": -6,
      "y": 6,
      "z": 1,
      "name": "Rock_Shale_Brick"
    },
    {
      "x": -6,
      "y": 7,
      "z": 1,
      "name": "Rock_Shale_Brick"
    },
    {
      "x": -6,
      "y": 8,
      "z": 1,
      "name": "Rock_Shale_Brick"
    },
    {
      "x": -6,
      "y": 9,
      "z": 1,
      "name": "Rock_Shale_Brick"
    },
    {
      "x": -6,
      "y": 10,
      "z": 1,
      "name": "Rock_Shale_Brick"
    },
    {
      "x": -6,
      "y": 11,
      "z": 1,
      "name": "Rock_Shale_Brick"
    },
    {
      "x": -6,
      "y": 12,
      "z": 1,
      "name": "Rock_Shale_Brick"
    },
    {
      "x": -6,
      "y": 13,
      "z": 1,
      "name": "Rock_Shale_Brick_Half",
      "rotation": 7
    },
    {
      "x": -6,
      "y": 14,
      "z": 1,
      "name": "Rock_Shale_Brick"
    },
    {
      "x": -6,
      "y": 15,
      "z": 1,
      "name": "Rock_Shale_Brick_Half",
      "rotation": 7
    },
    {
      "x": -6,
      "y": 16,
      "z": 1,
      "name": "Rock_Shale_Brick_Half",
      "rotation": 7
    },
    {
      "x": -6,
      "y": 17,
      "z": 1,
      "name": "Rock_Shale_Brick"
    },
    {
      "x": -6,
      "y": 18,
      "z": 1,
      "name": "Rock_Shale_Brick"
    },
    {
      "x": -6,
      "y": 19,
      "z": 1,
      "name": "Rock_Shale"
    },
    {
      "x": -6,
      "y": 20,
      "z": 1,
      "name": "Rock_Shale"
    },
    {
      "x": -6,
      "y": 21,
      "z": 1,
      "name": "Rock_Shale"
    },
    {
      "x": -6,
      "y": 6,
      "z": 2,
      "name": "Rock_Shale_Brick"
    },
    {
      "x": -6,
      "y": 7,
      "z": 2,
      "name": "Rock_Shale_Brick"
    },
    {
      "x": -6,
      "y": 8,
      "z": 2,
      "name": "Rock_Shale_Brick"
    },
    {
      "x": -6,
      "y": 9,
      "z": 2,
      "name": "Rock_Shale_Brick"
    },
    {
      "x": -6,
      "y": 10,
      "z": 2,
      "name": "Rock_Shale_Brick"
    },
    {
      "x": -6,
      "y": 11,
      "z": 2,
      "name": "Rock_Shale_Brick"
    },
    {
      "x": -6,
      "y": 12,
      "z": 2,
      "name": "Rock_Shale_Brick"
    },
    {
      "x": -6,
      "y": 13,
      "z": 2,
      "name": "Deco_Bone_Pile"
    },
    {
      "x": -6,
      "y": 14,
      "z": 2,
      "name": "Rock_Shale_Brick"
    },
    {
      "x": -6,
      "y": 15,
      "z": 2,
      "name": "Deco_Bone_Pile"
    },
    {
      "x": -6,
      "y": 17,
      "z": 2,
      "name": "Rock_Shale_Brick"
    },
    {
      "x": -6,
      "y": 18,
      "z": 2,
      "name": "Rock_Shale_Brick"
    },
    {
      "x": -6,
      "y": 19,
      "z": 2,
      "name": "Rock_Shale"
    },
    {
      "x": -6,
      "y": 20,
      "z": 2,
      "name": "Rock_Shale"
    },
    {
      "x": -6,
      "y": 21,
      "z": 2,
      "name": "Rock_Shale"
    },
    {
      "x": -6,
      "y": 6,
      "z": 3,
      "name": "Rock_Shale_Brick"
    },
    {
      "x": -6,
      "y": 7,
      "z": 3,
      "name": "Rock_Shale_Brick"
    },
    {
      "x": -6,
      "y": 8,
      "z": 3,
      "name": "Rock_Shale_Brick"
    },
    {
      "x": -6,
      "y": 9,
      "z": 3,
      "name": "Rock_Shale_Brick"
    },
    {
      "x": -6,
      "y": 10,
      "z": 3,
      "name": "Rock_Shale_Brick"
    },
    {
      "x": -6,
      "y": 11,
      "z": 3,
      "name": "Rock_Shale_Brick"
    },
    {
      "x": -6,
      "y": 12,
      "z": 3,
      "name": "Rock_Shale_Brick"
    },
    {
      "x": -6,
      "y": 13,
      "z": 3,
      "name": "Deco_Bone_Skulls"
    },
    {
      "x": -6,
      "y": 14,
      "z": 3,
      "name": "Rock_Shale_Brick"
    },
    {
      "x": -6,
      "y": 15,
      "z": 3,
      "name": "Deco_Bone_Pile"
    },
    {
      "x": -6,
      "y": 17,
      "z": 3,
      "name": "Rock_Shale_Brick"
    },
    {
      "x": -6,
      "y": 18,
      "z": 3,
      "name": "Rock_Shale_Brick"
    },
    {
      "x": -6,
      "y": 20,
      "z": 3,
      "name": "Rock_Shale"
    },
    {
      "x": -6,
      "y": 21,
      "z": 3,
      "name": "Rock_Shale"
    },
    {
      "x": -6,
      "y": 6,
      "z": 4,
      "name": "Rock_Shale_Brick"
    },
    {
      "x": -6,
      "y": 7,
      "z": 4,
      "name": "Rock_Shale_Brick"
    },
    {
      "x": -6,
      "y": 8,
      "z": 4,
      "name": "Rock_Shale_Brick"
    },
    {
      "x": -6,
      "y": 9,
      "z": 4,
      "name": "Rock_Shale_Brick"
    },
    {
      "x": -6,
      "y": 10,
      "z": 4,
      "name": "Rock_Shale_Brick"
    },
    {
      "x": -6,
      "y": 11,
      "z": 4,
      "name": "Rock_Shale_Brick"
    },
    {
      "x": -6,
      "y": 12,
      "z": 4,
      "name": "Rock_Shale"
    },
    {
      "x": -6,
      "y": 13,
      "z": 4,
      "name": "Rock_Shale"
    },
    {
      "x": -6,
      "y": 14,
      "z": 4,
      "name": "Rock_Shale"
    },
    {
      "x": -6,
      "y": 17,
      "z": 4,
      "name": "Rock_Shale_Brick"
    },
    {
      "x": -6,
      "y": 18,
      "z": 4,
      "name": "Rock_Shale_Brick"
    },
    {
      "x": -6,
      "y": 19,
      "z": 4,
      "name": "Rock_Shale_Brick_Half",
      "rotation": 7
    },
    {
      "x": -6,
      "y": 20,
      "z": 4,
      "name": "Rock_Shale_Brick_Half",
      "rotation": 7
    },
    {
      "x": -6,
      "y": 21,
      "z": 4,
      "name": "Rock_Shale_Brick_Half",
      "rotation": 7
    },
    {
      "x": -6,
      "y": 22,
      "z": 4,
      "name": "Rock_Shale_Brick_Half",
      "rotation": 7
    },
    {
      "x": -6,
      "y": 6,
      "z": 5,
      "name": "Rock_Shale_Brick"
    },
    {
      "x": -6,
      "y": 7,
      "z": 5,
      "name": "Rock_Shale_Brick"
    },
    {
      "x": -6,
      "y": 8,
      "z": 5,
      "name": "Rock_Shale_Brick"
    },
    {
      "x": -6,
      "y": 9,
      "z": 5,
      "name": "Rock_Shale_Brick"
    },
    {
      "x": -6,
      "y": 10,
      "z": 5,
      "name": "Rock_Shale_Brick"
    },
    {
      "x": -6,
      "y": 11,
      "z": 5,
      "name": "Rock_Shale_Brick"
    },
    {
      "x": -6,
      "y": 12,
      "z": 5,
      "name": "Rock_Shale"
    },
    {
      "x": -6,
      "y": 13,
      "z": 5,
      "name": "Rock_Shale"
    },
    {
      "x": -6,
      "y": 14,
      "z": 5,
      "name": "Rock_Shale"
    },
    {
      "x": -6,
      "y": 17,
      "z": 5,
      "name": "Rock_Shale_Brick"
    },
    {
      "x": -6,
      "y": 18,
      "z": 5,
      "name": "Rock_Shale_Brick"
    },
    {
      "x": -6,
      "y": 19,
      "z": 5,
      "name": "Rock_Shale"
    },
    {
      "x": -6,
      "y": 20,
      "z": 5,
      "name": "Rock_Shale"
    },
    {
      "x": -6,
      "y": 21,
      "z": 5,
      "name": "Rock_Shale"
    },
    {
      "x": -6,
      "y": 6,
      "z": 6,
      "name": "Rock_Shale_Brick"
    },
    {
      "x": -6,
      "y": 7,
      "z": 6,
      "name": "Rock_Shale_Brick"
    },
    {
      "x": -6,
      "y": 8,
      "z": 6,
      "name": "Rock_Shale_Brick"
    },
    {
      "x": -6,
      "y": 9,
      "z": 6,
      "name": "Rock_Shale_Brick"
    },
    {
      "x": -6,
      "y": 10,
      "z": 6,
      "name": "Rock_Shale_Brick"
    },
    {
      "x": -6,
      "y": 11,
      "z": 6,
      "name": "Rock_Shale_Brick"
    },
    {
      "x": -6,
      "y": 12,
      "z": 6,
      "name": "Rock_Shale_Brick_Pillar_Base"
    },
    {
      "x": -6,
      "y": 13,
      "z": 6,
      "name": "Rock_Shale_Brick_Pillar_Middle"
    },
    {
      "x": -6,
      "y": 14,
      "z": 6,
      "name": "Rock_Shale_Brick_Pillar_Middle"
    },
    {
      "x": -6,
      "y": 15,
      "z": 6,
      "name": "Rock_Shale_Brick_Pillar_Middle"
    },
    {
      "x": -6,
      "y": 16,
      "z": 6,
      "name": "Rock_Shale_Brick_Pillar_Base",
      "rotation": 8
    },
    {
      "x": -6,
      "y": 17,
      "z": 6,
      "name": "Rock_Shale_Brick"
    },
    {
      "x": -6,
      "y": 18,
      "z": 6,
      "name": "Rock_Shale_Brick"
    },
    {
      "x": -6,
      "y": 19,
      "z": 6,
      "name": "Rock_Shale"
    },
    {
      "x": -6,
      "y": 20,
      "z": 6,
      "name": "Rock_Shale"
    },
    {
      "x": -6,
      "y": 21,
      "z": 6,
      "name": "Rock_Shale"
    },
    {
      "x": -6,
      "y": 6,
      "z": 7,
      "name": "Rock_Shale_Brick"
    },
    {
      "x": -6,
      "y": 7,
      "z": 7,
      "name": "Rock_Shale_Brick"
    },
    {
      "x": -6,
      "y": 8,
      "z": 7,
      "name": "Rock_Shale_Brick"
    },
    {
      "x": -6,
      "y": 9,
      "z": 7,
      "name": "Rock_Shale_Brick"
    },
    {
      "x": -6,
      "y": 10,
      "z": 7,
      "name": "Rock_Shale_Brick"
    },
    {
      "x": -6,
      "y": 11,
      "z": 7,
      "name": "Rock_Shale_Brick"
    },
    {
      "x": -6,
      "y": 12,
      "z": 7,
      "name": "Rock_Shale_Brick_Pillar_Base"
    },
    {
      "x": -6,
      "y": 13,
      "z": 7,
      "name": "Rock_Shale_Brick_Pillar_Middle"
    },
    {
      "x": -6,
      "y": 14,
      "z": 7,
      "name": "Rock_Shale_Brick_Pillar_Middle"
    },
    {
      "x": -6,
      "y": 15,
      "z": 7,
      "name": "Rock_Shale_Brick_Pillar_Middle"
    },
    {
      "x": -6,
      "y": 16,
      "z": 7,
      "name": "Rock_Shale_Brick_Pillar_Base",
      "rotation": 8
    },
    {
      "x": -6,
      "y": 17,
      "z": 7,
      "name": "Rock_Shale_Brick"
    },
    {
      "x": -6,
      "y": 18,
      "z": 7,
      "name": "Rock_Shale_Brick"
    },
    {
      "x": -6,
      "y": 19,
      "z": 7,
      "name": "Rock_Shale_Brick_Half"
    },
    {
      "x": -6,
      "y": 20,
      "z": 7,
      "name": "Rock_Shale"
    },
    {
      "x": -6,
      "y": 21,
      "z": 7,
      "name": "Rock_Shale"
    },
    {
      "x": -6,
      "y": 17,
      "z": 8,
      "name": "Rock_Shale_Brick_Stairs",
      "rotation": 10
    },
    {
      "x": -6,
      "y": 18,
      "z": 8,
      "name": "Rock_Shale_Brick"
    },
    {
      "x": -6,
      "y": 21,
      "z": 8,
      "name": "Rock_Shale"
    },
    {
      "x": -6,
      "y": 18,
      "z": 9,
      "name": "Rock_Shale_Brick"
    },
    {
      "x": -5,
      "y": 1,
      "z": -8,
      "name": "Rock_Shale_Brick_Smooth"
    },
    {
      "x": -5,
      "y": 2,
      "z": -8,
      "name": "Rock_Shale"
    },
    {
      "x": -5,
      "y": 3,
      "z": -8,
      "name": "Rock_Shale"
    },
    {
      "x": -5,
      "y": 4,
      "z": -8,
      "name": "Rock_Shale"
    },
    {
      "x": -5,
      "y": 5,
      "z": -8,
      "name": "Rock_Shale"
    },
    {
      "x": -5,
      "y": 6,
      "z": -8,
      "name": "Rock_Shale"
    },
    {
      "x": -5,
      "y": 7,
      "z": -8,
      "name": "Rock_Shale"
    },
    {
      "x": -5,
      "y": 1,
      "z": -7,
      "name": "Rock_Shale_Brick_Smooth"
    },
    {
      "x": -5,
      "y": 2,
      "z": -7,
      "name": "Rock_Shale"
    },
    {
      "x": -5,
      "y": 3,
      "z": -7,
      "name": "Rock_Shale"
    },
    {
      "x": -5,
      "y": 4,
      "z": -7,
      "name": "Rock_Shale"
    },
    {
      "x": -5,
      "y": 5,
      "z": -7,
      "name": "Rock_Shale"
    },
    {
      "x": -5,
      "y": 6,
      "z": -7,
      "name": "Rock_Shale"
    },
    {
      "x": -5,
      "y": 7,
      "z": -7,
      "name": "Rock_Shale"
    },
    {
      "x": -5,
      "y": 1,
      "z": -6,
      "name": "Rock_Shale_Brick_Smooth"
    },
    {
      "x": -5,
      "y": 2,
      "z": -6,
      "name": "Rock_Shale"
    },
    {
      "x": -5,
      "y": 3,
      "z": -6,
      "name": "Rock_Shale"
    },
    {
      "x": -5,
      "y": 4,
      "z": -6,
      "name": "Rock_Shale"
    },
    {
      "x": -5,
      "y": 5,
      "z": -6,
      "name": "Rock_Shale"
    },
    {
      "x": -5,
      "y": 6,
      "z": -6,
      "name": "Rock_Shale"
    },
    {
      "x": -5,
      "y": 7,
      "z": -6,
      "name": "Rock_Shale"
    },
    {
      "x": -5,
      "y": 8,
      "z": -6,
      "name": "Rock_Shale"
    },
    {
      "x": -5,
      "y": 18,
      "z": -6,
      "name": "Rock_Shale_Brick"
    },
    {
      "x": -5,
      "y": 1,
      "z": -5,
      "name": "Rock_Shale_Brick_Smooth"
    },
    {
      "x": -5,
      "y": 2,
      "z": -5,
      "name": "Rock_Shale"
    },
    {
      "x": -5,
      "y": 3,
      "z": -5,
      "name": "Rock_Shale"
    },
    {
      "x": -5,
      "y": 4,
      "z": -5,
      "name": "Rock_Shale"
    },
    {
      "x": -5,
      "y": 5,
      "z": -5,
      "name": "Rock_Shale"
    },
    {
      "x": -5,
      "y": 6,
      "z": -5,
      "name": "Rock_Basalt"
    },
    {
      "x": -5,
      "y": 7,
      "z": -5,
      "name": "Rock_Basalt"
    },
    {
      "x": -5,
      "y": 8,
      "z": -5,
      "name": "Rock_Shale"
    },
    {
      "x": -5,
      "y": 9,
      "z": -5,
      "name": "Rock_Shale"
    },
    {
      "x": -5,
      "y": 17,
      "z": -5,
      "name": "Rock_Shale_Brick_Stairs",
      "rotation": 8
    },
    {
      "x": -5,
      "y": 18,
      "z": -5,
      "name": "Rock_Shale_Brick"
    },
    {
      "x": -5,
      "y": 19,
      "z": -5,
      "name": "Rock_Shale"
    },
    {
      "x": -5,
      "y": 20,
      "z": -5,
      "name": "Rock_Shale"
    },
    {
      "x": -5,
      "y": 22,
      "z": -5,
      "name": "Rock_Shale"
    },
    {
      "x": -5,
      "y": 2,
      "z": -4,
      "name": "Rock_Shale"
    },
    {
      "x": -5,
      "y": 3,
      "z": -4,
      "name": "Rock_Shale"
    },
    {
      "x": -5,
      "y": 4,
      "z": -4,
      "name": "Rock_Shale"
    },
    {
      "x": -5,
      "y": 5,
      "z": -4,
      "name": "Rock_Shale"
    },
    {
      "x": -5,
      "y": 6,
      "z": -4,
      "name": "Rock_Shale"
    },
    {
      "x": -5,
      "y": 7,
      "z": -4,
      "name": "Rock_Basalt"
    },
    {
      "x": -5,
      "y": 8,
      "z": -4,
      "name": "Rock_Basalt"
    },
    {
      "x": -5,
      "y": 9,
      "z": -4,
      "name": "Rock_Shale"
    },
    {
      "x": -5,
      "y": 10,
      "z": -4,
      "name": "Rock_Shale"
    },
    {
      "x": -5,
      "y": 11,
      "z": -4,
      "name": "Rock_Shale_Brick"
    },
    {
      "x": -5,
      "y": 12,
      "z": -4,
      "name": "Rock_Shale_Brick_Pillar_Base"
    },
    {
      "x": -5,
      "y": 13,
      "z": -4,
      "name": "Rock_Shale_Brick_Pillar_Middle"
    },
    {
      "x": -5,
      "y": 14,
      "z": -4,
      "name": "Rock_Shale_Brick_Pillar_Middle"
    },
    {
      "x": -5,
      "y": 15,
      "z": -4,
      "name": "Rock_Shale_Brick_Pillar_Middle"
    },
    {
      "x": -5,
      "y": 16,
      "z": -4,
      "name": "Rock_Shale_Brick_Pillar_Base",
      "rotation": 8
    },
    {
      "x": -5,
      "y": 17,
      "z": -4,
      "name": "Rock_Shale_Brick"
    },
    {
      "x": -5,
      "y": 18,
      "z": -4,
      "name": "Rock_Shale_Brick"
    },
    {
      "x": -5,
      "y": 19,
      "z": -4,
      "name": "Rock_Shale"
    },
    {
      "x": -5,
      "y": 20,
      "z": -4,
      "name": "Rock_Shale"
    },
    {
      "x": -5,
      "y": 21,
      "z": -4,
      "name": "Rock_Shale"
    },
    {
      "x": -5,
      "y": 22,
      "z": -4,
      "name": "Rock_Shale"
    },
    {
      "x": -5,
      "y": 23,
      "z": -4,
      "name": "Rock_Shale"
    },
    {
      "x": -5,
      "y": 3,
      "z": -3,
      "name": "Rock_Shale"
    },
    {
      "x": -5,
      "y": 4,
      "z": -3,
      "name": "Rock_Shale"
    },
    {
      "x": -5,
      "y": 5,
      "z": -3,
      "name": "Rock_Shale"
    },
    {
      "x": -5,
      "y": 6,
      "z": -3,
      "name": "Rock_Shale"
    },
    {
      "x": -5,
      "y": 7,
      "z": -3,
      "name": "Rock_Shale"
    },
    {
      "x": -5,
      "y": 8,
      "z": -3,
      "name": "Rock_Basalt"
    },
    {
      "x": -5,
      "y": 9,
      "z": -3,
      "name": "Rock_Basalt"
    },
    {
      "x": -5,
      "y": 10,
      "z": -3,
      "name": "Rock_Shale"
    },
    {
      "x": -5,
      "y": 11,
      "z": -3,
      "name": "Rock_Shale_Brick"
    },
    {
      "x": -5,
      "y": 12,
      "z": -3,
      "name": "Rock_Shale_Brick"
    },
    {
      "x": -5,
      "y": 13,
      "z": -3,
      "name": "Rock_Shale_Brick"
    },
    {
      "x": -5,
      "y": 14,
      "z": -3,
      "name": "Rock_Shale_Brick"
    },
    {
      "x": -5,
      "y": 15,
      "z": -3,
      "name": "Rock_Shale_Brick"
    },
    {
      "x": -5,
      "y": 16,
      "z": -3,
      "name": "Rock_Shale_Brick"
    },
    {
      "x": -5,
      "y": 17,
      "z": -3,
      "name": "Rock_Shale_Brick"
    },
    {
      "x": -5,
      "y": 18,
      "z": -3,
      "name": "Rock_Shale_Brick"
    },
    {
      "x": -5,
      "y": 19,
      "z": -3,
      "name": "Rock_Shale"
    },
    {
      "x": -5,
      "y": 20,
      "z": -3,
      "name": "Rock_Shale"
    },
    {
      "x": -5,
      "y": 21,
      "z": -3,
      "name": "Rock_Shale"
    },
    {
      "x": -5,
      "y": 22,
      "z": -3,
      "name": "Rock_Shale"
    },
    {
      "x": -5,
      "y": 23,
      "z": -3,
      "name": "Rock_Shale"
    },
    {
      "x": -5,
      "y": 4,
      "z": -2,
      "name": "Rock_Shale"
    },
    {
      "x": -5,
      "y": 5,
      "z": -2,
      "name": "Rock_Shale"
    },
    {
      "x": -5,
      "y": 6,
      "z": -2,
      "name": "Rock_Shale"
    },
    {
      "x": -5,
      "y": 7,
      "z": -2,
      "name": "Rock_Shale"
    },
    {
      "x": -5,
      "y": 8,
      "z": -2,
      "name": "Rock_Shale"
    },
    {
      "x": -5,
      "y": 9,
      "z": -2,
      "name": "Rock_Shale"
    },
    {
      "x": -5,
      "y": 10,
      "z": -2,
      "name": "Rock_Shale"
    },
    {
      "x": -5,
      "y": 11,
      "z": -2,
      "name": "Rock_Shale"
    },
    {
      "x": -5,
      "y": 12,
      "z": -2,
      "name": "Rock_Shale_Brick"
    },
    {
      "x": -5,
      "y": 13,
      "z": -2,
      "name": "Rock_Shale_Brick"
    },
    {
      "x": -5,
      "y": 14,
      "z": -2,
      "name": "Rock_Shale_Brick"
    },
    {
      "x": -5,
      "y": 15,
      "z": -2,
      "name": "Rock_Shale_Brick"
    },
    {
      "x": -5,
      "y": 16,
      "z": -2,
      "name": "Rock_Shale_Brick"
    },
    {
      "x": -5,
      "y": 17,
      "z": -2,
      "name": "Rock_Shale_Brick"
    },
    {
      "x": -5,
      "y": 18,
      "z": -2,
      "name": "Rock_Shale_Brick"
    },
    {
      "x": -5,
      "y": 19,
      "z": -2,
      "name": "Rock_Shale"
    },
    {
      "x": -5,
      "y": 20,
      "z": -2,
      "name": "Rock_Shale"
    },
    {
      "x": -5,
      "y": 21,
      "z": -2,
      "name": "Rock_Shale"
    },
    {
      "x": -5,
      "y": 22,
      "z": -2,
      "name": "Rock_Shale"
    },
    {
      "x": -5,
      "y": 23,
      "z": -2,
      "name": "Rock_Shale"
    },
    {
      "x": -5,
      "y": 5,
      "z": -1,
      "name": "Rock_Shale"
    },
    {
      "x": -5,
      "y": 6,
      "z": -1,
      "name": "Rock_Shale"
    },
    {
      "x": -5,
      "y": 7,
      "z": -1,
      "name": "Rock_Shale"
    },
    {
      "x": -5,
      "y": 8,
      "z": -1,
      "name": "Rock_Shale"
    },
    {
      "x": -5,
      "y": 9,
      "z": -1,
      "name": "Rock_Shale"
    },
    {
      "x": -5,
      "y": 10,
      "z": -1,
      "name": "Rock_Basalt"
    },
    {
      "x": -5,
      "y": 11,
      "z": -1,
      "name": "Rock_Basalt"
    },
    {
      "x": -5,
      "y": 12,
      "z": -1,
      "name": "Rock_Shale_Brick"
    },
    {
      "x": -5,
      "y": 13,
      "z": -1,
      "name": "Rock_Shale_Brick"
    },
    {
      "x": -5,
      "y": 14,
      "z": -1,
      "name": "Rock_Shale_Brick"
    },
    {
      "x": -5,
      "y": 15,
      "z": -1,
      "name": "Rock_Shale_Brick"
    },
    {
      "x": -5,
      "y": 16,
      "z": -1,
      "name": "Rock_Shale_Brick"
    },
    {
      "x": -5,
      "y": 17,
      "z": -1,
      "name": "Rock_Shale_Brick"
    },
    {
      "x": -5,
      "y": 18,
      "z": -1,
      "name": "Rock_Shale_Brick"
    },
    {
      "x": -5,
      "y": 19,
      "z": -1,
      "name": "Rock_Shale"
    },
    {
      "x": -5,
      "y": 20,
      "z": -1,
      "name": "Rock_Shale"
    },
    {
      "x": -5,
      "y": 21,
      "z": -1,
      "name": "Rock_Shale"
    },
    {
      "x": -5,
      "y": 22,
      "z": -1,
      "name": "Rock_Shale"
    },
    {
      "x": -5,
      "y": 23,
      "z": -1,
      "name": "Rock_Shale_Brick_Stairs",
      "rotation": 3
    },
    {
      "x": -5,
      "y": 6,
      "z": 0,
      "name": "Rock_Shale"
    },
    {
      "x": -5,
      "y": 7,
      "z": 0,
      "name": "Rock_Shale"
    },
    {
      "x": -5,
      "y": 8,
      "z": 0,
      "name": "Rock_Shale"
    },
    {
      "x": -5,
      "y": 9,
      "z": 0,
      "name": "Rock_Shale"
    },
    {
      "x": -5,
      "y": 10,
      "z": 0,
      "name": "Rock_Shale"
    },
    {
      "x": -5,
      "y": 11,
      "z": 0,
      "name": "Rock_Basalt"
    },
    {
      "x": -5,
      "y": 12,
      "z": 0,
      "name": "Rock_Shale_Brick"
    },
    {
      "x": -5,
      "y": 13,
      "z": 0,
      "name": "Rock_Shale_Brick"
    },
    {
      "x": -5,
      "y": 14,
      "z": 0,
      "name": "Rock_Shale_Brick"
    },
    {
      "x": -5,
      "y": 15,
      "z": 0,
      "name": "Rock_Shale_Brick"
    },
    {
      "x": -5,
      "y": 16,
      "z": 0,
      "name": "Rock_Shale_Brick"
    },
    {
      "x": -5,
      "y": 17,
      "z": 0,
      "name": "Rock_Shale_Brick"
    },
    {
      "x": -5,
      "y": 18,
      "z": 0,
      "name": "Rock_Shale_Brick"
    },
    {
      "x": -5,
      "y": 19,
      "z": 0,
      "name": "Rock_Shale"
    },
    {
      "x": -5,
      "y": 20,
      "z": 0,
      "name": "Rock_Shale"
    },
    {
      "x": -5,
      "y": 21,
      "z": 0,
      "name": "Rock_Shale"
    },
    {
      "x": -5,
      "y": 22,
      "z": 0,
      "name": "Rock_Shale"
    },
    {
      "x": -5,
      "y": 6,
      "z": 1,
      "name": "Rock_Shale_Brick"
    },
    {
      "x": -5,
      "y": 7,
      "z": 1,
      "name": "Rock_Shale"
    },
    {
      "x": -5,
      "y": 8,
      "z": 1,
      "name": "Rock_Shale"
    },
    {
      "x": -5,
      "y": 9,
      "z": 1,
      "name": "Rock_Shale"
    },
    {
      "x": -5,
      "y": 10,
      "z": 1,
      "name": "Rock_Shale"
    },
    {
      "x": -5,
      "y": 11,
      "z": 1,
      "name": "Rock_Shale"
    },
    {
      "x": -5,
      "y": 12,
      "z": 1,
      "name": "Rock_Shale_Brick"
    },
    {
      "x": -5,
      "y": 13,
      "z": 1,
      "name": "Rock_Shale_Brick"
    },
    {
      "x": -5,
      "y": 14,
      "z": 1,
      "name": "Rock_Shale_Brick"
    },
    {
      "x": -5,
      "y": 15,
      "z": 1,
      "name": "Rock_Shale_Brick"
    },
    {
      "x": -5,
      "y": 16,
      "z": 1,
      "name": "Rock_Shale_Brick"
    },
    {
      "x": -5,
      "y": 17,
      "z": 1,
      "name": "Rock_Shale_Brick"
    },
    {
      "x": -5,
      "y": 18,
      "z": 1,
      "name": "Rock_Shale_Brick"
    },
    {
      "x": -5,
      "y": 19,
      "z": 1,
      "name": "Rock_Shale"
    },
    {
      "x": -5,
      "y": 20,
      "z": 1,
      "name": "Rock_Shale"
    },
    {
      "x": -5,
      "y": 21,
      "z": 1,
      "name": "Rock_Shale"
    },
    {
      "x": -5,
      "y": 22,
      "z": 1,
      "name": "Rock_Shale"
    },
    {
      "x": -5,
      "y": 6,
      "z": 2,
      "name": "Rock_Shale_Brick"
    },
    {
      "x": -5,
      "y": 7,
      "z": 2,
      "name": "Rock_Shale_Brick"
    },
    {
      "x": -5,
      "y": 8,
      "z": 2,
      "name": "Rock_Shale"
    },
    {
      "x": -5,
      "y": 9,
      "z": 2,
      "name": "Rock_Shale"
    },
    {
      "x": -5,
      "y": 10,
      "z": 2,
      "name": "Rock_Shale"
    },
    {
      "x": -5,
      "y": 11,
      "z": 2,
      "name": "Rock_Shale"
    },
    {
      "x": -5,
      "y": 12,
      "z": 2,
      "name": "Rock_Shale_Brick"
    },
    {
      "x": -5,
      "y": 13,
      "z": 2,
      "name": "Rock_Shale_Brick"
    },
    {
      "x": -5,
      "y": 14,
      "z": 2,
      "name": "Rock_Shale_Brick"
    },
    {
      "x": -5,
      "y": 15,
      "z": 2,
      "name": "Rock_Shale_Brick"
    },
    {
      "x": -5,
      "y": 16,
      "z": 2,
      "name": "Rock_Shale_Brick"
    },
    {
      "x": -5,
      "y": 17,
      "z": 2,
      "name": "Rock_Shale_Brick"
    },
    {
      "x": -5,
      "y": 18,
      "z": 2,
      "name": "Rock_Shale_Brick"
    },
    {
      "x": -5,
      "y": 19,
      "z": 2,
      "name": "Rock_Shale"
    },
    {
      "x": -5,
      "y": 20,
      "z": 2,
      "name": "Rock_Shale"
    },
    {
      "x": -5,
      "y": 21,
      "z": 2,
      "name": "Rock_Shale"
    },
    {
      "x": -5,
      "y": 22,
      "z": 2,
      "name": "Rock_Shale"
    },
    {
      "x": -5,
      "y": 6,
      "z": 3,
      "name": "Rock_Shale_Brick"
    },
    {
      "x": -5,
      "y": 7,
      "z": 3,
      "name": "Rock_Shale_Brick"
    },
    {
      "x": -5,
      "y": 8,
      "z": 3,
      "name": "Rock_Shale_Brick"
    },
    {
      "x": -5,
      "y": 9,
      "z": 3,
      "name": "Rock_Shale"
    },
    {
      "x": -5,
      "y": 10,
      "z": 3,
      "name": "Rock_Shale"
    },
    {
      "x": -5,
      "y": 11,
      "z": 3,
      "name": "Rock_Shale"
    },
    {
      "x": -5,
      "y": 12,
      "z": 3,
      "name": "Rock_Shale_Brick"
    },
    {
      "x": -5,
      "y": 13,
      "z": 3,
      "name": "Rock_Shale_Brick"
    },
    {
      "x": -5,
      "y": 14,
      "z": 3,
      "name": "Rock_Shale_Brick"
    },
    {
      "x": -5,
      "y": 15,
      "z": 3,
      "name": "Rock_Shale_Brick"
    },
    {
      "x": -5,
      "y": 16,
      "z": 3,
      "name": "Rock_Shale_Brick"
    },
    {
      "x": -5,
      "y": 17,
      "z": 3,
      "name": "Rock_Shale_Brick"
    },
    {
      "x": -5,
      "y": 18,
      "z": 3,
      "name": "Rock_Shale_Brick"
    },
    {
      "x": -5,
      "y": 19,
      "z": 3,
      "name": "Rock_Shale"
    },
    {
      "x": -5,
      "y": 20,
      "z": 3,
      "name": "Rock_Shale"
    },
    {
      "x": -5,
      "y": 21,
      "z": 3,
      "name": "Rock_Shale"
    },
    {
      "x": -5,
      "y": 22,
      "z": 3,
      "name": "Rock_Shale"
    },
    {
      "x": -5,
      "y": 6,
      "z": 4,
      "name": "Rock_Shale_Brick"
    },
    {
      "x": -5,
      "y": 7,
      "z": 4,
      "name": "Rock_Shale_Brick"
    },
    {
      "x": -5,
      "y": 8,
      "z": 4,
      "name": "Rock_Shale_Brick"
    },
    {
      "x": -5,
      "y": 9,
      "z": 4,
      "name": "Rock_Shale_Brick"
    },
    {
      "x": -5,
      "y": 10,
      "z": 4,
      "name": "Rock_Shale"
    },
    {
      "x": -5,
      "y": 11,
      "z": 4,
      "name": "Rock_Shale"
    },
    {
      "x": -5,
      "y": 12,
      "z": 4,
      "name": "Rock_Shale_Brick"
    },
    {
      "x": -5,
      "y": 13,
      "z": 4,
      "name": "Rock_Shale_Brick"
    },
    {
      "x": -5,
      "y": 14,
      "z": 4,
      "name": "Rock_Shale_Brick"
    },
    {
      "x": -5,
      "y": 15,
      "z": 4,
      "name": "Rock_Shale_Brick"
    },
    {
      "x": -5,
      "y": 16,
      "z": 4,
      "name": "Rock_Shale_Brick"
    },
    {
      "x": -5,
      "y": 17,
      "z": 4,
      "name": "Rock_Shale_Brick"
    },
    {
      "x": -5,
      "y": 18,
      "z": 4,
      "name": "Rock_Shale_Brick"
    },
    {
      "x": -5,
      "y": 19,
      "z": 4,
      "name": "Rock_Shale"
    },
    {
      "x": -5,
      "y": 20,
      "z": 4,
      "name": "Rock_Shale"
    },
    {
      "x": -5,
      "y": 21,
      "z": 4,
      "name": "Rock_Shale"
    },
    {
      "x": -5,
      "y": 22,
      "z": 4,
      "name": "Rock_Shale"
    },
    {
      "x": -5,
      "y": 23,
      "z": 4,
      "name": "Rock_Shale_Brick_Stairs",
      "rotation": 3
    },
    {
      "x": -5,
      "y": 6,
      "z": 5,
      "name": "Rock_Shale"
    },
    {
      "x": -5,
      "y": 7,
      "z": 5,
      "name": "Rock_Shale"
    },
    {
      "x": -5,
      "y": 8,
      "z": 5,
      "name": "Rock_Shale"
    },
    {
      "x": -5,
      "y": 9,
      "z": 5,
      "name": "Rock_Shale"
    },
    {
      "x": -5,
      "y": 10,
      "z": 5,
      "name": "Rock_Shale"
    },
    {
      "x": -5,
      "y": 11,
      "z": 5,
      "name": "Rock_Shale"
    },
    {
      "x": -5,
      "y": 12,
      "z": 5,
      "name": "Rock_Shale_Brick"
    },
    {
      "x": -5,
      "y": 13,
      "z": 5,
      "name": "Rock_Shale_Brick"
    },
    {
      "x": -5,
      "y": 14,
      "z": 5,
      "name": "Rock_Shale_Brick"
    },
    {
      "x": -5,
      "y": 15,
      "z": 5,
      "name": "Rock_Shale_Brick"
    },
    {
      "x": -5,
      "y": 16,
      "z": 5,
      "name": "Rock_Shale_Brick"
    },
    {
      "x": -5,
      "y": 17,
      "z": 5,
      "name": "Rock_Shale_Brick"
    },
    {
      "x": -5,
      "y": 18,
      "z": 5,
      "name": "Rock_Shale_Brick"
    },
    {
      "x": -5,
      "y": 19,
      "z": 5,
      "name": "Rock_Shale"
    },
    {
      "x": -5,
      "y": 20,
      "z": 5,
      "name": "Rock_Shale"
    },
    {
      "x": -5,
      "y": 21,
      "z": 5,
      "name": "Rock_Shale"
    },
    {
      "x": -5,
      "y": 22,
      "z": 5,
      "name": "Rock_Shale"
    },
    {
      "x": -5,
      "y": 6,
      "z": 6,
      "name": "Rock_Shale_Brick"
    },
    {
      "x": -5,
      "y": 7,
      "z": 6,
      "name": "Rock_Shale_Brick"
    },
    {
      "x": -5,
      "y": 8,
      "z": 6,
      "name": "Rock_Shale_Brick"
    },
    {
      "x": -5,
      "y": 9,
      "z": 6,
      "name": "Rock_Shale_Brick"
    },
    {
      "x": -5,
      "y": 10,
      "z": 6,
      "name": "Rock_Shale_Brick"
    },
    {
      "x": -5,
      "y": 11,
      "z": 6,
      "name": "Rock_Shale_Brick"
    },
    {
      "x": -5,
      "y": 12,
      "z": 6,
      "name": "Rock_Shale_Brick"
    },
    {
      "x": -5,
      "y": 13,
      "z": 6,
      "name": "Rock_Shale_Brick"
    },
    {
      "x": -5,
      "y": 14,
      "z": 6,
      "name": "Rock_Shale_Brick"
    },
    {
      "x": -5,
      "y": 15,
      "z": 6,
      "name": "Rock_Shale_Brick"
    },
    {
      "x": -5,
      "y": 16,
      "z": 6,
      "name": "Rock_Shale_Brick"
    },
    {
      "x": -5,
      "y": 17,
      "z": 6,
      "name": "Rock_Shale_Brick"
    },
    {
      "x": -5,
      "y": 18,
      "z": 6,
      "name": "Rock_Shale_Brick"
    },
    {
      "x": -5,
      "y": 19,
      "z": 6,
      "name": "Rock_Shale"
    },
    {
      "x": -5,
      "y": 20,
      "z": 6,
      "name": "Rock_Shale"
    },
    {
      "x": -5,
      "y": 21,
      "z": 6,
      "name": "Rock_Shale"
    },
    {
      "x": -5,
      "y": 22,
      "z": 6,
      "name": "Rock_Shale"
    },
    {
      "x": -5,
      "y": 6,
      "z": 7,
      "name": "Rock_Shale_Brick"
    },
    {
      "x": -5,
      "y": 7,
      "z": 7,
      "name": "Rock_Shale_Brick"
    },
    {
      "x": -5,
      "y": 8,
      "z": 7,
      "name": "Rock_Shale_Brick"
    },
    {
      "x": -5,
      "y": 9,
      "z": 7,
      "name": "Rock_Shale_Brick"
    },
    {
      "x": -5,
      "y": 10,
      "z": 7,
      "name": "Rock_Shale_Brick"
    },
    {
      "x": -5,
      "y": 11,
      "z": 7,
      "name": "Rock_Shale_Brick"
    },
    {
      "x": -5,
      "y": 12,
      "z": 7,
      "name": "Rock_Shale_Brick_Pillar_Base"
    },
    {
      "x": -5,
      "y": 13,
      "z": 7,
      "name": "Rock_Shale_Brick_Pillar_Middle"
    },
    {
      "x": -5,
      "y": 14,
      "z": 7,
      "name": "Rock_Shale_Brick_Pillar_Middle"
    },
    {
      "x": -5,
      "y": 15,
      "z": 7,
      "name": "Rock_Shale_Brick_Pillar_Middle"
    },
    {
      "x": -5,
      "y": 16,
      "z": 7,
      "name": "Rock_Shale_Brick_Pillar_Base",
      "rotation": 8
    },
    {
      "x": -5,
      "y": 17,
      "z": 7,
      "name": "Rock_Shale_Brick"
    },
    {
      "x": -5,
      "y": 18,
      "z": 7,
      "name": "Rock_Shale_Brick"
    },
    {
      "x": -5,
      "y": 19,
      "z": 7,
      "name": "Rock_Shale"
    },
    {
      "x": -5,
      "y": 20,
      "z": 7,
      "name": "Rock_Shale"
    },
    {
      "x": -5,
      "y": 21,
      "z": 7,
      "name": "Rock_Shale"
    },
    {
      "x": -5,
      "y": 22,
      "z": 7,
      "name": "Rock_Shale"
    },
    {
      "x": -5,
      "y": 17,
      "z": 8,
      "name": "Rock_Shale_Brick_Stairs",
      "rotation": 10
    },
    {
      "x": -5,
      "y": 18,
      "z": 8,
      "name": "Rock_Shale_Brick"
    },
    {
      "x": -5,
      "y": 20,
      "z": 8,
      "name": "Rock_Shale"
    },
    {
      "x": -5,
      "y": 21,
      "z": 8,
      "name": "Rock_Shale"
    },
    {
      "x": -5,
      "y": 18,
      "z": 9,
      "name": "Rock_Shale_Brick"
    },
    {
      "x": -4,
      "y": 1,
      "z": -8,
      "name": "Rock_Shale_Brick_Smooth"
    },
    {
      "x": -4,
      "y": 2,
      "z": -8,
      "name": "Empty"
    },
    {
      "x": -4,
      "y": 3,
      "z": -8,
      "name": "Empty"
    },
    {
      "x": -4,
      "y": 4,
      "z": -8,
      "name": "Empty"
    },
    {
      "x": -4,
      "y": 5,
      "z": -8,
      "name": "Empty"
    },
    {
      "x": -4,
      "y": 6,
      "z": -8,
      "name": "Rock_Shale_Brick"
    },
    {
      "x": -4,
      "y": 7,
      "z": -8,
      "name": "Rock_Shale"
    },
    {
      "x": -4,
      "y": 8,
      "z": -8,
      "name": "Empty"
    },
    {
      "x": -4,
      "y": 9,
      "z": -8,
      "name": "Empty"
    },
    {
      "x": -4,
      "y": 10,
      "z": -8,
      "name": "Empty"
    },
    {
      "x": -4,
      "y": 11,
      "z": -8,
      "name": "Empty"
    },
    {
      "x": -4,
      "y": 12,
      "z": -8,
      "name": "Empty"
    },
    {
      "x": -4,
      "y": 13,
      "z": -8,
      "name": "Empty"
    },
    {
      "x": -4,
      "y": 14,
      "z": -8,
      "name": "Empty"
    },
    {
      "x": -4,
      "y": 15,
      "z": -8,
      "name": "Empty"
    },
    {
      "x": -4,
      "y": 16,
      "z": -8,
      "name": "Empty"
    },
    {
      "x": -4,
      "y": 17,
      "z": -8,
      "name": "Empty"
    },
    {
      "x": -4,
      "y": 18,
      "z": -8,
      "name": "Empty"
    },
    {
      "x": -4,
      "y": 19,
      "z": -8,
      "name": "Empty"
    },
    {
      "x": -4,
      "y": 20,
      "z": -8,
      "name": "Empty"
    },
    {
      "x": -4,
      "y": 1,
      "z": -7,
      "name": "Rock_Shale_Brick_Smooth"
    },
    {
      "x": -4,
      "y": 2,
      "z": -7,
      "name": "Empty"
    },
    {
      "x": -4,
      "y": 3,
      "z": -7,
      "name": "Empty"
    },
    {
      "x": -4,
      "y": 4,
      "z": -7,
      "name": "Empty"
    },
    {
      "x": -4,
      "y": 5,
      "z": -7,
      "name": "Rock_Shale_Brick_Stairs",
      "rotation": 8
    },
    {
      "x": -4,
      "y": 6,
      "z": -7,
      "name": "Rock_Shale_Brick"
    },
    {
      "x": -4,
      "y": 7,
      "z": -7,
      "name": "Rock_Shale"
    },
    {
      "x": -4,
      "y": 8,
      "z": -7,
      "name": "Empty"
    },
    {
      "x": -4,
      "y": 9,
      "z": -7,
      "name": "Empty"
    },
    {
      "x": -4,
      "y": 10,
      "z": -7,
      "name": "Empty"
    },
    {
      "x": -4,
      "y": 11,
      "z": -7,
      "name": "Empty"
    },
    {
      "x": -4,
      "y": 12,
      "z": -7,
      "name": "Empty"
    },
    {
      "x": -4,
      "y": 13,
      "z": -7,
      "name": "Empty"
    },
    {
      "x": -4,
      "y": 14,
      "z": -7,
      "name": "Empty"
    },
    {
      "x": -4,
      "y": 15,
      "z": -7,
      "name": "Empty"
    },
    {
      "x": -4,
      "y": 16,
      "z": -7,
      "name": "Empty"
    },
    {
      "x": -4,
      "y": 17,
      "z": -7,
      "name": "Empty"
    },
    {
      "x": -4,
      "y": 18,
      "z": -7,
      "name": "Empty"
    },
    {
      "x": -4,
      "y": 19,
      "z": -7,
      "name": "Empty"
    },
    {
      "x": -4,
      "y": 20,
      "z": -7,
      "name": "Empty"
    },
    {
      "x": -4,
      "y": 1,
      "z": -6,
      "name": "Rock_Shale_Brick_Smooth"
    },
    {
      "x": -4,
      "y": 2,
      "z": -6,
      "name": "Rock_Shale_Brick_Pillar_Base"
    },
    {
      "x": -4,
      "y": 3,
      "z": -6,
      "name": "Rock_Shale_Brick_Pillar_Middle"
    },
    {
      "x": -4,
      "y": 4,
      "z": -6,
      "name": "Rock_Shale_Brick_Pillar_Base",
      "rotation": 8
    },
    {
      "x": -4,
      "y": 5,
      "z": -6,
      "name": "Rock_Shale_Brick"
    },
    {
      "x": -4,
      "y": 6,
      "z": -6,
      "name": "Rock_Shale_Brick"
    },
    {
      "x": -4,
      "y": 7,
      "z": -6,
      "name": "Rock_Shale_Brick"
    },
    {
      "x": -4,
      "y": 8,
      "z": -6,
      "name": "Rock_Shale"
    },
    {
      "x": -4,
      "y": 9,
      "z": -6,
      "name": "Empty"
    },
    {
      "x": -4,
      "y": 10,
      "z": -6,
      "name": "Empty"
    },
    {
      "x": -4,
      "y": 11,
      "z": -6,
      "name": "Empty"
    },
    {
      "x": -4,
      "y": 12,
      "z": -6,
      "name": "Empty"
    },
    {
      "x": -4,
      "y": 13,
      "z": -6,
      "name": "Empty"
    },
    {
      "x": -4,
      "y": 14,
      "z": -6,
      "name": "Empty"
    },
    {
      "x": -4,
      "y": 15,
      "z": -6,
      "name": "Empty"
    },
    {
      "x": -4,
      "y": 16,
      "z": -6,
      "name": "Empty"
    },
    {
      "x": -4,
      "y": 17,
      "z": -6,
      "name": "Empty"
    },
    {
      "x": -4,
      "y": 18,
      "z": -6,
      "name": "Empty"
    },
    {
      "x": -4,
      "y": 19,
      "z": -6,
      "name": "Empty"
    },
    {
      "x": -4,
      "y": 20,
      "z": -6,
      "name": "Empty"
    },
    {
      "x": -4,
      "y": 1,
      "z": -5,
      "name": "Rock_Shale_Brick_Smooth"
    },
    {
      "x": -4,
      "y": 2,
      "z": -5,
      "name": "Rock_Shale_Brick"
    },
    {
      "x": -4,
      "y": 3,
      "z": -5,
      "name": "Empty"
    },
    {
      "x": -4,
      "y": 4,
      "z": -5,
      "name": "Empty"
    },
    {
      "x": -4,
      "y": 5,
      "z": -5,
      "name": "Empty"
    },
    {
      "x": -4,
      "y": 6,
      "z": -5,
      "name": "Empty"
    },
    {
      "x": -4,
      "y": 7,
      "z": -5,
      "name": "Rock_Shale_Brick_Stairs",
      "rotation": 10
    },
    {
      "x": -4,
      "y": 8,
      "z": -5,
      "name": "Rock_Shale_Brick"
    },
    {
      "x": -4,
      "y": 9,
      "z": -5,
      "name": "Rock_Shale"
    },
    {
      "x": -4,
      "y": 10,
      "z": -5,
      "name": "Empty"
    },
    {
      "x": -4,
      "y": 11,
      "z": -5,
      "name": "Empty"
    },
    {
      "x": -4,
      "y": 12,
      "z": -5,
      "name": "Empty"
    },
    {
      "x": -4,
      "y": 13,
      "z": -5,
      "name": "Empty"
    },
    {
      "x": -4,
      "y": 14,
      "z": -5,
      "name": "Empty"
    },
    {
      "x": -4,
      "y": 15,
      "z": -5,
      "name": "Empty"
    },
    {
      "x": -4,
      "y": 16,
      "z": -5,
      "name": "Empty"
    },
    {
      "x": -4,
      "y": 17,
      "z": -5,
      "name": "Empty"
    },
    {
      "x": -4,
      "y": 18,
      "z": -5,
      "name": "Rock_Shale"
    },
    {
      "x": -4,
      "y": 19,
      "z": -5,
      "name": "Rock_Shale"
    },
    {
      "x": -4,
      "y": 20,
      "z": -5,
      "name": "Rock_Shale"
    },
    {
      "x": -4,
      "y": 22,
      "z": -5,
      "name": "Rock_Shale"
    },
    {
      "x": -4,
      "y": 23,
      "z": -5,
      "name": "Rock_Shale"
    },
    {
      "x": -4,
      "y": 2,
      "z": -4,
      "name": "Rock_Shale_Brick"
    },
    {
      "x": -4,
      "y": 3,
      "z": -4,
      "name": "Rock_Shale_Brick"
    },
    {
      "x": -4,
      "y": 4,
      "z": -4,
      "name": "Empty"
    },
    {
      "x": -4,
      "y": 5,
      "z": -4,
      "name": "Empty"
    },
    {
      "x": -4,
      "y": 6,
      "z": -4,
      "name": "Empty"
    },
    {
      "x": -4,
      "y": 7,
      "z": -4,
      "name": "Empty"
    },
    {
      "x": -4,
      "y": 8,
      "z": -4,
      "name": "Rock_Shale_Brick_Stairs",
      "rotation": 10
    },
    {
      "x": -4,
      "y": 9,
      "z": -4,
      "name": "Rock_Shale_Brick"
    },
    {
      "x": -4,
      "y": 10,
      "z": -4,
      "name": "Rock_Shale"
    },
    {
      "x": -4,
      "y": 11,
      "z": -4,
      "name": "Rock_Shale_Brick"
    },
    {
      "x": -4,
      "y": 12,
      "z": -4,
      "name": "Rock_Shale_Brick"
    },
    {
      "x": -4,
      "y": 13,
      "z": -4,
      "name": "Deco_Bone_Pile"
    },
    {
      "x": -4,
      "y": 14,
      "z": -4,
      "name": "Rock_Shale_Brick"
    },
    {
      "x": -4,
      "y": 15,
      "z": -4,
      "name": "Deco_Bone_Skulls"
    },
    {
      "x": -4,
      "y": 16,
      "z": -4,
      "name": "Rock_Shale_Brick"
    },
    {
      "x": -4,
      "y": 17,
      "z": -4,
      "name": "Empty"
    },
    {
      "x": -4,
      "y": 18,
      "z": -4,
      "name": "Rock_Shale"
    },
    {
      "x": -4,
      "y": 19,
      "z": -4,
      "name": "Rock_Shale"
    },
    {
      "x": -4,
      "y": 20,
      "z": -4,
      "name": "Rock_Shale"
    },
    {
      "x": -4,
      "y": 21,
      "z": -4,
      "name": "Rock_Shale"
    },
    {
      "x": -4,
      "y": 22,
      "z": -4,
      "name": "Rock_Shale"
    },
    {
      "x": -4,
      "y": 23,
      "z": -4,
      "name": "Rock_Shale"
    },
    {
      "x": -4,
      "y": 2,
      "z": -3,
      "name": "Empty"
    },
    {
      "x": -4,
      "y": 3,
      "z": -3,
      "name": "Rock_Shale_Brick"
    },
    {
      "x": -4,
      "y": 4,
      "z": -3,
      "name": "Rock_Shale_Brick"
    },
    {
      "x": -4,
      "y": 5,
      "z": -3,
      "name": "Empty"
    },
    {
      "x": -4,
      "y": 6,
      "z": -3,
      "name": "Empty"
    },
    {
      "x": -4,
      "y": 7,
      "z": -3,
      "name": "Empty"
    },
    {
      "x": -4,
      "y": 8,
      "z": -3,
      "name": "Empty"
    },
    {
      "x": -4,
      "y": 9,
      "z": -3,
      "name": "Rock_Shale_Brick_Stairs",
      "rotation": 10
    },
    {
      "x": -4,
      "y": 10,
      "z": -3,
      "name": "Rock_Shale_Brick"
    },
    {
      "x": -4,
      "y": 11,
      "z": -3,
      "name": "Rock_Shale"
    },
    {
      "x": -4,
      "y": 12,
      "z": -3,
      "name": "Rock_Shale_Brick"
    },
    {
      "x": -4,
      "y": 13,
      "z": -3,
      "name": "Rock_Shale_Cobble"
    },
    {
      "x": -4,
      "y": 14,
      "z": -3,
      "name": "Rock_Shale_Cobble"
    },
    {
      "x": -4,
      "y": 15,
      "z": -3,
      "name": "Rock_Shale_Cobble"
    },
    {
      "x": -4,
      "y": 16,
      "z": -3,
      "name": "Rock_Shale_Cobble"
    },
    {
      "x": -4,
      "y": 17,
      "z": -3,
      "name": "Rock_Shale_Cobble"
    },
    {
      "x": -4,
      "y": 18,
      "z": -3,
      "name": "Rock_Shale_Brick"
    },
    {
      "x": -4,
      "y": 19,
      "z": -3,
      "name": "Rock_Shale"
    },
    {
      "x": -4,
      "y": 20,
      "z": -3,
      "name": "Rock_Shale"
    },
    {
      "x": -4,
      "y": 21,
      "z": -3,
      "name": "Rock_Shale"
    },
    {
      "x": -4,
      "y": 22,
      "z": -3,
      "name": "Rock_Shale"
    },
    {
      "x": -4,
      "y": 23,
      "z": -3,
      "name": "Rock_Shale"
    },
    {
      "x": -4,
      "y": 2,
      "z": -2,
      "name": "Empty"
    },
    {
      "x": -4,
      "y": 3,
      "z": -2,
      "name": "Empty"
    },
    {
      "x": -4,
      "y": 4,
      "z": -2,
      "name": "Rock_Shale_Brick"
    },
    {
      "x": -4,
      "y": 5,
      "z": -2,
      "name": "Rock_Shale_Brick_Pillar_Base"
    },
    {
      "x": -4,
      "y": 6,
      "z": -2,
      "name": "Rock_Shale_Brick_Pillar_Middle"
    },
    {
      "x": -4,
      "y": 7,
      "z": -2,
      "name": "Rock_Shale_Brick_Pillar_Middle"
    },
    {
      "x": -4,
      "y": 8,
      "z": -2,
      "name": "Rock_Shale_Brick_Pillar_Base",
      "rotation": 8
    },
    {
      "x": -4,
      "y": 9,
      "z": -2,
      "name": "Rock_Shale_Brick"
    },
    {
      "x": -4,
      "y": 10,
      "z": -2,
      "name": "Rock_Shale_Brick"
    },
    {
      "x": -4,
      "y": 11,
      "z": -2,
      "name": "Rock_Shale_Brick"
    },
    {
      "x": -4,
      "y": 12,
      "z": -2,
      "name": "Rock_Shale"
    },
    {
      "x": -4,
      "y": 13,
      "z": -2,
      "name": "Rock_Shale_Brick"
    },
    {
      "x": -4,
      "y": 14,
      "z": -2,
      "name": "Rock_Shale_Brick"
    },
    {
      "x": -4,
      "y": 15,
      "z": -2,
      "name": "Rock_Shale_Brick"
    },
    {
      "x": -4,
      "y": 16,
      "z": -2,
      "name": "Rock_Shale_Brick"
    },
    {
      "x": -4,
      "y": 17,
      "z": -2,
      "name": "Rock_Shale_Brick"
    },
    {
      "x": -4,
      "y": 18,
      "z": -2,
      "name": "Rock_Shale_Brick"
    },
    {
      "x": -4,
      "y": 19,
      "z": -2,
      "name": "Rock_Shale"
    },
    {
      "x": -4,
      "y": 20,
      "z": -2,
      "name": "Rock_Shale"
    },
    {
      "x": -4,
      "y": 21,
      "z": -2,
      "name": "Rock_Shale"
    },
    {
      "x": -4,
      "y": 22,
      "z": -2,
      "name": "Rock_Shale"
    },
    {
      "x": -4,
      "y": 23,
      "z": -2,
      "name": "Rock_Shale"
    },
    {
      "x": -4,
      "y": 2,
      "z": -1,
      "name": "Empty"
    },
    {
      "x": -4,
      "y": 3,
      "z": -1,
      "name": "Empty"
    },
    {
      "x": -4,
      "y": 4,
      "z": -1,
      "name": "Empty"
    },
    {
      "x": -4,
      "y": 5,
      "z": -1,
      "name": "Rock_Shale_Brick"
    },
    {
      "x": -4,
      "y": 6,
      "z": -1,
      "name": "Rock_Shale_Brick"
    },
    {
      "x": -4,
      "y": 7,
      "z": -1,
      "name": "Empty"
    },
    {
      "x": -4,
      "y": 8,
      "z": -1,
      "name": "Empty"
    },
    {
      "x": -4,
      "y": 9,
      "z": -1,
      "name": "Empty"
    },
    {
      "x": -4,
      "y": 10,
      "z": -1,
      "name": "Empty"
    },
    {
      "x": -4,
      "y": 11,
      "z": -1,
      "name": "Rock_Shale_Brick_Stairs",
      "rotation": 10
    },
    {
      "x": -4,
      "y": 12,
      "z": -1,
      "name": "Rock_Shale_Brick"
    },
    {
      "x": -4,
      "y": 13,
      "z": -1,
      "name": "Rock_Shale"
    },
    {
      "x": -4,
      "y": 14,
      "z": -1,
      "name": "Rock_Shale_Brick"
    },
    {
      "x": -4,
      "y": 15,
      "z": -1,
      "name": "Rock_Shale_Brick"
    },
    {
      "x": -4,
      "y": 16,
      "z": -1,
      "name": "Rock_Shale_Brick"
    },
    {
      "x": -4,
      "y": 17,
      "z": -1,
      "name": "Rock_Shale_Brick"
    },
    {
      "x": -4,
      "y": 18,
      "z": -1,
      "name": "Rock_Shale_Brick"
    },
    {
      "x": -4,
      "y": 19,
      "z": -1,
      "name": "Rock_Shale"
    },
    {
      "x": -4,
      "y": 20,
      "z": -1,
      "name": "Rock_Shale"
    },
    {
      "x": -4,
      "y": 21,
      "z": -1,
      "name": "Rock_Shale"
    },
    {
      "x": -4,
      "y": 22,
      "z": -1,
      "name": "Rock_Shale"
    },
    {
      "x": -4,
      "y": 23,
      "z": -1,
      "name": "Rock_Shale"
    },
    {
      "x": -4,
      "y": 24,
      "z": -1,
      "name": "Rock_Shale_Brick_Stairs",
      "rotation": 3
    },
    {
      "x": -4,
      "y": 2,
      "z": 0,
      "name": "Empty"
    },
    {
      "x": -4,
      "y": 3,
      "z": 0,
      "name": "Empty"
    },
    {
      "x": -4,
      "y": 4,
      "z": 0,
      "name": "Empty"
    },
    {
      "x": -4,
      "y": 5,
      "z": 0,
      "name": "Empty"
    },
    {
      "x": -4,
      "y": 6,
      "z": 0,
      "name": "Rock_Shale_Brick"
    },
    {
      "x": -4,
      "y": 7,
      "z": 0,
      "name": "Rock_Shale_Brick"
    },
    {
      "x": -4,
      "y": 8,
      "z": 0,
      "name": "Empty"
    },
    {
      "x": -4,
      "y": 9,
      "z": 0,
      "name": "Empty"
    },
    {
      "x": -4,
      "y": 10,
      "z": 0,
      "name": "Empty"
    },
    {
      "x": -4,
      "y": 11,
      "z": 0,
      "name": "Empty"
    },
    {
      "x": -4,
      "y": 12,
      "z": 0,
      "name": "Rock_Shale_Brick_Stairs",
      "rotation": 10
    },
    {
      "x": -4,
      "y": 13,
      "z": 0,
      "name": "Rock_Shale_Brick"
    },
    {
      "x": -4,
      "y": 14,
      "z": 0,
      "name": "Rock_Shale"
    },
    {
      "x": -4,
      "y": 15,
      "z": 0,
      "name": "Rock_Shale_Brick"
    },
    {
      "x": -4,
      "y": 16,
      "z": 0,
      "name": "Rock_Shale_Brick"
    },
    {
      "x": -4,
      "y": 17,
      "z": 0,
      "name": "Rock_Shale_Brick"
    },
    {
      "x": -4,
      "y": 18,
      "z": 0,
      "name": "Rock_Shale_Brick"
    },
    {
      "x": -4,
      "y": 19,
      "z": 0,
      "name": "Rock_Shale"
    },
    {
      "x": -4,
      "y": 20,
      "z": 0,
      "name": "Rock_Shale"
    },
    {
      "x": -4,
      "y": 21,
      "z": 0,
      "name": "Rock_Shale"
    },
    {
      "x": -4,
      "y": 22,
      "z": 0,
      "name": "Rock_Shale"
    },
    {
      "x": -4,
      "y": 23,
      "z": 0,
      "name": "Rock_Shale"
    },
    {
      "x": -4,
      "y": 2,
      "z": 1,
      "name": "Empty"
    },
    {
      "x": -4,
      "y": 3,
      "z": 1,
      "name": "Empty"
    },
    {
      "x": -4,
      "y": 4,
      "z": 1,
      "name": "Empty"
    },
    {
      "x": -4,
      "y": 5,
      "z": 1,
      "name": "Empty"
    },
    {
      "x": -4,
      "y": 6,
      "z": 1,
      "name": "Rock_Shale_Brick"
    },
    {
      "x": -4,
      "y": 7,
      "z": 1,
      "name": "Rock_Shale_Brick"
    },
    {
      "x": -4,
      "y": 8,
      "z": 1,
      "name": "Rock_Shale_Brick"
    },
    {
      "x": -4,
      "y": 9,
      "z": 1,
      "name": "Empty"
    },
    {
      "x": -4,
      "y": 10,
      "z": 1,
      "name": "Empty"
    },
    {
      "x": -4,
      "y": 11,
      "z": 1,
      "name": "Plant_Moss_Wall_Blue",
      "support": 15,
      "rotation": 1
    },
    {
      "x": -4,
      "y": 12,
      "z": 1,
      "name": "Empty"
    },
    {
      "x": -4,
      "y": 13,
      "z": 1,
      "name": "Rock_Shale_Brick_Stairs",
      "rotation": 10
    },
    {
      "x": -4,
      "y": 14,
      "z": 1,
      "name": "Rock_Shale_Brick"
    },
    {
      "x": -4,
      "y": 15,
      "z": 1,
      "name": "Rock_Shale"
    },
    {
      "x": -4,
      "y": 16,
      "z": 1,
      "name": "Rock_Shale_Brick"
    },
    {
      "x": -4,
      "y": 17,
      "z": 1,
      "name": "Rock_Shale_Brick"
    },
    {
      "x": -4,
      "y": 18,
      "z": 1,
      "name": "Rock_Shale_Brick"
    },
    {
      "x": -4,
      "y": 19,
      "z": 1,
      "name": "Rock_Shale"
    },
    {
      "x": -4,
      "y": 20,
      "z": 1,
      "name": "Rock_Shale"
    },
    {
      "x": -4,
      "y": 21,
      "z": 1,
      "name": "Rock_Shale"
    },
    {
      "x": -4,
      "y": 22,
      "z": 1,
      "name": "Rock_Shale"
    },
    {
      "x": -4,
      "y": 23,
      "z": 1,
      "name": "Rock_Shale"
    },
    {
      "x": -4,
      "y": 2,
      "z": 2,
      "name": "Empty"
    },
    {
      "x": -4,
      "y": 3,
      "z": 2,
      "name": "Empty"
    },
    {
      "x": -4,
      "y": 4,
      "z": 2,
      "name": "Empty"
    },
    {
      "x": -4,
      "y": 5,
      "z": 2,
      "name": "Empty"
    },
    {
      "x": -4,
      "y": 6,
      "z": 2,
      "name": "Rock_Shale_Brick"
    },
    {
      "x": -4,
      "y": 7,
      "z": 2,
      "name": "Rock_Shale_Brick"
    },
    {
      "x": -4,
      "y": 8,
      "z": 2,
      "name": "Rock_Shale_Brick"
    },
    {
      "x": -4,
      "y": 9,
      "z": 2,
      "name": "Rock_Shale_Brick_Pillar_Base"
    },
    {
      "x": -4,
      "y": 10,
      "z": 2,
      "name": "Rock_Shale_Brick_Pillar_Middle"
    },
    {
      "x": -4,
      "y": 11,
      "z": 2,
      "name": "Rock_Shale_Brick_Pillar_Middle"
    },
    {
      "x": -4,
      "y": 12,
      "z": 2,
      "name": "Rock_Shale_Brick_Pillar_Base",
      "rotation": 8
    },
    {
      "x": -4,
      "y": 13,
      "z": 2,
      "name": "Rock_Shale_Brick"
    },
    {
      "x": -4,
      "y": 14,
      "z": 2,
      "name": "Rock_Shale_Brick"
    },
    {
      "x": -4,
      "y": 15,
      "z": 2,
      "name": "Rock_Shale_Brick"
    },
    {
      "x": -4,
      "y": 16,
      "z": 2,
      "name": "Rock_Shale"
    },
    {
      "x": -4,
      "y": 17,
      "z": 2,
      "name": "Rock_Shale_Brick"
    },
    {
      "x": -4,
      "y": 18,
      "z": 2,
      "name": "Rock_Shale_Brick"
    },
    {
      "x": -4,
      "y": 19,
      "z": 2,
      "name": "Rock_Shale"
    },
    {
      "x": -4,
      "y": 20,
      "z": 2,
      "name": "Rock_Shale"
    },
    {
      "x": -4,
      "y": 21,
      "z": 2,
      "name": "Rock_Shale"
    },
    {
      "x": -4,
      "y": 22,
      "z": 2,
      "name": "Rock_Shale"
    },
    {
      "x": -4,
      "y": 23,
      "z": 2,
      "name": "Rock_Shale"
    },
    {
      "x": -4,
      "y": 2,
      "z": 3,
      "name": "Empty"
    },
    {
      "x": -4,
      "y": 3,
      "z": 3,
      "name": "Empty"
    },
    {
      "x": -4,
      "y": 4,
      "z": 3,
      "name": "Empty"
    },
    {
      "x": -4,
      "y": 5,
      "z": 3,
      "name": "Empty"
    },
    {
      "x": -4,
      "y": 6,
      "z": 3,
      "name": "Rock_Shale_Brick"
    },
    {
      "x": -4,
      "y": 7,
      "z": 3,
      "name": "Rock_Shale_Brick"
    },
    {
      "x": -4,
      "y": 8,
      "z": 3,
      "name": "Rock_Shale_Brick"
    },
    {
      "x": -4,
      "y": 9,
      "z": 3,
      "name": "Rock_Shale_Brick"
    },
    {
      "x": -4,
      "y": 10,
      "z": 3,
      "name": "Rock_Shale_Brick"
    },
    {
      "x": -4,
      "y": 11,
      "z": 3,
      "name": "Empty"
    },
    {
      "x": -4,
      "y": 12,
      "z": 3,
      "name": "Empty"
    },
    {
      "x": -4,
      "y": 13,
      "z": 3,
      "name": "Empty"
    },
    {
      "x": -4,
      "y": 14,
      "z": 3,
      "name": "Plant_Moss_Wall_Blue",
      "support": 15,
      "rotation": 1
    },
    {
      "x": -4,
      "y": 15,
      "z": 3,
      "name": "Rock_Shale_Brick_Stairs",
      "rotation": 10
    },
    {
      "x": -4,
      "y": 16,
      "z": 3,
      "name": "Rock_Shale_Brick"
    },
    {
      "x": -4,
      "y": 17,
      "z": 3,
      "name": "Rock_Shale"
    },
    {
      "x": -4,
      "y": 18,
      "z": 3,
      "name": "Rock_Shale_Brick"
    },
    {
      "x": -4,
      "y": 19,
      "z": 3,
      "name": "Rock_Shale"
    },
    {
      "x": -4,
      "y": 20,
      "z": 3,
      "name": "Rock_Shale"
    },
    {
      "x": -4,
      "y": 21,
      "z": 3,
      "name": "Rock_Shale"
    },
    {
      "x": -4,
      "y": 22,
      "z": 3,
      "name": "Rock_Shale"
    },
    {
      "x": -4,
      "y": 23,
      "z": 3,
      "name": "Rock_Shale"
    },
    {
      "x": -4,
      "y": 2,
      "z": 4,
      "name": "Empty"
    },
    {
      "x": -4,
      "y": 3,
      "z": 4,
      "name": "Empty"
    },
    {
      "x": -4,
      "y": 4,
      "z": 4,
      "name": "Empty"
    },
    {
      "x": -4,
      "y": 5,
      "z": 4,
      "name": "Empty"
    },
    {
      "x": -4,
      "y": 6,
      "z": 4,
      "name": "Rock_Shale_Brick"
    },
    {
      "x": -4,
      "y": 7,
      "z": 4,
      "name": "Rock_Shale_Brick"
    },
    {
      "x": -4,
      "y": 8,
      "z": 4,
      "name": "Rock_Shale_Brick"
    },
    {
      "x": -4,
      "y": 9,
      "z": 4,
      "name": "Rock_Shale_Brick"
    },
    {
      "x": -4,
      "y": 10,
      "z": 4,
      "name": "Rock_Shale_Brick"
    },
    {
      "x": -4,
      "y": 11,
      "z": 4,
      "name": "Rock_Shale_Brick"
    },
    {
      "x": -4,
      "y": 12,
      "z": 4,
      "name": "Furniture_Human_Ruins_Brazier"
    },
    {
      "x": -4,
      "y": 13,
      "z": 4,
      "name": "Empty"
    },
    {
      "x": -4,
      "y": 14,
      "z": 4,
      "name": "Empty"
    },
    {
      "x": -4,
      "y": 15,
      "z": 4,
      "name": "Plant_Moss_Wall_Blue",
      "support": 15,
      "rotation": 1
    },
    {
      "x": -4,
      "y": 16,
      "z": 4,
      "name": "Rock_Shale_Brick_Stairs",
      "rotation": 10
    },
    {
      "x": -4,
      "y": 17,
      "z": 4,
      "name": "Rock_Shale_Brick"
    },
    {
      "x": -4,
      "y": 18,
      "z": 4,
      "name": "Rock_Shale"
    },
    {
      "x": -4,
      "y": 19,
      "z": 4,
      "name": "Rock_Shale"
    },
    {
      "x": -4,
      "y": 20,
      "z": 4,
      "name": "Rock_Shale"
    },
    {
      "x": -4,
      "y": 21,
      "z": 4,
      "name": "Rock_Shale"
    },
    {
      "x": -4,
      "y": 22,
      "z": 4,
      "name": "Rock_Shale"
    },
    {
      "x": -4,
      "y": 23,
      "z": 4,
      "name": "Rock_Shale"
    },
    {
      "x": -4,
      "y": 24,
      "z": 4,
      "name": "Rock_Shale_Brick_Stairs",
      "rotation": 3
    },
    {
      "x": -4,
      "y": 2,
      "z": 5,
      "name": "Empty"
    },
    {
      "x": -4,
      "y": 3,
      "z": 5,
      "name": "Empty"
    },
    {
      "x": -4,
      "y": 4,
      "z": 5,
      "name": "Empty"
    },
    {
      "x": -4,
      "y": 5,
      "z": 5,
      "name": "Empty"
    },
    {
      "x": -4,
      "y": 6,
      "z": 5,
      "name": "Rock_Shale_Brick"
    },
    {
      "x": -4,
      "y": 7,
      "z": 5,
      "name": "Rock_Shale_Brick"
    },
    {
      "x": -4,
      "y": 8,
      "z": 5,
      "name": "Rock_Shale_Brick"
    },
    {
      "x": -4,
      "y": 9,
      "z": 5,
      "name": "Rock_Shale_Brick"
    },
    {
      "x": -4,
      "y": 10,
      "z": 5,
      "name": "Rock_Shale_Brick"
    },
    {
      "x": -4,
      "y": 11,
      "z": 5,
      "name": "Rock_Shale_Brick"
    },
    {
      "x": -4,
      "y": 12,
      "z": 5,
      "name": "Rock_Shale_Brick"
    },
    {
      "x": -4,
      "y": 13,
      "z": 5,
      "name": "Empty"
    },
    {
      "x": -4,
      "y": 14,
      "z": 5,
      "name": "Empty"
    },
    {
      "x": -4,
      "y": 15,
      "z": 5,
      "name": "Empty"
    },
    {
      "x": -4,
      "y": 16,
      "z": 5,
      "name": "Empty"
    },
    {
      "x": -4,
      "y": 17,
      "z": 5,
      "name": "Rock_Shale_Brick"
    },
    {
      "x": -4,
      "y": 18,
      "z": 5,
      "name": "Rock_Shale"
    },
    {
      "x": -4,
      "y": 19,
      "z": 5,
      "name": "Rock_Shale"
    },
    {
      "x": -4,
      "y": 20,
      "z": 5,
      "name": "Rock_Shale"
    },
    {
      "x": -4,
      "y": 21,
      "z": 5,
      "name": "Rock_Shale"
    },
    {
      "x": -4,
      "y": 22,
      "z": 5,
      "name": "Rock_Shale"
    },
    {
      "x": -4,
      "y": 23,
      "z": 5,
      "name": "Rock_Shale"
    },
    {
      "x": -4,
      "y": 2,
      "z": 6,
      "name": "Empty"
    },
    {
      "x": -4,
      "y": 3,
      "z": 6,
      "name": "Empty"
    },
    {
      "x": -4,
      "y": 4,
      "z": 6,
      "name": "Empty"
    },
    {
      "x": -4,
      "y": 5,
      "z": 6,
      "name": "Empty"
    },
    {
      "x": -4,
      "y": 6,
      "z": 6,
      "name": "Rock_Shale"
    },
    {
      "x": -4,
      "y": 7,
      "z": 6,
      "name": "Rock_Shale"
    },
    {
      "x": -4,
      "y": 8,
      "z": 6,
      "name": "Rock_Shale"
    },
    {
      "x": -4,
      "y": 9,
      "z": 6,
      "name": "Rock_Shale"
    },
    {
      "x": -4,
      "y": 10,
      "z": 6,
      "name": "Rock_Shale"
    },
    {
      "x": -4,
      "y": 11,
      "z": 6,
      "name": "Rock_Shale"
    },
    {
      "x": -4,
      "y": 12,
      "z": 6,
      "name": "Rock_Shale"
    },
    {
      "x": -4,
      "y": 13,
      "z": 6,
      "name": "Rock_Shale"
    },
    {
      "x": -4,
      "y": 14,
      "z": 6,
      "name": "Rock_Shale"
    },
    {
      "x": -4,
      "y": 15,
      "z": 6,
      "name": "Rock_Shale"
    },
    {
      "x": -4,
      "y": 16,
      "z": 6,
      "name": "Rock_Shale"
    },
    {
      "x": -4,
      "y": 17,
      "z": 6,
      "name": "Rock_Shale"
    },
    {
      "x": -4,
      "y": 18,
      "z": 6,
      "name": "Rock_Shale_Brick"
    },
    {
      "x": -4,
      "y": 19,
      "z": 6,
      "name": "Rock_Shale"
    },
    {
      "x": -4,
      "y": 20,
      "z": 6,
      "name": "Rock_Shale"
    },
    {
      "x": -4,
      "y": 21,
      "z": 6,
      "name": "Rock_Shale"
    },
    {
      "x": -4,
      "y": 22,
      "z": 6,
      "name": "Rock_Shale"
    },
    {
      "x": -4,
      "y": 23,
      "z": 6,
      "name": "Rock_Shale"
    },
    {
      "x": -4,
      "y": 2,
      "z": 7,
      "name": "Empty"
    },
    {
      "x": -4,
      "y": 3,
      "z": 7,
      "name": "Empty"
    },
    {
      "x": -4,
      "y": 4,
      "z": 7,
      "name": "Empty"
    },
    {
      "x": -4,
      "y": 5,
      "z": 7,
      "name": "Empty"
    },
    {
      "x": -4,
      "y": 6,
      "z": 7,
      "name": "Rock_Shale"
    },
    {
      "x": -4,
      "y": 7,
      "z": 7,
      "name": "Rock_Shale"
    },
    {
      "x": -4,
      "y": 8,
      "z": 7,
      "name": "Rock_Shale"
    },
    {
      "x": -4,
      "y": 9,
      "z": 7,
      "name": "Rock_Shale"
    },
    {
      "x": -4,
      "y": 10,
      "z": 7,
      "name": "Rock_Shale"
    },
    {
      "x": -4,
      "y": 11,
      "z": 7,
      "name": "Rock_Shale"
    },
    {
      "x": -4,
      "y": 12,
      "z": 7,
      "name": "Rock_Shale"
    },
    {
      "x": -4,
      "y": 13,
      "z": 7,
      "name": "Rock_Shale"
    },
    {
      "x": -4,
      "y": 14,
      "z": 7,
      "name": "Rock_Shale"
    },
    {
      "x": -4,
      "y": 15,
      "z": 7,
      "name": "Rock_Shale"
    },
    {
      "x": -4,
      "y": 16,
      "z": 7,
      "name": "Rock_Shale"
    },
    {
      "x": -4,
      "y": 17,
      "z": 7,
      "name": "Rock_Shale"
    },
    {
      "x": -4,
      "y": 18,
      "z": 7,
      "name": "Rock_Shale"
    },
    {
      "x": -4,
      "y": 19,
      "z": 7,
      "name": "Rock_Shale"
    },
    {
      "x": -4,
      "y": 20,
      "z": 7,
      "name": "Rock_Shale"
    },
    {
      "x": -4,
      "y": 21,
      "z": 7,
      "name": "Rock_Shale"
    },
    {
      "x": -4,
      "y": 22,
      "z": 7,
      "name": "Rock_Shale"
    },
    {
      "x": -4,
      "y": 23,
      "z": 7,
      "name": "Rock_Shale"
    },
    {
      "x": -4,
      "y": 2,
      "z": 8,
      "name": "Empty"
    },
    {
      "x": -4,
      "y": 3,
      "z": 8,
      "name": "Empty"
    },
    {
      "x": -4,
      "y": 4,
      "z": 8,
      "name": "Empty"
    },
    {
      "x": -4,
      "y": 5,
      "z": 8,
      "name": "Empty"
    },
    {
      "x": -4,
      "y": 6,
      "z": 8,
      "name": "Empty"
    },
    {
      "x": -4,
      "y": 7,
      "z": 8,
      "name": "Empty"
    },
    {
      "x": -4,
      "y": 8,
      "z": 8,
      "name": "Empty"
    },
    {
      "x": -4,
      "y": 9,
      "z": 8,
      "name": "Rock_Shale"
    },
    {
      "x": -4,
      "y": 10,
      "z": 8,
      "name": "Empty"
    },
    {
      "x": -4,
      "y": 11,
      "z": 8,
      "name": "Empty"
    },
    {
      "x": -4,
      "y": 12,
      "z": 8,
      "name": "Rock_Shale"
    },
    {
      "x": -4,
      "y": 13,
      "z": 8,
      "name": "Rock_Shale"
    },
    {
      "x": -4,
      "y": 14,
      "z": 8,
      "name": "Rock_Shale"
    },
    {
      "x": -4,
      "y": 15,
      "z": 8,
      "name": "Rock_Shale"
    },
    {
      "x": -4,
      "y": 16,
      "z": 8,
      "name": "Rock_Shale"
    },
    {
      "x": -4,
      "y": 17,
      "z": 8,
      "name": "Rock_Shale"
    },
    {
      "x": -4,
      "y": 18,
      "z": 8,
      "name": "Rock_Shale"
    },
    {
      "x": -4,
      "y": 19,
      "z": 8,
      "name": "Rock_Shale"
    },
    {
      "x": -4,
      "y": 20,
      "z": 8,
      "name": "Rock_Shale"
    },
    {
      "x": -4,
      "y": 21,
      "z": 8,
      "name": "Rock_Shale"
    },
    {
      "x": -4,
      "y": 2,
      "z": 9,
      "name": "Empty"
    },
    {
      "x": -4,
      "y": 3,
      "z": 9,
      "name": "Empty"
    },
    {
      "x": -4,
      "y": 4,
      "z": 9,
      "name": "Empty"
    },
    {
      "x": -4,
      "y": 5,
      "z": 9,
      "name": "Empty"
    },
    {
      "x": -4,
      "y": 6,
      "z": 9,
      "name": "Empty"
    },
    {
      "x": -4,
      "y": 7,
      "z": 9,
      "name": "Empty"
    },
    {
      "x": -4,
      "y": 8,
      "z": 9,
      "name": "Empty"
    },
    {
      "x": -4,
      "y": 9,
      "z": 9,
      "name": "Empty"
    },
    {
      "x": -4,
      "y": 10,
      "z": 9,
      "name": "Empty"
    },
    {
      "x": -4,
      "y": 11,
      "z": 9,
      "name": "Empty"
    },
    {
      "x": -4,
      "y": 12,
      "z": 9,
      "name": "Rock_Shale"
    },
    {
      "x": -4,
      "y": 13,
      "z": 9,
      "name": "Rock_Shale"
    },
    {
      "x": -4,
      "y": 14,
      "z": 9,
      "name": "Rock_Shale"
    },
    {
      "x": -4,
      "y": 15,
      "z": 9,
      "name": "Empty"
    },
    {
      "x": -4,
      "y": 16,
      "z": 9,
      "name": "Empty"
    },
    {
      "x": -4,
      "y": 17,
      "z": 9,
      "name": "Empty"
    },
    {
      "x": -4,
      "y": 18,
      "z": 9,
      "name": "Empty"
    },
    {
      "x": -4,
      "y": 19,
      "z": 9,
      "name": "Empty"
    },
    {
      "x": -4,
      "y": 20,
      "z": 9,
      "name": "Empty"
    },
    {
      "x": -4,
      "y": 2,
      "z": 10,
      "name": "Empty"
    },
    {
      "x": -4,
      "y": 3,
      "z": 10,
      "name": "Empty"
    },
    {
      "x": -4,
      "y": 4,
      "z": 10,
      "name": "Empty"
    },
    {
      "x": -4,
      "y": 5,
      "z": 10,
      "name": "Empty"
    },
    {
      "x": -4,
      "y": 6,
      "z": 10,
      "name": "Empty"
    },
    {
      "x": -4,
      "y": 7,
      "z": 10,
      "name": "Empty"
    },
    {
      "x": -4,
      "y": 8,
      "z": 10,
      "name": "Empty"
    },
    {
      "x": -4,
      "y": 9,
      "z": 10,
      "name": "Empty"
    },
    {
      "x": -4,
      "y": 10,
      "z": 10,
      "name": "Empty"
    },
    {
      "x": -4,
      "y": 11,
      "z": 10,
      "name": "Empty"
    },
    {
      "x": -4,
      "y": 12,
      "z": 10,
      "name": "Rock_Shale"
    },
    {
      "x": -4,
      "y": 13,
      "z": 10,
      "name": "Rock_Shale"
    },
    {
      "x": -4,
      "y": 14,
      "z": 10,
      "name": "Rock_Shale"
    },
    {
      "x": -4,
      "y": 15,
      "z": 10,
      "name": "Empty"
    },
    {
      "x": -4,
      "y": 16,
      "z": 10,
      "name": "Empty"
    },
    {
      "x": -4,
      "y": 17,
      "z": 10,
      "name": "Empty"
    },
    {
      "x": -4,
      "y": 18,
      "z": 10,
      "name": "Empty"
    },
    {
      "x": -4,
      "y": 19,
      "z": 10,
      "name": "Empty"
    },
    {
      "x": -4,
      "y": 20,
      "z": 10,
      "name": "Empty"
    },
    {
      "x": -4,
      "y": 2,
      "z": 11,
      "name": "Empty"
    },
    {
      "x": -4,
      "y": 3,
      "z": 11,
      "name": "Empty"
    },
    {
      "x": -4,
      "y": 4,
      "z": 11,
      "name": "Empty"
    },
    {
      "x": -4,
      "y": 5,
      "z": 11,
      "name": "Empty"
    },
    {
      "x": -4,
      "y": 6,
      "z": 11,
      "name": "Empty"
    },
    {
      "x": -4,
      "y": 7,
      "z": 11,
      "name": "Empty"
    },
    {
      "x": -4,
      "y": 8,
      "z": 11,
      "name": "Empty"
    },
    {
      "x": -4,
      "y": 9,
      "z": 11,
      "name": "Empty"
    },
    {
      "x": -4,
      "y": 10,
      "z": 11,
      "name": "Empty"
    },
    {
      "x": -4,
      "y": 11,
      "z": 11,
      "name": "Empty"
    },
    {
      "x": -4,
      "y": 12,
      "z": 11,
      "name": "Rock_Shale"
    },
    {
      "x": -4,
      "y": 13,
      "z": 11,
      "name": "Rock_Shale"
    },
    {
      "x": -4,
      "y": 14,
      "z": 11,
      "name": "Empty"
    },
    {
      "x": -4,
      "y": 15,
      "z": 11,
      "name": "Empty"
    },
    {
      "x": -4,
      "y": 16,
      "z": 11,
      "name": "Empty"
    },
    {
      "x": -4,
      "y": 17,
      "z": 11,
      "name": "Empty"
    },
    {
      "x": -4,
      "y": 18,
      "z": 11,
      "name": "Empty"
    },
    {
      "x": -4,
      "y": 19,
      "z": 11,
      "name": "Empty"
    },
    {
      "x": -4,
      "y": 20,
      "z": 11,
      "name": "Empty"
    },
    {
      "x": -4,
      "y": 12,
      "z": 12,
      "name": "Rock_Shale"
    },
    {
      "x": -4,
      "y": 13,
      "z": 12,
      "name": "Rock_Shale"
    },
    {
      "x": -3,
      "y": 1,
      "z": -8,
      "name": "Rock_Shale_Brick_Smooth"
    },
    {
      "x": -3,
      "y": 2,
      "z": -8,
      "name": "Empty"
    },
    {
      "x": -3,
      "y": 3,
      "z": -8,
      "name": "Empty"
    },
    {
      "x": -3,
      "y": 4,
      "z": -8,
      "name": "Empty"
    },
    {
      "x": -3,
      "y": 5,
      "z": -8,
      "name": "Empty"
    },
    {
      "x": -3,
      "y": 6,
      "z": -8,
      "name": "Empty"
    },
    {
      "x": -3,
      "y": 7,
      "z": -8,
      "name": "Rock_Shale"
    },
    {
      "x": -3,
      "y": 8,
      "z": -8,
      "name": "Empty"
    },
    {
      "x": -3,
      "y": 9,
      "z": -8,
      "name": "Empty"
    },
    {
      "x": -3,
      "y": 10,
      "z": -8,
      "name": "Empty"
    },
    {
      "x": -3,
      "y": 11,
      "z": -8,
      "name": "Empty"
    },
    {
      "x": -3,
      "y": 12,
      "z": -8,
      "name": "Empty"
    },
    {
      "x": -3,
      "y": 13,
      "z": -8,
      "name": "Empty"
    },
    {
      "x": -3,
      "y": 14,
      "z": -8,
      "name": "Empty"
    },
    {
      "x": -3,
      "y": 15,
      "z": -8,
      "name": "Empty"
    },
    {
      "x": -3,
      "y": 16,
      "z": -8,
      "name": "Empty"
    },
    {
      "x": -3,
      "y": 17,
      "z": -8,
      "name": "Empty"
    },
    {
      "x": -3,
      "y": 18,
      "z": -8,
      "name": "Empty"
    },
    {
      "x": -3,
      "y": 19,
      "z": -8,
      "name": "Empty"
    },
    {
      "x": -3,
      "y": 20,
      "z": -8,
      "name": "Empty"
    },
    {
      "x": -3,
      "y": 1,
      "z": -7,
      "name": "Soil_Dirt_Cold"
    },
    {
      "x": -3,
      "y": 2,
      "z": -7,
      "name": "Empty"
    },
    {
      "x": -3,
      "y": 3,
      "z": -7,
      "name": "Empty"
    },
    {
      "x": -3,
      "y": 4,
      "z": -7,
      "name": "Empty"
    },
    {
      "x": -3,
      "y": 5,
      "z": -7,
      "name": "Empty"
    },
    {
      "x": -3,
      "y": 6,
      "z": -7,
      "name": "Wood_Redwood_Beam",
      "rotation": 5
    },
    {
      "x": -3,
      "y": 7,
      "z": -7,
      "name": "Rock_Shale"
    },
    {
      "x": -3,
      "y": 8,
      "z": -7,
      "name": "Empty"
    },
    {
      "x": -3,
      "y": 9,
      "z": -7,
      "name": "Empty"
    },
    {
      "x": -3,
      "y": 10,
      "z": -7,
      "name": "Empty"
    },
    {
      "x": -3,
      "y": 11,
      "z": -7,
      "name": "Empty"
    },
    {
      "x": -3,
      "y": 12,
      "z": -7,
      "name": "Empty"
    },
    {
      "x": -3,
      "y": 13,
      "z": -7,
      "name": "Empty"
    },
    {
      "x": -3,
      "y": 14,
      "z": -7,
      "name": "Empty"
    },
    {
      "x": -3,
      "y": 15,
      "z": -7,
      "name": "Empty"
    },
    {
      "x": -3,
      "y": 16,
      "z": -7,
      "name": "Empty"
    },
    {
      "x": -3,
      "y": 17,
      "z": -7,
      "name": "Empty"
    },
    {
      "x": -3,
      "y": 18,
      "z": -7,
      "name": "Empty"
    },
    {
      "x": -3,
      "y": 19,
      "z": -7,
      "name": "Empty"
    },
    {
      "x": -3,
      "y": 20,
      "z": -7,
      "name": "Empty"
    },
    {
      "x": -3,
      "y": 1,
      "z": -6,
      "name": "Soil_Dirt_Cold"
    },
    {
      "x": -3,
      "y": 2,
      "z": -6,
      "name": "Rock_Shale_Brick_Beam"
    },
    {
      "x": -3,
      "y": 3,
      "z": -6,
      "name": "Furniture_Human_Ruins_Torch",
      "rotation": 1
    },
    {
      "x": -3,
      "y": 4,
      "z": -6,
      "name": "Empty"
    },
    {
      "x": -3,
      "y": 5,
      "z": -6,
      "name": "Empty"
    },
    {
      "x": -3,
      "y": 6,
      "z": -6,
      "name": "Empty"
    },
    {
      "x": -3,
      "y": 7,
      "z": -6,
      "name": "Rock_Shale_Brick_Stairs",
      "rotation": 11
    },
    {
      "x": -3,
      "y": 8,
      "z": -6,
      "name": "Rock_Shale"
    },
    {
      "x": -3,
      "y": 9,
      "z": -6,
      "name": "Empty"
    },
    {
      "x": -3,
      "y": 10,
      "z": -6,
      "name": "Empty"
    },
    {
      "x": -3,
      "y": 11,
      "z": -6,
      "name": "Empty"
    },
    {
      "x": -3,
      "y": 12,
      "z": -6,
      "name": "Empty"
    },
    {
      "x": -3,
      "y": 13,
      "z": -6,
      "name": "Empty"
    },
    {
      "x": -3,
      "y": 14,
      "z": -6,
      "name": "Empty"
    },
    {
      "x": -3,
      "y": 15,
      "z": -6,
      "name": "Empty"
    },
    {
      "x": -3,
      "y": 16,
      "z": -6,
      "name": "Empty"
    },
    {
      "x": -3,
      "y": 17,
      "z": -6,
      "name": "Empty"
    },
    {
      "x": -3,
      "y": 18,
      "z": -6,
      "name": "Empty"
    },
    {
      "x": -3,
      "y": 19,
      "z": -6,
      "name": "Empty"
    },
    {
      "x": -3,
      "y": 20,
      "z": -6,
      "name": "Empty"
    },
    {
      "x": -3,
      "y": 1,
      "z": -5,
      "name": "Soil_Dirt_Cold"
    },
    {
      "x": -3,
      "y": 2,
      "z": -5,
      "name": "Soil_Dirt_Cold"
    },
    {
      "x": -3,
      "y": 3,
      "z": -5,
      "name": "Empty"
    },
    {
      "x": -3,
      "y": 4,
      "z": -5,
      "name": "Empty"
    },
    {
      "x": -3,
      "y": 5,
      "z": -5,
      "name": "Empty"
    },
    {
      "x": -3,
      "y": 6,
      "z": -5,
      "name": "Empty"
    },
    {
      "x": -3,
      "y": 7,
      "z": -5,
      "name": "Empty"
    },
    {
      "x": -3,
      "y": 8,
      "z": -5,
      "name": "Empty"
    },
    {
      "x": -3,
      "y": 9,
      "z": -5,
      "name": "Rock_Shale"
    },
    {
      "x": -3,
      "y": 10,
      "z": -5,
      "name": "Empty"
    },
    {
      "x": -3,
      "y": 11,
      "z": -5,
      "name": "Empty"
    },
    {
      "x": -3,
      "y": 12,
      "z": -5,
      "name": "Empty"
    },
    {
      "x": -3,
      "y": 13,
      "z": -5,
      "name": "Empty"
    },
    {
      "x": -3,
      "y": 14,
      "z": -5,
      "name": "Empty"
    },
    {
      "x": -3,
      "y": 15,
      "z": -5,
      "name": "Empty"
    },
    {
      "x": -3,
      "y": 16,
      "z": -5,
      "name": "Empty"
    },
    {
      "x": -3,
      "y": 17,
      "z": -5,
      "name": "Empty"
    },
    {
      "x": -3,
      "y": 18,
      "z": -5,
      "name": "Rock_Shale"
    },
    {
      "x": -3,
      "y": 19,
      "z": -5,
      "name": "Rock_Shale"
    },
    {
      "x": -3,
      "y": 20,
      "z": -5,
      "name": "Rock_Shale"
    },
    {
      "x": -3,
      "y": 24,
      "z": -5,
      "name": "Rock_Shale"
    },
    {
      "x": -3,
      "y": 25,
      "z": -5,
      "name": "Rock_Shale"
    },
    {
      "x": -3,
      "y": 2,
      "z": -4,
      "name": "Soil_Dirt_Cold"
    },
    {
      "x": -3,
      "y": 3,
      "z": -4,
      "name": "Empty"
    },
    {
      "x": -3,
      "y": 4,
      "z": -4,
      "name": "Empty"
    },
    {
      "x": -3,
      "y": 5,
      "z": -4,
      "name": "Empty"
    },
    {
      "x": -3,
      "y": 6,
      "z": -4,
      "name": "Empty"
    },
    {
      "x": -3,
      "y": 7,
      "z": -4,
      "name": "Empty"
    },
    {
      "x": -3,
      "y": 8,
      "z": -4,
      "name": "Empty"
    },
    {
      "x": -3,
      "y": 9,
      "z": -4,
      "name": "Plant_Bush_Dead_Hanging"
    },
    {
      "x": -3,
      "y": 10,
      "z": -4,
      "name": "Rock_Shale"
    },
    {
      "x": -3,
      "y": 11,
      "z": -4,
      "name": "Rock_Shale_Brick"
    },
    {
      "x": -3,
      "y": 12,
      "z": -4,
      "name": "Rock_Shale_Brick"
    },
    {
      "x": -3,
      "y": 13,
      "z": -4,
      "name": "Deco_Bone_Pile"
    },
    {
      "x": -3,
      "y": 14,
      "z": -4,
      "name": "Rock_Shale_Brick"
    },
    {
      "x": -3,
      "y": 15,
      "z": -4,
      "name": "Deco_Bone_Skulls"
    },
    {
      "x": -3,
      "y": 16,
      "z": -4,
      "name": "Rock_Shale_Brick"
    },
    {
      "x": -3,
      "y": 17,
      "z": -4,
      "name": "Deco_Bone_Pile"
    },
    {
      "x": -3,
      "y": 18,
      "z": -4,
      "name": "Rock_Shale"
    },
    {
      "x": -3,
      "y": 19,
      "z": -4,
      "name": "Rock_Shale"
    },
    {
      "x": -3,
      "y": 20,
      "z": -4,
      "name": "Rock_Shale"
    },
    {
      "x": -3,
      "y": 21,
      "z": -4,
      "name": "Rock_Shale"
    },
    {
      "x": -3,
      "y": 22,
      "z": -4,
      "name": "Rock_Shale"
    },
    {
      "x": -3,
      "y": 23,
      "z": -4,
      "name": "Rock_Shale"
    },
    {
      "x": -3,
      "y": 24,
      "z": -4,
      "name": "Rock_Shale"
    },
    {
      "x": -3,
      "y": 25,
      "z": -4,
      "name": "Rock_Shale"
    },
    {
      "x": -3,
      "y": 2,
      "z": -3,
      "name": "Empty"
    },
    {
      "x": -3,
      "y": 3,
      "z": -3,
      "name": "Rock_Shale_Brick_Stairs",
      "rotation": 2
    },
    {
      "x": -3,
      "y": 4,
      "z": -3,
      "name": "Empty"
    },
    {
      "x": -3,
      "y": 5,
      "z": -3,
      "name": "Empty"
    },
    {
      "x": -3,
      "y": 6,
      "z": -3,
      "name": "Empty"
    },
    {
      "x": -3,
      "y": 7,
      "z": -3,
      "name": "Empty"
    },
    {
      "x": -3,
      "y": 8,
      "z": -3,
      "name": "Empty"
    },
    {
      "x": -3,
      "y": 9,
      "z": -3,
      "name": "Empty"
    },
    {
      "x": -3,
      "y": 10,
      "z": -3,
      "name": "Empty"
    },
    {
      "x": -3,
      "y": 11,
      "z": -3,
      "name": "Rock_Shale"
    },
    {
      "x": -3,
      "y": 12,
      "z": -3,
      "name": "Rock_Shale_Brick"
    },
    {
      "x": -3,
      "y": 13,
      "z": -3,
      "name": "Rock_Shale_Cobble"
    },
    {
      "x": -3,
      "y": 14,
      "z": -3,
      "name": "Rock_Shale_Cobble"
    },
    {
      "x": -3,
      "y": 15,
      "z": -3,
      "name": "Rock_Shale_Cobble"
    },
    {
      "x": -3,
      "y": 16,
      "z": -3,
      "name": "Rock_Shale_Cobble"
    },
    {
      "x": -3,
      "y": 17,
      "z": -3,
      "name": "Rock_Shale_Cobble"
    },
    {
      "x": -3,
      "y": 18,
      "z": -3,
      "name": "Rock_Shale_Brick"
    },
    {
      "x": -3,
      "y": 19,
      "z": -3,
      "name": "Rock_Shale"
    },
    {
      "x": -3,
      "y": 20,
      "z": -3,
      "name": "Rock_Shale"
    },
    {
      "x": -3,
      "y": 21,
      "z": -3,
      "name": "Rock_Shale"
    },
    {
      "x": -3,
      "y": 22,
      "z": -3,
      "name": "Rock_Shale"
    },
    {
      "x": -3,
      "y": 23,
      "z": -3,
      "name": "Rock_Shale"
    },
    {
      "x": -3,
      "y": 24,
      "z": -3,
      "name": "Rock_Shale"
    },
    {
      "x": -3,
      "y": 2,
      "z": -2,
      "name": "Empty"
    },
    {
      "x": -3,
      "y": 3,
      "z": -2,
      "name": "Empty"
    },
    {
      "x": -3,
      "y": 4,
      "z": -2,
      "name": "Rock_Shale_Brick_Stairs",
      "rotation": 2
    },
    {
      "x": -3,
      "y": 5,
      "z": -2,
      "name": "Empty"
    },
    {
      "x": -3,
      "y": 6,
      "z": -2,
      "name": "Empty"
    },
    {
      "x": -3,
      "y": 7,
      "z": -2,
      "name": "Empty"
    },
    {
      "x": -3,
      "y": 8,
      "z": -2,
      "name": "Empty"
    },
    {
      "x": -3,
      "y": 9,
      "z": -2,
      "name": "Empty"
    },
    {
      "x": -3,
      "y": 10,
      "z": -2,
      "name": "Empty"
    },
    {
      "x": -3,
      "y": 11,
      "z": -2,
      "name": "Rock_Shale_Brick_Stairs",
      "rotation": 11
    },
    {
      "x": -3,
      "y": 12,
      "z": -2,
      "name": "Rock_Shale"
    },
    {
      "x": -3,
      "y": 13,
      "z": -2,
      "name": "Rock_Shale_Brick"
    },
    {
      "x": -3,
      "y": 14,
      "z": -2,
      "name": "Rock_Shale_Brick"
    },
    {
      "x": -3,
      "y": 15,
      "z": -2,
      "name": "Rock_Shale_Brick"
    },
    {
      "x": -3,
      "y": 16,
      "z": -2,
      "name": "Rock_Shale_Brick"
    },
    {
      "x": -3,
      "y": 17,
      "z": -2,
      "name": "Rock_Shale_Brick"
    },
    {
      "x": -3,
      "y": 18,
      "z": -2,
      "name": "Rock_Shale_Brick"
    },
    {
      "x": -3,
      "y": 19,
      "z": -2,
      "name": "Rock_Shale"
    },
    {
      "x": -3,
      "y": 20,
      "z": -2,
      "name": "Rock_Shale"
    },
    {
      "x": -3,
      "y": 21,
      "z": -2,
      "name": "Rock_Shale"
    },
    {
      "x": -3,
      "y": 22,
      "z": -2,
      "name": "Rock_Shale"
    },
    {
      "x": -3,
      "y": 23,
      "z": -2,
      "name": "Rock_Shale"
    },
    {
      "x": -3,
      "y": 24,
      "z": -2,
      "name": "Rock_Shale"
    },
    {
      "x": -3,
      "y": 2,
      "z": -1,
      "name": "Empty"
    },
    {
      "x": -3,
      "y": 3,
      "z": -1,
      "name": "Empty"
    },
    {
      "x": -3,
      "y": 4,
      "z": -1,
      "name": "Empty"
    },
    {
      "x": -3,
      "y": 5,
      "z": -1,
      "name": "Soil_Dirt_Cold"
    },
    {
      "x": -3,
      "y": 6,
      "z": -1,
      "name": "Empty"
    },
    {
      "x": -3,
      "y": 7,
      "z": -1,
      "name": "Empty"
    },
    {
      "x": -3,
      "y": 8,
      "z": -1,
      "name": "Empty"
    },
    {
      "x": -3,
      "y": 9,
      "z": -1,
      "name": "Empty"
    },
    {
      "x": -3,
      "y": 10,
      "z": -1,
      "name": "Empty"
    },
    {
      "x": -3,
      "y": 11,
      "z": -1,
      "name": "Empty"
    },
    {
      "x": -3,
      "y": 12,
      "z": -1,
      "name": "Empty"
    },
    {
      "x": -3,
      "y": 13,
      "z": -1,
      "name": "Rock_Shale"
    },
    {
      "x": -3,
      "y": 14,
      "z": -1,
      "name": "Rock_Shale_Brick"
    },
    {
      "x": -3,
      "y": 15,
      "z": -1,
      "name": "Rock_Shale_Brick"
    },
    {
      "x": -3,
      "y": 16,
      "z": -1,
      "name": "Rock_Shale_Brick"
    },
    {
      "x": -3,
      "y": 17,
      "z": -1,
      "name": "Rock_Shale_Brick"
    },
    {
      "x": -3,
      "y": 18,
      "z": -1,
      "name": "Rock_Shale_Brick"
    },
    {
      "x": -3,
      "y": 19,
      "z": -1,
      "name": "Rock_Shale"
    },
    {
      "x": -3,
      "y": 20,
      "z": -1,
      "name": "Rock_Shale"
    },
    {
      "x": -3,
      "y": 21,
      "z": -1,
      "name": "Rock_Shale"
    },
    {
      "x": -3,
      "y": 22,
      "z": -1,
      "name": "Rock_Shale"
    },
    {
      "x": -3,
      "y": 23,
      "z": -1,
      "name": "Rock_Shale"
    },
    {
      "x": -3,
      "y": 24,
      "z": -1,
      "name": "Rock_Shale"
    },
    {
      "x": -3,
      "y": 25,
      "z": -1,
      "name": "Rock_Shale_Brick_Stairs",
      "rotation": 3
    },
    {
      "x": -3,
      "y": 2,
      "z": 0,
      "name": "Empty"
    },
    {
      "x": -3,
      "y": 3,
      "z": 0,
      "name": "Empty"
    },
    {
      "x": -3,
      "y": 4,
      "z": 0,
      "name": "Empty"
    },
    {
      "x": -3,
      "y": 5,
      "z": 0,
      "name": "Empty"
    },
    {
      "x": -3,
      "y": 6,
      "z": 0,
      "name": "Soil_Dirt_Cold"
    },
    {
      "x": -3,
      "y": 7,
      "z": 0,
      "name": "Plant_Bush_Dead_Twisted"
    },
    {
      "x": -3,
      "y": 8,
      "z": 0,
      "name": "Empty"
    },
    {
      "x": -3,
      "y": 9,
      "z": 0,
      "name": "Empty"
    },
    {
      "x": -3,
      "y": 10,
      "z": 0,
      "name": "Empty"
    },
    {
      "x": -3,
      "y": 11,
      "z": 0,
      "name": "Empty"
    },
    {
      "x": -3,
      "y": 12,
      "z": 0,
      "name": "Empty"
    },
    {
      "x": -3,
      "y": 13,
      "z": 0,
      "name": "Empty"
    },
    {
      "x": -3,
      "y": 14,
      "z": 0,
      "name": "Rock_Shale"
    },
    {
      "x": -3,
      "y": 15,
      "z": 0,
      "name": "Rock_Shale_Brick"
    },
    {
      "x": -3,
      "y": 16,
      "z": 0,
      "name": "Rock_Shale_Brick"
    },
    {
      "x": -3,
      "y": 17,
      "z": 0,
      "name": "Rock_Shale_Brick"
    },
    {
      "x": -3,
      "y": 18,
      "z": 0,
      "name": "Rock_Shale_Brick"
    },
    {
      "x": -3,
      "y": 19,
      "z": 0,
      "name": "Rock_Shale"
    },
    {
      "x": -3,
      "y": 20,
      "z": 0,
      "name": "Rock_Shale"
    },
    {
      "x": -3,
      "y": 21,
      "z": 0,
      "name": "Rock_Shale"
    },
    {
      "x": -3,
      "y": 22,
      "z": 0,
      "name": "Rock_Shale"
    },
    {
      "x": -3,
      "y": 23,
      "z": 0,
      "name": "Rock_Shale"
    },
    {
      "x": -3,
      "y": 24,
      "z": 0,
      "name": "Rock_Shale"
    },
    {
      "x": -3,
      "y": 2,
      "z": 1,
      "name": "Empty"
    },
    {
      "x": -3,
      "y": 3,
      "z": 1,
      "name": "Empty"
    },
    {
      "x": -3,
      "y": 4,
      "z": 1,
      "name": "Empty"
    },
    {
      "x": -3,
      "y": 5,
      "z": 1,
      "name": "Empty"
    },
    {
      "x": -3,
      "y": 6,
      "z": 1,
      "name": "Rock_Shale_Brick"
    },
    {
      "x": -3,
      "y": 7,
      "z": 1,
      "name": "Rock_Basalt"
    },
    {
      "x": -3,
      "y": 8,
      "z": 1,
      "name": "Rubble_Basalt"
    },
    {
      "x": -3,
      "y": 9,
      "z": 1,
      "name": "Empty"
    },
    {
      "x": -3,
      "y": 10,
      "z": 1,
      "name": "Empty"
    },
    {
      "x": -3,
      "y": 11,
      "z": 1,
      "name": "Empty"
    },
    {
      "x": -3,
      "y": 12,
      "z": 1,
      "name": "Empty"
    },
    {
      "x": -3,
      "y": 13,
      "z": 1,
      "name": "Empty"
    },
    {
      "x": -3,
      "y": 14,
      "z": 1,
      "name": "Plant_Bush_Dead_Hanging"
    },
    {
      "x": -3,
      "y": 15,
      "z": 1,
      "name": "Rock_Shale"
    },
    {
      "x": -3,
      "y": 16,
      "z": 1,
      "name": "Rock_Shale_Brick"
    },
    {
      "x": -3,
      "y": 17,
      "z": 1,
      "name": "Rock_Shale_Brick"
    },
    {
      "x": -3,
      "y": 18,
      "z": 1,
      "name": "Rock_Shale_Brick"
    },
    {
      "x": -3,
      "y": 19,
      "z": 1,
      "name": "Rock_Shale"
    },
    {
      "x": -3,
      "y": 20,
      "z": 1,
      "name": "Rock_Shale"
    },
    {
      "x": -3,
      "y": 21,
      "z": 1,
      "name": "Rock_Shale"
    },
    {
      "x": -3,
      "y": 22,
      "z": 1,
      "name": "Rock_Shale"
    },
    {
      "x": -3,
      "y": 23,
      "z": 1,
      "name": "Rock_Shale"
    },
    {
      "x": -3,
      "y": 24,
      "z": 1,
      "name": "Rock_Shale"
    },
    {
      "x": -3,
      "y": 2,
      "z": 2,
      "name": "Empty"
    },
    {
      "x": -3,
      "y": 3,
      "z": 2,
      "name": "Empty"
    },
    {
      "x": -3,
      "y": 4,
      "z": 2,
      "name": "Empty"
    },
    {
      "x": -3,
      "y": 5,
      "z": 2,
      "name": "Empty"
    },
    {
      "x": -3,
      "y": 6,
      "z": 2,
      "name": "Rock_Shale_Brick"
    },
    {
      "x": -3,
      "y": 7,
      "z": 2,
      "name": "Rock_Shale_Brick"
    },
    {
      "x": -3,
      "y": 8,
      "z": 2,
      "name": "Rock_Basalt"
    },
    {
      "x": -3,
      "y": 9,
      "z": 2,
      "name": "Rock_Basalt"
    },
    {
      "x": -3,
      "y": 10,
      "z": 2,
      "name": "Empty"
    },
    {
      "x": -3,
      "y": 11,
      "z": 2,
      "name": "Empty"
    },
    {
      "x": -3,
      "y": 12,
      "z": 2,
      "name": "Empty"
    },
    {
      "x": -3,
      "y": 13,
      "z": 2,
      "name": "Empty"
    },
    {
      "x": -3,
      "y": 14,
      "z": 2,
      "name": "Empty"
    },
    {
      "x": -3,
      "y": 15,
      "z": 2,
      "name": "Rock_Shale_Brick_Stairs",
      "rotation": 11
    },
    {
      "x": -3,
      "y": 16,
      "z": 2,
      "name": "Rock_Shale"
    },
    {
      "x": -3,
      "y": 17,
      "z": 2,
      "name": "Rock_Shale_Brick"
    },
    {
      "x": -3,
      "y": 18,
      "z": 2,
      "name": "Rock_Shale_Brick"
    },
    {
      "x": -3,
      "y": 19,
      "z": 2,
      "name": "Rock_Shale"
    },
    {
      "x": -3,
      "y": 20,
      "z": 2,
      "name": "Rock_Shale"
    },
    {
      "x": -3,
      "y": 21,
      "z": 2,
      "name": "Rock_Shale"
    },
    {
      "x": -3,
      "y": 22,
      "z": 2,
      "name": "Rock_Shale"
    },
    {
      "x": -3,
      "y": 23,
      "z": 2,
      "name": "Rock_Shale"
    },
    {
      "x": -3,
      "y": 24,
      "z": 2,
      "name": "Rock_Shale"
    },
    {
      "x": -3,
      "y": 2,
      "z": 3,
      "name": "Empty"
    },
    {
      "x": -3,
      "y": 3,
      "z": 3,
      "name": "Empty"
    },
    {
      "x": -3,
      "y": 4,
      "z": 3,
      "name": "Empty"
    },
    {
      "x": -3,
      "y": 5,
      "z": 3,
      "name": "Empty"
    },
